Workbook

Sheet 表紙
A1: システム名 | K1: システム種別 | AP1: 作成者 | AT1: 作成日 | AY1: 更新者 | BC1: 更新日 | BH1: 版数
A2: 現金専用簡易セルフPOS | K2: LUVINAコントローラー | AP2: =改廃履歴!$H$11 -> Thanh Nguyên | AT2: =改廃履歴!$B$11 -> 45209 | AY2: =LOOKUP(2,1/(改廃履歴!H11:H30000<>""),改廃履歴!H11:H30000) -> Thanh Nguyên | BC2: =LOOKUP(2,1/(改廃履歴!B11:B30000<>""),改廃履歴!B11:B30000) -> 45209 | BH2: =LOOKUP(2,1/(改廃履歴!O11:O30000<>""),改廃履歴!O11:O30000) -> 0.2
A4: 機能カテゴリ | H4: API | U4: 項目 | Z4: 基本設計書 | AP4: {=RIGHT(CELL("filename",$A$1),LEN(CELL("filename",$A$1))-FIND("]",CELL("filename",$A$1)))} -> 表紙
L16: 現金専用簡易セルフPOS 基本設計書
L24: =K2&"/"&H4&"/"&Z4 -> LUVINAコントローラー/API/基本設計書
Q44: 承認日 | AA44: 承認者 | AQ44: 版数

Sheet 改廃履歴
A1: システム名 | K1: システム種別 | W1: =IF(表紙!W1="","",表紙!W1) | AP1: 作成者 | AT1: 作成日 | AY1: 更新者 | BC1: 更新日 | BH1: 版数
A2: =IF(表紙!A2="","",表紙!A2) -> 現金専用簡易セルフPOS | K2: =IF(表紙!K2="","",表紙!K2) -> LUVINAコントローラー | AP2: =IF(表紙!AP2="","",表紙!AP2) -> Thanh Nguyên | AT2: =IF(表紙!AT2="","",表紙!AT2) -> 45209 | AY2: =IF(表紙!AY2="","",表紙!AY2) -> Thanh Nguyên | BC2: =IF(表紙!BC2="","",表紙!BC2) -> 45209 | BH2: =IF(表紙!BH2="","",表紙!BH2) -> 0.2
A4: 機能カテゴリ | H4: =IF(表紙!H4="","",表紙!H4) -> API | U4: 項目 | Z4: =IF(表紙!Z4="","",表紙!Z4) -> 基本設計書 | AP4: {=RIGHT(CELL("filename",$A$1),LEN(CELL("filename",$A$1))-FIND("]",CELL("filename",$A$1)))} -> 改廃履歴
B8: ■改廃履歴
B10: 更新日付 | H10: 更新者 | O10: 版数 | S10: 変更内容 | AX10: 承認日付 | BD10: 承認者
B11: 45209 | H11: Thanh Nguyên | O11: 0.2 | S11: 初版

Sheet Tổng hợp
A1: システム名 | K1: システム種別 | W1: =IF(表紙!W1="","",表紙!W1) | AP1: 作成者 | AT1: 作成日 | AY1: 更新者 | BC1: 更新日 | BH1: 版数
A2: =IF(表紙!A2="","",表紙!A2) -> 現金専用簡易セルフPOS | K2: =IF(表紙!K2="","",表紙!K2) -> LUVINAコントローラー | AP2: =IF(表紙!AP2="","",表紙!AP2) -> Thanh Nguyên | AT2: =IF(表紙!AT2="","",表紙!AT2) -> 45209 | AY2: =IF(表紙!AY2="","",表紙!AY2) -> Thanh Nguyên | BC2: =IF(表紙!BC2="","",表紙!BC2) -> 45209 | BH2: =IF(表紙!BH2="","",表紙!BH2) -> 0.2
A4: 機能カテゴリ | H4: =IF(表紙!H4="","",表紙!H4) -> API | U4: 項目 | Z4: =IF(表紙!Z4="","",表紙!Z4) -> 基本設計書 | AP4: {=RIGHT(CELL("filename",$A$1),LEN(CELL("filename",$A$1))-FIND("]",CELL("filename",$A$1)))} -> Tổng hợp
B7: Báo cáo điều tra
B8: Nội dung báo cáo:
B9: 1. Định nghĩa yêu cầu:
C10: Bối cảnh: Kiyohara nghĩ rằng khi release chức năng nạp point cho cty Maruestu sẽ phát sinh nhiều lỗi.
C11: Lỗi đó có thể do phía API.
C12: Để xác định được nguyên nhân, thời điểm phát sinh lỗi, bác Kiyoahara request team ghi log ở android app khi request API tới server
C13: Log này sẽ đặt ở Luvina controler. Cách ghi log chỉ làm đơn giản là log lại nội dung request gửi đi và response nhận về.
C14: Khi có log lỗi, server sẽ thực hiện gửi mail đính kèm file log vào 1 địa chỉ mail mặc định.
C15: Deadline mong muốn: trước khi chức năng 4_0 đc release
C17: Sau khi trao đổi lần 1, Mr. K mong muốn mỗi khi có lỗi sẽ gửi lên server, server gửi về mail, tương tự như chức năng attendance device
C18: Dưới đây là ảnh file log trong hệ thống hiện tại của khách hàng
B39: 2. Kết quả điều tra lần 1
C40: 2.1 Phía app POS-Android
C41: - Nội dung log: Nội dung request gửi đi và response nhận về của flow 4_0 của công ty Maruetsu
C42: - Phương thức ghi log:
C43: Ghi ra file, mỗi giao dịch nạp point 1 file
C44: Nếu là flow nạp point, thì tạo 1 folder để chứa file log giao dịch. Trong folder chỉ tồn tại duy nhất 1 file, trước khi tạo mới file log thì remove file log cũ.
C45: Tên file log: yyyymmddHHMMss-IMoneyCharging-CompanyCode-StoreCode-InstoreCode.text
C46: - Thời điểm gửi file lên server: Khi xảy ra lỗi API trong flow nạp point thì gửi file lên, gửi thành công thì xóa file log.
C49: 2.2 Phía server
C50: Khi có request gửi file log lên server, server thực hiện lưu file log, đồng thời gửi file log đến địa chỉ email mặc định.
C51: Phía server cần chuẩn bị 1 API để app gửi log. Tham khảo sheet API L001
B53: 3. Kết quả điều tra lần 2
B54: 3.1 Thời điểm gửi log
C55: Sau khi trao đổi lần 1, Mr.K đang mong muốn mỗi khi call API đều thực hiện gửi log lên server, việc phát hiện API lỗi thì là real time.
C56: Team đồng ý với phương án này. Khi call API có response thì thực hiện gửi log lên server
C57: Ngoài ra, ticket này còn xử lý thêm, nếu Log của API C002, M102, M103 thì thực hiện lưu vào bảng doanh thu để phục vụ cho flow 2_5 (#11317)
B59: 3.2 Nội dung log gửi lên server
C60: URL, header
C61: Request, response của API
B65: 3.3 Format request API
C66: Date time: yyyymmdd hhMMsss
C67: IP address
C68: Url
C69: Headers
C70: Request
C71: Response code
...

Sheet APX001
A1: 現金POS | M1: 製品 | AE1: 設計 | AR1: No. | BB1: API | BU1: METHOD | CJ1: 認証 | CX1: 作成情報 | DG1: 更新情報
M2: POS-Controller | AE2: WebAPI 設計 | AR2: =MID(CELL("filename",A1),FIND("]",CELL("filename",A1))+1,255) -> APX001 | BB2: pos/v1/APX001 | BU2: POST | CJ2: Bearer | CX2: 作成者 | DA2: DuNT | DG2: 更新者 | DJ2: DuNT
CX3: 作成日 | DA3: 45152 | DG3: 更新日 | DJ3: 45152
A5: ▪Client
B7: Request | BH7: Response<200：OK>
C8: Properties | P8: Type | U8: Length | Z8: Explanation | AK8: required | AN8: Example | BI8: Properties | BV8: Type | CA8: Length | CF8: Explanation | CS8: Example
C9: ip_address | P9: string | U9: 39 | BI9: なし | BV9: - | CA9: - | CF9: -
C10: url | P10: string | U10: -
C11: headers | P11: Map | U11: -
C12: request | P12: string | U12: -
C13: response_code | P13: Int | U13: -
C14: response | P14: string | U14: -
B16: Additional information | BH16: Error Message
BI17: HTTP Status | BQ17: message | CS17: Explaination
BI18: 401 | BQ18: 本文無し
A25: ▪Server
B27: Request mapping DB | BH27: Response mapping DB
C28: Properties | V28: Table [Column] | BI28: Properties | CB28: Table [Column]
C29: ip_address | V29: [logmaster]IpAddress
C30: url | V30: [logmaster]Url
C31: headers | V31: [logmaster]Headers
C32: request | V32: [logmaster]Request
C33: response_code | V33: [logmaster]ResponseCode
C34: response | V34: [logmaster]Response
B36: Additional Information | BH36: Additional Information
C37: Các cột CompanyCode, StoreCode, InstoreCode sẽ lấy giá trị được parse từ Bearer
C38: Trường hợp ghi log của API C002, M102, M103 thì thực hiện ghi data của response vào bảng charge_info
C39: để phục vụ chức năng 2_5.
C40: Tham khảo tài liệu của chức năng 2_5

Sheet L001
A1: 現金POS | M1: 製品 | AE1: 設計 | AR1: No. | BB1: API | BU1: METHOD | CJ1: 認証 | CX1: 作成情報 | DG1: 更新情報
M2: POS-Controller | AE2: WebAPI 設計 | AR2: =MID(CELL("filename",A1),FIND("]",CELL("filename",A1))+1,255) -> L001 | BB2: pos/v1/log | BU2: POST | CJ2: Bearer | CX2: 作成者 | DA2: DuNT | DG2: 更新者 | DJ2: DuNT
CX3: 作成日 | DA3: 45152 | DG3: 更新日 | DJ3: 45152
A5: ▪Client
B7: Request | BH7: Response<200：OK>
C8: Properties | P8: Type | U8: Length | Z8: Explanation | AK8: required | AN8: Example | BI8: Properties | BV8: Type | CA8: Length | CF8: Explanation | CS8: Example
C9: ip_address | P9: string | U9: 39 | BI9: なし | BV9: - | CA9: - | CF9: -
C10: url | P10: string | U10: -
C11: headers | P11: Map | U11: -
C12: request | P12: string | U12: -
C13: response_code | P13: Int | U13: -
C14: response | P14: string | U14: -
B16: Additional information | BH16: Error Message
BI17: HTTP Status | BQ17: message | CS17: Explaination
BI18: 401 | BQ18: 本文無し
A25: ▪Server
B27: Request mapping DB | BH27: Response mapping DB
C28: Properties | V28: Table [Column] | BI28: Properties | CB28: Table [Column]
C29: ip_address | V29: [logmaster]IpAddress
C30: url | V30: [logmaster]Url
C31: headers | V31: [logmaster]Headers
C32: request | V32: [logmaster]Request
C33: response_code | V33: [logmaster]ResponseCode
C34: response | V34: [logmaster]Response
B36: Additional Information | BH36: Additional Information
C37: Các cột CompanyCode, StoreCode, InstoreCode sẽ lấy giá trị được parse từ Bearer
C38: Trường hợp ghi log của API C002, M102, M103 thì thực hiện ghi data của response vào bảng charge_info
C39: để phục vụ chức năng 2_5.
C40: Tham khảo tài liệu của chức năng 2_5

Sheet テンプレート
A1: システム名 | K1: システム種別 | W1: =IF(表紙!W1="","",表紙!W1) | AP1: 作成者 | AT1: 作成日 | AY1: 更新者 | BC1: 更新日 | BH1: 版数
A2: =IF(表紙!A2="","",表紙!A2) -> 現金専用簡易セルフPOS | K2: =IF(表紙!K2="","",表紙!K2) -> LUVINAコントローラー | AP2: =IF(表紙!AP2="","",表紙!AP2) -> Thanh Nguyên | AT2: =IF(表紙!AT2="","",表紙!AT2) -> 45209 | AY2: =IF(表紙!AY2="","",表紙!AY2) -> Thanh Nguyên | BC2: =IF(表紙!BC2="","",表紙!BC2) -> 45209 | BH2: =IF(表紙!BH2="","",表紙!BH2) -> 0.2
A4: 機能カテゴリ | H4: =IF(表紙!H4="","",表紙!H4) -> API | U4: 項目 | Z4: =IF(表紙!Z4="","",表紙!Z4) -> 基本設計書 | AP4: {=RIGHT(CELL("filename",$A$1),LEN(CELL("filename",$A$1))-FIND("]",CELL("filename",$A$1)))} -> テンプレート
