Workbook

Sheet 表紙
A1: システム名 | K1: システム種別 | W1: 詳細設計書 | AP1: 作成者 | AT1: 作成日 | AY1: 更新者 | BC1: 更新日 | BH1: 版数
A2: POSサーバー | K2: POSサーバ | AP2: =改訂履歴!$H$11 -> TuyenNH | AT2: =改訂履歴!$B$11 -> 45642 | AY2: =LOOKUP(2,1/(改訂履歴!H11:H30000<>""),改訂履歴!H11:H30000) -> TuyenNH | BC2: =LOOKUP(2,1/(改訂履歴!B11:B30000<>""),改訂履歴!B11:B30000) -> 45642 | BH2: =LOOKUP(2,1/(改訂履歴!O11:O30000<>""),改訂履歴!O11:O30000) -> 0.1
A4: 機能カテゴリ | H4: AP0802 | U4: 項目 | Z4: API設計書 | AP4: {=RIGHT(CELL("filename",$A$1),LEN(CELL("filename",$A$1))-FIND("]",CELL("filename",$A$1)))} -> 表紙
L16: POSサーバーの詳細設計書
L24: =K2&"/"&H4&"/"&Z4 -> POSサーバ/AP0802/API設計書
Q44: 承認日 | AA44: 承認者 | AQ44: 版数

Sheet 改訂履歴
A1: システム名 | K1: システム種別 | W1: =IF(表紙!W1="","",表紙!W1) -> 詳細設計書 | AP1: 作成者 | AT1: 作成日 | AY1: 更新者 | BC1: 更新日 | BH1: 版数
A2: =IF(表紙!A2="","",表紙!A2) -> POSサーバー | K2: =IF(表紙!K2="","",表紙!K2) -> POSサーバ | AP2: =IF(表紙!AP2="","",表紙!AP2) -> TuyenNH | AT2: =IF(表紙!AT2="","",表紙!AT2) -> 45642 | AY2: =IF(表紙!AY2="","",表紙!AY2) -> TuyenNH | BC2: =IF(表紙!BC2="","",表紙!BC2) -> 45642 | BH2: =IF(表紙!BH2="","",表紙!BH2) -> 0.1
A4: 機能カテゴリ | H4: =IF(表紙!H4="","",表紙!H4) -> AP0802 | U4: 項目 | Z4: =IF(表紙!Z4="","",表紙!Z4) -> API設計書 | AP4: {=RIGHT(CELL("filename",$A$1),LEN(CELL("filename",$A$1))-FIND("]",CELL("filename",$A$1)))} -> 改訂履歴
B8: ■改訂履歴
B10: 更新日 | H10: 更新者 | O10: 版数 | S10: 更新内容 | AX10: 承認日 | BD10: 承認者
B11: 45642 | H11: TuyenNH | O11: 0.1 | S11: 新規

Sheet 処理フロー凡例
A1: システム名 | K1: システム種別 | W1: =IF(表紙!W1="","",表紙!W1) -> 詳細設計書 | AP1: 作成者 | AT1: 作成日 | AY1: 更新者 | BC1: 更新日 | BH1: 版数
A2: =IF(表紙!A2="","",表紙!A2) -> POSサーバー | K2: =IF(表紙!K2="","",表紙!K2) -> POSサーバ | AP2: =IF(表紙!AP2="","",表紙!AP2) -> TuyenNH | AT2: =IF(表紙!AT2="","",表紙!AT2) -> 45642 | AY2: =IF(表紙!AY2="","",表紙!AY2) -> TuyenNH | BC2: =IF(表紙!BC2="","",表紙!BC2) -> 45642 | BH2: =IF(表紙!BH2="","",表紙!BH2) -> 0.1
A4: 機能カテゴリ | H4: =IF(表紙!H4="","",表紙!H4) -> AP0802 | U4: 項目 | Z4: =IF(表紙!Z4="","",表紙!Z4) -> API設計書 | AP4: =MID(CELL("filename",A1),FIND("]",CELL("filename",A1))+1,255) -> 処理フロー凡例
B7: ●API処理フロー

Sheet AP0802
A1: システム名 | K1: システム種別 | W1: =IF(表紙!W1="","",表紙!W1) -> 詳細設計書 | AP1: 作成者 | AT1: 作成日 | AY1: 更新者 | BC1: 更新日 | BH1: 版数
A2: =IF(表紙!A2="","",表紙!A2) -> POSサーバー | K2: =IF(表紙!K2="","",表紙!K2) -> POSサーバ | AP2: =IF(表紙!AP2="","",表紙!AP2) -> TuyenNH | AT2: =IF(表紙!AT2="","",表紙!AT2) -> 45642 | AY2: =IF(表紙!AY2="","",表紙!AY2) -> TuyenNH | BC2: =IF(表紙!BC2="","",表紙!BC2) -> 45642 | BH2: =IF(表紙!BH2="","",表紙!BH2) -> 0.1
A4: 機能カテゴリ | H4: =IF(表紙!H4="","",表紙!H4) -> AP0802 | U4: 項目 | Z4: =IF(表紙!Z4="","",表紙!Z4) -> API設計書 | AP4: =MID(CELL("filename",A1),FIND("]",CELL("filename",A1))+1,255) -> AP0802
B7: 1. 概要
C9: カテゴリ値引・割引詳細情報を取得する。
B11: 2. リクエスト
C13: 2.1 Request URL
C15: No. | E15: URL | AG15: HTTPメソッド | AQ15: 備考
C16: 1 | E16: api/v1/discount-category/detail | AG16: GET | AQ16: -
C18: 2. 2 Request Header
C20: No. | E20: ヘッダー | L20: 必須 | O20: 型 | S20: デフォルト値 | Z20: 項目説明 | AQ20: 備考
C21: 1 | E21: Authorization | L21: ○ | O21: String | S21: - | Z21: Api key | AQ21: 代表ユーザーを認証するAPIキー値 フォーマット："Bearer {api_key}"
C23: 2 | E23: Accept | L23: - | O23: String | S23: - | Z23: Accept | AQ23: サーバーが返却できるデータ種類情報を説明する。
C24: 3 | E24: Content-Type | L24: ○ | O24: String | S24: application/json | Z24: Content-Type | AQ24: 送信リクエストの本文情報のタイプを定義する。例: application/json, mutilpart/form-data. 転送データのタイプによって、content-typeが必須又は必須ではない。例： ・入力がjsonの場合、content-typeが必須であり、application/jsonの値を受け取る。
C31: 4 | E31: User-Agent | L31: - | O31: String | S31: - | Z31: User-Agent | AQ31: サーバーを呼び出すクライアントのアプリケーション/ソフトウェア/ブラウザを定義する。
C32: 5 | E32: Accept-Encoding | L32: - | O32: String | S32: - | Z32: Accept-Encoding | AQ32: データ暗号化アルゴリズムを定義する。サーバーから受信したデータに使用できる： zip、gzip、png、gif等
C34: 2.3 Query Parameter/ path parameter
C36: No. | E36: パラメータ | L36: 必須 | O36: 型 | S36: デフォルト値 | Z36: 項目説明 | AQ36: 備考
C37: 1 | E37: selected_store | L37: ○ | O37: String | S37: - | Z37: 対象店舗コード | AQ37: ・バリデーションチェック：4桁未満の場合、 エラーメッセージ = MSG_VAL_002
C38: 2 | E38: record_id | L38: ○ | O38: Bigint | S38: - | Z38: レコードID | AQ38: -
C40: 2.4 Request Body
E41: NA
C43: ※サンプル
D44: N/A
B46: 3. レスポンス
C48: 3.1. 正常の場合のレスポンスフォーマット
C50: No. | E50: JSON name | O50: 型 | S50: 項目説明 | AC50: 備考
C51: 1 | E51: record_id | O51: Bigint | S51: M_DiscountMDHierarchy.RECORD_ID | AC51: -
C52: 2 | E52: company_code | O52: String | S52: M_DiscountMDHierarchy.CompanyCode | AC52: 企業コード
C53: 3 | E53: store_code | O53: String | S53: M_DiscountMDHierarchy.StoreCode | AC53: 店舗コード
C54: 4 | E54: discount_md_hierarchy_code | O54: String | S54: M_DiscountMDHierarchy.DiscountMDHierarchyCode | AC54: 割引コード
C55: 5 | E55: md_hierarchy_code | O55: String | S55: M_DiscountMDHierarchy.MDHierarchyCode | AC55: 割引が設定されている商品階層コード
C56: 6 | E56: md_hierarchy_level | O56: Int | S56: M_DiscountMDHierarchy.MDHierarchyLevel | AC56: 割引が設定されている商品階層
C57: 7 | E57: apply_date_time | O57: String | S57: M_DiscountMDHierarchy.ApplyDateTime | AC57: 適用日 形式：yyyy/MM/dd hh:mm:ss
C58: 8 | E58: code_level_one | O58: string | S58: M_MDHierarchy.Code | AC58: 部門コード
C59: 9 | E59: level_one | O59: Int | S59: M_MDHierarchy.Level | AC59: 部門
C60: 10 | E60: description_level_one | O60: string | S60: M_MDHierarchy.Description | AC60: 部門名称
C61: 11 | E61: code_level_two | O61: string | S61: M_MDHierarchy.Code | AC61: 品群コード
C62: 12 | E62: level_two | O62: Int | S62: M_MDHierarchy.Level | AC62: 品群
... C76: 26 | E76: discount_value | O76: Decimal | S76: DiscountValue | AC76: カテゴリ値引(割引率・値引金額)
...

Sheet 処理フロー
A1: システム名 | K1: システム種別 | W1: =IF(表紙!W1="","",表紙!W1) -> 詳細設計書 | AP1: 作成者 | AT1: 作成日 | AY1: 更新者 | BC1: 更新日 | BH1: 版数
A2: =IF(表紙!A2="","",表紙!A2) -> POSサーバー | K2: =IF(表紙!K2="","",表紙!K2) -> POSサーバ | AP2: =IF(表紙!AP2="","",表紙!AP2) -> TuyenNH | AT2: =IF(表紙!AT2="","",表紙!AT2) -> 45642 | AY2: =IF(表紙!AY2="","",表紙!AY2) -> TuyenNH | BC2: =IF(表紙!BC2="","",表紙!BC2) -> 45642 | BH2: =IF(表紙!BH2="","",表紙!BH2) -> 0.1
A4: 機能カテゴリ | H4: =IF(表紙!H4="","",表紙!H4) -> AP0802 | U4: 項目 | Z4: =IF(表紙!Z4="","",表紙!Z4) -> API設計書 | AP4: =MID(CELL("filename",A1),FIND("]",CELL("filename",A1))+1,255) -> 処理フロー

Sheet テンプレート
A1: システム名 | K1: システム種別 | W1: =IF(表紙!W1="","",表紙!W1) -> 詳細設計書 | AP1: 作成者 | AT1: 作成日 | AY1: 更新者 | BC1: 更新日 | BH1: 版数
A2: =IF(表紙!A2="","",表紙!A2) -> POSサーバー | K2: =IF(表紙!K2="","",表紙!K2) -> POSサーバ | AP2: =IF(表紙!AP2="","",表紙!AP2) -> TuyenNH | AT2: =IF(表紙!AT2="","",表紙!AT2) -> 45642 | AY2: =IF(表紙!AY2="","",表紙!AY2) -> TuyenNH | BC2: =IF(表紙!BC2="","",表紙!BC2) -> 45642 | BH2: =IF(表紙!BH2="","",表紙!BH2) -> 0.1
A4: 機能カテゴリ | H4: =IF(表紙!H4="","",表紙!H4) -> AP0802 | U4: 項目 | Z4: =IF(表紙!Z4="","",表紙!Z4) -> API設計書 | AP4: =MID(CELL("filename",A1),FIND("]",CELL("filename",A1))+1,255) -> テンプレート
