Workbook

Sheet 3.支払併用マトリクス
B2: いなげや様次期店舗システム | O2: システム名 | U2: 業務名 | Z2: 支払併用マトリクス | AP2: 履歴 | AS2: 改訂者 | AV2: 最終更新日 | AY2: 作成者 | BB2: 作成日
B3: UI設計書 | O3: コード決済 | U3: コード決済対応 | AP3: 第 | AQ3: =[5]改版履歴!$AQ$3 -> 2.3 | AR3: 版 | AS3: =[5]改版履歴!$AS$3 -> 富士通 | AV3: =[5]改版履歴!$AV$3 -> 45394 | AY3: =[5]改版履歴!$AY$3 -> 富士通 | BB3: =[5]改版履歴!$BB$3 -> 44811
C6: ３．支払併用マトリクス
C7: ３－1．支払併用マトリクス
D8: ３－１－１．＜＜通常ＰＯＳ＞＞
E10: ■コード決済と他支払との併用について（通常POS）
F11: ・原則としてコード決済支払は一括での支払いのみ可能とする。
F12: ・他支払との併用については、先に支払登録していた場合のみ可能とする。
F13: （例）
G14: ×：コード決済支払 → ポイント利用登録
G15: 〇：ポイント利用登録 → コード決済支払
F16: ・「クレジット」、「交通系IC」はコード決済と同じく一括支払いのみのため、先に支払登録をしても併用不可となる。
F17: ・「現金」については、先に支払登録をした場合併用可能となるが、いなげや様での運用制限を実施する。
A18: *1.9 | F18: ・QUOカードPay残高不足の場合のみ、現金、現外券、ポイント利用の後併用を可能とする。
F20: 支払併用マトリクス図（通常POS）
J21: 現金 | M21: 現外券 | P21: ポイント利用 | S21: クレジット | V21: 交通系IC | Y21: コード決済
F24: 現金 | AB24: ・「現金」はシステム上併用可能だが、
AB25: 運用上で制限を実施。
F26: 現外券
F28: ポイント 利用
F30: クレジット
F32: 交通系IC
A34: *1.9 | F34: コード決済
A35: *1.9
J36: ・コード決済を先に支払っての併用は、すべて「×」（一括支払のみのため）
J37: ・ただしQUOカードPay残高不足の場合のみ、△の金種との併用が可能
B54: いなげや様次期店舗システム | O54: システム名 | U54: 業務名 | Z54: =$Z$2 -> 支払併用マトリクス | AP54: 履歴 | AS54: 改訂者 | AV54: 最終更新日 | AY54: 作成者 | BB54: 作成日
B55: UI設計書 | O55: =$O$3 -> コード決済 | U55: =$U$3 -> コード決済対応 | AP55: 第 | AQ55: =$AQ$3 -> 2.3 | AR55: 版 | AS55: =$AS$3 -> 富士通 | AV55: =$AV$3 -> 45394 | AY55: =$AY$3 -> 富士通 | BB55: =$BB$3 -> 44811
D58: ３－１－２．＜＜スキャニングステーション＞＞
E60: ■コード決済と他支払との併用について（スキャニングステーション）
F61: ・原則としてコード決済支払は一括での支払いのみ可能とする。
F62: ・他支払との併用については、先に支払登録していた場合のみ可能とする。
F63: （例）
G64: ×：コード決済支払 → ポイント利用登録
G65: 〇：ポイント利用登録 → コード決済支払
F66: ・スキャニングステーションにおいては、釣銭釣札機、クレジット決済端末がないため関連する支払は除外する。
A67: *1.9 | F67: ・QUOカードPay残高不足の場合のみ、現外券、ポイント利用の後併用を可能とする。
F69: 支払併用マトリクス図（スキャニングステーション）
J70: 現金 | M70: 現外券 | P70: ポイント利用 | S70: クレジット | V70: 交通系IC | Y70: コード決済
F73: 現金
...
