Workbook

Sheet 表紙
A1: システム名 | K1: システム種別 | W1: 基本設計書 | AP1: 作成者 | AT1: 作成日 | AY1: 更新者 | BC1: 更新日 | BH1: 版数
A2: 現金専用簡易セルフPOS | K2: API | AP2: きよはら | AT2: 44867 | AY2: =LOOKUP(2,1/(改廃履歴!H11:H30000<>""),改廃履歴!H11:H30000) -> きよはら | BC2: 44867 | BH2: =LOOKUP(2,1/(改廃履歴!O11:O30000<>""),改廃履歴!O11:O30000) -> 0.1
A4: 機能カテゴリ | H4: 共通 | U4: 項目 | Z4: API(設定)定義書 | AP4: 表紙
L16: 現金専用簡易セルフPOS 基本設計書
L24: =K2&"/"&H4&"/"&Z4 -> API/共通/API(設定)定義書
Q44: 承認日 | AA44: 承認者 | AQ44: 版数

Sheet 改廃履歴
A1: システム名 | K1: システム種別 | W1: =IF(表紙!W1="","",表紙!W1) -> 基本設計書 | AP1: 作成者 | AT1: 作成日 | AY1: 更新者 | BC1: 更新日 | BH1: 版数
A2: =IF(表紙!A2="","",表紙!A2) -> 現金専用簡易セルフPOS | K2: =IF(表紙!K2="","",表紙!K2) -> API | AP2: =IF(表紙!AP2="","",表紙!AP2) -> きよはら | AT2: =IF(表紙!AT2="","",表紙!AT2) -> 44867 | AY2: =IF(表紙!AY2="","",表紙!AY2) -> きよはら | BC2: =IF(表紙!BC2="","",表紙!BC2) -> 44867 | BH2: =IF(表紙!BH2="","",表紙!BH2) -> 0.1
A4: 機能カテゴリ | H4: =IF(表紙!H4="","",表紙!H4) -> 共通 | U4: 項目 | Z4: =IF(表紙!Z4="","",表紙!Z4) -> API(設定)定義書 | AP4: 改廃履歴
B8: ■改廃履歴
B10: 更新日付 | H10: 更新者 | O10: 版数 | S10: 変更内容 | AX10: 承認日付 | BD10: 承認者
B11: 44867 | H11: きよはら | O11: 0.1 | S11: 新規作成

Sheet 概要
A1: システム名 | K1: システム種別 | W1: =IF(表紙!W1="","",表紙!W1) -> 基本設計書 | AP1: 作成者 | AT1: 作成日 | AY1: 更新者 | BC1: 更新日 | BH1: 版数
A2: =IF(表紙!A2="","",表紙!A2) -> 現金専用簡易セルフPOS | K2: =IF(表紙!K2="","",表紙!K2) -> API | AP2: =IF(表紙!AP2="","",表紙!AP2) -> きよはら | AT2: =IF(表紙!AT2="","",表紙!AT2) -> 44867 | AY2: =IF(表紙!AY2="","",表紙!AY2) -> きよはら | BC2: =IF(表紙!BC2="","",表紙!BC2) -> 44867 | BH2: =IF(表紙!BH2="","",表紙!BH2) -> 0.1
A4: 機能カテゴリ | H4: =IF(表紙!H4="","",表紙!H4) -> 共通 | U4: 項目 | Z4: =IF(表紙!Z4="","",表紙!Z4) -> API(設定)定義書 | AP4: Sheet7
B7: 〇目的
C9: ・当初設計では、端末ごとの各種設定については、アプリ内で保有する予定でした。しかしながら、今後の機能追加や、設定変更等の際の煩雑さを考えると、APIにてご提供いただくのがベストとなりました。
D11: ・問題点
E12: 各店舗内で利用されている、POS機器の設定を変更する際に、全会社、全端末のアプリを更新する必要がある。
E13: →すべてのサービス、すべての機能の開発が終わり、安定機に入れば、修正頻度はそんなに高くないと思われるが、ここ数年の過渡期においては、毎日アップデートが必要になる可能性がある。
E14: →アップデートの頻度が上がると、店員様、スタッフ様のお手を煩わせることになるばかりか、アップデート失敗等のトラブルも増加。
E15: →アップデートには、約3分から5分程度かかる見込みです。（ネットワークの速さに依存します）
D17: ・改善
E18: 起動時に端末ごとの設定をAPIにて読み込むようにする。
B20: 〇概要
B32: 〇対象
B34: ID | D34: 区分 | M34: 論理テーブル名 | AB34: 物理テーブル名 | AW34: 備考
D35: 端末設定DB | M35: POS機器設定 | AB35: PosDeviceSetting
D36: 釣銭機設定DB | M36: 釣銭機設定 | AB36: ChangeMachineSetting

Sheet POS機器設定
A1: システム名 | K1: システム種別 | W1: =IF(表紙!W1="","",表紙!W1) -> 基本設計書 | AP1: 作成者 | AT1: 作成日 | AY1: 更新者 | BC1: 更新日 | BH1: 版数
A2: =IF(表紙!A2="","",表紙!A2) -> 現金専用簡易セルフPOS | K2: =IF(表紙!K2="","",表紙!K2) -> API | AP2: =IF(表紙!AP2="","",表紙!AP2) -> きよはら | AT2: =IF(表紙!AT2="","",表紙!AT2) -> 44867 | AY2: =IF(表紙!AY2="","",表紙!AY2) -> きよはら | BC2: =IF(表紙!BC2="","",表紙!BC2) -> 44867 | BH2: =IF(表紙!BH2="","",表紙!BH2) -> 0.1
A4: 機能カテゴリ | H4: =IF(表紙!H4="","",表紙!H4) -> 共通 | U4: 項目 | Z4: =IF(表紙!Z4="","",表紙!Z4) -> API(設定)定義書 | AP4: テンプレート
B7: ■テーブル情報
B8: スキーマ名 | Y8: RDBMS名
B9: 論理名 | G9: POS機器設定 | Y9: バージョン
B10: 物理名 | G10: PosDeviceSetting
B11: 備考
B12: 各接続機器ごとに提供されるサービスを設定
B13: ・サービス種別・・・「いらっしゃいませ」の待機画面で表示される「ボタン(提供サービス)」を定義する。
B14: ・ポイント種別・・・支払画面の前に表示される利用ポイントの種別を定義する。
B15: ・支払種別・・・支払画面に表示される支払方法を定義する。
B18: ■カラム情報
B19: No. | D19: 論理名 | R19: 物理名 | AC19: データ型 | AH19: PK | AJ19: Not Null | AM19: デフォルト | AT19: 備考
B20: 1 | D20: レコードID | R20: RECORD_ID | AC20: BIGINT | AJ20: Yes | AM20: 自動追加
B21: =B20+1 -> 2 | D21: レコード作成日付 | R21: RECORD_CREATE_DATE | AC21: TIMESTAMP | AJ21: Yes | AM21: CURRENT_DATE
B22: =B21+1 -> 3 | D22: レコード作成時間 | R22: RECORD_CREATE_TIME | AC22: BIGINT | AJ22: Yes | AM22: CURRENT_TIME
B23: =B22+1 -> 4 | D23: レコード更新日付 | R23: RECORD_UPDATE_DATE | AC23: TIMESTAMP | AJ23: Yes | AM23: CURRENT_DATE | AT23: トリガーにより更新
B24: =B23+1 -> 5 | D24: レコード更新時間 | R24: RECORD_UPDATE_TIME | AC24: BIGINT | AJ24: Yes | AM24: CURRENT_TIME | AT24: トリガーにより更新
B25: =B24+1 -> 6 | D25: レコード無効フラグ | R25: RECORD_VOID_FLAG | AC25: BOOL | AJ25: Yes | AM25: "" | AT25: true:有効 / false:無効
B26: =B25+1 -> 7 | D26: 企業コード | R26: company_code | AC26: TEXT | AH26: Yes
B27: =B26+1 -> 8 | D27: 店舗コード | R27: store_code | AC27: TEXT | AH27: Yes
B28: =B27+1 -> 9 | D28: レジ番号 | R28: instore_code | AC28: TEXT | AH28: Yes
B29: =B28+1 -> 10 | D29: 区分 | R29: class | AC29: INTEGER | AT29: 本番機："1"、検証機："9" ：この区分でAPIの参照先を変更
B30: =B29+1 -> 11 | D30: サービス種別1(Scan&Go) | R30: ServiceClass01 | AC30: INTEGER | AJ30: Yes | AM30: "1" | AT30: 利用：可能："1"、不可："9"（デフォルトで利用可能とする）
B31: =B30+1 -> 12 | D31: サービス種別2(手動登録) | R31: ServiceClass02 | AC31: INTEGER | AJ31: Yes | AM31: "9" | AT31: 利用：可能："1"、不可："9"
B32: =B31+1 -> 13 | D32: サービス種別3(Ignicaチャージ) | R32: ServiceClass03 | AC32: INTEGER | AJ32: Yes | AM32: "9" | AT32: 利用：可能："1"、不可："9"
B33: =B32+1 -> 14 | D33: サービス種別4(Ignica残高照会) | R33: ServiceClass04 | AC33: INTEGER | AJ33: Yes | AM33: "9" | AT33: 利用：可能："1"、不可："9"
B34: =B33+1 -> 15 | D34: サービス種別5(WAONチャージ) | R34: ServiceClass05 | AC34: INTEGER | AJ34: Yes | AM34: "9" | AT34: 利用：可能："1"、不可："9"
B35: =B34+1 -> 16 | D35: サービス種別6(WAON残高照会) | R35: ServiceClass06 | AC35: INTEGER | AJ35: Yes | AM35: "9" | AT35: 利用：可能："1"、不可："9"
B36: =B35+1 -> 17 | D36: サービス種別7(予備) | R36: ServiceClass07 | AC36: INTEGER | AJ36: Yes | AM36: "9" | AT36: 利用：可能："1"、不可："9"
B37: =B36+1 -> 18 | D37: サービス種別8(予備) | R37: ServiceClass08 | AC37: INTEGER | AJ37: Yes | AM37: "9" | AT37: 利用：可能："1"、不可："9"
B38: =B37+1 -> 19 | D38: サービス種別9(予備) | R38: ServiceClass09 | AC38: INTEGER | AJ38: Yes | AM38: "9" | AT38: 利用：可能："1"、不可："9"
B39: =B38+1 -> 20 | D39: サービス種別10(予備) | R39: ServiceClass10 | AC39: INTEGER | AJ39: Yes | AM39: "9" | AT39: 利用：可能："1"、不可："9"
B40: =B39+1 -> 21 | D40: ポイント種別1(Ignica) | R40: PointClass01 | AC40: INTEGER | AJ40: Yes | AM40: "9" | AT40: 利用：可能："1"、不可："9"
B41: =B40+1 -> 22 | D41: ポイント種別2(WAONポイント) | R41: PointClass02 | AC41: INTEGER | AJ41: Yes | AM41: "9" | AT41: 利用：可能："1"、不可："9"
B42: =B41+1 -> 23 | D42: ポイント種別3(イオンカード) | R42: PointClass03 | AC42: INTEGER | AJ42: Yes | AM42: "9" | AT42: 利用：可能："1"、不可："9"
B43: =B42+1 -> 24 | D43: ポイント種別4(WAONカード支払) | R43: PointClass04 | X43: ="{ ""company_code"": """&T43&""",""store_code"": """&U43&""",""instore_code"": """&V43&""",""status"": "&LEFT(W43,1)&"}" -> { "company_code": "","store_code": "","instore_code": "","status": } | AC43: INTEGER | AJ43: Yes | AM43: "9" | AT43: 利用：可能："1"、不可："9"
B44: =B43+1 -> 25 | D44: ポイント種別5(予備) | R44: PointClass05 | AC44: INTEGER | AJ44: Yes | AM44: "9" | AT44: 利用：可能："1"、不可："9"
B45: =B44+1 -> 26 | D45: ポイント種別6(予備) | R45: PointClass06 | AC45: INTEGER | AJ45: Yes | AM45: "9" | AT45: 利用：可能："1"、不可："9"
...

Sheet 釣銭機設定
A1: システム名 | K1: システム種別 | W1: =IF(表紙!W1="","",表紙!W1) -> 基本設計書 | AP1: 作成者 | AT1: 作成日 | AY1: 更新者 | BC1: 更新日 | BH1: 版数
A2: =IF(表紙!A2="","",表紙!A2) -> 現金専用簡易セルフPOS | K2: =IF(表紙!K2="","",表紙!K2) -> API | AP2: =IF(表紙!AP2="","",表紙!AP2) -> きよはら | AT2: =IF(表紙!AT2="","",表紙!AT2) -> 44867 | AY2: =IF(表紙!AY2="","",表紙!AY2) -> きよはら | BC2: =IF(表紙!BC2="","",表紙!BC2) -> 44867 | BH2: =IF(表紙!BH2="","",表紙!BH2) -> 0.1
A4: 機能カテゴリ | H4: =IF(表紙!H4="","",表紙!H4) -> 共通 | U4: 項目 | Z4: =IF(表紙!Z4="","",表紙!Z4) -> API(設定)定義書 | AP4: テンプレート
B7: ■テーブル情報
B8: スキーマ名 | Y8: RDBMS名
B9: 論理名 | G9: 釣銭機設定 | Y9: バージョン
B10: 物理名 | G10: ChangeMachineSetting
B11: 備考
B12: ・釣銭機に設定される各種金種ごとの設定枚数を定義する。
B19: ■カラム情報
B20: No. | D20: 論理名 | R20: 物理名 | AC20: データ型 | AH20: PK | AJ20: Not Null | AM20: デフォルト | AT20: 備考
B21: 1 | D21: レコードID | R21: RECORD_ID | AC21: BIGINT | AJ21: Yes | AM21: 自動追加
B22: 2 | D22: レコード作成日付 | R22: RECORD_CREATE_DATE | AC22: TIMESTAMP | AJ22: Yes | AM22: CURRENT_DATE
B23: 3 | D23: レコード作成時間 | R23: RECORD_CREATE_TIME | AC23: BIGINT | AJ23: Yes | AM23: CURRENT_TIME
B24: 4 | D24: レコード更新日付 | R24: RECORD_UPDATE_DATE | AC24: TIMESTAMP | AJ24: Yes | AM24: CURRENT_DATE | AT24: トリガーにより更新
B25: 5 | D25: レコード更新時間 | R25: RECORD_UPDATE_TIME | AC25: BIGINT | AJ25: Yes | AM25: CURRENT_TIME | AT25: トリガーにより更新
B26: 6 | D26: レコード無効フラグ | R26: RECORD_VOID_FLAG | AC26: BOOL | AJ26: Yes | AM26: "" | AT26: true:有効 / false:無効
B27: =B26+1 -> 7 | D27: 企業コード | R27: company_code | AC27: TEXT | AH27: Yes | AJ27: Yes
B28: =B27+1 -> 8 | D28: 店舗コード | R28: store_code | AC28: TEXT | AH28: Yes | AJ28: Yes
B29: =B28+1 -> 9 | D29: レジ番号 | R29: instore_code | AC29: TEXT | AH29: Yes | AJ29: Yes
B30: 10 | D30: 区分 | R30: class | AC30: INT | AH30: Yes | AJ30: Yes | AT30: 1:フル 2:ニアフル 3:ニアエンプティ 4:エンプティ 5:残置 6:釣銭準備金
B31: 11 | D31: 10000円札 | R31: 10000yen | AC31: INT | AJ31: Yes | AM31: ”0”
B32: 12 | D32: 5000円札 | R32: 5000yen | AC32: INT | AJ32: Yes | AM32: ”0”
B33: 13 | D33: 2000円札 | R33: 2000yen | AC33: INT | AJ33: Yes | AM33: ”0”
B34: 14 | D34: 1000円札 | R34: 1000yen | AC34: INT | AJ34: Yes | AM34: ”0”
B35: 15 | D35: 500円玉 | R35: 500yen | AC35: INT | AJ35: Yes | AM35: ”0”
B36: 16 | D36: 100円玉 | R36: 100yen | AC36: INT | AJ36: Yes | AM36: ”0”
B37: 17 | D37: 50円玉 | R37: 50yen | AC37: INT | AJ37: Yes | AM37: ”0”
B38: 18 | D38: 10円玉 | R38: 10yen | AC38: INT | AJ38: Yes | AM38: ”0”
B39: 19 | D39: 5円玉 | R39: 5yen | AC39: INT | AJ39: Yes | AM39: ”0”
B40: 20 | D40: 1円玉 | R40: 1yen | AC40: INT | AJ40: Yes | AM40: ”0”
B41: 21 | D41: カセット | R41: cassette | AC41: INT | AJ41: Yes | AM41: ”0”
B43: ■インデックス情報
B44: No. | D44: Index名 | R44: カラム一覧 | AL44: プライマリキー | AP44: ユニーク | AT44: 備考
B45: 1 | D45: PRIMARY | R45: company_code,store_code,instore_code,class | AL45: Yes | AP45: Yes
B47: トリガー情報
B48: No. | D48: トリガー名 | R48: イベント | U48: タイミング | Y48: 条件
B49: 1 | D49: =G10&"_"&R49&"_"&"trg" -> ChangeMachineSetting_update_trg | R49: update | U49: Before row | Y49: auto_updated_date
B51: ※使用API
B52: No. | F52: API | AA52: METHOD | AF52: 認証 | AL52: ←参照(Select)、更新(Update）、追加（Insert）で、URLを分けていただきたい。
...

Sheet テンプレート
A1: システム名 | K1: システム種別 | W1: =IF(表紙!W1="","",表紙!W1) -> 基本設計書 | AP1: 作成者 | AT1: 作成日 | AY1: 更新者 | BC1: 更新日 | BH1: 版数
A2: =IF(表紙!A2="","",表紙!A2) -> 現金専用簡易セルフPOS | K2: =IF(表紙!K2="","",表紙!K2) -> API | AP2: =IF(表紙!AP2="","",表紙!AP2) -> きよはら | AT2: =IF(表紙!AT2="","",表紙!AT2) -> 44867 | AY2: =IF(表紙!AY2="","",表紙!AY2) -> きよはら | BC2: =IF(表紙!BC2="","",表紙!BC2) -> 44867 | BH2: =IF(表紙!BH2="","",表紙!BH2) -> 0.1
A4: 機能カテゴリ | H4: =IF(表紙!H4="","",表紙!H4) -> 共通 | U4: 項目 | Z4: =IF(表紙!Z4="","",表紙!Z4) -> API(設定)定義書 | AP4: テンプレート
B7: ■テーブル情報
B8: スキーマ名 | Y8: RDBMS名
B9: 論理名 | G9: 機器接続情報 | Y9: バージョン
B10: 物理名
B11: 備考
B19: ■カラム情報
B20: No. | D20: 論理名 | R20: 物理名 | AC20: データ型 | AH20: PK | AJ20: Not Null | AM20: デフォルト | AT20: 備考
B21: 1 | D21: レコードID | R21: RECORD_ID | AC21: BIGINT | AH21: Yes | AJ21: Yes | AM21: 自動追加
B22: 2 | D22: レコード作成日付 | R22: RECORD_CREATE_DATE | AC22: TIMESTAMP | AJ22: Yes | AM22: CURRENT_DATE
B23: 3 | D23: レコード作成時間 | R23: RECORD_CREATE_TIME | AC23: BIGINT | AJ23: Yes | AM23: CURRENT_TIME
B24: 4 | D24: レコード更新日付 | R24: RECORD_UPDATE_DATE | AC24: TIMESTAMP | AJ24: Yes | AM24: CURRENT_DATE | AT24: トリガーにより更新
B25: 5 | D25: レコード更新時間 | R25: RECORD_UPDATE_TIME | AC25: BIGINT | AJ25: Yes | AM25: CURRENT_TIME | AT25: トリガーにより更新
B26: 6 | D26: レコード無効フラグ | R26: RECORD_VOID_FLAG | AC26: BOOL | AJ26: Yes | AM26: "" | AT26: true:有効 / false:無効
B27: 7
B28: 8
B29: 9
B30: 10
B31: 11
B32: 12
B33: 13
B36: ■インデックス情報
B37: No. | D37: Index名 | R37: カラム一覧 | AL37: プライマリキー | AP37: ユニーク | AT37: 備考
B38: 1 | D38: PRIMARY | AL38: Yes | AP38: Yes
B41: トリガー情報
B42: No. | D42: トリガー名 | R42: イベント | U42: タイミング | Y42: 条件
B43: 1 | D43: =G10&"_"&R43&"_"&"trg" -> _update_trg | R43: update | U43: Before row | Y43: auto_updated_date
