Workbook

Sheet 表紙
B3: U.S.M.Holdings様／いなげや様
H24: =改版履歴!AO3 -> 1.6
G27: =改版履歴!AT3 -> 45672
F31: 富士通株式会社
D36: U.S.M.Holdings様／いなげや様 | J36: 富士通
D37: 承認 | F37: 承認 | H37: 承認 | J37: 承認 | L37: 確認 | N37: リーダー

Sheet 改版履歴
B2: TeamStore/M POSシステム | O2: システム名 | U2: 業務名 | AB2: 改版履歴 | AO2: 履歴 | AQ2: 改訂者 | AT2: 最新更新日 | AX2: 作成者 | BA2: 作成日
B3: UI設計書 | O3: マスタ連携対応 | U3: 方式設計 | AO3: =MAX(G10:H88) -> 1.6 | AQ3: 富士通 | AT3: =MAX(C10:F88) -> 45672 | AX3: 富士通 | BA3: 45427
C6: 改版履歴
C8: 日付 | G8: 版数 | I8: 章番号 | O8: 修正内容 | AZ8: 担当
C10: 45427 | G10: 0.1 | O10: 新規作成
C12: 45432 | G12: 0.2 | O12: ＜2024/5/15 打合せ内容の反映＞
I13: 2.連携ファイル仕様 全件 | O13: ・ENDファイルの作成仕様を変更(zipファイルサイズに加えて各ファイルの件数を追加) | AZ13: FJ)小林(令)
O14: ・SFTP通信仕様を開発環境と本番環境とに分けて記載
I15: 3.連携ファイル仕様 差分 | O15: ・ENDファイルの作成仕様を変更(zipファイルサイズに加えて各ファイルの件数を追加) | AZ15: FJ)小林(亮)
I16: 5.個別定義情報 | O16: ・5-3.プリセット設定を追加。5-3.システム設定を5-4.システム設定に変更。 | AZ16: FJ)小林(令)
O17: ・5-2.付加情報、5-4.システム設定の連携タイミングにイニシャルとランニングの列を追加
O18: ・5-4.システム設定の設定情報、レジグループ、OPT_IDは富士通POSの内部設定であることを追記
C20: 45434 | G20: 0.3 | O20: ＜2024/5/20 打合せ内容の反映＞ | AZ20: FJ)小林(令)
I21: 2.連携ファイル仕様 全件 | O21: ・zipファイル、ENDファイルのファイル名先頭に店舗コードを追加
I22: 3.連携ファイル仕様 差分 | O22: ・zipファイル、ENDファイルのファイル名先頭に店舗コードを追加
I23: 5.個別定義情報 | O23: ・音声ファイルの記載を変更（「年齢確認商品です」はignica側の音声を採用、「年齢確認できるものをご提示ください」を追加）
O24: ＜内部指摘を反映＞
I25: 3.連携ファイル仕様 差分 | O25: ・3-7.新店展開手順への反映 を削除（新店対応手順反映は不要であることが判明したため）
C27: 45439 | G27: 0.4 | O27: ＜2024/5/22 打合せ内容の反映＞ | AZ27: FJ)小林(令)
I28: 2.連携ファイル仕様 全件 | O28: ・zipファイル、ENDファイルのファイル名に"_"を追加（店舗コード追加時の修正漏れ）
O29: ・拡張子をCSVに統一する（MST→CSV：さんにち割データ、dat→CSV：入出金マスタ、現外設定マスタ、商品券バーコードマスタ）
I30: 3.連携ファイル仕様 差分 | O30: ・zipファイル、ENDファイルのファイル名に"_"を追加（店舗コード追加時の修正漏れ）
I31: 5.個別定義情報 | O31: ・5-2.付加情報の音声ファイルの情報「年齢確認商品です」は不採用のため、Ignica側の音声「年齢確認が必要です」を追記
O32: 備考欄に富士通POSは、「年齢確認商品です」のままであることを追記
O33: ＜内部指摘を反映＞
I34: 4.開閉店処理組込 | O34: ・5-4.バックアップ処理概要のzipファイル、ENDファイルのファイル名に"_"を追加（店舗コード追加時の修正漏れ）
I35: 5.個別定義情報 | O35: ・5-4.システム設定の年齢確認の記載を修正（「許可」を押下した際の電子ジャーナルは、「26歳以上」の表示をする。システム設定は未使用。
O36: 変更発生時はシステム改修対応となる旨を追記）
O37: ＜QA回答の反映＞
O38: ・2-2.SFTP通信仕様 開発環境の情報を追記（QANo.114回答反映）
C39: 45441 | G39: 0.5 | O39: ＜2024/5/27 打合せ内容の反映＞ | AZ39: FJ)小林(令)
I40: 2.連携ファイル仕様 全件 | O40: ・2-2.SFTP通信仕様 本番環境の情報は別途連携頂く旨を追記
O41: ＜内部指摘を反映＞
O42: ・2-7-1.異常の検知の記載を修正
O43: ・5-3.プリセット設定にカタリナクーポン支払い時に使用する現外種別コードの設定を追加
C45: 45462 | G45: 1 | I45: 初版 | AZ45: FJ）森谷
C47: 45511 | G47: 1.1 | I47: 2.連携ファイル仕様 全件 | O47: ＜QA回答の反映＞ | AZ47: FJ）小澤
O48: ・2-2.SFTP通信仕様 開発環境の情報を更新
P49: ホスト名を「ec2-35-77-173-176.ap-northeast-1.compute.amazonaws.com」に修正
P50: 接続ディレクトリを「/mnt/inageya/receive/Input/XXX」に修正
...

Sheet 要件概要
C2: TeamStore/M POSシステム | P2: システム名 | V2: 業務名 | AC2: 要件概要 | AP2: 履歴 | AR2: 改訂者 | AU2: 最新更新日 | AY2: 作成者 | BB2: 作成日
C3: UI設計書 | P3: マスタ連携対応 | V3: 方式設計 | AP3: =改版履歴!$AO$3 -> 1.6 | AR3: 富士通 | AU3: =改版履歴!$AT$3 -> 45672 | AY3: 富士通 | BB3: =改版履歴!$BA$3 -> 45427
E7: 運 用 目 的 | J7: ： | K7: 同一店内でいなげや様POSと同じ価格、値引きでignicaPOSが動作するようマスタデータを連携する。
E11: 要求仕様概要 | J11: ： | K11: TS/M側POSサーバにてマスタI/Fの新規ファイルレイアウトを作成し、POSサーバからignica変換サーバへSFTP連携する。
K12: ファイルの連携は、ignica変換サーバに店舗毎にフォルダを作成することとし、TS/Mサーバから該当店舗フォルダのマスタを送信する方式とする。
K13: 連携方式は、全件一括連携(営業開始前1日1回の全件)と差分連携(営業中更新時の差分)の2種類とする。
K14: TS/M側POSサーバの開店処理にて、バックアップを行う。連携ファイルは当日分を除いて6世代まで、ログファイルは当日分を除いて10世代まで管理する。
K15: SFTP送信の正常完了確認を行う。（ENDファイルを合わせて送信する。送信先にENDファイルがあった場合、対応するデータファイルの送信が完了していると判断する）
K16: 店番、POS番号、TS/M側のPOSシステムのシステム設定など、TSM側のPOSとignicaPOSで合わせる必要がある連携対象以外のマスタ情報、定義情報は、各システム個別に定義する。
K17: （例. 取引中止時の理由コードなど）
K20: ＜全店一括連携＞ | P20: 全13ファイル
K21: 営業開始前、全データ、全件を対象にignica変換サーバへ連携する。全件を連携し、営業開始前にPOSサーバとignica側サーバとのデータ同期を図る。
M22: ・ | N22: 商品階層マスタ | W22: ・ | X22: 営業日マスタ
M23: ・ | N23: 商品マスタ | W23: ・ | X23: 担当者マスタ
M24: ・ | N24: 企画マスタ | W24: ・ | X24: 入出金マスタ
M25: ・ | N25: 特売マスタ | W25: ・ | X25: 現外設定マスタ
M26: ・ | N26: 組合せマスタ | W26: ・ | X26: 緊急登録マスタ
M27: ・ | N27: 商品階層自動値引きマスタ | W27: ・ | X27: 商品券バーコードマスタ
M28: ・ | N28: さんにち割データ
K30: ＜差分連携＞ | P30: 全7ファイル
K31: 営業中更新が発生し、リアル反映が必要と判断したデータは、更新が発生した差分を対象にignica変換サーバへ連携する。
K32: また、開局処理内(営業開始前)で、全件一括作成後に値引スケジュール-抽出／反映処理で更新が発生した場合は、差分を対象にignica変換サーバへ連携する。 | BF32: *1.5
K33: ※全件一括連携のファイルレイアウトと同一とする。
M34: ・ | N34: 商品マスタ | W34: ・ | X34: 担当者マスタ
M35: ・ | N35: 企画マスタ | W35: ・ | X35: 緊急登録マスタ
M36: ・ | N36: 特売マスタ
M37: ・ | N37: 組合せマスタ
M38: ・ | N38: 商品階層自動値引きマスタ

Sheet 1.システム概略図
C2: TeamStore/M POSシステム | P2: システム名 | V2: 業務名 | AC2: １．システム概略図 | BD2: 履歴 | BF2: 改訂者 | BI2: 最新更新日 | BM2: 作成者 | BP2: 作成日
C3: UI設計書 | P3: マスタ連携対応 | V3: 方式設計 | BD3: =改版履歴!$AO$3 -> 1.6 | BF3: 富士通 | BI3: =改版履歴!$AT$3 -> 45672 | BM3: 富士通 | BP3: =改版履歴!$BA$3 -> 45427
D6: １．システム概略図

Sheet 2.連携ファイル仕様 全件
C2: TeamStore/M POSシステム | P2: システム名 | V2: 業務名 | AC2: ２．連携ファイル仕様（全件一括） | BD2: 履歴 | BF2: 改訂者 | BI2: 最新更新日 | BM2: 作成者 | BP2: 作成日
C3: UI設計書 | P3: マスタ連携対応 | V3: 方式設計 | BD3: =改版履歴!$AO$3 -> 1.6 | BF3: 富士通 | BI3: =改版履歴!$AT$3 -> 45672 | BM3: 富士通 | BP3: =改版履歴!$BA$3 -> 45427
D6: ２．連携ファイル仕様（全件一括データファイル連携）
E8: 全件一括データファイルの連携仕様について、以下に記す。
E10: 2-1. 処理イメージ
F12: ※POSサーバの開店処理に組み込む SFTP連携実現には別途FNETSにてネットワーク環境構築作業が必要
A28: *0.2
A29: *0.2
E35: 2-2. SFTP通信仕様
A37: *0.2 | F37: ■開発環境 【WinSCP設定値】 | AM37: ■開発環境 【接続先情報 ignica変換サーバ側情報】
F38: No. | H38: 項目名 | N38: 設定値 | Y38: 備考 | AM38: No. | AO38: 項目名 | AU38: 情報 | BF38: 備考
A39: *0.4*1.1*1.5 | F39: 1 | H39: ホスト名 | N39: 192.168.180.1 | AM39: 1 | AO39: 接続ディレクトリ | AU39: /mnt/inageya/receive/Input/XXX | BF39: 送信ファイル格納フォルダ（XXX：店舗番号）
F40: 2 | H40: ポート番号 | N40: 22 | Y40: 共通
A41: *0.4 | F41: 3 | H41: ユーザ名 | N41: ec2-user
F42: 4 | H42: パスワード | N42: （なし）
A43: *0.4 | F43: 5 | H43: 秘密鍵 | N43: common_dev_tokyo_kp_1a.ppk | Y43: 登録した公開鍵に対応する秘密鍵
F44: 6 | H44: 公開鍵のフィンガープリント | N44: (※2) | Y44: ssh_host_ed25519_key.pub
F45: 7 | H45: プロトコル | N45: SFTP
A47: *0.2*0.5 | F47: ■本番環境 【WinSCP設定値】 | O47: ※本番環境の情報は別途連携頂く | AM47: ■本番環境 【接続先情報 ignica変換サーバ側情報】
A48: *0.2 | F48: No. | H48: 項目名 | N48: 設定値 | Y48: 備考 | AM48: No. | AO48: 項目名 | AU48: 情報 | BF48: 備考
A49: *0.2*1.5 | F49: 1 | H49: ホスト名 | N49: 192.168.180.7 | AM49: 1 | AO49: 接続ディレクトリ | AU49: /mnt/inageya/receive/Input/XXX | BF49: 送信ファイル格納フォルダ
A50: *0.2 | F50: 2 | H50: ポート番号 | N50: 22 | Y50: 共通
A51: *0.2*1.5 | F51: 3 | H51: ユーザ名 | N51: ec2-user
A52: *0.2 | F52: 4 | H52: パスワード | N52: （なし）
A53: *0.2 | F53: 5 | H53: 秘密鍵 | N53: sftp_prd_tokyo_kp_1a.ppk | Y53: 登録した公開鍵に対応する秘密鍵
A54: *1.5 | F54: 6 | H54: 公開鍵のフィンガープリント | N54: (※3) | Y54: ssh_host_ed25519_key.pub
A55: *0.2 | F55: 7 | H55: プロトコル | N55: SFTP
F57: (※1)SFTP通信情報は、iniファイルに設定する。(iniファイルの修正により変更できるようにする。)
A58: *1.5 | F58: (※2)フィンガープリントの設定値
A59: *1.5 | G59: JhFWMzBfW2AzTN67u167jR+/70DdxQbwr6bzhHQ9chk
A60: *1.5 | F60: (※3)フィンガープリントの設定値
A61: *1.5 | G61: ZpjwM+4mT6Yff2hRvH9T1crX8Sh4YhQtpuMDVbgdUl0
C68: TeamStore/M POSシステム | P68: システム名 | V68: 業務名 | AC68: =$AC$2 -> ２．連携ファイル仕様（全件一括） | BD68: 履歴 | BF68: 改訂者 | BI68: 最新更新日 | BM68: 作成者 | BP68: 作成日
C69: UI設計書 | P69: マスタ連携対応 | V69: 方式設計 | BD69: =$BD$3 -> 1.6 | BF69: =$BF$3 -> 富士通 | BI69: =$BI$3 -> 45672 | BM69: =$BM$3 -> 富士通 | BP69: =$BP$3 -> 45427
E73: 2-3. 送信ファイル一覧
F75: No. | H75: 名称 | P75: ファイルID | AG75: 連携方法 | AJ75: 制御 | AM75: 追記/上書 | AP75: リトライ | AS75: 説明
A76: *0.3*0.4 | F76: 1 | H76: 全件一括データファイル | P76: [店舗コード 3桁]＋"_IG_ALLMST_" | AG76: SFTP | AJ76: 自局 | AM76: 上書き | AP76: 3 | AS76: POSサーバの開局時に、マスタデータを一括出力する。
P77: +[作成日時 yyyymmddhhmmss]+".zip"
A78: *0.3 | P78: 【例】 001_IG_ALLMST_20240710053122.zip
A79: *0.3 | P79: (店舗番号：1）
...

Sheet 3.連携ファイル仕様 差分
BU1: 1
C2: TeamStore/M POSシステム | P2: システム名 | V2: 業務名 | AC2: ３．連携ファイル仕様（差分） | BD2: 履歴 | BF2: 改訂者 | BI2: 最新更新日 | BM2: 作成者 | BP2: 作成日 | BU2: =OFFSET(BU2,-1,0,1,1)+1 -> 2
C3: UI設計書 | P3: マスタ連携対応 | V3: 方式設計 | BD3: =改版履歴!$AO$3 -> 1.6 | BF3: 富士通 | BI3: =改版履歴!$AT$3 -> 45672 | BM3: 富士通 | BP3: =改版履歴!$BA$3 -> 45427 | BU3: =OFFSET(BU3,-1,0,1,1)+1 -> 3
BU4: =OFFSET(BU4,-1,0,1,1)+1 -> 4
BU5: =OFFSET(BU5,-1,0,1,1)+1 -> 5
D6: ３．連携ファイル仕様（差分データファイル連携） | BU6: =OFFSET(BU6,-1,0,1,1)+1 -> 6
BU7: =OFFSET(BU7,-1,0,1,1)+1 -> 7
E8: 差分データファイルの連携仕様について、以下に記す。 | BU8: =OFFSET(BU8,-1,0,1,1)+1 -> 8
BU9: =OFFSET(BU9,-1,0,1,1)+1 -> 9
E10: 3-1. 処理イメージ | BU10: =OFFSET(BU10,-1,0,1,1)+1 -> 10
BU11: =OFFSET(BU11,-1,0,1,1)+1 -> 11
F12: ※既存のマスタ更新機能の処理時間の増加を最小限にするため、常駐プログラムでの監視による非同期処理で差分データファイルの作成/送信を行う方式とする。また、SFTP連携実現には別途FNETSにてネットワーク環境構築作業が必要。 | BU12: =OFFSET(BU12,-1,0,1,1)+1 -> 12
BU13: =OFFSET(BU13,-1,0,1,1)+1 -> 13
BU14: =OFFSET(BU14,-1,0,1,1)+1 -> 14
BU15: =OFFSET(BU15,-1,0,1,1)+1 -> 15
BU16: =OFFSET(BU16,-1,0,1,1)+1 -> 16
BU17: =OFFSET(BU17,-1,0,1,1)+1 -> 17
BU18: =OFFSET(BU18,-1,0,1,1)+1 -> 18
BU19: =OFFSET(BU19,-1,0,1,1)+1 -> 19
BU20: =OFFSET(BU20,-1,0,1,1)+1 -> 20
BU21: =OFFSET(BU21,-1,0,1,1)+1 -> 21
BU22: =OFFSET(BU22,-1,0,1,1)+1 -> 22
BU23: =OFFSET(BU23,-1,0,1,1)+1 -> 23
BU24: =OFFSET(BU24,-1,0,1,1)+1 -> 24
... BU79: =OFFSET(BU79,-1,0,1,1)+1 -> 79
BU80: 1
C81: TeamStore/M POSシステム | P81: システム名 | V81: 業務名 | AC81: =$AC$2 -> ３．連携ファイル仕様（差分） | BD81: 履歴 | BF81: 改訂者 | BI81: 最新更新日 | BM81: 作成者 | BP81: 作成日 | BU81: =OFFSET(BU81,-1,0,1,1)+1 -> 2
C82: UI設計書 | P82: マスタ連携対応 | V82: 方式設計 | BD82: =$BD$3 -> 1.6 | BF82: =$BF$3 -> 富士通 | BI82: =$BI$3 -> 45672 | BM82: =$BM$3 -> 富士通 | BP82: =$BP$3 -> 45427 | BU82: =OFFSET(BU82,-1,0,1,1)+1 -> 3
BU83: =OFFSET(BU83,-1,0,1,1)+1 -> 4
BU84: =OFFSET(BU84,-1,0,1,1)+1 -> 5
BU85: =OFFSET(BU85,-1,0,1,1)+1 -> 6
E86: 3-2. SFTP通信仕様 | BU86: =OFFSET(BU86,-1,0,1,1)+1 -> 7
BU87: =OFFSET(BU87,-1,0,1,1)+1 -> 8
F88: 【WinSCP設定値】 | AM88: 【接続先情報 ignica変換サーバ側情報】 | BU88: =OFFSET(BU88,-1,0,1,1)+1 -> 9
F89: No. | H89: 項目名 | N89: 設定値 | Y89: 備考 | AM89: No. | AO89: 項目名 | AU89: 情報 | BF89: 備考 | BU89: =OFFSET(BU89,-1,0,1,1)+1 -> 10
F90: 1 | H90: ホスト名 | AM90: 1 | AO90: 接続ディレクトリ | BF90: 送信ファイル格納フォルダ | BU90: =OFFSET(BU90,-1,0,1,1)+1 -> 11
F91: 2 | H91: ポート番号 | N91: 22 | Y91: 共通 | BU91: =OFFSET(BU91,-1,0,1,1)+1 -> 12
F92: 3 | H92: ユーザ名 | Y92: POSサーバ(店舗)毎のユーザ名 | BU92: =OFFSET(BU92,-1,0,1,1)+1 -> 13
F93: 4 | H93: パスワード | N93: （なし） | BU93: =OFFSET(BU93,-1,0,1,1)+1 -> 14
F94: 5 | H94: 秘密鍵 | N94: 登録した公開鍵に対応する秘密鍵 | BU94: =OFFSET(BU94,-1,0,1,1)+1 -> 15
...

Sheet 4.開閉店処理組込
BU1: 1
C2: TeamStore/M POSシステム | P2: システム名 | V2: 業務名 | AC2: ４．開閉店処理組み込み | BD2: 履歴 | BF2: 改訂者 | BI2: 最新更新日 | BM2: 作成者 | BP2: 作成日 | BU2: =OFFSET(BU2,-1,0,1,1)+1 -> 2
C3: UI設計書 | P3: マスタ連携対応 | V3: 方式設計 | BD3: =改版履歴!$AO$3 -> 1.6 | BF3: 富士通 | BI3: =改版履歴!$AT$3 -> 45672 | BM3: 富士通 | BP3: =改版履歴!$BA$3 -> 45427 | BU3: =OFFSET(BU3,-1,0,1,1)+1 -> 3
BU4: =OFFSET(BU4,-1,0,1,1)+1 -> 4
BU5: =OFFSET(BU5,-1,0,1,1)+1 -> 5
A6: *1.1 | D6: 4．開閉店処理組み込み | BU6: =OFFSET(BU6,-1,0,1,1)+1 -> 6
BU7: =OFFSET(BU7,-1,0,1,1)+1 -> 7
A8: *1.1 | E8: 4-1. 対応概要 | BU8: =OFFSET(BU8,-1,0,1,1)+1 -> 8
F9: ・ | G9: TS/M側POSサーバの開店処理に全件一括データファイルの作成処理、データ送信処理を組み込む。（連携時間は、朝5時から6時を想定） | BU9: =OFFSET(BU9,-1,0,1,1)+1 -> 9
F10: ・ | G10: TS/M側POSサーバの開店処理にて、バックアップを行う。連携ファイルおよび差分データのマスタ更新履歴は当日分を除いて6世代まで、ログファイルは当日分を除いて10世代まで管理する。 | BU10: =OFFSET(BU10,-1,0,1,1)+1 -> 10
F11: ・ | G11: TS/M側POSサーバの開店処理にて、差分データ連携用常駐プログラムの起動を行う。 | BU11: =OFFSET(BU11,-1,0,1,1)+1 -> 11
BU12: =OFFSET(BU12,-1,0,1,1)+1 -> 12
A13: *1.1 | E13: 4-2. 処理フロー（開店処理：処理抜粋） | BU13: =OFFSET(BU13,-1,0,1,1)+1 -> 13
BU14: =OFFSET(BU14,-1,0,1,1)+1 -> 14
F15: 連携データ・ログファイルのバックアップ処理と全件一括データ作成・送信の組み込み箇所は、以下とする。 | BU15: =OFFSET(BU15,-1,0,1,1)+1 -> 15
BU16: =OFFSET(BU16,-1,0,1,1)+1 -> 16
O17: ※主な処理を抜粋して記載 | BU17: =OFFSET(BU17,-1,0,1,1)+1 -> 17
BU18: =OFFSET(BU18,-1,0,1,1)+1 -> 18
Q19: *1 イニシャル／リスタートに関係なく必ず実行する | BU19: =OFFSET(BU19,-1,0,1,1)+1 -> 19
Q20: *2 イニシャルスタート時のみ実行する | BU20: =OFFSET(BU20,-1,0,1,1)+1 -> 20
BU21: =OFFSET(BU21,-1,0,1,1)+1 -> 21
BU22: =OFFSET(BU22,-1,0,1,1)+1 -> 22
BU23: =OFFSET(BU23,-1,0,1,1)+1 -> 23
BU24: =OFFSET(BU24,-1,0,1,1)+1 -> 24
BU25: =OFFSET(BU25,-1,0,1,1)+1 -> 25
BU26: =OFFSET(BU26,-1,0,1,1)+1 -> 26
BU27: =OFFSET(BU27,-1,0,1,1)+1 -> 27
BU28: =OFFSET(BU28,-1,0,1,1)+1 -> 28
BU29: =OFFSET(BU29,-1,0,1,1)+1 -> 29
BU30: =OFFSET(BU30,-1,0,1,1)+1 -> 30
A31: *1.4 | BU31: =OFFSET(BU31,-1,0,1,1)+1 -> 31
BU32: =OFFSET(BU32,-1,0,1,1)+1 -> 32
BU33: =OFFSET(BU33,-1,0,1,1)+1 -> 33
BU34: =OFFSET(BU34,-1,0,1,1)+1 -> 34
BU35: =OFFSET(BU35,-1,0,1,1)+1 -> 35
BU36: =OFFSET(BU36,-1,0,1,1)+1 -> 36
BU37: =OFFSET(BU37,-1,0,1,1)+1 -> 37
BU38: =OFFSET(BU38,-1,0,1,1)+1 -> 38
BU39: =OFFSET(BU39,-1,0,1,1)+1 -> 39
BU40: =OFFSET(BU40,-1,0,1,1)+1 -> 40
...

Sheet 5.個別定義情報
C2: TeamStore/M POSシステム | P2: システム名 | V2: 業務名 | AC2: ５．個別定義情報 | BD2: 履歴 | BF2: 改訂者 | BI2: 最新更新日 | BM2: 作成者 | BP2: 作成日
C3: UI設計書 | P3: マスタ連携対応 | V3: 方式設計 | BD3: =改版履歴!$AO$3 -> 1.6 | BF3: 富士通 | BI3: =改版履歴!$AT$3 -> 45672 | BM3: 富士通 | BP3: =改版履歴!$BA$3 -> 45427
D6: ５．個別定義情報
E8: マスタ連携対象以外のTS/M側のPOSとignicaPOSで合わせる必要があると想定される主なマスタ情報、定義情報を以下に記す。
E9: これらの情報は、必要に応じて、ignica側で個別に定義する。
E10: 価格コントロールについては、「価格マトリクス」を参照のこと。収益認識基準対応については、「収益認識基準対応プロジェクト UI1-B ユーザインタフェース仕様書(POS)」を参照のこと。
E11: TS/M側のシステム設定を変更しても、富士通POSとignicaPOSとの同期は行いません。同期対応が必要な場合は、USMH様、いなげや様にてignicaPOSでの対応調整をお願いいたします。（例. コマーシャルメッセージなど）
E12: 将来、TS/M側のバージョンアップ対応が発生し、ignicaPOS連携に影響があり、適用日程の調整が必要な場合は、USMH様、いなげや様にてignicaPOSでの対応調整をお願いいたします。（例. 取引ログのレイアウト変更など）
E15: 5-1. 基本情報
F17: No. | H17: 分類 | M17: 情報 | V17: 発信元 | AA17: 連携タイミング | AL17: 設定値 | AV17: 備考
F18: 1 | H18: 店舗情報 | M18: 店番 | V18: いなげや様 | AA18: 新店導入、既存店展開 | AL18: 店個別 | AP18: -
M19: 店名 | V19: いなげや様 | AA19: 新店導入、既存店展開 | AL19: 店個別 | AP19: -
F20: 2 | H20: POS情報 | M20: POS番号(ignicaPOS) | V20: いなげや様 | AA20: UI工程にて決定 | AL20: 全店共通 | AP20: xxx～xxx | AV20: 基本定義としてPOS番号の範囲を事前に決めておく。実際に導入するPOSは店舗ごとに決定する。
M21: POS番号(スマホ) | V21: いなげや様 | AA21: UI工程にて決定 | AL21: 全店共通 | AP21: xxx | AV21: Scan&Go(スマホ)のPOS番号は1つ。
M22: POS名称 | V22: いなげや様 | AA22: UI工程にて決定 | AL22: 全店共通 | AP22: - | AV22: ※詳細は、「コンピュータ名・IPアドレス規約」にて定義する。
E25: 5-2. 付加情報（画像、音声など）
F27: No. | H27: 分類 | M27: 情報 | V27: 連携タイミング | AP27: 設定値 | AZ27: 備考
A28: *0.2 | V28: イニシャル | AC28: ランニング *変更発生時
A29: *0.2 | F29: 1 | H29: レシート印字 | M29: レシートヘッダ印字(bmpファイル) | V29: 富士通よりVTI様へ連携 | AC29: データ作成:いなげや様 | AP29: 店個別 | AT29: - | AZ29: 業態変更に伴い入替が発生する場合がある
A30: *0.2 | M30: レシートフッダ印字(bmpファイル) | AC30: データ連携:いなげや様より各社へ | AP30: 店個別 | AT30: - | AZ30: キャンペーン実施の店舗、期間により入替が発生する
A31: *0.2 | AC31: 展開:いなげや様より各社に保守依頼発行
A32: *0.2 | F32: 2 | H32: 画像ファイル | M32: ヘルプ画像 | V32: 富士通よりVTI様へ連携 | AC32: データ作成:富士通 | AP32: 全店共通 | AT32: -
A33: *0.2 | AC33: データ連携: いなげや様了承のもと富士通よりVTI様へ
A34: *0.2 | AC34: 展開:いなげや様より各社に保守依頼発行
A35: *0.2 | M35: 電子多項目画像 | V35: 富士通よりVTI様へ連携 | AC35: データ作成:いなげや様 | AP35: 全店共通 | AT35: - | AZ35: 画像は全店共通、配置は店舗別POSグループ単位
A36: *0.2 | AC36: データ連携:なし
A37: *0.2 | AC37: 展開:いなげや様にて設定
A38: *0.2 | F38: 3 | H38: 音声ファイル | M38: ピヨピヨ | V38: 富士通よりVTI様へ連携 | AC38: データ作成:いなげや様 or 富士通 | AP38: 全店共通 | AT38: - | AZ38: いなげやing･fanカード/Vカード利用時の音声鳴動「ピヨピヨ」
A39: *0.2 | M39: ゴパー | AC39: データ連携:いなげや様より各社へ | AP39: 全店共通 | AT39: - | AZ39: いなげやing･fanカード/Vカード利用時の音声鳴動、さんにち割引時の「ゴパー」
A40: *0.2 | AC40: 展開:いなげや様より各社に保守依頼発行
A41: *0.2*0.3*0.4 | M41: 年齢確認商品です | V41: ignica側の音声を採用するため、イニシャル、ランニング運用なし | AP41: 全店共通 | AT41: - | AZ41: 年齢確認商品スキャン時の音声鳴動「年齢確認商品です」
A42: *0.4 | M42: →年齢確認が必要です | AZ42: ※富士通POSは上記「年齢確認商品です」のままとする
A43: *0.3 | M43: 年齢確認できるものをご提示ください | V43: 富士通よりVTI様へ連携 | AC43: データ作成:いなげや様 | AP43: 全店共通 | AT43: - | AZ43: 年齢確認商品スキャン時の音声鳴動 第2ガイダンス
A44: *0.3 | AC44: データ連携:いなげや様より各社へ | AZ44: 「年齢確認できるものをご提示ください」
A45: *0.3 | AC45: 展開:いなげや様より各社に保守依頼発行
A48: *0.2 | E48: 5-3. プリセット設定
A50: *0.2 | F50: No. | H50: 分類 | M50: 情報 | V50: 連携タイミング | AP50: 設定値 | AZ50: 備考
A51: *0.2 | V51: イニシャル | AC51: ランニング *変更発生時
A52: *0.2 | F52: 1 | H52: 現外券一覧 | M52: 現外券の額面表示 | V52: 富士通よりVTI様へ連携 | AC52: いなげや様より各社に保守依頼発行 | AP52: 全店共通 | AT52: - | AZ52: 現外ボタン押下時に表示する金額
A53: *0.2
...

Sheet 6.システム設定
C2: TeamStore/M POSシステム | P2: システム名 | V2: 業務名 | AC2: ６．システム設定 | BD2: 履歴 | BF2: 改訂者 | BI2: 最新更新日 | BM2: 作成者 | BP2: 作成日
C3: UI設計書 | P3: マスタ連携対応 | V3: 方式設計 | BD3: =改版履歴!$AO$3 -> 1.6 | BF3: 富士通 | BI3: =改版履歴!$AT$3 -> 45672 | BM3: 富士通 | BP3: =改版履歴!$BA$3 -> 45427
D6: ６．システム設定
E8: ※本対応に伴う新規システム設定
A18: *1.4

Sheet 《参照ネタ》新規システム設定
A1: ignicaPOS連携(マスタ連携) 新規システム設定
C3: 分類 | D3: OPT_ID | E3: 初期値 | F3: 設定値 | G3: 説明 | H3: 詳細説明 | I3: 分類 | J3: 公開／非公開
C4: その他オプション | D4: 348100000 | E4: 0 | F4: 1 (PTFでは変更せず、運用開始時に変更する) | G4: ignicaPOS連携（マスタ連携）を行うか否かを設定します。（０：行わない、１：行う） | H4: ignica連携（マスタ連携）を行うか否かを設定する。 ０：行わない マスタ連携ファイルの作成および送信を行わない １：行う マスタ連携ファイルの作成および送信を行う （別途、POSサーバの開閉店BATへの組み込みが必要） ※POSサーバの開閉店BATにignicaPOS連携を組み込んだ後でも、本システム設定が「0：行わない」の場合は下記動作としてマスタ連携を抑止可能とする。 [全件一括データ連携] ・POSサーバの開店処理への組み込みの先頭で本システム設定判定を行い、全件一括データの作成およびSFTP送信を行わないようにする。 [差分データ連携] ・常駐プログラム監視処理の起動時に本システム設定の判定を行い、常駐プログラム(マスタ更新履歴監視処理/SFTP送信処理)を起動せず即終了するようにする。 ・各マスタの更新時に本システム設定判定を行い、マスタ更新履歴作成処理を呼ばないようにする。 | I4: 店舗共通設定 | J4: 公開

Sheet 《別紙》VTI社提供資料
A2: Connect through SSH tunnel - Bastion host
L4: Host name: 54.64.180.67
L5: Port: 22
L6: User name: ec2-user
L7: Private key file: bastion_dev_tokyo_kp_1a.ppk
A29: Connect to server
L31: Hostname: ec2-35-77-173-176.ap-northeast-1.compute.amazonaws.com
L32: Port number: 22
L33: User name: ec2-user
L34: Private key file: common_dev_tokyo_kp_1a.ppk
L35: Protocol: SFTP
L80: Remote directory: /mnt/inageya/receive/Input
