Workbook

Sheet 表紙
A1: システム名 | K1: システム種別 | W1: 詳細設計書 | AP1: 作成者 | AT1: 作成日 | AY1: 更新者 | BC1: 更新日 | BH1: 版数
A2: POSサーバー | K2: POSサーバー | AP2: =改訂履歴!$H$11 -> DuNT | AT2: =改訂履歴!$B$11 -> 45469 | AY2: =LOOKUP(2,1/(改訂履歴!H11:H30000<>""),改訂履歴!H11:H30000) -> DuNT | BC2: =LOOKUP(2,1/(改訂履歴!B11:B30000<>""),改訂履歴!B11:B30000) -> 45551 | BH2: =LOOKUP(2,1/(改訂履歴!O11:O30000<>""),改訂履歴!O11:O30000) -> 0.5
A4: 機能カテゴリ | H4: AP1502 | U4: 項目 | Z4: API設計書 | AP4: {=RIGHT(CELL("filename",$A$1),LEN(CELL("filename",$A$1))-FIND("]",CELL("filename",$A$1)))} -> 表紙
L16: POSサーバーの詳細設計書
L24: =K2&"/"&H4&"/"&Z4 -> POSサーバー/AP1502/API設計書
Q44: 承認日 | AA44: 承認者 | AQ44: 版数

Sheet 改訂履歴
A1: システム名 | K1: システム種別 | W1: =IF(表紙!W1="","",表紙!W1) -> 詳細設計書 | AP1: 作成者 | AT1: 作成日 | AY1: 更新者 | BC1: 更新日 | BH1: 版数
A2: =IF(表紙!A2="","",表紙!A2) -> POSサーバー | K2: =IF(表紙!K2="","",表紙!K2) -> POSサーバー | AP2: =IF(表紙!AP2="","",表紙!AP2) -> DuNT | AT2: =IF(表紙!AT2="","",表紙!AT2) -> 45469 | AY2: =IF(表紙!AY2="","",表紙!AY2) -> DuNT | BC2: =IF(表紙!BC2="","",表紙!BC2) -> 45551 | BH2: =IF(表紙!BH2="","",表紙!BH2) -> 0.5
A4: 機能カテゴリ | H4: =IF(表紙!H4="","",表紙!H4) -> AP1502 | U4: 項目 | Z4: =IF(表紙!Z4="","",表紙!Z4) -> API設計書 | AP4: {=RIGHT(CELL("filename",$A$1),LEN(CELL("filename",$A$1))-FIND("]",CELL("filename",$A$1)))} -> 改訂履歴
B8: ■改訂履歴
B10: 更新日 | H10: 更新者 | O10: 版数 | S10: 更新内容 | AX10: 承認日 | BD10: 承認者
B11: 45469 | H11: DuNT | O11: 0.1 | S11: 新規
B13: 45503 | H13: DuNT | O13: 0.2 | S13: AP1502 Amountテーブルの列を追加
S14: AP1502 is_display_on_cash_machine、is_display_on_customer_screenのフィールドを追加する。
B15: 45540 | H15: DuNT | O15: 0.3 | S15: 処理フロー：結合条件を追加
S16: AP1502シート：リクエスト：preset_layout_name, apply_dateを追加
B17: 45544 | H17: DuNT | O17: 0.4 | S17: AP1502 url更新 Request parameterをquerry parameterに変換
S18: 処理フロー：CompanyCodeの結合条件を追加
B19: 45551 | H19: DuNT | O19: 0.5 | S19: AP1502:is_hiddenを追加
S20: AP1502: プリセットイメージurlの説明を追加

Sheet 処理フロー凡例
A1: システム名 | K1: システム種別 | W1: =IF(表紙!W1="","",表紙!W1) -> 詳細設計書 | AP1: 作成者 | AT1: 作成日 | AY1: 更新者 | BC1: 更新日 | BH1: 版数
A2: =IF(表紙!A2="","",表紙!A2) -> POSサーバー | K2: =IF(表紙!K2="","",表紙!K2) -> POSサーバー | AP2: =IF(表紙!AP2="","",表紙!AP2) -> DuNT | AT2: =IF(表紙!AT2="","",表紙!AT2) -> 45469 | AY2: =IF(表紙!AY2="","",表紙!AY2) -> DuNT | BC2: =IF(表紙!BC2="","",表紙!BC2) -> 45551 | BH2: =IF(表紙!BH2="","",表紙!BH2) -> 0.5
A4: 機能カテゴリ | H4: =IF(表紙!H4="","",表紙!H4) -> AP1502 | U4: 項目 | Z4: =IF(表紙!Z4="","",表紙!Z4) -> API設計書 | AP4: =MID(CELL("filename",A1),FIND("]",CELL("filename",A1))+1,255) -> 処理フロー凡例
B7: ●API処理フロー

Sheet AP1502
A1: システム名 | K1: システム種別 | W1: =IF(表紙!W1="","",表紙!W1) -> 詳細設計書 | AP1: 作成者 | AT1: 作成日 | AY1: 更新者 | BC1: 更新日 | BH1: 版数
A2: =IF(表紙!A2="","",表紙!A2) -> POSサーバー | K2: =IF(表紙!K2="","",表紙!K2) -> POSサーバー | AP2: =IF(表紙!AP2="","",表紙!AP2) -> DuNT | AT2: =IF(表紙!AT2="","",表紙!AT2) -> 45469 | AY2: =IF(表紙!AY2="","",表紙!AY2) -> DuNT | BC2: =IF(表紙!BC2="","",表紙!BC2) -> 45551 | BH2: =IF(表紙!BH2="","",表紙!BH2) -> 0.5
A4: 機能カテゴリ | H4: =IF(表紙!H4="","",表紙!H4) -> AP1502 | U4: 項目 | Z4: =IF(表紙!Z4="","",表紙!Z4) -> API設計書 | AP4: =MID(CELL("filename",A1),FIND("]",CELL("filename",A1))+1,255) -> AP1502
B7: 1. 概要
C9: 店舗と検索条件（プリセットレイアウトコード、名称）に従ってプリセットレイアウト一覧を取得する。
B11: 2. リクエスト
C13: 2.1 Request URL
C15: No. | E15: URL | AG15: HTTPメソッド | AQ15: 備考
C16: 1 | E16: api/v1/presets/detail | AG16: GET
C18: 2. 2 Request Header
C20: No. | E20: ヘッダー | L20: 必須 | O20: 型 | S20: デフォルト値 | Z20: 項目説明 | AQ20: 備考
C21: 1 | E21: Authorization | L21: ○ | O21: String | S21: - | Z21: Api key | AQ21: 形式："Bearer {api_key}"
C22: 2 | E22: Accept | L22: - | O22: String | S22: - | Z22: Accept
C23: 3 | E23: Content-Type | L23: ○ | O23: String | S23: application/json | Z23: application/json
C24: 4 | E24: User-Agent | L24: - | O24: String | S24: - | Z24: User-Agent
C25: 5 | E25: Accept-Encoding | L25: - | O25: String | S25: - | Z25: Accept-Encoding
C28: 2.3 Query Parameter/ path parameter
C29: No. | E29: パラメータ | L29: 必須 | O29: 型 | S29: デフォルト値 | Z29: 項目説明 | AQ29: 備考
C30: 1 | E30: store_code | L30: ○ | O30: string | S30: - | Z30: Querry parameter:詳細情報を取得する必要がある対象プリセットレイアウトを含む店舗ID
C31: 2 | E31: preset_layout_code | L31: ○ | O31: string | S31: - | Z31: Querry parameter: 対象プリセットレイアウトコード
C32: 3 | E32: apply_date | L32: ○ | O32: string | S32: - | Z32: Querry parameter: 予約日
C33: 4 | E33: preset_layout_name | L33: ○ | O33: string | S33: - | Z33: Querry parameter: 対象プリセットレイアウト名称
C34: 2.4 Request Body
D35: NA
C37: ※サンプル
D38: NA
B40: 3. レスポンス
C42: 3.1. 正常の場合のレスポンスフォーマット
C44: No. | E44: JSON name | L44: 型 | S44: 項目説明 | AC44: 備考
C45: 1 | E45: preset_menu | L45: List<Menu>
C46: 2 | E46: record_id | L46: BigInt | S46: PresetMenuMaster.ID
C47: 3 | E47: store_code | L47: String | S47: PresetMenuMaster.StoreCode
C48: 4 | E48: preset_layout_code | L48: String | S48: PresetMenuMaster.ButtonLayoutCode
C49: 5 | E49: preset_layout_name | L49: String | S49: PresetMenuMaster.ButtonLayoutName
C50: 6 | E50: booking_date | L50: String | S50: PresetMenuMaster.ApplyDate | AC50: フォーマット: yyyy/mm/dd
C51: 7 | E51: page_number | L51: Int | S51: PresetMenuMaster.PageNumber | AC51: タブ表示位置
C52: 8 | E52: description | L52: String | S52: PresetMenuMaster.Description | AC52: タブ名
C53: 9 | E53: button_column_count | L53: Int | S53: PresetMenuMaster.ButtonColumnCount | AC53: n行に分割されたタブ
C54: 10 | E54: button_row_count | L54: Int | S54: PresetMenuMaster.ButtonRowCount | AC54: n列に分割されたタブ
C55: 11 | E55: is_hidden | L55: Boolean | S55: PresetMenuMaster.IsHidden | AC55: タブ無効化設定
...

Sheet 処理フロー
A1: システム名 | K1: システム種別 | W1: =IF(表紙!W1="","",表紙!W1) -> 詳細設計書 | AP1: 作成者 | AT1: 作成日 | AY1: 更新者 | BC1: 更新日 | BH1: 版数
A2: =IF(表紙!A2="","",表紙!A2) -> POSサーバー | K2: =IF(表紙!K2="","",表紙!K2) -> POSサーバー | AP2: =IF(表紙!AP2="","",表紙!AP2) -> DuNT | AT2: =IF(表紙!AT2="","",表紙!AT2) -> 45469 | AY2: =IF(表紙!AY2="","",表紙!AY2) -> DuNT | BC2: =IF(表紙!BC2="","",表紙!BC2) -> 45551 | BH2: =IF(表紙!BH2="","",表紙!BH2) -> 0.5
A4: 機能カテゴリ | H4: =IF(表紙!H4="","",表紙!H4) -> AP1502 | U4: 項目 | Z4: =IF(表紙!Z4="","",表紙!Z4) -> API設計書 | AP4: =MID(CELL("filename",A1),FIND("]",CELL("filename",A1))+1,255) -> 処理フロー

Sheet テンプレート
A1: システム名 | K1: システム種別 | W1: =IF(表紙!W1="","",表紙!W1) -> 詳細設計書 | AP1: 作成者 | AT1: 作成日 | AY1: 更新者 | BC1: 更新日 | BH1: 版数
A2: =IF(表紙!A2="","",表紙!A2) -> POSサーバー | K2: =IF(表紙!K2="","",表紙!K2) -> POSサーバー | AP2: =IF(表紙!AP2="","",表紙!AP2) -> DuNT | AT2: =IF(表紙!AT2="","",表紙!AT2) -> 45469 | AY2: =IF(表紙!AY2="","",表紙!AY2) -> DuNT | BC2: =IF(表紙!BC2="","",表紙!BC2) -> 45551 | BH2: =IF(表紙!BH2="","",表紙!BH2) -> 0.5
A4: 機能カテゴリ | H4: =IF(表紙!H4="","",表紙!H4) -> AP1502 | U4: 項目 | Z4: =IF(表紙!Z4="","",表紙!Z4) -> API設計書 | AP4: =MID(CELL("filename",A1),FIND("]",CELL("filename",A1))+1,255) -> テンプレート
