Workbook

Sheet 表紙
A1: システム名 | K1: システム種別 | W1: 詳細設計書 | AP1: 作成者 | AT1: 作成日 | AY1: 更新者 | BC1: 更新日 | BH1: 版数
A2: POSサーバー | K2: POSサーバー | AP2: =改訂履歴!$H$11 -> DuNT | AT2: =改訂履歴!$B$11 -> 20245/02/25 | AY2: =LOOKUP(2,1/(改訂履歴!H11:H30000<>""),改訂履歴!H11:H30000) -> LoiLV | BC2: =LOOKUP(2,1/(改訂履歴!B11:B30000<>""),改訂履歴!B11:B30000) -> 45727 | BH2: =LOOKUP(2,1/(改訂履歴!O11:O30000<>""),改訂履歴!O11:O30000) -> 0.11
A4: 機能カテゴリ | H4: AP1511 | U4: 項目 | Z4: API設計書 | AP4: {=RIGHT(CELL("filename",$A$1),LEN(CELL("filename",$A$1))-FIND("]",CELL("filename",$A$1)))} -> 表紙
L16: POSサーバーの詳細設計書
L24: =K2&"/"&H4&"/"&Z4 -> POSサーバー/AP1511/API設計書
Q44: 承認日 | AA44: 承認者 | AQ44: 版数

Sheet 改訂履歴
A1: システム名 | K1: システム種別 | W1: =IF(表紙!W1="","",表紙!W1) -> 詳細設計書 | AP1: 作成者 | AT1: 作成日 | AY1: 更新者 | BC1: 更新日 | BH1: 版数
A2: =IF(表紙!A2="","",表紙!A2) -> POSサーバー | K2: =IF(表紙!K2="","",表紙!K2) -> POSサーバー | AP2: =IF(表紙!AP2="","",表紙!AP2) -> DuNT | AT2: =IF(表紙!AT2="","",表紙!AT2) -> 20245/02/25 | AY2: =IF(表紙!AY2="","",表紙!AY2) -> LoiLV | BC2: =IF(表紙!BC2="","",表紙!BC2) -> 45727 | BH2: =IF(表紙!BH2="","",表紙!BH2) -> 0.11
A4: 機能カテゴリ | H4: =IF(表紙!H4="","",表紙!H4) -> AP1511 | U4: 項目 | Z4: =IF(表紙!Z4="","",表紙!Z4) -> API設計書 | AP4: {=RIGHT(CELL("filename",$A$1),LEN(CELL("filename",$A$1))-FIND("]",CELL("filename",$A$1)))} -> 改訂履歴
B8: ■改訂履歴
B10: 更新日 | H10: 更新者 | O10: 版数 | S10: 更新内容 | AX10: 承認日 | BD10: 承認者
B11: 20245/02/25 | H11: DuNT | O11: 0.1 | S11: 新規
B13: 45727 | H13: LoiLV | O13: 0.11 | S13: プリセットレイアウトコードバリデーションチェック更新
S14: 店舗権限更新

Sheet 処理フロー凡例
A1: システム名 | K1: システム種別 | W1: =IF(表紙!W1="","",表紙!W1) -> 詳細設計書 | AP1: 作成者 | AT1: 作成日 | AY1: 更新者 | BC1: 更新日 | BH1: 版数
A2: =IF(表紙!A2="","",表紙!A2) -> POSサーバー | K2: =IF(表紙!K2="","",表紙!K2) -> POSサーバー | AP2: =IF(表紙!AP2="","",表紙!AP2) -> DuNT | AT2: =IF(表紙!AT2="","",表紙!AT2) -> 20245/02/25 | AY2: =IF(表紙!AY2="","",表紙!AY2) -> LoiLV | BC2: =IF(表紙!BC2="","",表紙!BC2) -> 45727 | BH2: =IF(表紙!BH2="","",表紙!BH2) -> 0.11
A4: 機能カテゴリ | H4: =IF(表紙!H4="","",表紙!H4) -> AP1511 | U4: 項目 | Z4: =IF(表紙!Z4="","",表紙!Z4) -> API設計書 | AP4: =MID(CELL("filename",A1),FIND("]",CELL("filename",A1))+1,255) -> 処理フロー凡例
B7: ●API処理フロー

Sheet AP1511
A1: システム名 | K1: システム種別 | W1: =IF(表紙!W1="","",表紙!W1) -> 詳細設計書 | AP1: 作成者 | AT1: 作成日 | AY1: 更新者 | BC1: 更新日 | BH1: 版数
A2: =IF(表紙!A2="","",表紙!A2) -> POSサーバー | K2: =IF(表紙!K2="","",表紙!K2) -> POSサーバー | AP2: =IF(表紙!AP2="","",表紙!AP2) -> DuNT | AT2: =IF(表紙!AT2="","",表紙!AT2) -> 20245/02/25 | AY2: =IF(表紙!AY2="","",表紙!AY2) -> LoiLV | BC2: =IF(表紙!BC2="","",表紙!BC2) -> 45727 | BH2: =IF(表紙!BH2="","",表紙!BH2) -> 0.11
A4: 機能カテゴリ | H4: =IF(表紙!H4="","",表紙!H4) -> AP1511 | U4: 項目 | Z4: =IF(表紙!Z4="","",表紙!Z4) -> API設計書 | AP4: =MID(CELL("filename",A1),FIND("]",CELL("filename",A1))+1,255) -> AP1511
B7: 1. 概要
C9: プリセットレイアウトを新規作成・削除する。
B11: 2. リクエスト
C13: 2.1 Request URL
C15: No. | E15: URL | AG15: HTTPメソッド | AQ15: 備考
C16: 1 | E16: api/v1/preset/maintenance/list | AG16: POST | AQ16: -
C18: 2. 2 Request Header
C20: No. | E20: ヘッダー | L20: 必須 | O20: 型 | S20: デフォルト値 | Z20: 項目説明 | AQ20: 備考
C21: 1 | E21: Authorization | L21: ○ | O21: String | S21: - | Z21: Api key | AQ21: 代表ユーザーを認証するAPIキー値 フォーマット："Bearer {api_key}"
C23: 2 | E23: Accept | L23: - | O23: String | S23: - | Z23: Accept
C24: 3 | E24: Content-Type | L24: ○ | O24: String | S24: application/json | Z24: Content-Type
C25: 4 | E25: User-Agent | L25: - | O25: String | S25: - | Z25: User-Agent
C26: 5 | E26: Accept-Encoding | L26: - | O26: String | S26: - | Z26: Accept-Encoding
C28: 2.3 Query Parameter/ path parameter
C30: No. | E30: パラメータ | L30: 必須 | O30: 型 | S30: デフォルト値 | Z30: 項目説明 | AQ30: 備考
C31: なし
C33: 2.4 Request Body
C35: No. | E35: パラメータ | L35: 必須 | O35: 型 | S35: デフォルト値 | Z35: 項目説明 | AQ35: 備考
C36: 1 | E36: mode | L36: ○ | O36: Int | S36: - | Z36: いなげやの場合、 0 = 保存 (翌日の新規作成・コピーに適用） 1= 確定 (即時に新規作成・コピーに適用） カスミの場合：以下のみがある。モード1= 確定 (即時に新規作成・コピーに適用） | AQ36: company_code = 100 (カスミ)の場合、「1」以外の場合、エラーメッセージ = MSG_VAL_019 company_code = 800 (いなげや)の場合、「0」又は「1」以外の場合、エラーメッセージ = MSG_VAL_019
C37: 2 | E37: preset_menu | L37: - | O37: List<Menu> | S37: -
C38: 3 | E38: operation_type | L38: ○ | O38: Small Int | S38: - | AQ38: ・新規作成の場合、operation_typeを「1」として渡す。 ・削除の場合、operation_typeを「3」として渡す。 上記以外の場合、エラーメッセージ = MSG_VAL_019
C39: 4 | E39: record_id | L39: - | O39: BigInt | S39: - | Z39: PresetMenuMaster.ID | AQ39: ・プリセットレイアウトを新規作成する場合、record_idをnullとして渡す。 ・プリセットレイアウトを削除する場合、該当するrecord_idを渡す。
C40: 5 | E40: store_code | L40: ○ | O40: String | S40: - | Z40: PresetMenuMaster.StoreCode | AQ40: バリデーションチェック：数字、4桁 バリデーションチェックNGの場合、エラーメッセージ = MSG_VAL_019
C41: 6 | E41: preset_layout_code | L41: ○ | O41: String | S41: - | Z41: PresetMenuMaster.ButtonLayoutCode | AQ41: バリデーションチェックの新規作成の場合： カスミ様：数字4桁 -> 数字ではない場合、エラーメッセージ = MSG_VAL_026、長さが4桁以外の場合、エラーメッセージ= MSG_VAL_002 いなげや様：形式：8XXX01 8XXX02（6桁、XXX：店舗コード）。エラーメッセージ = MSG_VAL_019。
C42: 7 | E42: preset_layout_name | L42: ○ | O42: String | S42: - | Z42: PresetMenuMaster.ButtonLayoutName | AQ42: 最大半角50文字（全角25文字）。文字数 > 50の場合、 エラーメッセージ = MSG_VAL_002
C43: 8 | E43: booking_date | L43: ○ | O43: String | S43: - | Z43: PresetMenuMaster.ApplyDate | AQ43: フォーマット: yyyy/mm/dd ・編集・削除モードの場合、予約日のバリデーションチェックを行わない。 ・新規作成の場合、 + モード = 0の場合、予約日 = 翌日 + モード = 1の場合、予約日 = 当日 エラーの場合、エラーメッセージ = MSG_VAL_019
C45: ※サンプル
C47: {
C48: "mode": 1,
C49: "preset_menu": [
D50: {
C51: "operation_type": 1
D52: "record_id: "",
D53: "store_code: "",
D54: "preset_layout_code: "",
D55: "preset_layout_name: "",
D56: "booking_date: "",
...

Sheet 処理フロー
A1: システム名 | K1: システム種別 | W1: =IF(表紙!W1="","",表紙!W1) -> 詳細設計書 | AP1: 作成者 | AT1: 作成日 | AY1: 更新者 | BC1: 更新日 | BH1: 版数
A2: =IF(表紙!A2="","",表紙!A2) -> POSサーバー | K2: =IF(表紙!K2="","",表紙!K2) -> POSサーバー | AP2: =IF(表紙!AP2="","",表紙!AP2) -> DuNT | AT2: =IF(表紙!AT2="","",表紙!AT2) -> 20245/02/25 | AY2: =IF(表紙!AY2="","",表紙!AY2) -> LoiLV | BC2: =IF(表紙!BC2="","",表紙!BC2) -> 45727 | BH2: =IF(表紙!BH2="","",表紙!BH2) -> 0.11
A4: 機能カテゴリ | H4: =IF(表紙!H4="","",表紙!H4) -> AP1511 | U4: 項目 | Z4: =IF(表紙!Z4="","",表紙!Z4) -> API設計書 | AP4: =MID(CELL("filename",A1),FIND("]",CELL("filename",A1))+1,255) -> 処理フロー
B11: ▪プリセットメニューの追加・更新・削除処理

Sheet テンプレート
A1: システム名 | K1: システム種別 | W1: =IF(表紙!W1="","",表紙!W1) -> 詳細設計書 | AP1: 作成者 | AT1: 作成日 | AY1: 更新者 | BC1: 更新日 | BH1: 版数
A2: =IF(表紙!A2="","",表紙!A2) -> POSサーバー | K2: =IF(表紙!K2="","",表紙!K2) -> POSサーバー | AP2: =IF(表紙!AP2="","",表紙!AP2) -> DuNT | AT2: =IF(表紙!AT2="","",表紙!AT2) -> 20245/02/25 | AY2: =IF(表紙!AY2="","",表紙!AY2) -> LoiLV | BC2: =IF(表紙!BC2="","",表紙!BC2) -> 45727 | BH2: =IF(表紙!BH2="","",表紙!BH2) -> 0.11
A4: 機能カテゴリ | H4: =IF(表紙!H4="","",表紙!H4) -> AP1511 | U4: 項目 | Z4: =IF(表紙!Z4="","",表紙!Z4) -> API設計書 | AP4: =MID(CELL("filename",A1),FIND("]",CELL("filename",A1))+1,255) -> テンプレート
