Workbook

Sheet 表紙
A1: システム名 | K1: システム種別 | W1: 詳細設計書 | AP1: 作成者 | AT1: 作成日 | AY1: 更新者 | BC1: 更新日 | BH1: 版数
A2: POSサーバー | K2: POSサーバー | AP2: =改訂履歴!$H$11 -> DuNT | AT2: =改訂履歴!$B$11 -> 45516 | AY2: =LOOKUP(2,1/(改訂履歴!H11:H30000<>""),改訂履歴!H11:H30000) -> LoiLV | BC2: =LOOKUP(2,1/(改訂履歴!B11:B30000<>""),改訂履歴!B11:B30000) -> 45964 | BH2: =LOOKUP(2,1/(改訂履歴!O11:O30000<>""),改訂履歴!O11:O30000) -> 0.12
A4: 機能カテゴリ | H4: AP1504 | U4: 項目 | Z4: API設計書 | AP4: {=RIGHT(CELL("filename",$A$1),LEN(CELL("filename",$A$1))-FIND("]",CELL("filename",$A$1)))} -> 表紙
L16: POSサーバーの詳細設計書
L24: =K2&"/"&H4&"/"&Z4 -> POSサーバー/AP1504/API設計書
Q44: 承認日 | AA44: 承認者 | AQ44: 版数

Sheet 改訂履歴
A1: システム名 | K1: システム種別 | W1: =IF(表紙!W1="","",表紙!W1) -> 詳細設計書 | AP1: 作成者 | AT1: 作成日 | AY1: 更新者 | BC1: 更新日 | BH1: 版数
A2: =IF(表紙!A2="","",表紙!A2) -> POSサーバー | K2: =IF(表紙!K2="","",表紙!K2) -> POSサーバー | AP2: =IF(表紙!AP2="","",表紙!AP2) -> DuNT | AT2: =IF(表紙!AT2="","",表紙!AT2) -> 45516 | AY2: =IF(表紙!AY2="","",表紙!AY2) -> LoiLV | BC2: =IF(表紙!BC2="","",表紙!BC2) -> 45964 | BH2: =IF(表紙!BH2="","",表紙!BH2) -> 0.12
A4: 機能カテゴリ | H4: =IF(表紙!H4="","",表紙!H4) -> AP1504 | U4: 項目 | Z4: =IF(表紙!Z4="","",表紙!Z4) -> API設計書 | AP4: {=RIGHT(CELL("filename",$A$1),LEN(CELL("filename",$A$1))-FIND("]",CELL("filename",$A$1)))} -> 改訂履歴
B8: ■改訂履歴
B10: 更新日 | H10: 更新者 | O10: 版数 | S10: 更新内容 | AX10: 承認日 | BD10: 承認者
B11: 45516 | H11: DuNT | O11: 0.1 | S11: 新規
B13: 45607 | H13: DuNT | O13: 0.11 | S13: AP1504: 予約日のバリデーションチェック更新
B15: 45964 | H15: LoiLV | O15: 0.12 | S15: プリセットレイアウトコードバリデーションチェック更新
S16: 店舗権限更新

Sheet 処理フロー凡例
A1: システム名 | K1: システム種別 | W1: =IF(表紙!W1="","",表紙!W1) -> 詳細設計書 | AP1: 作成者 | AT1: 作成日 | AY1: 更新者 | BC1: 更新日 | BH1: 版数
A2: =IF(表紙!A2="","",表紙!A2) -> POSサーバー | K2: =IF(表紙!K2="","",表紙!K2) -> POSサーバー | AP2: =IF(表紙!AP2="","",表紙!AP2) -> DuNT | AT2: =IF(表紙!AT2="","",表紙!AT2) -> 45516 | AY2: =IF(表紙!AY2="","",表紙!AY2) -> LoiLV | BC2: =IF(表紙!BC2="","",表紙!BC2) -> 45964 | BH2: =IF(表紙!BH2="","",表紙!BH2) -> 0.12
A4: 機能カテゴリ | H4: =IF(表紙!H4="","",表紙!H4) -> AP1504 | U4: 項目 | Z4: =IF(表紙!Z4="","",表紙!Z4) -> API設計書 | AP4: =MID(CELL("filename",A1),FIND("]",CELL("filename",A1))+1,255) -> 処理フロー凡例
B7: ●API処理フロー

Sheet AP1504
A1: システム名 | K1: システム種別 | W1: =IF(表紙!W1="","",表紙!W1) -> 詳細設計書 | AP1: 作成者 | AT1: 作成日 | AY1: 更新者 | BC1: 更新日 | BH1: 版数
A2: =IF(表紙!A2="","",表紙!A2) -> POSサーバー | K2: =IF(表紙!K2="","",表紙!K2) -> POSサーバー | AP2: =IF(表紙!AP2="","",表紙!AP2) -> DuNT | AT2: =IF(表紙!AT2="","",表紙!AT2) -> 45516 | AY2: =IF(表紙!AY2="","",表紙!AY2) -> LoiLV | BC2: =IF(表紙!BC2="","",表紙!BC2) -> 45964 | BH2: =IF(表紙!BH2="","",表紙!BH2) -> 0.12
A4: 機能カテゴリ | H4: =IF(表紙!H4="","",表紙!H4) -> AP1504 | U4: 項目 | Z4: =IF(表紙!Z4="","",表紙!Z4) -> API設計書 | AP4: =MID(CELL("filename",A1),FIND("]",CELL("filename",A1))+1,255) -> AP1504
B7: 1. 概要
C9: コピーすることでプリセットレイアウトを新規作成または編集する。
B11: 2. リクエスト
C13: 2.1 Request URL
C15: No. | E15: URL | AG15: HTTPメソッド | AQ15: 備考
C16: 1 | E16: api/v1/preset/copy | AG16: POST | AQ16: -
C18: 2. 2 Request Header
C20: No. | E20: ヘッダー | L20: 必須 | O20: 型 | S20: デフォルト値 | Z20: 項目説明 | AQ20: 備考
C21: 1 | E21: Authorization | L21: ○ | O21: String | S21: - | Z21: Api key | AQ21: 代表ユーザーを認証するAPIキー値 フォーマット："Bearer {api_key}"
C23: 2 | E23: Accept | L23: - | O23: String | S23: - | Z23: Accept
C24: 3 | E24: Content-Type | L24: ○ | O24: String | S24: application/json | Z24: Content-Type
C25: 4 | E25: User-Agent | L25: - | O25: String | S25: - | Z25: User-Agent
C26: 5 | E26: Accept-Encoding | L26: - | O26: String | S26: - | Z26: Accept-Encoding
C28: 2.3 Query Parameter/ path parameter
C30: No. | E30: パラメータ | L30: 必須 | O30: 型 | S30: デフォルト値 | Z30: 項目説明 | AQ30: 備考
C31: なし
C33: 2.4 Request Body
C35: No. | E35: パラメータ | L35: 必須 | O35: 型 | S35: デフォルト値 | Z35: 項目説明 | AQ35: 備考
C36: 1 | E36: mode | L36: ○ | O36: Int | S36: - | Z36: いなげやの場合、 0 = 保存 (翌日の新規作成・コピーに適用) 1= 確定 (即時に新規作成・コピーに適用) カスミの場合、以下のみがある。モード1= 確定 (即時に新規作成・コピーに適用) | AQ36: company_code = 100 (カスミ)の場合、「1」以外の場合、エラーメッセージ = MSG_VAL_019 company_code = 800 (いなげや)の場合、「0」又は「1」以外の場合、エラーメッセージ = MSG_VAL_019
C37: 2 | E37: store | L37: ○ | O37: String | S37: - | Z37: コピー用元プリセットレイアウトを含む店舗
C38: 3 | E38: preset_layout_code | L38: ○ | O38: String | S38: - | Z38: コピー用元プリセットレイアウトコード
C39: 4 | E39: preset_layout_name | L39: - | O39: String | S39: - | Z39: コピー用元プリセットレイアウト名称
C40: 5 | E40: booking_date | L40: - | O40: String | S40: - | Z40: コピー用元プリセットレイアウトの予約日
C41: 6 | E41: items | L41: ○ | O41: List<Object> | Z41: コピーデータを含む対象一覧
C42: 7 | E42: store | L42: ○ | O42: String | S42: - | Z42: PresetMenuMaster.StoreCode PresetMenuButtonMaster.StoreCode | AQ42: バリデーションチェック：数字、4桁 バリデーションチェックNGの場合、エラーメッセージ = MSG_VAL_019
C43: 8 | E43: preset_layout_code | L43: ○ | O43: String | S43: - | Z43: PresetMenuMaster.ButtonLayoutCode PresetMenuButtonMaster.ButtonLayoutCode | AQ43: バリデーションチェックの新規作成の場合： カスミ様：数字4桁 -> 数字ではない場合、エラーメッセージ = MSG_VAL_026、長さが4桁以外の場合、エラーメッセージ= MSG_VAL_002 いなげや様：形式：8XXX01 8XXX02（6桁、XXX：店舗コード）。エラーメッセージ = MSG_VAL_019。 ・プリセットレイアウトを新規作成する前に存在を確認する。存在した場合、エラーメッセージ = MSG_ERR_003
C44: 9 | E44: preset_layout_name | L44: ○ | O44: String | S44: - | Z44: PresetMenuMaster.ButtonLayoutName PresetMenuButtonMaster.ButtonLayoutName | AQ44: 最大半角50文字（全角25文字）。文字数 > 50の場合、 エラーメッセージ = MSG_VAL_002
C45: 10 | E45: booking_date | L45: ○ | O45: String | S45: - | Z45: PresetMenuMaster.ApplyDate | AQ45: フォーマット: yyyy/mm/dd + モード = 0の場合、予約日 = 翌日 + モード = 1の場合、予約日 = 当日 エラーの場合、エラーメッセージ = MSG_VAL_019
C47: ※サンプル
C49: {
C50: "items": [
D51: {
C52: "operation_type": 1,
C53: "original_preset_layout":
E54: {
E55: "store_code: "0914",
E56: "preset_layout_code: "2201",
...

Sheet 処理フロー
A1: システム名 | K1: システム種別 | W1: =IF(表紙!W1="","",表紙!W1) -> 詳細設計書 | AP1: 作成者 | AT1: 作成日 | AY1: 更新者 | BC1: 更新日 | BH1: 版数
A2: =IF(表紙!A2="","",表紙!A2) -> POSサーバー | K2: =IF(表紙!K2="","",表紙!K2) -> POSサーバー | AP2: =IF(表紙!AP2="","",表紙!AP2) -> DuNT | AT2: =IF(表紙!AT2="","",表紙!AT2) -> 45516 | AY2: =IF(表紙!AY2="","",表紙!AY2) -> LoiLV | BC2: =IF(表紙!BC2="","",表紙!BC2) -> 45964 | BH2: =IF(表紙!BH2="","",表紙!BH2) -> 0.12
A4: 機能カテゴリ | H4: =IF(表紙!H4="","",表紙!H4) -> AP1504 | U4: 項目 | Z4: =IF(表紙!Z4="","",表紙!Z4) -> API設計書 | AP4: =MID(CELL("filename",A1),FIND("]",CELL("filename",A1))+1,255) -> 処理フロー

Sheet テンプレート
A1: システム名 | K1: システム種別 | W1: =IF(表紙!W1="","",表紙!W1) -> 詳細設計書 | AP1: 作成者 | AT1: 作成日 | AY1: 更新者 | BC1: 更新日 | BH1: 版数
A2: =IF(表紙!A2="","",表紙!A2) -> POSサーバー | K2: =IF(表紙!K2="","",表紙!K2) -> POSサーバー | AP2: =IF(表紙!AP2="","",表紙!AP2) -> DuNT | AT2: =IF(表紙!AT2="","",表紙!AT2) -> 45516 | AY2: =IF(表紙!AY2="","",表紙!AY2) -> LoiLV | BC2: =IF(表紙!BC2="","",表紙!BC2) -> 45964 | BH2: =IF(表紙!BH2="","",表紙!BH2) -> 0.12
A4: 機能カテゴリ | H4: =IF(表紙!H4="","",表紙!H4) -> AP1504 | U4: 項目 | Z4: =IF(表紙!Z4="","",表紙!Z4) -> API設計書 | AP4: =MID(CELL("filename",A1),FIND("]",CELL("filename",A1))+1,255) -> テンプレート
