Workbook

Sheet 表紙
A1: システム名 | K1: システム種別 | W1: 詳細設計書 | AP1: 作成者 | AT1: 作成日 | AY1: 更新者 | BC1: 更新日 | BH1: 版数
A2: POSサーバー | K2: POSサーバー | AP2: =改訂履歴!$H$11 -> DuNT | AT2: =改訂履歴!$B$11 -> 45475 | AY2: =LOOKUP(2,1/(改訂履歴!H11:H30000<>""),改訂履歴!H11:H30000) -> AnhTTP | BC2: =LOOKUP(2,1/(改訂履歴!B11:B30000<>""),改訂履歴!B11:B30000) -> 45701 | BH2: =LOOKUP(2,1/(改訂履歴!O11:O30000<>""),改訂履歴!O11:O30000) -> 0.55
A4: 機能カテゴリ | H4: AP1506 | U4: 項目 | Z4: API設計書 | AP4: {=RIGHT(CELL("filename",$A$1),LEN(CELL("filename",$A$1))-FIND("]",CELL("filename",$A$1)))} -> 表紙
L16: POSサーバーの詳細設計書
L24: =K2&"/"&H4&"/"&Z4 -> POSサーバー/AP1506/API設計書
Q44: 承認日 | AA44: 承認者 | AQ44: 版数

Sheet 改訂履歴
A1: システム名 | K1: システム種別 | W1: =IF(表紙!W1="","",表紙!W1) -> 詳細設計書 | AP1: 作成者 | AT1: 作成日 | AY1: 更新者 | BC1: 更新日 | BH1: 版数
A2: =IF(表紙!A2="","",表紙!A2) -> POSサーバー | K2: =IF(表紙!K2="","",表紙!K2) -> POSサーバー | AP2: =IF(表紙!AP2="","",表紙!AP2) -> DuNT | AT2: =IF(表紙!AT2="","",表紙!AT2) -> 45475 | AY2: =IF(表紙!AY2="","",表紙!AY2) -> AnhTTP | BC2: =IF(表紙!BC2="","",表紙!BC2) -> 45701 | BH2: =IF(表紙!BH2="","",表紙!BH2) -> 0.55
A4: 機能カテゴリ | H4: =IF(表紙!H4="","",表紙!H4) -> AP1506 | U4: 項目 | Z4: =IF(表紙!Z4="","",表紙!Z4) -> API設計書 | AP4: {=RIGHT(CELL("filename",$A$1),LEN(CELL("filename",$A$1))-FIND("]",CELL("filename",$A$1)))} -> 改訂履歴
B8: ■改訂履歴
B10: 更新日 | H10: 更新者 | O10: 版数 | S10: 更新内容 | AX10: 承認日 | BD10: 承認者
B11: 45475 | H11: DuNT | O11: 0.1 | S11: 新規
B13: 45509 | H13: DuNT | O13: 0.2 | S13: urlの更新
S14: 部門コードと商品コードを使用した商品検索の説明を追加する。
B15: 45517 | H15: TuyeNH | O15: 0.3 | S15: 現在売価を取得する。
S16: AP1506、処理フロー
B17: 45541 | H17: DuNT | O17: 0.4 | S17: リクエストキーの変更：PLU -> plu
B19: 45544 | H19: TuyeNH | O19: 0.5 | S19: 会員売価取得
S20: AP1506、処理フロー
B21: 45624 | H21: TuyeNH | O21: 0.51 | S21: 現在売価のロジックを共通ファイルに移行する。
S22: AP1506、処理フロー
B23: 45628 | H23: DuNT | O23: 0.52 | S23: マッピングDBの更新
S24: unit_price、force_priceフィールドを追加
B25: 45646 | H25: DuNT | O25: 0.53 | S25: 親PLU検索ロジックを追加
B27: 45667 | H27: AnhTTP | O27: 0.54 | S27: 定番売価取得更新
B29: 45701 | H29: AnhTTP | O29: 0.55 | S29: my_company_codeで商品を取得する条件を更新する。

Sheet 処理フロー凡例
A1: システム名 | K1: システム種別 | W1: =IF(表紙!W1="","",表紙!W1) -> 詳細設計書 | AP1: 作成者 | AT1: 作成日 | AY1: 更新者 | BC1: 更新日 | BH1: 版数
A2: =IF(表紙!A2="","",表紙!A2) -> POSサーバー | K2: =IF(表紙!K2="","",表紙!K2) -> POSサーバー | AP2: =IF(表紙!AP2="","",表紙!AP2) -> DuNT | AT2: =IF(表紙!AT2="","",表紙!AT2) -> 45475 | AY2: =IF(表紙!AY2="","",表紙!AY2) -> AnhTTP | BC2: =IF(表紙!BC2="","",表紙!BC2) -> 45701 | BH2: =IF(表紙!BH2="","",表紙!BH2) -> 0.55
A4: 機能カテゴリ | H4: =IF(表紙!H4="","",表紙!H4) -> AP1506 | U4: 項目 | Z4: =IF(表紙!Z4="","",表紙!Z4) -> API設計書 | AP4: =MID(CELL("filename",A1),FIND("]",CELL("filename",A1))+1,255) -> 処理フロー凡例
B7: ●API処理フロー

Sheet AP1506
A1: システム名 | K1: システム種別 | W1: =IF(表紙!W1="","",表紙!W1) -> 詳細設計書 | AP1: 作成者 | AT1: 作成日 | AY1: 更新者 | BC1: 更新日 | BH1: 版数
A2: =IF(表紙!A2="","",表紙!A2) -> POSサーバー | K2: =IF(表紙!K2="","",表紙!K2) -> POSサーバー | AP2: =IF(表紙!AP2="","",表紙!AP2) -> DuNT | AT2: =IF(表紙!AT2="","",表紙!AT2) -> 45475 | AY2: =IF(表紙!AY2="","",表紙!AY2) -> AnhTTP | BC2: =IF(表紙!BC2="","",表紙!BC2) -> 45701 | BH2: =IF(表紙!BH2="","",表紙!BH2) -> 0.55
A4: 機能カテゴリ | H4: =IF(表紙!H4="","",表紙!H4) -> AP1506 | U4: 項目 | Z4: =IF(表紙!Z4="","",表紙!Z4) -> API設計書 | AP4: =MID(CELL("filename",A1),FIND("]",CELL("filename",A1))+1,255) -> AP1506
B7: 1. 概要
C9: PLUコード (13桁。13桁未満の場合、先頭に「0」を自動的に追加する)に基づいて商品を検索し、商品の基本情報を取得する。
B11: 2. リクエスト
C13: 2.1 Request URL
C15: No. | E15: URL | AG15: HTTPメソッド | AQ15: 備考
C16: 1 | E16: api/v1/product/suggest | AG16: GET
C18: 2. 2 Request Header
C20: No. | E20: ヘッダー | L20: 必須 | O20: 型 | S20: デフォルト値 | Z20: 項目説明 | AQ20: 備考
C21: 1 | E21: Authorization | L21: ○ | O21: String | S21: - | Z21: Api key | AQ21: 形式："Bearer {api_key}"
C22: 2 | E22: Accept | L22: - | O22: String | S22: - | Z22: Accept
C23: 3 | E23: Content-Type | L23: ○ | O23: String | S23: application/json | Z23: Content-Type
C26: 4 | E26: User-Agent | L26: - | O26: String | S26: - | Z26: User-Agent
C27: 5 | E27: Accept-Encoding | L27: - | O27: String | S27: - | Z27: Accept-Encoding
C30: 2.3 Query Parameter/ path parameter
C32: No. | E32: パラメータ | L32: 必須 | O32: 型 | S32: デフォルト値 | Z32: 項目説明 | AQ32: 備考
C33: 1 | E33: selected_store | L33: ○ | O33: string | S33: - | Z33: ユーザーが選択した店舗
C34: 2 | E34: plu | L34: - | O34: string | S34: - | Z34: Query parameter: PLUコード | AQ34: 13桁。13桁未満の場合、エラーメッセージ = MSG_VAL_002
C35: 3 | E35: group_code | L35: - | O35: string | S35: - | Z35: Query parameter: 部門 | AQ35: 2桁。2桁未満の場合、 エラーメッセージ = MSG_VAL_002
C36: 4 | E36: product_code | L36: - | O36: string | S36: - | Z36: Query parameter: 商品コード | AQ36: 6桁。6桁未満の場合、 エラーメッセージ = MSG_VAL_002
C37: 5 | E37: promotion_code | L37: - | O37: string | S37: - | Z37: プロモーションコード | AQ37: 5桁。5桁未満の場合、 エラーメッセージ = MSG_VAL_002
C38: 2.4 Request Body
D39: NA
B41: 3. レスポンス
C43: 3.1. 正常の場合のレスポンスフォーマット
C45: No. | E45: JSON Name | L45: 型 | S45: 項目説明 | AC45: 備考
C46: 1 | E46: company_code | L46: string | S46: m_item.CompanyCode | AC46: 企業コード カスミ =100、いなげや=800
C47: =C46+1 -> 2 | E47: store_code | L47: string | S47: m_item.StoreCode | AC47: 店舗コード: 5桁
C48: =C47+1 -> 3 | E48: item_code | L48: string | S48: m_item.ItemCode/ m_item.ParentItemCode | AC48: 表示するJANコード 13桁未満の場合、先頭に「0」を自動的に追加する。
C49: =C48+1 -> 4 | E49: my_company_code | L49: string | S49: m_item.MyCompanyCode | AC49: 社内商品コード
C50: =C49+1 -> 5 | E50: desciption | L50: string | S50: m_item.Description | AC50: 商品名称
C51: =C50+1 -> 6 | E51: unit_price | L51: decimal | S51: m_item.StandardPrice又はm_item.UnitPrice | AC51: 商品単価 m_item.StandardPrice != NULLの場合、m_item.StandardPriceを取得する。上記以外の場合、m_item.UnitPriceを取得する。
C52: =C51+1 -> 7 | E52: exist_in | L52: int | S52: m_item.ExistIn | AC52: 0: 全て（All）、1: カスミ、2: ウエルシア
C53: =C52+1 -> 8 | E53: belong_to | L53: int | S53: m_item.BelongTo | AC53: 1: カスミ、2: ウエルシア
C54: =C53+1 -> 9 | E54: force_price | L54: decimal | S54: m_item.ForcePrice | AC54: 緊急売価
C55: =C54+1 -> 10 | E55: current_price | L55: decimal | S55: m_item.ForcePrice SpecialPriceMaster.SpecialPrice | AC55: 現在売価、計算詳細は[処理フロー]シートをご参照ください。
C56: =C55+1 -> 11 | E56: special_valid | L56: small int | S56: - | AC56: 0: 新規: 新規 1: 変更: 変更
C57: ※サンプル
...

Sheet 処理フロー
A1: システム名 | K1: システム種別 | W1: =IF(表紙!W1="","",表紙!W1) -> 詳細設計書 | AP1: 作成者 | AT1: 作成日 | AY1: 更新者 | BC1: 更新日 | BH1: 版数
A2: =IF(表紙!A2="","",表紙!A2) -> POSサーバー | K2: =IF(表紙!K2="","",表紙!K2) -> POSサーバー | AP2: =IF(表紙!AP2="","",表紙!AP2) -> DuNT | AT2: =IF(表紙!AT2="","",表紙!AT2) -> 45475 | AY2: =IF(表紙!AY2="","",表紙!AY2) -> AnhTTP | BC2: =IF(表紙!BC2="","",表紙!BC2) -> 45701 | BH2: =IF(表紙!BH2="","",表紙!BH2) -> 0.55
A4: 機能カテゴリ | H4: =IF(表紙!H4="","",表紙!H4) -> AP1506 | U4: 項目 | Z4: =IF(表紙!Z4="","",表紙!Z4) -> API設計書 | AP4: =MID(CELL("filename",A1),FIND("]",CELL("filename",A1))+1,255) -> 処理フロー
O66: s

Sheet テンプレート
A1: システム名 | K1: システム種別 | W1: =IF(表紙!W1="","",表紙!W1) -> 詳細設計書 | AP1: 作成者 | AT1: 作成日 | AY1: 更新者 | BC1: 更新日 | BH1: 版数
A2: =IF(表紙!A2="","",表紙!A2) -> POSサーバー | K2: =IF(表紙!K2="","",表紙!K2) -> POSサーバー | AP2: =IF(表紙!AP2="","",表紙!AP2) -> DuNT | AT2: =IF(表紙!AT2="","",表紙!AT2) -> 45475 | AY2: =IF(表紙!AY2="","",表紙!AY2) -> AnhTTP | BC2: =IF(表紙!BC2="","",表紙!BC2) -> 45701 | BH2: =IF(表紙!BH2="","",表紙!BH2) -> 0.55
A4: 機能カテゴリ | H4: =IF(表紙!H4="","",表紙!H4) -> AP1506 | U4: 項目 | Z4: =IF(表紙!Z4="","",表紙!Z4) -> API設計書 | AP4: =MID(CELL("filename",A1),FIND("]",CELL("filename",A1))+1,255) -> テンプレート
