Workbook

Sheet 表紙
A1: システム名 | K1: システム種別 | W1: 詳細設計書 | AP1: 作成者 | AT1: 作成日 | AY1: 更新者 | BC1: 更新日 | BH1: 版数
A2: POSサーバー | K2: POSサーバ | AP2: =改訂履歴!$H$11 -> DuNT | AT2: =改訂履歴!$B$11 -> 45586 | AY2: =LOOKUP(2,1/(改訂履歴!H11:H30000<>""),改訂履歴!H11:H30000) -> DuNT | BC2: =LOOKUP(2,1/(改訂履歴!B11:B30000<>""),改訂履歴!B11:B30000) -> 45653 | BH2: =LOOKUP(2,1/(改訂履歴!O11:O30000<>""),改訂履歴!O11:O30000) -> 0.13
A4: 機能カテゴリ | H4: AP0504 | U4: 項目 | Z4: API設計書 | AP4: {=RIGHT(CELL("filename",$A$1),LEN(CELL("filename",$A$1))-FIND("]",CELL("filename",$A$1)))} -> 表紙
L16: POSサーバーの詳細設計書
L24: =K2&"/"&H4&"/"&Z4 -> POSサーバ/AP0504/API設計書
Q44: 承認日 | AA44: 承認者 | AQ44: 版数

Sheet 改訂履歴
A1: システム名 | K1: システム種別 | W1: =IF(表紙!W1="","",表紙!W1) -> 詳細設計書 | AP1: 作成者 | AT1: 作成日 | AY1: 更新者 | BC1: 更新日 | BH1: 版数
A2: =IF(表紙!A2="","",表紙!A2) -> POSサーバー | K2: =IF(表紙!K2="","",表紙!K2) -> POSサーバ | AP2: =IF(表紙!AP2="","",表紙!AP2) -> DuNT | AT2: =IF(表紙!AT2="","",表紙!AT2) -> 45586 | AY2: =IF(表紙!AY2="","",表紙!AY2) -> DuNT | BC2: =IF(表紙!BC2="","",表紙!BC2) -> 45653 | BH2: =IF(表紙!BH2="","",表紙!BH2) -> 0.13
A4: 機能カテゴリ | H4: =IF(表紙!H4="","",表紙!H4) -> AP0504 | U4: 項目 | Z4: =IF(表紙!Z4="","",表紙!Z4) -> API設計書 | AP4: {=RIGHT(CELL("filename",$A$1),LEN(CELL("filename",$A$1))-FIND("]",CELL("filename",$A$1)))} -> 改訂履歴
B8: ■改訂履歴
B10: 更新日 | H10: 更新者 | O10: 版数 | S10: 更新内容 | AX10: 承認日 | BD10: 承認者
B11: 45586 | H11: DuNT | O11: 0.1 | S11: 新規
B13: 45607 | H13: DuNT | O13: 0.11 | S13: バリデーションチェックの更新、record_idの削除
S14: 処理フロー更新
B15: 45649 | H15: DuNT | O15: 0.12 | S15: 会員売価の削除、会員売価設定
B17: 45653 | H17: AnhDD | O17: 0.13 | S17: M_Combination.CombinationTypeに渡される値を 01、02、03 に修正する。
B19: 45653 | H19: DuNT | O19: 0.13 | S19: バリデーションチェック：後のオプション <= 前のオプション

Sheet 処理フロー凡例
A1: システム名 | K1: システム種別 | W1: =IF(表紙!W1="","",表紙!W1) -> 詳細設計書 | AP1: 作成者 | AT1: 作成日 | AY1: 更新者 | BC1: 更新日 | BH1: 版数
A2: =IF(表紙!A2="","",表紙!A2) -> POSサーバー | K2: =IF(表紙!K2="","",表紙!K2) -> POSサーバ | AP2: =IF(表紙!AP2="","",表紙!AP2) -> DuNT | AT2: =IF(表紙!AT2="","",表紙!AT2) -> 45586 | AY2: =IF(表紙!AY2="","",表紙!AY2) -> DuNT | BC2: =IF(表紙!BC2="","",表紙!BC2) -> 45653 | BH2: =IF(表紙!BH2="","",表紙!BH2) -> 0.13
A4: 機能カテゴリ | H4: =IF(表紙!H4="","",表紙!H4) -> AP0504 | U4: 項目 | Z4: =IF(表紙!Z4="","",表紙!Z4) -> API設計書 | AP4: =MID(CELL("filename",A1),FIND("]",CELL("filename",A1))+1,255) -> 処理フロー凡例
B7: ●API処理フロー

Sheet AP0504
A1: システム名 | K1: システム種別 | W1: =IF(表紙!W1="","",表紙!W1) -> 詳細設計書 | AP1: 作成者 | AT1: 作成日 | AY1: 更新者 | BC1: 更新日 | BH1: 版数
A2: =IF(表紙!A2="","",表紙!A2) -> POSサーバー | K2: =IF(表紙!K2="","",表紙!K2) -> POSサーバ | AP2: =IF(表紙!AP2="","",表紙!AP2) -> DuNT | AT2: =IF(表紙!AT2="","",表紙!AT2) -> 45586 | AY2: =IF(表紙!AY2="","",表紙!AY2) -> DuNT | BC2: =IF(表紙!BC2="","",表紙!BC2) -> 45653 | BH2: =IF(表紙!BH2="","",表紙!BH2) -> 0.13
A4: 機能カテゴリ | H4: =IF(表紙!H4="","",表紙!H4) -> AP0504 | U4: 項目 | Z4: =IF(表紙!Z4="","",表紙!Z4) -> API設計書 | AP4: =MID(CELL("filename",A1),FIND("]",CELL("filename",A1))+1,255) -> AP0504
B7: 1. 概要
C9: ミックスマッチ情報を更新する。
B11: 2. リクエスト
C13: 2.1 Request URL
C15: No. | E15: URL | AG15: HTTPメソッド | AQ15: 備考
C16: 1 | E16: api/v1/combinations/maintenance | AG16: POST | AQ16: -
C18: 2. 2 Request Header
C20: No. | E20: ヘッダー | L20: 必須 | O20: 型 | S20: デフォルト値 | Z20: 項目説明 | AQ20: 備考
C21: 1 | E21: Authorization | L21: ○ | O21: String | S21: - | Z21: Api key | AQ21: 代表ユーザーを認証するAPIキー値 フォーマット："Bearer {api_key}"
C23: 2 | E23: Accept | L23: - | O23: String | S23: - | Z23: Accept | AQ23: サーバーが返却できるデータ種類情報を説明する。
C24: 3 | E24: Content-Type | L24: ○ | O24: String | S24: application/json | Z24: Content-Type | AQ24: 送信リクエストの本文情報のタイプを定義する。例: application/json, mutilpart/form-data. 転送データのタイプによって、content-typeが必須又は必須ではない。例： ・入力がjsonの場合、content-typeが必須であり、application/jsonの値を受け取る。
C31: 4 | E31: User-Agent | L31: - | O31: String | S31: - | Z31: User-Agent | AQ31: サーバーを呼び出すクライアントのアプリケーション/ソフトウェア/ブラウザを定義する。
C32: 5 | E32: Accept-Encoding | L32: - | O32: String | S32: - | Z32: Accept-Encoding | AQ32: データ暗号化アルゴリズムを定義する。サーバーから受信したデータに使用できる： zip、gzip、png、gif等
C34: 2.3 Query Parameter/ path parameter
E35: NA
C37: 2.4 Request Body
C39: No. | E39: パラメータ | L39: 必須 | O39: 型 | S39: デフォルト値 | Z39: 項目説明 | AQ39: 備考
C40: 1 | E40: store_code | L40: ○ | O40: String | S40: - | Z40: m_combination.StoreCode | AQ40: ・バリデーションチェック：入力必須（エラーメッセージ = MSG_VAL_001） ・バリデーションチェック：数字であること（エラーメッセージ = MSG_VAL_006） ・バリデーションチェック：3桁未満の場合、 エラーメッセージ = MSG_VAL_002
C41: 2 | E41: promotion_code | L41: ○ | O41: String | S41: - | Z41: m_combination.PromotionCode | AQ41: ・バリデーションチェック：入力必須（エラーメッセージ = MSG_VAL_001） ・バリデーションチェック：数字であること（エラーメッセージ = MSG_VAL_006） ・バリデーションチェック：5桁ではない場合、 エラーメッセージ = MSG_VAL_028
C42: 3 | E42: code | L42: ○ | O42: String | S42: - | Z42: m_combination.CombinationCode | AQ42: バリデーションチェック：入力必須（エラーメッセージ = MSG_VAL_001） ・バリデーションチェック：数字であること（エラーメッセージ = MSG_VAL_006） ・バリデーションチェック：3桁ではない場合、エラーメッセージ = MSG_VAL_028 ・新規作成の場合、コードが100から999の範囲内にあることを確認する。100から999の範囲外の場合、エラーメッセージ = MSG_VAL_054を返す。
C43: 4 | E43: start_date | L43: ○ | O43: String | S43: - | Z43: m_combination.StartDateTime | AQ43: ・バリデーションチェック：入力必須（エラーメッセージ = MSG_VAL_001） ・形式：yyyy/MM/dd。形式が不正な場合、エラーメッセージ = MSG_VAL_003 ・バリデーションチェック： start_date > end_dateの場合、MSG_VAL_004を表示する。
C44: 5 | E44: end_date | L44: ○ | O44: String | S44: - | Z44: m_combination.EndDateTime | AQ44: ・バリデーションチェック：入力必須（エラーメッセージ = MSG_VAL_001） ・形式：yyyy/MM/dd。形式が不正な場合、エラーメッセージ = MSG_VAL_003 ・過去日のバリデーションチェック（エラーメッセージ = MSG_VAL_022）
C45: 6 | E45: start_time | L45: ○ | O45: String | S45: - | Z45: m_combination.StartDateTime | AQ45: 形式：hh:mm。形式が不正な場合、エラーメッセージ= MSG_VAL_003
C46: 7 | E46: end_time | L46: ○ | O46: String | S46: - | Z46: m_combination.EndDateTime | AQ46: 形式：hh:mm。形式が不正な場合、エラーメッセージ= MSG_VAL_003 start_date = end_dateの場合、 +バリデーションチェック：start_time >= end_timeの場合、「MSG_VAL_004」エラーメッセージを表示する。 ・start_date = end_date = today()の場合、 ・バリデーションチェック：end_time <= now()の場合、「MSG_VAL_022」エラーメッセージを表示する。
C47: 10 | E47: time_service | L47: - | O47: SmallInt | S47: 0 | Z47: タイムサービス： 0：通常、1: タイムサービス m_combination.TimeService | AQ47: バリデーションチェック：値= 0 又は 1。上記の値以外の場合はエラーメッセージ = MSG_VAL_019を返す。
C48: 11 | E48: type | L48: - | O48: String | S48: 01 | Z48: ミックスマッチ区分：01: 売価、02:割引、03:値引 m_combination.CombinationType | AQ48: バリデーションチェック：値= "01" 又は "02" 又は "03"。上記の値以外の場合はエラーメッセージ = MSG_VAL_019を返す。
C49: 12 | E49: status | L49: - | O49: SmallInt | S49: 1 | Z49: m_combination.Status | AQ49: バリデーションチェック：値= 0 又は 1。上記の値以外の場合はエラーメッセージ = MSG_VAL_019を返す。
C50: 13 | E50: option | L50: ○ | O50: List<Object> | S50: - | Z50: m_combination.CombinationOptions | AQ50: 必須チェック：オプションに1つのアイテムがあること。
C51: 14 | E51: quantity | L51: - | O51: Int | S51: - | Z51: 1つのミックスマッチオプションでの購入可能な個数 key mQuantity | AQ51: オプション1の場合、以下のように個数のバリデーションチェックを行う。 ・バリデーションチェック：入力必須（エラーメッセージ = MSG_VAL_001） 全てのオプションに適用： ・いずれかの値が存在している場合、入力必須のバリデーションチェックを行う（エラーメッセージ= MSG_VAL_001） ・バリデーションチェック：個数 >= 2。2未満の場合、エラーメッセージ = MSG_VAL_021 ・バリデーションチェック：個数 > 99 （エラーメッセージ = MSG_VAL_002） ・各オプションの数量のバリデーションチェック： +数量が重複している場合、エラーメッセージ = MSG_VAL_053 +数量 <= オプション1の数量の場合、エラーメッセージ = MSG_VAL_053
C52: 15 | E52: value | L52: - | O52: Decimal | S52: - | Z52: 全てのミックスマッチ売価・割引・値引 key mValue | AQ52: 数量が設定されている全てのオプションに適用する。 ・バリデーションチェック：null以外。nullの場合、エラーメッセージ= MSG_VAL_001 ・ 「0」より大きいことのバリデーションチェック。条件を満たさない場合、エラーメッセージ = MSG_VAL_019 ミックスマッチタイプ = 1 h又は 3の場合、 ・バリデーションチェック：6桁を超える（エラーメッセージ= MSG_VAL_002） ミックスマッチ区分 = 2の場合、 ・バリデーションチェック：2桁を超える（エラーメッセージ= MSG_VAL_002）
C53: 18 | E53: product | L53: ○ | O53: List<Object> | S53: - | Z53: ミックスマッチの商品 | AQ53: 商品一覧が空の場合、エラーメッセージ = MSG_VAL_001を返す。
C54: 19 | E54: plu_code | L54: ○ | O54: String | S54: - | Z54: 商品のPLUコード m_combinationitem.ItemCode | AQ54: ・バリデーションチェック：入力必須（エラーメッセージ = MSG_VAL_001） ・バリデーションチェック：数字であること（エラーメッセージ = MSG_VAL_006） ・バリデーションチェック：13桁未満の場合、 エラーメッセージ = MSG_VAL_028
C55: 20 | E55: status | L55: - | O55: SmallInt | S55: - | Z55: 状態: 0: 実施 1: 中止 m_combinationitem.Status | AQ55: バリデーションチェック：値= 0 又は 1。上記の値以外の場合はエラーメッセージ = MSG_VAL_019を返す。
C56: 21 | E56: category_code | L56: ○ | O56: String | S56: - | Z56: m_combinationitem.CategoryCode | AQ56: ・バリデーションチェック：入力必須（エラーメッセージ = MSG_VAL_001） ・バリデーションチェック：数字であること（エラーメッセージ = MSG_VAL_006） ・バリデーションチェック：2桁未満の場合、 エラーメッセージ = MSG_VAL_028
C58: ※サンプル
C59: {
C60: "record_id": 1,
...

Sheet 処理フロー
A1: システム名 | K1: システム種別 | W1: =IF(表紙!W1="","",表紙!W1) -> 詳細設計書 | AP1: 作成者 | AT1: 作成日 | AY1: 更新者 | BC1: 更新日 | BH1: 版数
A2: =IF(表紙!A2="","",表紙!A2) -> POSサーバー | K2: =IF(表紙!K2="","",表紙!K2) -> POSサーバ | AP2: =IF(表紙!AP2="","",表紙!AP2) -> DuNT | AT2: =IF(表紙!AT2="","",表紙!AT2) -> 45586 | AY2: =IF(表紙!AY2="","",表紙!AY2) -> DuNT | BC2: =IF(表紙!BC2="","",表紙!BC2) -> 45653 | BH2: =IF(表紙!BH2="","",表紙!BH2) -> 0.13
A4: 機能カテゴリ | H4: =IF(表紙!H4="","",表紙!H4) -> AP0504 | U4: 項目 | Z4: =IF(表紙!Z4="","",表紙!Z4) -> API設計書 | AP4: =MID(CELL("filename",A1),FIND("]",CELL("filename",A1))+1,255) -> 処理フロー

Sheet テンプレート
A1: システム名 | K1: システム種別 | W1: =IF(表紙!W1="","",表紙!W1) -> 詳細設計書 | AP1: 作成者 | AT1: 作成日 | AY1: 更新者 | BC1: 更新日 | BH1: 版数
A2: =IF(表紙!A2="","",表紙!A2) -> POSサーバー | K2: =IF(表紙!K2="","",表紙!K2) -> POSサーバ | AP2: =IF(表紙!AP2="","",表紙!AP2) -> DuNT | AT2: =IF(表紙!AT2="","",表紙!AT2) -> 45586 | AY2: =IF(表紙!AY2="","",表紙!AY2) -> DuNT | BC2: =IF(表紙!BC2="","",表紙!BC2) -> 45653 | BH2: =IF(表紙!BH2="","",表紙!BH2) -> 0.13
A4: 機能カテゴリ | H4: =IF(表紙!H4="","",表紙!H4) -> AP0504 | U4: 項目 | Z4: =IF(表紙!Z4="","",表紙!Z4) -> API設計書 | AP4: =MID(CELL("filename",A1),FIND("]",CELL("filename",A1))+1,255) -> テンプレート
