Workbook

Sheet 表紙
A1: システム名 | K1: システム種別 | W1: 詳細設計書 | AP1: 作成者 | AT1: 作成日 | AY1: 更新者 | BC1: 更新日 | BH1: 版数
A2: POSサーバー | K2: POSサーバ | AP2: =改訂履歴!$H$11 -> DuNT | AT2: =改訂履歴!$B$11 -> 45583 | AY2: =LOOKUP(2,1/(改訂履歴!H11:H30000<>""),改訂履歴!H11:H30000) -> DuNT | BC2: =LOOKUP(2,1/(改訂履歴!B11:B30000<>""),改訂履歴!B11:B30000) -> 45650 | BH2: =LOOKUP(2,1/(改訂履歴!O11:O30000<>""),改訂履歴!O11:O30000) -> 0.13
A4: 機能カテゴリ | H4: AP0502 | U4: 項目 | Z4: API設計書 | AP4: {=RIGHT(CELL("filename",$A$1),LEN(CELL("filename",$A$1))-FIND("]",CELL("filename",$A$1)))} -> 表紙
L16: POSサーバーの詳細設計書
L24: =K2&"/"&H4&"/"&Z4 -> POSサーバ/AP0502/API設計書
Q44: 承認日 | AA44: 承認者 | AQ44: 版数

Sheet 改訂履歴
A1: システム名 | K1: システム種別 | W1: =IF(表紙!W1="","",表紙!W1) -> 詳細設計書 | AP1: 作成者 | AT1: 作成日 | AY1: 更新者 | BC1: 更新日 | BH1: 版数
A2: =IF(表紙!A2="","",表紙!A2) -> POSサーバー | K2: =IF(表紙!K2="","",表紙!K2) -> POSサーバ | AP2: =IF(表紙!AP2="","",表紙!AP2) -> DuNT | AT2: =IF(表紙!AT2="","",表紙!AT2) -> 45583 | AY2: =IF(表紙!AY2="","",表紙!AY2) -> DuNT | BC2: =IF(表紙!BC2="","",表紙!BC2) -> 45650 | BH2: =IF(表紙!BH2="","",表紙!BH2) -> 0.13
A4: 機能カテゴリ | H4: =IF(表紙!H4="","",表紙!H4) -> AP0502 | U4: 項目 | Z4: =IF(表紙!Z4="","",表紙!Z4) -> API設計書 | AP4: {=RIGHT(CELL("filename",$A$1),LEN(CELL("filename",$A$1))-FIND("]",CELL("filename",$A$1)))} -> 改訂履歴
B8: ■改訂履歴
B10: 更新日 | H10: 更新者 | O10: 版数 | S10: 更新内容 | AX10: 承認日 | BD10: 承認者
B11: 45583 | H11: DuNT | O11: 0.1 | S11: 新規
B13: 45602 | H13: DuNT | O13: 0.11 | S13: sql更新
B15: 45609 | H15: DuNT | O15: 0.12 | S15: AP0501：新しい設計に基づいてDB テーブルを更新し、record_id を削除する
S16: 処理フロー：sql文を更新する。
B17: 45650 | H17: DuNT | O17: 0.13 | S17: ミックスマッチオプション数を追加する。

Sheet 処理フロー凡例
A1: システム名 | K1: システム種別 | W1: =IF(表紙!W1="","",表紙!W1) -> 詳細設計書 | AP1: 作成者 | AT1: 作成日 | AY1: 更新者 | BC1: 更新日 | BH1: 版数
A2: =IF(表紙!A2="","",表紙!A2) -> POSサーバー | K2: =IF(表紙!K2="","",表紙!K2) -> POSサーバ | AP2: =IF(表紙!AP2="","",表紙!AP2) -> DuNT | AT2: =IF(表紙!AT2="","",表紙!AT2) -> 45583 | AY2: =IF(表紙!AY2="","",表紙!AY2) -> DuNT | BC2: =IF(表紙!BC2="","",表紙!BC2) -> 45650 | BH2: =IF(表紙!BH2="","",表紙!BH2) -> 0.13
A4: 機能カテゴリ | H4: =IF(表紙!H4="","",表紙!H4) -> AP0502 | U4: 項目 | Z4: =IF(表紙!Z4="","",表紙!Z4) -> API設計書 | AP4: =MID(CELL("filename",A1),FIND("]",CELL("filename",A1))+1,255) -> 処理フロー凡例
B7: ●API処理フロー

Sheet AP0502
A1: システム名 | K1: システム種別 | W1: =IF(表紙!W1="","",表紙!W1) -> 詳細設計書 | AP1: 作成者 | AT1: 作成日 | AY1: 更新者 | BC1: 更新日 | BH1: 版数
A2: =IF(表紙!A2="","",表紙!A2) -> POSサーバー | K2: =IF(表紙!K2="","",表紙!K2) -> POSサーバ | AP2: =IF(表紙!AP2="","",表紙!AP2) -> DuNT | AT2: =IF(表紙!AT2="","",表紙!AT2) -> 45583 | AY2: =IF(表紙!AY2="","",表紙!AY2) -> DuNT | BC2: =IF(表紙!BC2="","",表紙!BC2) -> 45650 | BH2: =IF(表紙!BH2="","",表紙!BH2) -> 0.13
A4: 機能カテゴリ | H4: =IF(表紙!H4="","",表紙!H4) -> AP0502 | U4: 項目 | Z4: =IF(表紙!Z4="","",表紙!Z4) -> API設計書 | AP4: =MID(CELL("filename",A1),FIND("]",CELL("filename",A1))+1,255) -> AP0502
B7: 1. 概要
C9: ミックスマッチコードを自動生成する：3桁、ミックスマッチコードは連番で増加、DBに存在しないコード（100から999の範囲）を生成する。
B12: 2. リクエスト
C14: 2.1 Request URL
C16: No. | E16: URL | AG16: HTTPメソッド | AQ16: 備考
C17: 1 | E17: api/v1/combinations/generate-code | AG17: GET
C19: 2. 2 Request Header
C21: No. | E21: ヘッダー | L21: 必須 | O21: 型 | S21: デフォルト値 | Z21: 項目説明 | AQ21: 備考
C22: 1 | E22: Authorization | L22: ○ | O22: String | S22: - | Z22: Api key | AQ22: 形式："Bearer {api_key}"
C23: 2 | E23: Accept | L23: - | O23: String | S23: - | Z23: Accept
C24: 3 | E24: Content-Type | L24: ○ | O24: String | S24: application/json | Z24: application/json
C27: 4 | E27: User-Agent | L27: - | O27: String | S27: - | Z27: User-Agent
C28: 5 | E28: Accept-Encoding | L28: - | O28: String | S28: - | Z28: Accept-Encoding
C31: 2.3 Query Parameter/ path parameter
C32: No. | E32: パラメータ | L32: 必須 | O32: 型 | S32: デフォルト値 | Z32: 項目説明 | AQ32: 備考
C33: 1 | E33: selected_store | L33: ○ | O33: String | S33: - | Z33: idの値を生成する店舗 | AQ33: ・バリデーションチェック：4桁未満の場合、 エラーメッセージ = MSG_VAL_002
C34: 2 | E34: promotion_code | L34: ○ | O34: String | S34: - | Z34: プロモーションコード | AQ34: ・バリデーションチェック：数字であること（メッセージ = MSG_VAL_006） ・バリデーションチェック：5桁未満の場合、 エラーメッセージ = MSG_VAL_002
C36: 2.4 Request Body
D37: NA
C39: ※サンプル
D40: NA
B42: 3. レスポンス
C44: 3.1. 正常の場合のレスポンスフォーマット
C46: No. | E46: JSON name | L46: 型 | S46: 項目説明 | AC46: 備考
C47: 1 | E47: store_code | L47: String | S47: m_combination.StoreCode | AC47: 店舗コード
C48: 2 | E48: promotion_code | L48: String | S48: m_combination.PromotionCode | AC48: 作成されたミックスマッチのプロモーションコード
C49: 3 | E49: mix_match_code | L49: String | S49: m_combination.CombinationCode | AC49: ミックスマッチコード
C50: =C49+1 -> 4 | E50: settings | L50: Object | O50: Object | AC50: 各ミックスマッチ区分のオプション数設定
C51: =C50+1 -> 5 | E51: type_one | L51: Int | O51: Int | S51: 一時的に固定値を2に設定する。 | AC51: ミックスマッチタイプ1のオプション数設定
C52: =C51+1 -> 6 | E52: type_two | L52: Int | O52: Int | S52: 一時的に固定値を5に設定する。 | AC52: ミックスマッチタイプ2のオプション数設定
C53: =C52+1 -> 7 | E53: type_three | L53: Int | O53: Int | S53: 一時的に固定値を5に設定する。 | AC53: ミックスマッチタイプ3のオプション数設定
C56: ※サンプル
C58: {
C59: "record_id":1,
C60: "store_code":"09176",
C61: "mix_match_code":"101"
C62: }
...

Sheet 処理フロー
A1: システム名 | K1: システム種別 | W1: =IF(表紙!W1="","",表紙!W1) -> 詳細設計書 | AP1: 作成者 | AT1: 作成日 | AY1: 更新者 | BC1: 更新日 | BH1: 版数
A2: =IF(表紙!A2="","",表紙!A2) -> POSサーバー | K2: =IF(表紙!K2="","",表紙!K2) -> POSサーバ | AP2: =IF(表紙!AP2="","",表紙!AP2) -> DuNT | AT2: =IF(表紙!AT2="","",表紙!AT2) -> 45583 | AY2: =IF(表紙!AY2="","",表紙!AY2) -> DuNT | BC2: =IF(表紙!BC2="","",表紙!BC2) -> 45650 | BH2: =IF(表紙!BH2="","",表紙!BH2) -> 0.13
A4: 機能カテゴリ | H4: =IF(表紙!H4="","",表紙!H4) -> AP0502 | U4: 項目 | Z4: =IF(表紙!Z4="","",表紙!Z4) -> API設計書 | AP4: =MID(CELL("filename",A1),FIND("]",CELL("filename",A1))+1,255) -> 処理フロー

Sheet テンプレート
A1: システム名 | K1: システム種別 | W1: =IF(表紙!W1="","",表紙!W1) -> 詳細設計書 | AP1: 作成者 | AT1: 作成日 | AY1: 更新者 | BC1: 更新日 | BH1: 版数
A2: =IF(表紙!A2="","",表紙!A2) -> POSサーバー | K2: =IF(表紙!K2="","",表紙!K2) -> POSサーバ | AP2: =IF(表紙!AP2="","",表紙!AP2) -> DuNT | AT2: =IF(表紙!AT2="","",表紙!AT2) -> 45583 | AY2: =IF(表紙!AY2="","",表紙!AY2) -> DuNT | BC2: =IF(表紙!BC2="","",表紙!BC2) -> 45650 | BH2: =IF(表紙!BH2="","",表紙!BH2) -> 0.13
A4: 機能カテゴリ | H4: =IF(表紙!H4="","",表紙!H4) -> AP0502 | U4: 項目 | Z4: =IF(表紙!Z4="","",表紙!Z4) -> API設計書 | AP4: =MID(CELL("filename",A1),FIND("]",CELL("filename",A1))+1,255) -> テンプレート
