Workbook

Sheet 表紙
A1: システム名 | K1: システム種別 | W1: 詳細設計書 | AP1: 作成者 | AT1: 作成日 | AY1: 更新者 | BC1: 更新日 | BH1: 版数
A2: POSサーバー | K2: POSサーバー | AP2: =改訂履歴!$H$11 -> LoiLV | AT2: =改訂履歴!$B$11 -> 45461 | AY2: =LOOKUP(2,1/(改訂履歴!H11:H30000<>""),改訂履歴!H11:H30000) -> TuyenNH | BC2: =LOOKUP(2,1/(改訂履歴!B11:B30000<>""),改訂履歴!B11:B30000) -> 45601 | BH2: =LOOKUP(2,1/(改訂履歴!O11:O30000<>""),改訂履歴!O11:O30000) -> 0.11
A4: 機能カテゴリ | H4: AP2102 | U4: 項目 | Z4: API設計書 | AP4: {=RIGHT(CELL("filename",$A$1),LEN(CELL("filename",$A$1))-FIND("]",CELL("filename",$A$1)))} -> 表紙
L16: POSサーバーの詳細設計書
L24: =K2&"/"&H4&"/"&Z4 -> POSサーバー/AP2102/API設計書
Q44: 承認日 | AA44: 承認者 | AQ44: 版数

Sheet 改訂履歴
A1: システム名 | K1: システム種別 | W1: =IF(表紙!W1="","",表紙!W1) -> 詳細設計書 | AP1: 作成者 | AT1: 作成日 | AY1: 更新者 | BC1: 更新日 | BH1: 版数
A2: =IF(表紙!A2="","",表紙!A2) -> POSサーバー | K2: =IF(表紙!K2="","",表紙!K2) -> POSサーバー | AP2: =IF(表紙!AP2="","",表紙!AP2) -> LoiLV | AT2: =IF(表紙!AT2="","",表紙!AT2) -> 45461 | AY2: =IF(表紙!AY2="","",表紙!AY2) -> TuyenNH | BC2: =IF(表紙!BC2="","",表紙!BC2) -> 45601 | BH2: =IF(表紙!BH2="","",表紙!BH2) -> 0.11
A4: 機能カテゴリ | H4: =IF(表紙!H4="","",表紙!H4) -> AP2102 | U4: 項目 | Z4: =IF(表紙!Z4="","",表紙!Z4) -> API設計書 | AP4: {=RIGHT(CELL("filename",$A$1),LEN(CELL("filename",$A$1))-FIND("]",CELL("filename",$A$1)))} -> 改訂履歴
B8: ■改訂履歴
B10: 更新日 | H10: 更新者 | O10: 版数 | S10: 更新内容 | AX10: 承認日 | BD10: 承認者
B11: 45461 | H11: LoiLV | O11: 0.1 | S11: 新規
B13: 45505 | H13: AnhDD | O13: 0.12 | S13: 更新
B15: 45566 | H15: DuNT | O15: 0.13 | S15: cash_register_codeマッピング更新
B17: 45580 | H17: TuyenNH | O17: 0.14 | S17: ・t_journalテーブルのDB構造を変更する。 ・金額での検索項目を削除する。 ・開始日から終了日までの期間で検索する。 ・複数の店舗を選択可能とする。
S18: シート：[AP2102]、[処理フロー]
B19: 45601 | H19: TuyenNH | O19: 0.11 | S19: 以下のフィールドを追加する。 IS_TRAINING_MODE（モード（トレーニング/本番）、PRCNAME: レシート区分 （取引・開設等)
S20: シート[AP2102]

Sheet 処理フロー凡例
A1: システム名 | K1: システム種別 | W1: =IF(表紙!W1="","",表紙!W1) -> 詳細設計書 | AP1: 作成者 | AT1: 作成日 | AY1: 更新者 | BC1: 更新日 | BH1: 版数
A2: =IF(表紙!A2="","",表紙!A2) -> POSサーバー | K2: =IF(表紙!K2="","",表紙!K2) -> POSサーバー | AP2: =IF(表紙!AP2="","",表紙!AP2) -> LoiLV | AT2: =IF(表紙!AT2="","",表紙!AT2) -> 45461 | AY2: =IF(表紙!AY2="","",表紙!AY2) -> TuyenNH | BC2: =IF(表紙!BC2="","",表紙!BC2) -> 45601 | BH2: =IF(表紙!BH2="","",表紙!BH2) -> 0.11
A4: 機能カテゴリ | H4: =IF(表紙!H4="","",表紙!H4) -> AP2102 | U4: 項目 | Z4: =IF(表紙!Z4="","",表紙!Z4) -> API設計書 | AP4: =MID(CELL("filename",A1),FIND("]",CELL("filename",A1))+1,255) -> 処理フロー凡例
B7: ●API処理フロー

Sheet AP2102
A1: システム名 | K1: システム種別 | W1: =IF(表紙!W1="","",表紙!W1) -> 詳細設計書 | AP1: 作成者 | AT1: 作成日 | AY1: 更新者 | BC1: 更新日 | BH1: 版数
A2: =IF(表紙!A2="","",表紙!A2) -> POSサーバー | K2: =IF(表紙!K2="","",表紙!K2) -> POSサーバー | AP2: =IF(表紙!AP2="","",表紙!AP2) -> LoiLV | AT2: =IF(表紙!AT2="","",表紙!AT2) -> 45461 | AY2: =IF(表紙!AY2="","",表紙!AY2) -> TuyenNH | BC2: =IF(表紙!BC2="","",表紙!BC2) -> 45601 | BH2: =IF(表紙!BH2="","",表紙!BH2) -> 0.11
A4: 機能カテゴリ | H4: =IF(表紙!H4="","",表紙!H4) -> AP2102 | U4: 項目 | Z4: =IF(表紙!Z4="","",表紙!Z4) -> API設計書 | AP4: =MID(CELL("filename",A1),FIND("]",CELL("filename",A1))+1,255) -> AP2102
B7: 1. 概要
C9: ジャーナル検索
B11: 2. リクエスト
C13: 2.1 Request URL
C15: No. | E15: URL | AG15: HTTPメソッド | AQ15: 備考
C16: 1 | E16: api/v1/journals | AG16: GET | AQ16: -
C18: 2. 2 Request Header
C20: No. | E20: ヘッダー | L20: 必須 | O20: 型 | S20: デフォルト値 | Z20: 項目説明 | AQ20: 備考
C21: 1 | E21: Authorization | L21: ○ | O21: String | S21: - | Z21: Api key | AQ21: 代表ユーザーを認証するAPIキー値 フォーマット："Bearer {api_key}"
C22: 2 | E22: Accept | L22: - | O22: String | S22: - | Z22: Accept | AQ22: サーバーが返却できるデータ種類情報を説明する。
C23: 3 | E23: Content-Type | L23: - | O23: String | S23: - | Z23: Content-Type | AQ23: 送信リクエストの本文情報のタイプを定義する。例: application/json, mutilpart/form-data. 転送データのタイプによって、content-typeが必須又は必須ではない。例： ・入力がjsonの場合、content-typeが必須であり、application/jsonの値を受け取る。
C26: 4 | E26: User-Agent | L26: - | O26: String | S26: - | Z26: User-Agent | AQ26: サーバーを呼び出すクライアントのアプリケーション/ソフトウェア/ブラウザを定義する。
C27: 5 | E27: Accept-Encoding | L27: - | O27: String | S27: - | Z27: Accept-Encoding | AQ27: データ暗号化アルゴリズムを定義する。サーバーから受信したデータに使用できる： zip、gzip、png、gif等
C30: 2.3 Query Parameter/ path parameter
D32: NA
C34: 2.4 Request Body
C36: No. | E36: パラメータ | L36: 必須 | O36: 型 | S36: デフォルト値 | Z36: 項目説明 | AQ36: 備考
C37: 1 | E37: selected_stores | L37: ○ | O37: Array | S37: - | Z37: 店舗コード | AQ37: 1つ又は複数の店舗がある
C38: 2 | E38: business_date_from | L38: ○ | O38: date | S38: - | Z38: 開始営業日 | AQ38: 形式：yyyy/MM/dd 入力なしのバリデーションチェック: エラーメッセージ：MSG_VAL_001 日付の形式が正しくないことのバリデーションチェック（エラーメッセージ：MSG_VAL_016。その中、{0} が「business_date_from」である。） 未来日のバリデーションチェック（エラーメッセージ：MSG_VAL_049）
C39: 3 | E39: business_date_to | L39: ○ | O39: date | S39: - | Z39: 終了営業日 | AQ39: 形式：yyyy/MM/dd 入力なしのバリデーションチェック：エラーメッセージ：MSG_VAL_001。その中、{0}が「business_date_to」である。 ・バリデーションチェック: 不正な形式の日付、未来日（エラーメッセージ：MSG_VAL_016。その中、{0}が 「business_date_to」である。） 未来日のバリデーションチェック（エラーメッセージ：MSG_VAL_049） バリデーションチェック：business_date_from>business_date_to。エラーメッセージ：MSG_VAL_004。その中、{0}が「business_date_from」であり、{1}が「business_date_to」である。
C40: 4 | E40: business_time_from | L40: ○ | O40: time | S40: - | Z40: 開始時間 | AQ40: 形式: HH:mm 入力なしのバリデーションチェック: エラーメッセージ：MSG_VAL_001 バリデーションチェック：不正な形式の時間（エラーメッセージ：MSG_VAL_016。その中、{0}が「business_time_from」である。
C41: 5 | E41: business_time_to | L41: ○ | O41: time | S41: - | Z41: 終了時間 | AQ41: 形式: HH:mm 入力なしのバリデーションチェック：エラーメッセージ：MSG_VAL_001。その中、{0}が「business_time_to」である。 バリデーションチェック：不正な形式の時間（エラーメッセージ：MSG_VAL_003。その中、{0}が「business_time_to」である。） バリデーションチェック：business_time_from>business_time_to（エラーメッセージ：MSG_VAL_004.その中、{0}：business_time_from、{1}：business_time_to）
C42: 6 | E42: cash_register_code | L42: - | O42: string | S42: - | Z42: レジ種別コード | AQ42: -
C43: 7 | E43: employee_code | L43: - | O43: string | S43: - | Z43: 担当者番号 | AQ43: -
C44: 8 | E44: receipt_no_from | L44: - | O44: int | S44: - | Z44: 開始レシートNo. | AQ44: -
C45: 9 | E45: receipt_no_to | L45: - | O45: int | S45: - | Z45: 終了レシートNo. | AQ45: バリデーションチェック：receipt_no_from > receipt_no_to。エラーメッセージ：MSG_VAL_004。リクエストにreceipt_no_fromとreceipt_no_toがある場合、{0}が「receipt_no_from」であり、{1}が「receipt_no_to」である。
C46: 10 | E46: keyword_1 | L46: - | O46: string | S46: - | Z46: 任意文字列 | AQ46: 入力された文字を含む値をジャーナルデータで検索する。
C47: 11 | E47: keyword_2 | L47: - | O47: string | S47: - | Z47: 任意文字列 | AQ47: 入力された文字を含む値をジャーナルデータで検索する。
C48: 12 | E48: condition_type | L48: ○ | O48: smallint | S48: - | Z48: keyword_1、keyword_2の検索条件組み合わせタイプ | AQ48: ・値： 0: Or 1: And
C49: 13 | E49: amount_money | L49: - | O49: string | S49: - | Z49: 金額 | AQ49: 入力された金額を含む値をジャーナルデータで検索する。 入力値は数字のみ可能 入力値が数字ではない場合、MSG_VAL_019を表示する。
B52: 3. レスポンス
C54: 3.1. 正常の場合のレスポンスフォーマット
C56: No. | E56: JSON name | L56: 型 | S56: 項目説明 | AC56: 備考
C57: 1 | E57: status_code | L57: Integer | S57: - | AC57: 返されたステータスコード
C58: =C57+1 -> 2 | E58: total_count | L58: int | S58: 検索できた総件数 | AC58: -
C59: =C58+1 -> 3 | E59: items | L59: List<Object> | S59: ジャーナル一覧 | AC59: 以下の順番に並べ替える。 cash_register_code -> transaction_date -> receipt no -> journal no
C60: =C59+1 -> 4 | E60: record_id | L60: bigint | S60: T_JOURNAL.RECORD_ID | AC60: -
...

Sheet 処理フロー
A1: システム名 | K1: システム種別 | W1: =IF(表紙!W1="","",表紙!W1) -> 詳細設計書 | AP1: 作成者 | AT1: 作成日 | AY1: 更新者 | BC1: 更新日 | BH1: 版数
A2: =IF(表紙!A2="","",表紙!A2) -> POSサーバー | K2: =IF(表紙!K2="","",表紙!K2) -> POSサーバー | AP2: =IF(表紙!AP2="","",表紙!AP2) -> LoiLV | AT2: =IF(表紙!AT2="","",表紙!AT2) -> 45461 | AY2: =IF(表紙!AY2="","",表紙!AY2) -> TuyenNH | BC2: =IF(表紙!BC2="","",表紙!BC2) -> 45601 | BH2: =IF(表紙!BH2="","",表紙!BH2) -> 0.11
A4: 機能カテゴリ | H4: =IF(表紙!H4="","",表紙!H4) -> AP2102 | U4: 項目 | Z4: =IF(表紙!Z4="","",表紙!Z4) -> API設計書 | AP4: =MID(CELL("filename",A1),FIND("]",CELL("filename",A1))+1,255) -> 処理フロー

Sheet テンプレート
A1: システム名 | K1: システム種別 | W1: =IF(表紙!W1="","",表紙!W1) -> 詳細設計書 | AP1: 作成者 | AT1: 作成日 | AY1: 更新者 | BC1: 更新日 | BH1: 版数
A2: =IF(表紙!A2="","",表紙!A2) -> POSサーバー | K2: =IF(表紙!K2="","",表紙!K2) -> POSサーバー | AP2: =IF(表紙!AP2="","",表紙!AP2) -> LoiLV | AT2: =IF(表紙!AT2="","",表紙!AT2) -> 45461 | AY2: =IF(表紙!AY2="","",表紙!AY2) -> TuyenNH | BC2: =IF(表紙!BC2="","",表紙!BC2) -> 45601 | BH2: =IF(表紙!BH2="","",表紙!BH2) -> 0.11
A4: 機能カテゴリ | H4: =IF(表紙!H4="","",表紙!H4) -> AP2102 | U4: 項目 | Z4: =IF(表紙!Z4="","",表紙!Z4) -> API設計書 | AP4: =MID(CELL("filename",A1),FIND("]",CELL("filename",A1))+1,255) -> テンプレート
