Workbook

Sheet 表紙
A1: システム名 | K1: システム種別 | W1: 詳細設計書 | AP1: 作成者 | AT1: 作成日 | AY1: 更新者 | BC1: 更新日 | BH1: 版数
A2: POSサーバー | K2: POSサーバ | AP2: =改訂履歴!$H$11 -> TuyenNH | AT2: =改訂履歴!$B$11 -> 45516 | AY2: =LOOKUP(2,1/(改訂履歴!H11:H30000<>""),改訂履歴!H11:H30000) -> TuyenNH | BC2: =LOOKUP(2,1/(改訂履歴!B11:B30000<>""),改訂履歴!B11:B30000) -> 45516 | BH2: =LOOKUP(2,1/(改訂履歴!O11:O30000<>""),改訂履歴!O11:O30000) -> 0.1
A4: 機能カテゴリ | H4: AP0201 | U4: 項目 | Z4: API設計書 | AP4: {=RIGHT(CELL("filename",$A$1),LEN(CELL("filename",$A$1))-FIND("]",CELL("filename",$A$1)))} -> 表紙
L16: POSサーバーの詳細設計書
L24: =K2&"/"&H4&"/"&Z4 -> POSサーバ/AP0201/API設計書
Q44: 承認日 | AA44: 承認者 | AQ44: 版数

Sheet 改訂履歴
A1: システム名 | K1: システム種別 | W1: =IF(表紙!W1="","",表紙!W1) -> 詳細設計書 | AP1: 作成者 | AT1: 作成日 | AY1: 更新者 | BC1: 更新日 | BH1: 版数
A2: =IF(表紙!A2="","",表紙!A2) -> POSサーバー | K2: =IF(表紙!K2="","",表紙!K2) -> POSサーバ | AP2: =IF(表紙!AP2="","",表紙!AP2) -> TuyenNH | AT2: =IF(表紙!AT2="","",表紙!AT2) -> 45516 | AY2: =IF(表紙!AY2="","",表紙!AY2) -> TuyenNH | BC2: =IF(表紙!BC2="","",表紙!BC2) -> 45516 | BH2: =IF(表紙!BH2="","",表紙!BH2) -> 0.1
A4: 機能カテゴリー | H4: =IF(表紙!H4="","",表紙!H4) -> AP0201 | U4: 項目 | Z4: =IF(表紙!Z4="","",表紙!Z4) -> API設計書 | AP4: {=RIGHT(CELL("filename",$A$1),LEN(CELL("filename",$A$1))-FIND("]",CELL("filename",$A$1)))} -> 改訂履歴
B8: ■改訂履歴
B10: 更新日 | H10: 更新者 | O10: 版数 | S10: 更新内容 | AX10: 承認日 | BD10: 承認者
B11: 45516 | H11: TuyenNH | O11: 0.1 | S11: 新規

Sheet 処理フロー凡例
A1: システム名 | K1: システム種別 | W1: =IF(表紙!W1="","",表紙!W1) -> 詳細設計書 | AP1: 作成者 | AT1: 作成日 | AY1: 更新者 | BC1: 更新日 | BH1: 版数
A2: =IF(表紙!A2="","",表紙!A2) -> POSサーバー | K2: =IF(表紙!K2="","",表紙!K2) -> POSサーバ | AP2: =IF(表紙!AP2="","",表紙!AP2) -> TuyenNH | AT2: =IF(表紙!AT2="","",表紙!AT2) -> 45516 | AY2: =IF(表紙!AY2="","",表紙!AY2) -> TuyenNH | BC2: =IF(表紙!BC2="","",表紙!BC2) -> 45516 | BH2: =IF(表紙!BH2="","",表紙!BH2) -> 0.1
A4: 機能カテゴリ | H4: =IF(表紙!H4="","",表紙!H4) -> AP0201 | U4: 項目 | Z4: =IF(表紙!Z4="","",表紙!Z4) -> API設計書 | AP4: =MID(CELL("filename",A1),FIND("]",CELL("filename",A1))+1,255) -> 処理フロー凡例
B7: ●API処理フロー

Sheet AP0201
A1: システム名 | K1: システム種別 | W1: =IF(表紙!W1="","",表紙!W1) -> 詳細設計書 | AP1: 作成者 | AT1: 作成日 | AY1: 更新者 | BC1: 更新日 | BH1: 版数
A2: =IF(表紙!A2="","",表紙!A2) -> POSサーバー | K2: =IF(表紙!K2="","",表紙!K2) -> POSサーバ | AP2: =IF(表紙!AP2="","",表紙!AP2) -> TuyenNH | AT2: =IF(表紙!AT2="","",表紙!AT2) -> 45516 | AY2: =IF(表紙!AY2="","",表紙!AY2) -> TuyenNH | BC2: =IF(表紙!BC2="","",表紙!BC2) -> 45516 | BH2: =IF(表紙!BH2="","",表紙!BH2) -> 0.1
A4: 機能カテゴリ | H4: =IF(表紙!H4="","",表紙!H4) -> AP0201 | U4: 項目 | Z4: =IF(表紙!Z4="","",表紙!Z4) -> API設計書 | AP4: =MID(CELL("filename",A1),FIND("]",CELL("filename",A1))+1,255) -> AP0201
B7: 1. 概要
C9: 商品の緊急売価一覧を取得する。
B11: 2. リクエスト
C13: 2.1 Request URL
C15: No. | E15: URL | AG15: HTTPメソッド | AQ15: 備考
C16: 1 | E16: api/v1/force-price/list | AG16: POST | AQ16: -
C18: 2. 2 Request Header
C20: No. | E20: ヘッダー | L20: 必須 | O20: 型 | S20: デフォルト値 | Z20: 項目説明 | AQ20: 備考
C21: 1 | E21: Authorization | L21: ○ | O21: String | S21: - | Z21: Api key | AQ21: 代表ユーザーを認証するAPIキー値 フォーマット："Bearer {api_key}"
C23: 2 | E23: Accept | L23: - | O23: String | S23: - | Z23: Accept | AQ23: サーバーが返却できるデータ種類情報を説明する。
C24: 3 | E24: Content-Type | L24: ○ | O24: String | S24: application/json | Z24: Content-Type | AQ24: 送信リクエストの本文情報のタイプを定義する。例: application/json, mutilpart/form-data. 転送データのタイプによって、content-typeが必須又は必須ではない。例： ・入力がjsonの場合、content-typeが必須であり、application/jsonの値を受け取る。
C31: 4 | E31: User-Agent | L31: - | O31: String | S31: - | Z31: User-Agent | AQ31: サーバーを呼び出すクライアントのアプリケーション/ソフトウェア/ブラウザを定義する。
C32: 5 | E32: Accept-Encoding | L32: - | O32: String | S32: - | Z32: Accept-Encoding | AQ32: データ暗号化アルゴリズムを定義する。サーバーから受信したデータに使用できる： zip、gzip、png、gif等
C34: 2.3 Query Parameter/ path parameter
C36: No. | E36: パラメータ | L36: 必須 | O36: 型 | S36: デフォルト値 | Z36: 項目説明 | AQ36: 備考
C37: 1 | E37: selected_store | L37: ○ | O37: String | S37: - | Z37: 対象店舗コード | AQ37: 店舗コード
C38: 2 | E38: booking_date | L38: ○ | O38: String | S38: - | Z38: 緊急売価の予約日付 | AQ38: ・過去日のバリデーションチェック（メッセージ = MSG_VAL_037） ・バリデーションチェック：不正な日付の形式（メッセージ = MSG_VAL_003）
C39: 3 | E39: md_hierachy_code_level1 | L39: - | O39: String | S39: - | Z39: 部門コード | AQ39: ・バリデーションチェック：2桁未満の場合、 エラーメッセージ = MSG_VAL_002
C40: 4 | E40: page_number | L40: - | O40: Integer | S40: 1 | Z40: 現在ページ | AQ40: -
C41: 5 | E41: limit | L41: - | O41: Integer | S41: - | Z41: 1ページあたりの件数 | AQ41: 1ページあたりの件数：14
C43: 2.4 Request Body
C45: No. | E45: パラメータ | L45: 必須 | O45: 型 | S45: デフォルト値 | Z45: 項目説明 | AQ45: 備考
C46: N/A
C48: ※サンプル
C50: {
C51: "selected_store": "09176",
C52: "booking_date": "2024/08/12",
C53: "md_hierachy_code_level1": "07",
C54: "page_number": 1,
C55: "limit": 18
C56: }
B58: 3. レスポンス
C60: 3.1. 正常の場合のレスポンスフォーマット
C62: No. | E62: JSON name | O62: 型 | S62: 項目説明 | AC62: 備考
C63: 1 | E63: status_code | O63: Smallint | S63: - | AC63: 返されたステータスコード
C64: =C63+1 -> 2 | E64: total_item | O64: Int | S64: - | AC64: 総件数
C65: =C64+1 -> 3 | E65: total_page | O65: Int | S65: - | AC65: 総頁数
...

Sheet 処理フロー
A1: システム名 | K1: システム種別 | W1: =IF(表紙!W1="","",表紙!W1) -> 詳細設計書 | AP1: 作成者 | AT1: 作成日 | AY1: 更新者 | BC1: 更新日 | BH1: 版数
A2: =IF(表紙!A2="","",表紙!A2) -> POSサーバー | K2: =IF(表紙!K2="","",表紙!K2) -> POSサーバ | AP2: =IF(表紙!AP2="","",表紙!AP2) -> TuyenNH | AT2: =IF(表紙!AT2="","",表紙!AT2) -> 45516 | AY2: =IF(表紙!AY2="","",表紙!AY2) -> TuyenNH | BC2: =IF(表紙!BC2="","",表紙!BC2) -> 45516 | BH2: =IF(表紙!BH2="","",表紙!BH2) -> 0.1
A4: 機能カテゴリ | H4: =IF(表紙!H4="","",表紙!H4) -> AP0201 | U4: 項目 | Z4: =IF(表紙!Z4="","",表紙!Z4) -> API設計書 | AP4: =MID(CELL("filename",A1),FIND("]",CELL("filename",A1))+1,255) -> 処理フロー

Sheet テンプレート
A1: システム名 | K1: システム種別 | W1: =IF(表紙!W1="","",表紙!W1) -> 詳細設計書 | AP1: 作成者 | AT1: 作成日 | AY1: 更新者 | BC1: 更新日 | BH1: 版数
A2: =IF(表紙!A2="","",表紙!A2) -> POSサーバー | K2: =IF(表紙!K2="","",表紙!K2) -> POSサーバ | AP2: =IF(表紙!AP2="","",表紙!AP2) -> TuyenNH | AT2: =IF(表紙!AT2="","",表紙!AT2) -> 45516 | AY2: =IF(表紙!AY2="","",表紙!AY2) -> TuyenNH | BC2: =IF(表紙!BC2="","",表紙!BC2) -> 45516 | BH2: =IF(表紙!BH2="","",表紙!BH2) -> 0.1
A4: 機能カテゴリ | H4: =IF(表紙!H4="","",表紙!H4) -> AP0201 | U4: 項目 | Z4: =IF(表紙!Z4="","",表紙!Z4) -> API設計書 | AP4: =MID(CELL("filename",A1),FIND("]",CELL("filename",A1))+1,255) -> テンプレート
