Workbook

Sheet 表紙
A1: システム名 | K1: システム種別 | W1: 詳細設計書 | AP1: 作成者 | AT1: 作成日 | AY1: 更新者 | BC1: 更新日 | BH1: 版数
A2: POSサーバー | K2: POSサーバー | AP2: =改訂履歴!$H$11 -> AnhDD | AT2: =改訂履歴!$B$11 -> 45467 | AY2: =LOOKUP(2,1/(改訂履歴!H11:H30000<>""),改訂履歴!H11:H30000) -> AnhDD | BC2: =LOOKUP(2,1/(改訂履歴!B11:B30000<>""),改訂履歴!B11:B30000) -> 45467 | BH2: =LOOKUP(2,1/(改訂履歴!O11:O30000<>""),改訂履歴!O11:O30000) -> 0.1
A4: 機能カテゴリ | H4: AP6601 | U4: 項目 | Z4: API設計書 | AP4: {=RIGHT(CELL("filename",$A$1),LEN(CELL("filename",$A$1))-FIND("]",CELL("filename",$A$1)))} -> 表紙
L16: POSサーバーの詳細設計書
L24: =K2&"/"&H4&"/"&Z4 -> POSサーバー/AP6601/API設計書
Q44: 承認日 | AA44: 承認者 | AQ44: 版数

Sheet 改訂履歴
A1: システム名 | K1: システム種別 | W1: =IF(表紙!W1="","",表紙!W1) -> 詳細設計書 | AP1: 作成者 | AT1: 作成日 | AY1: 更新者 | BC1: 更新日 | BH1: 版数
A2: =IF(表紙!A2="","",表紙!A2) -> POSサーバー | K2: =IF(表紙!K2="","",表紙!K2) -> POSサーバー | AP2: =IF(表紙!AP2="","",表紙!AP2) -> AnhDD | AT2: =IF(表紙!AT2="","",表紙!AT2) -> 45467 | AY2: =IF(表紙!AY2="","",表紙!AY2) -> AnhDD | BC2: =IF(表紙!BC2="","",表紙!BC2) -> 45467 | BH2: =IF(表紙!BH2="","",表紙!BH2) -> 0.1
A4: 機能カテゴリー | H4: =IF(表紙!H4="","",表紙!H4) -> AP6601 | U4: 項目 | Z4: =IF(表紙!Z4="","",表紙!Z4) -> API設計書 | AP4: {=RIGHT(CELL("filename",$A$1),LEN(CELL("filename",$A$1))-FIND("]",CELL("filename",$A$1)))} -> 改訂履歴
B8: ■改訂履歴
B10: 更新日 | H10: 更新者 | O10: 版数 | S10: 更新内容 | AX10: 承認日 | BD10: 承認者
B11: 45467 | H11: AnhDD | O11: 0.1 | S11: 新規作成

Sheet 処理フロー凡例
A1: システム名 | K1: システム種別 | W1: =IF(表紙!W1="","",表紙!W1) -> 詳細設計書 | AP1: 作成者 | AT1: 作成日 | AY1: 更新者 | BC1: 更新日 | BH1: 版数
A2: =IF(表紙!A2="","",表紙!A2) -> POSサーバー | K2: =IF(表紙!K2="","",表紙!K2) -> POSサーバー | AP2: =IF(表紙!AP2="","",表紙!AP2) -> AnhDD | AT2: =IF(表紙!AT2="","",表紙!AT2) -> 45467 | AY2: =IF(表紙!AY2="","",表紙!AY2) -> AnhDD | BC2: =IF(表紙!BC2="","",表紙!BC2) -> 45467 | BH2: =IF(表紙!BH2="","",表紙!BH2) -> 0.1
A4: 機能カテゴリ | H4: =IF(表紙!H4="","",表紙!H4) -> AP6601 | U4: 項目 | Z4: =IF(表紙!Z4="","",表紙!Z4) -> API設計書 | AP4: =MID(CELL("filename",A1),FIND("]",CELL("filename",A1))+1,255) -> 処理フロー凡例
B7: ●API処理フロー

Sheet AP6601
A1: システム名 | K1: システム種別 | W1: =IF(表紙!W1="","",表紙!W1) -> 詳細設計書 | AP1: 作成者 | AT1: 作成日 | AY1: 更新者 | BC1: 更新日 | BH1: 版数
A2: =IF(表紙!A2="","",表紙!A2) -> POSサーバー | K2: =IF(表紙!K2="","",表紙!K2) -> POSサーバー | AP2: =IF(表紙!AP2="","",表紙!AP2) -> AnhDD | AT2: =IF(表紙!AT2="","",表紙!AT2) -> 45467 | AY2: =IF(表紙!AY2="","",表紙!AY2) -> AnhDD | BC2: =IF(表紙!BC2="","",表紙!BC2) -> 45467 | BH2: =IF(表紙!BH2="","",表紙!BH2) -> 0.1
A4: 機能カテゴリ | H4: =IF(表紙!H4="","",表紙!H4) -> AP6601 | U4: 項目 | Z4: =IF(表紙!Z4="","",表紙!Z4) -> API設計書 | AP4: =MID(CELL("filename",A1),FIND("]",CELL("filename",A1))+1,255) -> AP6601
B7: 1. 概要
C8: APIが券一覧を取得する。
C9: 種類：支払券、値引券
C11: 注意：NA
B13: 2. リクエスト
C15: 2.1 Request URL
C17: No. | E17: URL | AG17: HTTPメソッド | AQ17: 備考
C18: 1 | E18: api/v1/ticket/list_ticket | AG18: POST | AQ18: -
C20: 2. 2 Request Header
C22: No. | E22: ヘッダー | L22: 必須 | O22: 型 | S22: デフォルト値 | Z22: 項目説明 | AQ22: 備考
C23: 1 | E23: Authorization | L23: ○ | O23: String | S23: - | Z23: Api key | AQ23: 代表ユーザーを認証するAPIキー値 フォーマット: "Bearer {api_key}"
C24: 2 | E24: Accept | L24: - | O24: String | S24: - | Z24: Accept | AQ24: サーバーが返却できるデータ種類情報を説明する。
C25: 3 | E25: Content-Type | L25: - | O25: String | S25: - | Z25: Content-Type | AQ25: 送信リクエストの本文情報のタイプを定義する。例: application/json, mutilpart/form-data. 転送データのタイプによって、content-typeが必須又は必須ではない。例： ・入力がjsonの場合、content-typeが必須であり、application/jsonの値を受け取る。
C28: 4 | E28: User-Agent | L28: - | O28: String | S28: - | Z28: User-Agent | AQ28: サーバーを呼び出すクライアントのアプリケーション/ソフトウェア/ブラウザを定義する。
C29: 5 | E29: Accept-Encoding | L29: - | O29: String | S29: - | Z29: Accept-Encoding | AQ29: データ暗号化アルゴリズムを定義する。サーバーから受信したデータに使用できる： zip、gzip、png、gif等
C32: 2.3 Query Parameter/ path parameter
C34: No. | E34: パラメータ | L34: 必須 | O34: 型 | S34: デフォルト値 | Z34: 項目説明 | AQ34: 備考
C35: 1 | E35: keyword | L35: - | O35: String | Z35: 支払券名称で検索に使用される値
C36: =C35+1 -> 2 | E36: search_type | L36: - | O36: Integer | Z36: 支払券名称の検索タイプ | AQ36: ・値： + 1: を含む + 2: から始まる + 3: で終わる キーワード値がある場合、search_type が渡されないと、デフォルトは 「1」である。
C37: 3 | E37: type | L37: ○ | O37: Integer | S37: 1 | Z37: 検索対象 | AQ37: 値： + 0: 券 + 1: 支払券 + 2: 値引券
C38: =C37+1 -> 4 | E38: page | L38: ○ | O38: Integer | S38: 1 | Z38: 現在ページ
C39: 5 | E39: limit | L39: ○ | O39: Integer | S39: 1000 | Z39: 1ページの件数の制限
C41: 2.4 Request Body
C42: NA
C43: No. | E43: パラメータ | L43: 必須 | O43: 型 | S43: デフォルト値 | Z43: 項目説明 | AQ43: 備考
C44: 1 | E44: slected_stores | L44: ○ | O44: Array | S44: - | Z44: 店舗コード | AQ44: 1つ又は複数の店舗がある
B46: 3. レスポンス
C48: 3.1. 正常の場合のレスポンスフォーマット
C50: No. | E50: JSON name | L50: 型 | S50: 項目説明 | AC50: 備考
C51: 1 | E51: status_code | L51: Integer | S51: - | AC51: 返されたステータスコード
C52: =C51+1 -> 2 | E52: total_count | L52: Integer | S52: - | AC52: 総件数
C53: 2 | E53: tickets | L53: Array<Object>
C54: =C53+1 -> 3 | E54: record_id | L54: Bigint | S54: TicketMaster.RECORD_ID
C55: 3 | E55: company_code | L55: String | S55: TicketMaster.CompanyCode | AC55: 企業コード：Kasumi =100, Inageya=800
C56: =C55+1 -> 4 | E56: store_code | L56: String | S56: TicketMaster.StoreCode | AC56: 店舗コード
C57: 4 | E57: store_name | L57: String | S57: StoreMaster.Name | AC57: 店舗名称
C58: =C57+1 -> 5 | E58: code | L58: String | S58: TicketMaster.Code | AC58: 券コード
...

Sheet 処理フロー
A1: システム名 | K1: システム種別 | W1: =IF(表紙!W1="","",表紙!W1) -> 詳細設計書 | AP1: 作成者 | AT1: 作成日 | AY1: 更新者 | BC1: 更新日 | BH1: 版数
A2: =IF(表紙!A2="","",表紙!A2) -> POSサーバー | K2: =IF(表紙!K2="","",表紙!K2) -> POSサーバー | AP2: =IF(表紙!AP2="","",表紙!AP2) -> AnhDD | AT2: =IF(表紙!AT2="","",表紙!AT2) -> 45467 | AY2: =IF(表紙!AY2="","",表紙!AY2) -> AnhDD | BC2: =IF(表紙!BC2="","",表紙!BC2) -> 45467 | BH2: =IF(表紙!BH2="","",表紙!BH2) -> 0.1
A4: 機能カテゴリ | H4: =IF(表紙!H4="","",表紙!H4) -> AP6601 | U4: 項目 | Z4: =IF(表紙!Z4="","",表紙!Z4) -> API設計書 | AP4: =MID(CELL("filename",A1),FIND("]",CELL("filename",A1))+1,255) -> 処理フロー
B7: 処理フロー

Sheet テンプレート
A1: システム名 | K1: システム種別 | W1: =IF(表紙!W1="","",表紙!W1) -> 詳細設計書 | AP1: 作成者 | AT1: 作成日 | AY1: 更新者 | BC1: 更新日 | BH1: 版数
A2: =IF(表紙!A2="","",表紙!A2) -> POSサーバー | K2: =IF(表紙!K2="","",表紙!K2) -> POSサーバー | AP2: =IF(表紙!AP2="","",表紙!AP2) -> AnhDD | AT2: =IF(表紙!AT2="","",表紙!AT2) -> 45467 | AY2: =IF(表紙!AY2="","",表紙!AY2) -> AnhDD | BC2: =IF(表紙!BC2="","",表紙!BC2) -> 45467 | BH2: =IF(表紙!BH2="","",表紙!BH2) -> 0.1
A4: 機能カテゴリ | H4: =IF(表紙!H4="","",表紙!H4) -> AP6601 | U4: 項目 | Z4: =IF(表紙!Z4="","",表紙!Z4) -> API設計書 | AP4: =MID(CELL("filename",A1),FIND("]",CELL("filename",A1))+1,255) -> テンプレート
