Workbook

Sheet 表紙
A1: システム名 | K1: システム種別 | W1: 詳細設計書 | AP1: 作成者 | AT1: 作成日 | AY1: 更新者 | BC1: 更新日 | BH1: 版数
A2: POSサーバー | K2: POSサーバー | AP2: =改訂履歴!$H$11 -> LoiLV | AT2: =改訂履歴!$B$11 -> 45469 | AY2: =LOOKUP(2,1/(改訂履歴!H11:H30000<>""),改訂履歴!H11:H30000) -> LoiLV | BC2: =LOOKUP(2,1/(改訂履歴!B11:B30000<>""),改訂履歴!B11:B30000) -> 45469 | BH2: =LOOKUP(2,1/(改訂履歴!O11:O30000<>""),改訂履歴!O11:O30000) -> 0.1
A4: 機能カテゴリ | H4: AP6603 | U4: 項目 | Z4: API設計書 | AP4: {=RIGHT(CELL("filename",$A$1),LEN(CELL("filename",$A$1))-FIND("]",CELL("filename",$A$1)))} -> 表紙
L16: POSサーバーの詳細設計書
L24: =K2&"/"&H4&"/"&Z4 -> POSサーバー/AP6603/API設計書
Q44: 承認日 | AA44: 承認者 | AQ44: 版数

Sheet 改訂履歴
A1: システム名 | K1: システム種別 | W1: =IF(表紙!W1="","",表紙!W1) -> 詳細設計書 | AP1: 作成者 | AT1: 作成日 | AY1: 更新者 | BC1: 更新日 | BH1: 版数
A2: =IF(表紙!A2="","",表紙!A2) -> POSサーバー | K2: =IF(表紙!K2="","",表紙!K2) -> POSサーバー | AP2: =IF(表紙!AP2="","",表紙!AP2) -> LoiLV | AT2: =IF(表紙!AT2="","",表紙!AT2) -> 45469 | AY2: =IF(表紙!AY2="","",表紙!AY2) -> LoiLV | BC2: =IF(表紙!BC2="","",表紙!BC2) -> 45469 | BH2: =IF(表紙!BH2="","",表紙!BH2) -> 0.1
A4: 機能カテゴリー | H4: =IF(表紙!H4="","",表紙!H4) -> AP6603 | U4: 項目 | Z4: =IF(表紙!Z4="","",表紙!Z4) -> API設計書 | AP4: {=RIGHT(CELL("filename",$A$1),LEN(CELL("filename",$A$1))-FIND("]",CELL("filename",$A$1)))} -> 改訂履歴
B8: ■改訂履歴
B10: 更新日 | H10: 更新者 | O10: 版数 | S10: 更新内容 | AX10: 承認日 | BD10: 承認者
B11: 45469 | H11: LoiLV | O11: 0.1 | S11: 新規作成

Sheet 処理フロー凡例
A1: システム名 | K1: システム種別 | W1: =IF(表紙!W1="","",表紙!W1) -> 詳細設計書 | AP1: 作成者 | AT1: 作成日 | AY1: 更新者 | BC1: 更新日 | BH1: 版数
A2: =IF(表紙!A2="","",表紙!A2) -> POSサーバー | K2: =IF(表紙!K2="","",表紙!K2) -> POSサーバー | AP2: =IF(表紙!AP2="","",表紙!AP2) -> LoiLV | AT2: =IF(表紙!AT2="","",表紙!AT2) -> 45469 | AY2: =IF(表紙!AY2="","",表紙!AY2) -> LoiLV | BC2: =IF(表紙!BC2="","",表紙!BC2) -> 45469 | BH2: =IF(表紙!BH2="","",表紙!BH2) -> 0.1
A4: 機能カテゴリ | H4: =IF(表紙!H4="","",表紙!H4) -> AP6603 | U4: 項目 | Z4: =IF(表紙!Z4="","",表紙!Z4) -> API設計書 | AP4: =MID(CELL("filename",A1),FIND("]",CELL("filename",A1))+1,255) -> 処理フロー凡例
B7: ●API処理フロー

Sheet AP6603
A1: システム名 | K1: システム種別 | W1: =IF(表紙!W1="","",表紙!W1) -> 詳細設計書 | AP1: 作成者 | AT1: 作成日 | AY1: 更新者 | BC1: 更新日 | BH1: 版数
A2: =IF(表紙!A2="","",表紙!A2) -> POSサーバー | K2: =IF(表紙!K2="","",表紙!K2) -> POSサーバー | AP2: =IF(表紙!AP2="","",表紙!AP2) -> LoiLV | AT2: =IF(表紙!AT2="","",表紙!AT2) -> 45469 | AY2: =IF(表紙!AY2="","",表紙!AY2) -> LoiLV | BC2: =IF(表紙!BC2="","",表紙!BC2) -> 45469 | BH2: =IF(表紙!BH2="","",表紙!BH2) -> 0.1
A4: 機能カテゴリ | H4: =IF(表紙!H4="","",表紙!H4) -> AP6603 | U4: 項目 | Z4: =IF(表紙!Z4="","",表紙!Z4) -> API設計書 | AP4: =MID(CELL("filename",A1),FIND("]",CELL("filename",A1))+1,255) -> AP6603
B7: 1. 概要
C9: 券マスタを新規作成、編集、削除する。
B11: 2. リクエスト
C13: 2.1 Request URL
C15: No. | E15: URL | AG15: HTTPメソッド | AQ15: 備考
C16: 1 | E16: api/v1/ticket/maintenance_ticket | AG16: POST | AQ16: -
C18: 2. 2 Request Header
C20: No. | E20: ヘッダー | L20: 必須 | O20: 型 | S20: デフォルト値 | Z20: 項目説明 | AQ20: 備考
C21: 1 | E21: Authorization | L21: ○ | O21: String | S21: - | Z21: Api key | AQ21: 代表ユーザーを認証するAPIキー値 フォーマット: "Bearer {api_key}"
C23: 2 | E23: Accept | L23: - | O23: String | S23: - | Z23: Accept | AQ23: サーバーが返却できるデータ種類情報を説明する。
C24: 3 | E24: Content-Type | L24: ○ | O24: String | S24: - | Z24: Content-Type | AQ24: 送信リクエストの本文情報のタイプを定義する。例: application/json, mutilpart/form-data. 転送データのタイプによって、content-typeが必須又は必須ではない。例： ・入力がjsonの場合、content-typeが必須であり、application/jsonの値を受け取る。
C31: 4 | E31: User-Agent | L31: - | O31: String | S31: - | Z31: User-Agent | AQ31: サーバーを呼び出すクライアントのアプリケーション/ソフトウェア/ブラウザを定義する。
C32: 5 | E32: Accept-Encoding | L32: - | O32: String | S32: - | Z32: Accept-Encoding | AQ32: データ暗号化アルゴリズムを定義する。サーバーから受信したデータに使用できる： zip、gzip、png、gif等
C35: 2.3 Query Parameter/ path parameter
C37: No. | E37: パラメータ | L37: 必須 | O37: 型 | S37: デフォルト値 | Z37: 項目説明 | AQ37: 備考
C38: なし
C40: 2.4 Request Body
C42: No. | E42: パラメータ | L42: 必須 | O42: 型 | S42: デフォルト値 | Z42: 項目説明 | AQ42: 備考
C43: 1 | E43: type | L43: ○ | O43: Smallint | S43: - | Z43: 券種類: 1 - 支払券、2 - 値引券 | AQ43: typeなし、1->2の範囲以外のバリデーションチェック： 表示エラーメッセージ： MSG_VAL_019（{0}：type） +type = 1の場合、支払券にはデータありが必須で、値引券 = null + type = 2の場合、値引券にはデータありが必須で、支払券 = null
C44: 2 | E44: payment_tickets | L44: - | O44: List<Object> | S44: - | Z44: master_ticketオブジェクトから継承オブジェクト | AQ44: 支払券データ一覧
C45: 3 | E45: record_id | L45: - | O45: Bigint | S45: - | Z45: TicketMaster.RECORD_ID | AQ45: ・新規作成の場合、record_idをnullとして渡す。 ・編集、削除の場合、該当するrecord_idを渡す。
C46: 4 | E46: store_code | L46: ○ | O46: String | S46: - | Z46: TicketMaster.StoreCode | AQ46: ・メッセージ = MSG_VAL_001で入力必須のバリデーションチェック。その中 ：{0}がstore_codeである。
C47: 5 | E47: code | L47: ○ | O47: String | S47: - | Z47: TicketMaster.Code | AQ47: ・メッセージ = MSG_VAL_001で入力必須のバリデーションチェック。その中 ：{0}がcodeである。 ・メッセージ = MSG_VAL_006でバリデーションチェック：数字。その中： {0} がcodeである。 ・メッセージ = MSG_VAL_004でバリデーションチェック： 最大15文字。その中：{0}がcodeであり、{1}が{9}である。
C48: 6 | E48: name | L48: ○ | O48: String | S48: - | Z48: TicketMaster.Name | AQ48: ・メッセージ = MSG_VAL_001で入力必須のバリデーションチェック。その中 ：{0}がnameである。
C49: 7 | E49: amount | L49: ○ | O49: Int | S49: - | Z49: TicketMaster.Amount | AQ49: ・メッセージ = MSG_VAL_001で入力必須のバリデーションチェック。その中 ：{0}がamountである。
C50: 8 | E50: category | L50: ○ | O50: Smallint | S50: 15 | Z50: TicketMaster.Category | AQ50: ・メッセージ = MSG_VAL_0014で選択必須のバリデーションチェック。その中：{0}がamountである。 カテゴリ値： ・type = 1 -> 15:売掛金, 16:カード, 17:カスミイオン, 18:古紙リサイクル券, 19:"商品券, 20:ギフト券, 21:エコスタンプ, 22:クーポン券, 23:株主優待券, 24:カスミ商品券. ・type = 2: + discount_type = 1 -> 1:単品値引1、1のみ選択可能。タッチすると、以下の一覧を表示する。 1:単品値引1, 2:単品値引2, 3:単品値引3, 4:単品値引4, 5:単品値引5, 11:小計値引1, 13:小計値引3, 14:小計値引4, 15:小計値引5 + discount_type = 2-> 6:単品割引1, 7:単品割引2, 8:単品割引3, 9:単品割引4, 10:単品割引, 16:小計割引1, 17:小計割引2, 18:小計割引3, 19:小計割引4, 20:小計割引5
C51: 9 | E51: discount_type | L51: ○ | O51: Smallint | S51: - | Z51: TicketMaster.DiscountType | AQ51: discount_typeなし、1->2の範囲以外のバリデーションチェック: 表示エラーメッセージ：MSG_VAL_019（{0}：discount_type） 1: amountが割引の場合（amount 1-> 99） ・メッセージ=MSG_VAL_001でamountが0以外のバリデーションチェック。その中：{0}がamountある。 ・メッセージ=MSG_VAL_004でamount<=99のバリデーションチェック。その中：{0}がamountであり、{1}が99.99である。 2: amountが値引の場合 ・メッセージ=MSG_VAL_004でamountのバリデーションチェック：最大6文字。その中：{0}がamountであり、{1}が{6}である。
C52: 10 | E52: operation_type | L52: - | O52: Smallint | S52: 1 | Z52: TicketMaster.OperationType | AQ52: ・渡さない場合又は1->3範囲外で渡した場合、MSG_VAL_019（{0}：operation_type）を表示する。 ・新規作成の場合、operation_typeを「1」として渡す。 ・編集の場合、operation_type を「2」として渡す。 ・削除の場合、operation_typeを「3」として渡す。
C53: 11 | E53: can_return | L53: - | O53: Boolean | S53: FALSE | Z53: TicketMaster.ExtraInfo.PaymentTicket.CanReturn | AQ53: 返品使用許可
C54: 12 | E54: can_exchange | L54: - | O54: Boolean | S54: TRUE | Z54: TicketMaster.ExtraInfo.PaymentTicket.CanExchange | AQ54: 一部返品交換許可
C55: 13 | E55: can_change | L55: - | O55: Boolean | S55: FALSE | Z55: TicketMaster.ExtraInfo.PaymentTicket.CanChange | AQ55: 釣り許可
C56: 14 | E56: can_just_fix | L56: - | O56: Boolean | S56: FALSE | Z56: TicketMaster.ExtraInfo.PaymentTicket.CanJustFix | AQ56: 丁度預かり許可
C57: 15 | E57: is_drawer | L57: - | O57: Boolean | S57: TRUE | Z57: TicketMaster.ExtraInfo.PaymentTicket.IsDrawer | AQ57: ドロア開閉制御
C58: 16 | E58: can_cancel | L58: - | O58: Boolean | S58: TRUE | Z58: TicketMaster.ExtraInfo.PaymentTicket.CanCancel | AQ58: 支払明細クリア
C59: 17 | E59: can_void | L59: - | O59: Boolean | S59: TRUE | Z59: TicketMaster.ExtraInfo.PaymentTicket.CanVoid | AQ59: レジマイナス許可
C60: 18 | E60: can_over_deposit | L60: - | O60: Boolean | S60: FALSE | Z60: TicketMaster.ExtraInfo.PaymentTicket.CanOverDeposit | AQ60: 預かりオーバー許可
C61: 19 | E61: can_change_cout | L61: - | O61: Boolean | S61: FALSE | Z61: TicketMaster.ExtraInfo.PaymentTicket.CanChangeCout | AQ61: 枚数変更許可
...

Sheet 処理フロー
A1: システム名 | K1: システム種別 | W1: =IF(表紙!W1="","",表紙!W1) -> 詳細設計書 | AP1: 作成者 | AT1: 作成日 | AY1: 更新者 | BC1: 更新日 | BH1: 版数
A2: =IF(表紙!A2="","",表紙!A2) -> POSサーバー | K2: =IF(表紙!K2="","",表紙!K2) -> POSサーバー | AP2: =IF(表紙!AP2="","",表紙!AP2) -> LoiLV | AT2: =IF(表紙!AT2="","",表紙!AT2) -> 45469 | AY2: =IF(表紙!AY2="","",表紙!AY2) -> LoiLV | BC2: =IF(表紙!BC2="","",表紙!BC2) -> 45469 | BH2: =IF(表紙!BH2="","",表紙!BH2) -> 0.1
A4: 機能カテゴリ | H4: =IF(表紙!H4="","",表紙!H4) -> AP6603 | U4: 項目 | Z4: =IF(表紙!Z4="","",表紙!Z4) -> API設計書 | AP4: =MID(CELL("filename",A1),FIND("]",CELL("filename",A1))+1,255) -> 処理フロー

Sheet テンプレート
A1: システム名 | K1: システム種別 | W1: =IF(表紙!W1="","",表紙!W1) -> 詳細設計書 | AP1: 作成者 | AT1: 作成日 | AY1: 更新者 | BC1: 更新日 | BH1: 版数
A2: =IF(表紙!A2="","",表紙!A2) -> POSサーバー | K2: =IF(表紙!K2="","",表紙!K2) -> POSサーバー | AP2: =IF(表紙!AP2="","",表紙!AP2) -> LoiLV | AT2: =IF(表紙!AT2="","",表紙!AT2) -> 45469 | AY2: =IF(表紙!AY2="","",表紙!AY2) -> LoiLV | BC2: =IF(表紙!BC2="","",表紙!BC2) -> 45469 | BH2: =IF(表紙!BH2="","",表紙!BH2) -> 0.1
A4: 機能カテゴリ | H4: =IF(表紙!H4="","",表紙!H4) -> AP6603 | U4: 項目 | Z4: =IF(表紙!Z4="","",表紙!Z4) -> API設計書 | AP4: =MID(CELL("filename",A1),FIND("]",CELL("filename",A1))+1,255) -> テンプレート
