Workbook

Sheet 表紙
A1: システム名 | K1: システム種別 | W1: 詳細設計書 | AP1: 作成者 | AT1: 作成日 | AY1: 更新者 | BC1: 更新日 | BH1: 版数
A2: POSサーバー | K2: POSサーバ | AP2: =改訂履歴!$H$11 -> DuNT | AT2: =改訂履歴!$B$11 -> 45559 | AY2: =LOOKUP(2,1/(改訂履歴!H11:H30000<>""),改訂履歴!H11:H30000) -> DuNT | BC2: =LOOKUP(2,1/(改訂履歴!B11:B30000<>""),改訂履歴!B11:B30000) -> 45624 | BH2: =LOOKUP(2,1/(改訂履歴!O11:O30000<>""),改訂履歴!O11:O30000) -> 0.11
A4: 機能カテゴリ | H4: AP0602 | U4: 項目 | Z4: API設計書 | AP4: {=RIGHT(CELL("filename",$A$1),LEN(CELL("filename",$A$1))-FIND("]",CELL("filename",$A$1)))} -> 表紙
L16: POSサーバーの詳細設計書
L24: =K2&"/"&H4&"/"&Z4 -> POSサーバ/AP0602/API設計書
Q44: 承認日 | AA44: 承認者 | AQ44: 版数

Sheet 改訂履歴
A1: システム名 | K1: システム種別 | W1: =IF(表紙!W1="","",表紙!W1) -> 詳細設計書 | AP1: 作成者 | AT1: 作成日 | AY1: 更新者 | BC1: 更新日 | BH1: 版数
A2: =IF(表紙!A2="","",表紙!A2) -> POSサーバー | K2: =IF(表紙!K2="","",表紙!K2) -> POSサーバ | AP2: =IF(表紙!AP2="","",表紙!AP2) -> DuNT | AT2: =IF(表紙!AT2="","",表紙!AT2) -> 45559 | AY2: =IF(表紙!AY2="","",表紙!AY2) -> DuNT | BC2: =IF(表紙!BC2="","",表紙!BC2) -> 45624 | BH2: =IF(表紙!BH2="","",表紙!BH2) -> 0.11
A4: 機能カテゴリ | H4: =IF(表紙!H4="","",表紙!H4) -> AP0602 | U4: 項目 | Z4: =IF(表紙!Z4="","",表紙!Z4) -> API設計書 | AP4: {=RIGHT(CELL("filename",$A$1),LEN(CELL("filename",$A$1))-FIND("]",CELL("filename",$A$1)))} -> 改訂履歴
B8: ■改訂履歴
B10: 更新日 | H10: 更新者 | O10: 版数 | S10: 更新内容 | AX10: 承認日 | BD10: 承認者
B11: 45559 | H11: DuNT | O11: 0.1 | S11: 新規
B13: 45624 | H13: DuNT | O13: 0.11 | S13: 処理フロー更新

Sheet 処理フロー凡例
A1: システム名 | K1: システム種別 | W1: =IF(表紙!W1="","",表紙!W1) -> 詳細設計書 | AP1: 作成者 | AT1: 作成日 | AY1: 更新者 | BC1: 更新日 | BH1: 版数
A2: =IF(表紙!A2="","",表紙!A2) -> POSサーバー | K2: =IF(表紙!K2="","",表紙!K2) -> POSサーバ | AP2: =IF(表紙!AP2="","",表紙!AP2) -> DuNT | AT2: =IF(表紙!AT2="","",表紙!AT2) -> 45559 | AY2: =IF(表紙!AY2="","",表紙!AY2) -> DuNT | BC2: =IF(表紙!BC2="","",表紙!BC2) -> 45624 | BH2: =IF(表紙!BH2="","",表紙!BH2) -> 0.11
A4: 機能カテゴリ | H4: =IF(表紙!H4="","",表紙!H4) -> AP0602 | U4: 項目 | Z4: =IF(表紙!Z4="","",表紙!Z4) -> API設計書 | AP4: =MID(CELL("filename",A1),FIND("]",CELL("filename",A1))+1,255) -> 処理フロー凡例
B7: ●API処理フロー

Sheet AP0602
A1: システム名 | K1: システム種別 | W1: =IF(表紙!W1="","",表紙!W1) -> 詳細設計書 | AP1: 作成者 | AT1: 作成日 | AY1: 更新者 | BC1: 更新日 | BH1: 版数
A2: =IF(表紙!A2="","",表紙!A2) -> POSサーバー | K2: =IF(表紙!K2="","",表紙!K2) -> POSサーバ | AP2: =IF(表紙!AP2="","",表紙!AP2) -> DuNT | AT2: =IF(表紙!AT2="","",表紙!AT2) -> 45559 | AY2: =IF(表紙!AY2="","",表紙!AY2) -> DuNT | BC2: =IF(表紙!BC2="","",表紙!BC2) -> 45624 | BH2: =IF(表紙!BH2="","",表紙!BH2) -> 0.11
A4: 機能カテゴリ | H4: =IF(表紙!H4="","",表紙!H4) -> AP0602 | U4: 項目 | Z4: =IF(表紙!Z4="","",表紙!Z4) -> API設計書 | AP4: =MID(CELL("filename",A1),FIND("]",CELL("filename",A1))+1,255) -> AP0602
B7: 1. 概要
C9: 未来日で対象店舗の1, 7, 8 定番売価一覧を保存する。
B11: 2. リクエスト
C13: 2.1 Request URL
C15: No. | E15: URL | AG15: HTTPメソッド | AQ15: 備考
C16: 1 | E16: api/v1/changed-standard-prices/maintenance | AG16: POST | AQ16: -
C18: 2. 2 Request Header
C20: No. | E20: ヘッダー | L20: 必須 | O20: 型 | S20: デフォルト値 | Z20: 項目説明 | AQ20: 備考
C21: 1 | E21: Authorization | L21: ○ | O21: String | S21: - | Z21: Api key | AQ21: 代表ユーザーを認証するAPIキー値 フォーマット："Bearer {api_key}"
C23: 2 | E23: Accept | L23: - | O23: String | S23: - | Z23: Accept
C24: 3 | E24: Content-Type | L24: ○ | O24: String | S24: application/json | Z24: Content-Type
C25: 4 | E25: User-Agent | L25: - | O25: String | S25: - | Z25: User-Agent
C26: 5 | E26: Accept-Encoding | L26: - | O26: String | S26: - | Z26: Accept-Encoding
C28: 2.3 Query Parameter/ path parameter
D29: NA
C31: 2.4 Request Body
C33: No. | E33: パラメータ | L33: 必須 | O33: 型 | S33: デフォルト値 | Z33: 項目説明 | AQ33: 備考
C34: 1 | E34: standard_prices | L34: ○ | O34: Array | S34: - | Z34: 売価変更データリスト
C35: =C34+1 -> 2 | E35: record_id | L35: - | O35: BigInt | S35: - | Z35: StandardPriceHistory.RECORD_ID | AQ35: 新規作成の場合はrecord_id = nullとし、編集・削除の場合は該当するrecord_idを渡す。
C36: =C35+1 -> 3 | E36: operation_type | L36: - | O36: SmallInt | S36: - | AQ36: ・新規作成の場合、operation_typeを「1」として渡す。 ・編集の場合、operation_type を「2」として渡す。 ・削除の場合、operation_typeを「3」として渡す。 上記以外の場合、エラーメッセージ = MSG_VAL_019
C37: =C36+1 -> 4 | E37: store_code | L37: ○ | O37: String | S37: - | Z37: StandardPriceHistory.StoreCode | AQ37: バリデーションチェック：数字、4桁 バリデーションチェックNGの場合、エラーメッセージ = MSG_VAL_019 store_codeがユーザーが所属する会社のstore_masterに存在しているかをバリデーションチェックする。
C38: =C37+1 -> 5 | E38: item_code | L38: ○ | O38: String | S38: - | Z38: StandardPriceHistory.ItemCode | AQ38: ・数字13桁 -> 数字ではない場合、エラーメッセージ = MSG_VAL_026、長さが13桁以外の場合、エラーメッセージ= MSG_VAL_002。 item_codeがitem_master に存在しているかをバリデーションチェックする。存在していない場合、 エラーメッセージ = MSG_VAL_019 存在している場合、my_company_codeの6番目と7番目の桁が「01」または「07」、または「08」であるかをバリデーションチェックする。エラーの場合、「MSG_VAL_045」エラーメッセージを表示する。
C39: =C38+1 -> 6 | E39: booking_date | L39: ○ | O39: String | S39: - | Z39: StandardPriceHistory.BookingDate | AQ39: フォーマット: yyyy/mm/dd 現在日または未来日のみを許可する。
C40: =C39+1 -> 7 | E40: group_code | L40: ○ | O40: String | S40: - | Z40: StandardPriceHistory.GroupCode | AQ40: 数字の2桁。数字ではない場合、エラーメッセージ = MSG_VAL_026。長さが2桁以外の場合、エラーメッセージ= MSG_VAL_002。 group_code = 「01」又は「07」又は「08」であるかをバリデーションチェックする。エラーの場合、「MSG_VAL_045」エラーメッセージを表示する。
C41: =C40+1 -> 8 | E41: new_price | L41: ○ | O41: Decimal | S41: - | Z41: StandardPriceHistory.Price | AQ41: 最大6桁。バリデーションチェック：0より大きい値であること。「0」以下の場合、エラーメッセージ = MSG_VAL_019
C43: ※サンプル
C45: {
C46: [
C47: {
C48: "record_id":1,
C49: "operation_type":1,
C50: "store_code":"00002",
C51: "item_code":"0000000000017",
C52: "booking_date":"2024/09/09",
C53: "group_code":"01",
C54: "new_price":290
C55: }
...

Sheet 処理フロー
A1: システム名 | K1: システム種別 | W1: =IF(表紙!W1="","",表紙!W1) -> 詳細設計書 | AP1: 作成者 | AT1: 作成日 | AY1: 更新者 | BC1: 更新日 | BH1: 版数
A2: =IF(表紙!A2="","",表紙!A2) -> POSサーバー | K2: =IF(表紙!K2="","",表紙!K2) -> POSサーバ | AP2: =IF(表紙!AP2="","",表紙!AP2) -> DuNT | AT2: =IF(表紙!AT2="","",表紙!AT2) -> 45559 | AY2: =IF(表紙!AY2="","",表紙!AY2) -> DuNT | BC2: =IF(表紙!BC2="","",表紙!BC2) -> 45624 | BH2: =IF(表紙!BH2="","",表紙!BH2) -> 0.11
A4: 機能カテゴリ | H4: =IF(表紙!H4="","",表紙!H4) -> AP0602 | U4: 項目 | Z4: =IF(表紙!Z4="","",表紙!Z4) -> API設計書 | AP4: =MID(CELL("filename",A1),FIND("]",CELL("filename",A1))+1,255) -> 処理フロー
AB68: `

Sheet テンプレート
A1: システム名 | K1: システム種別 | W1: =IF(表紙!W1="","",表紙!W1) -> 詳細設計書 | AP1: 作成者 | AT1: 作成日 | AY1: 更新者 | BC1: 更新日 | BH1: 版数
A2: =IF(表紙!A2="","",表紙!A2) -> POSサーバー | K2: =IF(表紙!K2="","",表紙!K2) -> POSサーバ | AP2: =IF(表紙!AP2="","",表紙!AP2) -> DuNT | AT2: =IF(表紙!AT2="","",表紙!AT2) -> 45559 | AY2: =IF(表紙!AY2="","",表紙!AY2) -> DuNT | BC2: =IF(表紙!BC2="","",表紙!BC2) -> 45624 | BH2: =IF(表紙!BH2="","",表紙!BH2) -> 0.11
A4: 機能カテゴリ | H4: =IF(表紙!H4="","",表紙!H4) -> AP0602 | U4: 項目 | Z4: =IF(表紙!Z4="","",表紙!Z4) -> API設計書 | AP4: =MID(CELL("filename",A1),FIND("]",CELL("filename",A1))+1,255) -> テンプレート
