Workbook

Sheet 表紙
A1: XXX基本設計 | L1: 大分類 | V1: 中分類 | AF1: 小分類 | AP1: 作成者 | AU1: 作成日 | AZ1: 更新日
L2: 基本設計書 | V2: - | AF2: =RIGHT(CELL("filename",$A$2),LEN(CELL("filename",$A$2))-FIND("]",CELL("filename",$A$2))) -> 表紙 | AU2: 45078 | AZ2: 45635
D9: XXX 基本設計書
AV16: 版番 | AZ16: 1.2

Sheet 変更履歴
A1: =表紙!A1 -> XXX基本設計 | L1: 大分類 | V1: 中分類 | AF1: 小分類 | AP1: 作成者 | AU1: 作成日 | AZ1: 更新日
L2: =表紙!L2 -> 基本設計書 | V2: =表紙!V2 -> - | AF2: =RIGHT(CELL("filename",$A$2),LEN(CELL("filename",$A$2))-FIND("]",CELL("filename",$A$2))) -> 変更履歴
B4: 発行日 | F4: 版 | I4: 変更箇所 | W4: 発行／改定内容 | BB4: 変更者
F5: 1.00 | W5: 初版発行

Sheet 目次
A1: =表紙!A1 -> XXX基本設計 | L1: 大分類 | V1: 中分類 | AF1: 小分類 | AP1: 作成者 | AU1: 作成日 | AZ1: 更新日
L2: =表紙!L2 -> 基本設計書 | V2: =表紙!V2 -> - | AF2: =RIGHT(CELL("filename",$A$2),LEN(CELL("filename",$A$2))-FIND("]",CELL("filename",$A$2))) -> 目次 | AU2: =表紙!AU2 -> 45078
B4: ０．はじめに | AH4: ６．ログ運用設計
C5: １．１．案件の目的 | AI5: ６．１ ログ運用方針
C6: １．２．本書の記述範囲 | AI6: ６．２ ログ運用
AI7: ６．３ ログ保管期間
B9: １．アカウント設計 | AH9: ７．バックアップ・リストア運用設計
C10: １．１．案件の目的 | AI10: ７．１ バックアップ・リストア運用方針
C11: １．２．本書の記述範囲 | AI11: ７．２ バックアップ運用
AI12: ７．３ リストア運用
B14: ２．システム構成 | AH14: ８．監視設計
C15: ２．１ 本環境構成 | AI15: ８．１ 監視方針
C16: ２．２ サービス一覧 | AI16: ８．２ 監視運用フロー
AI17: ８．３ 監視体制と役割
B18: ３．ネットワーク設計 | AI18: ８．４ 監視方式
C19: ３．１ XXX
AH20: ９．運用機能設計
B21: ４．可用性設計 | AI21: ９．１ 運用機能一覧
C22: ４．１ 可用性方針 | AI22: ９．２ 各運用機能方針
B24: ５．セキュリティ設計
C25: ５．１ セキュリティ方針
C26: ５．２ ネットワークセキュリティ
C27: ５．３ アクセス権限制御
C28: ５．４ セキュリティポリシー対応方針
C29: ５．５ SSLサーバ証明書

Sheet ０．はじめに
A1: =表紙!A1 -> XXX基本設計 | L1: 大分類 | V1: 中分類 | AF1: 小分類 | AP1: 作成者 | AU1: 作成日 | AZ1: 更新日
L2: =表紙!L2 -> 基本設計書 | V2: =表紙!V2 -> - | AF2: =RIGHT(CELL("filename",$A$2),LEN(CELL("filename",$A$2))-FIND("]",CELL("filename",$A$2))) -> ０．はじめに | AP2: =表紙!AP2 -> 0 | AU2: =表紙!AU2 -> 45078
A3: ０．はじめに
B5: ０．１．案件の目的
C6: 各屋号に対してオンプレミス上にあるPOSデータを毎朝送信するシステムを作成する。
C7: 屋号単位で細かな要件は存在するが、共通機能を整理し標準化を行う。
C8: 屋号で異なる要件が発生した場合は共通機能と異なる点を設計として残し、環境・運用をご提供する。
C9: AWSリセラーではない為、提供環境はサービスとして顧客提供するものとする。
B11: ０．２．本書の記述範囲
C12: 本書では、AWSに関する基本設計を記述範囲とする。
B14: ０．０．基本方針
C15: 利用するAWSとの責任分界点はAWSが提示している責任共有モデルに準じた実装とする。
C16: AWSのベストプラクティスに準じてシステム設計を行う。
C17: システムを実装するリージョンは東京リージョンを利用し、災対環境は考慮しない。
C18: USMH様網とAWS環境に構築するPOSサーバ 2.0間との通信は、
C19: 情報システム部が所管するAWS Direct Connect環境を利用した専用線網を利用し、通信を可能にする。
C20: 可用性を担保するため、マルチAZ構成でシステムを実装する。
C21: AWSサービス（CloudWatch、SNS等）を利用したシステム監視を実装する。
C22: インターネットアクセスから本システムにアクセスすることは原則禁止とし、本システムアクセスの場合はお客様提供のVPNを利用してアクセスを行う。
C23: スケーラビリティ、開発・保守䛾簡素化、コスト削減を最大化するために可能な限り、サーバレスでの構築を行う。
C24: 運用コスト・オペミス䛾リスク䛾軽減させるために、インフラはIaCで構築を行う。
C25: サービスダウンタイム軽減、障害未然防止するために、包括的䛺モニタリングを行う。
B27: ０．３．前提条件
C28: 本システムは2025年3月30日までに提供されたAWSサービスの仕様を基とする。
C29: 本システムのサービス提供中に、AWSによる仕様変更に伴い本書記載の設計と異なる動作が生じた場合は、都度協議の上で方式を見直す
C30: 以下、ガイドラインに準じたシステム構築を実施する
D31: ・今のところ特になし

Sheet １．アカウント設計
A1: =表紙!A1 -> XXX基本設計 | L1: 大分類 | V1: 中分類 | AF1: 小分類 | AP1: 作成者 | AU1: 作成日 | AZ1: 更新日
L2: =表紙!L2 -> 基本設計書 | V2: =表紙!V2 -> - | AF2: =RIGHT(CELL("filename",$A$2),LEN(CELL("filename",$A$2))-FIND("]",CELL("filename",$A$2))) -> １．アカウント設計 | AP2: =表紙!AP2 -> 0 | AU2: =表紙!AU2 -> 45078
B4: ２．アカウント設計
D6: AWSアカウントおよびIAMユーザについて以下に記載する。
B8: ２．1．AWSアカウント
C10: （１）方針
D11: ・AWSアカウントは、ルビナ社が発行したAWSアカウントを利用する。
D12: ・本番環境と開発環境でアカウントを分離する。
D13: ・各アカウントのルートユーザはルビナ社にて管理し、ルビナ社側で多要素認証（MFA）の設定を行う。
C15: （２）AWSアカウント一覧
D16: 利用するAWSアカウントは以下の通り。
D18: # | F18: AWSアカウント | P18: 利用用途
D19: 1 | F19: スパイク環境アカウント | P19: スパイク環境を構築するAWSアカウント。既存のAndroidPoSアカウント上に構築する。
F20: （AndroidPoS）
D21: 2 | F21: 本番環境アカウント | P21: 本番サービスを提供するアカウント。
D22: 3 | F22: 開発環境アカウント | P22: ルビナ社にて検証に利用するアカウント。
C24: （３）AWSアカウント管理概要
D25: AWS環境におけるアカウントの管理概要は以下の通り。
B47: ２．2．IAM設計
C49: （１）方針
D50: ・AWSリソースへのアクセス制御は、IAMの機能を利用して実現する。
D51: ・IAMのユーザ、ポリシー、グループ、ロール機能に適切な権限を付与し、アクセスを制御する。
E53: # | G53: IAM機能 | M53: 利用用途
E54: 1 | G54: ユーザ | M54: AWS環境を運用する個人に対してアクセス権を付与する。
E55: 2 | G55: ポリシー | M55: ユーザ、グループ、ロールに対する権限を定義する。
E56: 3 | G56: グループ | M56: 役割に応じて、複数のユーザを所属させ、効率的なアクセス管理を実施する。
E57: 4 | G57: ロール | M57: AWSリソースやサービスに対して権限を付与し、アクセス管理を実施する。
D59: ・不正アクセスを防ぐため、AWSマネジメントコンソールへのログイン時はMFAを必須とする。
D60: ・アカウントを払い出された際に発行されるAWSアカウント管理者は、同等の権限を持つシステム管理グループを作成し、IAMユーザーを紐付けた後、
D61: セキュリティの観点から削除する。
C63: （２）IAM構成概要
D64: IAM構成概要は以下の通り。
C105: （３）IAMユーザ
E106: ・IAMユーザは、個人単位で作成し、役割に応じたIAMグループに所属させる。
E107: ・IAMユーザ名は以下で作成する。
E109: # | G109: 担当者 | O109: IAMユーザ名
E110: 1 | G110: システム管理者 | O110: メールアドレス
E111: 2 | G111: アプリメンバー | O111: メールアドレス
E112: 3 | G112: インフラメンバー | O112: メールアドレス
E113: 3 | G113: ユーザー管理者 | O113: メールアドレス
...

Sheet ２．システム構成
A1: =表紙!A1 -> XXX基本設計 | L1: 大分類 | V1: 中分類 | AF1: 小分類 | AP1: 作成者 | AU1: 作成日 | AZ1: 更新日
L2: =表紙!L2 -> 基本設計書 | V2: =表紙!V2 -> - | AF2: =RIGHT(CELL("filename",$A$2),LEN(CELL("filename",$A$2))-FIND("]",CELL("filename",$A$2))) -> ２．システム構成 | AU2: =表紙!AU2 -> 45078 | AZ2: 45635
A4: ２．システム構成
B5: 本システムはアカウント単位で環境を分離する。
B6: 本番、開発環境において1アカウント１VPCで構成する。尚、屋号のNW分離についてはサブネットで分離する。
B7: １VPCの中で屋号を分割する背景としてAWS環境とオンプレミスを繋ぐDirectConectGatewayの接続上限が20VPCという制限によるもので、接続数を節約のための構成とする。
C9: VPC構成イメージ
C25: 各環境定義
C26: 環境 | D26: 環境 | I26: 用途
C27: 1 | D27: 本番環境 | I27: 本番サービスを提供する環境とする。
C28: 2 | D28: 開発環境 | I28: USMH様にて業務機能の検証を行う環境とする。
C29: 3 | D29: スパイク環境 | I29: ルビナ社にて検証を行う環境とする。
B31: ２．１ 環境構成
C32: 本環境の構成図は別紙1.構成図 シートを参照
B35: ２．２ サービス一覧
C36: 本環境で利用するAWSサービス一覧は以下のとおり。
C37: 利用サービス一覧 | P37: サービス説明 | AX37: 用途
C38: AWS Transfer Family for SFTP | P38: AWSの他のシステム、例えばS3アプリケーションなどと結合可能なアプリケーション転送に特化したサービス | AX38: マスタファイルをSFTPで入出力するために使用
C39: AWS Lambda | P39: AWSのイベントの受信、フィルタリング、変換、ルーティング、および配信を可能にするサービス | AX39: マスタファイルの変換処理や送信を行う
C40: Amazon EventBridge | P40: AWS、既存のシステム、または SaaS アプリケーション全体でイベント駆動型アプリケーションを大規模に構築するサービス | AX40: S3バケットにファイルが配置されたタイミングをトリガーとして、Lambdaを実行する
C41: AWS Step Functions | P41: 複数のAWSサービスを連携させ、ワークフローを簡単に構築・管理するためのサービス | AX41: ファイルを分散処理することで、処理の高速化を実現する
C42: Amazon S3 | P42: 高可用性のオブジェクトストレージ機能を提供するサービス | AX42: マスタファイルやトランファイルを保存する
C43: Application Load Balancer | P43: アプリケーション層でのトラフィックのルーティング、ロードバランシングを提供するサービス | AX43: 管理画面へのアクセスに対して、負荷分散をする
C44: Amazon Elastic Container Service (ECS) | P44: コンテナ化されたアプリケーションの管理とオーケストレーションを提供するサービス | AX44: POS用マスタファイルの作成や
C45: Amazon Elastic Container Registry （ECR） | P45: Kubernetesクラスターを簡単にデプロイ、管理、スケーリングするためのサービス | AX45: アプリケーションのイメージを保管する
C46: NAT Gateway | P46: プライベートサブネットからインターネットへ接続するための中継機能を提供し、アウトバウンドインターネットアクセスを許可するサービス | AX46: プライベートサブネットにあるECSのコンテナイメージをECRから取得するために使用
C47: Amazon Aurora | P47: 高いパフォーマンスと可用性を持つリレーショナルデータベースサービス | AX47: マスタ情報や集計情報をデータ保存する
C48: AWS Secrets Manager | P48: アプリケーションやサービスで必要な秘密情報（APIキーやパスワードなど）を安全に保存、管理、取得するサービス | AX48: SFTP通信をする際に必要な、SSH鍵を保管する

Sheet ３．ネットワーク設計
A1: =表紙!A1 -> XXX基本設計 | L1: 大分類 | V1: 中分類 | AF1: 小分類 | AP1: 作成者 | AU1: 作成日 | AZ1: 更新日
L2: =表紙!L2 -> 基本設計書 | V2: =表紙!V2 -> - | AF2: =RIGHT(CELL("filename",$A$2),LEN(CELL("filename",$A$2))-FIND("]",CELL("filename",$A$2))) -> ３．ネットワーク設計
B4: ３．ネットワーク設計
C6: AWS環境におけるネットワーク設計について下記に記載する。
B8: ３．１．仮想ネットワーク設計
C10: （１） | E10: 方針
E11: ・AWS環境のネットワークは、AWSの仮想ネットワークサービスであるVPC（Virtual Private Cloud）を用いる。
E12: ・AWS環境のネットワーク構成は、AWS内に閉じた通信先を用途毎にCommon Subnet、Public Subnet、Private Subnet、Protected Subnet
E13: 分割し、サブネットに対してAWSのルートテーブル機能を用いて通信先を制御する。
E14: ・共通で利用するエンドポイントについてはCommon Subnetを設計するが、作成は行わない。
E15: ・DBを配置しない屋号に対してもProtected Subnetを設計するが、作成は行わない。
E16: ・VPCサブネット間通信やVPC外部への通信経路制御は、ルートテーブル機能とセキュリティグループ機能、ネットワークACL機能を用いて実現する。
E17: ・通信元からの通信制御は基本的にセキュリティグループにて実施し、ネットワークACLでは特に制御を行わない。
E18: ・１VPCに屋号単位でサブネットを分割する。
C20: （２） | E20: 構成概要
E21: ネットワーク構成概要は以下の通り。
E22: ・スパイク環境環境
E81: ・開発環境
G83: 後でつくる
E87: ・本番環境
G89: 後でつくる
B119: ３．２．VPC／サブネット設計
C121: （１） | E121: VPC設計
E122: 各環境のVPCに割り当てるアドレス領域は以下の通り。
E124: # | G124: VPC | O124: VPC CIDR | W124: アカウント
E125: 1 | G125: スパイク環境 | W125: AndroidPosアカウント
E126: 2 | G126: 本番環境 | W126: 本番アカウント
E127: 3 | G127: 開発環境 | W127: 開発アカウント
C129: （２） | E129: サブネット設計
E130: サブネットは、用途毎に以下4つに分割する。
E132: ＃ | G132: サブネット | P132: 用途
E133: 1 | G133: Common Subnet
E135: 2 | G135: Public Subnet | P135: インターネットとの直接通信を許可とするサブネット。
E137: 3 | G137: Private Subnet | P137: インターネットから直接の通信を不可とし、アプリケーション機能、エンドポイントを設定するサブネット。
E139: 4 | G139: Protected Subnet | P139: インターネットからの通信を不可とし、Private Subnetからのみ通信を可能とするDB配置想定のサブネット。
P140: 配置するサブネット。
E142: 各VPCにおけるサブネットの配置は以下の通り。
E143: 屋号単位でサブネットマスク/23でIPを払い出し、IPの余剰がないように各サブネットに割り当てる。
E144: 尚、サブネットは屋号単位で設計する
E146: （２）ー１スパイク環境
...

Sheet ４．可用性設計
A1: =表紙!A1 -> XXX基本設計 | L1: 大分類 | V1: 中分類 | AF1: 小分類 | AP1: 作成者 | AU1: 作成日 | AZ1: 更新日
L2: =表紙!L2 -> 基本設計書 | V2: =表紙!V2 -> - | AF2: =RIGHT(CELL("filename",$A$2),LEN(CELL("filename",$A$2))-FIND("]",CELL("filename",$A$2))) -> ４．可用性設計 | AU2: =表紙!AU2 -> 45078 | AZ2: 45467
A4: ４．可用性設計
C6: AWS環境における可用性について以下に記載する。
B8: ４．１．方針
D10: 本システムにて使用するAWSサービスについてAZ障害に耐えうる可用性確保のため、マルチAZ構成とする。
D11: 一つのAZに障害発生が発生した場合でも業務継続できる設計とする。
D12: データ連携先のシステムの障害や各AWSコンポーネントの二重障害は対象外とする。
D13: AWSのサービス自体の可用性はAWSの公開するSLAを基準とする。
D14: ※AWS SLA：https://aws.amazon.com/jp/legal/service-level-agreements/
B16: ４．２．可用性確保方式
C18: （１） | E18: システムの可用性確保方式
E19: 以下の可用性確保方式によってシステム可用性を担保する。方式はAWSよって提供される可用性確保方式を利用するものとする。
E21: Ａ．マルチAZ方式
E22: 本システムではAWS 東京リージョン内で2つのAZを使用したマルチAZ構成とする。
E23: 以下のサービスにおいてマルチAZ方式を使用する。
E25: No | G25: AWSサービス | N25: 詳細
E26: 1 | G26: VPC | N26: AWS上の仮想ネットワーク。マルチAZ構成とする。
E27: 2 | G27: ALB | N27: HTTP/HTTPSトラフィックの負荷分散を行う。ALBは制約で2つ以上のAZに紐づける必要があり、WAFを使用するために必要。
N28: 単一障害対策のためにクロスゾーン負荷分散を有効にする。
N29: ターゲットグループを設定することでトラフィック先のリソースを指定できる。
N30: リスナールールを設定することで特定のプロトコルとポート番号を受けることができる。
E31: 3 | G31: VPCエンドポイント
G32: ECS
G33: とかとか
E36: B．業務停止時のデータ復旧
E37: 以下のサービスにおいて障害発生時に利用可能なバックアップからインスタンスを復元することで業務の継続を図る。
E39: No | G39: AWSサービス | N39: 詳細
E40: 1 | G40: Aurora MySQL | N40: AWS Backupにより日次でバックアップの取得を行う。
N41: ポイントインタイムリカバリ機能で可能な限り障害発生時点まで復旧できるようにする。
E43: C．オートスケーリング
E44: 以下のサービスにおいてリソース利用状況に応じて自動的に不足リソースを追加、削除することで、常に最適なリソースを確保し、負荷に対応し業務の継続を図る。
E46: No | G46: AWSサービス | N46: 詳細
E47: 1 | G47: ALB
G48: RDS
G49: ECS
C51: （２） | E51: システムの可用性確保方式詳細
E52: 可用性確保方式の動作について詳細を記載する。
E53: 要件を満たすため、本システムは次の方針で設計を行う。
E55: AZレベルの障害に対応できるようにするため、一部のAWSリソース(VPC、NLB、ALBなど)はマルチAZ構成で作成し、
...

Sheet ⇒大生整理中

Sheet ４．セキュリティ設計
A1: =表紙!A1 -> XXX基本設計 | L1: 大分類 | V1: 中分類 | AF1: 小分類 | AP1: 作成者 | AU1: 作成日 | AZ1: 更新日
L2: =表紙!L2 -> 基本設計書 | V2: =表紙!V2 -> - | AF2: =RIGHT(CELL("filename",$A$2),LEN(CELL("filename",$A$2))-FIND("]",CELL("filename",$A$2))) -> ４．セキュリティ設計 | AU2: =表紙!AU2 -> 45078 | AZ2: 45635
A4: ４．セキュリティ設計
B6: ４．１ セキュリティ方針
C7: AWSアカウントの発行はYYY社が行い、顧客毎にAWSアカウントを分けて運用する。
C8: 利用するIAMユーザー用のポリシーについては、業務処理に最低限必要な権限を付与することで、セキュリティ的なリスクを回避する。
C9: AWSが提供する機能を利用することで、効率よくセキュリティの確保を行う。
C10: 当プラットフォーム環境は サーバーレス構成の為 ウイルス対策ソフトは導入せず S3へのファイルアップ時に事前のウイルススキャンを必須とすることでウイルス感染リスクを排除する。
B13: ４．２ ネットワークセキュリティ
C14: ユーザーからAWSリソースへの通信をHTTPSにすることで、暗号化されたセキュアな通信を行う。
B17: ４．３ アクセス権限制御
C18: IAMはAWSManagedPolicyを利用するものとする。
C20: ４．３．１ AWS環境へのログインについて
D21: AWS環境へのログインについては、共通のユーザーは使用せず、個人単位のログインとする。
C24: ４．３．２ IAMユーザー
D25: IAMユーザーの発行について記載する。
D27: IAMユーザーは、個人単位に払い出す。
D28: 付与する権限については、所属するグループの権限に準ずる。
D29: パスワードの有効期限は40日とする。
D30: パスワードポリシーは以下の通りとする。
D31: ・8文字以上とする。
D32: ・大文字 (A～Z) を少なくとも 1 つ含める。
D33: ・小文字 (a～z) を少なくとも 1 つ含める。
D34: ・数字を少なくとも 1 つ含める。
D35: ・英数字以外の文字 (! @ # $ % ^ & * ( ) _ + - = [ ] { } | ') を少なくとも 1 つ含める。
C38: ４．３．3 IAMグループ
D39: IAMグループの作成について記載する。
D41: IAMグループに付与するIAMポリシーは以下のとおり。
D42: IAMグループ | Q42: 役割 | AQ42: 付与権限
D43: AdminGroup | Q43: クレスコ及びXXXの管理ユーザーが所属するグループ | AQ43: AdministratorAccess管理ポリシー
D44: VendorGroup（専用環境/標準版を使用の場合） | Q44: 上記以外のベンダーが所属するグループ（XXXの作業時もこちらを使用） | AQ44: ファイルアップロード、削除、CloudFrontキャッシュ削除のみ
D45: 個別Group（共用環境/簡易版を使用の場合） | Q45: 上記以外のベンダーが所属するグループ（XXXの作業時もこちらを使用） | AQ45: ファイルアップロード、削除、CloudFrontキャッシュ削除のみ
C48: ４．３．4 IAMポリシー
D49: AWSManagedPolicyを利用することを基本とし、必要に応じて権限を絞り込んだポリシーを作成するものとする。
D50: IAMポリシーは、後述のIAMロールで利用する。
D51: 2024/12/9以降の環境についてはCI/CD削除対応後となるため、以下の全てのIAMポリシーを使用/構築しない。
D53: IAMロールに対するIAMポリシーは以下のとおり。
D54: IAMロールは、AWSリソースに対して割り当てる権限であり、その権限には、IAMグループに割りあてるポリシーとは別のものを使用する。
D55: IAMポリシー | X55: 用途
D56: AWSCodeCommitFullAccess | X56: CodeCommitへの実行権限
...

Sheet ５．ログ運用設計
A1: =表紙!A1 -> XXX基本設計 | L1: 大分類 | V1: 中分類 | AF1: 小分類 | AP1: 作成者 | AU1: 作成日 | AZ1: 更新日
L2: =表紙!L2 -> 基本設計書 | V2: =表紙!V2 -> - | AF2: =RIGHT(CELL("filename",$A$2),LEN(CELL("filename",$A$2))-FIND("]",CELL("filename",$A$2))) -> ５．ログ運用設計 | AU2: =表紙!AU2 -> 45078 | AZ2: 45635
A4: ５．ログ運用設計
B6: ５．１ ログ運用方針
C7: システムの状態を収集してモニタリング、異常が発生していないか監視を行う必要がある。
C8: システムがどのように利用されているかを把握するための情報を集め、メトリクスやログの収集、監視や可視化を行う。
B11: ５．２ ログ運用
C12: 保管先がS3に指定されているサービスはS3に保管をし、Athenaでクエリ分析を行う。
C13: それ以外のログについては、CloudWatchLogsにてログ運用を行う。
C14: S3は標準クラスを使用し、ストレージクラスの移行は行わない。
C16: ログ運用が必要となる対象を以下に記載する。
C17: サービス名（ログ取得対象） | M17: ログ内容 | AJ17: ログデータ保管 | AQ17: ログデータ保管期間
C18: CloudFront | M18: セキュリティやアクセスの監査用ログを含む標準ログをS3へ出力する。 | AJ18: S3 | AQ18: 13ヶ月(400日)
C20: S3 | M20: バケットに対するリクエスト/アクセスの詳細を記録する。 | AJ20: S3 | AQ20: 13ヶ月(400日)
C22: Athena | M22: クエリの実行結果を記録する。 | AJ22: S3 | AQ22: 13ヶ月(400日)
C24: CloudTrail | M24: ユーザー、ロール、または AWS のサービスによって実行された | AJ24: S3 | AQ24: 13ヶ月(400日)
M25: アクションを記録する。
C26: Lambda | M26: Lambda実行に対する詳細なログを出力する。 | AJ26: CloudWatchLogs | AQ26: 13ヶ月(400日)
C28: WAF | M28: AWS WAF が AWS リソースからウェブリクエストを受信した時刻、 | AJ28: CloudWatchLogs | AQ28: 13ヶ月(400日)
M29: リクエストに関する詳細情報、およびリクエストが一致したルールに
M30: 関する詳細を含む。
C31: 注、サイト閉塞時に400日に関わらず全件削除となるが、利用者の要望に応じてサイト閉塞後もログのみを保管することが可能とする。
C32: 2024/12/9以降の環境についてはCI/CD削除対応後となるため、Lambdaのログは存在しない。
B35: ５．３ ログ保管期間経過後の対応
C36: 保管期間を超過したログについては、費用圧縮の観点から削除する。

Sheet ６．バックアップ・リストア設計
A1: =表紙!A1 -> XXX基本設計 | L1: 大分類 | V1: 中分類 | AF1: 小分類 | AP1: 作成者 | AU1: 作成日 | AZ1: 更新日
L2: =表紙!L2 -> 基本設計書 | V2: =表紙!V2 -> - | AF2: =RIGHT(CELL("filename",$A$2),LEN(CELL("filename",$A$2))-FIND("]",CELL("filename",$A$2))) -> ６．バックアップ・リストア設計 | AU2: =表紙!AU2 -> 45078 | AZ2: 45467
A4: ６．バックアップ・リストア運用設計
B6: ６．１ バックアップ・リストア運用方針
C7: AWSが提供する機能を利用することで、バックアップ・リストア運用を実現する。
B10: ６．２ バックアップ運用
C11: S3は耐久性を考慮し、バージョン管理によるバックアップは本環境では行わない。
C12: コンテンツのマスターデータ管理は、ページ製作ベンダーにて行う。
B15: ６．３ リストア運用
C16: リストア方法については別途ドキュメント「Webサイトリリース手順書」を参照。

Sheet ７．監視設計
A1: =表紙!A1 -> XXX基本設計 | L1: 大分類 | V1: 中分類 | AF1: 小分類 | AP1: 作成者 | AU1: 作成日 | AZ1: 更新日
L2: =表紙!L2 -> 基本設計書 | V2: =表紙!V2 -> - | AF2: =RIGHT(CELL("filename",$A$2),LEN(CELL("filename",$A$2))-FIND("]",CELL("filename",$A$2))) -> ７．監視設計 | AU2: =表紙!AU2 -> 45078
A4: ７．監視設計
B6: ７．１． 監視設計方針
C7: (1) 本章は、システム監視で必要な項目について記載する。
C8: (2) 監視には、クレスコ社のCreageサービス（CreageOpe+ Silver）を用いる。
C9: (3) 監視対象は本番用リソースのみとし、検証用リソースは監視対象外とする。
C10: (4) システムログの保管については、AWSのサービスを用いて保管を行う。
B12: ７．２． 監視運用フロー
C13: 障害発生時の監視運用フローを以下に示す。
B20: ７．３． 監視体制と役割
C21: 障害発生時の体制と役割および運用時間について以下に示す。
D23: 以下の監視はCreageOpe+監視チームが行う。
D24: NO | G24: 作業項目 | N24: 対応時間 | Y24: 作業内容
D25: 1 | G25: システム監視 | N25: 0:00 ～ 24:00 365日対応 | Y25: システムの常時監視を実施
B28: ７．４．監視方式
C29: 本システムでは、以下の方式にて検知及び対応を行う。
C30: 監視は、以下の3項目に分けて実施する。
D32: NO | F32: 監視の種別 | K32: 概要
D33: 1 | F33: 死活監視 | K33: 監視対象の応答を確認し、応答がない（または）場合はエラー検知する。
C36: ７．４．１．死活監視
D37: ７．４．１．１．URI監視
E38: 指定した URI に対して HTTPSリクエストを送信し、レスポンスが返ってくるか、またレスポンスの内容を監視する。
E39: 監視設定のパラメータは、監視周期、レスポンスタイムアウト(秒、回数)の設定が可能である。
E40: 指定パラメータ以内に応答がない場合アラートを通知する。
E41: 本環境では監視周期=3分、レスポンスタイムアウト=5秒で3回とする。
E44: (１) 目的
F45: 本番用の Web サイト(master.XXX.click)を外部から監視して、その URL の正常性、およびパフォーマンスを監視する。
E47: (２) 方式
F48: 下記方式で監視を行う。
G49: ・定期的にURLを監視し、異常があればアラートを発砲する。
H50: ※監視URLは、監視周期毎（1周期=3分）にチェックされ、HTTPステータスが指定のステータスコード以外の場合にエラーとする。応答がない場合は、タイムアウト（秒）で設定した時間まで待機します。
H51: ※タイムアウトで設定した時間を超えて応答がない場合、リトライで設定した回数分ステータスコードを繰り返し確認する。（リトライ3回であれば、合計4回ステータスコードを確認)
H52: リトライ数＋1回目の確認時に応答がない場合に警報として検知する。
F55: 破線部分の機能要求詳細は以下の通り。
G56: NO | I56: 実装方式 | P56: 監視方式 | X56: 監視内容 | AT56: 機能要求 | BN56: 備考
G57: 1 | I57: Creageサービス | P57: URI監視 | X57: URIの応答により正常性を判断する | AT57: 監視要件の指定はない為、最大3分以内に検知する。
E59: (３) 監視対象
F60: 本方式による監視対象は以下の通り。
G61: NO | I61: 環境 | O61: コンポーネント | V61: 備考
...

Sheet ８．運用機能設計
A1: =表紙!A1 -> XXX基本設計 | L1: 大分類 | V1: 中分類 | AF1: 小分類 | AP1: 作成者 | AU1: 作成日 | AZ1: 更新日
L2: =表紙!L2 -> 基本設計書 | V2: =表紙!V2 -> - | AF2: =RIGHT(CELL("filename",$A$2),LEN(CELL("filename",$A$2))-FIND("]",CELL("filename",$A$2))) -> ８．運用機能設計 | AU2: =表紙!AU2 -> 45078 | AZ2: 45474
A4: ８．運用機能設計
B6: ８．１ 本システムでの運用機能について
C7: 本環境における運用について記載を行う。
B10: ８．２ 本システムでの運用機能一覧
C11: 運用機能として実装するものは下記のとおり。
D12: No | F12: 運用 | M12: 機能 | Z12: 実装方式 | AQ12: 実施者 | AX12: 備考
D13: 1 | F13: サイト開設 | M13: ヒアリングシート | Z13: システム構築に必要となる情報のヒアリングシート | AQ13: XXX | AX13: ヒアリングシートに必要となる情報を提示予定
M14: AWSアカウント提供 | Z14: 手順により実装 | AQ14: XXX/YYY | AX14: XXXで用意するユーザーの構築手順は提供予定
M15: 環境構築・検証 | Z15: CloudFormationにより実装する | AQ15: クレスコ
D16: 2 | F16: サイト閉塞 | M16: 依頼受領 | Z16: ー | AQ16: XXX
M17: 環境破棄 | Z17: シェルスクリプトの実行により実装する。 | AQ17: クレスコ | AX17: 90日間の閉鎖後期間を保持しない。
M18: AWSアカウント削除 | Z18: ー | AQ18: XXX/YYY
D19: 3 | F19: コンテンツリリース | M19: リリース運用 | Z19: コンソールでのドラッグドロップ | AQ19: XXX/外部ベンダー | AX19: Admin権限には CI/CDによる実装も可とする。
M20: 検証用Webサイトの検証完了後の運用 | Z20: 手順書により実装 | AQ20: XXX
D21: 4 | F21: メンテナンス | M21: ログ確認運用 | Z21: 手順書を別途作成する | AQ21: XXX
M22: アクセス数確認運用 | Z22: 手順書を別途作成する | AQ22: XXX
C25: ８．２．１．サイト開設
D26: （１）ヒアリングシート
E27: エンドユーザーに対してヒアリングを行い、個別環境のカスタマイズを実施する。
E28: ヒアリングはヒアリングシートに基づいて行う。
E30: 構築に係わるヒアリング内容は以下のとおり。
E31: ヒアリング内容 | Y31: 備考
E32: 本番・検証用ドメイン名
E33: ドメイン登録情報
E34: 証明書の発行要否 | Y34: ※外部発行時はACMのコンソール上でインポートをする
D37: （２）AWSアカウント発行・ユーザー作成
E38: YYY社がAWSアカウントを設定後、XXX社が自社管理用Adminユーザー及びクレスコ用Adminユーザーを作成する。
E39: 作成されたユーザーを使用して、クレスコが環境構築を実施する。
E40: XXX用Vendor権限ユーザーの１個目はクレスコが作成する。
E41: XXX用Vendor権限ユーザーの２個目以降は必要に応じてXXXが作成する。
E42: 共用環境の場合、サブディレクトリへの制御ポリシー及び、グループ＆ユーザーをXXX が作成する。
D44: （３）環境構築・検証
E45: 構築用ユーザーを使用して、CloudFormationを実行する。
E46: CloudFormationのテンプレートは、ヒアリング内容に沿って編集する。
C49: ８．２．２．サイト閉塞
D50: （１）依頼受領
E51: エンドユーザーからサイト閉塞の依頼を受領し、クレスコ社へリソース削除の依頼をする。
D54: （２）環境破棄
...

Sheet 別紙1.構成図
A1: =表紙!A1 -> XXX基本設計 | L1: 大分類 | V1: 中分類 | AF1: 小分類 | AP1: 作成者 | AU1: 作成日 | AZ1: 更新日
L2: =表紙!L2 -> 基本設計書 | V2: =表紙!V2 -> - | AF2: =RIGHT(CELL("filename",$A$2),LEN(CELL("filename",$A$2))-FIND("]",CELL("filename",$A$2))) -> 別紙1.構成図 | AP2: =表紙!AP2 -> 0 | AU2: =表紙!AU2 -> 45078 | AZ2: 45635
A3: 別紙1 | D3: 構成図
B4: 本構成で構築する環境は以下の通り。
D5: 本番環境
D20: 開発環境
D32: スパイク環境
