Workbook

Sheet 表紙
A1: POS Server2.0基本設計 | L1: 大分類 | V1: 中分類 | AF1: 小分類 | AP1: 作成者 | AU1: 作成日 | AZ1: 更新日
L2: 基本設計書 | V2: - | AF2: =RIGHT(CELL("filename",$A$2),LEN(CELL("filename",$A$2))-FIND("]",CELL("filename",$A$2))) -> 表紙 | AP2: 山本 | AU2: 45803
D9: POS Server2.0 基本設計書
AV16: 版番 | AZ16: 0.1

Sheet 変更履歴
A1: =表紙!A1 -> POS Server2.0基本設計 | L1: 大分類 | V1: 中分類 | AF1: 小分類 | AP1: 作成者 | AU1: 作成日 | AZ1: 更新日
L2: =表紙!L2 -> 基本設計書 | V2: =表紙!V2 -> - | AF2: =RIGHT(CELL("filename",$A$2),LEN(CELL("filename",$A$2))-FIND("]",CELL("filename",$A$2))) -> 変更履歴 | AP2: 山本 | AU2: 45803
B4: 発行日 | F4: 版 | I4: 変更箇所 | W4: 発行／改定内容 | BB4: 変更者
B5: 45803 | F5: 0.1 | W5: ドラフト版

Sheet 目次
A1: =表紙!A1 -> POS Server2.0基本設計 | L1: 大分類 | V1: 中分類 | AF1: 小分類 | AP1: 作成者 | AU1: 作成日 | AZ1: 更新日
L2: =表紙!L2 -> 基本設計書 | V2: =表紙!V2 -> - | AF2: =RIGHT(CELL("filename",$A$2),LEN(CELL("filename",$A$2))-FIND("]",CELL("filename",$A$2))) -> 目次 | AP2: 山本 | AU2: =表紙!AU2 -> 45803
B4: ０．はじめに | AH4: ６．ログ運用設計
C5: １．１．案件の目的 | AI5: ６．１ ログ運用方針
C6: １．２．本書の記述範囲 | AI6: ６．２ ログ運用
AI7: ６．３ ログ保管期間
B9: １．アカウント設計 | AH9: ７．バックアップ・リストア運用設計
C10: １．１．案件の目的 | AI10: ７．１ バックアップ・リストア運用方針
C11: １．２．本書の記述範囲 | AI11: ７．２ バックアップ運用
AI12: ７．３ リストア運用
B14: ２．システム構成 | AH14: ８．監視設計
C15: ２．１ 本環境構成 | AI15: ８．１ 監視方針
C16: ２．２ サービス一覧 | AI16: ８．２ 監視運用フロー
AI17: ８．３ 監視体制と役割
B18: ３．ネットワーク設計 | AI18: ８．４ 監視方式
C19: ３．１ XXX
AH20: ９．運用機能設計
B21: ４．可用性設計 | AI21: ９．１ 運用機能一覧
C22: ４．１ 可用性確保方式 | AI22: ９．２ 各運用機能方針
B24: ５．セキュリティ設計
C25: ５．１ セキュリティ方針
C26: ５．２ ネットワークセキュリティ
C27: ５．３ アクセス権限制御
C28: ５．４ セキュリティポリシー対応方針
C29: ５．５ SSLサーバ証明書

Sheet ０．はじめに
A1: =表紙!A1 -> POS Server2.0基本設計 | L1: 大分類 | V1: 中分類 | AF1: 小分類 | AP1: 作成者 | AU1: 作成日 | AZ1: 更新日
L2: =表紙!L2 -> 基本設計書 | V2: =表紙!V2 -> - | AF2: =RIGHT(CELL("filename",$A$2),LEN(CELL("filename",$A$2))-FIND("]",CELL("filename",$A$2))) -> ０．はじめに | AP2: =表紙!AP2 -> 山本 | AU2: =表紙!AU2 -> 45803
A3: ０．はじめに
B5: ０．１．案件の目的
C7: （１）各屋号共通目的
E8: 既存の富士通のシステムを入れ替えたい。 | BF8: 各屋号に対してオンプレミス上にあるPOSデータを毎朝送信するシステムを作成する。
E9: →背景は？？？？ | BF9: 屋号単位で細かな要件は存在するが、共通機能を整理し標準化を行う。
E10: USMHの4社を同じシステムで管理しコストを削減したい。 | BF10: 屋号で異なる要件が発生した場合は共通機能と異なる点を設計として残し、環境・運用をご提供する。
E11: ※富士通のコストが高い | BF11: AWSリセラーではない為、提供環境はサービスとして顧客提供するものとする。
E12: ※データ社4社バラバラ持っている | BF12: カスミは掲示板に表示する
E13: USMHで自社POSをもって外販していきたい。 | BF13: いなげやはPOS機能にマスタデータを表示する
C16: （２）個別目的
E17: カスミ
F18: 既定のタイミングでマスタデータをUSMH網経由してISHISDA電子棚札に対してデータ送付すること。
F19: 電子棚札への送付は大きく以下、三つの送付タイミングとなる
G20: ・毎朝
G21: ・随時
G22: ・予約時間
E24: いなげや
F25: マスタデータをUSMH網を経由してPOSアプリ端末に送付すること
F26: POSアプリで収集したデータをUSMH網を経由してオンプレミス環境のScan＆Goに送付すること。
B30: ０．２．本書の記述範囲
C31: 本書では、AWSに関する基本設計を記述範囲とする。
B33: ０．０．基本方針
C34: 利用するAWSとの責任分界点はAWSが提示している責任共有モデルに準じた実装とする。
C35: AWSのベストプラクティスに準じてシステム設計を行う。
C36: システムを実装するリージョンは東京リージョンを利用し、災対環境は考慮しない。
C37: USMH様網とAWS環境に構築するPOSサーバ 2.0間との通信は、
C38: 情報システム部が所管するAWS Direct Connect環境を利用した専用線網を利用し、通信を可能にする。
C39: 可用性を担保するため、マルチAZ構成でシステムを実装する。
C40: AWSサービス（CloudWatch、SNS等）を利用したシステム監視を実装する。
C41: インターネットアクセスから本システムにアクセスすることは原則禁止とし、本システムアクセスの場合はお客様提供のVPNを利用してアクセスを行う。
C42: スケーラビリティ、開発・保守䛾簡素化、コスト削減を最大化するために可能な限り、サーバレスでの構築を行う。
C43: 運用コスト・オペミス䛾リスク䛾軽減させるために、インフラはIaCで構築を行う。
C44: サービスダウンタイム軽減、障害未然防止するために、包括的䛺モニタリングを行う。
B46: ０．３．前提条件
C47: 本システムは2025年3月30日までに提供されたAWSサービスの仕様を基とする。
C48: 本システムのサービス提供中に、AWSによる仕様変更に伴い本書記載の設計と異なる動作が生じた場合は、都度協議の上で方式を見直す
C49: 以下、ガイドラインに準じたシステム構築を実施する
D50: ・今のところ特になし
...

Sheet １．アカウント設計
A1: =表紙!A1 -> POS Server2.0基本設計 | L1: 大分類 | V1: 中分類 | AF1: 小分類 | AP1: 作成者 | AU1: 作成日 | AZ1: 更新日
L2: =表紙!L2 -> 基本設計書 | V2: =表紙!V2 -> - | AF2: =RIGHT(CELL("filename",$A$2),LEN(CELL("filename",$A$2))-FIND("]",CELL("filename",$A$2))) -> １．アカウント設計 | AP2: =表紙!AP2 -> 山本 | AU2: =表紙!AU2 -> 45803
B4: １．アカウント設計
D6: AWSアカウントおよびIAMユーザについて以下に記載する。
B8: １．1．AWSアカウント
C10: （１） | E10: 方針
D11: ・AWSアカウントは、ルビナ社が発行したAWSアカウントを利用する。
D12: ・本番環境と開発環境でアカウントを分離する。
D13: ・各アカウントのルートユーザはルビナ社にて管理し、ルビナ社側で多要素認証（MFA）の設定を行う。
D14: ・AWSサポートプランは利用状況を加味し、適宜見直しをする。
C16: （２）AWSアカウント一覧
D17: 利用するAWSアカウントは以下の通り。
D19: # | F19: AWSアカウント | P19: 利用用途
D20: 1 | F20: スパイク環境アカウント | P20: スパイク環境を構築するAWSアカウント。既存のAndroidPoSアカウント上に構築する。
F21: （AndroidPoS）
D22: 2 | F22: 本番環境アカウント | P22: 本番サービスを提供するアカウント。
D23: 3 | F23: 開発環境アカウント | P23: ルビナ社にて検証に利用するアカウント。
B25: １．２．コスト配分
C27: （１）方針
D28: ・コスト配分タグを利用し、各屋号単位でのコストを明確化する。
D29: ・共通で利用しているコストについてはAWS利用の割合に応じて各屋号にコストを分配する。

Sheet ２．システム構成
A1: =表紙!A1 -> POS Server2.0基本設計 | L1: 大分類 | V1: 中分類 | AF1: 小分類 | AP1: 作成者 | AU1: 作成日 | AZ1: 更新日
L2: =表紙!L2 -> 基本設計書 | V2: =表紙!V2 -> - | AF2: =RIGHT(CELL("filename",$A$2),LEN(CELL("filename",$A$2))-FIND("]",CELL("filename",$A$2))) -> ２．システム構成 | AP2: 山本 | AU2: =表紙!AU2 -> 45803
B4: ２．システム構成
C6: （１）システム構成方針
D7: 本システムはアカウント単位で環境を分離する。
D8: AWS環境とオンプレミスを繋ぐDirectConectGatewayの接続上限が20VPCという制限があるため、屋号単位でのAWSアカウントは作成しない。
D9: 本番、開発環境において1アカウント１VPCで構成する。尚、屋号のNW分離についてはサブネットで分離する。
D10: 各屋号で共通で利用するリソース（VPCエンドポイント等）はコスト削減の観点で共通化する。
C12: （２）各環境定義
D13: 各環境の定義は以下の通り。
D14: ＃ | E14: 環境 | J14: 用途
D15: 1 | E15: 本番環境 | J15: 本番サービスを提供する環境とする。
D16: 2 | E16: 開発環境 | J16: USMH様にて業務機能の検証を行う環境とする。
D17: 3 | E17: スパイク環境 | J17: ルビナ社にて検証を行う環境とする。
B19: ２．１ 環境構成
D20: 別紙、「別紙1.構成図」を参照
B22: ２．２ サービス一覧
C23: 本環境で利用するAWSサービス一覧は以下のとおり。 | AI23: ;
B24: No | C24: 利用サービス一覧 | Q24: サービス説明 | AI24: 用途
B25: 1 | C25: AWS Transfer Family for SFTP | Q25: AWSの他のシステム、例えばS3アプリケーションなどと結合 | AI25: マスタファイルをSFTPで入出力するために使用
Q26: 可能なアプリケーション転送に特化したサービス
B27: 2 | C27: AWS Lambda | Q27: AWSのイベントの受信、フィルタリング、変換、ルーティン | AI27: マスタファイルの変換処理や送信を行う
Q28: グ、および配信を可能にするサービス
B29: 3 | C29: Amazon EventBridge | Q29: AWS、既存のシステム、または SaaS アプリケーション全体で | AI29: S3バケットにファイルが配置されたタイミングをトリガーとして、
Q30: イベント駆動型アプリケーションを大規模に構築するサービス | AI30: Lambdaを実行する
B31: 4 | C31: AWS Step Functions | Q31: 複数のAWSサービスを連携させ、ワークフローを簡単に構築・ | AI31: ファイルを分散処理することで、処理の高速化を実現する
Q32: 管理するためのサービス
B33: 5 | C33: Amazon S3 | Q33: 高可用性のオブジェクトストレージ機能を提供するサービス | AI33: マスタファイルやトランファイルを保存する
B34: 6 | C34: Application Load Balancer | Q34: アプリケーション層でのトラフィックのルーティング、ロード | AI34: 管理画面へのアクセスに対して、負荷分散をする
Q35: バランシングを提供するサービス
B36: 7 | C36: Amazon Elastic Container Service (ECS) | Q36: コンテナ化されたアプリケーションの管理とオーケストレーシ | AI36: POS用マスタファイルの作成やDB登録用のデータの変換など行う
Q37: ョンを提供するサービス
B38: 8 | C38: Amazon Elastic Container Registry (ECR) | Q38: Kubernetesクラスターを簡単にデプロイ、管理、スケーリング | AI38: アプリケーションのイメージを保管する
Q39: するためのサービス
B40: 9 | C40: NAT Gateway | Q40: プライベートサブネットからインターネットへ接続するための | AI40: プライベートサブネットにあるECSのコンテナイメージをECRから取得す
Q41: 中継機能を提供し、アウトバウンドインターネットアクセスを | AI41: るために使用
Q42: 許可するサービス
B43: 10 | C43: Amazon Aurora | Q43: 高いパフォーマンスと可用性を持つリレーショナルデータベー | AI43: マスタ情報や集計情報をデータ保存する
Q44: スサービス
B45: 11 | C45: AWS Secrets Manager | Q45: アプリケーションやサービスで必要な秘密情報（APIキーやパス | AI45: SFTP通信をする際に必要な、SSH鍵を保管する
...

Sheet ３．ネットワーク設計
A1: =表紙!A1 -> POS Server2.0基本設計 | L1: 大分類 | V1: 中分類 | AF1: 小分類 | AP1: 作成者 | AU1: 作成日 | AZ1: 更新日
L2: =表紙!L2 -> 基本設計書 | V2: =表紙!V2 -> - | AF2: =RIGHT(CELL("filename",$A$2),LEN(CELL("filename",$A$2))-FIND("]",CELL("filename",$A$2))) -> ３．ネットワーク設計 | AP2: 山本 | AU2: 45803
B4: ３．ネットワーク設計
C6: （１） | E6: 全体方針
D7: ・1つの屋号で障害が発生しても、他の屋号に影響が出ないようにネットワークを屋号単位で分離したネットワーク構成とする。
D8: ・インターネットからのインバウンド接続は極力避け、可能な限りプライベート接続を行う。
D9: ・インターネットへのアウトバウンドについては利用用途を明確にする。
D10: ・AWSのグローバルリソースにアクセスする際は、可能な限りエンドポイントを利用しセキュアな通信を行う。
D11: ・他システム連携に名前解決を行わずIPアドレス接続を行うようにする。
D12: ・IPが固定できない場合の要件がある場合はその都度検討する。
D13: ・共通領域以外は各屋号での通信は行わない。
B15: ３．１．仮想ネットワーク設計
C17: ・AWS環境のネットワークは、AWSの仮想ネットワークサービスであるVPC（Virtual Private Cloud）を用いる。
C18: ・AWS環境のネットワーク構成は、AWS内に閉じた通信先を用途毎にCommon Subnet、Public Subnet、Private Subnet、Protected Subnet
C19: 分割し、サブネットに対してAWSのルートテーブル機能を用いて通信先を制御する。
C20: ・共通で利用するエンドポイントについてはCommon Subnetを設計するが、作成は行わない。
C21: ・DBを配置しない屋号に対してもProtected Subnetを設計するが、作成は行わない。
C22: ・VPCサブネット間通信やVPC外部への通信経路制御は、ルートテーブル機能とセキュリティグループ機能、ネットワークACL機能を用いて実現する。
C23: ・通信元からの通信制御は基本的にセキュリティグループにて実施し、ネットワークACLでは特に制御を行わない。
C24: ・１VPCに屋号単位でサブネットを分割する。
C26: （1） | E26: 全体ネットワーク
E27: 全体ネットワーク構成概要は以下の通り。
C51: （２） | E51: AWS内ネットワーク
E52: AWS内のネットワーク構成要素は以下の通り。
B85: ３．２．VPC／サブネット設計
C87: ・屋号を論理的にNW分離を行う。
C88: ・NW分離はサブネット単位に行い、通信制御は通信元で制御を行う。
C89: ・屋号単位でサブネットマスク/23でIPを払い出す。
C90: ・屋号単位で払い出した領域については、IPの余剰が無いように設計する。
C91: ・共有領域について屋号と同一に切り出す。今後の拡張を見越して余剰のIPを確保する。
C92: ・使用しないサブネットにおいても設計、構築は実施する。
C94: （１） | E94: VPC設計
E95: 各環境のVPCに割り当てるアドレス領域は以下の通り。
E97: # | G97: VPC | O97: VPC CIDR | W97: アカウント
E98: 1 | G98: スパイク環境 | O98: 10.226.51.0/24 | W98: AndroidPosアカウント
E99: 2 | G99: 本番環境 | O99: 10.238.0.0/16 | W99: 本番アカウント
E100: 3 | G100: 開発環境 | O100: 10.239.0.0/16 | W100: 開発アカウント
C102: （２） | E102: サブネット設計
E103: サブネットは、用途毎に以下4つに分割する。
E105: ＃ | G105: サブネット | P105: 用途
...

Sheet ４．可用性設計
A1: =表紙!A1 -> POS Server2.0基本設計 | L1: 大分類 | V1: 中分類 | AF1: 小分類 | AP1: 作成者 | AU1: 作成日 | AZ1: 更新日
L2: =表紙!L2 -> 基本設計書 | V2: =表紙!V2 -> - | AF2: =RIGHT(CELL("filename",$A$2),LEN(CELL("filename",$A$2))-FIND("]",CELL("filename",$A$2))) -> ４．可用性設計 | AP2: 山本 | AU2: =表紙!AU2 -> 45803
B4: ４．可用性設計
C6: （１） | E6: 全体方針
E7: ・本システムにて使用するAWSサービスについてAZ障害に耐えうる可用性確保のため、マルチAZ構成とする。
E8: ・一つのAZに障害発生が発生した場合でも業務継続できる設計とする。
E9: ・データ連携先のシステムの障害や各AWSコンポーネントの二重障害は対象外とする。
E10: ・AWSのサービス自体の可用性はAWSの公開するSLAを基準とする。
E11: ※AWS SLA：https://aws.amazon.com/jp/legal/service-level-agreements/
B13: ４．1．可用性確保方式
C15: （１） | E15: システムの可用性確保方式
E16: 以下の可用性確保方式によってシステム可用性を担保する。方式はAWSよって提供される可用性確保方式を利用するものとする。
E18: Ａ．マルチAZ方式
E19: 本システムではAWS 東京リージョン内で2つのAZを使用したマルチAZ構成とする。
E20: 以下のサービスにおいてマルチAZ方式を使用する。
E22: No | G22: AWSサービス | N22: 詳細
E23: 1 | G23: VPC | N23: AWS上の仮想ネットワーク。マルチAZ構成とする。
E24: 2 | G24: ALB | N24: HTTP/HTTPSトラフィックの負荷分散を行う。ALBは制約で2つ以上のAZに紐づける必要があり、WAFを使用するために必要。
N25: 単一障害対策のためにクロスゾーン負荷分散を有効にする。
N26: ターゲットグループを設定することでトラフィック先のリソースを指定できる。
N27: リスナールールを設定することで特定のプロトコルとポート番号を受けることができる。
E28: 3 | G28: ECS
E32: 4 | G32: Lambda
E36: 5 | G36: VPCエンドポイント | N36: エンドポイントのインターフェイスはマルチAZ構成とする。
N37: FQDNでのアクセスにより、正常系にアクセス可能。
E39: B．業務停止時のデータ復旧
E40: 以下のサービスにおいて障害発生時に利用可能なバックアップからインスタンスを復元することで業務の継続を図る。
E42: No | G42: AWSサービス | N42: 詳細
E43: 1 | G43: Aurora MySQL | N43: AWS Backupにより日次でバックアップの取得を行う。
N44: ポイントインタイムリカバリ機能で可能な限り障害発生時点まで復旧できるようにする。
E46: C．オートスケーリング
E47: 以下のサービスにおいてリソース利用状況に応じて自動的に不足リソースを追加、削除することで、常に最適なリソースを確保し、負荷に対応し業務の継続を図る。
E49: No | G49: AWSサービス | N49: 詳細
E50: 1 | G50: ALB | N50: トラフィック量に応じてAWS側で自動でスケーリングあれる
E52: 2 | G52: Aurora MySQL | N52: 事前に設定した最小・最大容量を基に自動でスケーリングされる
G53: Serverless
E54: 3 | G54: ECS | N54: CPUorメモリ使用率に応じてECSのスケーリングを行う
C58: （２） | E58: システムの可用性確保方式詳細
E59: 可用性確保方式の動作について詳細を記載する。
E60: 要件を満たすため、本システムは次の方針で設計を行う。
...

Sheet ５．セキュリティ設計
A1: =表紙!A1 -> POS Server2.0基本設計 | L1: 大分類 | V1: 中分類 | AF1: 小分類 | AP1: 作成者 | AU1: 作成日 | AZ1: 更新日
L2: =表紙!L2 -> 基本設計書 | V2: =表紙!V2 -> - | AF2: =RIGHT(CELL("filename",$A$2),LEN(CELL("filename",$A$2))-FIND("]",CELL("filename",$A$2))) -> ５．セキュリティ設計 | AP2: 山本 | AU2: =表紙!AU2 -> 45803
B4: ５．セキュリティ設計
C6: （１） | E6: 全体方針
D7: ・AWSが提供する機能を利用することで、効率よくセキュリティの確保を行う。
D8: ・リリース時にAWSが提供する機能の脆弱性が出ていないことを確認すること。
D9: ・定期的に脆弱性を確認し、脆弱性の対応を行うこと。
D10: ・各リソース間の通信Portを明確にし、余計なPortの開放は行わない。
D11: ・作成するユーザについては個人別に作成すること。共有ユーザは許可しない。
D12: ・利用するIAMユーザー用のポリシーについては、業務処理に最低限必要な権限を付与することで、セキュリティ的なリスクを回避する。
B14: ５．１ ネットワークセキュリティ
D15: ・AWSリソースへの通信は暗号化されたセキュアな通信を行う。
D16: ・AWSリソースへのアクセス制御はアクセス先でアクセス制御を行う。
D17: ・AWSリソースにおいてはAWSの機能であるセキュリティグループの機能を行い制御する。
D18: ・セキュリティグループを付与したリソース同士の制御はセキュリティグループのIDで送信元を制御する。
D19: ・送信元が絞れない場合は可能な限り小さいなサブネット帯を指定するものとする。
D20: ・インターネットからのアクセスがある場合は、ファイアウォール機能を利用する。
B22: ５．２ データ保護
D23: ・ディスクレベルの暗号化を設定する。
D24: ・機密性の高いDBのデータについては、データ暗号化を用いる。
D25: ・データのアクセスについては適切なユーザがアクセスできるように権限の制御を行う。
B27: ５．３．アクセス管理
D28: ・AWSリソースへのアクセス制御は、IAMの機能を利用して実現する。
D29: ・IAM以外にアクセス権が制御できるサービスについては設計方針を定める。
D30: ・IAMのユーザ、ポリシー、グループ、ロール機能に適切な権限を付与し、アクセスを制御する。
E32: # | G32: IAM機能 | M32: 利用用途
E33: 1 | G33: ユーザ | M33: AWS環境を運用する個人に対してアクセス権を付与する。
E34: 2 | G34: ポリシー | M34: ユーザ、グループ、ロールに対する権限を定義する。
E35: 3 | G35: グループ | M35: 役割に応じて、複数のユーザを所属させ、効率的なアクセス管理を実施する。
E36: 4 | G36: ロール | M36: AWSリソースやサービスに対して権限を付与し、アクセス管理を実施する。
D38: ・不正アクセスを防ぐため、AWSマネジメントコンソールへのログイン時はMFAを必須とする。
D39: ・アカウントを払い出された際に発行されるAWSアカウント管理者は、同等の権限を持つシステム管理グループを作成し、IAMユーザーを紐付けた後、
D40: セキュリティの観点から削除する。
C42: （１）IAM構成概要
D43: IAM構成概要は以下の通り。
C73: （２）IAMユーザ
E74: ・IAMユーザは、個人単位で作成し、役割に応じたIAMグループに所属させる。
E75: ・IAMユーザ名は原則メールアドレスを利用する。
C77: （３）IAMユーザのパスワードポリシー
E78: パスワードポリシー設定はカスタムパスワードポリシーを全て以下の通り設定する。
...

Sheet ６．ログ運用設計
A1: =表紙!A1 -> POS Server2.0基本設計 | L1: 大分類 | V1: 中分類 | AF1: 小分類 | AP1: 作成者 | AU1: 作成日 | AZ1: 更新日
L2: =表紙!L2 -> 基本設計書 | V2: =表紙!V2 -> - | AF2: =RIGHT(CELL("filename",$A$2),LEN(CELL("filename",$A$2))-FIND("]",CELL("filename",$A$2))) -> ６．ログ運用設計 | AP2: 山本 | AU2: =表紙!AU2 -> 45803
B4: ６．ログ運用設計
C6: （１） | E6: 全体方針
D7: ・システムの状態を収集してモニタリング、異常が発生していないか監視を行う必要がある。
D8: ・システムがどのように利用されているかを把握するための情報を集め、メトリクスやログの収集、監視や可視化を行う。
B10: 6．１ ログ運用
C11: 保管先がS3に指定されているサービスはS3に保管する。
C12: それ以外のログについては、CloudWatchLogsにてログ運用を行う。
C13: S3は標準クラスを使用し、ストレージクラスの移行は行わない。
C15: ログ運用が必要となる対象を以下に記載する。
C16: サービス名（ログ取得対象） | M16: ログ内容 | AJ16: ログデータ保管 | AQ16: ログデータ保管期間
C17: CloudTrail | M17: ユーザー、ロール、または AWS のサービスによって実行された | AJ17: S3 | AQ17: 13ヶ月(400日)
M18: アクションを記録する。
C19: ALB | M19: アクセスログを記録する。 | AJ19: S3 | AQ19: 13ヶ月(400日)
C21: Lambda | M21: Lambda実行に対する詳細なログを出力する。 | AJ21: CloudWatchLogs | AQ21: 13ヶ月(400日)
B24: 6．３ ログ保管期間経過後の対応
C25: 保管期間を超過したログについては、費用圧縮の観点から削除する。

Sheet 7．バックアップ・リストア設計
A1: =表紙!A1 -> POS Server2.0基本設計 | L1: 大分類 | V1: 中分類 | AF1: 小分類 | AP1: 作成者 | AU1: 作成日 | AZ1: 更新日
L2: =表紙!L2 -> 基本設計書 | V2: =表紙!V2 -> - | AF2: =RIGHT(CELL("filename",$A$2),LEN(CELL("filename",$A$2))-FIND("]",CELL("filename",$A$2))) -> 7．バックアップ・リストア設計 | AP2: 山本 | AU2: =表紙!AU2 -> 45803
B4: ７．バックアップ・リストア運用設計
C6: （１） | E6: 全体方針
D7: ・AWSが提供する機能を利用することで、バックアップ・リストア運用を実現する。
D8: ・システムバックアップについては構築する際のリポジトリを利用する。
D9: ・データバックアップについては、DBログを使用した時間指定のリストアを実現するためポイントインタイムリカバリ機能（以下、PITR）を有効化したバックアップを利用する。
D10: ・東京リージョン以外へのバックアップは実施しない。
D11: ・法的・規制要件による一定期間のデータ保存要求を満たすため、バックアップを取得する。
B13: ７．２ バックアップ・リストア運用
D14: ・本システムのバックアップ対象はマスタデータ、ログとなり、以下サービスを利用してバックアップを実装する。
E15: No | G15: バックアップ対象物 | U15: 利用サービス | AF15: リストア方法
E16: 1 | G16: インスタンス（Aurora MySQL） | U16: AWS Backup | AF16: PITRによるリストア
E17: 2 | G17: ログ（OS、AWS等） | U17: CloudWatch Logs、S3 | AF17: バックアップファイル取得によるリストア
C19: （１） | E19: バックアップ設計方式
D20: ・バックアップツールとしてAWS Backupを利用する。
D21: ・各バックアップ対象物の実装は、「バックアップ対象物、環境、バックアップ」の単位でAWS Backupのバックアッププランを作成し、実装する。
D22: ・バックアッププランでバックアップ頻度、保持期間、PITRの実行を実装する。
D23: ・バックアップ対象物の一元管理を念頭に作成するバックアップボールトは環境毎（本番、開発）に1つバックアップボルトを作成し、実装する。
D24: ・バックアップボールトは、AWSのカスターマスターキーを使用した暗号化を実装する。
D25: ・本システムでのバックアップ対象は以下となる。
E27: No | G27: バックアップ対象物 | O27: 環境 | S27: バックアップ頻度 | Z27: 保持期間 | AE27: PITR | AI27: バックアッププラン
E28: 1 | G28: インスタンス | O28: 本番 | S28: 日次 | Z28: 5日 | AE28: 有効 | AI28: DBサーバ本番日次用バックアッププラン
G29: （Aurora MySQL)
E30: 2 | G30: インスタンス | O30: 開発 | S30: 日次 | Z30: 5日 | AE30: 無効 | AI30: DBサーバ開発日次用バックアッププラン
G31: （Aurora MySQL)

Sheet 8．監視設計
A1: =表紙!A1 -> POS Server2.0基本設計 | L1: 大分類 | V1: 中分類 | AF1: 小分類 | AP1: 作成者 | AU1: 作成日 | AZ1: 更新日
L2: =表紙!L2 -> 基本設計書 | V2: =表紙!V2 -> - | AF2: =RIGHT(CELL("filename",$A$2),LEN(CELL("filename",$A$2))-FIND("]",CELL("filename",$A$2))) -> 8．監視設計 | AP2: 山本 | AU2: =表紙!AU2 -> 45803
B4: 8．監視設計
C6: （１） | E6: 全体方針
D7: ・本章は、システム監視で必要な項目について記載する。
D8: ・ 監視には、AWS機能のCloudWatch＋SNSを用いる。
D9: ・ 監視は24時間365日で実施する。
D10: ・ インシデント発生時はルビナ社の営業日にベストエフォートにて対応をする。
D11: ・ 監視対象は本番用リソースのみとし、検証用リソースは監視対象外とする。
B13: 8．１． 監視運用フロー
C14: 障害発生時の監視運用フローを以下に示す。
B21: 8．２． 監視体制と役割
C22: 障害発生時の体制と役割および監視時間について以下に示す。
C24: （１） | E24: 体制図
C36: （２） | E36: 役割
E37: # | G37: 担当者 | O37: 役割
E38: 1 | G38: システム管理者 | O38: 状況整理、お客様エスカレーション
E39: 2 | G39: アプリメンバー | O39: エラー内容分析、アプリエラー対応、システム管理者へのエスカレーション
E40: 3 | G40: インフラメンバー | O40: エラー内容分析、インフラエラー対応、アプリメンバー、システム管理者へのエスカレーション
B42: 8．3．監視方式
C43: 本システムでは、以下の方式にて検知及び対応を行う。
E45: No | G45: 監視種別 | P45: 概要
E46: 1 | G46: 死活監視 | P46: システム内のリソースが正常に稼働していることを確認するための監視。
E47: 2 | G47: リソース監視 | P47: リソース使用量（CPU、メモリ等）が正常かを確認するための監視。
E48: 3 | G48: ログ監視 | P48: アプリケーションのエラーログを検知するための監視。
E49: 4 | G49: セキュリティ監視 | P49: 脆弱性やセキュリティインシデントを検知するための監視。
E51: 監視対象
E52: No | G52: 監視対象 | U52: 監視種別 | AB52: 監視方式 | AI52: 備考
E53: 1 | G53: Transfer Family | U53: 死活監視 | AB53: Health Dashboard
E54: 2 | G54: Lambda | U54: 死活監視 | AB54: Health Dashboard
E55: 3 | U55: ログ監視 | AB55: CloudWatch Logs
E56: 4 | G56: ECS | U56: 死活監視 | AB56: Health Dashboard
E57: 5 | U57: ログ監視 | AB57: CloudWatch Logs
E58: 6 | G58: Aurora MySQL | U58: 死活監視 | AB58: Health Dashboard
E59: 7 | U59: リソース監視 | AB59: CloudWatchメトリクス
E60: 8 | U60: ログ監視 | AB60: CloudWatch Logs
E61: 9 | G61: SNS | U61: 死活監視 | AB61: Health Dashboard
E62: 10 | G62: S3 | U62: 死活監視 | AB62: Health Dashboard
E63: 11 | G63: CloudWatch | U63: 死活監視 | AB63: Health Dashboard
E64: 12 | G64: ECR | U64: 死活監視 | AB64: Health Dashboard
...

Sheet 9．運用機能設計
A1: =表紙!A1 -> POS Server2.0基本設計 | L1: 大分類 | V1: 中分類 | AF1: 小分類 | AP1: 作成者 | AU1: 作成日 | AZ1: 更新日
L2: =表紙!L2 -> 基本設計書 | V2: =表紙!V2 -> - | AF2: =RIGHT(CELL("filename",$A$2),LEN(CELL("filename",$A$2))-FIND("]",CELL("filename",$A$2))) -> 9．運用機能設計 | AU2: =表紙!AU2 -> 45803
B4: ９．運用機能設計
C6: （１） | E6: 全体方針
B14: 9．１．運用時間
C16: オンラインサービス時間、バッチ処理時間およびシステムメンテナンスの時間帯は以下の通り。
C17: 開発環境についても本番環境と同様とする。
C19: （１） | E19: オンラインサービス時間
D21: POS Serverのサービス提供時間帯は以下の通り。
D23: # | F23: サービス提供時間帯 | N23: 備考
D24: 1
C26: （２） | E26: バッチ処理時間
D28: バッチ処理の設計はルビナアプリチームにて設計する。
D29: バッチ処理時間は以下の通り。
D31: # | F31: 対象 | Q31: 処理時間帯 | AC31: 備考欄
D32: 1 | Q32: 日次
D33: 2
D35: 3 | Q35: 月次
D39: 4 | Q39: 年次
C44: （３） | E44: システムメンテナンス
D46: メンテナンス作業が必要な場合は、以下の時間帯で計画停止を行う。
D47: 計画停止を行う場合は関連部署へ事前アナウンスが必要となるため、XX日前に通知する。
D49: # | F49: メンテナンス時間帯 | P49: 備考
D50: 1 | F50: 毎週日曜日 XX:XX ~ YY:YY | P50: メンテナンス作業が無い場合は通常通りサービスを提供する。
B52: 9．1．通常運用
B54: 9．1．１．定期運用
C56: 定期運用の運用項目は以下の通り。
D58: タイミング | I58: 運用項目 | T58: 実行方式 | AC58: 内容
D59: 日次 | I59: バックアップ（データ） | T59: ・Systemwalker Operation | AC59: APサーバにDBサーバから取得した業務データをSystemwalker Operation
T60: Manager | AC60: Managerでスクリプト実行し、東京リージョンのS3へアップロードする。
T61: ・S3
I62: バックアップ（インスタンス） | T62: ・AWS Backup | AC62: ・インスタンス全体のバックアップを東京リージョンに取得する。
AC63: ・DBサーバはポイントインタイムリカバリを有効化し、バックアップを取得する。
D64: 月次
I70: 月次レポート報告 | T70: ・XXX | AC70: パッチリリース情報、不正検知結果件数を報告する。
D71: 年次
I76: ID管理 | T76: ・IAM | AC76: 年次でID棚卸を行い、必要に応じて変更、削除を実施する。
D77: 随時 | I77: システム監視 | T77: ・CloudWatch | AC77: システムの障害発生を検知し、担当者への通知を行う。
T78: ・SNS
I79: アクセス管理 | T79: ・IAM | AC79: ・通信元のIP制限、適切な権限をIAMグループにIAMロールに付与する。
...

Sheet 大生対応中→

Sheet 別紙1.構成図
A1: =表紙!A1 -> POS Server2.0基本設計 | L1: 大分類 | V1: 中分類 | AF1: 小分類 | AP1: 作成者 | AU1: 作成日 | AZ1: 更新日
L2: =表紙!L2 -> 基本設計書 | V2: =表紙!V2 -> - | AF2: =RIGHT(CELL("filename",$A$2),LEN(CELL("filename",$A$2))-FIND("]",CELL("filename",$A$2))) -> 別紙1.構成図 | AP2: =表紙!AP2 -> 山本 | AU2: =表紙!AU2 -> 45803
A3: 別紙1 | D3: 構成図
B4: 本構成で構築する環境は以下の通り。
D5: 本番環境
D25: 開発環境
D37: スパイク環境

Sheet 別紙2.システム間通信
A1: =表紙!A1 -> POS Server2.0基本設計 | L1: 大分類 | V1: 中分類 | AF1: 小分類 | AP1: 作成者 | AU1: 作成日 | AZ1: 更新日
L2: =表紙!L2 -> 基本設計書 | V2: =表紙!V2 -> - | AF2: =RIGHT(CELL("filename",$A$2),LEN(CELL("filename",$A$2))-FIND("]",CELL("filename",$A$2))) -> 別紙2.システム間通信 | AP2: =表紙!AP2 -> 山本 | AU2: =表紙!AU2 -> 45803
A3: 別紙2 | D3: システム間通信
D6: データ受け取り概要
D37: データ送信概要（取得にくるかも）
