Workbook
Name _生産性_設定値: [2]生産性基準!$I$20:$R$29
Name a: [3]部品!$B$2:$B$27
Name aa: SUM(#REF!)
Name aa: SUM(#REF!)
Name Android_集計: #REF!
Name Android_集計: #REF!
Name b: [3]部品!$B$2:$B$27
Name iPhone_集計: #REF!
Name iPhone_集計: #REF!
Name Level: '[4]Do kho-ty le'!$B$20:$B$24
Name Level: '[5]Do kho-ty le'!$B$20:$B$24
Name MsgSample2: マスタースケジュール!MsgSample2
Name MsgSample2: [0]!MsgSample2
Name PG工数: [6]見積基準値!$I$5:$I$98
Name PG単価: #REF!
Name PG単価: #REF!
Name ｐｐ: #REF!
Name ｐｐ: #REF!
Name s: [3]部品!$B$2:$B$27
Name SE単価: #REF!
Name SE単価: #REF!
Name uyyyu: SUM(#REF!)
Name uyyyu: SUM(#REF!)
Name U数_除外製品: [8]構成DB!$G$76:$G$116
Name WEB_集計: #REF!
Name WEB_集計: #REF!
Name WEB表示パターンLIST: [9]部品!$I$2:$I$8
Name ZeeM変動要素: '[6]見積基準値(変動係数)'!$C$25:$C$28
Name ｚｚ: #REF!
Name ｚｚ: #REF!
Name あ: #REF!
Name オンバッチLIST: #REF!
Name クレジット加盟店番号・連絡先: #REF!
Name サマリ_画面_削除: SUM(#REF!)
Name サマリ_画面_削除: SUM(#REF!)
Name サマリ_画面_削除_Android: SUM(#REF!)
Name サマリ_画面_削除_Android: SUM(#REF!)
Name サマリ_画面_削除_iPhone: SUM(#REF!)
Name サマリ_画面_削除_iPhone: SUM(#REF!)
Name サマリ_画面_削除_WEB: SUM(#REF!)
Name サマリ_画面_削除_WEB: SUM(#REF!)
Name サマリ_画面_削除_バッチ: SUM(#REF!)
Name サマリ_画面_削除_バッチ: SUM(#REF!)
Name サマリ_画面_修正: SUM(#REF!)
Name サマリ_画面_修正: SUM(#REF!)
Name サマリ_画面_修正_Android: SUM(#REF!)
Name サマリ_画面_修正_Android: SUM(#REF!)
Name サマリ_画面_修正_iPhone: SUM(#REF!)
Name サマリ_画面_修正_iPhone: SUM(#REF!)
Name サマリ_画面_修正_WEB: SUM(#REF!)
Name サマリ_画面_修正_WEB: SUM(#REF!)
Name サマリ_画面_修正_バッチ: SUM(#REF!)
Name サマリ_画面_修正_バッチ: SUM(#REF!)
Name サマリ_画面_新規: SUM(#REF!)
Name サマリ_画面_新規: SUM(#REF!)
Name サマリ_画面_新規_Android: SUM(#REF!)
Name サマリ_画面_新規_Android: SUM(#REF!)
Name サマリ_画面_新規_iPhone: SUM(#REF!)
Name サマリ_画面_新規_iPhone: SUM(#REF!)
Name サマリ_画面_新規_WEB: SUM(#REF!)

Sheet 表紙
A1: システム名 | K1: システム種類 | W1: 見積 | AP1: 作成者 | AT1: 作成日 | AY1: 更新者 | BC1: 更新日 | BH1: バージョン
A2: セルフPOS | K2: POSサーバ | AP2: =改訂履歴!$H$11 -> XoaLT | AT2: =改訂履歴!$B$11 -> 45408 | AY2: =LOOKUP(2,1/(改訂履歴!H11:H30000<>""),改訂履歴!H11:H30000) -> XoaLT | BC2: =LOOKUP(2,1/(改訂履歴!B11:B30000<>""),改訂履歴!B11:B30000) -> 45408 | BH2: =LOOKUP(2,1/(改訂履歴!O11:O30000<>""),改訂履歴!O11:O30000) -> 0.1
A4: 昨日カテゴリー | H4: 機能概要 | U4: 項目 | Z4: 業務フロー | AP4: 表紙
L16: セルフPOS
L24: =K2&"/"&H4&"/"&Z4 -> POSサーバ/機能概要/業務フロー
Q44: Ngày phê chuẩn | AA44: Người phê chuẩn | AQ44: Version

Sheet 改訂履歴
A1: システム名 | K1: システム種類 | W1: 見積 | AP1: 作成者 | AT1: 作成日 | AY1: 更新者 | BC1: 更新日 | BH1: バージョン
A2: セルフPOS | K2: POSサーバ | AP2: =改訂履歴!$H$11 -> XoaLT | AT2: =改訂履歴!$B$11 -> 45408 | AY2: =LOOKUP(2,1/(改訂履歴!H11:H30000<>""),改訂履歴!H11:H30000) -> XoaLT | BC2: =LOOKUP(2,1/(改訂履歴!B11:B30000<>""),改訂履歴!B11:B30000) -> 45408 | BH2: =LOOKUP(2,1/(改訂履歴!O11:O30000<>""),改訂履歴!O11:O30000) -> 0.1
A4: 昨日カテゴリー | H4: 機能概要 | U4: 項目 | Z4: 業務フロー | AP4: 改訂履歴
B8: ■History
B10: 更新日 | H10: 更新者 | O10: バージョン | S10: 更新内容 | AX10: Ngày phê chuẩn | BD10: Người phê chuẩn
B11: 45408 | H11: XoaLT | O11: 0.1 | S11: 新規作成

Sheet まとめ
A1: システム名 | K1: システム種類 | W1: 見積 | AP1: 作成者 | AT1: 作成日 | AY1: 更新者 | BC1: 更新日 | BH1: バージョン
A2: セルフPOS | K2: POSサーバ | AP2: =改訂履歴!$H$11 -> XoaLT | AT2: =改訂履歴!$B$11 -> 45408 | AY2: =LOOKUP(2,1/(改訂履歴!H11:H30000<>""),改訂履歴!H11:H30000) -> XoaLT | BC2: =LOOKUP(2,1/(改訂履歴!B11:B30000<>""),改訂履歴!B11:B30000) -> 45408 | BH2: =LOOKUP(2,1/(改訂履歴!O11:O30000<>""),改訂履歴!O11:O30000) -> 0.1
A4: 昨日カテゴリー | H4: 機能概要 | U4: 項目 | Z4: 業務フロー | AP4: 改訂履歴
D7: A.前提
E8: 1.インプット、アウトプット
G9: インプット
H10: 資料：POSサーバー_機能概要
L11: Version 0.2
H12: 借りていただいたパソコンで操作
G14: アウトプット
H15: 各機能の機能概要_画面遷移資料
L16: 機能概要説明
L17: 機能概要
H18: 以下の情報をPOSサーバ_機能概要には
L19: 画面一覧（20_画面設計）
L20: 機能一覧（30_機能設計）
L21: API一覧（40_API設計）
H22: ●バッチ処理
G23: ※ソースコード、プログラミングは別途見積
H25: 画面のXD作成は清原さんが担当
I26: →今度見積なし
E28: 2.やり取り
G29: 次週、お客様と打ち合わせを行う。その場で、各機能についてご相談を行い、お客様のご意見をいただく
G30: お客様のご担当
G31: 時間：次週の水、金
G32: Luvina側の担当者：清原、AnhNM、HuyVQ
D34: B.見積
H36: 項目 | R36: 数量 | X36: 単位 | AC36: 備考
H37: システムの理解 | R37: =機能一覧!BS6 -> 1.295625 | X37: MM
H38: 機能概要資料作成 | R38: =機能一覧!BT6 -> 4.31875 | X38: MM
H39: 内部レビュー | R39: =機能一覧!BU6 -> 0.86375 | X39: MM
H40: レビュー後の修正 | R40: =機能一覧!BV6 -> 0.431875 | X40: MM
H41: お客様と打ち合わせ | R41: =機能一覧!BW6 -> 0.86375 | X41: MM
H42: お客様のごコメントよりの修正 | R42: =機能一覧!BX6 -> 0.431875 | X42: MM
H43: リスク（予防） | R43: =機能一覧!BY6 -> 0.86375 | X43: MM
H44: 開発工数 | R44: =SUM(R37:W43) -> 9.069375 | X44: MM
H45: 管理工数 | R45: =R44*AC45 -> 1.3604062 | X45: MM | AC45: 0.15
H46: 合計 | R46: =SUM(R44,R45) -> 10.429781 | X46: MM

Sheet マスタースケジュール
B2: 体制（Luvinaの案）
C3: 作業 | D3: 担当者 | E3: 期限 | F3: 5月 | J3: 6月
F4: 1 | G4: 2 | H4: 3 | I4: 4 | J4: 1 | K4: 2 | L4: 3 | M4: 4
B6: 1 | C6: 要件定義 | E6: -
B7: 3 | C7: 機能X0、X1，01～40 | D7: Luvina-SE | E7: -
B8: 4 | C8: お客様との打ち合わせ | D8: USMH様 Luvina | E8: 45443
B9: 5 | C9: お客様の指摘・コメントよりの修正 | D9: Luvina-SE | E9: 45446
C10: 機能62～92 | D10: Luvina-SE
B11: 6 | C11: お客様との打ち合わせ | D11: USMH様 Luvina | E11: 45473
B12: 7 | C12: お客様の指摘・コメントよりの修正 | D12: Luvina-SE | E12: 45473
D14: Luvina-SE | E14: =SUM(F14:M14)/4 -> 8 | F14: 4 | G14: 4 | H14: 4 | I14: 4 | J14: 4 | K14: 4 | L14: 4 | M14: 4
C15: USMH様のプログレスライン | D15: Luvina-BSE | E15: =SUM(F15:M15)/4 -> 2 | F15: 1 | G15: 1 | H15: 1 | I15: 1 | J15: 1 | K15: 1 | L15: 1 | M15: 1
D16: Luvina-PM | E16: =SUM(F16:M16)/4 -> 2 | F16: 1 | G16: 1 | H16: 1 | I16: 1 | J16: 1 | K16: 1 | L16: 1 | M16: 1
C17: Luvinaのプログレスライン | D17: 合計 | E17: =SUM(E14:E16) -> 12 | F17: =SUM(F14:F16) -> 6 | J17: =SUM(J14:M16)/4 -> 6
C19: 未確定のプログレスライン | F19: =SUM(F17:M17) -> 12
C21: 作業 | D21: 期限 | F21: 5月 | J21: 6月 | N21: 備考
F22: 1 | G22: 2 | H22: 3 | I22: 4 | J22: 1 | K22: 2 | L22: 3 | M22: 4
B23: 1 | C23: 要件定義
B24: 2 | C24: X0_ログイン機能 | D24: 作成済み
B25: 3 | C25: X1 メニュー機能 | D25: 作成済み
B26: 4 | C26: 21_ジャーナル検索 | D26: 作成済み | N26: いなげや様の要件定義を頂いた後、資料をバージョンアップする
B27: 5 | C27: 01_商品管理 | D27: 45420
B28: 6 | C28: 15_タッチメニュー設定 | D28: 45420
B29: 7 | C29: 02_緊急売価変更 | D29: 45420 | J29: 45422
B30: 8 | C30: 03_店舗特売入力 | D30: 45420 | E30: 45420
B31: 9 | C31: 11_部門別売上速報 | D31: 45421 | E31: 45421 | J31: 45422
B32: 10 | C32: 08_カテゴリ値引／割引設定 ※寺岡さんが正解 | D32: 45422 | E32: 45422
B33: 11 | C33: 12_単品速報／日報 | D33: 45422 | E33: 45422
B34: 12 | C34: 13_部門別売上日報 | D34: 45422 | E34: 45422 | J34: 45422
B35: 13 | C35: 05_ミックスマッチ設定 | D35: 45427 | E35: 45427
B36: 14 | C36: 20_レジ精算入力 | D36: 45427 | E36: 45427
B37: 15 | C37: 04_商品採用店舗確認 | D37: 45428 | E37: 45428
B38: 16 | C38: 06_1，7，8定番変更 | D38: 45429 | E38: 45429 | J38: 45422
B39: 17 | C39: 10_プロモーションメンテ | D39: 45429 | E39: 45429
B40: 18 | C40: 14_テナント売上速報／日報 | D40: 45429 | E40: 45429
B41: 19 | C41: 25 取扱設定マスタ設定(KSM) | D41: 45429 | E41: 45429
B42: 20 | C42: 28 レシートクーポン設定 | D42: 45429 | E42: 45429
B43: 21 | C43: 19_売価変更勧告リスト | D43: 45434 | E43: 45434
B44: 22 | C44: 22_クレジット小計割引設定 | D44: 45434 | E44: 45434
B45: 23 | C45: 29 レジ別時間帯別点検 | D45: 45435 | E45: 45435
...

Sheet 機能一覧
A1: システム名 | K1: システム種類 | W1: 見積 | AP1: 作成者 | AT1: 作成日 | AY1: 更新者 | BC1: 更新日 | BH1: バージョン
A2: セルフPOS | K2: POSサーバ | AP2: =改訂履歴!$H$11 -> XoaLT | AT2: =改訂履歴!$B$11 -> 45408 | AY2: =LOOKUP(2,1/(改訂履歴!H11:H30000<>""),改訂履歴!H11:H30000) -> XoaLT | BC2: =LOOKUP(2,1/(改訂履歴!B11:B30000<>""),改訂履歴!B11:B30000) -> 45408 | BH2: =LOOKUP(2,1/(改訂履歴!O11:O30000<>""),改訂履歴!O11:O30000) -> 0.1
A4: 昨日カテゴリー | H4: 機能概要 | U4: 項目 | Z4: 業務フロー | AP4: 機能一覧
BR6: Man Month | BS6: =BS7/20 -> 1.295625 | BT6: =BT7/20 -> 4.31875 | BU6: =BU7/20 -> 0.86375 | BV6: =BV7/20 -> 0.431875 | BW6: =BW7/20 -> 0.86375 | BX6: =BX7/20 -> 0.431875 | BY6: =BY7/20 -> 0.86375 | BZ6: =BZ7/20 -> 9.069375
B7: ●店舗担当者向けメニュー | BR7: Man Day | BS7: =SUM(BS9:BS314) -> 25.9125 | BT7: =SUM(BT9:BT314) -> 86.375 | BU7: =SUM(BU9:BU314) -> 17.275 | BV7: =SUM(BV9:BV314) -> 8.6375 | BW7: =SUM(BW9:BW314) -> 17.275 | BX7: =SUM(BX9:BX314) -> 8.6375 | BY7: =SUM(BY9:BY314) -> 17.275 | BZ7: =SUM(BZ9:BZ314) -> 181.3875
B8: 10_機能概要_画面遷移 | P8: 20_画面設計 | Y8: 画面ID | AB8: 30_機能設計 | AK8: 機能ID | AN8: 40_API設計 | AW8: APIID | AZ8: API | BM8: 画面・帳票の数量 | BN8: DBのテーブル・ファイルの数量 | BO8: ロジック・ステップ(Batch,API,…) | BP8: 業務 | BR8: 分類 | BS8: システムの理解 | BT8: 機能概要作成 | BU8: 内部のレビュー | BV8: レビュー後の修正 | BW8: お客様と打ち合わせ | BX8: お客様のごコメントよりの修正 | BY8: 利楠 | BZ8: 合計
B9: X0_ログイン機能 | P9: ログイン画面 | Y9: SCX001 | AB9: ID照会機能 | AK9: KNX001 | AN9: ID照会API | AW9: APX001 | BM9: 1 | BR9: 極小 | BS9: =_xlfn.IFNA(VLOOKUP($BR9,[15]Master!$C$4:$J$13,2,FALSE),"-") -> 0.15 | BT9: =_xlfn.IFNA(VLOOKUP($BR9,[15]Master!$C$4:$J$13,3,FALSE),"-") -> 0.5 | BU9: =_xlfn.IFNA(VLOOKUP($BR9,[15]Master!$C$4:$J$13,4,FALSE),"-") -> 0.1 | BV9: =_xlfn.IFNA(VLOOKUP($BR9,[15]Master!$C$4:$J$13,5,FALSE),"-") -> 0.05 | BW9: =_xlfn.IFNA(VLOOKUP($BR9,[15]Master!$C$4:$J$13,6,FALSE),"-") -> 0.1 | BX9: =_xlfn.IFNA(VLOOKUP($BR9,[15]Master!$C$4:$J$13,7,FALSE),"-") -> 0.05 | BY9: =_xlfn.IFNA(VLOOKUP($BR9,[15]Master!$C$4:$J$13,8,FALSE),"-") -> 0.1 | BZ9: =SUM(BS9:BY9) -> 1.05
AB10: Password照会機能 | AK10: KNX002 | AN10: Password照会API | AW10: APX002 | BS10: =_xlfn.IFNA(VLOOKUP($BR10,[15]Master!$C$4:$J$13,2,FALSE),"-") -> - | BT10: =_xlfn.IFNA(VLOOKUP($BR10,[15]Master!$C$4:$J$13,3,FALSE),"-") -> - | BU10: =_xlfn.IFNA(VLOOKUP($BR10,[15]Master!$C$4:$J$13,4,FALSE),"-") -> - | BV10: =_xlfn.IFNA(VLOOKUP($BR10,[15]Master!$C$4:$J$13,5,FALSE),"-") -> - | BW10: =_xlfn.IFNA(VLOOKUP($BR10,[15]Master!$C$4:$J$13,6,FALSE),"-") -> - | BX10: =_xlfn.IFNA(VLOOKUP($BR10,[15]Master!$C$4:$J$13,7,FALSE),"-") -> - | BY10: =_xlfn.IFNA(VLOOKUP($BR10,[15]Master!$C$4:$J$13,8,FALSE),"-") -> - | BZ10: =SUM(BS10:BY10) -> 0
B11: X1 メニュー機能 | P11: メニュー画面 | Y11: SCX101 | BM11: 1 | BR11: 極小 | BS11: =_xlfn.IFNA(VLOOKUP($BR11,[15]Master!$C$4:$J$13,2,FALSE),"-") -> 0.15 | BT11: =_xlfn.IFNA(VLOOKUP($BR11,[15]Master!$C$4:$J$13,3,FALSE),"-") -> 0.5 | BU11: =_xlfn.IFNA(VLOOKUP($BR11,[15]Master!$C$4:$J$13,4,FALSE),"-") -> 0.1 | BV11: =_xlfn.IFNA(VLOOKUP($BR11,[15]Master!$C$4:$J$13,5,FALSE),"-") -> 0.05 | BW11: =_xlfn.IFNA(VLOOKUP($BR11,[15]Master!$C$4:$J$13,6,FALSE),"-") -> 0.1 | BX11: =_xlfn.IFNA(VLOOKUP($BR11,[15]Master!$C$4:$J$13,7,FALSE),"-") -> 0.05 | BY11: =_xlfn.IFNA(VLOOKUP($BR11,[15]Master!$C$4:$J$13,8,FALSE),"-") -> 0.1 | BZ11: =SUM(BS11:BY11) -> 1.05
B12: 01_商品管理 | P12: 商品検索画面 | AB12: 商品検索機能 | AN12: 商品検索API | BM12: 6 | BR12: 大 | BS12: =_xlfn.IFNA(VLOOKUP($BR12,[15]Master!$C$4:$J$13,2,FALSE),"-") -> 0.75 | BT12: =_xlfn.IFNA(VLOOKUP($BR12,[15]Master!$C$4:$J$13,3,FALSE),"-") -> 2.5 | BU12: =_xlfn.IFNA(VLOOKUP($BR12,[15]Master!$C$4:$J$13,4,FALSE),"-") -> 0.5 | BV12: =_xlfn.IFNA(VLOOKUP($BR12,[15]Master!$C$4:$J$13,5,FALSE),"-") -> 0.25 | BW12: =_xlfn.IFNA(VLOOKUP($BR12,[15]Master!$C$4:$J$13,6,FALSE),"-") -> 0.5 | BX12: =_xlfn.IFNA(VLOOKUP($BR12,[15]Master!$C$4:$J$13,7,FALSE),"-") -> 0.25 | BY12: =_xlfn.IFNA(VLOOKUP($BR12,[15]Master!$C$4:$J$13,8,FALSE),"-") -> 0.5 | BZ12: =SUM(BS12:BY12) -> 5.25
P13: 簡易商品情報画面 | AB13: POS売価更新機能 | AN13: POS売価更新API | BS13: =_xlfn.IFNA(VLOOKUP($BR13,[15]Master!$C$4:$J$13,2,FALSE),"-") -> - | BT13: =_xlfn.IFNA(VLOOKUP($BR13,[15]Master!$C$4:$J$13,3,FALSE),"-") -> - | BU13: =_xlfn.IFNA(VLOOKUP($BR13,[15]Master!$C$4:$J$13,4,FALSE),"-") -> - | BV13: =_xlfn.IFNA(VLOOKUP($BR13,[15]Master!$C$4:$J$13,5,FALSE),"-") -> - | BW13: =_xlfn.IFNA(VLOOKUP($BR13,[15]Master!$C$4:$J$13,6,FALSE),"-") -> - | BX13: =_xlfn.IFNA(VLOOKUP($BR13,[15]Master!$C$4:$J$13,7,FALSE),"-") -> - | BY13: =_xlfn.IFNA(VLOOKUP($BR13,[15]Master!$C$4:$J$13,8,FALSE),"-") -> - | BZ13: =SUM(BS13:BY13) -> 0
P14: 緊急売価変更画面 | AB14: 緊急売価更新機能 | AN14: 緊急売価更新API | BS14: =_xlfn.IFNA(VLOOKUP($BR14,[15]Master!$C$4:$J$13,2,FALSE),"-") -> - | BT14: =_xlfn.IFNA(VLOOKUP($BR14,[15]Master!$C$4:$J$13,3,FALSE),"-") -> - | BU14: =_xlfn.IFNA(VLOOKUP($BR14,[15]Master!$C$4:$J$13,4,FALSE),"-") -> - | BV14: =_xlfn.IFNA(VLOOKUP($BR14,[15]Master!$C$4:$J$13,5,FALSE),"-") -> - | BW14: =_xlfn.IFNA(VLOOKUP($BR14,[15]Master!$C$4:$J$13,6,FALSE),"-") -> - | BX14: =_xlfn.IFNA(VLOOKUP($BR14,[15]Master!$C$4:$J$13,7,FALSE),"-") -> - | BY14: =_xlfn.IFNA(VLOOKUP($BR14,[15]Master!$C$4:$J$13,8,FALSE),"-") -> - | BZ14: =SUM(BS14:BY14) -> 0
P15: 【帳票】緊急売価更新一覧 | AB15: 【帳票】緊急売価更新一覧 | AN15: 【帳票】緊急売価更新一覧API | BS15: =_xlfn.IFNA(VLOOKUP($BR15,[15]Master!$C$4:$J$13,2,FALSE),"-") -> - | BT15: =_xlfn.IFNA(VLOOKUP($BR15,[15]Master!$C$4:$J$13,3,FALSE),"-") -> - | BU15: =_xlfn.IFNA(VLOOKUP($BR15,[15]Master!$C$4:$J$13,4,FALSE),"-") -> - | BV15: =_xlfn.IFNA(VLOOKUP($BR15,[15]Master!$C$4:$J$13,5,FALSE),"-") -> - | BW15: =_xlfn.IFNA(VLOOKUP($BR15,[15]Master!$C$4:$J$13,6,FALSE),"-") -> - | BX15: =_xlfn.IFNA(VLOOKUP($BR15,[15]Master!$C$4:$J$13,7,FALSE),"-") -> - | BY15: =_xlfn.IFNA(VLOOKUP($BR15,[15]Master!$C$4:$J$13,8,FALSE),"-") -> - | BZ15: =SUM(BS15:BY15) -> 0
P16: ミックスマッチ新規設定画面 | BS16: =_xlfn.IFNA(VLOOKUP($BR16,[15]Master!$C$4:$J$13,2,FALSE),"-") -> - | BT16: =_xlfn.IFNA(VLOOKUP($BR16,[15]Master!$C$4:$J$13,3,FALSE),"-") -> - | BU16: =_xlfn.IFNA(VLOOKUP($BR16,[15]Master!$C$4:$J$13,4,FALSE),"-") -> - | BV16: =_xlfn.IFNA(VLOOKUP($BR16,[15]Master!$C$4:$J$13,5,FALSE),"-") -> - | BW16: =_xlfn.IFNA(VLOOKUP($BR16,[15]Master!$C$4:$J$13,6,FALSE),"-") -> - | BX16: =_xlfn.IFNA(VLOOKUP($BR16,[15]Master!$C$4:$J$13,7,FALSE),"-") -> - | BY16: =_xlfn.IFNA(VLOOKUP($BR16,[15]Master!$C$4:$J$13,8,FALSE),"-") -> - | BZ16: =SUM(BS16:BY16) -> 0
P17: ミックスマッチ更新設定画面 | BS17: =_xlfn.IFNA(VLOOKUP($BR17,[15]Master!$C$4:$J$13,2,FALSE),"-") -> - | BT17: =_xlfn.IFNA(VLOOKUP($BR17,[15]Master!$C$4:$J$13,3,FALSE),"-") -> - | BU17: =_xlfn.IFNA(VLOOKUP($BR17,[15]Master!$C$4:$J$13,4,FALSE),"-") -> - | BV17: =_xlfn.IFNA(VLOOKUP($BR17,[15]Master!$C$4:$J$13,5,FALSE),"-") -> - | BW17: =_xlfn.IFNA(VLOOKUP($BR17,[15]Master!$C$4:$J$13,6,FALSE),"-") -> - | BX17: =_xlfn.IFNA(VLOOKUP($BR17,[15]Master!$C$4:$J$13,7,FALSE),"-") -> - | BY17: =_xlfn.IFNA(VLOOKUP($BR17,[15]Master!$C$4:$J$13,8,FALSE),"-") -> - | BZ17: =SUM(BS17:BY17) -> 0
P18: 特売新規設定画面 | BS18: =_xlfn.IFNA(VLOOKUP($BR18,[15]Master!$C$4:$J$13,2,FALSE),"-") -> - | BT18: =_xlfn.IFNA(VLOOKUP($BR18,[15]Master!$C$4:$J$13,3,FALSE),"-") -> - | BU18: =_xlfn.IFNA(VLOOKUP($BR18,[15]Master!$C$4:$J$13,4,FALSE),"-") -> - | BV18: =_xlfn.IFNA(VLOOKUP($BR18,[15]Master!$C$4:$J$13,5,FALSE),"-") -> - | BW18: =_xlfn.IFNA(VLOOKUP($BR18,[15]Master!$C$4:$J$13,6,FALSE),"-") -> - | BX18: =_xlfn.IFNA(VLOOKUP($BR18,[15]Master!$C$4:$J$13,7,FALSE),"-") -> - | BY18: =_xlfn.IFNA(VLOOKUP($BR18,[15]Master!$C$4:$J$13,8,FALSE),"-") -> - | BZ18: =SUM(BS18:BY18) -> 0
P19: 特売更新設定画面 | BS19: =_xlfn.IFNA(VLOOKUP($BR19,[15]Master!$C$4:$J$13,2,FALSE),"-") -> - | BT19: =_xlfn.IFNA(VLOOKUP($BR19,[15]Master!$C$4:$J$13,3,FALSE),"-") -> - | BU19: =_xlfn.IFNA(VLOOKUP($BR19,[15]Master!$C$4:$J$13,4,FALSE),"-") -> - | BV19: =_xlfn.IFNA(VLOOKUP($BR19,[15]Master!$C$4:$J$13,5,FALSE),"-") -> - | BW19: =_xlfn.IFNA(VLOOKUP($BR19,[15]Master!$C$4:$J$13,6,FALSE),"-") -> - | BX19: =_xlfn.IFNA(VLOOKUP($BR19,[15]Master!$C$4:$J$13,7,FALSE),"-") -> - | BY19: =_xlfn.IFNA(VLOOKUP($BR19,[15]Master!$C$4:$J$13,8,FALSE),"-") -> - | BZ19: =SUM(BS19:BY19) -> 0
B20: 02_緊急売価変更 | P20: 緊急売価変更画面 | AB20: 緊急売価変更検索機能 | BM20: 1 | BR20: 【重複】よ極小 | BS20: =_xlfn.IFNA(VLOOKUP($BR20,[15]Master!$C$4:$J$13,2,FALSE),"-") -> 0.1275 | BT20: =_xlfn.IFNA(VLOOKUP($BR20,[15]Master!$C$4:$J$13,3,FALSE),"-") -> 0.425 | BU20: =_xlfn.IFNA(VLOOKUP($BR20,[15]Master!$C$4:$J$13,4,FALSE),"-") -> 0.085 | BV20: =_xlfn.IFNA(VLOOKUP($BR20,[15]Master!$C$4:$J$13,5,FALSE),"-") -> 0.0425 | BW20: =_xlfn.IFNA(VLOOKUP($BR20,[15]Master!$C$4:$J$13,6,FALSE),"-") -> 0.085 | BX20: =_xlfn.IFNA(VLOOKUP($BR20,[15]Master!$C$4:$J$13,7,FALSE),"-") -> 0.0425 | BY20: =_xlfn.IFNA(VLOOKUP($BR20,[15]Master!$C$4:$J$13,8,FALSE),"-") -> 0.085 | BZ20: =SUM(BS20:BY20) -> 0.8925
P21: 登録確認モーダル | AB21: 緊急売価変更更新機能 | BS21: =_xlfn.IFNA(VLOOKUP($BR21,[15]Master!$C$4:$J$13,2,FALSE),"-") -> - | BT21: =_xlfn.IFNA(VLOOKUP($BR21,[15]Master!$C$4:$J$13,3,FALSE),"-") -> - | BU21: =_xlfn.IFNA(VLOOKUP($BR21,[15]Master!$C$4:$J$13,4,FALSE),"-") -> - | BV21: =_xlfn.IFNA(VLOOKUP($BR21,[15]Master!$C$4:$J$13,5,FALSE),"-") -> - | BW21: =_xlfn.IFNA(VLOOKUP($BR21,[15]Master!$C$4:$J$13,6,FALSE),"-") -> - | BX21: =_xlfn.IFNA(VLOOKUP($BR21,[15]Master!$C$4:$J$13,7,FALSE),"-") -> - | BY21: =_xlfn.IFNA(VLOOKUP($BR21,[15]Master!$C$4:$J$13,8,FALSE),"-") -> - | BZ21: =SUM(BS21:BY21) -> 0
P22: 削除確認モーダル | AB22: 緊急売価変更削除機能 | BS22: =_xlfn.IFNA(VLOOKUP($BR22,[15]Master!$C$4:$J$13,2,FALSE),"-") -> - | BT22: =_xlfn.IFNA(VLOOKUP($BR22,[15]Master!$C$4:$J$13,3,FALSE),"-") -> - | BU22: =_xlfn.IFNA(VLOOKUP($BR22,[15]Master!$C$4:$J$13,4,FALSE),"-") -> - | BV22: =_xlfn.IFNA(VLOOKUP($BR22,[15]Master!$C$4:$J$13,5,FALSE),"-") -> - | BW22: =_xlfn.IFNA(VLOOKUP($BR22,[15]Master!$C$4:$J$13,6,FALSE),"-") -> - | BX22: =_xlfn.IFNA(VLOOKUP($BR22,[15]Master!$C$4:$J$13,7,FALSE),"-") -> - | BY22: =_xlfn.IFNA(VLOOKUP($BR22,[15]Master!$C$4:$J$13,8,FALSE),"-") -> - | BZ22: =SUM(BS22:BY22) -> 0
P23: 変更完了モーダル | BS23: =_xlfn.IFNA(VLOOKUP($BR23,[15]Master!$C$4:$J$13,2,FALSE),"-") -> - | BT23: =_xlfn.IFNA(VLOOKUP($BR23,[15]Master!$C$4:$J$13,3,FALSE),"-") -> - | BU23: =_xlfn.IFNA(VLOOKUP($BR23,[15]Master!$C$4:$J$13,4,FALSE),"-") -> - | BV23: =_xlfn.IFNA(VLOOKUP($BR23,[15]Master!$C$4:$J$13,5,FALSE),"-") -> - | BW23: =_xlfn.IFNA(VLOOKUP($BR23,[15]Master!$C$4:$J$13,6,FALSE),"-") -> - | BX23: =_xlfn.IFNA(VLOOKUP($BR23,[15]Master!$C$4:$J$13,7,FALSE),"-") -> - | BY23: =_xlfn.IFNA(VLOOKUP($BR23,[15]Master!$C$4:$J$13,8,FALSE),"-") -> - | BZ23: =SUM(BS23:BY23) -> 0
P24: 【帳票】緊急売価更新一覧 | BS24: =_xlfn.IFNA(VLOOKUP($BR24,[15]Master!$C$4:$J$13,2,FALSE),"-") -> - | BT24: =_xlfn.IFNA(VLOOKUP($BR24,[15]Master!$C$4:$J$13,3,FALSE),"-") -> - | BU24: =_xlfn.IFNA(VLOOKUP($BR24,[15]Master!$C$4:$J$13,4,FALSE),"-") -> - | BV24: =_xlfn.IFNA(VLOOKUP($BR24,[15]Master!$C$4:$J$13,5,FALSE),"-") -> - | BW24: =_xlfn.IFNA(VLOOKUP($BR24,[15]Master!$C$4:$J$13,6,FALSE),"-") -> - | BX24: =_xlfn.IFNA(VLOOKUP($BR24,[15]Master!$C$4:$J$13,7,FALSE),"-") -> - | BY24: =_xlfn.IFNA(VLOOKUP($BR24,[15]Master!$C$4:$J$13,8,FALSE),"-") -> - | BZ24: =SUM(BS24:BY24) -> 0
B25: 03_店舗特売入力 | P25: 特売マスタ売価設定画面 | AB25: 対象期間検索機能 | BM25: 1 | BR25: 【重複】よ小 | BS25: =_xlfn.IFNA(VLOOKUP($BR25,[15]Master!$C$4:$J$13,2,FALSE),"-") -> 0.255 | BT25: =_xlfn.IFNA(VLOOKUP($BR25,[15]Master!$C$4:$J$13,3,FALSE),"-") -> 0.85 | BU25: =_xlfn.IFNA(VLOOKUP($BR25,[15]Master!$C$4:$J$13,4,FALSE),"-") -> 0.17 | BV25: =_xlfn.IFNA(VLOOKUP($BR25,[15]Master!$C$4:$J$13,5,FALSE),"-") -> 0.085 | BW25: =_xlfn.IFNA(VLOOKUP($BR25,[15]Master!$C$4:$J$13,6,FALSE),"-") -> 0.17 | BX25: =_xlfn.IFNA(VLOOKUP($BR25,[15]Master!$C$4:$J$13,7,FALSE),"-") -> 0.085 | BY25: =_xlfn.IFNA(VLOOKUP($BR25,[15]Master!$C$4:$J$13,8,FALSE),"-") -> 0.17 | BZ25: =SUM(BS25:BY25) -> 1.785
AB26: 特売売価新規機能 | BS26: =_xlfn.IFNA(VLOOKUP($BR26,[15]Master!$C$4:$J$13,2,FALSE),"-") -> - | BT26: =_xlfn.IFNA(VLOOKUP($BR26,[15]Master!$C$4:$J$13,3,FALSE),"-") -> - | BU26: =_xlfn.IFNA(VLOOKUP($BR26,[15]Master!$C$4:$J$13,4,FALSE),"-") -> - | BV26: =_xlfn.IFNA(VLOOKUP($BR26,[15]Master!$C$4:$J$13,5,FALSE),"-") -> - | BW26: =_xlfn.IFNA(VLOOKUP($BR26,[15]Master!$C$4:$J$13,6,FALSE),"-") -> - | BX26: =_xlfn.IFNA(VLOOKUP($BR26,[15]Master!$C$4:$J$13,7,FALSE),"-") -> - | BY26: =_xlfn.IFNA(VLOOKUP($BR26,[15]Master!$C$4:$J$13,8,FALSE),"-") -> - | BZ26: =SUM(BS26:BY26) -> 0
AB27: 特売売価更新機能 | BS27: =_xlfn.IFNA(VLOOKUP($BR27,[15]Master!$C$4:$J$13,2,FALSE),"-") -> - | BT27: =_xlfn.IFNA(VLOOKUP($BR27,[15]Master!$C$4:$J$13,3,FALSE),"-") -> - | BU27: =_xlfn.IFNA(VLOOKUP($BR27,[15]Master!$C$4:$J$13,4,FALSE),"-") -> - | BV27: =_xlfn.IFNA(VLOOKUP($BR27,[15]Master!$C$4:$J$13,5,FALSE),"-") -> - | BW27: =_xlfn.IFNA(VLOOKUP($BR27,[15]Master!$C$4:$J$13,6,FALSE),"-") -> - | BX27: =_xlfn.IFNA(VLOOKUP($BR27,[15]Master!$C$4:$J$13,7,FALSE),"-") -> - | BY27: =_xlfn.IFNA(VLOOKUP($BR27,[15]Master!$C$4:$J$13,8,FALSE),"-") -> - | BZ27: =SUM(BS27:BY27) -> 0
AB28: 特売割引新規機能 | BS28: =_xlfn.IFNA(VLOOKUP($BR28,[15]Master!$C$4:$J$13,2,FALSE),"-") -> - | BT28: =_xlfn.IFNA(VLOOKUP($BR28,[15]Master!$C$4:$J$13,3,FALSE),"-") -> - | BU28: =_xlfn.IFNA(VLOOKUP($BR28,[15]Master!$C$4:$J$13,4,FALSE),"-") -> - | BV28: =_xlfn.IFNA(VLOOKUP($BR28,[15]Master!$C$4:$J$13,5,FALSE),"-") -> - | BW28: =_xlfn.IFNA(VLOOKUP($BR28,[15]Master!$C$4:$J$13,6,FALSE),"-") -> - | BX28: =_xlfn.IFNA(VLOOKUP($BR28,[15]Master!$C$4:$J$13,7,FALSE),"-") -> - | BY28: =_xlfn.IFNA(VLOOKUP($BR28,[15]Master!$C$4:$J$13,8,FALSE),"-") -> - | BZ28: =SUM(BS28:BY28) -> 0
AB29: 特売割引更新機能 | BS29: =_xlfn.IFNA(VLOOKUP($BR29,[15]Master!$C$4:$J$13,2,FALSE),"-") -> - | BT29: =_xlfn.IFNA(VLOOKUP($BR29,[15]Master!$C$4:$J$13,3,FALSE),"-") -> - | BU29: =_xlfn.IFNA(VLOOKUP($BR29,[15]Master!$C$4:$J$13,4,FALSE),"-") -> - | BV29: =_xlfn.IFNA(VLOOKUP($BR29,[15]Master!$C$4:$J$13,5,FALSE),"-") -> - | BW29: =_xlfn.IFNA(VLOOKUP($BR29,[15]Master!$C$4:$J$13,6,FALSE),"-") -> - | BX29: =_xlfn.IFNA(VLOOKUP($BR29,[15]Master!$C$4:$J$13,7,FALSE),"-") -> - | BY29: =_xlfn.IFNA(VLOOKUP($BR29,[15]Master!$C$4:$J$13,8,FALSE),"-") -> - | BZ29: =SUM(BS29:BY29) -> 0
P30: プロモーション検索画面 | BS30: =_xlfn.IFNA(VLOOKUP($BR30,[15]Master!$C$4:$J$13,2,FALSE),"-") -> - | BT30: =_xlfn.IFNA(VLOOKUP($BR30,[15]Master!$C$4:$J$13,3,FALSE),"-") -> - | BU30: =_xlfn.IFNA(VLOOKUP($BR30,[15]Master!$C$4:$J$13,4,FALSE),"-") -> - | BV30: =_xlfn.IFNA(VLOOKUP($BR30,[15]Master!$C$4:$J$13,5,FALSE),"-") -> - | BW30: =_xlfn.IFNA(VLOOKUP($BR30,[15]Master!$C$4:$J$13,6,FALSE),"-") -> - | BX30: =_xlfn.IFNA(VLOOKUP($BR30,[15]Master!$C$4:$J$13,7,FALSE),"-") -> - | BY30: =_xlfn.IFNA(VLOOKUP($BR30,[15]Master!$C$4:$J$13,8,FALSE),"-") -> - | BZ30: =SUM(BS30:BY30) -> 0
P31: 登録確認モーダル | BS31: =_xlfn.IFNA(VLOOKUP($BR31,[15]Master!$C$4:$J$13,2,FALSE),"-") -> - | BT31: =_xlfn.IFNA(VLOOKUP($BR31,[15]Master!$C$4:$J$13,3,FALSE),"-") -> - | BU31: =_xlfn.IFNA(VLOOKUP($BR31,[15]Master!$C$4:$J$13,4,FALSE),"-") -> - | BV31: =_xlfn.IFNA(VLOOKUP($BR31,[15]Master!$C$4:$J$13,5,FALSE),"-") -> - | BW31: =_xlfn.IFNA(VLOOKUP($BR31,[15]Master!$C$4:$J$13,6,FALSE),"-") -> - | BX31: =_xlfn.IFNA(VLOOKUP($BR31,[15]Master!$C$4:$J$13,7,FALSE),"-") -> - | BY31: =_xlfn.IFNA(VLOOKUP($BR31,[15]Master!$C$4:$J$13,8,FALSE),"-") -> - | BZ31: =SUM(BS31:BY31) -> 0
P32: 削除確認モーダル | BS32: =_xlfn.IFNA(VLOOKUP($BR32,[15]Master!$C$4:$J$13,2,FALSE),"-") -> - | BT32: =_xlfn.IFNA(VLOOKUP($BR32,[15]Master!$C$4:$J$13,3,FALSE),"-") -> - | BU32: =_xlfn.IFNA(VLOOKUP($BR32,[15]Master!$C$4:$J$13,4,FALSE),"-") -> - | BV32: =_xlfn.IFNA(VLOOKUP($BR32,[15]Master!$C$4:$J$13,5,FALSE),"-") -> - | BW32: =_xlfn.IFNA(VLOOKUP($BR32,[15]Master!$C$4:$J$13,6,FALSE),"-") -> - | BX32: =_xlfn.IFNA(VLOOKUP($BR32,[15]Master!$C$4:$J$13,7,FALSE),"-") -> - | BY32: =_xlfn.IFNA(VLOOKUP($BR32,[15]Master!$C$4:$J$13,8,FALSE),"-") -> - | BZ32: =SUM(BS32:BY32) -> 0
P33: 変更完了モーダル | BS33: =_xlfn.IFNA(VLOOKUP($BR33,[15]Master!$C$4:$J$13,2,FALSE),"-") -> - | BT33: =_xlfn.IFNA(VLOOKUP($BR33,[15]Master!$C$4:$J$13,3,FALSE),"-") -> - | BU33: =_xlfn.IFNA(VLOOKUP($BR33,[15]Master!$C$4:$J$13,4,FALSE),"-") -> - | BV33: =_xlfn.IFNA(VLOOKUP($BR33,[15]Master!$C$4:$J$13,5,FALSE),"-") -> - | BW33: =_xlfn.IFNA(VLOOKUP($BR33,[15]Master!$C$4:$J$13,6,FALSE),"-") -> - | BX33: =_xlfn.IFNA(VLOOKUP($BR33,[15]Master!$C$4:$J$13,7,FALSE),"-") -> - | BY33: =_xlfn.IFNA(VLOOKUP($BR33,[15]Master!$C$4:$J$13,8,FALSE),"-") -> - | BZ33: =SUM(BS33:BY33) -> 0
B34: 04_商品採用店舗確認 | BM34: 1 | BP34: 未判定 | BR34: 中 | BS34: =_xlfn.IFNA(VLOOKUP($BR34,[15]Master!$C$4:$J$13,2,FALSE),"-") -> 0.525 | BT34: =_xlfn.IFNA(VLOOKUP($BR34,[15]Master!$C$4:$J$13,3,FALSE),"-") -> 1.75 | BU34: =_xlfn.IFNA(VLOOKUP($BR34,[15]Master!$C$4:$J$13,4,FALSE),"-") -> 0.35 | BV34: =_xlfn.IFNA(VLOOKUP($BR34,[15]Master!$C$4:$J$13,5,FALSE),"-") -> 0.175 | BW34: =_xlfn.IFNA(VLOOKUP($BR34,[15]Master!$C$4:$J$13,6,FALSE),"-") -> 0.35 | BX34: =_xlfn.IFNA(VLOOKUP($BR34,[15]Master!$C$4:$J$13,7,FALSE),"-") -> 0.175 | BY34: =_xlfn.IFNA(VLOOKUP($BR34,[15]Master!$C$4:$J$13,8,FALSE),"-") -> 0.35 | BZ34: =SUM(BS34:BY34) -> 3.675
B35: 05_ミックスマッチ設定 | P35: ミックスマッチ設定画面 | AB35: 対象期間検索機能 | BM35: 2 | BR35: 【重複】よ小 | BS35: =_xlfn.IFNA(VLOOKUP($BR35,[15]Master!$C$4:$J$13,2,FALSE),"-") -> 0.255 | BT35: =_xlfn.IFNA(VLOOKUP($BR35,[15]Master!$C$4:$J$13,3,FALSE),"-") -> 0.85 | BU35: =_xlfn.IFNA(VLOOKUP($BR35,[15]Master!$C$4:$J$13,4,FALSE),"-") -> 0.17 | BV35: =_xlfn.IFNA(VLOOKUP($BR35,[15]Master!$C$4:$J$13,5,FALSE),"-") -> 0.085 | BW35: =_xlfn.IFNA(VLOOKUP($BR35,[15]Master!$C$4:$J$13,6,FALSE),"-") -> 0.17 | BX35: =_xlfn.IFNA(VLOOKUP($BR35,[15]Master!$C$4:$J$13,7,FALSE),"-") -> 0.085 | BY35: =_xlfn.IFNA(VLOOKUP($BR35,[15]Master!$C$4:$J$13,8,FALSE),"-") -> 0.17 | BZ35: =SUM(BS35:BY35) -> 1.785
AB36: 特売売価新規機能 | BS36: =_xlfn.IFNA(VLOOKUP($BR36,[15]Master!$C$4:$J$13,2,FALSE),"-") -> - | BT36: =_xlfn.IFNA(VLOOKUP($BR36,[15]Master!$C$4:$J$13,3,FALSE),"-") -> - | BU36: =_xlfn.IFNA(VLOOKUP($BR36,[15]Master!$C$4:$J$13,4,FALSE),"-") -> - | BV36: =_xlfn.IFNA(VLOOKUP($BR36,[15]Master!$C$4:$J$13,5,FALSE),"-") -> - | BW36: =_xlfn.IFNA(VLOOKUP($BR36,[15]Master!$C$4:$J$13,6,FALSE),"-") -> - | BX36: =_xlfn.IFNA(VLOOKUP($BR36,[15]Master!$C$4:$J$13,7,FALSE),"-") -> - | BY36: =_xlfn.IFNA(VLOOKUP($BR36,[15]Master!$C$4:$J$13,8,FALSE),"-") -> - | BZ36: =SUM(BS36:BY36) -> 0
AB37: 特売売価更新機能 | BS37: =_xlfn.IFNA(VLOOKUP($BR37,[15]Master!$C$4:$J$13,2,FALSE),"-") -> - | BT37: =_xlfn.IFNA(VLOOKUP($BR37,[15]Master!$C$4:$J$13,3,FALSE),"-") -> - | BU37: =_xlfn.IFNA(VLOOKUP($BR37,[15]Master!$C$4:$J$13,4,FALSE),"-") -> - | BV37: =_xlfn.IFNA(VLOOKUP($BR37,[15]Master!$C$4:$J$13,5,FALSE),"-") -> - | BW37: =_xlfn.IFNA(VLOOKUP($BR37,[15]Master!$C$4:$J$13,6,FALSE),"-") -> - | BX37: =_xlfn.IFNA(VLOOKUP($BR37,[15]Master!$C$4:$J$13,7,FALSE),"-") -> - | BY37: =_xlfn.IFNA(VLOOKUP($BR37,[15]Master!$C$4:$J$13,8,FALSE),"-") -> - | BZ37: =SUM(BS37:BY37) -> 0
AB38: 特売割引新規機能 | BS38: =_xlfn.IFNA(VLOOKUP($BR38,[15]Master!$C$4:$J$13,2,FALSE),"-") -> - | BT38: =_xlfn.IFNA(VLOOKUP($BR38,[15]Master!$C$4:$J$13,3,FALSE),"-") -> - | BU38: =_xlfn.IFNA(VLOOKUP($BR38,[15]Master!$C$4:$J$13,4,FALSE),"-") -> - | BV38: =_xlfn.IFNA(VLOOKUP($BR38,[15]Master!$C$4:$J$13,5,FALSE),"-") -> - | BW38: =_xlfn.IFNA(VLOOKUP($BR38,[15]Master!$C$4:$J$13,6,FALSE),"-") -> - | BX38: =_xlfn.IFNA(VLOOKUP($BR38,[15]Master!$C$4:$J$13,7,FALSE),"-") -> - | BY38: =_xlfn.IFNA(VLOOKUP($BR38,[15]Master!$C$4:$J$13,8,FALSE),"-") -> - | BZ38: =SUM(BS38:BY38) -> 0
AB39: 特売割引更新機能 | BS39: =_xlfn.IFNA(VLOOKUP($BR39,[15]Master!$C$4:$J$13,2,FALSE),"-") -> - | BT39: =_xlfn.IFNA(VLOOKUP($BR39,[15]Master!$C$4:$J$13,3,FALSE),"-") -> - | BU39: =_xlfn.IFNA(VLOOKUP($BR39,[15]Master!$C$4:$J$13,4,FALSE),"-") -> - | BV39: =_xlfn.IFNA(VLOOKUP($BR39,[15]Master!$C$4:$J$13,5,FALSE),"-") -> - | BW39: =_xlfn.IFNA(VLOOKUP($BR39,[15]Master!$C$4:$J$13,6,FALSE),"-") -> - | BX39: =_xlfn.IFNA(VLOOKUP($BR39,[15]Master!$C$4:$J$13,7,FALSE),"-") -> - | BY39: =_xlfn.IFNA(VLOOKUP($BR39,[15]Master!$C$4:$J$13,8,FALSE),"-") -> - | BZ39: =SUM(BS39:BY39) -> 0
P40: ミックスマッチ検索画面 | BS40: =_xlfn.IFNA(VLOOKUP($BR40,[15]Master!$C$4:$J$13,2,FALSE),"-") -> - | BT40: =_xlfn.IFNA(VLOOKUP($BR40,[15]Master!$C$4:$J$13,3,FALSE),"-") -> - | BU40: =_xlfn.IFNA(VLOOKUP($BR40,[15]Master!$C$4:$J$13,4,FALSE),"-") -> - | BV40: =_xlfn.IFNA(VLOOKUP($BR40,[15]Master!$C$4:$J$13,5,FALSE),"-") -> - | BW40: =_xlfn.IFNA(VLOOKUP($BR40,[15]Master!$C$4:$J$13,6,FALSE),"-") -> - | BX40: =_xlfn.IFNA(VLOOKUP($BR40,[15]Master!$C$4:$J$13,7,FALSE),"-") -> - | BY40: =_xlfn.IFNA(VLOOKUP($BR40,[15]Master!$C$4:$J$13,8,FALSE),"-") -> - | BZ40: =SUM(BS40:BY40) -> 0
P41: 登録確認モーダル | BS41: =_xlfn.IFNA(VLOOKUP($BR41,[15]Master!$C$4:$J$13,2,FALSE),"-") -> - | BT41: =_xlfn.IFNA(VLOOKUP($BR41,[15]Master!$C$4:$J$13,3,FALSE),"-") -> - | BU41: =_xlfn.IFNA(VLOOKUP($BR41,[15]Master!$C$4:$J$13,4,FALSE),"-") -> - | BV41: =_xlfn.IFNA(VLOOKUP($BR41,[15]Master!$C$4:$J$13,5,FALSE),"-") -> - | BW41: =_xlfn.IFNA(VLOOKUP($BR41,[15]Master!$C$4:$J$13,6,FALSE),"-") -> - | BX41: =_xlfn.IFNA(VLOOKUP($BR41,[15]Master!$C$4:$J$13,7,FALSE),"-") -> - | BY41: =_xlfn.IFNA(VLOOKUP($BR41,[15]Master!$C$4:$J$13,8,FALSE),"-") -> - | BZ41: =SUM(BS41:BY41) -> 0
P42: 削除確認モーダル | BS42: =_xlfn.IFNA(VLOOKUP($BR42,[15]Master!$C$4:$J$13,2,FALSE),"-") -> - | BT42: =_xlfn.IFNA(VLOOKUP($BR42,[15]Master!$C$4:$J$13,3,FALSE),"-") -> - | BU42: =_xlfn.IFNA(VLOOKUP($BR42,[15]Master!$C$4:$J$13,4,FALSE),"-") -> - | BV42: =_xlfn.IFNA(VLOOKUP($BR42,[15]Master!$C$4:$J$13,5,FALSE),"-") -> - | BW42: =_xlfn.IFNA(VLOOKUP($BR42,[15]Master!$C$4:$J$13,6,FALSE),"-") -> - | BX42: =_xlfn.IFNA(VLOOKUP($BR42,[15]Master!$C$4:$J$13,7,FALSE),"-") -> - | BY42: =_xlfn.IFNA(VLOOKUP($BR42,[15]Master!$C$4:$J$13,8,FALSE),"-") -> - | BZ42: =SUM(BS42:BY42) -> 0
...

Sheet Master
C1: 1 | D1: 2 | E1: 3 | F1: 4 | G1: 5 | H1: 6 | I1: 7 | J1: 8
D2: 単位：MD
C3: 区分 | D3: 要件調べ | E3: 作成 | F3: 内部レビュー | G3: 内部レビューによる修正 | H3: お客様への提示 | I3: お客様のレビューによる修正 | J3: リスク | K3: 合計
B4: 極小 | C4: 極小 | D4: 0.15 | E4: 0.5 | F4: 0.1 | G4: 0.05 | H4: 0.1 | I4: 0.05 | J4: 0.1 | K4: =SUM(D4:J4) -> 1.05
B5: 小 | C5: 小 | D5: 0.3 | E5: 1 | F5: 0.2 | G5: 0.1 | H5: 0.2 | I5: 0.1 | J5: 0.2 | K5: =SUM(D5:J5) -> 2.1
B6: 中 | C6: 中 | D6: 0.525 | E6: 1.75 | F6: 0.35 | G6: 0.175 | H6: 0.35 | I6: 0.175 | J6: 0.35 | K6: =SUM(D6:J6) -> 3.675
B7: 大 | C7: 大 | D7: 0.75 | E7: 2.5 | F7: 0.5 | G7: 0.25 | H7: 0.5 | I7: 0.25 | J7: 0.5 | K7: =SUM(D7:J7) -> 5.25
B8: 極大 | C8: 極大 | D8: 0 | E8: 0 | F8: 0 | G8: 0 | H8: 0 | I8: 0 | J8: 0 | K8: =SUM(D8:J8) -> 0
B9: 【重複】よ極小 | C9: 【重複】よ極小 | D9: =85%*D4 -> 0.1275 | E9: =85%*E4 -> 0.425 | F9: =85%*F4 -> 0.085 | G9: =85%*G4 -> 0.0425 | H9: =85%*H4 -> 0.085 | I9: =85%*I4 -> 0.0425 | J9: =85%*J4 -> 0.085 | K9: =SUM(D9:J9) -> 0.8925
B10: 【重複】よ小 | C10: 【重複】よ小 | D10: =85%*D5 -> 0.255 | E10: =85%*E5 -> 0.85 | F10: =85%*F5 -> 0.17 | G10: =85%*G5 -> 0.085 | H10: =85%*H5 -> 0.17 | I10: =85%*I5 -> 0.085 | J10: =85%*J5 -> 0.17 | K10: =SUM(D10:J10) -> 1.785
B11: 【重複】よ中 | C11: 【重複】よ中 | D11: =85%*D6 -> 0.44625 | E11: =85%*E6 -> 1.4875 | F11: =85%*F6 -> 0.2975 | G11: =85%*G6 -> 0.14875 | H11: =85%*H6 -> 0.2975 | I11: =85%*I6 -> 0.14875 | J11: =85%*J6 -> 0.2975 | K11: =SUM(D11:J11) -> 3.12375
B12: 【重複】よ大 | C12: 【重複】よ大 | D12: =85%*D7 -> 0.6375 | E12: =85%*E7 -> 2.125 | F12: =85%*F7 -> 0.425 | G12: =85%*G7 -> 0.2125 | H12: =85%*H7 -> 0.425 | I12: =85%*I7 -> 0.2125 | J12: =85%*J7 -> 0.425 | K12: =SUM(D12:J12) -> 4.4625
B13: 【重複】よ極大 | C13: 【重複】よ極大 | D13: =85%*D8 -> 0 | E13: =85%*E8 -> 0 | F13: =85%*F8 -> 0 | G13: =85%*G8 -> 0 | H13: =85%*H8 -> 0 | I13: =85%*I8 -> 0 | J13: =85%*J8 -> 0 | K13: =SUM(D13:J13) -> 0
C17: 要素 | D17: 極小 | E17: 小 | F17: 中 | G17: 大 | H17: 極大
B18: 評価基準は または | C18: 画面数/伝票 | D18: <=1 | E18: 2 | F18: 3 ~ 4 | G18: 5~6 | H18: 7 ~
C19: データベースのテブール数 /ファイル | D19: <=2 | E19: <= 4 | F19: <=6 | G19: <=8 | H19: まだ定義されていない
C20: ロジック数/ステップ(バッチ、API など) | D20: <=2 | E20: <=4 | F20: <=6 | G20: <=8 | H20: まだ定義されていない
C21: 業務（修正） | D21: ・追加、修正、削除 (CRUD) | E21: ・追加、修正、削除 (CRUD) | F21: ・外部システムと対話する業務 ・他のモジュールと連携 ・リクエストを処理するためのポイントを持っている（経験が必要である)。例：売上、POSマシンの初期金額の設定、プリセット、支払いなど ・ファイル処理業務（例：売価変更など） | G21: ・外部システムと対話する業務 ・他のモジュールと連携 ・データの計算と更新 ・権限付与関連: 動的権限付与、静的権限付与 | H21: 品質変更、最適化の業務
C22: 工数 | D22: ~ 1MD | E22: ~ 2MD | F22: ~ 3.5MD | G22: ~5MD | H22: 未確定

Sheet 全体構成図
A1: システム名 | K1: システム種類 | W1: 見積 | AP1: 作成者 | AT1: 作成日 | AY1: 更新者 | BC1: 更新日 | BH1: バージョン
A2: セルフPOS | K2: POSサーバ | AP2: =改訂履歴!$H$11 -> XoaLT | AT2: =改訂履歴!$B$11 -> 45408 | AY2: =LOOKUP(2,1/(改訂履歴!H11:H30000<>""),改訂履歴!H11:H30000) -> XoaLT | BC2: =LOOKUP(2,1/(改訂履歴!B11:B30000<>""),改訂履歴!B11:B30000) -> 45408 | BH2: =LOOKUP(2,1/(改訂履歴!O11:O30000<>""),改訂履歴!O11:O30000) -> 0.1
A4: 昨日カテゴリー | H4: 機能概要 | U4: 項目 | Z4: 業務フロー | AP4: 全体構成図
B7: ※30_POSサーバー/システム全体像_POS-SV-20240117.pptx
