Workbook

Sheet 表紙
A1: システム名 | K1: システム種別 | W1: 基本設計書 | AP1: 作成者 | AT1: 作成日 | AY1: 更新者 | BC1: 更新日 | BH1: 版数
A2: POSサーバー | K2: POSサーバー | AP2: =改訂履歴!$H$11 -> LoiLV | AT2: =改訂履歴!$B$11 -> 45418 | AY2: =LOOKUP(2,1/(改訂履歴!H11:H30000<>""),改訂履歴!H11:H30000) -> LoiLV | BC2: =LOOKUP(2,1/(改訂履歴!B11:B30000<>""),改訂履歴!B11:B30000) -> 45457 | BH2: =LOOKUP(2,1/(改訂履歴!O11:O30000<>""),改訂履歴!O11:O30000) -> 0.41
A4: 機能カテゴリ | H4: 28_レシートクーポン設定 | U4: 項目 | Z4: 概要設計書 | AP4: {=RIGHT(CELL("filename",$A$1),LEN(CELL("filename",$A$1))-FIND("]",CELL("filename",$A$1)))} -> 表紙
L16: POSサーバーの基本設計書
L24: =K2&"/"&H4&"/"&Z4 -> POSサーバー/28_レシートクーポン設定/概要設計書
Q44: 承認日 | AA44: 承認者 | AQ44: 版数

Sheet 改訂履歴
A1: システム名 | K1: システム種別 | W1: =IF(表紙!W1="","",表紙!W1) -> 基本設計書 | AP1: 作成者 | AT1: 作成日 | AY1: 更新者 | BC1: 更新日 | BH1: 版数
A2: =IF(表紙!A2="","",表紙!A2) -> POSサーバー | K2: =IF(表紙!K2="","",表紙!K2) -> POSサーバー | AP2: =IF(表紙!AP2="","",表紙!AP2) -> LoiLV | AT2: =IF(表紙!AT2="","",表紙!AT2) -> 45418 | AY2: =IF(表紙!AY2="","",表紙!AY2) -> LoiLV | BC2: =IF(表紙!BC2="","",表紙!BC2) -> 45457 | BH2: =IF(表紙!BH2="","",表紙!BH2) -> 0.41
A4: 機能カテゴリ | H4: =IF(表紙!H4="","",表紙!H4) -> 28_レシートクーポン設定 | U4: 項目 | Z4: =IF(表紙!Z4="","",表紙!Z4) -> 概要設計書 | AP4: {=RIGHT(CELL("filename",$A$1),LEN(CELL("filename",$A$1))-FIND("]",CELL("filename",$A$1)))} -> 改訂履歴
B8: ■改訂履歴
B10: 更新日 | H10: 更新者 | O10: 版数 | S10: 更新内容 | AX10: 承認日 | BD10: 承認者
B11: 45418 | H11: LoiLV | O11: 0.1 | S11: 新規作成
B13: 45422 | H13: LoiLV | O13: 0.2 | S13: 更新
B15: 45425 | H15: LoiLV | O15: 0.3 | S15: レビューによる更新
B17: 45448 | H17: LoiLV | O17: 0.4 | S17: 2024年06月04日のコメントによる更新
B19: 45457 | H19: LoiLV | O19: 0.41 | S19: 2024年06月14日のコメントによる更新

Sheet 指摘履歴
A1: システム名 | K1: システム種別 | W1: =IF(表紙!W1="","",表紙!W1) -> 基本設計書 | AP1: 作成者 | AT1: 作成日 | AY1: 更新者 | BC1: 更新日 | BH1: 版数
A2: =IF(表紙!A2="","",表紙!A2) -> POSサーバー | K2: =IF(表紙!K2="","",表紙!K2) -> POSサーバー | AP2: =IF(表紙!AP2="","",表紙!AP2) -> LoiLV | AT2: =IF(表紙!AT2="","",表紙!AT2) -> 45418 | AY2: =IF(表紙!AY2="","",表紙!AY2) -> LoiLV | BC2: =IF(表紙!BC2="","",表紙!BC2) -> 45457 | BH2: =IF(表紙!BH2="","",表紙!BH2) -> 0.41
A4: 機能カテゴリ | H4: =IF(表紙!H4="","",表紙!H4) -> 28_レシートクーポン設定 | U4: 項目 | Z4: =IF(表紙!Z4="","",表紙!Z4) -> 概要設計書 | AP4: {=RIGHT(CELL("filename",$A$1),LEN(CELL("filename",$A$1))-FIND("]",CELL("filename",$A$1)))} -> 指摘履歴
B8: ■改訂履歴
B10: 更新日 | H10: 更新者 | O10: 版数 | S10: 更新内容 | AX10: 承認日 | BD10: 承認者
H11: 小川 | S11: 機能概要
S12: 取消」ボタンではなく「戻る」ボタンに変更。 ※ 全店舗一覧モーダル統一で。
H13: 小川 | S13: 機能概要
S14: 除外店舗とは何を指していますか？ 店舗一覧には全店表示される認識です。
H15: 小川 | S15: 機能概要
S16: 並び順は、下記としてください。 ①店舗コード昇順 ②印字期間【From】昇順 ③印字期間【To】昇順 ④利用可能期間【From】昇順 ⑤利用可能期間【To】昇順 ⑥クーポンコード
H17: 小川 | S17: 機能概要
S18: 除外店舗エリアではなく、登録店舗エリアとしてください。
H19: 小川 | S19: 機能概要
S20: 新規ボタンクリック時は、クーポンコード未設定の状態のためクーポンコードが重複することはないと思われます。 どのような状態を想定しているのでしょうか？
H21: 小川 | S21: 機能概要
S22: 「小計割引券名称」項目は不要ですので、削除をお願いいたします。
H23: 小川 | S23: 機能概要
S24: 「小計割引券名称」項目を削除していただくので、エラーメッセージの出し方の検討をお願いいたします。
H25: 小川 | S25: 機能概要
S26: 除外店舗エリアではなく、登録店舗（対象店舗）エリアとしてください。 ※ 名称については、後日QA表にて回答。 また、チェックが入っている店舗に対して登録処理を実施してください。
H27: 小川 | S27: 機能概要
S28: 「店舗」項目で設定した店舗に対してレシートクーポンを作成してください。
H29: 小川 | S29: 機能概要
S30: 削除された場合、削除を取り消す」とは、どのような動きをするのでしょうか？
H31: 小川 | S31: 機能概要
S32: 編集についての記載だと思いますが、削除機能についての説明が混在しています。 修正をお願いいたします。
H33: 小川 | S33: 機能概要
S34: 更新対象のデータがある場合に「更新」ボタンが活性状態となる認識です。 そのため、通知モーダルは不要となると思います

Sheet 業務フロー凡例
A1: システム名 | K1: システム種別 | W1: =IF(表紙!W1="","",表紙!W1) -> 基本設計書 | AP1: 作成者 | AT1: 作成日 | AY1: 更新者 | BC1: 更新日 | BH1: 版数
A2: =IF(表紙!A2="","",表紙!A2) -> POSサーバー | K2: =IF(表紙!K2="","",表紙!K2) -> POSサーバー | AP2: =IF(表紙!AP2="","",表紙!AP2) -> LoiLV | AT2: 45084 | AY2: =IF(表紙!AY2="","",表紙!AY2) -> LoiLV | BC2: =IF(表紙!BC2="","",表紙!BC2) -> 45457 | BH2: =IF(表紙!BH2="","",表紙!BH2) -> 0.41
A4: 機能カテゴリ | H4: =IF(表紙!H4="","",表紙!H4) -> 28_レシートクーポン設定 | U4: 項目 | Z4: =IF(表紙!Z4="","",表紙!Z4) -> 概要設計書 | AP4: {=RIGHT(CELL("filename",$A$1),LEN(CELL("filename",$A$1))-FIND("]",CELL("filename",$A$1)))} -> 業務フロー凡例
B7: ●1_レジ内
B22: ●1_レジ周辺機器
B42: ●外部連携

Sheet 機能概要説明
A1: システム名 | K1: システム種別 | W1: =IF(表紙!W1="","",表紙!W1) -> 基本設計書 | AP1: 作成者 | AT1: 作成日 | AY1: 更新者 | BC1: 更新日 | BH1: 版数
A2: =IF(表紙!A2="","",表紙!A2) -> POSサーバー | K2: =IF(表紙!K2="","",表紙!K2) -> POSサーバー | AP2: =IF(表紙!AP2="","",表紙!AP2) -> LoiLV | AT2: =IF(表紙!AT2="","",表紙!AT2) -> 45418 | AY2: =IF(表紙!AY2="","",表紙!AY2) -> LoiLV | BC2: =IF(表紙!BC2="","",表紙!BC2) -> 45457 | BH2: =IF(表紙!BH2="","",表紙!BH2) -> 0.41
A4: 機能カテゴリ | H4: =IF(表紙!H4="","",表紙!H4) -> 28_レシートクーポン設定 | U4: 項目 | Z4: =IF(表紙!Z4="","",表紙!Z4) -> 概要設計書 | AP4: {=RIGHT(CELL("filename",$A$1),LEN(CELL("filename",$A$1))-FIND("]",CELL("filename",$A$1)))} -> 機能概要説明
C7: レシートクーポン設定機能は次のことが可能になる。 | BM7: =IF(BM6=50,1,BM6+1) -> 1
D8: ・1つ以上の店舗のレシートクーポンの閲覧、追加、編集、削除 | BM8: =IF(BM7=50,1,BM7+1) -> 2
D9: ・レシートクーポンは、ユーザーが発券期間内にお買い物をした場合にお買い上げレシートの後に印刷されるクーポン券である。 | BM9: =IF(BM8=50,1,BM8+1) -> 3
D10: ・また、クーポン券に印字されている期間内でのお買い物時に使用できるものとなる。 | BM10: =IF(BM9=50,1,BM9+1) -> 4
BM11: =IF(BM10=50,1,BM10+1) -> 5
BM12: =IF(BM11=50,1,BM11+1) -> 6
BM13: =IF(BM12=50,1,BM12+1) -> 7
BM14: =IF(BM13=50,1,BM13+1) -> 8
BM15: =IF(BM14=50,1,BM14+1) -> 9
BM16: =IF(BM15=50,1,BM15+1) -> 10
BM17: =IF(BM16=50,1,BM16+1) -> 11
BM18: =IF(BM17=50,1,BM17+1) -> 12
BM19: =IF(BM18=50,1,BM18+1) -> 13
BM20: =IF(BM19=50,1,BM19+1) -> 14
BM21: =IF(BM20=50,1,BM20+1) -> 15
BM22: =IF(BM21=50,1,BM21+1) -> 16
... BM56: =IF(BM55=50,1,BM55+1) -> 50

Sheet 機能概要
A1: システム名 | K1: システム種別 | W1: =IF(表紙!W1="","",表紙!W1) -> 基本設計書 | AP1: 作成者 | AT1: 作成日 | AY1: 更新者 | BC1: 更新日 | BH1: 版数
A2: =IF(表紙!A2="","",表紙!A2) -> POSサーバー | K2: =IF(表紙!K2="","",表紙!K2) -> POSサーバー | AP2: =IF(表紙!AP2="","",表紙!AP2) -> LoiLV | AT2: =IF(表紙!AT2="","",表紙!AT2) -> 45418 | AY2: =IF(表紙!AY2="","",表紙!AY2) -> LoiLV | BC2: =IF(表紙!BC2="","",表紙!BC2) -> 45457 | BH2: =IF(表紙!BH2="","",表紙!BH2) -> 0.41
A4: 機能カテゴリ | H4: =IF(表紙!H4="","",表紙!H4) -> 28_レシートクーポン設定 | U4: 項目 | Z4: =IF(表紙!Z4="","",表紙!Z4) -> 概要設計書 | AP4: {=RIGHT(CELL("filename",$A$1),LEN(CELL("filename",$A$1))-FIND("]",CELL("filename",$A$1)))} -> 機能概要
B7: 28_レシートクーポン設定
BM8: =IF(BM7=50,1,BM7+1) -> 1
BM9: =IF(BM8=50,1,BM8+1) -> 2
BM10: =IF(BM9=50,1,BM9+1) -> 3
BM11: =IF(BM10=50,1,BM10+1) -> 4
BM12: =IF(BM11=50,1,BM11+1) -> 5
BM13: =IF(BM12=50,1,BM12+1) -> 6
BM14: =IF(BM13=50,1,BM13+1) -> 7
BM15: =IF(BM14=50,1,BM14+1) -> 8
BM16: =IF(BM15=50,1,BM15+1) -> 9
BM17: =IF(BM16=50,1,BM16+1) -> 10
BM18: =IF(BM17=50,1,BM17+1) -> 11
BM19: =IF(BM18=50,1,BM18+1) -> 12
... BM48: =IF(BM47=50,1,BM47+1) -> 41
BM49: =IF(BM48=50,1,BM48+1) -> 42 | BO49: SC2801_レシートクーポン設定画面
BM50: =IF(BM49=50,1,BM49+1) -> 43
BM51: =IF(BM50=50,1,BM50+1) -> 44
BM52: =IF(BM51=50,1,BM51+1) -> 45
BM53: =IF(BM52=50,1,BM52+1) -> 46
BM54: =IF(BM53=50,1,BM53+1) -> 47
BM55: =IF(BM54=50,1,BM54+1) -> 48
BM56: =IF(BM55=50,1,BM55+1) -> 49
BM57: =IF(BM56=50,1,BM56+1) -> 50
BM58: =IF(BM57=50,1,BM57+1) -> 1
BM59: =IF(BM58=50,1,BM58+1) -> 2
BM60: =IF(BM59=50,1,BM59+1) -> 3
BM61: =IF(BM60=50,1,BM60+1) -> 4
... BM83: =IF(BM82=50,1,BM82+1) -> 26
BM84: =IF(BM83=50,1,BM83+1) -> 27 | BO84: MD2801_レシートクーポン追加・編集モーダル | CW84: MD2801_レシートクーポン追加・編集モーダル
BM85: =IF(BM84=50,1,BM84+1) -> 28 | BO85: 追加の場合 | CW85: 編集の場合
BM86: =IF(BM85=50,1,BM85+1) -> 29
BM87: =IF(BM86=50,1,BM86+1) -> 30
BM88: =IF(BM87=50,1,BM87+1) -> 31
BM89: =IF(BM88=50,1,BM88+1) -> 32
BM90: =IF(BM89=50,1,BM89+1) -> 33
BM91: =IF(BM90=50,1,BM90+1) -> 34
BM92: =IF(BM91=50,1,BM91+1) -> 35
...

Sheet 画面設計書
A1: システム名 | K1: システム種別 | W1: =IF(表紙!W1="","",表紙!W1) -> 基本設計書 | AP1: 作成者 | AT1: 作成日 | AY1: 更新者 | BC1: 更新日 | BH1: 版数
A2: =IF(表紙!A2="","",表紙!A2) -> POSサーバー | K2: =IF(表紙!K2="","",表紙!K2) -> POSサーバー | AP2: =IF(表紙!AP2="","",表紙!AP2) -> LoiLV | AT2: =IF(表紙!AT2="","",表紙!AT2) -> 45418 | AY2: =IF(表紙!AY2="","",表紙!AY2) -> LoiLV | BC2: =IF(表紙!BC2="","",表紙!BC2) -> 45457 | BH2: =IF(表紙!BH2="","",表紙!BH2) -> 0.41
A4: 機能カテゴリ | H4: =IF(表紙!H4="","",表紙!H4) -> 28_レシートクーポン設定 | U4: 項目 | Z4: =IF(表紙!Z4="","",表紙!Z4) -> 概要設計書 | AP4: =MID(CELL("filename",A1),FIND("]",CELL("filename",A1))+1,255) -> 画面設計書
B7: ■ログイン画面のイメージ
B35: ■画面項目定義
B37: 画面項目ID | D37: 項目 | K37: タイプ | N37: I/O | O37: 多言語対象 | P37: アウトプット | AR37: インプット | BC37: 備考
P38: マッピングデータ | X38: 初期値 | AA38: 表示コントロール | AI38: Control enable | AR38: 必須 | AS38: 数字 | AT38: 文字 | AU38: マッピングデータ
P39: API名 | T39: 項目 | AU39: API名 | AY39: 項目
B40: 1 | K40: テキスト | N40: － | O40: ● | P40: － | T40: － | X40: Android POS Control | AA40: ー | AI40: － | AR40: － | AS40: ー | AT40: ー | AU40: － | AY40: ー
B41: 2 | K41: テキスト | N41: O | O41: ● | P41: － | T41: － | X41: User ID | AA41: ー | AI41: ー | AR41: － | AS41: ー | AT41: ー | AU41: － | AY41: ー
B42: 3 | K42: テキスト | N42: I | O42: － | P42: － | X42: － | AA42: ー | AI42: ー | AR42: － | AS42: ー | AT42: ー | AU42: － | AY42: ー
B43: 4 | K43: テキスト | N43: O | O43: ● | P43: － | T43: － | X43: Password | AA43: ー | AI43: ー | AR43: － | AS43: ー | AT43: ー | AU43: － | AY43: ー
B44: 5 | K44: EditText | N44: I | O44: － | P44: － | T44: － | X44: － | AA44: ー | AI44: ー | AR44: － | AS44: ー | AT44: ー | AU44: － | AY44: ー
B45: 6 | K45: ボタン | N45: I | O45: ● | P45: － | T45: － | X45: Login | AA45: ー | AI45: Enable | AR45: － | AS45: ー | AT45: ー | AU45: － | AY45: ー | BC45: Login-01/EmployeeMaster

Sheet テンプレート
A1: システム名 | K1: システム種別 | W1: =IF(表紙!W1="","",表紙!W1) -> 基本設計書 | AP1: 作成者 | AT1: 作成日 | AY1: 更新者 | BC1: 更新日 | BH1: 版数
A2: =IF(表紙!A2="","",表紙!A2) -> POSサーバー | K2: =IF(表紙!K2="","",表紙!K2) -> POSサーバー | AP2: =IF(表紙!AP2="","",表紙!AP2) -> LoiLV | AT2: =IF(表紙!AT2="","",表紙!AT2) -> 45418 | AY2: =IF(表紙!AY2="","",表紙!AY2) -> LoiLV | BC2: =IF(表紙!BC2="","",表紙!BC2) -> 45457 | BH2: =IF(表紙!BH2="","",表紙!BH2) -> 0.41
A4: 機能カテゴリ | H4: =IF(表紙!H4="","",表紙!H4) -> 28_レシートクーポン設定 | U4: 項目 | Z4: =IF(表紙!Z4="","",表紙!Z4) -> 概要設計書 | AP4: =MID(CELL("filename",A1),FIND("]",CELL("filename",A1))+1,255) -> テンプレート
AX12: `
