Workbook

Sheet 表紙
A1: システム名 | K1: システム種別 | W1: 基本設計書 | AP1: 作成者 | AT1: 作成日 | AY1: 更新者 | BC1: 更新日 | BH1: 版数
A2: POSサーバー | K2: POSサーバー | AP2: =改訂履歴!$H$11 -> TuyenNH | AT2: =改訂履歴!$B$11 -> 45448 | AY2: =LOOKUP(2,1/(改訂履歴!H11:H30000<>""),改訂履歴!H11:H30000) -> TuyenNH | BC2: =LOOKUP(2,1/(改訂履歴!B11:B30000<>""),改訂履歴!B11:B30000) -> 45448 | BH2: =LOOKUP(2,1/(改訂履歴!O11:O30000<>""),改訂履歴!O11:O30000) -> 0.1
A4: 機能カテゴリ | H4: 83_メッセージマスタ設定 | U4: 項目 | Z4: 概要設計書 | AP4: {=RIGHT(CELL("filename",$A$1),LEN(CELL("filename",$A$1))-FIND("]",CELL("filename",$A$1)))} -> 表紙
L16: POSサーバーの基本設計書
L24: =K2&"/"&H4&"/"&Z4 -> POSサーバー/83_メッセージマスタ設定/概要設計書
Q44: 承認日 | AA44: 承認者 | AQ44: 版数

Sheet 改訂履歴
A1: システム名 | K1: システム種別 | W1: =IF(表紙!W1="","",表紙!W1) -> 基本設計書 | AP1: 作成者 | AT1: 作成日 | AY1: 更新者 | BC1: 更新日 | BH1: 版数
A2: =IF(表紙!A2="","",表紙!A2) -> POSサーバー | K2: =IF(表紙!K2="","",表紙!K2) -> POSサーバー | AP2: =IF(表紙!AP2="","",表紙!AP2) -> TuyenNH | AT2: =IF(表紙!AT2="","",表紙!AT2) -> 45448 | AY2: =IF(表紙!AY2="","",表紙!AY2) -> TuyenNH | BC2: =IF(表紙!BC2="","",表紙!BC2) -> 45448 | BH2: =IF(表紙!BH2="","",表紙!BH2) -> 0.1
A4: 機能カテゴリ | H4: =IF(表紙!H4="","",表紙!H4) -> 83_メッセージマスタ設定 | U4: 項目 | Z4: =IF(表紙!Z4="","",表紙!Z4) -> 概要設計書 | AP4: {=RIGHT(CELL("filename",$A$1),LEN(CELL("filename",$A$1))-FIND("]",CELL("filename",$A$1)))} -> 改訂履歴
B8: ■改訂履歴
B10: 更新日 | H10: 更新者 | O10: 版数 | S10: 更新内容 | AX10: 承認日 | BD10: 承認者
B11: 45448 | H11: TuyenNH | O11: 0.1 | S11: 新規作成

Sheet 業務フロー凡例
A1: システム名 | K1: システム種別 | W1: =IF(表紙!W1="","",表紙!W1) -> 基本設計書 | AP1: 作成者 | AT1: 作成日 | AY1: 更新者 | BC1: 更新日 | BH1: 版数
A2: =IF(表紙!A2="","",表紙!A2) -> POSサーバー | K2: =IF(表紙!K2="","",表紙!K2) -> POSサーバー | AP2: =IF(表紙!AP2="","",表紙!AP2) -> TuyenNH | AT2: 45084 | AY2: =IF(表紙!AY2="","",表紙!AY2) -> TuyenNH | BC2: =IF(表紙!BC2="","",表紙!BC2) -> 45448 | BH2: =IF(表紙!BH2="","",表紙!BH2) -> 0.1
A4: 機能カテゴリ | H4: =IF(表紙!H4="","",表紙!H4) -> 83_メッセージマスタ設定 | U4: 項目 | Z4: =IF(表紙!Z4="","",表紙!Z4) -> 概要設計書 | AP4: {=RIGHT(CELL("filename",$A$1),LEN(CELL("filename",$A$1))-FIND("]",CELL("filename",$A$1)))} -> 業務フロー凡例
B7: ●1_レジ内
B22: ●1_レジ周辺機器
B42: ●外部連携

Sheet 機能概要説明
A1: システム名 | K1: システム種別 | W1: =IF(表紙!W1="","",表紙!W1) -> 基本設計書 | AP1: 作成者 | AT1: 作成日 | AY1: 更新者 | BC1: 更新日 | BH1: 版数
A2: =IF(表紙!A2="","",表紙!A2) -> POSサーバー | K2: =IF(表紙!K2="","",表紙!K2) -> POSサーバー | AP2: =IF(表紙!AP2="","",表紙!AP2) -> TuyenNH | AT2: =IF(表紙!AT2="","",表紙!AT2) -> 45448 | AY2: =IF(表紙!AY2="","",表紙!AY2) -> TuyenNH | BC2: =IF(表紙!BC2="","",表紙!BC2) -> 45448 | BH2: =IF(表紙!BH2="","",表紙!BH2) -> 0.1
A4: 機能カテゴリ | H4: =IF(表紙!H4="","",表紙!H4) -> 83_メッセージマスタ設定 | U4: 項目 | Z4: =IF(表紙!Z4="","",表紙!Z4) -> 概要設計書 | AP4: {=RIGHT(CELL("filename",$A$1),LEN(CELL("filename",$A$1))-FIND("]",CELL("filename",$A$1)))} -> 機能概要説明
C7: メッセージマスタ設定機能では次のことが可能になる。 | BM7: =IF(BM6=50,1,BM6+1) -> 1
D8: ・種類、メッセージコード、メッセージ種別、メッセージに従って1つ又は複数の店舗のメッセージマスタリストを検索して表示する。 | BM8: =IF(BM7=50,1,BM7+1) -> 2
D9: ・1つ又は複数の店舗のメッセージマスタを設定する。
E10: ‣新規作成
E11: ‣編集 | BM11: =IF(BM8=50,1,BM8+1) -> 3
E12: ‣削除 | BM12: =IF(BM11=50,1,BM11+1) -> 4
E13: ‣コピー | BM13: =IF(BM12=50,1,BM12+1) -> 5
D14: ・種類をレシート、ラインディスプレイとしてメッセージマスタを新規作成する。 | BM14: =IF(BM13=50,1,BM13+1) -> 6
E15: ・28_レシートクーポン設定のフローでレシートが使用される。 | BM15: =IF(BM14=50,1,BM14+1) -> 7
E16: ・ラインディスプレイはどの機能で使用されますが、分かりませんのでご教示お願い致します。 | BM16: =IF(BM15=50,1,BM15+1) -> 8
BM17: =IF(BM16=50,1,BM16+1) -> 9
BM18: =IF(BM17=50,1,BM17+1) -> 10
BM19: =IF(BM18=50,1,BM18+1) -> 11
BM20: =IF(BM19=50,1,BM19+1) -> 12
BM21: =IF(BM20=50,1,BM20+1) -> 13
BM22: =IF(BM21=50,1,BM21+1) -> 14
BM23: =IF(BM22=50,1,BM22+1) -> 15
BM24: =IF(BM23=50,1,BM23+1) -> 16
BM25: =IF(BM24=50,1,BM24+1) -> 17
BM26: =IF(BM25=50,1,BM25+1) -> 18
BM27: =IF(BM26=50,1,BM26+1) -> 19
BM28: =IF(BM27=50,1,BM27+1) -> 20
... BM58: =IF(BM57=50,1,BM57+1) -> 50

Sheet 機能概要
A1: システム名 | K1: システム種別 | W1: =IF(表紙!W1="","",表紙!W1) -> 基本設計書 | AP1: 作成者 | AT1: 作成日 | AY1: 更新者 | BC1: 更新日 | BH1: 版数
A2: =IF(表紙!A2="","",表紙!A2) -> POSサーバー | K2: =IF(表紙!K2="","",表紙!K2) -> POSサーバー | AP2: =IF(表紙!AP2="","",表紙!AP2) -> TuyenNH | AT2: =IF(表紙!AT2="","",表紙!AT2) -> 45448 | AY2: =IF(表紙!AY2="","",表紙!AY2) -> TuyenNH | BC2: =IF(表紙!BC2="","",表紙!BC2) -> 45448 | BH2: =IF(表紙!BH2="","",表紙!BH2) -> 0.1
A4: 機能カテゴリ | H4: =IF(表紙!H4="","",表紙!H4) -> 83_メッセージマスタ設定 | U4: 項目 | Z4: =IF(表紙!Z4="","",表紙!Z4) -> 概要設計書 | AP4: {=RIGHT(CELL("filename",$A$1),LEN(CELL("filename",$A$1))-FIND("]",CELL("filename",$A$1)))} -> 機能概要
B7: 83_メッセージマスタ設定
BM8: =IF(BM7=50,1,BM7+1) -> 1
BM9: =IF(BM8=50,1,BM8+1) -> 2
BM10: =IF(BM9=50,1,BM9+1) -> 3
BM11: =IF(BM10=50,1,BM10+1) -> 4
BM12: =IF(BM11=50,1,BM11+1) -> 5
BM13: =IF(BM12=50,1,BM12+1) -> 6
BM14: =IF(BM13=50,1,BM13+1) -> 7
BM15: =IF(BM14=50,1,BM14+1) -> 8
BM16: =IF(BM15=50,1,BM15+1) -> 9
B17: FC8301_メッセージマスタ設定機能 | BM17: =IF(BM16=50,1,BM16+1) -> 10
BM18: =IF(BM17=50,1,BM17+1) -> 11
BM19: =IF(BM18=50,1,BM18+1) -> 12
BM20: =IF(BM19=50,1,BM19+1) -> 13
BM21: =IF(BM20=50,1,BM20+1) -> 14
BM22: =IF(BM21=50,1,BM21+1) -> 15
BM23: =IF(BM22=50,1,BM22+1) -> 16
BM24: =IF(BM23=50,1,BM23+1) -> 17
BM25: =IF(BM24=50,1,BM24+1) -> 18
BM26: =IF(BM25=50,1,BM25+1) -> 19
BM27: =IF(BM26=50,1,BM26+1) -> 20
BM28: =IF(BM27=50,1,BM27+1) -> 21
BM29: =IF(BM28=50,1,BM28+1) -> 22
... BM84: =IF(BM83=50,1,BM83+1) -> 27
BM85: =IF(BM84=50,1,BM84+1) -> 28 | BP85: 検索後にデータがある
BM86: =IF(BM85=50,1,BM85+1) -> 29
BM87: =IF(BM86=50,1,BM86+1) -> 30
BM88: =IF(BM87=50,1,BM87+1) -> 31
BM89: =IF(BM88=50,1,BM88+1) -> 32
BM90: =IF(BM89=50,1,BM89+1) -> 33
BM91: =IF(BM90=50,1,BM90+1) -> 34
BM92: =IF(BM91=50,1,BM91+1) -> 35
BM93: =IF(BM92=50,1,BM92+1) -> 36
BM94: =IF(BM93=50,1,BM93+1) -> 37
BM95: =IF(BM94=50,1,BM94+1) -> 38
BM96: =IF(BM95=50,1,BM95+1) -> 39
BM97: =IF(BM96=50,1,BM96+1) -> 40
...

Sheet メッセージ種別
A1: システム名 | K1: システム種別 | W1: =IF(表紙!W1="","",表紙!W1) -> 基本設計書 | AP1: 作成者 | AT1: 作成日 | AY1: 更新者 | BC1: 更新日 | BH1: 版数
A2: =IF(表紙!A2="","",表紙!A2) -> POSサーバー | K2: =IF(表紙!K2="","",表紙!K2) -> POSサーバー | AP2: =IF(表紙!AP2="","",表紙!AP2) -> TuyenNH | AT2: =IF(表紙!AT2="","",表紙!AT2) -> 45448 | AY2: =IF(表紙!AY2="","",表紙!AY2) -> TuyenNH | BC2: =IF(表紙!BC2="","",表紙!BC2) -> 45448 | BH2: =IF(表紙!BH2="","",表紙!BH2) -> 0.1
A4: 機能カテゴリ | H4: =IF(表紙!H4="","",表紙!H4) -> 83_メッセージマスタ設定 | U4: 項目 | Z4: =IF(表紙!Z4="","",表紙!Z4) -> 概要設計書 | AP4: =MID(CELL("filename",A1),FIND("]",CELL("filename",A1))+1,255) -> メッセージ種別
B7: メッセージ種別リスト
C9: No | E9: メッセージ種別 | J9: メッセージID | O9: イメージフラグ | S9: 説明
C10: 1 | E10: レシート | J10: 1 | O10: 0 | S10: ヘッダー文言
C11: 2 | E11: レシート | J11: 2 | O11: 0 | S11: 顧客登録済み取引時の文言(オフライン)
C12: 3 | E12: レシート | J12: 4 | O12: 0 | S12: ポイントカード忘れ時の文言
C13: 4 | E13: レシート | J13: 5 | O13: 0 | S13: 屋号
C14: 5 | E14: レシート | J14: 6 | O14: 0 | S14: 保証書貼付レシートの文言
C15: 6 | E15: レシート | J15: 7 | O15: 0 | S15: ランク文言(次ランクアップに必要なポイント数)
C16: 7 | E16: レシート | J16: 8 | O16: 0 | S16: ランク文言(ランクアップ)
C17: 8 | E17: レシート | J17: 9 | O17: 0 | S17: ランク文言(ランク)
C18: 9 | E18: レシート | J18: 11 | O18: 0 | S18: フッターCMメッセージ(会員)
C19: 10 | E19: レシート | J19: 12 | O19: 1 | S19: フッターCM画像(会員)
C20: 11 | E20: レシート | J20: 13 | O20: 0 | S20: 顧客登録済み取引時の文言(オンライン・還元可)
C21: 12 | E21: レシート | J21: 16 | O21: 1 | S21: 免税メッセージ画像
... C31: 22 | E31: ラインディスプレイ | J31: 2 | O31: 0 | S31: Waitメッセージ

Sheet 画面設計書
A1: システム名 | K1: システム種別 | W1: =IF(表紙!W1="","",表紙!W1) -> 基本設計書 | AP1: 作成者 | AT1: 作成日 | AY1: 更新者 | BC1: 更新日 | BH1: 版数
A2: =IF(表紙!A2="","",表紙!A2) -> POSサーバー | K2: =IF(表紙!K2="","",表紙!K2) -> POSサーバー | AP2: =IF(表紙!AP2="","",表紙!AP2) -> TuyenNH | AT2: =IF(表紙!AT2="","",表紙!AT2) -> 45448 | AY2: =IF(表紙!AY2="","",表紙!AY2) -> TuyenNH | BC2: =IF(表紙!BC2="","",表紙!BC2) -> 45448 | BH2: =IF(表紙!BH2="","",表紙!BH2) -> 0.1
A4: 機能カテゴリ | H4: =IF(表紙!H4="","",表紙!H4) -> 83_メッセージマスタ設定 | U4: 項目 | Z4: =IF(表紙!Z4="","",表紙!Z4) -> 概要設計書 | AP4: =MID(CELL("filename",A1),FIND("]",CELL("filename",A1))+1,255) -> 画面設計書
B7: ■ログイン画面のイメージ
B35: ■画面項目定義
B37: 画面項目ID | D37: 項目 | K37: タイプ | N37: I/O | O37: 多言語対象 | P37: アウトプット | AR37: インプット | BC37: 備考
P38: マッピングデータ | X38: 初期値 | AA38: 表示コントロール | AI38: Control enable | AR38: 必須 | AS38: 数字 | AT38: 文字 | AU38: マッピングデータ
P39: API名 | T39: 項目 | AU39: API名 | AY39: 項目
B40: 1 | K40: テキスト | N40: － | O40: ● | P40: － | T40: － | X40: Android POS Control | AA40: ー | AI40: － | AR40: － | AS40: ー | AT40: ー | AU40: － | AY40: ー
B41: 2 | K41: テキスト | N41: O | O41: ● | P41: － | T41: － | X41: User ID | AA41: ー | AI41: ー | AR41: － | AS41: ー | AT41: ー | AU41: － | AY41: ー
B42: 3 | K42: テキスト | N42: I | O42: － | P42: － | X42: － | AA42: ー | AI42: ー | AR42: － | AS42: ー | AT42: ー | AU42: － | AY42: ー
B43: 4 | K43: テキスト | N43: O | O43: ● | P43: － | T43: － | X43: Password | AA43: ー | AI43: ー | AR43: － | AS43: ー | AT43: ー | AU43: － | AY43: ー
B44: 5 | K44: EditText | N44: I | O44: － | P44: － | T44: － | X44: － | AA44: ー | AI44: ー | AR44: － | AS44: ー | AT44: ー | AU44: － | AY44: ー
B45: 6 | K45: ボタン | N45: I | O45: ● | P45: － | T45: － | X45: Login | AA45: ー | AI45: Enable | AR45: － | AS45: ー | AT45: ー | AU45: － | AY45: ー | BC45: Login-01/EmployeeMaster

Sheet テンプレート
A1: システム名 | K1: システム種別 | W1: =IF(表紙!W1="","",表紙!W1) -> 基本設計書 | AP1: 作成者 | AT1: 作成日 | AY1: 更新者 | BC1: 更新日 | BH1: 版数
A2: =IF(表紙!A2="","",表紙!A2) -> POSサーバー | K2: =IF(表紙!K2="","",表紙!K2) -> POSサーバー | AP2: =IF(表紙!AP2="","",表紙!AP2) -> TuyenNH | AT2: =IF(表紙!AT2="","",表紙!AT2) -> 45448 | AY2: =IF(表紙!AY2="","",表紙!AY2) -> TuyenNH | BC2: =IF(表紙!BC2="","",表紙!BC2) -> 45448 | BH2: =IF(表紙!BH2="","",表紙!BH2) -> 0.1
A4: 機能カテゴリ | H4: =IF(表紙!H4="","",表紙!H4) -> 83_メッセージマスタ設定 | U4: 項目 | Z4: =IF(表紙!Z4="","",表紙!Z4) -> 概要設計書 | AP4: =MID(CELL("filename",A1),FIND("]",CELL("filename",A1))+1,255) -> テンプレート
AX12: `
