Workbook

Sheet 表紙
A1: システム名 | K1: システム種別 | W1: 基本設計書 | AP1: 作成者 | AT1: 作成日 | AY1: 更新者 | BC1: 更新日 | BH1: 版数
A2: POSサーバー | K2: POSサーバー | AP2: =改訂履歴!$H$11 -> TinNH | AT2: =改訂履歴!$B$11 -> 45441 | AY2: =LOOKUP(2,1/(改訂履歴!H11:H30000<>""),改訂履歴!H11:H30000) -> TinNH | BC2: =LOOKUP(2,1/(改訂履歴!B11:B30000<>""),改訂履歴!B11:B30000) -> 45443 | BH2: =LOOKUP(2,1/(改訂履歴!O11:O30000<>""),改訂履歴!O11:O30000) -> 0.2
A4: 機能カテゴリ | H4: 71_ノードマスタ設定 | U4: 項目 | Z4: 概要設計書 | AP4: {=RIGHT(CELL("filename",$A$1),LEN(CELL("filename",$A$1))-FIND("]",CELL("filename",$A$1)))} -> 表紙
L16: POSサーバーの基本設計書
L24: =K2&"/"&H4&"/"&Z4 -> POSサーバー/71_ノードマスタ設定/概要設計書
Q44: 承認日 | AA44: 承認者 | AQ44: 版数

Sheet 改訂履歴
A1: システム名 | K1: システム種別 | W1: =IF(表紙!W1="","",表紙!W1) -> 基本設計書 | AP1: 作成者 | AT1: 作成日 | AY1: 更新者 | BC1: 更新日 | BH1: 版数
A2: =IF(表紙!A2="","",表紙!A2) -> POSサーバー | K2: =IF(表紙!K2="","",表紙!K2) -> POSサーバー | AP2: =IF(表紙!AP2="","",表紙!AP2) -> TinNH | AT2: =IF(表紙!AT2="","",表紙!AT2) -> 45441 | AY2: =IF(表紙!AY2="","",表紙!AY2) -> TinNH | BC2: =IF(表紙!BC2="","",表紙!BC2) -> 45443 | BH2: =IF(表紙!BH2="","",表紙!BH2) -> 0.2
A4: 機能カテゴリ | H4: =IF(表紙!H4="","",表紙!H4) -> 71_ノードマスタ設定 | U4: 項目 | Z4: =IF(表紙!Z4="","",表紙!Z4) -> 概要設計書 | AP4: {=RIGHT(CELL("filename",$A$1),LEN(CELL("filename",$A$1))-FIND("]",CELL("filename",$A$1)))} -> 改訂履歴
B8: ■改訂履歴
B10: 更新日 | H10: 更新者 | O10: 版数 | S10: 更新内容 | AX10: 承認日 | BD10: 承認者
B11: 45441 | H11: TinNH | O11: 0.1 | S11: 新規作成
B13: 45443 | H13: TinNH | O13: 0.2 | S13: 2024年05月30日の議事録による更新

Sheet 業務フロー凡例
A1: システム名 | K1: システム種別 | W1: =IF(表紙!W1="","",表紙!W1) -> 基本設計書 | AP1: 作成者 | AT1: 作成日 | AY1: 更新者 | BC1: 更新日 | BH1: 版数
A2: =IF(表紙!A2="","",表紙!A2) -> POSサーバー | K2: =IF(表紙!K2="","",表紙!K2) -> POSサーバー | AP2: =IF(表紙!AP2="","",表紙!AP2) -> TinNH | AT2: 45084 | AY2: =IF(表紙!AY2="","",表紙!AY2) -> TinNH | BC2: =IF(表紙!BC2="","",表紙!BC2) -> 45443 | BH2: =IF(表紙!BH2="","",表紙!BH2) -> 0.2
A4: 機能カテゴリ | H4: =IF(表紙!H4="","",表紙!H4) -> 71_ノードマスタ設定 | U4: 項目 | Z4: =IF(表紙!Z4="","",表紙!Z4) -> 概要設計書 | AP4: {=RIGHT(CELL("filename",$A$1),LEN(CELL("filename",$A$1))-FIND("]",CELL("filename",$A$1)))} -> 業務フロー凡例
B7: ●1_レジ内
B22: ●1_レジ周辺機器
B42: ●外部連携

Sheet 機能概要説明
A1: システム名 | K1: システム種別 | W1: =IF(表紙!W1="","",表紙!W1) -> 基本設計書 | AP1: 作成者 | AT1: 作成日 | AY1: 更新者 | BC1: 更新日 | BH1: 版数
A2: =IF(表紙!A2="","",表紙!A2) -> POSサーバー | K2: =IF(表紙!K2="","",表紙!K2) -> POSサーバー | AP2: =IF(表紙!AP2="","",表紙!AP2) -> TinNH | AT2: =IF(表紙!AT2="","",表紙!AT2) -> 45441 | AY2: =IF(表紙!AY2="","",表紙!AY2) -> TinNH | BC2: =IF(表紙!BC2="","",表紙!BC2) -> 45443 | BH2: =IF(表紙!BH2="","",表紙!BH2) -> 0.2
A4: 機能カテゴリ | H4: =IF(表紙!H4="","",表紙!H4) -> 71_ノードマスタ設定 | U4: 項目 | Z4: =IF(表紙!Z4="","",表紙!Z4) -> 概要設計書 | AP4: {=RIGHT(CELL("filename",$A$1),LEN(CELL("filename",$A$1))-FIND("]",CELL("filename",$A$1)))} -> 機能概要説明
D7: ノードマスタ設定機能では次のことが可能になる。 | BM7: =IF(BM6=50,1,BM6+1) -> 1
E8: レジのマスタ情報を表示する。 | BM8: =IF(BM7=50,1,BM7+1) -> 2
E9: レジのマスタ情報を追加・編集・削除する。 | BM9: =IF(BM8=50,1,BM8+1) -> 3
E10: レジのマスタ情報をCSVファイルで取込・出力。 | BM10: =IF(BM9=50,1,BM9+1) -> 4
E11: Q&A:レジのメイン画面で使用するレジ種別を追加・削除する。 | BM11: =IF(BM10=50,1,BM10+1) -> 5
BM12: =IF(BM11=50,1,BM11+1) -> 6
BM13: =IF(BM12=50,1,BM12+1) -> 7
BM14: =IF(BM13=50,1,BM13+1) -> 8
BM15: =IF(BM14=50,1,BM14+1) -> 9
BM16: =IF(BM15=50,1,BM15+1) -> 10
BM17: =IF(BM16=50,1,BM16+1) -> 11
BM18: =IF(BM17=50,1,BM17+1) -> 12
BM19: =IF(BM18=50,1,BM18+1) -> 13
BM20: =IF(BM19=50,1,BM19+1) -> 14
BM21: =IF(BM20=50,1,BM20+1) -> 15
BM22: =IF(BM21=50,1,BM21+1) -> 16
BM23: =IF(BM22=50,1,BM22+1) -> 17
... BM57: =IF(BM56=50,1,BM56+1) -> 1

Sheet 機能概要
A1: システム名 | K1: システム種別 | W1: =IF(表紙!W1="","",表紙!W1) -> 基本設計書 | AP1: 作成者 | AT1: 作成日 | AY1: 更新者 | BC1: 更新日 | BH1: 版数
A2: =IF(表紙!A2="","",表紙!A2) -> POSサーバー | K2: =IF(表紙!K2="","",表紙!K2) -> POSサーバー | AP2: =IF(表紙!AP2="","",表紙!AP2) -> TinNH | AT2: =IF(表紙!AT2="","",表紙!AT2) -> 45441 | AY2: =IF(表紙!AY2="","",表紙!AY2) -> TinNH | BC2: =IF(表紙!BC2="","",表紙!BC2) -> 45443 | BH2: =IF(表紙!BH2="","",表紙!BH2) -> 0.2
A4: 機能カテゴリ | H4: =IF(表紙!H4="","",表紙!H4) -> 71_ノードマスタ設定 | U4: 項目 | Z4: =IF(表紙!Z4="","",表紙!Z4) -> 概要設計書 | AP4: {=RIGHT(CELL("filename",$A$1),LEN(CELL("filename",$A$1))-FIND("]",CELL("filename",$A$1)))} -> 機能概要
B7: 71_ノードマスタ設定
BM8: =IF(BM7=50,1,BM7+1) -> 1
BM9: =IF(BM8=50,1,BM8+1) -> 2
BM10: =IF(BM9=50,1,BM9+1) -> 3
BM11: =IF(BM10=50,1,BM10+1) -> 4
BM12: =IF(BM11=50,1,BM11+1) -> 5
BM13: =IF(BM12=50,1,BM12+1) -> 6
BM14: =IF(BM13=50,1,BM13+1) -> 7
BM15: =IF(BM14=50,1,BM14+1) -> 8
BM16: =IF(BM15=50,1,BM15+1) -> 9
B17: FC7101_ノードマスタ検索機能 | BM17: =IF(BM16=50,1,BM16+1) -> 10
BM18: =IF(BM17=50,1,BM17+1) -> 11
BM19: =IF(BM18=50,1,BM18+1) -> 12
BM20: =IF(BM19=50,1,BM19+1) -> 13
BM21: =IF(BM20=50,1,BM20+1) -> 14
BM22: =IF(BM21=50,1,BM21+1) -> 15
BM23: =IF(BM22=50,1,BM22+1) -> 16
BM24: =IF(BM23=50,1,BM23+1) -> 17
BM25: =IF(BM24=50,1,BM24+1) -> 18
BM26: =IF(BM25=50,1,BM25+1) -> 19
BM27: =IF(BM26=50,1,BM26+1) -> 20
BM28: =IF(BM27=50,1,BM27+1) -> 21
BM29: =IF(BM28=50,1,BM28+1) -> 22
... BM67: =IF(BM66=50,1,BM66+1) -> 10
BM68: =IF(BM67=50,1,BM67+1) -> 11 | BO68: 追加
BM69: =IF(BM68=50,1,BM68+1) -> 12
BM70: =IF(BM69=50,1,BM69+1) -> 13
BM71: =IF(BM70=50,1,BM70+1) -> 14
BM72: =IF(BM71=50,1,BM71+1) -> 15
BM73: =IF(BM72=50,1,BM72+1) -> 16
BM74: =IF(BM73=50,1,BM73+1) -> 17
BM75: =IF(BM74=50,1,BM74+1) -> 18
BM76: =IF(BM75=50,1,BM75+1) -> 19
BM77: =IF(BM76=50,1,BM76+1) -> 20
BM78: =IF(BM77=50,1,BM77+1) -> 21
BM79: =IF(BM78=50,1,BM78+1) -> 22
BM80: =IF(BM79=50,1,BM79+1) -> 23
...

Sheet 画面設計書
A1: システム名 | K1: システム種別 | W1: =IF(表紙!W1="","",表紙!W1) -> 基本設計書 | AP1: 作成者 | AT1: 作成日 | AY1: 更新者 | BC1: 更新日 | BH1: 版数
A2: =IF(表紙!A2="","",表紙!A2) -> POSサーバー | K2: =IF(表紙!K2="","",表紙!K2) -> POSサーバー | AP2: =IF(表紙!AP2="","",表紙!AP2) -> TinNH | AT2: =IF(表紙!AT2="","",表紙!AT2) -> 45441 | AY2: =IF(表紙!AY2="","",表紙!AY2) -> TinNH | BC2: =IF(表紙!BC2="","",表紙!BC2) -> 45443 | BH2: =IF(表紙!BH2="","",表紙!BH2) -> 0.2
A4: 機能カテゴリ | H4: =IF(表紙!H4="","",表紙!H4) -> 71_ノードマスタ設定 | U4: 項目 | Z4: =IF(表紙!Z4="","",表紙!Z4) -> 概要設計書 | AP4: =MID(CELL("filename",A1),FIND("]",CELL("filename",A1))+1,255) -> 画面設計書
B7: ■ログイン画面のイメージ
B35: ■画面項目定義
B37: 画面項目ID | D37: 項目 | K37: タイプ | N37: I/O | O37: 多言語対象 | P37: アウトプット | AR37: インプット | BC37: 備考
P38: マッピングデータ | X38: 初期値 | AA38: 表示コントロール | AI38: Control enable | AR38: 必須 | AS38: 数字 | AT38: 文字 | AU38: マッピングデータ
P39: API名 | T39: 項目 | AU39: API名 | AY39: 項目
B40: 1 | K40: テキスト | N40: － | O40: ● | P40: － | T40: － | X40: Android POS Control | AA40: ー | AI40: － | AR40: － | AS40: ー | AT40: ー | AU40: － | AY40: ー
B41: 2 | K41: テキスト | N41: O | O41: ● | P41: － | T41: － | X41: User ID | AA41: ー | AI41: ー | AR41: － | AS41: ー | AT41: ー | AU41: － | AY41: ー
B42: 3 | K42: テキスト | N42: I | O42: － | P42: － | X42: － | AA42: ー | AI42: ー | AR42: － | AS42: ー | AT42: ー | AU42: － | AY42: ー
B43: 4 | K43: テキスト | N43: O | O43: ● | P43: － | T43: － | X43: Password | AA43: ー | AI43: ー | AR43: － | AS43: ー | AT43: ー | AU43: － | AY43: ー
B44: 5 | K44: EditText | N44: I | O44: － | P44: － | T44: － | X44: － | AA44: ー | AI44: ー | AR44: － | AS44: ー | AT44: ー | AU44: － | AY44: ー
B45: 6 | K45: ボタン | N45: I | O45: ● | P45: － | T45: － | X45: Login | AA45: ー | AI45: Enable | AR45: － | AS45: ー | AT45: ー | AU45: － | AY45: ー | BC45: Login-01/EmployeeMaster

Sheet 参照
A1: システム名 | K1: システム種別 | W1: =IF(表紙!W1="","",表紙!W1) -> 基本設計書 | AP1: 作成者 | AT1: 作成日 | AY1: 更新者 | BC1: 更新日 | BH1: 版数
A2: =IF(表紙!A2="","",表紙!A2) -> POSサーバー | K2: =IF(表紙!K2="","",表紙!K2) -> POSサーバー | AP2: =IF(表紙!AP2="","",表紙!AP2) -> TinNH | AT2: =IF(表紙!AT2="","",表紙!AT2) -> 45441 | AY2: =IF(表紙!AY2="","",表紙!AY2) -> TinNH | BC2: =IF(表紙!BC2="","",表紙!BC2) -> 45443 | BH2: =IF(表紙!BH2="","",表紙!BH2) -> 0.2
A4: 機能カテゴリ | H4: =IF(表紙!H4="","",表紙!H4) -> 71_ノードマスタ設定 | U4: 項目 | Z4: =IF(表紙!Z4="","",表紙!Z4) -> 概要設計書 | AP4: =MID(CELL("filename",A1),FIND("]",CELL("filename",A1))+1,255) -> 参照
C9: ノード種別 | I9: レジ種別 | V9: ファンクションレイアウト | AE9: キーボードレイアウト | AN9: プリセットレイアウト
C10: No | D10: ノード種別 | I10: No | J10: レジ種別 | V10: No | W10: ファンクションレイアウト | AE10: No | AF10: キーボードレイアウト | AN10: KN1501機能から値を取得 (コードと名称のみ)
C11: 1 | D11: 代表レジ | I11: 1 | J11: 1人制 | K11: 1人制 | L11: 1人制 | M11: 1人制 | N11: 1人制 | O11: 1人制 | P11: 1人制 | Q11: 1人制 | V11: 1 | W11: １人制 | X11: １人制 | Y11: １人制 | Z11: １人制 | AA11: １人制 | AB11: １人制 | AC11: １人制 | AE11: 1 | AF11: 1111:ベーカリー | AG11: １人制 | AH11: １人制 | AI11: １人制 | AJ11: １人制 | AK11: １人制 | AL11: １人制
C12: 2 | D12: 子レジ | I12: 2 | J12: 2人制 | K12: 2人制 | L12: 2人制 | M12: 2人制 | N12: 2人制 | O12: 2人制 | P12: 2人制 | Q12: 2人制 | V12: 2 | W12: 1人制 | X12: 1人制 | Y12: 1人制 | Z12: 1人制 | AA12: 1人制 | AB12: 1人制 | AC12: 1人制 | AX12: `
C13: 3 | D13: スマートPOS | I13: 3 | J13: 現金セルフ | K13: 現金セルフ | L13: 現金セルフ | M13: 現金セルフ | N13: 現金セルフ | O13: 現金セルフ | P13: 現金セルフ | Q13: 現金セルフ | V13: 3 | W13: １人制（応援） | X13: １人制（応援） | Y13: １人制（応援） | Z13: １人制（応援） | AA13: １人制（応援） | AB13: １人制（応援） | AC13: １人制（応援）
C14: 4 | D14: アテンダントステーション | I14: 4 | J14: キャッシュレスセルフ | K14: キャッシュレスセルフ | L14: キャッシュレスセルフ | M14: キャッシュレスセルフ | N14: キャッシュレスセルフ | O14: キャッシュレスセルフ | P14: キャッシュレスセルフ | Q14: キャッシュレスセルフ | V14: 4 | W14: 1人制（応援レジ） | X14: 1人制（応援レジ） | Y14: 1人制（応援レジ） | Z14: 1人制（応援レジ） | AA14: 1人制（応援レジ） | AB14: 1人制（応援レジ） | AC14: 1人制（応援レジ）
C15: 5 | D15: テナントレジ | I15: 5 | J15: サービスカウンター | K15: サービスカウンター | L15: サービスカウンター | M15: サービスカウンター | N15: サービスカウンター | O15: サービスカウンター | P15: サービスカウンター | Q15: サービスカウンター | V15: 5 | W15: MyQR決済 | X15: MyQR決済 | Y15: MyQR決済 | Z15: MyQR決済 | AA15: MyQR決済 | AB15: MyQR決済 | AC15: MyQR決済
I16: 6 | J16: ベーカリー（エミーノ） | K16: ベーカリー（エミーノ） | L16: ベーカリー（エミーノ） | M16: ベーカリー（エミーノ） | N16: ベーカリー（エミーノ） | O16: ベーカリー（エミーノ） | P16: ベーカリー（エミーノ） | Q16: ベーカリー（エミーノ） | V16: 6 | W16: MyQR決済用 | X16: MyQR決済用 | Y16: MyQR決済用 | Z16: MyQR決済用 | AA16: MyQR決済用 | AB16: MyQR決済用 | AC16: MyQR決済用 | AE16: 支払い種別
I17: 7 | J17: ベーカリー（フェンダイン・デリー） | K17: ベーカリー（フェンダイン・デリー） | L17: ベーカリー（フェンダイン・デリー） | M17: ベーカリー（フェンダイン・デリー） | N17: ベーカリー（フェンダイン・デリー） | O17: ベーカリー（フェンダイン・デリー） | P17: ベーカリー（フェンダイン・デリー） | Q17: ベーカリー（フェンダイン・デリー） | V17: 7 | W17: Order&Eat | X17: Order&Eat | Y17: Order&Eat | Z17: Order&Eat | AA17: Order&Eat | AB17: Order&Eat | AC17: Order&Eat | AE17: No | AF17: 支払い種別 | AN17: レシートメッセージ
I18: 8 | J18: ベーカリー（モルバン） | K18: ベーカリー（モルバン） | L18: ベーカリー（モルバン） | M18: ベーカリー（モルバン） | N18: ベーカリー（モルバン） | O18: ベーカリー（モルバン） | P18: ベーカリー（モルバン） | Q18: ベーカリー（モルバン） | V18: 8 | W18: Order＆Eat | X18: Order＆Eat | Y18: Order＆Eat | Z18: Order＆Eat | AA18: Order＆Eat | AB18: Order＆Eat | AC18: Order＆Eat | AE18: 1 | AF18: 01:Visa カード | AG18: １人制 | AH18: １人制 | AI18: １人制 | AJ18: １人制 | AK18: １人制 | AL18: １人制 | AN18: KN8301機能から値を取得 (コードのみ)
I19: 9 | J19: ベーカリー（リトルマーメイド） | K19: ベーカリー（リトルマーメイド） | L19: ベーカリー（リトルマーメイド） | M19: ベーカリー（リトルマーメイド） | N19: ベーカリー（リトルマーメイド） | O19: ベーカリー（リトルマーメイド） | P19: ベーカリー（リトルマーメイド） | Q19: ベーカリー（リトルマーメイド） | V19: 9 | W19: Scan&Go | X19: Scan&Go | Y19: Scan&Go | Z19: Scan&Go | AA19: Scan&Go | AB19: Scan&Go | AC19: Scan&Go | AE19: 2 | AF19: 02:現金 | AG19: １人制 | AH19: １人制 | AI19: １人制 | AJ19: １人制 | AK19: １人制 | AL19: １人制
I20: 10 | J20: ベーカリー（直営） | K20: ベーカリー（直営） | L20: ベーカリー（直営） | M20: ベーカリー（直営） | N20: ベーカリー（直営） | O20: ベーカリー（直営） | P20: ベーカリー（直営） | Q20: ベーカリー（直営） | V20: 10 | W20: Scan&Go(MyQR) | X20: Scan&Go(MyQR) | Y20: Scan&Go(MyQR) | Z20: Scan&Go(MyQR) | AA20: Scan&Go(MyQR) | AB20: Scan&Go(MyQR) | AC20: Scan&Go(MyQR) | AE20: 3 | AF20: 03:クレジットカード | AG20: １人制 | AH20: １人制 | AI20: １人制 | AJ20: １人制 | AK20: １人制 | AL20: １人制
I21: 11 | J21: ベーカリー（BENKEI） | K21: ベーカリー（BENKEI） | L21: ベーカリー（BENKEI） | M21: ベーカリー（BENKEI） | N21: ベーカリー（BENKEI） | O21: ベーカリー（BENKEI） | P21: ベーカリー（BENKEI） | Q21: ベーカリー（BENKEI） | V21: 11 | W21: Scan＆Go(Order&Eat) | X21: Scan＆Go(Order&Eat) | Y21: Scan＆Go(Order&Eat) | Z21: Scan＆Go(Order&Eat) | AA21: Scan＆Go(Order&Eat) | AB21: Scan＆Go(Order&Eat) | AC21: Scan＆Go(Order&Eat) | AE21: 4 | AF21: 04:Internet Banking | AG21: １人制 | AH21: １人制 | AI21: １人制 | AJ21: １人制 | AK21: １人制 | AL21: １人制
I22: 12 | J22: 衣料 | K22: 衣料 | L22: 衣料 | M22: 衣料 | N22: 衣料 | O22: 衣料 | P22: 衣料 | Q22: 衣料 | V22: 12 | W22: SG_移動スーパー | X22: SG_移動スーパー | Y22: SG_移動スーパー | Z22: SG_移動スーパー | AA22: SG_移動スーパー | AB22: SG_移動スーパー | AC22: SG_移動スーパー
I23: 13 | J23: 花 | K23: 花 | L23: 花 | M23: 花 | N23: 花 | O23: 花 | P23: 花 | Q23: 花 | V23: 13 | W23: SG移動スーパー | X23: SG移動スーパー | Y23: SG移動スーパー | Z23: SG移動スーパー | AA23: SG移動スーパー | AB23: SG移動スーパー | AC23: SG移動スーパー
I24: 14 | J24: 催事 | K24: 催事 | L24: 催事 | M24: 催事 | N24: 催事 | O24: 催事 | P24: 催事 | Q24: 催事 | V24: 14 | W24: WAONチャージ | X24: WAONチャージ | Y24: WAONチャージ | Z24: WAONチャージ | AA24: WAONチャージ | AB24: WAONチャージ | AC24: WAONチャージ
I25: 15 | J25: カフェ | K25: カフェ | L25: カフェ | M25: カフェ | N25: カフェ | O25: カフェ | P25: カフェ | Q25: カフェ | V25: 15 | W25: WAONチャージ機 | X25: WAONチャージ機 | Y25: WAONチャージ機 | Z25: WAONチャージ機 | AA25: WAONチャージ機 | AB25: WAONチャージ機 | AC25: WAONチャージ機
I26: 16 | J26: コスメ | K26: コスメ | L26: コスメ | M26: コスメ | N26: コスメ | O26: コスメ | P26: コスメ | Q26: コスメ | V26: 16 | W26: アテンダントステーション | X26: アテンダントステーション | Y26: アテンダントステーション | Z26: アテンダントステーション | AA26: アテンダントステーション | AB26: アテンダントステーション | AC26: アテンダントステーション
I27: 17 | J27: WAONチャージ機 | K27: WAONチャージ機 | L27: WAONチャージ機 | M27: WAONチャージ機 | N27: WAONチャージ機 | O27: WAONチャージ機 | P27: WAONチャージ機 | Q27: WAONチャージ機 | V27: 17 | W27: カフェレジ | X27: カフェレジ | Y27: カフェレジ | Z27: カフェレジ | AA27: カフェレジ | AB27: カフェレジ | AC27: カフェレジ
I28: 18 | J28: 移動販売 | K28: 移動販売 | L28: 移動販売 | M28: 移動販売 | N28: 移動販売 | O28: 移動販売 | P28: 移動販売 | Q28: 移動販売 | V28: 18 | W28: コスメレジ | X28: コスメレジ | Y28: コスメレジ | Z28: コスメレジ | AA28: コスメレジ | AB28: コスメレジ | AC28: コスメレジ
I29: 19 | J29: Scan&Go | K29: Scan&Go | L29: Scan&Go | M29: Scan&Go | N29: Scan&Go | O29: Scan&Go | P29: Scan&Go | Q29: Scan&Go | V29: 19 | W29: サービスカウンター | X29: サービスカウンター | Y29: サービスカウンター | Z29: サービスカウンター | AA29: サービスカウンター | AB29: サービスカウンター | AC29: サービスカウンター
I30: 20 | J30: Scan&Go（移動販売） | K30: Scan&Go（移動販売） | L30: Scan&Go（移動販売） | M30: Scan&Go（移動販売） | N30: Scan&Go（移動販売） | O30: Scan&Go（移動販売） | P30: Scan&Go（移動販売） | Q30: Scan&Go（移動販売） | V30: 20 | W30: スマートPOS | X30: スマートPOS | Y30: スマートPOS | Z30: スマートPOS | AA30: スマートPOS | AB30: スマートPOS | AC30: スマートPOS
I31: 21 | J31: OnlineDelivery | K31: OnlineDelivery | L31: OnlineDelivery | M31: OnlineDelivery | N31: OnlineDelivery | O31: OnlineDelivery | P31: OnlineDelivery | Q31: OnlineDelivery | V31: 21 | W31: スマートPSO | X31: スマートPSO | Y31: スマートPSO | Z31: スマートPSO | AA31: スマートPSO | AB31: スマートPSO | AC31: スマートPSO
I32: 22 | J32: Order&Eat | K32: Order&Eat | L32: Order&Eat | M32: Order&Eat | N32: Order&Eat | O32: Order&Eat | P32: Order&Eat | Q32: Order&Eat | V32: 22 | W32: セルフ（キャッシュ） | X32: セルフ（キャッシュ） | Y32: セルフ（キャッシュ） | Z32: セルフ（キャッシュ） | AA32: セルフ（キャッシュ） | AB32: セルフ（キャッシュ） | AC32: セルフ（キャッシュ）
I33: 23 | J33: MyQR決済 | K33: MyQR決済 | L33: MyQR決済 | M33: MyQR決済 | N33: MyQR決済 | O33: MyQR決済 | P33: MyQR決済 | Q33: MyQR決済 | V33: 23 | W33: セルフ（キャッシュレス） | X33: セルフ（キャッシュレス） | Y33: セルフ（キャッシュレス） | Z33: セルフ（キャッシュレス） | AA33: セルフ（キャッシュレス） | AB33: セルフ（キャッシュレス） | AC33: セルフ（キャッシュレス）
... I37: 27 | J37: 応援機（2人制） | K37: 応援機（2人制） | L37: 応援機（2人制） | M37: 応援機（2人制） | N37: 応援機（2人制） | O37: 応援機（2人制） | P37: 応援機（2人制） | Q37: 応援機（2人制） | V37: 27 | W37: セルフPOS(キャッシュレス) | X37: セルフPOS(キャッシュレス) | Y37: セルフPOS(キャッシュレス) | Z37: セルフPOS(キャッシュレス) | AA37: セルフPOS(キャッシュレス) | AB37: セルフPOS(キャッシュレス) | AC37: セルフPOS(キャッシュレス)
V38: 28 | W38: セルフPOSキャッシュ | X38: セルフPOSキャッシュ | Y38: セルフPOSキャッシュ | Z38: セルフPOSキャッシュ | AA38: セルフPOSキャッシュ | AB38: セルフPOSキャッシュ | AC38: セルフPOSキャッシュ
V39: 29 | W39: セルフPOSキャッシュレス | X39: セルフPOSキャッシュレス | Y39: セルフPOSキャッシュレス | Z39: セルフPOSキャッシュレス | AA39: セルフPOSキャッシュレス | AB39: セルフPOSキャッシュレス | AC39: セルフPOSキャッシュレス
V40: 30 | W40: セルフキャッシュ | X40: セルフキャッシュ | Y40: セルフキャッシュ | Z40: セルフキャッシュ | AA40: セルフキャッシュ | AB40: セルフキャッシュ | AC40: セルフキャッシュ
V41: 31 | W41: セルフキャッシュレス | X41: セルフキャッシュレス | Y41: セルフキャッシュレス | Z41: セルフキャッシュレス | AA41: セルフキャッシュレス | AB41: セルフキャッシュレス | AC41: セルフキャッシュレス
V42: 32 | W42: テナントレジ | X42: テナントレジ | Y42: テナントレジ | Z42: テナントレジ | AA42: テナントレジ | AB42: テナントレジ | AC42: テナントレジ
V43: 33 | W43: ネットスーパー | X43: ネットスーパー | Y43: ネットスーパー | Z43: ネットスーパー | AA43: ネットスーパー | AB43: ネットスーパー | AC43: ネットスーパー
V44: 34 | W44: ベーカリー | X44: ベーカリー | Y44: ベーカリー | Z44: ベーカリー | AA44: ベーカリー | AB44: ベーカリー | AC44: ベーカリー
V45: 35 | W45: ベーカリー（エミーノ） | X45: ベーカリー（エミーノ） | Y45: ベーカリー（エミーノ） | Z45: ベーカリー（エミーノ） | AA45: ベーカリー（エミーノ） | AB45: ベーカリー（エミーノ） | AC45: ベーカリー（エミーノ）
V46: 36 | W46: ベーカリー（フェンダイン・デリー） | X46: ベーカリー（フェンダイン・デリー） | Y46: ベーカリー（フェンダイン・デリー） | Z46: ベーカリー（フェンダイン・デリー） | AA46: ベーカリー（フェンダイン・デリー） | AB46: ベーカリー（フェンダイン・デリー） | AC46: ベーカリー（フェンダイン・デリー）
V47: 37 | W47: ベーカリー（モルバン） | X47: ベーカリー（モルバン） | Y47: ベーカリー（モルバン） | Z47: ベーカリー（モルバン） | AA47: ベーカリー（モルバン） | AB47: ベーカリー（モルバン） | AC47: ベーカリー（モルバン）
V48: 38 | W48: ベーカリー（リトルマーメイド） | X48: ベーカリー（リトルマーメイド） | Y48: ベーカリー（リトルマーメイド） | Z48: ベーカリー（リトルマーメイド） | AA48: ベーカリー（リトルマーメイド） | AB48: ベーカリー（リトルマーメイド） | AC48: ベーカリー（リトルマーメイド）
...
