Workbook

Sheet 表紙
A1: システム名 | K1: システム種別 | W1: 基本設計書 | AP1: 作成者 | AT1: 作成日 | AY1: 更新者 | BC1: 更新日 | BH1: 版数
A2: POSサーバー | K2: POSサーバー | AP2: =改訂履歴!$H$11 -> DuNT | AT2: =改訂履歴!$B$11 -> 45336 | AY2: =LOOKUP(2,1/(改訂履歴!H11:H29999<>""),改訂履歴!H11:H29999) -> DuNT | BC2: =LOOKUP(2,1/(改訂履歴!B11:B29999<>""),改訂履歴!B11:B29999) -> 45419 | BH2: =LOOKUP(2,1/(改訂履歴!O11:O29999<>""),改訂履歴!O11:O29999) -> 0.23
A4: 機能カテゴリ | H4: ●15_タッチメニュー設定 | U4: 項目 | Z4: 概要設計書 | AP4: {=RIGHT(CELL("filename",$A$1),LEN(CELL("filename",$A$1))-FIND("]",CELL("filename",$A$1)))} -> 表紙
L16: POSサーバーの基本設計書
L24: =K2&"/"&H4&"/"&Z4 -> POSサーバー/●15_タッチメニュー設定/概要設計書
Q44: 承認日 | AA44: 承認者 | AQ44: 版数

Sheet 改訂履歴
A1: システム名 | K1: システム種別 | W1: =IF(表紙!W1="","",表紙!W1) -> 基本設計書 | AP1: 作成者 | AT1: 作成日 | AY1: 更新者 | BC1: 更新日 | BH1: 版数
A2: =IF(表紙!A2="","",表紙!A2) -> POSサーバー | K2: =IF(表紙!K2="","",表紙!K2) -> POSサーバー | AP2: =IF(表紙!AP2="","",表紙!AP2) -> DuNT | AT2: =IF(表紙!AT2="","",表紙!AT2) -> 45336 | AY2: =IF(表紙!AY2="","",表紙!AY2) -> DuNT | BC2: =IF(表紙!BC2="","",表紙!BC2) -> 45419 | BH2: =IF(表紙!BH2="","",表紙!BH2) -> 0.23
A4: 機能カテゴリ | H4: =IF(表紙!H4="","",表紙!H4) -> ●15_タッチメニュー設定 | U4: 項目 | Z4: =IF(表紙!Z4="","",表紙!Z4) -> 概要設計書 | AP4: {=RIGHT(CELL("filename",$A$1),LEN(CELL("filename",$A$1))-FIND("]",CELL("filename",$A$1)))} -> 改訂履歴
B8: ■改訂履歴
B10: 更新日 | H10: 更新者 | O10: 版数 | S10: 更新内容 | AX10: 承認日 | BD10: 承認者
B11: 45336 | H11: DuNT | O11: 0.1 | S11: 新規作成
B13: 45391 | H13: DuNT | O13: 0.2 | S13: 更新
B15: 45399 | H15: DuNT | O15: 0.21 | S15: 2024/04/17の定例会後の更新
B17: 45407 | H17: DuNT | O17: 0.22 | S17: 2024/04/24の定例会後の更新
S18: 機能概要説明シートの追加
B19: 45419 | H19: DuNT | O19: 0.23 | S19: 「機能概要」シートを以下のように記載を追加 ・一時的に使用しないプリセットボタンに対して【表示】・【非表示】設定が出来るようにする。 ・タッチメニューのタブの移動が出来るようにする。

Sheet 業務フロー凡例
A1: システム名 | K1: システム種別 | W1: =IF(表紙!W1="","",表紙!W1) -> 基本設計書 | AP1: 作成者 | AT1: 作成日 | AY1: 更新者 | BC1: 更新日 | BH1: 版数
A2: =IF(表紙!A2="","",表紙!A2) -> POSサーバー | K2: =IF(表紙!K2="","",表紙!K2) -> POSサーバー | AP2: =IF(表紙!AP2="","",表紙!AP2) -> DuNT | AT2: =IF(表紙!AT2="","",表紙!AT2) -> 45336 | AY2: =IF(表紙!AY2="","",表紙!AY2) -> DuNT | BC2: =IF(表紙!BC2="","",表紙!BC2) -> 45419 | BH2: =IF(表紙!BH2="","",表紙!BH2) -> 0.23
A4: 機能カテゴリ | H4: =IF(表紙!H4="","",表紙!H4) -> ●15_タッチメニュー設定 | U4: 項目 | Z4: =IF(表紙!Z4="","",表紙!Z4) -> 概要設計書 | AP4: {=RIGHT(CELL("filename",$A$1),LEN(CELL("filename",$A$1))-FIND("]",CELL("filename",$A$1)))} -> 業務フロー凡例
B7: ●1_レジ内
B22: ●1_レジ周辺機器
B42: ●外部連携

Sheet 機能概要説明
A1: システム名 | K1: システム種別 | W1: =IF(表紙!W1="","",表紙!W1) -> 基本設計書 | AP1: 作成者 | AT1: 作成日 | AY1: 更新者 | BC1: 更新日 | BH1: 版数
A2: =IF(表紙!A2="","",表紙!A2) -> POSサーバー | K2: =IF(表紙!K2="","",表紙!K2) -> POSサーバー | AP2: =IF(表紙!AP2="","",表紙!AP2) -> DuNT | AT2: =IF(表紙!AT2="","",表紙!AT2) -> 45336 | AY2: =IF(表紙!AY2="","",表紙!AY2) -> DuNT | BC2: =IF(表紙!BC2="","",表紙!BC2) -> 45419 | BH2: =IF(表紙!BH2="","",表紙!BH2) -> 0.23
A4: 機能カテゴリ | H4: =IF(表紙!H4="","",表紙!H4) -> ●15_タッチメニュー設定 | U4: 項目 | Z4: =IF(表紙!Z4="","",表紙!Z4) -> 概要設計書 | AP4: {=RIGHT(CELL("filename",$A$1),LEN(CELL("filename",$A$1))-FIND("]",CELL("filename",$A$1)))} -> 機能概要説明
B7: タッチメニュー設定機能により、次のことが可能になる。
C8: ・店舗のレイアウトプリセットを管理する。
D9: ‣ビジネスレイアウト一覧を見る。
D10: ‣1種類のビジネスレイアウトの詳細を見る。
D11: ‣ビジネスレイアウトを検索する。
C12: ・店舗のビジネスレイアウトを設定する。
D13: ‣新規作成
D14: ‣編集
D15: ‣削除
D16: ‣コピー
C17: ・1種類のビジネスレイアウトの詳細を設定する。
D18: ‣ ビジネスレイアウトのレイアウトプリセットの変更：名称、色など
D19: ‣ボタンレイアウトプリセットを変更する。
E20: ●色、イメージ、名称、サイズ、有効・無効など
E21: ●ボタンレイアウトプリセットの機能：商品、クーポン、割引など

Sheet 機能概要
A1: システム名 | K1: システム種別 | W1: =IF(表紙!W1="","",表紙!W1) -> 基本設計書 | AP1: 作成者 | AT1: 作成日 | AY1: 更新者 | BC1: 更新日 | BH1: 版数
A2: =IF(表紙!A2="","",表紙!A2) -> POSサーバー | K2: =IF(表紙!K2="","",表紙!K2) -> POSサーバー | AP2: =IF(表紙!AP2="","",表紙!AP2) -> DuNT | AT2: =IF(表紙!AT2="","",表紙!AT2) -> 45336 | AY2: =IF(表紙!AY2="","",表紙!AY2) -> DuNT | BC2: =IF(表紙!BC2="","",表紙!BC2) -> 45419 | BH2: =IF(表紙!BH2="","",表紙!BH2) -> 0.23
A4: 機能カテゴリ | H4: =IF(表紙!H4="","",表紙!H4) -> ●15_タッチメニュー設定 | U4: 項目 | Z4: =IF(表紙!Z4="","",表紙!Z4) -> 概要設計書 | AP4: {=RIGHT(CELL("filename",$A$1),LEN(CELL("filename",$A$1))-FIND("]",CELL("filename",$A$1)))} -> 機能概要
BM6: =IF(BM5=50,1,BM5+1) -> 1
B7: ●15_タッチメニュー設定 | BM7: =IF(BM6=50,1,BM6+1) -> 2
BM8: =IF(BM7=50,1,BM7+1) -> 3
BM9: =IF(BM8=50,1,BM8+1) -> 4
BM10: =IF(BM9=50,1,BM9+1) -> 5
BM11: =IF(BM10=50,1,BM10+1) -> 6
BM12: =IF(BM11=50,1,BM11+1) -> 7
BM13: =IF(BM12=50,1,BM12+1) -> 8
BM14: =IF(BM13=50,1,BM13+1) -> 9
BM15: =IF(BM14=50,1,BM14+1) -> 10
B16: FC1501_タッチメニュー設定グループ機能 | BM16: =IF(BM15=50,1,BM15+1) -> 11
BM17: =IF(BM16=50,1,BM16+1) -> 12
BM18: =IF(BM17=50,1,BM17+1) -> 13
BM19: =IF(BM18=50,1,BM18+1) -> 14
BM20: =IF(BM19=50,1,BM19+1) -> 15
BM21: =IF(BM20=50,1,BM20+1) -> 16
BM22: =IF(BM21=50,1,BM21+1) -> 17
BM23: =IF(BM22=50,1,BM22+1) -> 18
BM24: =IF(BM23=50,1,BM23+1) -> 19
BM25: =IF(BM24=50,1,BM24+1) -> 20
BM26: =IF(BM25=50,1,BM25+1) -> 21
BM27: =IF(BM26=50,1,BM26+1) -> 22
BM28: =IF(BM27=50,1,BM27+1) -> 23
... BM79: =IF(BM78=50,1,BM78+1) -> 24
B80: FC1502_プリセットレイアウト編集機能（確定済み） | BM80: =IF(BM79=50,1,BM79+1) -> 25
BM81: =IF(BM80=50,1,BM80+1) -> 26
BM82: =IF(BM81=50,1,BM81+1) -> 27
BM83: =IF(BM82=50,1,BM82+1) -> 28
BM84: =IF(BM83=50,1,BM83+1) -> 29
BM85: =IF(BM84=50,1,BM84+1) -> 30
BM86: =IF(BM85=50,1,BM85+1) -> 31
BM87: =IF(BM86=50,1,BM86+1) -> 32
BM88: =IF(BM87=50,1,BM87+1) -> 33
BM89: =IF(BM88=50,1,BM88+1) -> 34
BM90: =IF(BM89=50,1,BM89+1) -> 35
BM91: =IF(BM90=50,1,BM90+1) -> 36
BM92: =IF(BM91=50,1,BM91+1) -> 37
...

Sheet 「プリセット画面1」
A1: システム名 | K1: システム種別 | W1: =IF(表紙!W1="","",表紙!W1) -> 基本設計書 | AP1: 作成者 | AT1: 作成日 | AY1: 更新者 | BC1: 更新日 | BH1: 版数
A2: =IF(表紙!A2="","",表紙!A2) -> POSサーバー | K2: =IF(表紙!K2="","",表紙!K2) -> POSサーバー | AP2: =IF(表紙!AP2="","",表紙!AP2) -> DuNT | AT2: =IF(表紙!AT2="","",表紙!AT2) -> 45336 | AY2: =IF(表紙!AY2="","",表紙!AY2) -> DuNT | BC2: =IF(表紙!BC2="","",表紙!BC2) -> 45419 | BH2: =IF(表紙!BH2="","",表紙!BH2) -> 0.23
A4: 機能カテゴリ | H4: =IF(表紙!H4="","",表紙!H4) -> ●15_タッチメニュー設定 | U4: 項目 | Z4: =IF(表紙!Z4="","",表紙!Z4) -> 概要設計書 | AP4: {=RIGHT(CELL("filename",$A$1),LEN(CELL("filename",$A$1))-FIND("]",CELL("filename",$A$1)))} -> 「プリセット画面1」
B7: ■プリセット1画面イメージ
B44: ■画面項目定義
B46: 画面項目ID | D46: 項目名 | K46: タイプ | N46: I/O | O46: 多言語対象 | P46: アウトプット | AR46: インプット | BC46: 備考
P47: マッピングデータ | X47: 初期値 | AA47: 表示コントロール | AI47: 有効コントロール | AR47: 必須 | AS47: 数字 | AT47: 文字 | AU47: マッピングデータ
P48: API名 | T48: 項目名 | AU48: API名 | AY48: 項目名
D49: ヘッダー | K49: TEXT | N49: － | O49: ● | P49: － | T49: － | X49: Thiết định preset | AA49: ー | AI49: － | AR49: － | AS49: ー | AT49: ー | AU49: － | AY49: ー
B50: 1 | D50: タイトルヘッダー | K50: TEXT | N50: － | O50: ● | P50: － | T50: － | X50: Thiết định preset | AA50: ー | AI50: － | AR50: － | AS50: ー | AT50: ー | AU50: － | AY50: ー
B51: 2 | D51: 担当者名 | K51: TEXT | N51: O | O51: － | P51: － | T51: － | X51: － | AA51: ー | AI51: ー | AR51: － | AS51: ー | AT51: ー | AU51: － | AY51: ー
B52: 3 | D52: 店舗名 | K52: TEXT | N52: O | O52: ● | P52: － | T52: － | X52: － | AA52: ー | AI52: ー | AR52: － | AS52: ー | AT52: ー | AU52: － | AY52: ー
B53: 4 | D53: メインメニューに遷移する。 | K53: View | N53: I | O53: ● | P53: － | T53: － | X53: メインメニュー | AA53: ー | AI53: ー | AR53: － | AS53: ー | AT53: ー | AU53: － | AY53: ー
B54: 5 | D54: 【X】ボタン | K54: ボタン | N54: I | O54: － | P54: － | T54: － | X54: － | AA54: ー | AI54: 有効 | AR54: － | AS54: ー | AT54: ー | AU54: － | AY54: ー
B55: 6 | D55: preset layout code title | K55: TEXT | N55: O | O55: ● | P55: － | T55: － | X55: Code layout preset | AA55: ー | AI55: 有効 | AR55: － | AS55: ー | AT55: ー | AU55: － | AY55: ー
B56: 7 | D56: Input Code | K56: EditText | N56: I | O56: － | P56: － | T56: － | X56: － | AA56: ー | AI56: ー | AR56: － | AS56: ー | AT56: ー | AU56: － | AY56: ー
B57: 8 | D57: Option | K57: View | N57: I | O57: ● | P57: － | T57: － | X57: － | AA57: ー | AI57: ー | AR57: － | AS57: ー | AT57: ー | AU57: － | AY57: ー
B58: 9 | D58: Store name Title | K58: TEXT | N58: O | O58: ● | P58: － | T58: － | X58: Tên | AA58: ー | AI58: ー | AR58: － | AS58: ー | AT58: ー | AU58: － | AY58: ー
B59: 10 | D59: Input name | K59: テキスト | N59: I | O59: － | P59: － | T59: － | AA59: ー | AI59: ー | AR59: － | AS59: ー | AT59: ー | AU59: － | AY59: ー
B60: 11 | D60: area column | K60: TEXT | N60: O | O60: ● | P60: － | T60: － | X60: Vùng | AA60: ー | AI60: ー | AR60: － | AS60: ー | AT60: ー | AU60: － | AY60: ー
B61: 12 | D61: Store Info column | K61: TEXT | N61: O | O61: ● | P61: － | T61: － | X61: Cửa hàng | AA61: ー | AI61: ー | AR61: － | AS61: ー | AT61: ー | AU61: － | AY61: ー | BC61: Response P001 [store_code]
B62: 13 | D62: business type code | K62: TEXT | N62: O | O62: ● | P62: － | T62: － | X62: Code layout preset | AA62: ー | AI62: ー | AR62: － | AS62: ー | AT62: ー | AU62: － | AY62: ー | BC62: Response P001 [business_type_code]
B63: 14 | D63: busines type name | K63: TEXT | N63: O | O63: ● | P63: － | T63: － | X63: Tên | AA63: ー | AI63: ー | AR63: － | AS63: ー | AT63: ー | AU63: － | AY63: ー | BC63: Response P001 [branch_name]
B64: 15 | D64: 予約日 | K64: TEXT | N64: I | O64: ● | P64: － | T64: － | X64: 予約日 | AA64: ー | AI64: ー | AR64: － | AS64: ー | AT64: ー | AU64: － | AY64: ー | BC64: Response P001 [last_update]
B65: 16 | D65: Xóa | K65: ボタン | N65: I | O65: ● | P65: － | T65: － | X65: F08：削除 | AA65: ー | AI65: 有効 | AR65: － | AS65: ー | AT65: ー | AU65: － | AY65: ー
B66: 17 | D66: 編集 | K66: ボタン | N66: I | O66: ● | P66: － | T66: － | X66: 編集 | AA66: ー | AI66: Enable | AR66: － | AS66: ー | AT66: ー | AU66: － | AY66: ー
B67: 18 | D67: 新規作成 | K67: ボタン | N67: I | O67: ● | P67: － | T67: － | X67: 新規作成 | AA67: ー | AI67: Enable | AR67: － | AS67: ー | AT67: ー | AU67: － | AY67: ー
B68: 19 | D68: Copy | K68: ボタン | N68: I | O68: ● | P68: － | T68: － | AA68: ー | AI68: Enable | AR68: － | AS68: ー | AT68: ー | AU68: － | AY68: ー
B69: 20 | D69: 確定」 | K69: ボタン | N69: I | O69: ● | P69: － | T69: － | AA69: ー | AI69: Enable | AR69: － | AS69: ー | AT69: ー | AU69: － | AY69: ー
B70: 21 | D70: 検索 | K70: ボタン | N70: I | O70: ● | P70: － | T70: － | AA70: ー | AI70: Enable | AR70: － | AS70: ー | AT70: ー | AU70: － | AY70: ー

Sheet 「プリセット画面2」
A1: システム名 | K1: システム種別 | W1: =IF(表紙!W1="","",表紙!W1) -> 基本設計書 | AP1: 作成者 | AT1: 作成日 | AY1: 更新者 | BC1: 更新日 | BH1: 版数
A2: =IF(表紙!A2="","",表紙!A2) -> POSサーバー | K2: =IF(表紙!K2="","",表紙!K2) -> POSサーバー | AP2: =IF(表紙!AP2="","",表紙!AP2) -> DuNT | AT2: =IF(表紙!AT2="","",表紙!AT2) -> 45336 | AY2: =IF(表紙!AY2="","",表紙!AY2) -> DuNT | BC2: =IF(表紙!BC2="","",表紙!BC2) -> 45419 | BH2: =IF(表紙!BH2="","",表紙!BH2) -> 0.23
A4: 機能カテゴリ | H4: =IF(表紙!H4="","",表紙!H4) -> ●15_タッチメニュー設定 | U4: 項目 | Z4: =IF(表紙!Z4="","",表紙!Z4) -> 概要設計書 | AP4: {=RIGHT(CELL("filename",$A$1),LEN(CELL("filename",$A$1))-FIND("]",CELL("filename",$A$1)))} -> 「プリセット画面2」
B7: ■プリセット3画面イメージ
B43: ■画面項目定義
B45: 画面項目ID | D45: 項目名 | K45: タイプ | N45: I/O | O45: 多言語対象 | P45: アウトプット | AR45: インプット | BC45: 備考
P46: マッピングデータ | X46: 初期値 | AA46: 表示コントロール | AI46: 有効コントロール | AR46: 必須 | AS46: 数字 | AT46: 文字 | AU46: マッピングデータ
P47: API名 | T47: 項目名 | AU47: API名 | AY47: 項目名
B48: 1 | D48: ヘッダー | K48: View | N48: － | O48: ● | P48: － | T48: － | X48: － | AA48: ー | AI48: － | AR48: － | AS48: ー | AT48: ー | AU48: － | AY48: ー
B49: 2 | D49: Edit Tab Title | K49: TEXT | N49: O | O49: ● | P49: － | T49: － | X49: 編集 | AA49: ー | AI49: ー | AR49: － | AS49: ー | AT49: ー | AU49: － | AY49: ー
B50: 3 | D50: Tab name title | K50: TEXT | N50: O | O50: ● | P50: － | T50: － | X50: タブ名 | AA50: ー | AI50: ー | AR50: － | AS50: ー | AT50: ー | AU50: － | AY50: ー
B51: 4 | D51: Tab name | K51: EditText | N51: I | O51: － | P51: － | T51: － | X51: － | AA51: ー | AI51: ー | AR51: － | AS51: ー | AT51: ー | AU51: － | AY51: ー | BC51: フォーカスして編集しているタブ名を表示する。
B52: 5 | D52: Color selection | K52: View | N52: － | O52: ● | P52: － | T52: － | X52: タブの色 | AA52: ー | AI52: 有効 | AR52: － | AS52: ー | AT52: ー | AU52: － | AY52: ー | BC52: フォーカスして編集しているタブの色を表示する。
B53: 6 | D53: empty tab | K53: View | N53: I | O53: ● | P53: － | T53: － | X53: 空のタブ | AA53: ー | AI53: 有効 | AR53: － | AS53: ー | AT53: ー | AU53: － | AY53: ー
B54: 7 | D54: Apply | K54: ボタン | N54: I | O54: ● | P54: － | T54: － | X54: Apply | AA54: ー | AI54: ー | AR54: － | AS54: ー | AT54: ー | AU54: － | AY54: ー
B55: 8 | D55: Store ID title | K55: TEXT | N55: O | O55: ● | P55: － | T55: － | X55: Cửa hàng | AA55: ー | AI55: ー | AR55: － | AS55: ー | AT55: ー | AU55: － | AY55: ー
B56: 9 | D56: Store Code | K56: TEXT | N56: I | O56: ● | P56: － | T56: － | AA56: ー | AI56: ー | AR56: － | AS56: ー | AT56: ー | AU56: － | AY56: ー | BC56: 「プリセット画面」から[store_code]がフォーカスされる
B57: 10 | D57: Business Type Name Title | K57: TEXT | N57: O | O57: ● | P57: － | T57: － | X57: Code layout preset | AA57: ー | AI57: ー | AR57: － | AS57: ー | AT57: ー | AU57: － | AY57: ー
B58: 11 | D58: busines type name | K58: TEXT | N58: O | O58: ● | P58: － | T58: － | AA58: ー | AI58: ー | AR58: － | AS58: ー | AT58: ー | AU58: － | AY58: ー | BC58: 「プリセット画面」から[branch_name]がフォーカスされる
B59: 12 | D59: Business Type Code Title | K59: TEXT | N59: O | O59: ● | P59: － | T59: － | X59: Tên | AA59: ー | AI59: ー | AR59: － | AS59: ー | AT59: ー | AU59: － | AY59: ー
B60: 13 | D60: Business Type Code | K60: TEXT | N60: O | O60: ● | P60: － | T60: － | AA60: ー | AI60: ー | AR60: － | AS60: ー | AT60: ー | AU60: － | AY60: ー | BC60: 「プリセット画面」から[business_type_code]がフォーカスされる
B61: 14 | D61: clear | K61: ボタン | N61: I | O61: ● | P61: － | T61: － | X61: F04: clear | AA61: ー | AI61: ー | AR61: － | AS61: ー | AT61: ー | AU61: － | AY61: ー
B62: 15 | D62: 検索 | K62: ボタン | N62: I | O62: ● | P62: － | T62: － | X62: F09: 確定」 | AA62: ー | AI62: ー | AR62: － | AS62: ー | AT62: ー | AU62: － | AY62: ー
B63: 16 | D63: Get tab | K63: View | N63: O | O63: ● | P63: － | T63: － | X63: － | AA63: ー | AI63: ー | AR63: － | AS63: ー | AT63: ー | AU63: － | AY63: ー
D64: Title | K64: TEXT | N64: O | O64: ● | P64: － | T64: － | X64: － | AA64: ー | AI64: ー | AR64: － | AS64: ー | AT64: ー | AU64: － | AY64: ー | BC64: Response P002 [desctiption]
D65: Color | K65: － | N65: O | O65: － | P65: － | T65: － | X65: － | AA65: ー | AI65: ー | AR65: － | AS65: ー | AT65: ー | AU65: － | AY65: ー | BC65: Response P002 [style_key]
D66: 位置 | K66: － | N66: O | O66: － | P66: － | T66: － | X66: － | AA66: ー | AI66: ー | AR66: － | AS66: ー | AT66: ー | AU66: － | AY66: ー | BC66: Response P002 [page_number]
B67: 17 | D67: タブ詳細 | K67: View | N67: O | O67: ● | P67: － | T67: － | AA67: ー | AI67: ー | AR67: － | AS67: ー | AT67: ー | AU67: － | AY67: ー
D68: コラムカウンタ | K68: － | N68: O | O68: － | P68: － | T68: － | AA68: ー | AI68: ー | AR68: － | AS68: ー | AT68: ー | AU68: － | AY68: ー | BC68: Response P002 [button_column_count]
D69: ロウカラム | K69: － | N69: O | O69: － | P69: － | T69: － | AA69: ー | AI69: ー | AR69: － | AS69: ー | AT69: ー | AU69: － | AY69: ー | BC69: Response P002 [button_row_count]
B70: 18 | D70: Item | K70: View | N70: O | O70: ● | P70: － | T70: － | AA70: ー | AI70: ー | AR70: － | AS70: ー | AT70: ー | AU70: － | AY70: ー
D71: カラム位置 | K71: － | N71: O | O71: － | P71: － | T71: － | AA71: ー | AI71: ー | AR71: － | AS71: ー | AT71: ー | AU71: － | AY71: ー | BC71: Response P002 [menu_buttons][].[button_column_number]
D72: ロウ位置 | K72: － | N72: O | O72: － | P72: － | T72: － | AA72: ー | AI72: ー | AR72: － | AS72: ー | AT72: ー | AU72: － | AY72: ー | BC72: Response P002 [menu_buttons][].[button_row_number]
D73: アイテムの幅 | K73: － | N73: O | O73: － | P73: － | T73: － | AA73: ー | AI73: ー | AR73: － | AS73: ー | AT73: ー | AU73: － | AY73: ー | BC73: Response P002 [menu_buttons][].[button_column_span]\
D74: アイテムの長さ | K74: － | N74: O | O74: － | P74: － | T74: － | AA74: ー | AI74: ー | AR74: － | AS74: ー | AT74: ー | AU74: － | AY74: ー | BC74: Response P002 [menu_buttons][].[button_column_span]
D75: Title | K75: － | N75: O | O75: － | P75: － | T75: － | AA75: ー | AI75: ー | AR75: － | AS75: ー | AT75: ー | AU75: － | AY75: ー | BC75: Response P002 [menu_buttons][].[description]
D76: イメージ | K76: － | N76: O | O76: － | P76: － | T76: － | AA76: ー | AI76: ー | AR76: － | AS76: ー | AT76: ー | AU76: － | AY76: ー | BC76: Response P002 [menu_buttons][].[style_information]

Sheet 「プリセット画面3」
A1: システム名 | K1: システム種別 | W1: =IF(表紙!W1="","",表紙!W1) -> 基本設計書 | AP1: 作成者 | AT1: 作成日 | AY1: 更新者 | BC1: 更新日 | BH1: 版数
A2: =IF(表紙!A2="","",表紙!A2) -> POSサーバー | K2: =IF(表紙!K2="","",表紙!K2) -> POSサーバー | AP2: =IF(表紙!AP2="","",表紙!AP2) -> DuNT | AT2: =IF(表紙!AT2="","",表紙!AT2) -> 45336 | AY2: =IF(表紙!AY2="","",表紙!AY2) -> DuNT | BC2: =IF(表紙!BC2="","",表紙!BC2) -> 45419 | BH2: =IF(表紙!BH2="","",表紙!BH2) -> 0.23
A4: 機能カテゴリ | H4: =IF(表紙!H4="","",表紙!H4) -> ●15_タッチメニュー設定 | U4: 項目 | Z4: =IF(表紙!Z4="","",表紙!Z4) -> 概要設計書 | AP4: {=RIGHT(CELL("filename",$A$1),LEN(CELL("filename",$A$1))-FIND("]",CELL("filename",$A$1)))} -> 「プリセット画面3」
B7: ■プリセット3画面イメージ
B43: ■画面項目定義
B45: 画面項目ID | D45: 項目名 | K45: タイプ | N45: I/O | O45: 多言語対象 | P45: アウトプット | AR45: インプット | BC45: 備考
P46: マッピングデータ | X46: 初期値 | AA46: 表示コントロール | AI46: 有効コントロール | AR46: 必須 | AS46: 数字 | AT46: 文字 | AU46: マッピングデータ
P47: API名 | T47: 項目名 | AU47: API名 | AY47: 項目名
B48: 1 | D48: Button edit title | K48: TEXT | N48: O | O48: ● | P48: － | T48: － | X48: Edit button | AA48: ー | AI48: － | AR48: － | AS48: ー | AT48: ー | AU48: － | AY48: ー
B49: 2 | D49: Button type title | K49: TEXT | N49: O | O49: ● | P49: － | T49: － | X49: Button type | AA49: ー | AI49: ー | AR49: － | AS49: ー | AT49: ー | AU49: － | AY49: ー
B50: 3 | D50: Tab product info | K50: ボタン | N50: O | O50: ● | P50: － | T50: － | X50: Sản phẩm D | AA50: ー | AI50: Enable | AR50: － | AS50: ー | AT50: ー | AU50: － | AY50: ー
B51: 3.1 | D51: product ID title | K51: TEXT | N51: O | O51: ● | P51: － | T51: － | X51: Code sản phẩm/code PLU | AA51: ー | AI51: ー | AR51: － | AS51: ー | AT51: ー | AU51: － | AY51: ー
B52: 3.2 | D52: Product sub description | K52: TEXT | N52: O | O52: － | P52: － | T52: － | X52: ー | AA52: ー | AI52: ー | AR52: － | AS52: ー | AT52: ー | AU52: － | AY52: ー | BC52: Res P002 [productInfo]. [sub_description]
B53: 3.3 | D53: Parent code | K53: TEXT | N53: O | O53: － | P53: － | T53: － | X53: ー | AA53: ー | AI53: ー | AR53: － | AS53: ー | AT53: ー | AU53: － | AY53: ー | BC53: Res P002 [productInfo]. [parent_code]
B54: 3.4 | D54: PLU code value | K54: TEXT | N54: O | O54: － | P54: － | T54: － | X54: ー | AA54: ー | AI54: ー | AR54: － | AS54: ー | AT54: ー | AU54: － | AY54: ー | BC54: Res P002 [productInfo]. [item_code]
B55: 3.5 | D55: price title | K55: TEXT | N55: O | O55: ● | P55: － | T55: － | X55: Giá bán | AA55: ー | AI55: ー | AR55: － | AS55: ー | AT55: ー | AU55: － | AY55: ー
B56: 3.6 | D56: price value | K56: テキスト | N56: I | O56: － | P56: － | T56: － | X56: － | AA56: ー | AI56: ー | AR56: － | AS56: ー | AT56: ー | AU56: － | AY56: ー | BC56: Res S100-sales/item/add-item : [item_unit_price]
B57: 3.7 | D57: Button type title | K57: TEXT | N57: O | O57: ● | P57: － | T57: － | X57: ボタン名 | AA57: ー | AI57: ー | AR57: － | AS57: ー | AT57: ー | AU57: － | AY57: ー
B58: 3.8 | D58: name | K58: テキスト | N58: I | O58: － | P58: － | T58: － | X58: － | AA58: ー | AI58: ー | AR58: － | AS58: ー | AT58: ー | AU58: － | AY58: ー | BC58: Res S100-sales/item/add-item : [item_name]
B59: 3.9 | D59: Button color | K59: View | N59: O | O59: ● | P59: － | T59: － | X59: Màu button | AA59: ー | AI59: ー | AR59: － | AS59: ー | AT59: ー | AU59: － | AY59: ー | BC59: Res P002[menu_buttons][]. [style_key]
B60: 3.10 | D60: Button size title | K60: TEXT | N60: O | O60: ● | P60: － | T60: － | X60: Button size | AA60: ー | AI60: ー | AR60: － | AS60: ー | AT60: ー | AU60: － | AY60: ー
B61: 3.11 | D61: button height title | K61: TEXT | N61: O | O61: ● | P61: － | T61: － | X61: Chiều dọc | AA61: ー | AI61: ー | AR61: － | AS61: ー | AT61: ー | AU61: － | AY61: ー
B62: 3.12 | D62: button height title | K62: テキスト | N62: I | O62: － | P62: － | T62: － | X62: － | AA62: ー | AI62: ー | AR62: － | AS62: ー | AT62: ー | AU62: － | AY62: ー | BC62: Res P002[menu_buttons][]. [button_row_span]
B63: 3.13 | D63: button width title | K63: TEXT | N63: O | O63: ● | P63: － | T63: － | X63: － | AA63: ー | AI63: ー | AR63: － | AS63: ー | AT63: ー | AU63: － | AY63: ー
B64: 3.14 | D64: button width value | K64: テキスト | N64: I | O64: － | P64: － | T64: － | X64: － | AA64: ー | AI64: ー | AR64: － | AS64: ー | AT64: ー | AU64: － | AY64: ー | BC64: Res P002[menu_buttons][]. [button_column_span]
B65: 3.15 | D65: image title | K65: TEXT | N65: O | O65: ● | P65: － | T65: － | X65: イメージ | AA65: ー | AI65: ー | AR65: － | AS65: ー | AT65: ー | AU65: － | AY65: ー
B66: 3.16 | D66: イメージ | K66: View | N66: I | O66: － | P66: － | T66: － | X66: － | AA66: ー | AI66: ー | AR66: － | AS66: ー | AT66: ー | AU66: － | AY66: ー | BC66: Res P002[menu_buttons][]. [style_information]
B67: 3.17 | D67: Change price | K67: ボタン | N67: I | O67: ● | P67: － | T67: － | X67: 売価変更 | AA67: ー | AI67: ー | AR67: － | AS67: ー | AT67: ー | AU67: － | AY67: ー | BC67: PresetMenuButtonMaster[StyleInformation]
B68: 4 | D68: Department tab | K68: ボタン | N68: I | O68: ● | P68: － | T68: － | X68: Phòng ban | AA68: ー | AI68: ー | AR68: － | AS68: ー | AT68: ー | AU68: － | AY68: ー
B69: 5 | D69: brand tab | K69: ボタン | N69: I | O69: ● | P69: － | T69: － | X69: 商品種類 | AA69: ー | AI69: ー | AR69: － | AS69: ー | AT69: ー | AU69: － | AY69: ー
B70: 6 | D70: function tab | K70: ボタン | N70: I | O70: ● | P70: － | T70: － | X70: Tên chức năng | AA70: ー | AI70: ー | AR70: － | AS70: ー | AT70: ー | AU70: － | AY70: ー
B71: 7 | D71: presview | K71: ボタン | N71: I | O71: ● | P71: － | T71: － | X71: Apply | AA71: ー | AI71: ー | AR71: － | AS71: ー | AT71: ー | AU71: － | AY71: ー
B72: 8 | D72: Xóa preset | K72: ボタン | N72: I | O72: ● | P72: － | T72: － | X72: Xóa | AA72: ー | AI72: ー | AR72: － | AS72: ー | AT72: ー | AU72: － | AY72: ー
B73: 9 | D73: Clear thay đổi | K73: ボタン | N73: I | O73: ● | P73: － | T73: － | X73: clear | AA73: ー | AI73: ー | AR73: － | AS73: ー | AT73: ー | AU73: － | AY73: ー
B74: 10 | D74: Apply | K74: ボタン | N74: I | O74: ● | P74: － | T74: － | X74: 確定」 | AA74: ー | AI74: ー | AR74: － | AS74: ー | AT74: ー | AU74: － | AY74: ー | BC74: プレビューされた変更はDBに更新される。

Sheet 画面設計
A1: システム名 | K1: システム種別 | W1: =IF(表紙!W1="","",表紙!W1) -> 基本設計書 | AP1: 作成者 | AT1: 作成日 | AY1: 更新者 | BC1: 更新日 | BH1: 版数
A2: =IF(表紙!A2="","",表紙!A2) -> POSサーバー | K2: =IF(表紙!K2="","",表紙!K2) -> POSサーバー | AP2: =IF(表紙!AP2="","",表紙!AP2) -> DuNT | AT2: =IF(表紙!AT2="","",表紙!AT2) -> 45336 | AY2: =IF(表紙!AY2="","",表紙!AY2) -> DuNT | BC2: =IF(表紙!BC2="","",表紙!BC2) -> 45419 | BH2: =IF(表紙!BH2="","",表紙!BH2) -> 0.23
A4: 機能カテゴリ | H4: =IF(表紙!H4="","",表紙!H4) -> ●15_タッチメニュー設定 | U4: 項目 | Z4: =IF(表紙!Z4="","",表紙!Z4) -> 概要設計書 | AP4: {=RIGHT(CELL("filename",$A$1),LEN(CELL("filename",$A$1))-FIND("]",CELL("filename",$A$1)))} -> 画面設計

Sheet テンプレート
A1: システム名 | K1: システム種別 | W1: =IF(表紙!W1="","",表紙!W1) -> 基本設計書 | AP1: 作成者 | AT1: 作成日 | AY1: 更新者 | BC1: 更新日 | BH1: 版数
A2: =IF(表紙!A2="","",表紙!A2) -> POSサーバー | K2: =IF(表紙!K2="","",表紙!K2) -> POSサーバー | AP2: =IF(表紙!AP2="","",表紙!AP2) -> DuNT | AT2: =IF(表紙!AT2="","",表紙!AT2) -> 45336 | AY2: =IF(表紙!AY2="","",表紙!AY2) -> DuNT | BC2: =IF(表紙!BC2="","",表紙!BC2) -> 45419 | BH2: =IF(表紙!BH2="","",表紙!BH2) -> 0.23
A4: 機能カテゴリ | H4: =IF(表紙!H4="","",表紙!H4) -> ●15_タッチメニュー設定 | U4: 項目 | Z4: =IF(表紙!Z4="","",表紙!Z4) -> 概要設計書 | AP4: {=RIGHT(CELL("filename",$A$1),LEN(CELL("filename",$A$1))-FIND("]",CELL("filename",$A$1)))} -> テンプレート
