Workbook

Sheet 表紙
A1: システム名 | K1: システム種別 | W1: 基本設計書 | AP1: 作成者 | AT1: 作成日 | AY1: 更新者 | BC1: 更新日 | BH1: 版数
A2: POSサーバー | K2: POSサーバ | AP2: =改訂履歴!$H$11 -> TinNH | AT2: =改訂履歴!$B$11 -> 45467 | AY2: =LOOKUP(2,1/(改訂履歴!H11:H30000<>""),改訂履歴!H11:H30000) -> AnhNM | BC2: =LOOKUP(2,1/(改訂履歴!B11:B30000<>""),改訂履歴!B11:B30000) -> 45590 | BH2: =LOOKUP(2,1/(改訂履歴!O11:O30000<>""),改訂履歴!O11:O30000) -> 0.4
A4: 機能カテゴリ | H4: 96_カテゴリ割引レシートクーポン設定 | U4: 項目 | Z4: 概要設計 | AP4: {=RIGHT(CELL("filename",$A$1),LEN(CELL("filename",$A$1))-FIND("]",CELL("filename",$A$1)))} -> 表紙
L16: POSサーバーの基本設計書
L24: =K2&"/"&H4&"/"&Z4 -> POSサーバ/96_カテゴリ割引レシートクーポン設定/概要設計
Q44: 承認日 | AA44: 承認者 | AQ44: 版数

Sheet 改訂履歴
A1: システム名 | K1: システム種別 | W1: =IF(表紙!W1="","",表紙!W1) -> 基本設計書 | AP1: 作成者 | AT1: 作成日 | AY1: 更新者 | BC1: 更新日 | BH1: 版数
A2: =IF(表紙!A2="","",表紙!A2) -> POSサーバー | K2: =IF(表紙!K2="","",表紙!K2) -> POSサーバ | AP2: =IF(表紙!AP2="","",表紙!AP2) -> TinNH | AT2: =IF(表紙!AT2="","",表紙!AT2) -> 45467 | AY2: =IF(表紙!AY2="","",表紙!AY2) -> AnhNM | BC2: =IF(表紙!BC2="","",表紙!BC2) -> 45590 | BH2: =IF(表紙!BH2="","",表紙!BH2) -> 0.4
A4: 機能カテゴリー | H4: =IF(表紙!H4="","",表紙!H4) -> 96_カテゴリ割引レシートクーポン設定 | U4: 項目 | Z4: =IF(表紙!Z4="","",表紙!Z4) -> 概要設計 | AP4: {=RIGHT(CELL("filename",$A$1),LEN(CELL("filename",$A$1))-FIND("]",CELL("filename",$A$1)))} -> 改訂履歴
B8: ■改訂履歴
B10: 更新日 | H10: 更新者 | O10: 版数 | S10: 更新内容 | AX10: 承認日 | BD10: 承認者
B11: 45467 | H11: TinNH | O11: 0.1 | S11: 新規
B13: 45469 | H13: TinNH | O13: 0.2 | S13: お客様から送付された資料による更新
B15: 45476 | H15: TinNH | O15: 0.3 | S15: 6月27日にお客様から送付された資料による更新
B17: 45590 | H17: AnhNM | O17: 0.4 | S17: 機能概要
S18: ・カテゴリ（階層）設定画面の記載を追加する。 ・複数のメッセージ（表・裏）作成の記載を追加する。

Sheet 指摘履歴
A1: システム名 | K1: システム種別 | W1: 基本設計書 | AP1: 作成者 | AT1: 作成日 | AY1: 更新者 | BC1: 更新日 | BH1: 版数
A2: POSサーバー | K2: POSサーバー | AP2: カスミ | AT2: 45586 | AY2: 佐々木 | BC2: 45586 | BH2: 0.3
A4: 機能カテゴリ | H4: 96_カテゴリ割引レシートクーポン設定 | U4: 項目 | Z4: 概要設計書 | AP4: 指摘履歴
B8: ■改訂履歴
B10: 更新日 | H10: 更新者 | O10: 版数 | S10: 更新内容 | AX10: 確認日 | BD10: 確認者
B11: 45586 | H11: 佐々木 | S11: 機能概要
S12: カテゴリ（階層）設定画面が記載されていません。
B13: 45586 | H13: 佐々木 | S13: 機能概要
S14: メッセージ（表・裏）複数行設定が必要です。

Sheet 業務フロー
A1: システム名 | K1: システム種別 | W1: =IF(表紙!W1="","",表紙!W1) -> 基本設計書 | AP1: 作成者 | AT1: 作成日 | AY1: 更新者 | BC1: 更新日 | BH1: 版数
A2: =IF(表紙!A2="","",表紙!A2) -> POSサーバー | K2: =IF(表紙!K2="","",表紙!K2) -> POSサーバ | AP2: =IF(表紙!AP2="","",表紙!AP2) -> TinNH | AT2: 45084 | AY2: =IF(表紙!AY2="","",表紙!AY2) -> AnhNM | BC2: =IF(表紙!BC2="","",表紙!BC2) -> 45590 | BH2: =IF(表紙!BH2="","",表紙!BH2) -> 0.4
A4: 機能カテゴリー | H4: =IF(表紙!H4="","",表紙!H4) -> 96_カテゴリ割引レシートクーポン設定 | U4: 項目 | Z4: =IF(表紙!Z4="","",表紙!Z4) -> 概要設計 | AP4: {=RIGHT(CELL("filename",$A$1),LEN(CELL("filename",$A$1))-FIND("]",CELL("filename",$A$1)))} -> 業務フロー
B7: ●1_自動釣銭機
B22: ●1_レジ周辺機器
B42: ●外部連携

Sheet 機能概要説明
A1: システム名 | K1: システム種別 | W1: =IF(表紙!W1="","",表紙!W1) -> 基本設計書 | AP1: 作成者 | AT1: 作成日 | AY1: 更新者 | BC1: 更新日 | BH1: 版数
A2: =IF(表紙!A2="","",表紙!A2) -> POSサーバー | K2: =IF(表紙!K2="","",表紙!K2) -> POSサーバ | AP2: =IF(表紙!AP2="","",表紙!AP2) -> TinNH | AT2: =IF(表紙!AT2="","",表紙!AT2) -> 45467 | AY2: =IF(表紙!AY2="","",表紙!AY2) -> AnhNM | BC2: =IF(表紙!BC2="","",表紙!BC2) -> 45590 | BH2: =IF(表紙!BH2="","",表紙!BH2) -> 0.4
A4: 機能カテゴリ | H4: =IF(表紙!H4="","",表紙!H4) -> 96_カテゴリ割引レシートクーポン設定 | U4: 項目 | Z4: =IF(表紙!Z4="","",表紙!Z4) -> 概要設計 | AP4: {=RIGHT(CELL("filename",$A$1),LEN(CELL("filename",$A$1))-FIND("]",CELL("filename",$A$1)))} -> 機能概要説明
B7: カテゴリ割引レシートクーポン設定機能では次のことが可能になる。 | BM7: =IF(BM6=50,1,BM6+1) -> 1
C8: ・1つ又は複数の店舗のカテゴリのレシートクーポンを閲覧、追加、編集、削除する。 | BM8: =IF(BM7=50,1,BM7+1) -> 2
C9: ・カテゴリ割引レシートクーポンは、ユーザーが発券期間内にお買い物をした場合にお買い上げレシートの後に印刷されるカテゴリのクーポン券である。 | BM9: =IF(BM8=50,1,BM8+1) -> 3
C10: ・また、クーポン券に印字されている期間内でのお買い物時に使用できるものとなる。 | BM10: =IF(BM9=50,1,BM9+1) -> 4
BM11: =IF(BM10=50,1,BM10+1) -> 5
BM12: =IF(BM11=50,1,BM11+1) -> 6
BM13: =IF(BM12=50,1,BM12+1) -> 7
BM14: =IF(BM13=50,1,BM13+1) -> 8
BM15: =IF(BM14=50,1,BM14+1) -> 9
BM16: =IF(BM15=50,1,BM15+1) -> 10
BM17: =IF(BM16=50,1,BM16+1) -> 11
BM18: =IF(BM17=50,1,BM17+1) -> 12
BM19: =IF(BM18=50,1,BM18+1) -> 13
BM20: =IF(BM19=50,1,BM19+1) -> 14
BM21: =IF(BM20=50,1,BM20+1) -> 15
BM22: =IF(BM21=50,1,BM21+1) -> 16
... BM57: =IF(BM56=50,1,BM56+1) -> 1

Sheet 機能概要
A1: システム名 | K1: システム種別 | W1: =IF(表紙!W1="","",表紙!W1) -> 基本設計書 | AP1: 作成者 | AT1: 作成日 | AY1: 更新者 | BC1: 更新日 | BH1: 版数
A2: =IF(表紙!A2="","",表紙!A2) -> POSサーバー | K2: =IF(表紙!K2="","",表紙!K2) -> POSサーバ | AP2: =IF(表紙!AP2="","",表紙!AP2) -> TinNH | AT2: =IF(表紙!AT2="","",表紙!AT2) -> 45467 | AY2: =IF(表紙!AY2="","",表紙!AY2) -> AnhNM | BC2: =IF(表紙!BC2="","",表紙!BC2) -> 45590 | BH2: =IF(表紙!BH2="","",表紙!BH2) -> 0.4
A4: 機能カテゴリ | U4: 項目 | Z4: =IF(表紙!Z4="","",表紙!Z4) -> 概要設計 | AP4: {=RIGHT(CELL("filename",$A$1),LEN(CELL("filename",$A$1))-FIND("]",CELL("filename",$A$1)))} -> 機能概要
B7: 96_カテゴリ割引レシートクーポン設定
BM8: =IF(BM7=50,1,BM7+1) -> 1
BM9: =IF(BM8=50,1,BM8+1) -> 2
BM10: =IF(BM9=50,1,BM9+1) -> 3
BM11: =IF(BM10=50,1,BM10+1) -> 4
BM12: =IF(BM11=50,1,BM11+1) -> 5
BM13: =IF(BM12=50,1,BM12+1) -> 6
BM14: =IF(BM13=50,1,BM13+1) -> 7
BM15: =IF(BM14=50,1,BM14+1) -> 8
B16: FC9601_カテゴリ割引レシートクーポン追加・編集機能 | BM16: =IF(BM15=50,1,BM15+1) -> 9
BM17: =IF(BM16=50,1,BM16+1) -> 10
BM18: =IF(BM17=50,1,BM17+1) -> 11
BM19: =IF(BM18=50,1,BM18+1) -> 12
BM20: =IF(BM19=50,1,BM19+1) -> 13
BM21: =IF(BM20=50,1,BM20+1) -> 14
BM22: =IF(BM21=50,1,BM21+1) -> 15
BM23: =IF(BM22=50,1,BM22+1) -> 16
BM24: =IF(BM23=50,1,BM23+1) -> 17 | BO24: サンプル：
BM25: =IF(BM24=50,1,BM24+1) -> 18 | BO25: StoreIdが「09999」以外である。
BM26: =IF(BM25=50,1,BM25+1) -> 19
BM27: =IF(BM26=50,1,BM26+1) -> 20
BM28: =IF(BM27=50,1,BM27+1) -> 21
BM29: =IF(BM28=50,1,BM28+1) -> 22
BM30: =IF(BM29=50,1,BM29+1) -> 23
BM31: =IF(BM30=50,1,BM30+1) -> 24
BM32: =IF(BM31=50,1,BM31+1) -> 25
BM33: =IF(BM32=50,1,BM32+1) -> 26
BM34: =IF(BM33=50,1,BM33+1) -> 27
BM35: =IF(BM34=50,1,BM34+1) -> 28
BM36: =IF(BM35=50,1,BM35+1) -> 29
BM37: =IF(BM36=50,1,BM36+1) -> 30
... BM50: =IF(BM49=50,1,BM49+1) -> 43
BM51: =IF(BM50=50,1,BM50+1) -> 44 | BO51: StoreIdが「09999」である。
BM52: =IF(BM51=50,1,BM51+1) -> 45
BM53: =IF(BM52=50,1,BM52+1) -> 46
BM54: =IF(BM53=50,1,BM53+1) -> 47
BM55: =IF(BM54=50,1,BM54+1) -> 48
...

Sheet 画面イメージ
B2: 新規
C6: 店舗 | P6: ▼
C8: タイトル
C10: 印字期間 | Z10: ～
C12: 利用可能期間 | Z12: ～
C14: クーポン券コード
C16: 表面
C17: メッセージ | P17: ▼
C19: 裏面
C20: タイトル
C21: メッセージ | P21: ▼
C23: 更新日 | P23: yy/mm/dd
C24: 更新者 | P24: 〇〇
D30: +
D31: -
D32: -
B43: 編集
C47: 店舗 | P47: ▼
C49: タイトル
C51: 印字期間 | Z51: ～
C53: 利用可能期間 | Z53: ～
C55: クーポン券コード
C57: 表面
C58: メッセージ | P58: ▼
C60: 裏面
C61: タイトル
C62: メッセージ | P62: ▼
C64: 更新日 | P64: yy/mm/dd
C65: 更新者 | P65: 〇〇
D71: +
D72: -
D73: -

Sheet 画面設計書
A1: システム名 | K1: システム種別 | W1: =IF(表紙!W1="","",表紙!W1) -> 基本設計書 | AP1: 作成者 | AT1: 作成日 | AY1: 更新者 | BC1: 更新日 | BH1: 版数
A2: =IF(表紙!A2="","",表紙!A2) -> POSサーバー | K2: =IF(表紙!K2="","",表紙!K2) -> POSサーバ | AP2: =IF(表紙!AP2="","",表紙!AP2) -> TinNH | AT2: =IF(表紙!AT2="","",表紙!AT2) -> 45467 | AY2: =IF(表紙!AY2="","",表紙!AY2) -> AnhNM | BC2: =IF(表紙!BC2="","",表紙!BC2) -> 45590 | BH2: =IF(表紙!BH2="","",表紙!BH2) -> 0.4
A4: 機能カテゴリ | H4: =IF(表紙!H4="","",表紙!H4) -> 96_カテゴリ割引レシートクーポン設定 | U4: 項目 | Z4: =IF(表紙!Z4="","",表紙!Z4) -> 概要設計 | AP4: =MID(CELL("filename",A1),FIND("]",CELL("filename",A1))+1,255) -> 画面設計書
B7: ■ログイン画面のイメージ
B35: ■画面項目定義
B37: 画面項目ID | D37: 項目 | K37: タイプ | N37: I/O | O37: 多言語対象 | P37: 出力 | AR37: インプット | BC37: 備考
P38: マッピングデータ | X38: 初期値 | AA38: 表示コントロール | AI38: Control enable | AR38: 必須 | AS38: 数字 | AT38: 桁 | AU38: マッピングデータ
P39: API名 | T39: 項目 | AU39: API名 | AY39: 項目
B40: 1 | K40: テキスト | N40: － | O40: ● | P40: － | T40: － | X40: Android POS Control | AA40: ー | AI40: － | AR40: － | AS40: ー | AT40: ー | AU40: － | AY40: ー
B41: 2 | K41: テキスト | N41: O | O41: ● | P41: － | T41: － | X41: User ID | AA41: ー | AI41: ー | AR41: － | AS41: ー | AT41: ー | AU41: － | AY41: ー
B42: 3 | K42: テキスト | N42: I | O42: － | P42: － | X42: － | AA42: ー | AI42: ー | AR42: － | AS42: ー | AT42: ー | AU42: － | AY42: ー
B43: 4 | K43: テキスト | N43: O | O43: ● | P43: － | T43: － | X43: Password | AA43: ー | AI43: ー | AR43: － | AS43: ー | AT43: ー | AU43: － | AY43: ー
B44: 5 | K44: EditText | N44: I | O44: － | P44: － | T44: － | X44: － | AA44: ー | AI44: ー | AR44: － | AS44: ー | AT44: ー | AU44: － | AY44: ー
B45: 6 | K45: ボタン | N45: I | O45: ● | P45: － | T45: － | X45: Login | AA45: ー | AI45: 有効 | AR45: － | AS45: ー | AT45: ー | AU45: － | AY45: ー | BC45: Login-01/EmployeeMaster

Sheet テンプレート
A1: システム名 | K1: システム種別 | W1: =IF(表紙!W1="","",表紙!W1) -> 基本設計書 | AP1: 作成者 | AT1: 作成日 | AY1: 更新者 | BC1: 更新日 | BH1: 版数
A2: =IF(表紙!A2="","",表紙!A2) -> POSサーバー | K2: =IF(表紙!K2="","",表紙!K2) -> POSサーバ | AP2: =IF(表紙!AP2="","",表紙!AP2) -> TinNH | AT2: =IF(表紙!AT2="","",表紙!AT2) -> 45467 | AY2: =IF(表紙!AY2="","",表紙!AY2) -> AnhNM | BC2: =IF(表紙!BC2="","",表紙!BC2) -> 45590 | BH2: =IF(表紙!BH2="","",表紙!BH2) -> 0.4
A4: 機能カテゴリ | H4: =IF(表紙!H4="","",表紙!H4) -> 96_カテゴリ割引レシートクーポン設定 | U4: 項目 | Z4: =IF(表紙!Z4="","",表紙!Z4) -> 概要設計 | AP4: =MID(CELL("filename",A1),FIND("]",CELL("filename",A1))+1,255) -> テンプレート
AX12: `
