Workbook

Sheet 表紙
A1: システム名 | K1: システム種別 | W1: 基本設計書 | AP1: 作成者 | AT1: 作成日 | AY1: 更新者 | BC1: 更新日 | BH1: 版数
A2: POSサーバー | K2: POSサーバ | AP2: =改訂履歴!$H$11 -> LoiLV | AT2: =改訂履歴!$B$11 -> 45427 | AY2: =LOOKUP(2,1/(改訂履歴!H11:H29999<>""),改訂履歴!H11:H29999) -> AnhNM | BC2: =LOOKUP(2,1/(改訂履歴!B11:B29999<>""),改訂履歴!B11:B29999) -> 45588 | BH2: =LOOKUP(2,1/(改訂履歴!O11:O29999<>""),改訂履歴!O11:O29999) -> 0.4
A4: 機能カテゴリ | H4: 31_レジ別速報/日報 | U4: 項目 | Z4: 概要設計 | AP4: {=RIGHT(CELL("filename",$A$1),LEN(CELL("filename",$A$1))-FIND("]",CELL("filename",$A$1)))} -> 表紙
L16: POSサーバーの基本設計書
L24: =K2&"/"&H4&"/"&Z4 -> POSサーバ/31_レジ別速報/日報/概要設計
Q44: 承認日 | AA44: 承認者 | AQ44: 版数

Sheet 改訂履歴
A1: システム名 | K1: システム種別 | W1: =IF(表紙!W1="","",表紙!W1) -> 基本設計書 | AP1: 作成者 | AT1: 作成日 | AY1: 更新者 | BC1: 更新日 | BH1: 版数
A2: =IF(表紙!A2="","",表紙!A2) -> POSサーバー | K2: =IF(表紙!K2="","",表紙!K2) -> POSサーバ | AP2: =IF(表紙!AP2="","",表紙!AP2) -> LoiLV | AT2: =IF(表紙!AT2="","",表紙!AT2) -> 45427 | AY2: =IF(表紙!AY2="","",表紙!AY2) -> AnhNM | BC2: =IF(表紙!BC2="","",表紙!BC2) -> 45588 | BH2: =IF(表紙!BH2="","",表紙!BH2) -> 0.4
A4: 機能カテゴリー | H4: =IF(表紙!H4="","",表紙!H4) -> 31_レジ別速報/日報 | U4: 項目 | Z4: =IF(表紙!Z4="","",表紙!Z4) -> 概要設計 | AP4: {=RIGHT(CELL("filename",$A$1),LEN(CELL("filename",$A$1))-FIND("]",CELL("filename",$A$1)))} -> 改訂履歴
B8: ■改訂履歴
B10: 更新日 | H10: 更新者 | O10: 版数 | S10: 更新内容 | AX10: 承認日 | BD10: 承認者
B11: 45427 | H11: LoiLV | O11: 0.1 | S11: 新規
B13: 45503 | H13: TinNH | O13: 0.2 | S13: コメントによる更新
S14: ・テナント項目を追加し、一覧画面と詳細画面でテナント別レジの売上レポートを表示可能とする。
B15: 45524 | H15: DuNT | O15: 0.3 | S15: 機能概要説明：説明追加
S16: 機能概要：レジ別レポート出力AP3103を追加する
S17: 機能概要：テナント項目を削除し、店舗選択モーダルを削除する
B18: 45588 | H18: AnhNM | O18: 0.4 | S18: 機能概要
S19: ・「入金・出金」：詳細の画面に表示する項目名は「レジ精算」の項目名と合わせる ・レジ別日報画面へ380アテンダントモニタはを表示するかはレジマスタで持たせて管理する ・「在高・値引」：「+当月度累計件数」を「+当月度累計金額」に修正 ・「在高・値引」：SM値引きを追加

Sheet 指摘履歴
A1: システム名 | K1: システム種別 | W1: =IF([1]表紙!W1="","",[1]表紙!W1) -> 基本設計書 | AP1: 作成者 | AT1: 作成日 | AY1: 更新者 | BC1: 更新日 | BH1: 版数
A2: =IF([1]表紙!A2="","",[1]表紙!A2) -> POSサーバー | K2: =IF([1]表紙!K2="","",[1]表紙!K2) -> POSサーバ | AP2: =IF([1]表紙!AP2="","",[1]表紙!AP2) -> LoiLV | AT2: =IF([1]表紙!AT2="","",[1]表紙!AT2) -> 45427 | AY2: =IF([1]表紙!AY2="","",[1]表紙!AY2) -> DuNT | BC2: =IF([1]表紙!BC2="","",[1]表紙!BC2) -> 45524 | BH2: =IF([1]表紙!BH2="","",[1]表紙!BH2) -> 0.3
A4: 機能カテゴリー | H4: =IF([1]表紙!H4="","",[1]表紙!H4) -> 31_レジ別速報/日報 | U4: 項目 | Z4: =IF([1]表紙!Z4="","",[1]表紙!Z4) -> 概要設計 | AP4: {=RIGHT(CELL("filename",$A$1),LEN(CELL("filename",$A$1))-FIND("]",CELL("filename",$A$1)))} -> 指摘履歴
B8: ■指摘履歴
B10: 更新日 | H10: 更新者 | O10: 版数 | S10: 更新内容 | AX10: 確認日 | BD10: 確認者
B11: 45545 | H11: KSM中澤 | S11: 詳細の画面に表示する項目名は「レジ精算」の項目名と合わせてください
S12: ※ 現在の仕様と同じようにクーポン等は明細を表示する
B13: 45545 | H13: KSM中澤 | S13: 380アテンダントモニタはレジ一覧に表示しないようにしてください
S14: ※レジ別日報画面へ表示するかはレジマスタで持たせて管理する
B15: 45545 | H15: KSM中澤 | S15: 【機能概要】シートより SC3102_レジ別速報/日報（詳細）画面での印刷アイコンをタッチすると、画面上の項目一覧を印刷するでしょうか。
S16: ご説明お願い致します。
S17: →その認識です、【レジ別詳細の印刷データ】シートに実際に印刷されるデータを添付しましたのでご確認ください
B18: 45545 | H18: KSM中澤 | S18: 【機能概要】シートに記載されている「+当月度累計件数」という文言に誤りがありましたので修正お願いします
S19: ※ 該当箇所に赤丸で印をつけましたのでご確認ください

Sheet 業務フロー
A1: システム名 | K1: システム種別 | W1: =IF(表紙!W1="","",表紙!W1) -> 基本設計書 | AP1: 作成者 | AT1: 作成日 | AY1: 更新者 | BC1: 更新日 | BH1: 版数
A2: =IF(表紙!A2="","",表紙!A2) -> POSサーバー | K2: =IF(表紙!K2="","",表紙!K2) -> POSサーバ | AP2: =IF(表紙!AP2="","",表紙!AP2) -> LoiLV | AT2: 45084 | AY2: =IF(表紙!AY2="","",表紙!AY2) -> AnhNM | BC2: =IF(表紙!BC2="","",表紙!BC2) -> 45588 | BH2: =IF(表紙!BH2="","",表紙!BH2) -> 0.4
A4: 機能カテゴリー | H4: =IF(表紙!H4="","",表紙!H4) -> 31_レジ別速報/日報 | U4: 項目 | Z4: =IF(表紙!Z4="","",表紙!Z4) -> 概要設計 | AP4: {=RIGHT(CELL("filename",$A$1),LEN(CELL("filename",$A$1))-FIND("]",CELL("filename",$A$1)))} -> 業務フロー
B7: ●1_自動釣銭機
B22: ●1_レジ周辺機器
B42: ●外部連携

Sheet 機能概要説明
A1: システム名 | K1: システム種別 | W1: =IF(表紙!W1="","",表紙!W1) -> 基本設計書 | AP1: 作成者 | AT1: 作成日 | AY1: 更新者 | BC1: 更新日 | BH1: 版数
A2: =IF(表紙!A2="","",表紙!A2) -> POSサーバー | K2: =IF(表紙!K2="","",表紙!K2) -> POSサーバ | AP2: =IF(表紙!AP2="","",表紙!AP2) -> LoiLV | AT2: =IF(表紙!AT2="","",表紙!AT2) -> 45427 | AY2: =IF(表紙!AY2="","",表紙!AY2) -> AnhNM | BC2: =IF(表紙!BC2="","",表紙!BC2) -> 45588 | BH2: =IF(表紙!BH2="","",表紙!BH2) -> 0.4
A4: 機能カテゴリ | H4: =IF(表紙!H4="","",表紙!H4) -> 31_レジ別速報/日報 | U4: 項目 | Z4: =IF(表紙!Z4="","",表紙!Z4) -> 概要設計 | AP4: {=RIGHT(CELL("filename",$A$1),LEN(CELL("filename",$A$1))-FIND("]",CELL("filename",$A$1)))} -> 機能概要説明
B7: レジ別速報/日報機能では次のことが可能になる。 | BM7: =IF(BM6=50,1,BM6+1) -> 1
C8: ・現在日の速報、店舗の特定日別各レジのレポート一覧を検索する。 | BM8: =IF(BM7=50,1,BM7+1) -> 2
C9: ・店舗内の各レジ機の合計レポートを統計する。 | BM9: =IF(BM8=50,1,BM8+1) -> 3
C10: ・各レジのレポート詳細を速報、日報、月報の形式で閲覧する。 | BM10: =IF(BM9=50,1,BM9+1) -> 4
C11: ・レポート詳細情報：売上部門、税・決済、入金・出、在高・値引、操作 | BM11: =IF(BM10=50,1,BM10+1) -> 5
C12: ・レジのレポートを印刷する。 | BM12: =IF(BM11=50,1,BM11+1) -> 6
BM13: =IF(BM12=50,1,BM12+1) -> 7
B14: 適用対象店舗: 通常店舗、ベンケイ店舗、ブランデ店舗など | BM14: =IF(BM13=50,1,BM13+1) -> 8
BM15: =IF(BM14=50,1,BM14+1) -> 9
BM16: =IF(BM15=50,1,BM15+1) -> 10
BM17: =IF(BM16=50,1,BM16+1) -> 11
BM18: =IF(BM17=50,1,BM17+1) -> 12
BM19: =IF(BM18=50,1,BM18+1) -> 13
BM20: =IF(BM19=50,1,BM19+1) -> 14
BM21: =IF(BM20=50,1,BM20+1) -> 15
BM22: =IF(BM21=50,1,BM21+1) -> 16
BM23: =IF(BM22=50,1,BM22+1) -> 17
BM24: =IF(BM23=50,1,BM23+1) -> 18
BM25: =IF(BM24=50,1,BM24+1) -> 19
BM26: =IF(BM25=50,1,BM25+1) -> 20
... BM57: =IF(BM56=50,1,BM56+1) -> 1

Sheet 機能概要
A1: システム名 | K1: システム種別 | W1: =IF(表紙!W1="","",表紙!W1) -> 基本設計書 | AP1: 作成者 | AT1: 作成日 | AY1: 更新者 | BC1: 更新日 | BH1: 版数
A2: =IF(表紙!A2="","",表紙!A2) -> POSサーバー | K2: =IF(表紙!K2="","",表紙!K2) -> POSサーバ | AP2: =IF(表紙!AP2="","",表紙!AP2) -> LoiLV | AT2: =IF(表紙!AT2="","",表紙!AT2) -> 45427 | AY2: =IF(表紙!AY2="","",表紙!AY2) -> AnhNM | BC2: =IF(表紙!BC2="","",表紙!BC2) -> 45588 | BH2: =IF(表紙!BH2="","",表紙!BH2) -> 0.4
A4: 機能カテゴリ | H4: =IF(表紙!H4="","",表紙!H4) -> 31_レジ別速報/日報 | U4: 項目 | Z4: =IF(表紙!Z4="","",表紙!Z4) -> 概要設計 | AP4: {=RIGHT(CELL("filename",$A$1),LEN(CELL("filename",$A$1))-FIND("]",CELL("filename",$A$1)))} -> 機能概要
B7: 25_取扱設定マスタ設定(KSM)
BM8: =IF(BM7=50,1,BM7+1) -> 1
BM9: =IF(BM8=50,1,BM8+1) -> 2
BM10: =IF(BM9=50,1,BM9+1) -> 3
BM11: =IF(BM10=50,1,BM10+1) -> 4
BM12: =IF(BM11=50,1,BM11+1) -> 5
BM13: =IF(BM12=50,1,BM12+1) -> 6
BM14: =IF(BM13=50,1,BM13+1) -> 7
BM15: =IF(BM14=50,1,BM14+1) -> 8
BM16: =IF(BM15=50,1,BM15+1) -> 9
BM17: =IF(BM16=50,1,BM16+1) -> 10
BM18: =IF(BM17=50,1,BM17+1) -> 11
BM19: =IF(BM18=50,1,BM18+1) -> 12
... BM44: =IF(BM43=50,1,BM43+1) -> 37
BM45: =IF(BM44=50,1,BM44+1) -> 38 | BO45: SC3101_レジ別速報/日報画面
BM46: =IF(BM45=50,1,BM45+1) -> 39
BM47: =IF(BM46=50,1,BM46+1) -> 40
BM48: =IF(BM47=50,1,BM47+1) -> 41
BM49: =IF(BM48=50,1,BM48+1) -> 42
BM50: =IF(BM49=50,1,BM49+1) -> 43
BM51: =IF(BM50=50,1,BM50+1) -> 44
BM52: =IF(BM51=50,1,BM51+1) -> 45
BM53: =IF(BM52=50,1,BM52+1) -> 46
BM54: =IF(BM53=50,1,BM53+1) -> 47
BM55: =IF(BM54=50,1,BM54+1) -> 48
BM56: =IF(BM55=50,1,BM55+1) -> 49
BM57: =IF(BM56=50,1,BM56+1) -> 50
... BM118: =IF(BM117=50,1,BM117+1) -> 11
BM119: =IF(BM118=50,1,BM118+1) -> 12 | BO119: SC3102_レジ別速報/日報（詳細）画面
BM120: =IF(BM119=50,1,BM119+1) -> 13
BM121: =IF(BM120=50,1,BM120+1) -> 14
BM122: =IF(BM121=50,1,BM121+1) -> 15
BM123: =IF(BM122=50,1,BM122+1) -> 16
BM124: =IF(BM123=50,1,BM123+1) -> 17
BM125: =IF(BM124=50,1,BM124+1) -> 18
BM126: =IF(BM125=50,1,BM125+1) -> 19
BM127: =IF(BM126=50,1,BM126+1) -> 20
...

Sheet レジ別詳細の印刷データ

Sheet 画面設計書
A1: システム名 | K1: システム種別 | W1: =IF(表紙!W1="","",表紙!W1) -> 基本設計書 | AP1: 作成者 | AT1: 作成日 | AY1: 更新者 | BC1: 更新日 | BH1: 版数
A2: =IF(表紙!A2="","",表紙!A2) -> POSサーバー | K2: =IF(表紙!K2="","",表紙!K2) -> POSサーバ | AP2: =IF(表紙!AP2="","",表紙!AP2) -> LoiLV | AT2: =IF(表紙!AT2="","",表紙!AT2) -> 45427 | AY2: =IF(表紙!AY2="","",表紙!AY2) -> AnhNM | BC2: =IF(表紙!BC2="","",表紙!BC2) -> 45588 | BH2: =IF(表紙!BH2="","",表紙!BH2) -> 0.4
A4: 機能カテゴリ | H4: =IF(表紙!H4="","",表紙!H4) -> 31_レジ別速報/日報 | U4: 項目 | Z4: =IF(表紙!Z4="","",表紙!Z4) -> 概要設計 | AP4: =MID(CELL("filename",A1),FIND("]",CELL("filename",A1))+1,255) -> 画面設計書
B7: ■ログイン画面のイメージ
B35: ■画面項目定義
B37: 画面項目ID | D37: 項目 | K37: タイプ | N37: I/O | O37: 多言語対象 | P37: 出力 | AR37: インプット | BC37: 備考
P38: マッピングデータ | X38: 初期値 | AA38: 表示コントロール | AI38: Control enable | AR38: 必須 | AS38: 数字 | AT38: 桁 | AU38: マッピングデータ
P39: API名 | T39: 項目 | AU39: API名 | AY39: 項目
B40: 1 | K40: テキスト | N40: － | O40: ● | P40: － | T40: － | X40: Android POS Control | AA40: ー | AI40: － | AR40: － | AS40: ー | AT40: ー | AU40: － | AY40: ー
B41: 2 | K41: テキスト | N41: O | O41: ● | P41: － | T41: － | X41: User ID | AA41: ー | AI41: ー | AR41: － | AS41: ー | AT41: ー | AU41: － | AY41: ー
B42: 3 | K42: テキスト | N42: I | O42: － | P42: － | X42: － | AA42: ー | AI42: ー | AR42: － | AS42: ー | AT42: ー | AU42: － | AY42: ー
B43: 4 | K43: テキスト | N43: O | O43: ● | P43: － | T43: － | X43: Password | AA43: ー | AI43: ー | AR43: － | AS43: ー | AT43: ー | AU43: － | AY43: ー
B44: 5 | K44: EditText | N44: I | O44: － | P44: － | T44: － | X44: － | AA44: ー | AI44: ー | AR44: － | AS44: ー | AT44: ー | AU44: － | AY44: ー
B45: 6 | K45: ボタン | N45: I | O45: ● | P45: － | T45: － | X45: Login | AA45: ー | AI45: 有効 | AR45: － | AS45: ー | AT45: ー | AU45: － | AY45: ー | BC45: Login-01/EmployeeMaster

Sheet テンプレート
A1: システム名 | K1: システム種別 | W1: =IF(表紙!W1="","",表紙!W1) -> 基本設計書 | AP1: 作成者 | AT1: 作成日 | AY1: 更新者 | BC1: 更新日 | BH1: 版数
A2: =IF(表紙!A2="","",表紙!A2) -> POSサーバー | K2: =IF(表紙!K2="","",表紙!K2) -> POSサーバ | AP2: =IF(表紙!AP2="","",表紙!AP2) -> LoiLV | AT2: =IF(表紙!AT2="","",表紙!AT2) -> 45427 | AY2: =IF(表紙!AY2="","",表紙!AY2) -> AnhNM | BC2: =IF(表紙!BC2="","",表紙!BC2) -> 45588 | BH2: =IF(表紙!BH2="","",表紙!BH2) -> 0.4
A4: 機能カテゴリ | H4: =IF(表紙!H4="","",表紙!H4) -> 31_レジ別速報/日報 | U4: 項目 | Z4: =IF(表紙!Z4="","",表紙!Z4) -> 概要設計 | AP4: =MID(CELL("filename",A1),FIND("]",CELL("filename",A1))+1,255) -> テンプレート
AX12: `
