Workbook

Sheet 表紙
A1: システム名 | K1: システム種別 | W1: 基本設計書 | AP1: 作成者 | AT1: 作成日 | AY1: 更新者 | BC1: 更新日 | BH1: 版数
A2: POSサーバー | K2: POSサーバー | AP2: =改訂履歴!$H$11 -> TuyenNH | AT2: =改訂履歴!$B$11 -> 45420 | AY2: =LOOKUP(2,1/(改訂履歴!H11:H30000<>""),改訂履歴!H11:H30000) -> AnhDD | BC2: =LOOKUP(2,1/(改訂履歴!B11:B30000<>""),改訂履歴!B11:B30000) -> 45558 | BH2: =LOOKUP(2,1/(改訂履歴!O11:O30000<>""),改訂履歴!O11:O30000) -> 0.14
A4: 機能カテゴリ | H4: 20_レジ精算入力 | U4: 項目 | Z4: 概要設計書 | AP4: {=RIGHT(CELL("filename",$A$1),LEN(CELL("filename",$A$1))-FIND("]",CELL("filename",$A$1)))} -> 表紙
L16: POSサーバーの基本設計書
L24: =K2&"/"&H4&"/"&Z4 -> POSサーバー/20_レジ精算入力/概要設計書
Q44: 承認日 | AA44: 承認者 | AQ44: 版数

Sheet 改訂履歴
A1: システム名 | K1: システム種別 | W1: =IF(表紙!W1="","",表紙!W1) -> 基本設計書 | AP1: 作成者 | AT1: 作成日 | AY1: 更新者 | BC1: 更新日 | BH1: 版数
A2: =IF(表紙!A2="","",表紙!A2) -> POSサーバー | K2: =IF(表紙!K2="","",表紙!K2) -> POSサーバー | AP2: =IF(表紙!AP2="","",表紙!AP2) -> TuyenNH | AT2: =IF(表紙!AT2="","",表紙!AT2) -> 45420 | AY2: =IF(表紙!AY2="","",表紙!AY2) -> AnhDD | BC2: =IF(表紙!BC2="","",表紙!BC2) -> 45558 | BH2: =IF(表紙!BH2="","",表紙!BH2) -> 0.14
A4: 機能カテゴリ | H4: =IF(表紙!H4="","",表紙!H4) -> 20_レジ精算入力 | U4: 項目 | Z4: =IF(表紙!Z4="","",表紙!Z4) -> 概要設計書 | AP4: {=RIGHT(CELL("filename",$A$1),LEN(CELL("filename",$A$1))-FIND("]",CELL("filename",$A$1)))} -> 改訂履歴
B8: ■改訂履歴
B10: 更新日 | H10: 更新者 | O10: 版数 | S10: 更新内容 | AX10: 承認日 | BD10: 承認者
B11: 45420 | H11: TuyenNH | O11: 0.1 | S11: 新規作成
B13: 45432 | H13: TuyenNH | O13: 0.11 | S13: 2024年5月17日のコメントによる更新
B15: 45436 | H15: TuyenNH | O15: 0.12 | S15: 2024年5月23日のコメントによる更新
B17: 45524 | H17: DuNT | O17: 0.13 | S17: 機能概要説明： テナントレジ入力機能を追加で記載する。
S18: 機能概要：店舗選択モーダルを削除する
B19: 45558 | H19: AnhDD | O19: 0.14 | S19: レジ精算実
S20: ・精算テナント情報を追加する 2024年9月12日のコメントによる更新

Sheet 業務フロー凡例
A1: システム名 | K1: システム種別 | W1: =IF(表紙!W1="","",表紙!W1) -> 基本設計書 | AP1: 作成者 | AT1: 作成日 | AY1: 更新者 | BC1: 更新日 | BH1: 版数
A2: =IF(表紙!A2="","",表紙!A2) -> POSサーバー | K2: =IF(表紙!K2="","",表紙!K2) -> POSサーバー | AP2: =IF(表紙!AP2="","",表紙!AP2) -> TuyenNH | AT2: 45084 | AY2: =IF(表紙!AY2="","",表紙!AY2) -> AnhDD | BC2: =IF(表紙!BC2="","",表紙!BC2) -> 45558 | BH2: =IF(表紙!BH2="","",表紙!BH2) -> 0.14
A4: 機能カテゴリ | H4: =IF(表紙!H4="","",表紙!H4) -> 20_レジ精算入力 | U4: 項目 | Z4: =IF(表紙!Z4="","",表紙!Z4) -> 概要設計書 | AP4: {=RIGHT(CELL("filename",$A$1),LEN(CELL("filename",$A$1))-FIND("]",CELL("filename",$A$1)))} -> 業務フロー凡例
B7: ●1_レジ内
B22: ●1_レジ周辺機器
B42: ●外部連携

Sheet 機能概要説明
A1: システム名 | K1: システム種別 | W1: =IF(表紙!W1="","",表紙!W1) -> 基本設計書 | AP1: 作成者 | AT1: 作成日 | AY1: 更新者 | BC1: 更新日 | BH1: 版数
A2: =IF(表紙!A2="","",表紙!A2) -> POSサーバー | K2: =IF(表紙!K2="","",表紙!K2) -> POSサーバー | AP2: =IF(表紙!AP2="","",表紙!AP2) -> TuyenNH | AT2: =IF(表紙!AT2="","",表紙!AT2) -> 45420 | AY2: =IF(表紙!AY2="","",表紙!AY2) -> AnhDD | BC2: =IF(表紙!BC2="","",表紙!BC2) -> 45558 | BH2: =IF(表紙!BH2="","",表紙!BH2) -> 0.14
A4: 機能カテゴリ | H4: =IF(表紙!H4="","",表紙!H4) -> 20_レジ精算入力 | U4: 項目 | Z4: =IF(表紙!Z4="","",表紙!Z4) -> 概要設計書 | AP4: {=RIGHT(CELL("filename",$A$1),LEN(CELL("filename",$A$1))-FIND("]",CELL("filename",$A$1)))} -> 機能概要説明
C7: レジ精算入力機能では次のことが可能になる。 | BM7: =IF(BM6=50,1,BM6+1) -> 1
D8: ・店舗のレジの状態を表示する。 | BM8: =IF(BM7=50,1,BM7+1) -> 2
D9: ・選択した日付ごとにより店舗全体の売上が出力可能 | BM9: =IF(BM8=50,1,BM8+1) -> 3
E10: ‣ログインユーザーが管理者ユーザーの場合、62日以内選択可能 | BM10: =IF(BM9=50,1,BM9+1) -> 4
E11: ‣ログインユーザーが管理者ユーザーではない場合、当日から直近3日選択可能 | BM11: =IF(BM10=50,1,BM10+1) -> 5
D12: ・レジごとの詳細売上を表示して実際で金額が編集可能 | BM12: =IF(BM11=50,1,BM11+1) -> 6
D13: テナントレジの売上があがらないため、この機能はテナント機の売上を手動で入力するために使用される。 | BM13: =IF(BM12=50,1,BM12+1) -> 7
D14: ・レジが精算を忘れた場合、POSサーバーがバッチを使用して自動的に精算する。 | BM14: =IF(BM13=50,1,BM13+1) -> 8
BM15: =IF(BM14=50,1,BM14+1) -> 9
BM16: =IF(BM15=50,1,BM15+1) -> 10
BM17: =IF(BM16=50,1,BM16+1) -> 11
BM18: =IF(BM17=50,1,BM17+1) -> 12
BM19: =IF(BM18=50,1,BM18+1) -> 13
BM20: =IF(BM19=50,1,BM19+1) -> 14
BM21: =IF(BM20=50,1,BM20+1) -> 15
BM22: =IF(BM21=50,1,BM21+1) -> 16
BM23: =IF(BM22=50,1,BM22+1) -> 17
BM24: =IF(BM23=50,1,BM23+1) -> 18
BM25: =IF(BM24=50,1,BM24+1) -> 19
BM26: =IF(BM25=50,1,BM25+1) -> 20
... BM58: =IF(BM57=50,1,BM57+1) -> 2

Sheet 機能概要
A1: システム名 | K1: システム種別 | W1: =IF(表紙!W1="","",表紙!W1) -> 基本設計書 | AP1: 作成者 | AT1: 作成日 | AY1: 更新者 | BC1: 更新日 | BH1: 版数
A2: =IF(表紙!A2="","",表紙!A2) -> POSサーバー | K2: =IF(表紙!K2="","",表紙!K2) -> POSサーバー | AP2: =IF(表紙!AP2="","",表紙!AP2) -> TuyenNH | AT2: =IF(表紙!AT2="","",表紙!AT2) -> 45420 | AY2: =IF(表紙!AY2="","",表紙!AY2) -> AnhDD | BC2: =IF(表紙!BC2="","",表紙!BC2) -> 45558 | BH2: =IF(表紙!BH2="","",表紙!BH2) -> 0.14
A4: 機能カテゴリ | H4: =IF(表紙!H4="","",表紙!H4) -> 20_レジ精算入力 | U4: 項目 | Z4: =IF(表紙!Z4="","",表紙!Z4) -> 概要設計書 | AP4: {=RIGHT(CELL("filename",$A$1),LEN(CELL("filename",$A$1))-FIND("]",CELL("filename",$A$1)))} -> 機能概要
B7: 20_レジ精算入力
BM8: =IF(BM7=50,1,BM7+1) -> 1
BM9: =IF(BM8=50,1,BM8+1) -> 2
BM10: =IF(BM9=50,1,BM9+1) -> 3
BM11: =IF(BM10=50,1,BM10+1) -> 4
BM12: =IF(BM11=50,1,BM11+1) -> 5
BM13: =IF(BM12=50,1,BM12+1) -> 6
BM14: =IF(BM13=50,1,BM13+1) -> 7
BM15: =IF(BM14=50,1,BM14+1) -> 8
BM16: =IF(BM15=50,1,BM15+1) -> 9
B17: FC2001_レジ精算日付検索機能 | BM17: =IF(BM16=50,1,BM16+1) -> 10
BM18: =IF(BM17=50,1,BM17+1) -> 11
BM19: =IF(BM18=50,1,BM18+1) -> 12
BM20: =IF(BM19=50,1,BM19+1) -> 13
BM21: =IF(BM20=50,1,BM20+1) -> 14
BM22: =IF(BM21=50,1,BM21+1) -> 15
BM23: =IF(BM22=50,1,BM22+1) -> 16
BM24: =IF(BM23=50,1,BM23+1) -> 17
BM25: =IF(BM24=50,1,BM24+1) -> 18
BM26: =IF(BM25=50,1,BM25+1) -> 19
BM27: =IF(BM26=50,1,BM26+1) -> 20
BM28: =IF(BM27=50,1,BM27+1) -> 21
BM29: =IF(BM28=50,1,BM28+1) -> 22
... BM112: =IF(BM111=50,1,BM111+1) -> 5
B113: FC2002_レジ精算訂正機能 | BM113: =IF(BM112=50,1,BM112+1) -> 6
BM114: =IF(BM113=50,1,BM113+1) -> 7
BM115: =IF(BM114=50,1,BM114+1) -> 8
BM116: =IF(BM115=50,1,BM115+1) -> 9
BM117: =IF(BM116=50,1,BM116+1) -> 10
BM118: =IF(BM117=50,1,BM117+1) -> 11
BM119: =IF(BM118=50,1,BM118+1) -> 12
BM120: =IF(BM119=50,1,BM119+1) -> 13
BM121: =IF(BM120=50,1,BM120+1) -> 14
BM122: =IF(BM121=50,1,BM121+1) -> 15
BM123: =IF(BM122=50,1,BM122+1) -> 16
BM124: =IF(BM123=50,1,BM123+1) -> 17
BM125: =IF(BM124=50,1,BM124+1) -> 18
...

Sheet 自動精算バッチ
A1: システム名 | K1: システム種別 | W1: =IF(表紙!W1="","",表紙!W1) -> 基本設計書 | AP1: 作成者 | AT1: 作成日 | AY1: 更新者 | BC1: 更新日 | BH1: 版数
A2: =IF(表紙!A2="","",表紙!A2) -> POSサーバー | K2: =IF(表紙!K2="","",表紙!K2) -> POSサーバー | AP2: =IF(表紙!AP2="","",表紙!AP2) -> TuyenNH | AT2: =IF(表紙!AT2="","",表紙!AT2) -> 45420 | AY2: =IF(表紙!AY2="","",表紙!AY2) -> AnhDD | BC2: =IF(表紙!BC2="","",表紙!BC2) -> 45558 | BH2: =IF(表紙!BH2="","",表紙!BH2) -> 0.14
A4: 機能カテゴリ | H4: =IF(表紙!H4="","",表紙!H4) -> 20_レジ精算入力 | U4: 項目 | Z4: =IF(表紙!Z4="","",表紙!Z4) -> 概要設計書 | AP4: =MID(CELL("filename",A1),FIND("]",CELL("filename",A1))+1,255) -> 自動精算バッチ
B7: レジの自動精算バッチ
C9: 概要説明
D10: ▪営業日終了時に精算を忘れた場合、レジの自動精算を行う。
E11: (各店舗の営業日は異なるため、各店舗の設定に応じて、バッチを毎日24時に固定で実行するか、営業日終了時に実行する。)
D12: ▪ 関係者に精算を促すメールを送信する。
E13: ・メールを3回送信する。各送信時間は1時間間隔である。 | AX13: `
D14: ▪ レジの自動精算を行う。
E15: ・3回目のメール送信でもレジで精算されていない場合は、自動精算を行う。
E16: ・自動精算完了後：
F17: +「状態」を「自動精算済」に更新する。
F18: +レジの自動精算完了について関係者にメールを送信する。
F19: + レジに自動精算済通知を表示する。自動精算確認を行い、レジがお金を出して請求書や精算レポートなどを印刷する。

Sheet 画面設計書
A1: システム名 | K1: システム種別 | W1: =IF(表紙!W1="","",表紙!W1) -> 基本設計書 | AP1: 作成者 | AT1: 作成日 | AY1: 更新者 | BC1: 更新日 | BH1: 版数
A2: =IF(表紙!A2="","",表紙!A2) -> POSサーバー | K2: =IF(表紙!K2="","",表紙!K2) -> POSサーバー | AP2: =IF(表紙!AP2="","",表紙!AP2) -> TuyenNH | AT2: =IF(表紙!AT2="","",表紙!AT2) -> 45420 | AY2: =IF(表紙!AY2="","",表紙!AY2) -> AnhDD | BC2: =IF(表紙!BC2="","",表紙!BC2) -> 45558 | BH2: =IF(表紙!BH2="","",表紙!BH2) -> 0.14
A4: 機能カテゴリ | H4: =IF(表紙!H4="","",表紙!H4) -> 20_レジ精算入力 | U4: 項目 | Z4: =IF(表紙!Z4="","",表紙!Z4) -> 概要設計書 | AP4: =MID(CELL("filename",A1),FIND("]",CELL("filename",A1))+1,255) -> 画面設計書
B7: ■ログイン画面のイメージ
B35: ■画面項目定義
B37: 画面項目ID | D37: 項目 | K37: タイプ | N37: I/O | O37: 多言語対象 | P37: アウトプット | AR37: インプット | BC37: 備考
P38: マッピングデータ | X38: 初期値 | AA38: 表示コントロール | AI38: Control enable | AR38: 必須 | AS38: 数字 | AT38: 文字 | AU38: マッピングデータ
P39: API名 | T39: 項目 | AU39: API名 | AY39: 項目
B40: 1 | K40: テキスト | N40: － | O40: ● | P40: － | T40: － | X40: Android POS Control | AA40: ー | AI40: － | AR40: － | AS40: ー | AT40: ー | AU40: － | AY40: ー
B41: 2 | K41: テキスト | N41: O | O41: ● | P41: － | T41: － | X41: User ID | AA41: ー | AI41: ー | AR41: － | AS41: ー | AT41: ー | AU41: － | AY41: ー
B42: 3 | K42: テキスト | N42: I | O42: － | P42: － | X42: － | AA42: ー | AI42: ー | AR42: － | AS42: ー | AT42: ー | AU42: － | AY42: ー
B43: 4 | K43: テキスト | N43: O | O43: ● | P43: － | T43: － | X43: Password | AA43: ー | AI43: ー | AR43: － | AS43: ー | AT43: ー | AU43: － | AY43: ー
B44: 5 | K44: EditText | N44: I | O44: － | P44: － | T44: － | X44: － | AA44: ー | AI44: ー | AR44: － | AS44: ー | AT44: ー | AU44: － | AY44: ー
B45: 6 | K45: ボタン | N45: I | O45: ● | P45: － | T45: － | X45: Login | AA45: ー | AI45: Enable | AR45: － | AS45: ー | AT45: ー | AU45: － | AY45: ー | BC45: Login-01/EmployeeMaster

Sheet レジ精算実
A1: システム名 | L1: システム種別 | X1: =IF(表紙!W1="","",表紙!W1) -> 基本設計書 | AP1: 作成者 | AT1: 作成日 | AY1: 更新者 | BC1: 更新日 | BH1: 版数
A2: =IF(表紙!A2="","",表紙!A2) -> POSサーバー | L2: =IF(表紙!K2="","",表紙!K2) -> POSサーバー | AP2: =IF(表紙!AP2="","",表紙!AP2) -> TuyenNH | AT2: =IF(表紙!AT2="","",表紙!AT2) -> 45420 | AY2: =IF(表紙!AY2="","",表紙!AY2) -> AnhDD | BC2: =IF(表紙!BC2="","",表紙!BC2) -> 45558 | BH2: =IF(表紙!BH2="","",表紙!BH2) -> 0.14
A4: 機能カテゴリ | I4: =IF(表紙!H4="","",表紙!H4) -> 20_レジ精算入力 | V4: 項目 | AA4: =IF(表紙!Z4="","",表紙!Z4) -> 概要設計書 | AP4: =MID(CELL("filename",A1),FIND("]",CELL("filename",A1))+1,255) -> レジ精算実
C9: No | E9: 項目名 | S9: 説明
C10: 1 | E10: +売上8% | S10: ・消費税8%対象商品の販売金額 ・消費税8%が含まれていない。 ・非課税商品の金額は含まれていない。
C11: 2 | E11: +消費税8% | S11: ・消費税8%の金額
C12: 3 | E12: +売上10% | S12: ・消費税10%対象商品の販売金額 ・消費税10%が含まれていない。 ・非課税商品の金額は含まれていない。
C13: 4 | E13: +消費税10% | S13: ・消費税10%の金額
C14: 5 | E14: +非課税額 | S14: 消費税が非課税になる販売金額
C15: 6 | E15: +入金合計 | S15: ・No7 ~ No14から金額合計
C16: 7 | E16: 践平備金 | S16: ・つり銭準備金：オープン時に用意しておくつり銭用のお金。
C17: 8 | E17: 商品券1000円 | S17: 商品券1000円の販売額
C18: 9 | E18: 商品券500円 | S18: 商品券500円の販売額
C19: 10 | E19: 配送料(カスミ使) | S19: 配送料（カスミ）：委託料金
C20: 11 | E20: 配送料 | S20: 配送料：ヤマト代行
C21: 12 | E21: WAONカード販売(内税) | S21: WAONカード発行売上（内税）
... C55: 46 | E55: 現金過不足 | S55: = NO45 - NO44 ‣計算した上、正数の場合、レジに投入された最初の金額と比較して、レジには余剰が生じる。 ‣計算した上、負数の場合、レジに投入された最初の金額と比較して、レジが不足している。

Sheet サンプル
A1: システム名 | K1: システム種別 | W1: =IF(表紙!W1="","",表紙!W1) -> 基本設計書 | AP1: 作成者 | AT1: 作成日 | AY1: 更新者 | BC1: 更新日 | BH1: 版数
A2: =IF(表紙!A2="","",表紙!A2) -> POSサーバー | K2: =IF(表紙!K2="","",表紙!K2) -> POSサーバー | AP2: =IF(表紙!AP2="","",表紙!AP2) -> TuyenNH | AT2: =IF(表紙!AT2="","",表紙!AT2) -> 45420 | AY2: =IF(表紙!AY2="","",表紙!AY2) -> AnhDD | BC2: =IF(表紙!BC2="","",表紙!BC2) -> 45558 | BH2: =IF(表紙!BH2="","",表紙!BH2) -> 0.14
A4: 機能カテゴリ | H4: =IF(表紙!H4="","",表紙!H4) -> 20_レジ精算入力 | U4: 項目 | Z4: =IF(表紙!Z4="","",表紙!Z4) -> 概要設計書 | AP4: =MID(CELL("filename",A1),FIND("]",CELL("filename",A1))+1,255) -> サンプル
C9: 日報出力順 | G9: 日報種別 | J9: 日報名称 | U9: 符号 | W9: 金額 | AB9: レジ内金額符号 | AF9: あるべき現金有高 | AK9: 差額 | AP9: 訂正額
C10: 1 | G10: 01 | J10: 売上8％ | U10: + | W10: 5770131 | AB10: + | AF10: 5770131 | AK10: 37213 | AP10: 5807344
C11: 2 | G11: 08 | J11: 売上10％ | U11: + | W11: 549183 | AB11: + | AF11: 549183 | AK11: 467 | AP11: 549650
C12: 3 | G12: 12 | J12: 非課税売上 | AF12: 0 | AP12: 0 | AX12: `
C13: 4 | G13: 03 | J13: WAON現金チャージ | U13: + | W13: 85000 | AB13: + | AF13: 85000 | AP13: 85000
C14: 5 | G14: 44 | J14: ignica moneyチャージ | U14: + | W14: 131000 | AB14: + | AF14: 131000 | AP14: 131000
C15: 6 | G15: 02 | J15: 《レジ》釣銭準備金 | U15: + | W15: 1327359 | AB15: + | AF15: 1327359 | AK15: 122200 | AP15: 1449559
C16: 7 | G16: 04 | J16: 商品券発行千円 | U16: + | W16: 38000 | AB16: + | AF16: 38000 | AP16: 38000
C17: 8 | G17: 10 | J17: 商品券発行五百円 | AF17: 0 | AP17: 0
C18: 9 | G18: 06 | J18: 配送料（カスミ便） | AF18: 0 | AP18: 0
C19: 10 | G19: 05 | J19: 配送料 | U19: + | W19: 330 | AB19: + | AF19: 330 | AP19: 330
C20: 11 | G20: 11 | J20: WAONカード販売（内税） | AF20: 0 | AP20: 0
C21: 13 | G21: 07 | J21: 仮受消費税8％ | U21: + | W21: 460368 | AB21: + | AF21: 460368 | AK21: 2965 | AP21: 463333
C22: 14 | G22: 09 | J22: 仮受消費税10％ | U22: + | W22: 54484 | AB22: + | AF22: 54484 | AK22: 46 | AP22: 54530
C23: 21 | G23: 17 | J23: レジ預金 | AF23: 0 | AP23: 0
C24: 22 | G24: 23 | J24: 配送料支払 | AF24: 0 | AP24: 0
C25: 23 | G25: 24 | J25: カスミ商品券千円回収 | U25: + | W25: 48000 | AB25: - | AF25: -48000 | AP25: 48000
C26: 24 | G26: 18 | J26: カスミ商品券五百円回収 | U26: + | W26: 500 | AB26: - | AF26: -500 | AP26: 500
C27: 25 | G27: 20 | J27: GoToクーポン | AF27: 0 | AP27: 0
C28: 26 | G28: 16 | J28: 古紙ﾘｻｲｸﾙ | U28: + | W28: 100 | AB28: - | AF28: -100 | AP28: 100
C29: 27 | G29: 22 | J29: 株主優待券回収 | U29: + | W29: 4400 | AB29: - | AF29: -4400 | AP29: 4400
C30: 30 | G30: 21 | J30: クーポン券 | AF30: 0 | AP30: 0
C31: 31 | G31: 19 | J31: ギフト券回収 | U31: + | W31: 702 | AB31: - | AF31: -702 | AP31: 702
C32: 32 | G32: 26 | J32: QR決済（アプリ） | U32: + | W32: 99318 | AB32: - | AF32: -99318 | AP32: 99318
C33: 35 | G33: 41 | J33: QR決済（レジ） | U33: + | W33: 449581 | AB33: - | AF33: -449581 | AP33: 449581
C34: 36 | G34: 54 | J34: スマートPOSポイント | U34: + | W34: 111787 | AB34: - | AF34: -111787 | AP34: 111787
C35: 37 | G35: 45 | J35: ignica money 支払 | U35: + | W35: 187595 | AB35: - | AF35: -187595 | AP35: 187595
C36: 38 | G36: 46 | J36: みんなの銀行 | AF36: 0 | AP36: 0
C37: 40 | G37: 55 | J37: メーカークーポン券回収 | AF37: 0 | AP37: 0
J38: カスミ管理外レジ | AF38: 0 | AP38: 0
C39: 41 | G39: 14 | J39: 手書きクレジット（イオン） | U39: + | W39: 529686 | AB39: - | AF39: -529686 | AP39: 529686
C40: 42 | G40: 58 | J40: イオンクレジット | U40: + | W40: 1784090 | AB40: - | AF40: -1784090 | AK40: 216 | AP40: 1784306
C41: 44 | G41: 40 | J41: 常陽クレジット | U41: + | W41: 427366 | AB41: - | AF41: -427366 | AP41: 427366
C42: 46 | G42: 47 | J42: アメックスクレジット | U42: + | W42: 45104 | AB42: - | AF42: -45104 | AP42: 45104
C43: 48 | G43: 15 | J43: ＷＡＯＮ | U43: + | W43: 374562 | AB43: - | AF43: -374562 | AK43: 1909 | AP43: 376471
C44: 49 | G44: 25 | J44: オフＷＡＯＮ | AP44: 0
C45: 50 | G45: 27 | J45: ◆あるべき現金有高◆ | U45: + | W45: 4353064 | AF45: 4353064 | AK45: 160766 | AP45: 4513830
...

Sheet テンプレート
A1: システム名 | K1: システム種別 | W1: =IF(表紙!W1="","",表紙!W1) -> 基本設計書 | AP1: 作成者 | AT1: 作成日 | AY1: 更新者 | BC1: 更新日 | BH1: 版数
A2: =IF(表紙!A2="","",表紙!A2) -> POSサーバー | K2: =IF(表紙!K2="","",表紙!K2) -> POSサーバー | AP2: =IF(表紙!AP2="","",表紙!AP2) -> TuyenNH | AT2: =IF(表紙!AT2="","",表紙!AT2) -> 45420 | AY2: =IF(表紙!AY2="","",表紙!AY2) -> AnhDD | BC2: =IF(表紙!BC2="","",表紙!BC2) -> 45558 | BH2: =IF(表紙!BH2="","",表紙!BH2) -> 0.14
A4: 機能カテゴリ | H4: =IF(表紙!H4="","",表紙!H4) -> 20_レジ精算入力 | U4: 項目 | Z4: =IF(表紙!Z4="","",表紙!Z4) -> 概要設計書 | AP4: =MID(CELL("filename",A1),FIND("]",CELL("filename",A1))+1,255) -> テンプレート
AX12: `
