Workbook

Sheet 表紙
A1: システム名 | K1: システム種別 | W1: 詳細設計書 | AP1: 作成者 | AT1: 作成日 | AY1: 更新者 | BC1: 更新日 | BH1: 版数
A2: POSサーバー | K2: POSサーバ | AP2: =改訂履歴!$H$11 -> DuNT | AT2: =改訂履歴!$B$11 -> 45581 | AY2: =LOOKUP(2,1/(改訂履歴!H11:H30000<>""),改訂履歴!H11:H30000) -> DuNT | BC2: =LOOKUP(2,1/(改訂履歴!B11:B30000<>""),改訂履歴!B11:B30000) -> 45649 | BH2: =LOOKUP(2,1/(改訂履歴!O11:O30000<>""),改訂履歴!O11:O30000) -> 0.13
A4: 機能カテゴリ | H4: 05_ミックスマッチ設定 | U4: 項目 | Z4: 画面設計書 | AP4: {=RIGHT(CELL("filename",$A$1),LEN(CELL("filename",$A$1))-FIND("]",CELL("filename",$A$1)))} -> 表紙
L16: POSサーバーの基本設計書
L24: =K2&"/"&H4&"/"&Z4 -> POSサーバ/05_ミックスマッチ設定/画面設計書
Q44: 承認日 | AA44: 承認者 | AQ44: 版数

Sheet 改訂履歴
A1: システム名 | K1: システム種別 | W1: =IF(表紙!W1="","",表紙!W1) -> 詳細設計書 | AP1: 作成者 | AT1: 作成日 | AY1: 更新者 | BC1: 更新日 | BH1: 版数
A2: =IF(表紙!A2="","",表紙!A2) -> POSサーバー | K2: =IF(表紙!K2="","",表紙!K2) -> POSサーバ | AP2: =IF(表紙!AP2="","",表紙!AP2) -> DuNT | AT2: =IF(表紙!AT2="","",表紙!AT2) -> 45581 | AY2: =IF(表紙!AY2="","",表紙!AY2) -> DuNT | BC2: =IF(表紙!BC2="","",表紙!BC2) -> 45649 | BH2: =IF(表紙!BH2="","",表紙!BH2) -> 0.13
A4: 機能カテゴリ | H4: =IF(表紙!H4="","",表紙!H4) -> 05_ミックスマッチ設定 | U4: 項目 | Z4: =IF(表紙!Z4="","",表紙!Z4) -> 画面設計書 | AP4: {=RIGHT(CELL("filename",$A$1),LEN(CELL("filename",$A$1))-FIND("]",CELL("filename",$A$1)))} -> 改訂履歴
B8: ■改訂履歴
B10: 更新日 | H10: 更新者 | O10: 版数 | S10: 更新内容 | AX10: 承認日 | BD10: 承認者
B11: 45581 | H11: DuNT | O11: 0.1 | S11: 新規
B13: 45601 | H13: DuNT | O13: 0.11 | S13: SC0501 項目29、38を追加で説明
B15: 45608 | H15: DuNT | O15: 0.12 | S15: MD0501：プロモーションコードの必須入力を削除し、category_code を追加
S16: SC0501 イベントID：SC0501-04-1、イベントID：SC0501-04-2
B17: 45649 | H17: DuNT | O17: 0.13 | S17: SC0501：会員売価、マスタ設定ボタンを削除
S18: MD0502を削除

Sheet SC0501
A1: システム名 | K1: システム種別 | W1: =IF(表紙!W1="","",表紙!W1) -> 詳細設計書 | AP1: 作成者 | AT1: 作成日 | AY1: 更新者 | BC1: 更新日 | BH1: 版数
A2: =IF(表紙!A2="","",表紙!A2) -> POSサーバー | K2: =IF(表紙!K2="","",表紙!K2) -> POSサーバ | AP2: =IF(表紙!AP2="","",表紙!AP2) -> DuNT | AT2: =IF(表紙!AT2="","",表紙!AT2) -> 45581 | AY2: =IF(表紙!AY2="","",表紙!AY2) -> DuNT | BC2: =IF(表紙!BC2="","",表紙!BC2) -> 45649 | BH2: =IF(表紙!BH2="","",表紙!BH2) -> 0.13
A4: 機能カテゴリ | H4: =IF(表紙!H4="","",表紙!H4) -> 05_ミックスマッチ設定 | U4: 項目 | Z4: =IF(表紙!Z4="","",表紙!Z4) -> 画面設計書 | AP4: =MID(CELL("filename",A1),FIND("]",CELL("filename",A1))+1,255) -> SC0501
B7: ■SC0501_ミックスマッチ設定画面のイメージ
B46: ■画面項目定義
B48: 画面項目ID | D48: 項目 | K48: タイプ | N48: I/O | O48: 多言語 | P48: 出力 | AR48: インプット | BC48: 備考
P49: マッピングデータ | X49: 初期値 | AA49: 表示コントロール | AI49: Control enable | AR49: 必須 | AS49: 数字 | AT49: 桁 | AU49: マッピングデータ
P50: API名 | T50: 項目 | AU50: API名 | AY50: 項目
B51: 0 | D51: 画面タイトル | K51: テキスト | N51: － | O51: ● | P51: － | T51: － | X51: ミックスマッチ設定 | AA51: ー | AI51: － | AR51: － | AS51: － | AT51: － | AU51: － | AY51: ー | BC51: イベントID：SC0501-01をご参照ください。
B52: =B51+1 -> 1 | D52: プロモーションコード（タイトル） | K52: テキスト | N52: O | O52: ● | P52: － | T52: － | X52: プロモーションコード* | AA52: ー | AI52: ー | AR52: － | AS52: － | AT52: － | AU52: － | AY52: ー
B53: =B52+1 -> 2 | D53: プロモーションコード（値） | K53: EditText | N53: I | O53: － | P53: AP0106 | T53: code | X53: ー | AA53: MD0102で選択されたプロモーションコード、またはAP0106のレスポンスのコードを表示する。 | AI53: 店舗が選択された場合は有効になる。・有効なプロモーションコードがある場合：無効 | AR53: ● | AS53: ● | AT53: － | AU53: AP0106 AP0504 | AY53: promotion_code | BC53: 最大5桁の数字のみ入力可能とする。 イベントID：SC0501-02
B54: =B53+1 -> 3 | D54: プロモーション検索 | K54: ボタン | N54: I | O54: ● | P54: － | T54: － | X54: 検索 | AA54: ー | AI54: 店舗が選択された場合に有効になり、店舗が選択されていない場合または有効なプロモーションが選択された後に無効になる。 | AR54: － | AS54: － | AT54: － | AU54: － | AY54: ー | BC54: イベントID：SC0501-03
B55: =B54+1 -> 4 | D55: プロモーション名 | K55: EditText | N55: O | O55: － | P55: AP0106 | T55: name | X55: プロモーション名 | AA55: プロモーションを提案したが、プロモーションが見つからない場合、AP0106から返されたエラーメッセージを表示する。 プロモーションを提案して有効なプロモーションがある場合、AP0106のレスポンスの名称を表示する。 MD0102でプロモーションが選択された場合、選択されたプロモーション名を表示する。 | AI55: 無効 | AR55: － | AS55: － | AT55: － | AU55: － | AY55: ー
B56: =B55+1 -> 5 | D56: ミックスマッチコード（タイトル） | K56: テキスト | N56: O | O56: － | P56: － | T56: － | X56: － | AA56: ー | AI56: ー | AR56: － | AS56: － | AT56: － | AU56: － | AY56: ー
B57: =B56+1 -> 6 | D57: ミックスマッチコード（値） | K57: EditText | N57: I | O57: － | P57: AP0502 AP0501 | T57: mix_match_code code | X57: － | AA57: 初期化モードの場合、空を表示する。 編集モードの場合、AP0501のレスポンスのコードを表示する。 新規作成モードの場合、AP0502のレスポンスのmix_match_codeを表示する。 | AI57: 有効なミックスマッチコードがない場合：有効 有効なミックスマッチコードがある場合：無効 | AR57: － | AS57: ● | AT57: － | AU57: AP0501 AP0504 | AY57: code | BC57: 最大3桁の数字のみ入力可能とする。 イベントID：SC0501-04-1
B58: =B57+1 -> 7 | D58: ミックスマッチ検索 | K58: ボタン | N58: I | O58: ● | P58: － | T58: － | X58: 検索 | AA58: ー | AI58: デフォルトで有効になり、ミックスマッチ新規作成モード又は編集モードの場合に無効になる。 | AR58: － | AS58: － | AT58: － | AU58: － | AY58: ー | BC58: イベントID：SC0501-04-2
B59: =B58+1 -> 8 | D59: ミックスマッチ新規 | K59: ボタン | N59: I | O59: ● | P59: － | T59: － | X59: 新規 | AA59: ー | AI59: デフォルト：無効 有効なプロモーションが選択された場合は有効になる。新規モード又は編集モードの場合、無効になる。 | AR59: － | AS59: － | AT59: － | AU59: － | AY59: ー | BC59: イベントID：SC0501-05
B60: =B59+1 -> 9 | D60: ミックスマッチ期間（タイトル） | K60: テキスト | N60: O | O60: ● | P60: － | T60: － | X60: ミックスマッチ期間 | AA60: ー | AI60: ー | AR60: － | AS60: － | AT60: － | AU60: － | AY60: ー
B61: =B60+1 -> 10 | D61: 開始年月日 | K61: DatePicker | N61: I | O61: － | P61: AP0501 | T61: start_date | X61: 現在日 | AA61: 開始年月日の初期値： ・新規作成モードの場合、選択されているプロモーションの開始年月日 ・編集モードの場合：AP0501のレスポンスのstart_date 。 | AI61: デフォルト：無効 新規作成モードまたは編集モードの場合は有効になる。 | AR61: － | AS61: － | AT61: － | AU61: AP0504 | AY61: start_date | BC61: フォーマット: yyyy/mm/dd
B62: =B61+1 -> 11 | D62: 開始時間 | K62: TimePicker | N62: I | O62: － | P62: AP0501 | T62: start_time | X62: 00:00 | AA62: 開始時間の初期値 ・新規作成モードの場合、選択されているプロモーションの開始時間 ・編集モードの場合：AP0501のレスポンスのstart_time 。 | AI62: デフォルト：無効 新規作成モードまたは編集モードの場合は有効になる。 | AR62: － | AS62: － | AT62: － | AU62: AP0504 | AY62: start_time | BC62: 形式: hh:mm
B63: =B62+1 -> 12 | D63: 終了年月日 | K63: DatePicker | N63: I | O63: － | P63: AP0501 | T63: end_date | X63: 現在日 | AA63: 終了年月日の初期値： ・新規作成モードの場合、選択されているプロモーションの終了年月日 ・編集モードの場合：AP0501のレスポンスのend_date 。 | AI63: デフォルト：無効 新規作成モードまたは編集モードの場合は有効になる。 | AR63: － | AS63: － | AT63: － | AU63: AP0504 | AY63: end_date | BC63: フォーマット: yyyy/mm/dd
B64: =B63+1 -> 13 | D64: 終了時間 | K64: TimePicker | N64: I | O64: － | P64: AP0501 | T64: end_time | X64: 00:00 | AA64: 終了時間の初期値： ・新規作成モードの場合、選択されているプロモーションの終了時間 ・編集モードの場合：AP0501のレスポンスのend_time 。 | AI64: デフォルト：無効 新規作成モードまたは編集モードの場合は有効になる。 | AR64: － | AS64: － | AT64: － | AU64: AP0504 | AY64: end_time | BC64: 形式: hh:mm
B65: =B64+1 -> 14 | D65: 会員価格（S&G）（タイトル） | K65: テキスト | N65: O | O65: ● | P65: － | T65: － | X65: 会員価格（Ｓ＆G） | AA65: ー | AI65: ー | AR65: － | AS65: － | AT65: － | AU65: － | AY65: ー
B66: =B65+1 -> 15 | D66: 会員価格（S&G）（値） | K66: ドロップダウン | N66: I | O66: － | P66: AP0501 | T66: sg_member_included | X66: 0 | AA66: 0:扱いなし 1:扱い | AI66: デフォルト：無効 新規作成モードまたは編集モードの場合に有効になる。 | AR66: － | AS66: ● | AT66: － | AU66: AP0504 | AY66: sg_member_included | BC66: 「0」、「1」の値のみ入力可能。
B67: =B66+1 -> 16 | D67: タイムサービス（タイトル） | K67: テキスト | N67: O | O67: ● | P67: － | T67: － | X67: タイムサービス | AA67: ー | AI67: ー | AR67: － | AS67: － | AT67: － | AU67: － | AY67: ー
B68: =B67+1 -> 17 | D68: タイムサービス（値） | K68: ドロップダウン | N68: I | O68: － | P68: AP0501 | T68: time_service | X68: 0 | AA68: 0:通常 1:タイムサービ | AI68: デフォルト：無効 新規作成モードまたは編集モードの場合に有効になる。 | AR68: － | AS68: ● | AT68: － | AU68: AP0504 | AY68: time_service | BC68: 「0」、「1」の値のみ入力可能。
B69: =B68+1 -> 18 | D69: 会員価格（カスミカード）（タイトル） | K69: テキスト | N69: O | O69: ● | P69: － | T69: － | X69: 会員価格（カスミカード） | AA69: ー | AI69: ー | AR69: － | AS69: － | AT69: － | AU69: － | AY69: ー
B70: =B69+1 -> 19 | D70: 会員価格（カスミカード）（値） | K70: ドロップダウン | N70: I | O70: － | P70: AP0501 | T70: kasumi_card_member_included | X70: 0 | AA70: 0:扱いなし 1:扱い | AI70: デフォルト：無効 新規作成モードまたは編集モードの場合に有効になる。 | AR70: － | AS70: ● | AT70: － | AU70: AP0504 | AY70: kasumi_card_member_included | BC70: 「0」、「1」の値のみ入力可能。
B71: =B70+1 -> 20 | D71: ミックスマッチ区分（タイトル） | K71: テキスト | N71: O | O71: ● | P71: － | T71: － | X71: ミックスマッチ区分 | AA71: ー | AI71: ー | AR71: － | AS71: － | AT71: － | AU71: － | AY71: ー
B72: =B71+1 -> 21 | D72: ミックスマッチ区分（値） | K72: ドロップダウン | N72: I | O72: － | P72: AP0501 | T72: type | X72: 1 | AA72: 1:売価 2:割引 3:値引 | AI72: デフォルト：無効 新規作成モードまたは編集モードの場合に有効になる。 | AR72: － | AS72: ● | AT72: － | AU72: AP0504 | AY72: type | BC72: 「1」、「2」、「3」の値のみ入力可能。 イベントID：SC0501-12
B73: =B72+1 -> 22 | D73: 状態（タイトル） | K73: テキスト | N73: O | O73: ● | P73: － | T73: － | X73: 状態 | AA73: ー | AI73: ー | AR73: － | AS73: － | AT73: － | AU73: － | AY73: ー
B74: =B73+1 -> 23 | D74: 状態（値） | K74: EditText | N74: I | O74: － | P74: AP0501 | T74: status | X74: 0 | AA74: ー | AI74: 編集モードまたは新規作成モードの場合に有効になる。 | AR74: － | AS74: ● | AT74: － | AU74: AP0504 | AY74: status | BC74: 以下の値入力可能。「0:実施」 「1: 中止」
B75: =B74+1 -> 24 | D75: ミックスマッチオプション | K75: テキスト | N75: O | O75: － | P75: AP0501 | T75: settings | X75: － | AA75: ー | AI75: ー | AR75: － | AS75: － | AT75: － | AU75: － | AY75: ー | BC75: 各ミックスマッチ区分のミックスマッチオプション列数は type_one、 type_two、type_threeの値に依存する。
B76: =B75+1 -> 25 | D76: 成立個数（タイトル） | K76: テキスト | N76: O | O76: ● | P76: － | T76: － | X76: 成立個数 | AA76: ー | AI76: ー | AR76: － | AS76: － | AT76: － | AU76: － | AY76: ー
B77: =B76+1 -> 26 | D77: 成立個数（値） | K77: EditText | N77: I | O77: － | P77: AP0501 | T77: options[i].quantity | X77: － | AA77: ー | AI77: デフォルト：無効 新規作成モードまたは編集モードの場合に有効になる。 | AR77: － | AS77: ● | AT77: － | AU77: AP0504 | AY77: quantity | BC77: 最大2桁の数字のみ入力可能とする。
B78: =B77+1 -> 27 | D78: 成立（タイトル） | K78: テキスト | N78: O | O78: ● | P78: － | T78: － | X78: 成立 | AA78: ー | AI78: ー | AR78: － | AS78: － | AT78: － | AU78: － | AY78: ー
B79: =B78+1 -> 28 | D79: 成立（値） | K79: EditText | N79: I/O | O79: － | P79: AP0501 | T79: options[i].m_value | X79: 0 | AA79: ー | AI79: ー | AR79: － | AS79: ● | AT79: － | AU79: AP0504 | AY79: m_value | BC79: 「1:売価」又は「3:値引」：最大6桁の数字のみ入力可能とする。 「2:割引」：最大2桁の数字のみ入力可能とする。
B80: =B79+1 -> 29 | D80: 会員価格（S&G） (タイトル) | K80: テキスト | N80: O | O80: ● | P80: － | T80: － | X80: 会員価格（Ｓ＆G） | AA80: ー | AI80: ー | AR80: － | AS80: － | AT80: － | AU80: － | AY80: ー
B81: =B80+1 -> 30 | D81: 会員価格（S&G）(値) | K81: EditText | N81: I/O | O81: － | P81: AP0501 | T81: options[i].m_value_sg_member | X81: 0 | AA81: ー | AI81: 項目ID15の値 (会員価格（S&G）） = 1の場合に有効になる。 | AR81: － | AS81: ● | AT81: － | AU81: AP0504 | AY81: m_value_sg_member | BC81: 「1:売価」又は「3:値引」：最大6桁の数字のみ入力可能とする。 「2:割引」：最大2桁の数字のみ入力可能とする。
B82: =B81+1 -> 31 | D82: 会員価格（カスミカード）（タイトル） | K82: テキスト | N82: O | O82: ● | P82: － | T82: － | X82: 会員価格（カスミカード） | AA82: ー | AI82: ー | AR82: － | AS82: － | AT82: － | AU82: － | AY82: ー
...

Sheet MD0501
A1: システム名 | K1: システム種別 | W1: =IF(表紙!W1="","",表紙!W1) -> 詳細設計書 | AP1: 作成者 | AT1: 作成日 | AY1: 更新者 | BC1: 更新日 | BH1: 版数
A2: =IF(表紙!A2="","",表紙!A2) -> POSサーバー | K2: =IF(表紙!K2="","",表紙!K2) -> POSサーバ | AP2: =IF(表紙!AP2="","",表紙!AP2) -> DuNT | AT2: =IF(表紙!AT2="","",表紙!AT2) -> 45581 | AY2: =IF(表紙!AY2="","",表紙!AY2) -> DuNT | BC2: =IF(表紙!BC2="","",表紙!BC2) -> 45649 | BH2: =IF(表紙!BH2="","",表紙!BH2) -> 0.13
A4: 機能カテゴリ | H4: =IF(表紙!H4="","",表紙!H4) -> 05_ミックスマッチ設定 | U4: 項目 | Z4: =IF(表紙!Z4="","",表紙!Z4) -> 画面設計書 | AP4: =MID(CELL("filename",A1),FIND("]",CELL("filename",A1))+1,255) -> MD0501
B7: ■MD0501_ミックスマッチ検索モーダル（初期化）のイメージ
B37: ■画面項目定義 | AW37: p
B39: 画面項目ID | D39: 項目 | K39: タイプ | N39: I/O | O39: 多言語 | P39: 出力 | AR39: インプット | BC39: 備考
P40: マッピングデータ | X40: 初期値 | AA40: 表示コントロール | AI40: Control enable | AR40: 必須 | AS40: 数字 | AT40: 桁 | AU40: マッピングデータ
P41: API名 | T41: 項目 | AU41: API名 | AY41: 項目
B42: 0 | D42: 画面タイトル | K42: テキスト | N42: － | O42: ● | P42: － | T42: － | X42: ミックスマッチ検索 | AA42: － | AI42: － | AR42: － | AS42: － | AT42: － | AU42: － | AY42: － | BC42: イベントID：MD0501-01
B43: =B42+1 -> 1 | D43: プロモーション（タイトル） | K43: テキスト | N43: － | O43: ● | P43: － | T43: － | X43: プロモーション | AA43: － | AI43: － | AR43: － | AS43: － | AT43: － | AU43: － | AY43: －
B44: =B43+1 -> 2 | D44: プロモーション(値） | K44: EditText | N44: I | O44: － | P44: － | T44: － | X44: SC0501画面から渡される値 | AA44: － | AI44: － | AR44: － | AS44: ● | AT44: － | AU44: AP0505 | AY44: promotion_code | BC44: 最大5桁の数字のみ入力可能とする。
B45: =B44+1 -> 3 | D45: ミックスマッチ（タイトル） | K45: テキスト | N45: － | O45: ● | P45: － | T45: － | X45: ミックスマッチ | AA45: － | AI45: － | AR45: － | AS45: － | AT45: － | AU45: － | AY45: －
B46: =B45+1 -> 4 | D46: ミックスマッチ（値） | K46: EditText | N46: I | O46: － | P46: － | T46: － | X46: － | AA46: － | AI46: － | AR46: － | AS46: － | AT46: － | AU46: AP0505 | AY46: mix_match_code | BC46: 最大3桁の数字のみ入力可能とする。
B47: =B46+1 -> 5 | D47: 部門コード（タイトル） | K47: テキスト | N47: － | O47: ● | P47: － | T47: － | X47: 部門 | AA47: － | AI47: － | AR47: － | AS47: － | AT47: － | AU47: － | AY47: －
B48: =B47+1 -> 6 | D48: 部門コード（値） | K48: EditText | N48: I | O48: － | P48: － | T48: － | X48: － | AA48: － | AI48: － | AR48: － | AS48: － | AT48: － | AU48: AP0505 | AY48: code_level_one | BC48: 最大2桁の数字のみ入力可能とする。
B49: =B48+1 -> 7 | D49: 期間（タイトル） | K49: テキスト | N49: － | O49: ● | P49: － | T49: － | X49: 期間 | AA49: － | AI49: － | AR49: － | AS49: － | AT49: － | AU49: － | AY49: －
B50: =B49+1 -> 8 | D50: 期間（値） | K50: ドロップダウン | N50: I | O50: － | P50: － | T50: － | X50: リストの3番目の値（指定なし）：期間中、 開始日、 指定なし | AA50: － | AI50: － | AR50: － | AS50: － | AT50: － | AU50: AP0505 | AY50: duration
B51: =B50+1 -> 9 | D51: 日付（タイトル） | K51: テキスト | N51: － | O51: ● | P51: － | T51: － | X51: 日付 | AA51: － | AI51: － | AR51: － | AS51: － | AT51: － | AU51: － | AY51: －
B52: =B51+1 -> 10 | D52: 日付（値） | K52: DatePicker | N52: I | O52: － | P52: － | T52: － | X52: 現在日 | AA52: － | AI52: 無効：期限の値 (項目ID8) = 0または2の場合 有効：期限の値 (項目ID8) = 1の場合 | AR52: － | AS52: － | AT52: － | AU52: AP0505 | AY52: date | BC52: フォーマット: yyyy/mm/dd
B53: =B52+1 -> 11 | D53: 検索 | K53: ボタン | N53: I | O53: ● | P53: － | T53: － | X53: 検索 | AA53: － | AR53: － | AS53: － | AT53: － | AU53: － | AY53: － | BC53: イベントID：MD0501-02
B54: =B53+1 -> 12 | D54: 閉じる | K54: ボタン | N54: I | O54: ● | P54: － | T54: － | X54: ESC: 前画面 | AA54: － | AI54: － | AR54: － | AS54: － | AT54: － | AU54: － | AY54: － | BC54: イベントID：MD0501-03
B57: ■MD0501_ミックスマッチ検索モーダル (検索結果あり)のイメージ
B88: ■画面項目定義
B90: 画面項目ID | D90: 項目 | K90: タイプ | N90: I/O | O90: 多言語 | P90: 出力 | AR90: インプット | BC90: 備考
P91: マッピングデータ | X91: 初期値 | AA91: 表示コントロール | AI91: Control enable | AR91: 必須 | AS91: 数字 | AT91: 桁 | AU91: マッピングデータ
P92: API名 | T92: 項目 | AU92: API名 | AY92: 項目
B93: 13 | D93: 選択（タイトル） | K93: テキスト | N93: － | O93: ● | P93: － | T93: － | X93: 選択 | AA93: － | AI93: － | AR93: － | AS93: － | AT93: － | AU93: － | AY93: －
B94: =B93+1 -> 14 | D94: 選択 | K94: ボタン | N94: I | O94: － | P94: － | T94: － | X94: － | AA94: － | AI94: － | AR94: － | AS94: － | AT94: － | AU94: － | AY94: － | BC94: イベントID：MD0501-04
B95: =B94+1 -> 15 | D95: プロモーションコード（タイトル） | K95: テキスト | N95: － | O95: ● | P95: － | T95: － | X95: ミックスマッチ | AA95: － | AI95: － | AR95: － | AS95: － | AT95: － | AU95: － | AY95: －
B96: =B95+1 -> 16 | D96: プロモーションコード（値） | K96: テキスト | N96: O | O96: － | P96: AP0505 | T96: promotion_code | X96: － | AA96: － | AI96: － | AR96: － | AS96: － | AT96: － | AU96: － | AY96: －
B97: =B96+1 -> 17 | D97: ミックスマッチコード（タイトル） | K97: テキスト | N97: － | O97: ● | P97: － | T97: － | X97: ミックスマッチ | AA97: － | AI97: － | AR97: － | AS97: － | AT97: － | AU97: － | AY97: －
B98: =B97+1 -> 18 | D98: ミックスマッチコード（値） | K98: テキスト | N98: O | O98: － | P98: AP0505 | T98: code | X98: － | AA98: － | AI98: － | AR98: － | AS98: － | AT98: － | AU98: － | AY98: －
B99: =B98+1 -> 19 | D99: 代表商品（タイトル） | K99: テキスト | N99: － | O99: ● | P99: － | T99: － | X99: 代表商品 | AA99: － | AI99: － | AR99: － | AS99: － | AT99: － | AU99: － | AY99: －
B100: =B99+1 -> 20 | D100: 代表商品（値） | K100: テキスト | N100: O | O100: － | P100: AP0505 | T100: category_code product_name | AA100: － | AI100: － | AR100: － | AS100: － | AT100: － | AU100: － | AY100: －
B101: =B100+1 -> 21 | D101: 開始日時（タイトル） | K101: テキスト | N101: － | O101: ● | P101: － | T101: － | X101: 開始日時 | AA101: － | AI101: － | AR101: － | AS101: － | AT101: － | AU101: － | AY101: －
B102: =B101+1 -> 22 | D102: 開始日時（値） | K102: テキスト | N102: O | O102: － | P102: AP0505 | T102: start_date_time | AA102: － | AI102: － | AR102: － | AS102: － | AT102: － | AU102: － | AY102: － | BC102: 形式：yyyy/MM/dd hh:mm
B103: =B102+1 -> 23 | D103: 終了日時（タイトル） | K103: テキスト | N103: － | O103: ● | P103: － | T103: － | X103: 終了日時 | AA103: － | AI103: － | AR103: － | AS103: － | AT103: － | AU103: － | AY103: －
B104: =B103+1 -> 24 | D104: 終了日時（値） | K104: テキスト | N104: O | O104: － | P104: AP0505 | T104: end_date_time | AA104: － | AI104: － | AR104: － | AS104: － | AT104: － | AU104: － | AY104: － | BC104: 形式：yyyy/MM/dd hh:mm
B105: =B104+1 -> 25 | D105: 成立個数・金額（タイトル） | K105: テキスト | N105: － | O105: ● | P105: － | T105: － | X105: 成立個数・金額 | AA105: － | AI105: － | AR105: － | AS105: － | AT105: － | AU105: － | AY105: －
B106: =B105+1 -> 26 | D106: 成立個数・金額（値） | K106: テキスト | N106: O | O106: － | P106: AP0505 | T106: options | AA106: － | AI106: － | AR106: － | AS106: － | AT106: － | AU106: － | AY106: － | BC106: 形式： {option[i].quantity}個{option[i].discount_value}円/% AP0505のレスポンスのタイプ = 2の場合=> 単位： % AP0505のレスポンスのタイプ = 1又は3 =>単位：円 複数のオプションがある場合は、オプション間を「,」で区切る 多言語表示がある。

Sheet SCxxxx
A1: システム名 | K1: システム種別 | W1: =IF(表紙!W1="","",表紙!W1) -> 詳細設計書 | AP1: 作成者 | AT1: 作成日 | AY1: 更新者 | BC1: 更新日 | BH1: 版数
A2: =IF(表紙!A2="","",表紙!A2) -> POSサーバー | K2: =IF(表紙!K2="","",表紙!K2) -> POSサーバ | AP2: =IF(表紙!AP2="","",表紙!AP2) -> DuNT | AT2: =IF(表紙!AT2="","",表紙!AT2) -> 45581 | AY2: =IF(表紙!AY2="","",表紙!AY2) -> DuNT | BC2: =IF(表紙!BC2="","",表紙!BC2) -> 45649 | BH2: =IF(表紙!BH2="","",表紙!BH2) -> 0.13
A4: 機能カテゴリ | H4: =IF(表紙!H4="","",表紙!H4) -> 05_ミックスマッチ設定 | U4: 項目 | Z4: =IF(表紙!Z4="","",表紙!Z4) -> 画面設計書 | AP4: =MID(CELL("filename",A1),FIND("]",CELL("filename",A1))+1,255) -> SCxxxx
B7: ■イメージ
B35: ■画面項目定義
B37: 画面項目ID | D37: 項目 | K37: タイプ | N37: I/O | O37: 多言語 | P37: 出力 | AR37: インプット | BC37: 備考
P38: マッピングデータ | X38: 初期値 | AA38: 表示コントロール | AI38: Control enable | AR38: 必須 | AS38: 数字 | AT38: 桁 | AU38: マッピングデータ
P39: API名 | T39: 項目 | AU39: API名 | AY39: 項目
B40: 1 | K40: テキスト | N40: － | O40: ● | P40: － | T40: － | X40: Android POS Control | AA40: ー | AI40: － | AR40: － | AS40: ー | AT40: ー | AU40: － | AY40: ー
B41: 2 | K41: テキスト | N41: O | O41: ● | P41: － | T41: － | X41: ユーザーID | AA41: ー | AI41: ー | AR41: － | AS41: ー | AT41: ー | AU41: － | AY41: ー
B42: 3 | K42: テキスト | N42: I | O42: － | P42: － | X42: － | AA42: ー | AI42: ー | AR42: － | AS42: ー | AT42: ー | AU42: － | AY42: ー
B43: 4 | K43: テキスト | N43: O | O43: ● | P43: － | T43: － | X43: Password | AA43: ー | AI43: ー | AR43: － | AS43: ー | AT43: ー | AU43: － | AY43: ー
B44: 5 | K44: EditText | N44: I | O44: － | P44: － | T44: － | X44: － | AA44: ー | AI44: ー | AR44: － | AS44: ー | AT44: ー | AU44: － | AY44: ー
B45: 6 | K45: ボタン | N45: I | O45: ● | P45: － | T45: － | X45: ログイン | AA45: ー | AI45: 有効 | AR45: － | AS45: ー | AT45: ー | AU45: － | AY45: ー | BC45: Login-01/EmployeeMaster
