Workbook

Sheet 表紙
A1: システム名 | K1: システム種別 | W1: 詳細設計書 | AP1: 作成者 | AT1: 作成日 | AY1: 更新者 | BC1: 更新日 | BH1: 版数
A2: POSサーバー | K2: POSサーバ | AP2: =改訂履歴!$H$11 -> DuNT | AT2: =改訂履歴!$B$11 -> 45635 | AY2: =LOOKUP(2,1/(改訂履歴!H11:H30000<>""),改訂履歴!H11:H30000) -> DuNT | BC2: =LOOKUP(2,1/(改訂履歴!B11:B30000<>""),改訂履歴!B11:B30000) -> 45635 | BH2: =LOOKUP(2,1/(改訂履歴!O11:O30000<>""),改訂履歴!O11:O30000) -> 0.1
A4: 機能カテゴリ | H4: 32_レジ別単品別売上点検 | U4: 項目 | Z4: 画面設計書 | AP4: {=RIGHT(CELL("filename",$A$1),LEN(CELL("filename",$A$1))-FIND("]",CELL("filename",$A$1)))} -> 表紙
L16: POSサーバーの詳細設計書
L24: =K2&"/"&H4&"/"&Z4 -> POSサーバ/32_レジ別単品別売上点検/画面設計書
Q44: 承認日 | AA44: 承認者 | AQ44: 版数

Sheet 改訂履歴
A1: システム名 | K1: システム種別 | W1: =IF(表紙!W1="","",表紙!W1) -> 詳細設計書 | AP1: 作成者 | AT1: 作成日 | AY1: 更新者 | BC1: 更新日 | BH1: 版数
A2: =IF(表紙!A2="","",表紙!A2) -> POSサーバー | K2: =IF(表紙!K2="","",表紙!K2) -> POSサーバ | AP2: =IF(表紙!AP2="","",表紙!AP2) -> DuNT | AT2: =IF(表紙!AT2="","",表紙!AT2) -> 45635 | AY2: =IF(表紙!AY2="","",表紙!AY2) -> DuNT | BC2: =IF(表紙!BC2="","",表紙!BC2) -> 45635 | BH2: =IF(表紙!BH2="","",表紙!BH2) -> 0.1
A4: 機能カテゴリ | H4: =IF(表紙!H4="","",表紙!H4) -> 32_レジ別単品別売上点検 | U4: 項目 | Z4: =IF(表紙!Z4="","",表紙!Z4) -> 画面設計書 | AP4: {=RIGHT(CELL("filename",$A$1),LEN(CELL("filename",$A$1))-FIND("]",CELL("filename",$A$1)))} -> 改訂履歴
B8: ■改訂履歴
B10: 更新日 | H10: 更新者 | O10: 版数 | S10: 更新内容 | AX10: 承認日 | BD10: 承認者
B11: 45635 | H11: DuNT | O11: 0.1 | S11: 新規

Sheet SC3201
A1: システム名 | K1: システム種別 | W1: =IF(表紙!W1="","",表紙!W1) -> 詳細設計書 | AP1: 作成者 | AT1: 作成日 | AY1: 更新者 | BC1: 更新日 | BH1: 版数
A2: =IF(表紙!A2="","",表紙!A2) -> POSサーバー | K2: =IF(表紙!K2="","",表紙!K2) -> POSサーバ | AP2: =IF(表紙!AP2="","",表紙!AP2) -> DuNT | AT2: =IF(表紙!AT2="","",表紙!AT2) -> 45635 | AY2: =IF(表紙!AY2="","",表紙!AY2) -> DuNT | BC2: =IF(表紙!BC2="","",表紙!BC2) -> 45635 | BH2: =IF(表紙!BH2="","",表紙!BH2) -> 0.1
A4: 機能カテゴリ | H4: =IF(表紙!H4="","",表紙!H4) -> 32_レジ別単品別売上点検 | U4: 項目 | Z4: =IF(表紙!Z4="","",表紙!Z4) -> 画面設計書 | AP4: =MID(CELL("filename",A1),FIND("]",CELL("filename",A1))+1,255) -> SC3201
B7: ■初期画面のイメージ
B45: ■画面項目定義
B47: 画面項目ID | D47: 項目 | K47: タイプ | N47: I/O | O47: 多言語 | P47: 出力 | AR47: インプット | BC47: 備考
P48: マッピングデータ | X48: 初期値 | AA48: 表示コントロール | AI48: Control enable | AR48: 必須 | AS48: 数字 | AT48: 桁 | AU48: マッピングデータ
P49: API名 | T49: 項目 | AU49: API名 | AY49: 項目
B50: 0 | D50: 画面タイトル | K50: テキスト | N50: － | O50: ● | P50: － | T50: － | X50: レジ別単品別売上点検 | AA50: ー | AI50: － | AR50: － | AS50: ー | AT50: ー | AU50: － | AY50: ー | BC50: イベントID：SC3201-01
B51: =B50+1 -> 1 | D51: 営業種別（タイトル） | K51: テキスト | N51: － | O51: ● | P51: － | T51: － | X51: 営業種別* | AA51: ー | AI51: ー | AR51: － | AS51: ー | AT51: ー | AU51: － | AY51: ー
B52: =B51+1 -> 2 | D52: 営業種別（値） | K52: ラジオボタン | N52: I | O52: ● | P52: － | T52: － | X52: 速報 | AA52: 以下の2つオプションがある。 ・速報 ・日報 | AI52: 対象店舗が選択された場合は有効になる。 | AR52: ● | AS52: ー | AT52: ー | AU52: － | AY52: ー
B53: =B52+1 -> 3 | D53: 営業日（タイトル） | K53: テキスト | N53: － | O53: ● | P53: － | T53: － | X53: 営業日 | AA53: ー | AI53: ー | AR53: － | AS53: ー | AT53: ー | AU53: － | AY53: ー
B54: =B53+1 -> 4 | D54: 営業日（値） | K54: Date picker | N54: I | O54: － | P54: － | T54: － | X54: 当日 | AA54: ー | AI54: 対象店舗が選択され、営業種別 = 日報の場合に有効になる。 | AR54: ● | AS54: － | AT54: ー | AU54: － | AY54: ー
B55: =B54+1 -> 5 | D55: 表示件数（タイトル） | K55: テキスト | N55: ー | O55: ● | X55: 表示件数* | AI55: ` | AR55: － | AS55: － | AT55: ー | AU55: － | AY55: ー
B56: =B55+1 -> 6 | D56: 表示件数（値） | K56: EditText | N56: I | O56: － | P56: － | T56: － | X56: － | AA56: ー | AI56: 対象店舗が選択された場合は有効になる。 | AR56: ● | AS56: ● | AT56: ー | AU56: － | AY56: ー | BC56: > 0、最大1000
B57: =B56+1 -> 7 | D57: 出力単位（タイトル） | K57: テキスト | N57: － | O57: ● | P57: － | T57: － | X57: 出力単位* | AA57: ー | AI57: ー | AR57: － | AS57: － | AT57: ー | AU57: － | AY57: ー
B58: =B57+1 -> 8 | D58: 出力単位（値） | K58: ドロップダウン | N58: I | O58: － | P58: － | T58: － | X58: 0. 全部で | AA58: 以下のオプションが含まれている。 0. 全部で 1. 部門 2. 品群 3. 品種 4. 分類 5. 商品 | AI58: 対象店舗が選択された場合は有効になる。 | AR58: － | AS58: － | AT58: ー | AU58: － | AY58: ー | BC58: イベントID：SC3201-02 階層を選択すると、その階層一覧をロードして項目9に表示する。
B59: 9.1 | D59: 階層一覧（値） | K59: ドロップダウン | N59: I/O | O59: － | P59: － | T59: － | X59: 最初のアイテム | AA59: 項目8で選択されているアイテムが以下の値の場合に表示する。 0. 全部で 1. 部門 2. 品群 3. 品種 4. 分類 | AI59: ・対象店舗が選択され、かつ項目8で選択されているアイテムが「0. 全部で」の場合に行が無効になる。 ・対象店舗が選択され、かつ項目8で選択されているアイテムが以下の値である場合に行が有効になる。 1. 部門 2. 品群 3. 品種 4. 分類 | AR59: － | AS59: － | AT59: ー | AU59: － | AY59: ー | BC59: イベントID：SC3201-03
B60: 9.2 | D60: PLUコード | K60: EditText | N60: I/O | O60: － | P60: － | T60: － | X60: － | AA60: 項目8で選択されているアイテムが「5. 商品」の場合に表示する。 | AI60: 対象店舗が選択された場合は有効になる。 | AR60: ● | AS60: ● | AT60: ー | AU60: － | AY60: ー | BC60: イベントID：SC3201-04 最大数字の13桁。フォーカスアウト時に「0」を追加する。
B61: 9.3 | D61: 商品検索 | K61: ボタン | N61: I | O61: － | P61: － | T61: － | X61: － | AA61: 項目8で選択されているアイテムが「5. 商品」の場合に表示する。 | AI61: 対象店舗が選択された場合は有効になる。 | AR61: － | AS61: － | AT61: ー | AU61: － | AY61: ー | BC61: イベントID：SC3201-05
B62: 9.4 | D62: 商品名称 | K62: テキスト | N62: O | O62: － | P62: － | T62: － | X62: － | AA62: 項目8で選択されているアイテムが「5. 商品」の場合に表示する。 | AI62: ー | AR62: － | AS62: － | AT62: ー | AU62: － | AY62: ー
B63: =B58+2 -> 10 | D63: レジNo（タイトル） | K63: テキスト | N63: － | O63: ● | P63: － | T63: － | X63: － | AA63: ー | AI63: ー | AR63: － | AS63: － | AT63: ー | AU63: － | AY63: ー
B64: =B63+1 -> 11 | D64: レジNo（値） | K64: ドロップダウン | N64: I/O | O64: － | P64: － | T64: － | X64: － | AA64: ー | AI64: 対象店舗が選択された場合は有効になる。 | AR64: － | AS64: ● | AT64: ー | AU64: － | AY64: ー | BC64: レジ番号一覧
B96: ■画面項目定義
B98: 画面項目ID | D98: 項目 | K98: Type | N98: I/O | O98: 多言語 | P98: 出力 | AR98: インプット | BC98: 備考
P99: マッピングデータ | X99: 初期値 | AA99: 表示コントロール | AI99: Control enable | AR99: 必須 | AS99: 数字 | AT99: 桁 | AU99: マッピングデータ
P100: API名 | T100: 項目 | AU100: API名 | AY100: 項目
B101: 14 | D101: 検索 | K101: ボタン | N101: I | O101: ● | P101: － | T101: － | X101: 検索 | AA101: ー | AI101: 対象店舗が選択された場合は有効になる。 | AR101: － | AS101: ー | AT101: ー | AU101: － | AY101: ー | BC101: イベントID：SC3201-06
B102: =B101+1 -> 15 | D102: 順位（タイトル） | K102: テキスト | N102: － | O102: ● | P102: － | T102: － | X102: 順位 | AA102: ー | AI102: ー | AR102: － | AS102: ー | AT102: ー | AU102: － | AY102: ー
B103: =B102+1 -> 16 | D103: 順位（値） | K103: テキスト | N103: O | O103: － | P103: － | T103: － | X103: － | AA103: ー | AI103: ー | AR103: － | AS103: ー | AT103: ー | AU103: － | AY103: ー
B104: =B103+1 -> 17 | D104: レジ番号（タイトル） | K104: テキスト | N104: － | O104: ● | P104: － | T104: － | X104: レジ番号 | AA104: ー | AI104: ー | AR104: － | AS104: ー | AT104: ー | AU104: － | AY104: ー
B105: =B104+1 -> 18 | D105: レジ番号（値） | K105: テキスト | N105: O | O105: － | P105: － | T105: － | X105: － | AA105: ー | AI105: ー | AR105: － | AS105: － | AT105: ー | AU105: － | AY105: ー
B106: =B105+1 -> 19 | D106: 商品コード（タイトル） | K106: テキスト | N106: － | O106: ● | X106: 商品コード▼ | AA106: ー | AI106: ー | AR106: － | AS106: － | AT106: ー | AU106: － | AY106: ー
B107: =B106+1 -> 20 | D107: 商品コード（値） | K107: テキスト | N107: O | O107: － | P107: － | T107: － | X107: － | AA107: ー | AI107: ー | AR107: － | AS107: － | AT107: ー | AU107: － | AY107: ー
B108: =B107+1 -> 21 | D108: PLUコード（タイトル） | K108: テキスト | N108: － | O108: ● | P108: － | T108: － | X108: PLUコード | AA108: ー | AI108: ー | AR108: － | AS108: － | AT108: ー | AU108: － | AY108: ー
B109: =B108+1 -> 22 | D109: PLUコード（値） | K109: テキスト | N109: O | O109: － | P109: － | T109: － | X109: － | AA109: ー | AI109: ー | AR109: － | AS109: － | AT109: ー | AU109: － | AY109: ー
B110: =B109+1 -> 23 | D110: 商品名称（値） | K110: テキスト | N110: － | O110: ● | P110: － | T110: － | X110: 名称 | AA110: ー | AI110: ー | AR110: － | AS110: － | AT110: ー | AU110: － | AY110: ー
B111: =B110+1 -> 24 | D111: 商品名称（タイトル） | K111: テキスト | N111: O | O111: － | P111: － | T111: － | X111: － | AA111: ー | AI111: ー | AR111: － | AS111: － | AT111: ー | AU111: － | AY111: ー
B112: =B111+1 -> 25 | D112: 売上金額（タイトル） | K112: テキスト | N112: － | O112: ● | P112: － | T112: － | X112: 売上金額▼ | AA112: ー | AI112: ー | AR112: － | AS112: － | AT112: ー | AU112: － | AY112: ー
B113: =B112+1 -> 26 | D113: 売上金額（値） | K113: テキスト | N113: O | O113: － | P113: － | T113: － | X113: － | AA113: ー | AI113: ー | AR113: － | AS113: － | AT113: ー | AU113: － | AY113: ー
...

Sheet MD3201
A1: システム名 | K1: システム種別 | W1: =IF(表紙!W1="","",表紙!W1) -> 詳細設計書 | AP1: 作成者 | AT1: 作成日 | AY1: 更新者 | BC1: 更新日 | BH1: 版数
A2: =IF(表紙!A2="","",表紙!A2) -> POSサーバー | K2: =IF(表紙!K2="","",表紙!K2) -> POSサーバ | AP2: =IF(表紙!AP2="","",表紙!AP2) -> DuNT | AT2: =IF(表紙!AT2="","",表紙!AT2) -> 45635 | AY2: =IF(表紙!AY2="","",表紙!AY2) -> DuNT | BC2: =IF(表紙!BC2="","",表紙!BC2) -> 45635 | BH2: =IF(表紙!BH2="","",表紙!BH2) -> 0.1
A4: 機能カテゴリ | H4: =IF(表紙!H4="","",表紙!H4) -> 32_レジ別単品別売上点検 | U4: 項目 | Z4: =IF(表紙!Z4="","",表紙!Z4) -> 画面設計書 | AP4: =MID(CELL("filename",A1),FIND("]",CELL("filename",A1))+1,255) -> MD3201
B7: ■商品検索モーダルのイメージ
B35: ■画面項目定義
B37: 画面項目ID | D37: 項目 | K37: タイプ | N37: I/O | O37: 多言語 | P37: 出力 | AR37: インプット | BC37: 備考
P38: マッピングデータ | X38: 初期値 | AA38: 表示コントロール | AI38: Control enable | AR38: 必須 | AS38: 数字 | AT38: 桁 | AU38: マッピングデータ
P39: API名 | T39: 項目 | AU39: API名 | AY39: 項目
B40: 0 | D40: 画面タイトル | K40: テキスト | N40: － | O40: ● | P40: － | T40: － | X40: 商品検索 | AA40: ー | AI40: － | AR40: － | AS40: ー | AT40: ー | AU40: － | AY40: ー | BC40: イベントID：MD3201-01
B41: =B40+1 -> 1 | D41: 商品名称（タイトル） | K41: テキスト | N41: － | O41: ● | P41: － | T41: － | X41: 商品名称 | AA41: ー | AI41: ー | AR41: － | AS41: ー | AT41: ー | AU41: － | AY41: ー
B42: =B41+1 -> 2 | D42: 商品名称（値） | K42: EditText | N42: I | O42: － | P42: － | T42: － | AA42: ー | AI42: デフォルト：有効 | AR42: － | AS42: ー | AT42: ー | AU42: － | AY42: ー | BC42: 最大半角50文字、全角25文字
B43: =B42+1 -> 3 | D43: 検索 | K43: ボタン | N43: － | O43: ● | P43: － | T43: － | X43: 検索 | AA43: ー | AI43: ー | AR43: － | AS43: ー | AT43: ー | AU43: － | AY43: ー | BC43: イベントID：MD3201-02
B44: =B43+1 -> 4 | D44: 選択（列名） | K44: テキスト | N44: I | O44: － | P44: － | T44: － | AA44: ー | AI44: デフォルト：有効 | AR44: － | AS44: － | AT44: ー | AU44: － | AY44: ー
B45: =B44+1 -> 5 | D45: 選択 | K45: ボタン | N45: ー | O45: ● | X45: 選択 | AA45: ー | AI45: ー | AR45: － | AS45: － | AT45: ー | AU45: － | AY45: ー | BC45: イベントID：MD3201-03
B46: =B45+1 -> 6 | D46: 商品コード（列名） | K46: テキスト | N46: ー | O46: ● | P46: － | T46: － | X46: 商品コード | AA46: ー | AI46: ー | AR46: － | AS46: － | AT46: ー | AU46: － | AY46: ー
B47: =B46+1 -> 7 | D47: 商品コード（値） | K47: テキスト | N47: O | O47: － | P47: － | T47: － | X47: － | AA47: ー | AI47: ー | AR47: － | AS47: － | AT47: ー | AU47: － | AY47: ー
B48: =B47+1 -> 8 | D48: PLUコード（列名） | K48: テキスト | N48: ー | O48: ● | P48: － | T48: － | X48: PLUコード | AA48: ー | AI48: ー | AR48: － | AS48: － | AT48: ー | AU48: － | AY48: ー
B49: =B48+1 -> 9 | D49: PLUコード（値） | K49: テキスト | N49: O | O49: － | P49: － | T49: － | X49: － | AA49: ー | AI49: ー | AR49: － | AS49: － | AT49: ー | AU49: － | AY49: ー
B50: =B49+1 -> 10 | D50: 商品名称（列名） | K50: テキスト | N50: ー | O50: ● | X50: 商品名称 | AA50: ー | AI50: ー | AR50: － | AS50: － | AT50: ー | AU50: － | AY50: ー
B51: =B50+1 -> 11 | D51: 商品名称（値） | K51: テキスト | N51: O | O51: － | P51: － | T51: － | X51: － | AA51: ー | AI51: ー | AR51: － | AS51: － | AT51: ー | AU51: － | AY51: ー
B52: =B51+1 -> 12 | D52: 単価（列名） | K52: テキスト | N52: O | O52: ● | P52: － | T52: － | X52: 単価 | AA52: ー | AI52: ー | AR52: － | AS52: － | AT52: ー | AU52: － | AY52: ー
B53: =B52+1 -> 13 | D53: 単価（値） | K53: テキスト | N53: － | O53: － | P53: － | T53: － | X53: － | AA53: ー | AI53: ー | AR53: － | AS53: － | AT53: ー | AU53: － | AY53: ー
B54: =B53+1 -> 14 | D54: 適用日（列名） | K54: テキスト | N54: － | O54: ● | P54: － | T54: － | X54: － | AA54: ー | AI54: ー | AR54: － | AS54: － | AT54: ー | AU54: － | AY54: ー
B55: =B54+1 -> 15 | D55: 適用日（値） | K55: テキスト | N55: I/O | O55: － | P55: － | T55: － | X55: 適用日 | AA55: ー | AI55: ー | AR55: － | AS55: － | AT55: ー | AU55: － | AY55: ー
B56: =B55+1 -> 16 | D56: 前画面 | K56: ボタン | N56: I | O56: － | P56: － | T56: － | X56: 前画面 | AA56: ー | AI56: デフォルト：有効 | AR56: － | AS56: － | AT56: ー | AU56: － | AY56: ー | BC56: イベントID：MD3201-04

Sheet SC3202
A1: システム名 | K1: システム種別 | W1: =IF(表紙!W1="","",表紙!W1) -> 詳細設計書 | AP1: 作成者 | AT1: 作成日 | AY1: 更新者 | BC1: 更新日 | BH1: 版数
A2: =IF(表紙!A2="","",表紙!A2) -> POSサーバー | K2: =IF(表紙!K2="","",表紙!K2) -> POSサーバ | AP2: =IF(表紙!AP2="","",表紙!AP2) -> DuNT | AT2: =IF(表紙!AT2="","",表紙!AT2) -> 45635 | AY2: =IF(表紙!AY2="","",表紙!AY2) -> DuNT | BC2: =IF(表紙!BC2="","",表紙!BC2) -> 45635 | BH2: =IF(表紙!BH2="","",表紙!BH2) -> 0.1
A4: 機能カテゴリ | H4: =IF(表紙!H4="","",表紙!H4) -> 32_レジ別単品別売上点検 | U4: 項目 | Z4: =IF(表紙!Z4="","",表紙!Z4) -> 画面設計書 | AP4: =MID(CELL("filename",A1),FIND("]",CELL("filename",A1))+1,255) -> SC3202
B7: ■初期画面のイメージ
B43: ■画面項目定義
B45: 画面項目ID | D45: 項目 | K45: タイプ | N45: I/O | O45: 多言語 | P45: 出力 | AR45: インプット | BC45: 備考
P46: マッピングデータ | X46: 初期値 | AA46: 表示コントロール | AI46: Control enable | AR46: 必須 | AS46: 数字 | AT46: 桁 | AU46: マッピングデータ
P47: API名 | T47: 項目 | AU47: API名 | AY47: 項目
B48: 0 | D48: 画面タイトル | K48: テキスト | N48: － | O48: ● | P48: － | T48: － | X48: レジ別単品別売上点検 | AA48: ー | AI48: － | AR48: － | AS48: ー | AT48: ー | AU48: － | AY48: ー | BC48: イベントID：SC3202-01
B49: =B48+1 -> 1 | D49: 商品コード（タイトル） | K49: テキスト | N49: － | O49: ● | X49: 商品コード | AA49: ー | AI49: ー | AR49: － | AS49: ー | AT49: ー | AU49: － | AY49: ー
B50: =B49+1 -> 2 | D50: 商品コード（値） | K50: テキスト | N50: O | O50: － | P50: － | T50: － | X50: － | AA50: ー | AI50: ー | AR50: ● | AS50: ー | AT50: ー | AU50: － | AY50: ー
B51: =B50+1 -> 3 | D51: PLUコード（タイトル） | K51: テキスト | N51: － | O51: ● | P51: － | T51: － | X51: PLUコード | AA51: ー | AI51: ー | AR51: － | AS51: ー | AT51: ー | AU51: － | AY51: ー
B52: =B51+1 -> 4 | D52: PLUコード（値） | K52: テキスト | N52: O | O52: － | P52: － | T52: － | X52: － | AA52: ー | AI52: ー | AR52: ● | AS52: － | AT52: ー | AU52: － | AY52: ー
B53: =B52+1 -> 5 | D53: 商品名称（値） | K53: テキスト | N53: － | O53: ● | P53: － | T53: － | X53: 商品名称 | AA53: ー | AI53: ー | AR53: － | AS53: － | AT53: ー | AU53: － | AY53: ー
B54: =B53+1 -> 6 | D54: 商品名称（タイトル） | K54: テキスト | N54: O | O54: － | P54: － | T54: － | X54: － | AA54: ー | AI54: ー | AR54: ● | AS54: ● | AT54: ー | AU54: － | AY54: ー
B55: =B54+1 -> 7 | D55: レジ番号（タイトル） | K55: テキスト | N55: － | O55: ● | P55: － | T55: － | X55: 端末番号 | AA55: ー | AI55: ー | AR55: － | AS55: － | AT55: ー | AU55: － | AY55: ー
B56: =B55+1 -> 8 | D56: レジ番号（値） | K56: テキスト | N56: O | O56: － | P56: － | T56: － | X56: － | AA56: ー | AI56: ー | AR56: － | AS56: － | AT56: ー | AU56: － | AY56: ー
B57: =B56+1 -> 9 | D57: 予約日（タイトル） | K57: テキスト | N57: － | O57: ● | P57: － | T57: － | X57: 営業日 | AA57: ー | AI57: ー | AR57: － | AS57: － | AT57: ー | AU57: － | AY57: ー
B58: =B57+1 -> 10 | D58: 予約日（値） | K58: テキスト | N58: O | O58: － | P58: － | T58: － | X58: － | AA58: ー | AI58: ー
B59: =B58+1 -> 11 | D59: 時間帯（列名） | K59: テキスト | N59: ー | O59: － | P59: － | T59: － | X59: 時間帯 | AA59: ー | AI59: ー | AR59: － | AS59: － | AT59: ー | AU59: － | AY59: ー
B60: =B59+1 -> 12 | D60: 時間帯（値） | K60: テキスト | N60: O | O60: － | P60: － | T60: － | X60: － | AA60: ー | AI60: ー | AR60: － | AS60: － | AT60: ー | AU60: － | AY60: ー | BC60: 形式：hh:mm - hh:mm 00:00～23:59の時間帯を表示する。
B61: =B60+1 -> 13 | D61: 売上金額（列名） | K61: テキスト | N61: － | O61: ● | P61: － | T61: － | X61: 売上金額 (円) | AA61: ー | AI61: ー | AR61: － | AS61: － | AT61: ー | AU61: － | AY61: ー
B62: =B61+1 -> 14 | D62: 売上金額（値） | K62: テキスト | N62: O | O62: － | P62: － | T62: － | AA62: ー | AI62: ー | AR62: － | AS62: ー | AT62: ー | AU62: － | AY62: ー
B63: =B62+1 -> 15 | D63: 件数（列名） | K63: テキスト | N63: ー | O63: ● | P63: － | T63: － | X63: 数量 | AA63: ー | AI63: ー | AR63: － | AS63: ー | AT63: ー | AU63: － | AY63: ー
B64: =B63+1 -> 16 | D64: 件数（値） | K64: テキスト | N64: O | O64: ● | P64: － | T64: － | AA64: ー | AI64: ー | AR64: － | AS64: ー | AT64: ー | AU64: － | AY64: ー
B65: =B64+1 -> 17 | D65: 客数（列名） | K65: テキスト | N65: O | O65: － | P65: － | T65: － | X65: 客数 | AA65: ー | AI65: ー | AR65: － | AS65: － | AT65: ー | AU65: － | AY65: ー
B66: =B65+1 -> 18 | D66: 客数（値） | K66: テキスト | N66: － | O66: ● | X66: 商品コード▼ | AA66: ー | AI66: ー | AR66: － | AS66: － | AT66: ー | AU66: － | AY66: ー
B67: =B66+1 -> 19 | D67: グラフ | K67: ビュー | N67: O | O67: － | P67: － | T67: － | X67: － | AA67: ー | AI67: ー | AR67: － | AS67: － | AT67: ー | AU67: － | AY67: ー
B68: =B67+1 -> 20 | D68: 売上金額 (円) | K68: ビュー | N68: － | O68: ● | P68: － | T68: － | X68: [売上金額 (円) | AA68: ー | AI68: ー | AR68: － | AS68: － | AT68: ー | AU68: － | AY68: ー
B69: =B68+1 -> 21 | D69: 数量 | K69: ビュー | N69: O | O69: － | P69: － | T69: － | X69: 数量 | AA69: ー | AI69: ー | AR69: － | AS69: － | AT69: ー | AU69: － | AY69: ー
B70: =B69+1 -> 22 | D70: 客数 | K70: ビュー | N70: － | O70: ● | P70: － | T70: － | X70: 客数 | AA70: ー | AI70: ー | AR70: － | AS70: － | AT70: ー | AU70: － | AY70: ー
B71: =B70+1 -> 23 | D71: 検索 | K71: ボタン | N71: I | O71: ● | P71: － | T71: － | X71: 検索 | AA71: ー | AI71: ー | AR71: － | AS71: － | AT71: ー | AU71: － | AY71: ー | BC71: イベントID：SC3202-02
