Workbook

Sheet 表紙
A1: システム名 | K1: システム種別 | W1: DB定義書 | AP1: 作成者 | AT1: 作成日 | AY1: 更新者 | BC1: 更新日 | BH1: 版数
A2: 現金専用簡易セルフPOS | AP2: きよはら | AT2: 44652 | AY2: =LOOKUP(2,1/(改廃履歴!H11:H30000<>""),改廃履歴!H11:H30000) -> Thanh Nguyên | BC2: =LOOKUP(2,1/(改廃履歴!B11:B30000<>""),改廃履歴!B11:B30000) -> 45285 | BH2: =LOOKUP(2,1/(改廃履歴!O11:O30000<>""),改廃履歴!O11:O30000) -> 0.2
A4: 機能カテゴリ | H4: 共通 | U4: 項目 | AP4: 表紙
L16: 現金専用簡易セルフPOS 基本設計書
L24: =K2&"/"&H4&"/"&Z4 -> /共通/
Q44: 承認日 | AA44: 承認者 | AQ44: 版数

Sheet 改廃履歴
A1: システム名 | K1: システム種別 | W1: =IF(表紙!W1="","",表紙!W1) -> DB定義書 | AP1: 作成者 | AT1: 作成日 | AY1: 更新者 | BC1: 更新日 | BH1: 版数
A2: =IF(表紙!A2="","",表紙!A2) -> 現金専用簡易セルフPOS | K2: =IF(表紙!K2="","",表紙!K2) | AP2: =IF(表紙!AP2="","",表紙!AP2) -> きよはら | AT2: =IF(表紙!AT2="","",表紙!AT2) -> 44652 | AY2: =IF(表紙!AY2="","",表紙!AY2) -> Thanh Nguyên | BC2: =IF(表紙!BC2="","",表紙!BC2) -> 45285 | BH2: =IF(表紙!BH2="","",表紙!BH2) -> 0.2
A4: 機能カテゴリ | H4: =IF(表紙!H4="","",表紙!H4) -> 共通 | U4: 項目 | Z4: =IF(表紙!Z4="","",表紙!Z4) | AP4: 改廃履歴
B8: ■改廃履歴
B10: 更新日付 | H10: 更新者 | O10: 版数 | S10: 変更内容 | AX10: 承認日付 | BD10: 承認者
B11: 44652 | H11: きよはら | O11: 0.1 | S11: 新規作成
B13: 45285 | H13: Thanh Nguyên | O13: 0.2 | S13: プリセットメニューマスタに、プリセットボタンレイアウト名称を追加

Sheet DB一覧
A1: システム名 | K1: システム種別 | W1: =IF(表紙!W1="","",表紙!W1) -> DB定義書 | AP1: 作成者 | AT1: 作成日 | AY1: 更新者 | BC1: 更新日 | BH1: 版数
A2: =IF(表紙!A2="","",表紙!A2) -> 現金専用簡易セルフPOS | K2: =IF(表紙!K2="","",表紙!K2) | AP2: =IF(表紙!AP2="","",表紙!AP2) -> きよはら | AT2: =IF(表紙!AT2="","",表紙!AT2) -> 44652 | AY2: =IF(表紙!AY2="","",表紙!AY2) -> Thanh Nguyên | BC2: =IF(表紙!BC2="","",表紙!BC2) -> 45285 | BH2: =IF(表紙!BH2="","",表紙!BH2) -> 0.2
A4: 機能カテゴリ | H4: =IF(表紙!H4="","",表紙!H4) -> 共通 | U4: 項目 | Z4: =IF(表紙!Z4="","",表紙!Z4) | AP4: Sheet7
B7: ID | D7: 区分 | M7: 論理テーブル名 | AB7: 物理テーブル名 | AW7: 備考
D8: マスタ連携 | M8: PLUメンテ | AB8: GHPLUM.CSV
D9: マスタ連携 | M9: 特売マスタ | AB9: GHDISCOUNTM.CSV
D10: マスタ連携 | M10: MMマスタ | AB10: GHBUNDLEM.CSV
D11: マスタ連携 | M11: 企画マスタ | AB11: GHEVENTM.CSV
AB12: GHPLUPOINT.CSV
D13: マスタ連携 | M13: P001(POP商品情報送付データ) | AB13: Ｐ001_yyyymmdd.csv
D14: マスタ連携 | M14: Ｐ003(POP棚番情報送付データ) | AB14: Ｐ003_yyyymmdd.csv

Sheet テスト
A1: システム名 | K1: システム種別 | W1: =IF(表紙!W1="","",表紙!W1) -> DB定義書 | AP1: 作成者 | AT1: 作成日 | AY1: 更新者 | BC1: 更新日 | BH1: 版数
A2: =IF(表紙!A2="","",表紙!A2) -> 現金専用簡易セルフPOS | K2: =IF(表紙!K2="","",表紙!K2) | AP2: =IF(表紙!AP2="","",表紙!AP2) -> きよはら | AT2: =IF(表紙!AT2="","",表紙!AT2) -> 44652 | AY2: =IF(表紙!AY2="","",表紙!AY2) -> Thanh Nguyên | BC2: =IF(表紙!BC2="","",表紙!BC2) -> 45285 | BH2: =IF(表紙!BH2="","",表紙!BH2) -> 0.2
A4: 機能カテゴリ | H4: =IF(表紙!H4="","",表紙!H4) -> 共通 | U4: 項目 | Z4: =IF(表紙!Z4="","",表紙!Z4) | AP4: Sheet7
B7: ID | D7: 論理テーブル名 | M7: テストデータ | Y7: CSV | AC7: レプリカ | AG7: レプリカ
Y8: ﾚｺｰﾄﾞ数 | AC8: ｲﾝﾎﾟｰﾄ数 | AG8: 所要時間
B9: 01 | D9: PLUメンテ | M9: 20240110223036GHPLUM.CSV | Y9: 87383 | AC9: 87383 | AG9: 0.00076388889
B10: 02 | D10: 特売マスタ | M10: 20240110223046GHDISCOUNTM.CSV | Y10: 36176 | AC10: 36176 | AG10: 0.00017361111
B11: 03 | D11: MMマスタ | M11: 20240110223101GHBUNDLEM.CSV | Y11: 17201 | AC11: 17201 | AG11: 0.00015046296
B12: 04 | D12: 企画マスタ | M12: 20240108223019GHEVENTM.CSV | Y12: 469 | AC12: 469 | AG12: 2.3148148e-05
D13: ????????? | M13: 20240110200005GHPLUPOINT.CSV | Y13: 0 | AC13: 0
D14: 階層マスタ
B15: 06 | D15: P001(POP商品情報送付データ) | M15: Ｐ001_yyyymmdd.csv | Y15: 201250 | AC15: 200810 | AG15: 0.0035416667
D16: P001(ヘッダー) | Y16: - | AC16: 220
D17: P001(エンドレコード) | Y17: - | AC17: 220
B18: 07 | D18: P003(POP棚番情報送付データ) | M18: Ｐ003_yyyymmdd.csv | Y18: 2770268 | AC18: 2717635 | AG18: 0.014074074
AF19: 合計 | AG19: =SUM(AG9:AJ18) -> 0.018726852

Sheet ER
A1: システム名 | K1: システム種別 | W1: =IF(表紙!W1="","",表紙!W1) -> DB定義書 | AP1: 作成者 | AT1: 作成日 | AY1: 更新者 | BC1: 更新日 | BH1: 版数
A2: =IF(表紙!A2="","",表紙!A2) -> 現金専用簡易セルフPOS | K2: =IF(表紙!K2="","",表紙!K2) | AP2: =IF(表紙!AP2="","",表紙!AP2) -> きよはら | AT2: =IF(表紙!AT2="","",表紙!AT2) -> 44652 | AY2: =IF(表紙!AY2="","",表紙!AY2) -> Thanh Nguyên | BC2: =IF(表紙!BC2="","",表紙!BC2) -> 45285 | BH2: =IF(表紙!BH2="","",表紙!BH2) -> 0.2
A4: 機能カテゴリ | H4: =IF(表紙!H4="","",表紙!H4) -> 共通 | U4: 項目 | Z4: =IF(表紙!Z4="","",表紙!Z4) | AP4: ER

Sheet PLUメンテ
A1: システム名 | K1: システム種別 | W1: =IF(表紙!W1="","",表紙!W1) -> DB定義書 | AP1: 作成者 | AT1: 作成日 | AY1: 更新者 | BC1: 更新日 | BH1: 版数
A2: =IF(表紙!A2="","",表紙!A2) -> 現金専用簡易セルフPOS | K2: =IF(表紙!K2="","",表紙!K2) | AP2: =IF(表紙!AP2="","",表紙!AP2) -> きよはら | AT2: =IF(表紙!AT2="","",表紙!AT2) -> 44652 | AY2: =IF(表紙!AY2="","",表紙!AY2) -> Thanh Nguyên | BC2: =IF(表紙!BC2="","",表紙!BC2) -> 45285 | BH2: =IF(表紙!BH2="","",表紙!BH2) -> 0.2
A4: 機能カテゴリ | H4: =IF(表紙!H4="","",表紙!H4) -> 共通 | U4: 項目 | Z4: =IF(表紙!Z4="","",表紙!Z4) | AP4: テンプレート
B7: ■テーブル情報
B8: スキーマ名 | G8: Replica_Kasumi | Y8: RDBMS名
B9: 論理名 | G9: ＰＬＵメンテ | Y9: バージョン
B10: 物理名 | G10: GHPLUM
B11: 備考
B19: ■カラム情報 | BP19: ="DROP TABLE IF EXISTS `"&$G$8&"`.`"&$G$10&"`;" -> DROP TABLE IF EXISTS `Replica_Kasumi`.`GHPLUM`;
B20: No. | D20: 論理名 | R20: 物理名 | AC20: データ型 | AH20: PK | AJ20: Not Null | AM20: デフォルト | AT20: 備考 | BP20: ="CREATE TABLE `"&$G$8&"`.`"&$G$10&"` (" -> CREATE TABLE `Replica_Kasumi`.`GHPLUM` (
B21: 1 | D21: レコードID | R21: RECORD_ID | AC21: bigint | AJ21: Y | AM21: 自動追加 | BL21: =REPT("a"&CHAR(10)&"b",INT(LENB(SUBSTITUTE(AT21,CHAR(10),""))/70)+1) -> a b | BP21: `RECORD_ID` bigint NOT NULL AUTO_INCREMENT COMMENT 'レコードID'
B22: =B21+1 -> 2 | D22: レコード作成日付 | R22: RECORD_CREATE_DATE | AC22: date | AJ22: Y | AM22: CURRENT_DATE | BL22: =REPT("a"&CHAR(10)&"b",INT(LENB(SUBSTITUTE(AT22,CHAR(10),""))/70)+1) -> a b | BP22: ,`RECORD_CREATE_DATE` date NOT NULL COMMENT 'レコード作成日付'
B23: =B22+1 -> 3 | D23: レコード作成時間 | R23: RECORD_CREATE_TIME | AC23: time | AJ23: Y | AM23: CURRENT_TIME | BL23: =REPT("a"&CHAR(10)&"b",INT(LENB(SUBSTITUTE(AT23,CHAR(10),""))/70)+1) -> a b | BP23: ,`RECORD_CREATE_TIME` time NOT NULL COMMENT 'レコード作成時間' | BV23: SET CHARACTER_SET_DATABASE = UTF8;
B24: =B23+1 -> 4 | D24: レコード更新日付 | R24: RECORD_UPDATE_DATE | AC24: date | AJ24: Y | AM24: CURRENT_DATE | AT24: トリガーにより更新 | BL24: =REPT("a"&CHAR(10)&"b",INT(LENB(SUBSTITUTE(AT24,CHAR(10),""))/70)+1) -> a b | BP24: ,`RECORD_UPDATE_DATE` date NOT NULL COMMENT 'レコード更新日付/トリガーにより更新' | BV24: ="UPDATE `REPLICA_KASUMI`.`"&$G$10&"` A,`TMP`.`"&$G$10&"` B" -> UPDATE `REPLICA_KASUMI`.`GHPLUM` A,`TMP`.`GHPLUM` B
B25: =B24+1 -> 5 | D25: レコード更新時間 | R25: RECORD_UPDATE_TIME | AC25: time | AJ25: Y | AM25: CURRENT_TIME | AT25: トリガーにより更新 | BL25: =REPT("a"&CHAR(10)&"b",INT(LENB(SUBSTITUTE(AT25,CHAR(10),""))/70)+1) -> a b | BP25: ,`RECORD_UPDATE_TIME` time NOT NULL COMMENT 'レコード更新時間/トリガーにより更新' | BR25: ="DROP TABLE IF EXISTS `TMP`.`"&$G$10&"`;" -> DROP TABLE IF EXISTS `TMP`.`GHPLUM`; | BT25: ="LOAD DATA INFILE 'C:/04_DATAFILE/"&$G$10&"/TMP/"&$G$10&".CSV' " -> LOAD DATA INFILE 'C:/04_DATAFILE/GHPLUM/TMP/GHPLUM.CSV' | BV25: SET
A26: @1 | B26: =B25+1 -> 6 | D26: レコード無効フラグ | R26: RECORD_VOID_FLAG | AC26: char(1) | AJ26: Y | AM26: "" | AT26: 0: 有効フラグ、 1:無効フラグ | BL26: =REPT("a"&CHAR(10)&"b",INT(LENB(SUBSTITUTE(AT26,CHAR(10),""))/70)+1) -> a b | BP26: ,`RECORD_VOID_FLAG` char(1) NOT NULL DEFAULT '' COMMENT 'レコード無効フラグ '''': 有効フラグ、 1:無効フラグ' | BR26: ="CREATE TABLE `TMP`.`"&G10&"` (" -> CREATE TABLE `TMP`.`GHPLUM` ( | BT26: ="REPLACE INTO TABLE TMP.`"&$G$10&"` FIELDS TERMINATED BY ',' ENCLOSED BY '\""' LINES TERMINATED BY '\r\n' (" -> REPLACE INTO TABLE TMP.`GHPLUM` FIELDS TERMINATED BY ',' ENCLOSED BY '\"' LINES TERMINATED BY '\r\n' ( | BX26: ="INSERT INTO `REPLICA_KASUMI`.`"&$G$10&"` (" -> INSERT INTO `REPLICA_KASUMI`.`GHPLUM` ( | BZ26: ) SELECT
A27: @2 | B27: 7 | D27: 処理区分 | R27: PRCS_TYP | AC27: {=_xlfn.SWITCH(BM27,"String","varchar("&BN27&")","Long","int","Integer","smallint","Double","decimal(9,2)","Currency","int")} -> varchar(1) | AT27: Ａ：登録 Ｕ：更新 Ｄ：削除 | BL27: =REPT("a"&CHAR(10)&"b",INT(LENB(SUBSTITUTE(AT27,CHAR(10),""))/70)+1) -> a b | BM27: String | BN27: 1 | BP27: =",`"&R27&"` "&AC27&" "&IF(AJ27="Y","NOT NULL","")&" COMMENT '"&D27&"'" -> ,`PRCS_TYP` varchar(1) COMMENT '処理区分' | BR27: ="`"&R27&"` "&AC27&" "&IF(AJ27="Y","NOT NULL","") -> `PRCS_TYP` varchar(1) | BT27: ="`"&R27&"`" -> `PRCS_TYP` | BV27: ="A.`"&R27&"` = B.`"&R27&"`" -> A.`PRCS_TYP` = B.`PRCS_TYP` | BX27: ="`"&R27&"`" -> `PRCS_TYP` | BZ27: ="`"&R27&"`" -> `PRCS_TYP`
A28: @3 | B28: 8 | D28: 商品コード | R28: PLUID | AC28: {=_xlfn.SWITCH(BM28,"String","varchar("&BN28&")","Long","int","Integer","smallint","Double","decimal(9,2)","Currency","int")} -> varchar(24) | AH28: 1 | AT28: 左づめ 数字で最大19桁（5桁分はシステムで使用する） 特にＰＬＵコードを使用しない場合はｽｷｬﾝｺｰﾄﾞと同じ値を入れておくこと | BL28: =REPT("a"&CHAR(10)&"b",INT(LENB(SUBSTITUTE(AT28,CHAR(10),""))/70)+1) -> a ba b | BM28: String | BN28: 24 | BP28: =",`"&R28&"` "&AC28&" "&IF(AJ28="Y","NOT NULL","")&" COMMENT '"&D28&"'" -> ,`PLUID` varchar(24) COMMENT '商品コード' | BR28: =",`"&R28&"` "&AC28&" "&IF(AJ28="Y","NOT NULL","") -> ,`PLUID` varchar(24) | BT28: =",`"&R28&"`" -> ,`PLUID` | BV28: =",A.`"&R28&"` = B.`"&R28&"`" -> ,A.`PLUID` = B.`PLUID` | BX28: =",`"&R28&"`" -> ,`PLUID` | BZ28: =",`"&R28&"`" -> ,`PLUID`
A29: @4 | B29: 9 | D29: 店舗コード | R29: STR_ID | AC29: {=_xlfn.SWITCH(BM29,"String","varchar("&BN29&")","Long","int","Integer","smallint","Double","decimal(9,2)","Currency","int")} -> int | AH29: 2 | AT29: ０は不可 | BL29: =REPT("a"&CHAR(10)&"b",INT(LENB(SUBSTITUTE(AT29,CHAR(10),""))/70)+1) -> a b | BM29: Long | BP29: =",`"&R29&"` "&AC29&" "&IF(AJ29="Y","NOT NULL","")&" COMMENT '"&D29&"'" -> ,`STR_ID` int COMMENT '店舗コード' | BR29: =",`"&R29&"` "&AC29&" "&IF(AJ29="Y","NOT NULL","") -> ,`STR_ID` int | BT29: =",`"&R29&"`" -> ,`STR_ID` | BV29: =",A.`"&R29&"` = B.`"&R29&"`" -> ,A.`STR_ID` = B.`STR_ID` | BX29: =",`"&R29&"`" -> ,`STR_ID` | BZ29: =",`"&R29&"`" -> ,`STR_ID`
A30: @5 | B30: 9 | D30: 税種別コード | R30: TAXBLTY_CD | AC30: {=_xlfn.SWITCH(BM30,"String","varchar("&BN30&")","Long","int","Integer","smallint","Double","decimal(9,2)","Currency","int")} -> smallint | AT30: 例 １：外税 ２：内税 ３：非課税 （ＧＳの税設定で指定したものと同じものを入れる） | BL30: =REPT("a"&CHAR(10)&"b",INT(LENB(SUBSTITUTE(AT30,CHAR(10),""))/70)+1) -> a ba b | BM30: Integer | BP30: =",`"&R30&"` "&AC30&" "&IF(AJ30="Y","NOT NULL","")&" COMMENT '"&D30&"'" -> ,`TAXBLTY_CD` smallint COMMENT '税種別コード' | BR30: =",`"&R30&"` "&AC30&" "&IF(AJ30="Y","NOT NULL","") -> ,`TAXBLTY_CD` smallint | BT30: =",`"&R30&"`" -> ,`TAXBLTY_CD` | BV30: =",A.`"&R30&"` = B.`"&R30&"`" -> ,A.`TAXBLTY_CD` = B.`TAXBLTY_CD` | BX30: =",`"&R30&"`" -> ,`TAXBLTY_CD` | BZ30: =",`"&R30&"`" -> ,`TAXBLTY_CD`
A31: @6 | B31: 9 | D31: 単品名称 | R31: DSPL_DESCR | AC31: {=_xlfn.SWITCH(BM31,"String","varchar("&BN31&")","Long","int","Integer","smallint","Double","decimal(9,2)","Currency","int")} -> varchar(20) | AT31: 日本語２０文字以内 | BL31: =REPT("a"&CHAR(10)&"b",INT(LENB(SUBSTITUTE(AT31,CHAR(10),""))/70)+1) -> a b | BM31: String | BN31: 20 | BP31: =",`"&R31&"` "&AC31&" "&IF(AJ31="Y","NOT NULL","")&" COMMENT '"&D31&"'" -> ,`DSPL_DESCR` varchar(20) COMMENT '単品名称' | BR31: =",`"&R31&"` "&AC31&" "&IF(AJ31="Y","NOT NULL","") -> ,`DSPL_DESCR` varchar(20) | BT31: =",`"&R31&"`" -> ,`DSPL_DESCR` | BV31: =",A.`"&R31&"` = B.`"&R31&"`" -> ,A.`DSPL_DESCR` = B.`DSPL_DESCR` | BX31: =",`"&R31&"`" -> ,`DSPL_DESCR` | BZ31: =",`"&R31&"`" -> ,`DSPL_DESCR`
A32: @7 | B32: 9 | D32: レシート記述名 | R32: DCPT_DESCR | AC32: {=_xlfn.SWITCH(BM32,"String","varchar("&BN32&")","Long","int","Integer","smallint","Double","decimal(9,2)","Currency","int")} -> varchar(10) | AT32: レシートに印字される名称 日本語１0文字以内 | BL32: =REPT("a"&CHAR(10)&"b",INT(LENB(SUBSTITUTE(AT32,CHAR(10),""))/70)+1) -> a b | BM32: String | BN32: 10 | BP32: =",`"&R32&"` "&AC32&" "&IF(AJ32="Y","NOT NULL","")&" COMMENT '"&D32&"'" -> ,`DCPT_DESCR` varchar(10) COMMENT 'レシート記述名' | BR32: =",`"&R32&"` "&AC32&" "&IF(AJ32="Y","NOT NULL","") -> ,`DCPT_DESCR` varchar(10) | BT32: =",`"&R32&"`" -> ,`DCPT_DESCR` | BV32: =",A.`"&R32&"` = B.`"&R32&"`" -> ,A.`DCPT_DESCR` = B.`DCPT_DESCR` | BX32: =",`"&R32&"`" -> ,`DCPT_DESCR` | BZ32: =",`"&R32&"`" -> ,`DCPT_DESCR`
A33: @8 | B33: 9 | D33: 店舗階層コード | R33: STR_HIER_ID | AC33: {=_xlfn.SWITCH(BM33,"String","varchar("&BN33&")","Long","int","Integer","smallint","Double","decimal(9,2)","Currency","int")} -> int | AT33: 現在未使用 ０固定 | BL33: =REPT("a"&CHAR(10)&"b",INT(LENB(SUBSTITUTE(AT33,CHAR(10),""))/70)+1) -> a b | BM33: Long | BP33: =",`"&R33&"` "&AC33&" "&IF(AJ33="Y","NOT NULL","")&" COMMENT '"&D33&"'" -> ,`STR_HIER_ID` int COMMENT '店舗階層コード' | BR33: =",`"&R33&"` "&AC33&" "&IF(AJ33="Y","NOT NULL","") -> ,`STR_HIER_ID` int | BT33: =",`"&R33&"`" -> ,`STR_HIER_ID` | BV33: =",A.`"&R33&"` = B.`"&R33&"`" -> ,A.`STR_HIER_ID` = B.`STR_HIER_ID` | BX33: =",`"&R33&"`" -> ,`STR_HIER_ID` | BZ33: =",`"&R33&"`" -> ,`STR_HIER_ID`
A34: @9 | B34: 9 | D34: 商品／非商品識別コード | R34: LN_ITM_CD | AC34: {=_xlfn.SWITCH(BM34,"String","varchar("&BN34&")","Long","int","Integer","smallint","Double","decimal(9,2)","Currency","int")} -> int | AT34: 現在０固定 ０：通常商品 １：売上除外商品 ２：非商品 ３：非商品＆売上除外商品 | BL34: =REPT("a"&CHAR(10)&"b",INT(LENB(SUBSTITUTE(AT34,CHAR(10),""))/70)+1) -> a ba b | BM34: Long | BP34: =",`"&R34&"` "&AC34&" "&IF(AJ34="Y","NOT NULL","")&" COMMENT '"&D34&"'" -> ,`LN_ITM_CD` int COMMENT '商品／非商品識別コード' | BR34: =",`"&R34&"` "&AC34&" "&IF(AJ34="Y","NOT NULL","") -> ,`LN_ITM_CD` int | BT34: =",`"&R34&"`" -> ,`LN_ITM_CD` | BV34: =",A.`"&R34&"` = B.`"&R34&"`" -> ,A.`LN_ITM_CD` = B.`LN_ITM_CD` | BX34: =",`"&R34&"`" -> ,`LN_ITM_CD` | BZ34: =",`"&R34&"`" -> ,`LN_ITM_CD`
A35: @10 | B35: 9 | D35: 限定商品グループ | R35: SLS_RSTRCT_GRP | AC35: {=_xlfn.SWITCH(BM35,"String","varchar("&BN35&")","Long","int","Integer","smallint","Double","decimal(9,2)","Currency","int")} -> int | AT35: 現在未使用 ０固定 | BL35: =REPT("a"&CHAR(10)&"b",INT(LENB(SUBSTITUTE(AT35,CHAR(10),""))/70)+1) -> a b | BM35: Long | BP35: =",`"&R35&"` "&AC35&" "&IF(AJ35="Y","NOT NULL","")&" COMMENT '"&D35&"'" -> ,`SLS_RSTRCT_GRP` int COMMENT '限定商品グループ' | BR35: =",`"&R35&"` "&AC35&" "&IF(AJ35="Y","NOT NULL","") -> ,`SLS_RSTRCT_GRP` int | BT35: =",`"&R35&"`" -> ,`SLS_RSTRCT_GRP` | BV35: =",A.`"&R35&"` = B.`"&R35&"`" -> ,A.`SLS_RSTRCT_GRP` = B.`SLS_RSTRCT_GRP` | BX35: =",`"&R35&"`" -> ,`SLS_RSTRCT_GRP` | BZ35: =",`"&R35&"`" -> ,`SLS_RSTRCT_GRP`
A36: @11 | B36: 9 | D36: 商品返品場所 | R36: DFLT_RTN_LOC_ID | AC36: {=_xlfn.SWITCH(BM36,"String","varchar("&BN36&")","Long","int","Integer","smallint","Double","decimal(9,2)","Currency","int")} -> varchar(10) | AT36: 現在未使用 Ｎｕｌｌ固定 | BL36: =REPT("a"&CHAR(10)&"b",INT(LENB(SUBSTITUTE(AT36,CHAR(10),""))/70)+1) -> a b | BM36: String | BN36: 10 | BP36: =",`"&R36&"` "&AC36&" "&IF(AJ36="Y","NOT NULL","")&" COMMENT '"&D36&"'" -> ,`DFLT_RTN_LOC_ID` varchar(10) COMMENT '商品返品場所' | BR36: =",`"&R36&"` "&AC36&" "&IF(AJ36="Y","NOT NULL","") -> ,`DFLT_RTN_LOC_ID` varchar(10) | BT36: =",`"&R36&"`" -> ,`DFLT_RTN_LOC_ID` | BV36: =",A.`"&R36&"` = B.`"&R36&"`" -> ,A.`DFLT_RTN_LOC_ID` = B.`DFLT_RTN_LOC_ID` | BX36: =",`"&R36&"`" -> ,`DFLT_RTN_LOC_ID` | BZ36: =",`"&R36&"`" -> ,`DFLT_RTN_LOC_ID`
A37: @12 | B37: 9 | D37: 単品販売単位 | R37: UOM | AC37: {=_xlfn.SWITCH(BM37,"String","varchar("&BN37&")","Long","int","Integer","smallint","Double","decimal(9,2)","Currency","int")} -> varchar(10) | AT37: 現在未使用 Ｎｕｌｌ固定 | BL37: =REPT("a"&CHAR(10)&"b",INT(LENB(SUBSTITUTE(AT37,CHAR(10),""))/70)+1) -> a b | BM37: String | BN37: 10 | BP37: =",`"&R37&"` "&AC37&" "&IF(AJ37="Y","NOT NULL","")&" COMMENT '"&D37&"'" -> ,`UOM` varchar(10) COMMENT '単品販売単位' | BR37: =",`"&R37&"` "&AC37&" "&IF(AJ37="Y","NOT NULL","") -> ,`UOM` varchar(10) | BT37: =",`"&R37&"`" -> ,`UOM` | BV37: =",A.`"&R37&"` = B.`"&R37&"`" -> ,A.`UOM` = B.`UOM` | BX37: =",`"&R37&"`" -> ,`UOM` | BZ37: =",`"&R37&"`" -> ,`UOM`
A38: @13 | B38: 9 | D38: 最小販売単位 | R38: UNT_QTY | AC38: {=_xlfn.SWITCH(BM38,"String","varchar("&BN38&")","Long","int","Integer","smallint","Double","decimal(9,2)","Currency","int")} -> decimal(9,2) | AT38: 現在未使用 ０固定 | BL38: =REPT("a"&CHAR(10)&"b",INT(LENB(SUBSTITUTE(AT38,CHAR(10),""))/70)+1) -> a b | BM38: Double | BP38: =",`"&R38&"` "&AC38&" "&IF(AJ38="Y","NOT NULL","")&" COMMENT '"&D38&"'" -> ,`UNT_QTY` decimal(9,2) COMMENT '最小販売単位' | BR38: =",`"&R38&"` "&AC38&" "&IF(AJ38="Y","NOT NULL","") -> ,`UNT_QTY` decimal(9,2) | BT38: =",`"&R38&"`" -> ,`UNT_QTY` | BV38: =",A.`"&R38&"` = B.`"&R38&"`" -> ,A.`UNT_QTY` = B.`UNT_QTY` | BX38: =",`"&R38&"`" -> ,`UNT_QTY` | BZ38: =",`"&R38&"`" -> ,`UNT_QTY`
A39: @14 | B39: 9 | D39: 値引識別フラグ | R39: MD_FG | AC39: {=_xlfn.SWITCH(BM39,"String","varchar("&BN39&")","Long","int","Integer","smallint","Double","decimal(9,2)","Currency","int")} -> smallint | AT39: 現在未使用 ０固定 | BL39: =REPT("a"&CHAR(10)&"b",INT(LENB(SUBSTITUTE(AT39,CHAR(10),""))/70)+1) -> a b | BM39: Integer | BP39: =",`"&R39&"` "&AC39&" "&IF(AJ39="Y","NOT NULL","")&" COMMENT '"&D39&"'" -> ,`MD_FG` smallint COMMENT '値引識別フラグ' | BR39: =",`"&R39&"` "&AC39&" "&IF(AJ39="Y","NOT NULL","") -> ,`MD_FG` smallint | BT39: =",`"&R39&"`" -> ,`MD_FG` | BV39: =",A.`"&R39&"` = B.`"&R39&"`" -> ,A.`MD_FG` = B.`MD_FG` | BX39: =",`"&R39&"`" -> ,`MD_FG` | BZ39: =",`"&R39&"`" -> ,`MD_FG`
A40: @15 | B40: 9 | D40: 数量登録必須フラグ | R40: QTY_RQED_FG | AC40: {=_xlfn.SWITCH(BM40,"String","varchar("&BN40&")","Long","int","Integer","smallint","Double","decimal(9,2)","Currency","int")} -> smallint | AT40: 現在未使用 ０固定 | BL40: =REPT("a"&CHAR(10)&"b",INT(LENB(SUBSTITUTE(AT40,CHAR(10),""))/70)+1) -> a b | BM40: Integer | BP40: =",`"&R40&"` "&AC40&" "&IF(AJ40="Y","NOT NULL","")&" COMMENT '"&D40&"'" -> ,`QTY_RQED_FG` smallint COMMENT '数量登録必須フラグ' | BR40: =",`"&R40&"` "&AC40&" "&IF(AJ40="Y","NOT NULL","") -> ,`QTY_RQED_FG` smallint | BT40: =",`"&R40&"`" -> ,`QTY_RQED_FG` | BV40: =",A.`"&R40&"` = B.`"&R40&"`" -> ,A.`QTY_RQED_FG` = B.`QTY_RQED_FG` | BX40: =",`"&R40&"`" -> ,`QTY_RQED_FG` | BZ40: =",`"&R40&"`" -> ,`QTY_RQED_FG`
A41: @16 | B41: 9 | D41: 数量登録可否フラグ | R41: QTY_ALLOWD | AC41: {=_xlfn.SWITCH(BM41,"String","varchar("&BN41&")","Long","int","Integer","smallint","Double","decimal(9,2)","Currency","int")} -> smallint | AT41: 現在未使用 ０固定 | BL41: =REPT("a"&CHAR(10)&"b",INT(LENB(SUBSTITUTE(AT41,CHAR(10),""))/70)+1) -> a b | BM41: Integer | BP41: =",`"&R41&"` "&AC41&" "&IF(AJ41="Y","NOT NULL","")&" COMMENT '"&D41&"'" -> ,`QTY_ALLOWD` smallint COMMENT '数量登録可否フラグ' | BR41: =",`"&R41&"` "&AC41&" "&IF(AJ41="Y","NOT NULL","") -> ,`QTY_ALLOWD` smallint | BT41: =",`"&R41&"`" -> ,`QTY_ALLOWD` | BV41: =",A.`"&R41&"` = B.`"&R41&"`" -> ,A.`QTY_ALLOWD` = B.`QTY_ALLOWD` | BX41: =",`"&R41&"`" -> ,`QTY_ALLOWD` | BZ41: =",`"&R41&"`" -> ,`QTY_ALLOWD`
A42: @17 | B42: 9 | D42: 販売時の承認フラグ | R42: SLS_AURH_FG | AC42: {=_xlfn.SWITCH(BM42,"String","varchar("&BN42&")","Long","int","Integer","smallint","Double","decimal(9,2)","Currency","int")} -> smallint | AT42: 現在未使用 ０固定 | BL42: =REPT("a"&CHAR(10)&"b",INT(LENB(SUBSTITUTE(AT42,CHAR(10),""))/70)+1) -> a b | BM42: Integer | BP42: =",`"&R42&"` "&AC42&" "&IF(AJ42="Y","NOT NULL","")&" COMMENT '"&D42&"'" -> ,`SLS_AURH_FG` smallint COMMENT '販売時の承認フラグ' | BR42: =",`"&R42&"` "&AC42&" "&IF(AJ42="Y","NOT NULL","") -> ,`SLS_AURH_FG` smallint | BT42: =",`"&R42&"`" -> ,`SLS_AURH_FG` | BV42: =",A.`"&R42&"` = B.`"&R42&"`" -> ,A.`SLS_AURH_FG` = B.`SLS_AURH_FG` | BX42: =",`"&R42&"`" -> ,`SLS_AURH_FG` | BZ42: =",`"&R42&"`" -> ,`SLS_AURH_FG`
A43: @18 | B43: 9 | D43: 手入力価格変更フラグ | R43: MNL_PRC_LVL | AC43: {=_xlfn.SWITCH(BM43,"String","varchar("&BN43&")","Long","int","Integer","smallint","Double","decimal(9,2)","Currency","int")} -> smallint | AT43: 現在未使用 ０固定 | BL43: =REPT("a"&CHAR(10)&"b",INT(LENB(SUBSTITUTE(AT43,CHAR(10),""))/70)+1) -> a b | BM43: Integer | BP43: =",`"&R43&"` "&AC43&" "&IF(AJ43="Y","NOT NULL","")&" COMMENT '"&D43&"'" -> ,`MNL_PRC_LVL` smallint COMMENT '手入力価格変更フラグ' | BR43: =",`"&R43&"` "&AC43&" "&IF(AJ43="Y","NOT NULL","") -> ,`MNL_PRC_LVL` smallint | BT43: =",`"&R43&"`" -> ,`MNL_PRC_LVL` | BV43: =",A.`"&R43&"` = B.`"&R43&"`" -> ,A.`MNL_PRC_LVL` = B.`MNL_PRC_LVL` | BX43: =",`"&R43&"`" -> ,`MNL_PRC_LVL` | BZ43: =",`"&R43&"`" -> ,`MNL_PRC_LVL`
A44: @19 | B44: 9 | D44: 商品特定フラグ | R44: SRLZD_MDSE_FG | AC44: {=_xlfn.SWITCH(BM44,"String","varchar("&BN44&")","Long","int","Integer","smallint","Double","decimal(9,2)","Currency","int")} -> smallint | AT44: 現在未使用 ０固定 | BL44: =REPT("a"&CHAR(10)&"b",INT(LENB(SUBSTITUTE(AT44,CHAR(10),""))/70)+1) -> a b | BM44: Integer | BP44: =",`"&R44&"` "&AC44&" "&IF(AJ44="Y","NOT NULL","")&" COMMENT '"&D44&"'" -> ,`SRLZD_MDSE_FG` smallint COMMENT '商品特定フラグ' | BR44: =",`"&R44&"` "&AC44&" "&IF(AJ44="Y","NOT NULL","") -> ,`SRLZD_MDSE_FG` smallint | BT44: =",`"&R44&"`" -> ,`SRLZD_MDSE_FG` | BV44: =",A.`"&R44&"` = B.`"&R44&"`" -> ,A.`SRLZD_MDSE_FG` = B.`SRLZD_MDSE_FG` | BX44: =",`"&R44&"`" -> ,`SRLZD_MDSE_FG` | BZ44: =",`"&R44&"`" -> ,`SRLZD_MDSE_FG`
A45: @20 | B45: 9 | D45: フードスタンプ対象 | R45: FD_STMP_FG | AC45: {=_xlfn.SWITCH(BM45,"String","varchar("&BN45&")","Long","int","Integer","smallint","Double","decimal(9,2)","Currency","int")} -> smallint | AT45: 現在未使用 ０固定 | BL45: =REPT("a"&CHAR(10)&"b",INT(LENB(SUBSTITUTE(AT45,CHAR(10),""))/70)+1) -> a b | BM45: Integer | BP45: =",`"&R45&"` "&AC45&" "&IF(AJ45="Y","NOT NULL","")&" COMMENT '"&D45&"'" -> ,`FD_STMP_FG` smallint COMMENT 'フードスタンプ対象' | BR45: =",`"&R45&"` "&AC45&" "&IF(AJ45="Y","NOT NULL","") -> ,`FD_STMP_FG` smallint | BT45: =",`"&R45&"`" -> ,`FD_STMP_FG` | BV45: =",A.`"&R45&"` = B.`"&R45&"`" -> ,A.`FD_STMP_FG` = B.`FD_STMP_FG` | BX45: =",`"&R45&"`" -> ,`FD_STMP_FG` | BZ45: =",`"&R45&"`" -> ,`FD_STMP_FG`
A46: @21 | B46: 9 | D46: ＷＩＣ有効商品フラグ | R46: WIC_FG | AC46: {=_xlfn.SWITCH(BM46,"String","varchar("&BN46&")","Long","int","Integer","smallint","Double","decimal(9,2)","Currency","int")} -> smallint | AT46: 現在未使用 ０固定 | BL46: =REPT("a"&CHAR(10)&"b",INT(LENB(SUBSTITUTE(AT46,CHAR(10),""))/70)+1) -> a b | BM46: Integer | BP46: =",`"&R46&"` "&AC46&" "&IF(AJ46="Y","NOT NULL","")&" COMMENT '"&D46&"'" -> ,`WIC_FG` smallint COMMENT 'ＷＩＣ有効商品フラグ' | BR46: =",`"&R46&"` "&AC46&" "&IF(AJ46="Y","NOT NULL","") -> ,`WIC_FG` smallint | BT46: =",`"&R46&"`" -> ,`WIC_FG` | BV46: =",A.`"&R46&"` = B.`"&R46&"`" -> ,A.`WIC_FG` = B.`WIC_FG` | BX46: =",`"&R46&"`" -> ,`WIC_FG` | BZ46: =",`"&R46&"`" -> ,`WIC_FG`
A47: @22 | B47: 9 | D47: 在庫コード | R47: PERPET_INV_CD | AC47: {=_xlfn.SWITCH(BM47,"String","varchar("&BN47&")","Long","int","Integer","smallint","Double","decimal(9,2)","Currency","int")} -> smallint | AT47: 現在未使用 ０固定 | BL47: =REPT("a"&CHAR(10)&"b",INT(LENB(SUBSTITUTE(AT47,CHAR(10),""))/70)+1) -> a b | BM47: Integer | BP47: =",`"&R47&"` "&AC47&" "&IF(AJ47="Y","NOT NULL","")&" COMMENT '"&D47&"'" -> ,`PERPET_INV_CD` smallint COMMENT '在庫コード' | BR47: =",`"&R47&"` "&AC47&" "&IF(AJ47="Y","NOT NULL","") -> ,`PERPET_INV_CD` smallint | BT47: =",`"&R47&"`" -> ,`PERPET_INV_CD` | BV47: =",A.`"&R47&"` = B.`"&R47&"`" -> ,A.`PERPET_INV_CD` = B.`PERPET_INV_CD` | BX47: =",`"&R47&"`" -> ,`PERPET_INV_CD` | BZ47: =",`"&R47&"`" -> ,`PERPET_INV_CD`
A48: @23 | B48: 9 | D48: 売価 | R48: RTL_PRC NV_CD | AC48: {=_xlfn.SWITCH(BM48,"String","varchar("&BN48&")","Long","int","Integer","smallint","Double","decimal(9,2)","Currency","int")} -> int | BL48: =REPT("a"&CHAR(10)&"b",INT(LENB(SUBSTITUTE(AT48,CHAR(10),""))/70)+1) -> a b | BM48: Currency | BP48: =",`"&R48&"` "&AC48&" "&IF(AJ48="Y","NOT NULL","")&" COMMENT '"&D48&"'" -> ,`RTL_PRC NV_CD` int COMMENT '売価' | BR48: =",`"&R48&"` "&AC48&" "&IF(AJ48="Y","NOT NULL","") -> ,`RTL_PRC NV_CD` int | BT48: =",`"&R48&"`" -> ,`RTL_PRC NV_CD` | BV48: =",A.`"&R48&"` = B.`"&R48&"`" -> ,A.`RTL_PRC NV_CD` = B.`RTL_PRC NV_CD` | BX48: =",`"&R48&"`" -> ,`RTL_PRC NV_CD` | BZ48: =",`"&R48&"`" -> ,`RTL_PRC NV_CD`
A49: @24 | B49: 9 | D49: 単位原価 | R49: UNT_CST | AC49: {=_xlfn.SWITCH(BM49,"String","varchar("&BN49&")","Long","int","Integer","smallint","Double","decimal(9,2)","Currency","int")} -> decimal(9,2) | AT49: 商品の原価を設定する。少数第２位まで可 | BL49: =REPT("a"&CHAR(10)&"b",INT(LENB(SUBSTITUTE(AT49,CHAR(10),""))/70)+1) -> a b | BM49: Double | BP49: =",`"&R49&"` "&AC49&" "&IF(AJ49="Y","NOT NULL","")&" COMMENT '"&D49&"'" -> ,`UNT_CST` decimal(9,2) COMMENT '単位原価' | BR49: =",`"&R49&"` "&AC49&" "&IF(AJ49="Y","NOT NULL","") -> ,`UNT_CST` decimal(9,2) | BT49: =",`"&R49&"`" -> ,`UNT_CST` | BV49: =",A.`"&R49&"` = B.`"&R49&"`" -> ,A.`UNT_CST` = B.`UNT_CST` | BX49: =",`"&R49&"`" -> ,`UNT_CST` | BZ49: =",`"&R49&"`" -> ,`UNT_CST`
A50: @25 | B50: 9 | D50: 最低取引額 | R50: MIN_MDSE_AMT | AC50: {=_xlfn.SWITCH(BM50,"String","varchar("&BN50&")","Long","int","Integer","smallint","Double","decimal(9,2)","Currency","int")} -> int | AT50: 現在未使用 ０固定 | BL50: =REPT("a"&CHAR(10)&"b",INT(LENB(SUBSTITUTE(AT50,CHAR(10),""))/70)+1) -> a b | BM50: Currency | BP50: =",`"&R50&"` "&AC50&" "&IF(AJ50="Y","NOT NULL","")&" COMMENT '"&D50&"'" -> ,`MIN_MDSE_AMT` int COMMENT '最低取引額' | BR50: =",`"&R50&"` "&AC50&" "&IF(AJ50="Y","NOT NULL","") -> ,`MIN_MDSE_AMT` int | BT50: =",`"&R50&"`" -> ,`MIN_MDSE_AMT` | BV50: =",A.`"&R50&"` = B.`"&R50&"`" -> ,A.`MIN_MDSE_AMT` = B.`MIN_MDSE_AMT` | BX50: =",`"&R50&"`" -> ,`MIN_MDSE_AMT` | BZ50: =",`"&R50&"`" -> ,`MIN_MDSE_AMT`
...

Sheet 特売メンテ
A1: システム名 | K1: システム種別 | W1: =IF(表紙!W1="","",表紙!W1) -> DB定義書 | AP1: 作成者 | AT1: 作成日 | AY1: 更新者 | BC1: 更新日 | BH1: 版数
A2: =IF(表紙!A2="","",表紙!A2) -> 現金専用簡易セルフPOS | K2: =IF(表紙!K2="","",表紙!K2) | AP2: =IF(表紙!AP2="","",表紙!AP2) -> きよはら | AT2: =IF(表紙!AT2="","",表紙!AT2) -> 44652 | AY2: =IF(表紙!AY2="","",表紙!AY2) -> Thanh Nguyên | BC2: =IF(表紙!BC2="","",表紙!BC2) -> 45285 | BH2: =IF(表紙!BH2="","",表紙!BH2) -> 0.2
A4: 機能カテゴリ | H4: =IF(表紙!H4="","",表紙!H4) -> 共通 | U4: 項目 | Z4: =IF(表紙!Z4="","",表紙!Z4) | AP4: テンプレート
B7: ■テーブル情報
B8: スキーマ名 | G8: Replica_Kasumi | Y8: RDBMS名
B9: 論理名 | G9: 特売メンテ | Y9: バージョン
B10: 物理名 | G10: GHDISCOUNTM
B11: 備考
B19: ■カラム情報 | BP19: ="DROP TABLE IF EXISTS `"&$G$8&"`.`"&$G$10&"`;" -> DROP TABLE IF EXISTS `Replica_Kasumi`.`GHDISCOUNTM`; | BQ19: DROP TABLE IF EXISTS `Replica_Kasumi`.`GHDISCOUNTM`;
B20: No. | D20: 論理名 | R20: 物理名 | AC20: データ型 | AH20: PK | AJ20: Not Null | AM20: デフォルト | AT20: 備考 | BP20: ="CREATE TABLE `"&$G$8&"`.`"&$G$10&"` (" -> CREATE TABLE `Replica_Kasumi`.`GHDISCOUNTM` ( | BQ20: CREATE TABLE `Replica_Kasumi`.`ghdiscountm` (
B21: 1 | D21: レコードID | R21: RECORD_ID | AC21: bigint | AJ21: Y | AM21: 自動追加 | BP21: `RECORD_ID` bigint NOT NULL AUTO_INCREMENT COMMENT 'レコードID' | BQ21: `RECORD_ID` bigint NOT NULL AUTO_INCREMENT COMMENT 'レコードID',
B22: =B21+1 -> 2 | D22: レコード作成日付 | R22: RECORD_CREATE_DATE | AC22: date | AJ22: Y | AM22: CURRENT_DATE | BP22: ,`RECORD_CREATE_DATE` date NOT NULL COMMENT 'レコード作成日付' | BQ22: `RECORD_CREATE_DATE` date NOT NULL COMMENT 'レコード作成日付',
B23: =B22+1 -> 3 | D23: レコード作成時間 | R23: RECORD_CREATE_TIME | AC23: time | AJ23: Y | AM23: CURRENT_TIME | BP23: ,`RECORD_CREATE_TIME` time NOT NULL COMMENT 'レコード作成時間' | BQ23: `RECORD_CREATE_TIME` time NOT NULL COMMENT 'レコード作成時間', | BV23: SET CHARACTER_SET_DATABASE = UTF8;
B24: =B23+1 -> 4 | D24: レコード更新日付 | R24: RECORD_UPDATE_DATE | AC24: date | AJ24: Y | AM24: CURRENT_DATE | AT24: トリガーにより更新 | BP24: ,`RECORD_UPDATE_DATE` date NOT NULL COMMENT 'レコード更新日付/トリガーにより更新' | BQ24: `RECORD_UPDATE_DATE` date NOT NULL COMMENT 'レコード更新日付/トリガーにより更新', | BV24: ="UPDATE `REPLICA_KASUMI`.`"&$G$10&"` A,`TMP`.`"&$G$10&"` B" -> UPDATE `REPLICA_KASUMI`.`GHDISCOUNTM` A,`TMP`.`GHDISCOUNTM` B
B25: =B24+1 -> 5 | D25: レコード更新時間 | R25: RECORD_UPDATE_TIME | AC25: time | AJ25: Y | AM25: CURRENT_TIME | AT25: トリガーにより更新 | BP25: ,`RECORD_UPDATE_TIME` time NOT NULL COMMENT 'レコード更新時間/トリガーにより更新' | BQ25: `RECORD_UPDATE_TIME` time NOT NULL COMMENT 'レコード更新時間/トリガーにより更新', | BR25: ="DROP TABLE IF EXISTS `TMP`.`"&$G$10&"`;" -> DROP TABLE IF EXISTS `TMP`.`GHDISCOUNTM`; | BT25: ="LOAD DATA INFILE 'C:/04_DATAFILE/"&$G$10&"/TMP/"&$G$10&".CSV' " -> LOAD DATA INFILE 'C:/04_DATAFILE/GHDISCOUNTM/TMP/GHDISCOUNTM.CSV' | BV25: SET
A26: @1 | B26: =B25+1 -> 6 | D26: レコード無効フラグ | R26: RECORD_VOID_FLAG | AC26: char(1) | AJ26: Y | AM26: "" | AT26: 0: 有効フラグ、 1:無効フラグ | BP26: ,`RECORD_VOID_FLAG` char(1) NOT NULL DEFAULT '' COMMENT 'レコード無効フラグ '''': 有効フラグ、 1:無効フラグ' | BQ26: `RECORD_VOID_FLAG` char(1) NOT NULL DEFAULT '' COMMENT 'レコード無効フラグ '''': 有効フラグ、 1:無効フラグ', | BR26: ="CREATE TABLE `TMP`.`"&G10&"` (" -> CREATE TABLE `TMP`.`GHDISCOUNTM` ( | BT26: ="REPLACE INTO TABLE TMP.`"&$G$10&"` FIELDS TERMINATED BY ',' ENCLOSED BY '\""' LINES TERMINATED BY '\r\n' (" -> REPLACE INTO TABLE TMP.`GHDISCOUNTM` FIELDS TERMINATED BY ',' ENCLOSED BY '\"' LINES TERMINATED BY '\r\n' ( | BX26: ="INSERT INTO `REPLICA_KASUMI`.`"&$G$10&"` (" -> INSERT INTO `REPLICA_KASUMI`.`GHDISCOUNTM` ( | BZ26: ) SELECT
A27: @2 | B27: 7 | D27: 処理区分 | R27: PRCS_TYP | AC27: {=_xlfn.SWITCH(BM27,"String","varchar("&BN27&")","Long","int","Integer","smallint","Double","decimal(9,2)","Currency","int")} -> varchar(1) | AT27: Ａ：登録 Ｕ：更新 Ｄ：削除 | BM27: String | BN27: 1 | BP27: =",`"&R27&"` "&AC27&" "&IF(AJ27="Y","NOT NULL","")&" COMMENT '"&D27&" "&AT27&"'" -> ,`PRCS_TYP` varchar(1) COMMENT '処理区分 Ａ：登録 Ｕ：更新 Ｄ：削除' | BQ27: `PRCS_TYP` varchar(1) DEFAULT NULL COMMENT '処理区分 Ａ：登録 Ｕ：更新 Ｄ：削除', | BR27: ="`"&R27&"` "&AC27&" "&IF(AJ27="Y","NOT NULL","") -> `PRCS_TYP` varchar(1) | BT27: ="`"&R27&"`" -> `PRCS_TYP` | BV27: ="A.`"&R27&"` = B.`"&R27&"`" -> A.`PRCS_TYP` = B.`PRCS_TYP` | BX27: ="`"&R27&"`" -> `PRCS_TYP` | BZ27: ="`"&R27&"`" -> `PRCS_TYP`
A28: @3 | B28: 8 | D28: 店舗コード | R28: STR_ID | AC28: {=_xlfn.SWITCH(BM28,"String","varchar("&BN28&")","Long","int","Integer","smallint","Double","decimal(9,2)","Currency","int")} -> int | AH28: 1 | AT28: ０は不可 | BM28: Long | BP28: =",`"&R28&"` "&AC28&" "&IF(AJ28="Y","NOT NULL","")&" COMMENT '"&D28&" "&AT28&"'" -> ,`STR_ID` int COMMENT '店舗コード ０は不可' | BQ28: `STR_ID` int NOT NULL COMMENT '店舗コード ０は不可', | BR28: =",`"&R28&"` "&AC28&" "&IF(AJ28="Y","NOT NULL","") -> ,`STR_ID` int | BT28: =",`"&R28&"`" -> ,`STR_ID` | BV28: =",A.`"&R28&"` = B.`"&R28&"`" -> ,A.`STR_ID` = B.`STR_ID` | BX28: =",`"&R28&"`" -> ,`STR_ID` | BZ28: =",`"&R28&"`" -> ,`STR_ID`
A29: @4 | B29: 9 | D29: 企画Ｎo． | R29: EVNT_NBR | AC29: {=_xlfn.SWITCH(BM29,"String","varchar("&BN29&")","Long","int","Integer","smallint","Double","decimal(9,2)","Currency","int")} -> varchar(7) | AH29: 2 | AT29: 左詰 企画マスタに存在すること | BM29: String | BN29: 7 | BP29: =",`"&R29&"` "&AC29&" "&IF(AJ29="Y","NOT NULL","")&" COMMENT '"&D29&" "&AT29&"'" -> ,`EVNT_NBR` varchar(7) COMMENT '企画Ｎo． 左詰 企画マスタに存在すること' | BQ29: `EVNT_NBR` varchar(7) CHARACTER SET utf8mb4 COLLATE utf8mb4_0900_ai_ci NOT NULL COMMENT '企画Ｎo． 左詰 企画マスタに存在すること', | BR29: =",`"&R29&"` "&AC29&" "&IF(AJ29="Y","NOT NULL","") -> ,`EVNT_NBR` varchar(7) | BT29: =",`"&R29&"`" -> ,`EVNT_NBR` | BV29: =",A.`"&R29&"` = B.`"&R29&"`" -> ,A.`EVNT_NBR` = B.`EVNT_NBR` | BX29: =",`"&R29&"`" -> ,`EVNT_NBR` | BZ29: =",`"&R29&"`" -> ,`EVNT_NBR`
A30: @5 | B30: 9 | D30: 会員フラグ | R30: MBR_FG | AC30: {=_xlfn.SWITCH(BM30,"String","varchar("&BN30&")","Long","int","Integer","smallint","Double","decimal(9,2)","Currency","int")} -> smallint | AH30: 6 | AT30: ０：一般特売 １：会員特売 | BM30: Integer | BP30: =",`"&R30&"` "&AC30&" "&IF(AJ30="Y","NOT NULL","")&" COMMENT '"&D30&" "&AT30&"'" -> ,`MBR_FG` smallint COMMENT '会員フラグ ０：一般特売 １：会員特売' | BQ30: `MBR_FG` smallint NOT NULL COMMENT '会員フラグ ０：一般特売 １：会員特売', | BR30: =",`"&R30&"` "&AC30&" "&IF(AJ30="Y","NOT NULL","") -> ,`MBR_FG` smallint | BT30: =",`"&R30&"`" -> ,`MBR_FG` | BV30: =",A.`"&R30&"` = B.`"&R30&"`" -> ,A.`MBR_FG` = B.`MBR_FG` | BX30: =",`"&R30&"`" -> ,`MBR_FG` | BZ30: =",`"&R30&"`" -> ,`MBR_FG`
A31: @6 | B31: 9 | D31: 商品コード | R31: PLU_ID | AC31: {=_xlfn.SWITCH(BM31,"String","varchar("&BN31&")","Long","int","Integer","smallint","Double","decimal(9,2)","Currency","int")} -> varchar(24) | AH31: 5 | AT31: 左詰 数字で最大19桁。 特にＰＬＵコードを使用しない場合はスキャンコードと同じ値を入れておくこと | BM31: String | BN31: 24 | BP31: =",`"&R31&"` "&AC31&" "&IF(AJ31="Y","NOT NULL","")&" COMMENT '"&D31&" "&AT31&"'" -> ,`PLU_ID` varchar(24) COMMENT '商品コード 左詰 数字で最大19桁。 特にＰＬＵコードを使用しない場合はスキャンコードと同じ値を入れておくこと' | BQ31: `PLU_ID` varchar(24) CHARACTER SET utf8mb4 COLLATE utf8mb4_0900_ai_ci NOT NULL COMMENT '商品コード 左詰 数字で最大19桁。 特にＰＬＵコードを使用しない場合はスキャンコードと同じ値を入れておくこと', | BR31: =",`"&R31&"` "&AC31&" "&IF(AJ31="Y","NOT NULL","") -> ,`PLU_ID` varchar(24) | BT31: =",`"&R31&"`" -> ,`PLU_ID` | BV31: =",A.`"&R31&"` = B.`"&R31&"`" -> ,A.`PLU_ID` = B.`PLU_ID` | BX31: =",`"&R31&"`" -> ,`PLU_ID` | BZ31: =",`"&R31&"`" -> ,`PLU_ID`
A32: @7 | B32: 9 | D32: 特売開始日 | R32: EVNT_BGN_TM | AC32: {=_xlfn.SWITCH(BM32,"String","varchar("&BN32&")","Long","int","Integer","smallint","Double","decimal(9,2)","Currency","int")} -> varchar(8) | AH32: 3 | AT32: ＹＹＹＹＭＭＤＤ形式で８桁フルに設定すること | BM32: String | BN32: 8 | BP32: =",`"&R32&"` "&AC32&" "&IF(AJ32="Y","NOT NULL","")&" COMMENT '"&D32&" "&AT32&"'" -> ,`EVNT_BGN_TM` varchar(8) COMMENT '特売開始日 ＹＹＹＹＭＭＤＤ形式で８桁フルに設定すること' | BQ32: `EVNT_BGN_TM` varchar(8) CHARACTER SET utf8mb4 COLLATE utf8mb4_0900_ai_ci NOT NULL COMMENT '特売開始日 ＹＹＹＹＭＭＤＤ形式で８桁フルに設定すること', | BR32: =",`"&R32&"` "&AC32&" "&IF(AJ32="Y","NOT NULL","") -> ,`EVNT_BGN_TM` varchar(8) | BT32: =",`"&R32&"`" -> ,`EVNT_BGN_TM` | BV32: =",A.`"&R32&"` = B.`"&R32&"`" -> ,A.`EVNT_BGN_TM` = B.`EVNT_BGN_TM` | BX32: =",`"&R32&"`" -> ,`EVNT_BGN_TM` | BZ32: =",`"&R32&"`" -> ,`EVNT_BGN_TM`
A33: @8 | B33: 9 | D33: 特売終了日 | R33: EVNT_END_TM | AC33: {=_xlfn.SWITCH(BM33,"String","varchar("&BN33&")","Long","int","Integer","smallint","Double","decimal(9,2)","Currency","int")} -> varchar(8) | AH33: 4 | AT33: ＹＹＹＹＭＭＤＤ形式で８桁フルに設定すること | BM33: String | BN33: 8 | BP33: =",`"&R33&"` "&AC33&" "&IF(AJ33="Y","NOT NULL","")&" COMMENT '"&D33&" "&AT33&"'" -> ,`EVNT_END_TM` varchar(8) COMMENT '特売終了日 ＹＹＹＹＭＭＤＤ形式で８桁フルに設定すること' | BQ33: `EVNT_END_TM` varchar(8) CHARACTER SET utf8mb4 COLLATE utf8mb4_0900_ai_ci NOT NULL COMMENT '特売終了日 ＹＹＹＹＭＭＤＤ形式で８桁フルに設定すること', | BR33: =",`"&R33&"` "&AC33&" "&IF(AJ33="Y","NOT NULL","") -> ,`EVNT_END_TM` varchar(8) | BT33: =",`"&R33&"`" -> ,`EVNT_END_TM` | BV33: =",A.`"&R33&"` = B.`"&R33&"`" -> ,A.`EVNT_END_TM` = B.`EVNT_END_TM` | BX33: =",`"&R33&"`" -> ,`EVNT_END_TM` | BZ33: =",`"&R33&"`" -> ,`EVNT_END_TM`
A34: @9 | B34: 9 | D34: 特売削除日数 | R34: EVNT_HLDL_DY | AC34: {=_xlfn.SWITCH(BM34,"String","varchar("&BN34&")","Long","int","Integer","smallint","Double","decimal(9,2)","Currency","int")} -> varchar(3) | AT34: 期間終了後の削除猶予期間 ００２－０９９ 未使用時はＮＵＬＬ | BM34: String | BN34: 3 | BP34: =",`"&R34&"` "&AC34&" "&IF(AJ34="Y","NOT NULL","")&" COMMENT '"&D34&" "&AT34&"'" -> ,`EVNT_HLDL_DY` varchar(3) COMMENT '特売削除日数 期間終了後の削除猶予期間 ００２－０９９ 未使用時はＮＵＬＬ' | BQ34: `EVNT_HLDL_DY` varchar(3) DEFAULT NULL COMMENT '特売削除日数 期間終了後の削除猶予期間 ００２－０９９ 未使用時はＮＵＬＬ', | BR34: =",`"&R34&"` "&AC34&" "&IF(AJ34="Y","NOT NULL","") -> ,`EVNT_HLDL_DY` varchar(3) | BT34: =",`"&R34&"`" -> ,`EVNT_HLDL_DY` | BV34: =",A.`"&R34&"` = B.`"&R34&"`" -> ,A.`EVNT_HLDL_DY` = B.`EVNT_HLDL_DY` | BX34: =",`"&R34&"`" -> ,`EVNT_HLDL_DY` | BZ34: =",`"&R34&"`" -> ,`EVNT_HLDL_DY`
A35: @10 | B35: 9 | D35: 特売優先区分 | R35: EVNT_SRC | AC35: {=_xlfn.SWITCH(BM35,"String","varchar("&BN35&")","Long","int","Integer","smallint","Double","decimal(9,2)","Currency","int")} -> smallint | AT35: 現在１固定 ０：店舗優先 １：本部優先 | BM35: Integer | BP35: =",`"&R35&"` "&AC35&" "&IF(AJ35="Y","NOT NULL","")&" COMMENT '"&D35&" "&AT35&"'" -> ,`EVNT_SRC` smallint COMMENT '特売優先区分 現在１固定 ０：店舗優先 １：本部優先' | BQ35: `EVNT_SRC` smallint DEFAULT NULL COMMENT '特売優先区分 現在１固定 ０：店舗優先 １：本部優先', | BR35: =",`"&R35&"` "&AC35&" "&IF(AJ35="Y","NOT NULL","") -> ,`EVNT_SRC` smallint | BT35: =",`"&R35&"`" -> ,`EVNT_SRC` | BV35: =",A.`"&R35&"` = B.`"&R35&"`" -> ,A.`EVNT_SRC` = B.`EVNT_SRC` | BX35: =",`"&R35&"`" -> ,`EVNT_SRC` | BZ35: =",`"&R35&"`" -> ,`EVNT_SRC`
A36: @11 | B36: 9 | D36: 特売保留フラグ | R36: EVNT_EXCL_FG | AC36: {=_xlfn.SWITCH(BM36,"String","varchar("&BN36&")","Long","int","Integer","smallint","Double","decimal(9,2)","Currency","int")} -> smallint | AT36: ０：保留しない １：保留する | BM36: Integer | BP36: =",`"&R36&"` "&AC36&" "&IF(AJ36="Y","NOT NULL","")&" COMMENT '"&D36&" "&AT36&"'" -> ,`EVNT_EXCL_FG` smallint COMMENT '特売保留フラグ ０：保留しない １：保留する' | BQ36: `EVNT_EXCL_FG` smallint DEFAULT NULL COMMENT '特売保留フラグ ０：保留しない １：保留する', | BR36: =",`"&R36&"` "&AC36&" "&IF(AJ36="Y","NOT NULL","") -> ,`EVNT_EXCL_FG` smallint | BT36: =",`"&R36&"`" -> ,`EVNT_EXCL_FG` | BV36: =",A.`"&R36&"` = B.`"&R36&"`" -> ,A.`EVNT_EXCL_FG` = B.`EVNT_EXCL_FG` | BX36: =",`"&R36&"`" -> ,`EVNT_EXCL_FG` | BZ36: =",`"&R36&"`" -> ,`EVNT_EXCL_FG`
A37: @12 | B37: 9 | D37: タイムサービスフラグ | R37: TIME_SERVICE_FG | AC37: {=_xlfn.SWITCH(BM37,"String","varchar("&BN37&")","Long","int","Integer","smallint","Double","decimal(9,2)","Currency","int")} -> smallint | AT37: ０：期間 １：期間＆曜日 ２：期間＆時間 ３：期間＆時間＆曜日 | BM37: Integer | BP37: =",`"&R37&"` "&AC37&" "&IF(AJ37="Y","NOT NULL","")&" COMMENT '"&D37&" "&AT37&"'" -> ,`TIME_SERVICE_FG` smallint COMMENT 'タイムサービスフラグ ０：期間 １：期間＆曜日 ２：期間＆時間 ３：期間＆時間＆曜日' | BQ37: `TIME_SERVICE_FG` smallint DEFAULT NULL COMMENT 'タイムサービスフラグ ０：期間 １：期間＆曜日 ２：期間＆時間 ３：期間＆時間＆曜日', | BR37: =",`"&R37&"` "&AC37&" "&IF(AJ37="Y","NOT NULL","") -> ,`TIME_SERVICE_FG` smallint | BT37: =",`"&R37&"`" -> ,`TIME_SERVICE_FG` | BV37: =",A.`"&R37&"` = B.`"&R37&"`" -> ,A.`TIME_SERVICE_FG` = B.`TIME_SERVICE_FG` | BX37: =",`"&R37&"`" -> ,`TIME_SERVICE_FG` | BZ37: =",`"&R37&"`" -> ,`TIME_SERVICE_FG`
A38: @13 | B38: 9 | D38: 月曜日除外フラグ | R38: MON_EXCL_FG | AC38: {=_xlfn.SWITCH(BM38,"String","varchar("&BN38&")","Long","int","Integer","smallint","Double","decimal(9,2)","Currency","int")} -> smallint | AT38: ０：除外しない １：除外する | BM38: Integer | BP38: =",`"&R38&"` "&AC38&" "&IF(AJ38="Y","NOT NULL","")&" COMMENT '"&D38&" "&AT38&"'" -> ,`MON_EXCL_FG` smallint COMMENT '月曜日除外フラグ ０：除外しない １：除外する' | BQ38: `MON_EXCL_FG` smallint DEFAULT NULL COMMENT '月曜日除外フラグ ０：除外しない １：除外する', | BR38: =",`"&R38&"` "&AC38&" "&IF(AJ38="Y","NOT NULL","") -> ,`MON_EXCL_FG` smallint | BT38: =",`"&R38&"`" -> ,`MON_EXCL_FG` | BV38: =",A.`"&R38&"` = B.`"&R38&"`" -> ,A.`MON_EXCL_FG` = B.`MON_EXCL_FG` | BX38: =",`"&R38&"`" -> ,`MON_EXCL_FG` | BZ38: =",`"&R38&"`" -> ,`MON_EXCL_FG`
A39: @14 | B39: 9 | D39: 火曜日除外フラグ | R39: TUES_EXCL_FG | AC39: {=_xlfn.SWITCH(BM39,"String","varchar("&BN39&")","Long","int","Integer","smallint","Double","decimal(9,2)","Currency","int")} -> smallint | AT39: ０：除外しない １：除外する | BM39: Integer | BP39: =",`"&R39&"` "&AC39&" "&IF(AJ39="Y","NOT NULL","")&" COMMENT '"&D39&" "&AT39&"'" -> ,`TUES_EXCL_FG` smallint COMMENT '火曜日除外フラグ ０：除外しない １：除外する' | BQ39: `TUES_EXCL_FG` smallint DEFAULT NULL COMMENT '火曜日除外フラグ ０：除外しない １：除外する', | BR39: =",`"&R39&"` "&AC39&" "&IF(AJ39="Y","NOT NULL","") -> ,`TUES_EXCL_FG` smallint | BT39: =",`"&R39&"`" -> ,`TUES_EXCL_FG` | BV39: =",A.`"&R39&"` = B.`"&R39&"`" -> ,A.`TUES_EXCL_FG` = B.`TUES_EXCL_FG` | BX39: =",`"&R39&"`" -> ,`TUES_EXCL_FG` | BZ39: =",`"&R39&"`" -> ,`TUES_EXCL_FG`
A40: @15 | B40: 9 | D40: 水曜日除外フラグ | R40: WED_EXCL_FG | AC40: {=_xlfn.SWITCH(BM40,"String","varchar("&BN40&")","Long","int","Integer","smallint","Double","decimal(9,2)","Currency","int")} -> smallint | AT40: ０：除外しない １：除外する | BM40: Integer | BP40: =",`"&R40&"` "&AC40&" "&IF(AJ40="Y","NOT NULL","")&" COMMENT '"&D40&" "&AT40&"'" -> ,`WED_EXCL_FG` smallint COMMENT '水曜日除外フラグ ０：除外しない １：除外する' | BQ40: `WED_EXCL_FG` smallint DEFAULT NULL COMMENT '水曜日除外フラグ ０：除外しない １：除外する', | BR40: =",`"&R40&"` "&AC40&" "&IF(AJ40="Y","NOT NULL","") -> ,`WED_EXCL_FG` smallint | BT40: =",`"&R40&"`" -> ,`WED_EXCL_FG` | BV40: =",A.`"&R40&"` = B.`"&R40&"`" -> ,A.`WED_EXCL_FG` = B.`WED_EXCL_FG` | BX40: =",`"&R40&"`" -> ,`WED_EXCL_FG` | BZ40: =",`"&R40&"`" -> ,`WED_EXCL_FG`
A41: @16 | B41: 9 | D41: 木曜日除外フラグ | R41: THUS_EXCL_FG | AC41: {=_xlfn.SWITCH(BM41,"String","varchar("&BN41&")","Long","int","Integer","smallint","Double","decimal(9,2)","Currency","int")} -> smallint | AT41: ０：除外しない １：除外する | BM41: Integer | BP41: =",`"&R41&"` "&AC41&" "&IF(AJ41="Y","NOT NULL","")&" COMMENT '"&D41&" "&AT41&"'" -> ,`THUS_EXCL_FG` smallint COMMENT '木曜日除外フラグ ０：除外しない １：除外する' | BQ41: `THUS_EXCL_FG` smallint DEFAULT NULL COMMENT '木曜日除外フラグ ０：除外しない １：除外する', | BR41: =",`"&R41&"` "&AC41&" "&IF(AJ41="Y","NOT NULL","") -> ,`THUS_EXCL_FG` smallint | BT41: =",`"&R41&"`" -> ,`THUS_EXCL_FG` | BV41: =",A.`"&R41&"` = B.`"&R41&"`" -> ,A.`THUS_EXCL_FG` = B.`THUS_EXCL_FG` | BX41: =",`"&R41&"`" -> ,`THUS_EXCL_FG` | BZ41: =",`"&R41&"`" -> ,`THUS_EXCL_FG`
A42: @17 | B42: 9 | D42: 金曜日除外フラグ | R42: FRI_EXCL_FG | AC42: {=_xlfn.SWITCH(BM42,"String","varchar("&BN42&")","Long","int","Integer","smallint","Double","decimal(9,2)","Currency","int")} -> smallint | AT42: ０：除外しない １：除外する | BM42: Integer | BP42: =",`"&R42&"` "&AC42&" "&IF(AJ42="Y","NOT NULL","")&" COMMENT '"&D42&" "&AT42&"'" -> ,`FRI_EXCL_FG` smallint COMMENT '金曜日除外フラグ ０：除外しない １：除外する' | BQ42: `FRI_EXCL_FG` smallint DEFAULT NULL COMMENT '金曜日除外フラグ ０：除外しない １：除外する', | BR42: =",`"&R42&"` "&AC42&" "&IF(AJ42="Y","NOT NULL","") -> ,`FRI_EXCL_FG` smallint | BT42: =",`"&R42&"`" -> ,`FRI_EXCL_FG` | BV42: =",A.`"&R42&"` = B.`"&R42&"`" -> ,A.`FRI_EXCL_FG` = B.`FRI_EXCL_FG` | BX42: =",`"&R42&"`" -> ,`FRI_EXCL_FG` | BZ42: =",`"&R42&"`" -> ,`FRI_EXCL_FG`
A43: @18 | B43: 9 | D43: 土曜日除外フラグ | R43: SAT_EXCL_FG | AC43: {=_xlfn.SWITCH(BM43,"String","varchar("&BN43&")","Long","int","Integer","smallint","Double","decimal(9,2)","Currency","int")} -> smallint | AT43: ０：除外しない １：除外する | BM43: Integer | BP43: =",`"&R43&"` "&AC43&" "&IF(AJ43="Y","NOT NULL","")&" COMMENT '"&D43&" "&AT43&"'" -> ,`SAT_EXCL_FG` smallint COMMENT '土曜日除外フラグ ０：除外しない １：除外する' | BQ43: `SAT_EXCL_FG` smallint DEFAULT NULL COMMENT '土曜日除外フラグ ０：除外しない １：除外する', | BR43: =",`"&R43&"` "&AC43&" "&IF(AJ43="Y","NOT NULL","") -> ,`SAT_EXCL_FG` smallint | BT43: =",`"&R43&"`" -> ,`SAT_EXCL_FG` | BV43: =",A.`"&R43&"` = B.`"&R43&"`" -> ,A.`SAT_EXCL_FG` = B.`SAT_EXCL_FG` | BX43: =",`"&R43&"`" -> ,`SAT_EXCL_FG` | BZ43: =",`"&R43&"`" -> ,`SAT_EXCL_FG`
A44: @19 | B44: 9 | D44: 日曜日除外フラグ | R44: SUN_EXCL_FG | AC44: {=_xlfn.SWITCH(BM44,"String","varchar("&BN44&")","Long","int","Integer","smallint","Double","decimal(9,2)","Currency","int")} -> smallint | AT44: ０：除外しない ２：除外する | BM44: Integer | BP44: =",`"&R44&"` "&AC44&" "&IF(AJ44="Y","NOT NULL","")&" COMMENT '"&D44&" "&AT44&"'" -> ,`SUN_EXCL_FG` smallint COMMENT '日曜日除外フラグ ０：除外しない ２：除外する' | BQ44: `SUN_EXCL_FG` smallint DEFAULT NULL COMMENT '日曜日除外フラグ ０：除外しない ２：除外する', | BR44: =",`"&R44&"` "&AC44&" "&IF(AJ44="Y","NOT NULL","") -> ,`SUN_EXCL_FG` smallint | BT44: =",`"&R44&"`" -> ,`SUN_EXCL_FG` | BV44: =",A.`"&R44&"` = B.`"&R44&"`" -> ,A.`SUN_EXCL_FG` = B.`SUN_EXCL_FG` | BX44: =",`"&R44&"`" -> ,`SUN_EXCL_FG` | BZ44: =",`"&R44&"`" -> ,`SUN_EXCL_FG`
A45: @20 | B45: 9 | D45: 特売原価 | R45: PROMO_COST | AC45: {=_xlfn.SWITCH(BM45,"String","varchar("&BN45&")","Long","int","Integer","smallint","Double","decimal(9,2)","Currency","int")} -> int | AT45: ０以上 | BM45: Currency | BP45: =",`"&R45&"` "&AC45&" "&IF(AJ45="Y","NOT NULL","")&" COMMENT '"&D45&" "&AT45&"'" -> ,`PROMO_COST` int COMMENT '特売原価 ０以上' | BQ45: `PROMO_COST` int DEFAULT NULL COMMENT '特売原価 ０以上', | BR45: =",`"&R45&"` "&AC45&" "&IF(AJ45="Y","NOT NULL","") -> ,`PROMO_COST` int | BT45: =",`"&R45&"`" -> ,`PROMO_COST` | BV45: =",A.`"&R45&"` = B.`"&R45&"`" -> ,A.`PROMO_COST` = B.`PROMO_COST` | BX45: =",`"&R45&"`" -> ,`PROMO_COST` | BZ45: =",`"&R45&"`" -> ,`PROMO_COST`
A46: @21 | B46: 9 | D46: 割引タイプ | R46: DISC_MTHD | AC46: {=_xlfn.SWITCH(BM46,"String","varchar("&BN46&")","Long","int","Integer","smallint","Double","decimal(9,2)","Currency","int")} -> smallint | AT46: 現在６固定 １：差額 ２：％（率） ６：金額 | BM46: Integer | BP46: =",`"&R46&"` "&AC46&" "&IF(AJ46="Y","NOT NULL","")&" COMMENT '"&D46&" "&AT46&"'" -> ,`DISC_MTHD` smallint COMMENT '割引タイプ 現在６固定 １：差額 ２：％（率） ６：金額' | BQ46: `DISC_MTHD` smallint DEFAULT NULL COMMENT '割引タイプ 現在６固定 １：差額 ２：％（率） ６：金額', | BR46: =",`"&R46&"` "&AC46&" "&IF(AJ46="Y","NOT NULL","") -> ,`DISC_MTHD` smallint | BT46: =",`"&R46&"`" -> ,`DISC_MTHD` | BV46: =",A.`"&R46&"` = B.`"&R46&"`" -> ,A.`DISC_MTHD` = B.`DISC_MTHD` | BX46: =",`"&R46&"`" -> ,`DISC_MTHD` | BZ46: =",`"&R46&"`" -> ,`DISC_MTHD`
A47: @22 | B47: 9 | D47: 特売価格 | R47: DISC_VALUE | AC47: {=_xlfn.SWITCH(BM47,"String","varchar("&BN47&")","Long","int","Integer","smallint","Double","decimal(9,2)","Currency","int")} -> decimal(9,2) | BM47: Double | BP47: =",`"&R47&"` "&AC47&" "&IF(AJ47="Y","NOT NULL","")&" COMMENT '"&D47&" "&AT47&"'" -> ,`DISC_VALUE` decimal(9,2) COMMENT '特売価格 ' | BQ47: `DISC_VALUE` decimal(9,2) DEFAULT NULL COMMENT '特売価格 ', | BR47: =",`"&R47&"` "&AC47&" "&IF(AJ47="Y","NOT NULL","") -> ,`DISC_VALUE` decimal(9,2) | BT47: =",`"&R47&"`" -> ,`DISC_VALUE` | BV47: =",A.`"&R47&"` = B.`"&R47&"`" -> ,A.`DISC_VALUE` = B.`DISC_VALUE` | BX47: =",`"&R47&"`" -> ,`DISC_VALUE` | BZ47: =",`"&R47&"`" -> ,`DISC_VALUE`
A48: @23 | B48: 9 | D48: 個数制限 | R48: DISC_ITM_LMT | AC48: {=_xlfn.SWITCH(BM48,"String","varchar("&BN48&")","Long","int","Integer","smallint","Double","decimal(9,2)","Currency","int")} -> decimal(9,2) | AT48: 現在未使用 ０固定 | BM48: Double | BP48: =",`"&R48&"` "&AC48&" "&IF(AJ48="Y","NOT NULL","")&" COMMENT '"&D48&" "&AT48&"'" -> ,`DISC_ITM_LMT` decimal(9,2) COMMENT '個数制限 現在未使用 ０固定' | BQ48: `DISC_ITM_LMT` decimal(9,2) DEFAULT NULL COMMENT '個数制限 現在未使用 ０固定', | BR48: =",`"&R48&"` "&AC48&" "&IF(AJ48="Y","NOT NULL","") -> ,`DISC_ITM_LMT` decimal(9,2) | BT48: =",`"&R48&"`" -> ,`DISC_ITM_LMT` | BV48: =",A.`"&R48&"` = B.`"&R48&"`" -> ,A.`DISC_ITM_LMT` = B.`DISC_ITM_LMT` | BX48: =",`"&R48&"`" -> ,`DISC_ITM_LMT` | BZ48: =",`"&R48&"`" -> ,`DISC_ITM_LMT`
A49: @24 | B49: 9 | D49: 特売開始時間 | R49: PROMO_BGN_TM | AC49: {=_xlfn.SWITCH(BM49,"String","varchar("&BN49&")","Long","int","Integer","smallint","Double","decimal(9,2)","Currency","int")} -> varchar(4) | AT49: ＨＨＭＭ形式で４桁フルに設定すること（２４時間制） | BM49: String | BN49: 4 | BP49: =",`"&R49&"` "&AC49&" "&IF(AJ49="Y","NOT NULL","")&" COMMENT '"&D49&" "&AT49&"'" -> ,`PROMO_BGN_TM` varchar(4) COMMENT '特売開始時間 ＨＨＭＭ形式で４桁フルに設定すること（２４時間制）' | BQ49: `PROMO_BGN_TM` varchar(4) DEFAULT NULL COMMENT '特売開始時間 ＨＨＭＭ形式で４桁フルに設定すること（２４時間制）', | BR49: =",`"&R49&"` "&AC49&" "&IF(AJ49="Y","NOT NULL","") -> ,`PROMO_BGN_TM` varchar(4) | BT49: =",`"&R49&"`" -> ,`PROMO_BGN_TM` | BV49: =",A.`"&R49&"` = B.`"&R49&"`" -> ,A.`PROMO_BGN_TM` = B.`PROMO_BGN_TM` | BX49: =",`"&R49&"`" -> ,`PROMO_BGN_TM` | BZ49: =",`"&R49&"`" -> ,`PROMO_BGN_TM`
A50: @25 | B50: 9 | D50: 特売終了時間 | R50: PROMO_END_TM | AC50: {=_xlfn.SWITCH(BM50,"String","varchar("&BN50&")","Long","int","Integer","smallint","Double","decimal(9,2)","Currency","int")} -> varchar(4) | AT50: ＨＨＭＭ形式で４桁フルに設定すること（２４時間制） | BM50: String | BN50: 4 | BP50: =",`"&R50&"` "&AC50&" "&IF(AJ50="Y","NOT NULL","")&" COMMENT '"&D50&" "&AT50&"'" -> ,`PROMO_END_TM` varchar(4) COMMENT '特売終了時間 ＨＨＭＭ形式で４桁フルに設定すること（２４時間制）' | BQ50: `PROMO_END_TM` varchar(4) DEFAULT NULL COMMENT '特売終了時間 ＨＨＭＭ形式で４桁フルに設定すること（２４時間制）', | BR50: =",`"&R50&"` "&AC50&" "&IF(AJ50="Y","NOT NULL","") -> ,`PROMO_END_TM` varchar(4) | BT50: =",`"&R50&"`" -> ,`PROMO_END_TM` | BV50: =",A.`"&R50&"` = B.`"&R50&"`" -> ,A.`PROMO_END_TM` = B.`PROMO_END_TM` | BX50: =",`"&R50&"`" -> ,`PROMO_END_TM` | BZ50: =",`"&R50&"`" -> ,`PROMO_END_TM`
...

Sheet MMマスタ
A1: システム名 | K1: システム種別 | W1: =IF(表紙!W1="","",表紙!W1) -> DB定義書 | AP1: 作成者 | AT1: 作成日 | AY1: 更新者 | BC1: 更新日 | BH1: 版数
A2: =IF(表紙!A2="","",表紙!A2) -> 現金専用簡易セルフPOS | K2: =IF(表紙!K2="","",表紙!K2) | AP2: =IF(表紙!AP2="","",表紙!AP2) -> きよはら | AT2: =IF(表紙!AT2="","",表紙!AT2) -> 44652 | AY2: =IF(表紙!AY2="","",表紙!AY2) -> Thanh Nguyên | BC2: =IF(表紙!BC2="","",表紙!BC2) -> 45285 | BH2: =IF(表紙!BH2="","",表紙!BH2) -> 0.2
A4: 機能カテゴリ | H4: =IF(表紙!H4="","",表紙!H4) -> 共通 | U4: 項目 | Z4: =IF(表紙!Z4="","",表紙!Z4) | AP4: テンプレート
B7: ■テーブル情報
B8: スキーマ名 | G8: Replica_Kasumi | Y8: RDBMS名
B9: 論理名 | G9: MMマスタ | Y9: バージョン
B10: 物理名 | G10: GHBUNDLEM
B11: 備考
B19: ■カラム情報 | BP19: ="DROP TABLE IF EXISTS `"&$G$8&"`.`"&$G$10&"`;" -> DROP TABLE IF EXISTS `Replica_Kasumi`.`GHBUNDLEM`;
B20: No. | D20: 論理名 | R20: 物理名 | AC20: データ型 | AH20: PK | AJ20: Not Null | AM20: デフォルト | AT20: 備考 | BP20: ="CREATE TABLE `"&$G$8&"`.`"&$G$10&"` (" -> CREATE TABLE `Replica_Kasumi`.`GHBUNDLEM` (
B21: 1 | D21: レコードID | R21: RECORD_ID | AC21: bigint | AJ21: Y | AM21: 自動追加 | BP21: `RECORD_ID` bigint NOT NULL AUTO_INCREMENT COMMENT 'レコードID'
B22: =B21+1 -> 2 | D22: レコード作成日付 | R22: RECORD_CREATE_DATE | AC22: date | AJ22: Y | AM22: CURRENT_DATE | BP22: ,`RECORD_CREATE_DATE` date NOT NULL COMMENT 'レコード作成日付'
B23: =B22+1 -> 3 | D23: レコード作成時間 | R23: RECORD_CREATE_TIME | AC23: time | AJ23: Y | AM23: CURRENT_TIME | BP23: ,`RECORD_CREATE_TIME` time NOT NULL COMMENT 'レコード作成時間' | BV23: SET CHARACTER_SET_DATABASE = UTF8;
B24: =B23+1 -> 4 | D24: レコード更新日付 | R24: RECORD_UPDATE_DATE | AC24: date | AJ24: Y | AM24: CURRENT_DATE | AT24: トリガーにより更新 | BP24: ,`RECORD_UPDATE_DATE` date NOT NULL COMMENT 'レコード更新日付/トリガーにより更新' | BV24: ="UPDATE `REPLICA_KASUMI`.`"&$G$10&"` A,`TMP`.`"&$G$10&"` B" -> UPDATE `REPLICA_KASUMI`.`GHBUNDLEM` A,`TMP`.`GHBUNDLEM` B
B25: =B24+1 -> 5 | D25: レコード更新時間 | R25: RECORD_UPDATE_TIME | AC25: time | AJ25: Y | AM25: CURRENT_TIME | AT25: トリガーにより更新 | BP25: ,`RECORD_UPDATE_TIME` time NOT NULL COMMENT 'レコード更新時間/トリガーにより更新' | BR25: ="DROP TABLE IF EXISTS `TMP`.`"&$G$10&"`;" -> DROP TABLE IF EXISTS `TMP`.`GHBUNDLEM`; | BT25: ="LOAD DATA INFILE 'C:/04_DATAFILE/"&$G$10&"/TMP/"&$G$10&".CSV' " -> LOAD DATA INFILE 'C:/04_DATAFILE/GHBUNDLEM/TMP/GHBUNDLEM.CSV' | BV25: SET
A26: @1 | B26: =B25+1 -> 6 | D26: レコード無効フラグ | R26: RECORD_VOID_FLAG | AC26: char(1) | AJ26: Y | AM26: "" | AT26: 0: 有効フラグ、 1:無効フラグ | BP26: ,`RECORD_VOID_FLAG` char(1) NOT NULL DEFAULT '' COMMENT 'レコード無効フラグ '''': 有効フラグ、 1:無効フラグ' | BR26: ="CREATE TABLE `TMP`.`"&G10&"` (" -> CREATE TABLE `TMP`.`GHBUNDLEM` ( | BT26: ="REPLACE INTO TABLE TMP.`"&$G$10&"` FIELDS TERMINATED BY ',' ENCLOSED BY '\""' LINES TERMINATED BY '\r\n' (" -> REPLACE INTO TABLE TMP.`GHBUNDLEM` FIELDS TERMINATED BY ',' ENCLOSED BY '\"' LINES TERMINATED BY '\r\n' ( | BX26: ="INSERT INTO `REPLICA_KASUMI`.`"&$G$10&"` (" -> INSERT INTO `REPLICA_KASUMI`.`GHBUNDLEM` ( | BZ26: ) SELECT
A27: @2 | B27: 7 | D27: 処理区分 | R27: PRCS_TYP | AC27: {=_xlfn.SWITCH(BM27,"String","varchar("&BN27&")","Long","int","Integer","smallint","Double","decimal(9,2)","Currency","int")} -> varchar(1) | AT27: Ａ：登録 Ｕ：更新 Ｄ：削除 | AZ27: 更新区分によりセット（ＡまたはＵまたはＤ） | BM27: String | BN27: 1 | BP27: =",`"&R27&"` "&AC27&" "&IF(AJ27="Y","NOT NULL","")&" COMMENT '"&D27&"'" -> ,`PRCS_TYP` varchar(1) COMMENT '処理区分' | BR27: ="`"&R27&"` "&AC27&" "&IF(AJ27="Y","NOT NULL","") -> `PRCS_TYP` varchar(1) | BT27: ="`"&R27&"`" -> `PRCS_TYP` | BV27: ="A.`"&R27&"` = B.`"&R27&"`" -> A.`PRCS_TYP` = B.`PRCS_TYP` | BX27: ="`"&R27&"`" -> `PRCS_TYP` | BZ27: ="`"&R27&"`" -> `PRCS_TYP`
A28: @3 | B28: 8 | D28: 店舗コード | R28: STR_ID | AC28: {=_xlfn.SWITCH(BM28,"String","varchar("&BN28&")","Long","int","Integer","smallint","Double","decimal(9,2)","Currency","int")} -> int | AH28: 1 | AT28: ０は不可 | AZ28: 店舗コードをセット | BM28: Long | BP28: =",`"&R28&"` "&AC28&" "&IF(AJ28="Y","NOT NULL","")&" COMMENT '"&D28&"'" -> ,`STR_ID` int COMMENT '店舗コード' | BR28: =",`"&R28&"` "&AC28&" "&IF(AJ28="Y","NOT NULL","") -> ,`STR_ID` int | BT28: =",`"&R28&"`" -> ,`STR_ID` | BV28: =",A.`"&R28&"` = B.`"&R28&"`" -> ,A.`STR_ID` = B.`STR_ID` | BX28: =",`"&R28&"`" -> ,`STR_ID` | BZ28: =",`"&R28&"`" -> ,`STR_ID`
A29: @4 | B29: 9 | D29: 関連企画Ｎo. | R29: PARNT_ENVT_ID | AC29: {=_xlfn.SWITCH(BM29,"String","varchar("&BN29&")","Long","int","Integer","smallint","Double","decimal(9,2)","Currency","int")} -> varchar(7) | AT29: 現在未使用 Ｎull固定 | BM29: String | BN29: 7 | BP29: =",`"&R29&"` "&AC29&" "&IF(AJ29="Y","NOT NULL","")&" COMMENT '"&D29&"'" -> ,`PARNT_ENVT_ID` varchar(7) COMMENT '関連企画Ｎo.' | BR29: =",`"&R29&"` "&AC29&" "&IF(AJ29="Y","NOT NULL","") -> ,`PARNT_ENVT_ID` varchar(7) | BT29: =",`"&R29&"`" -> ,`PARNT_ENVT_ID` | BV29: =",A.`"&R29&"` = B.`"&R29&"`" -> ,A.`PARNT_ENVT_ID` = B.`PARNT_ENVT_ID` | BX29: =",`"&R29&"`" -> ,`PARNT_ENVT_ID` | BZ29: =",`"&R29&"`" -> ,`PARNT_ENVT_ID`
A30: @5 | B30: 9 | D30: 企画Ｎo. | R30: EVNT_NBR | AC30: {=_xlfn.SWITCH(BM30,"String","varchar("&BN30&")","Long","int","Integer","smallint","Double","decimal(9,2)","Currency","int")} -> varchar(7) | AH30: 3 | AT30: 左詰 企画マスタに存在すること | AZ30: プロモーションＮＯをセット | BM30: String | BN30: 7 | BP30: =",`"&R30&"` "&AC30&" "&IF(AJ30="Y","NOT NULL","")&" COMMENT '"&D30&"'" -> ,`EVNT_NBR` varchar(7) COMMENT '企画Ｎo.' | BR30: =",`"&R30&"` "&AC30&" "&IF(AJ30="Y","NOT NULL","") -> ,`EVNT_NBR` varchar(7) | BT30: =",`"&R30&"`" -> ,`EVNT_NBR` | BV30: =",A.`"&R30&"` = B.`"&R30&"`" -> ,A.`EVNT_NBR` = B.`EVNT_NBR` | BX30: =",`"&R30&"`" -> ,`EVNT_NBR` | BZ30: =",`"&R30&"`" -> ,`EVNT_NBR`
A31: @6 | B31: 9 | D31: Ｍ＆Ｍ ＮＯ | R31: DESCR | AC31: {=_xlfn.SWITCH(BM31,"String","varchar("&BN31&")","Long","int","Integer","smallint","Double","decimal(9,2)","Currency","int")} -> varchar(24) | AH31: 5 | AT31: 数字２桁 左詰め | AZ31: Ｍ＆ＭＮＯをセット | BM31: String | BN31: 24 | BP31: =",`"&R31&"` "&AC31&" "&IF(AJ31="Y","NOT NULL","")&" COMMENT '"&D31&"'" -> ,`DESCR` varchar(24) COMMENT 'Ｍ＆Ｍ ＮＯ' | BR31: =",`"&R31&"` "&AC31&" "&IF(AJ31="Y","NOT NULL","") -> ,`DESCR` varchar(24) | BT31: =",`"&R31&"`" -> ,`DESCR` | BV31: =",A.`"&R31&"` = B.`"&R31&"`" -> ,A.`DESCR` = B.`DESCR` | BX31: =",`"&R31&"`" -> ,`DESCR` | BZ31: =",`"&R31&"`" -> ,`DESCR`
A32: @7 | B32: 9 | D32: 会員フラグ | R32: MBR_FG | AC32: {=_xlfn.SWITCH(BM32,"String","varchar("&BN32&")","Long","int","Integer","smallint","Double","decimal(9,2)","Currency","int")} -> smallint | AH32: 4 | AT32: ０：一般組合せ １：会員組合せ | AZ32: ０をセット | BM32: Integer | BP32: =",`"&R32&"` "&AC32&" "&IF(AJ32="Y","NOT NULL","")&" COMMENT '"&D32&"'" -> ,`MBR_FG` smallint COMMENT '会員フラグ' | BR32: =",`"&R32&"` "&AC32&" "&IF(AJ32="Y","NOT NULL","") -> ,`MBR_FG` smallint | BT32: =",`"&R32&"`" -> ,`MBR_FG` | BV32: =",A.`"&R32&"` = B.`"&R32&"`" -> ,A.`MBR_FG` = B.`MBR_FG` | BX32: =",`"&R32&"`" -> ,`MBR_FG` | BZ32: =",`"&R32&"`" -> ,`MBR_FG`
A33: @8 | B33: 9 | D33: 商品コード | R33: PLU_ID | AC33: {=_xlfn.SWITCH(BM33,"String","varchar("&BN33&")","Long","int","Integer","smallint","Double","decimal(9,2)","Currency","int")} -> varchar(24) | AT33: 左詰 数字で最大19桁。特にＰＬUコードを使用しない場合はｽｷｬﾝｺｰﾄﾞと同じ値を入れておくこと | AZ33: 部門＋商品コードをセット | BM33: String | BN33: 24 | BP33: =",`"&R33&"` "&AC33&" "&IF(AJ33="Y","NOT NULL","")&" COMMENT '"&D33&"'" -> ,`PLU_ID` varchar(24) COMMENT '商品コード' | BR33: =",`"&R33&"` "&AC33&" "&IF(AJ33="Y","NOT NULL","") -> ,`PLU_ID` varchar(24) | BT33: =",`"&R33&"`" -> ,`PLU_ID` | BV33: =",A.`"&R33&"` = B.`"&R33&"`" -> ,A.`PLU_ID` = B.`PLU_ID` | BX33: =",`"&R33&"`" -> ,`PLU_ID` | BZ33: =",`"&R33&"`" -> ,`PLU_ID`
A34: @9 | B34: 9 | D34: 組合せ開始日 | R34: EVNT_BGN_TM | AC34: {=_xlfn.SWITCH(BM34,"String","varchar("&BN34&")","Long","int","Integer","smallint","Double","decimal(9,2)","Currency","int")} -> varchar(8) | AT34: ＹＹＹＹＭＭＤＤ形式で8桁フルに設定すること | AZ34: 販売開始日をセット | BM34: String | BN34: 8 | BP34: =",`"&R34&"` "&AC34&" "&IF(AJ34="Y","NOT NULL","")&" COMMENT '"&D34&"'" -> ,`EVNT_BGN_TM` varchar(8) COMMENT '組合せ開始日' | BR34: =",`"&R34&"` "&AC34&" "&IF(AJ34="Y","NOT NULL","") -> ,`EVNT_BGN_TM` varchar(8) | BT34: =",`"&R34&"`" -> ,`EVNT_BGN_TM` | BV34: =",A.`"&R34&"` = B.`"&R34&"`" -> ,A.`EVNT_BGN_TM` = B.`EVNT_BGN_TM` | BX34: =",`"&R34&"`" -> ,`EVNT_BGN_TM` | BZ34: =",`"&R34&"`" -> ,`EVNT_BGN_TM`
A35: @10 | B35: 9 | D35: 組合せ終了日 | R35: EVNT_END_TM | AC35: {=_xlfn.SWITCH(BM35,"String","varchar("&BN35&")","Long","int","Integer","smallint","Double","decimal(9,2)","Currency","int")} -> varchar(8) | AT35: ＹＹＹＹＭＭＤＤ形式で8桁フルに設定すること | AZ35: 販売終了日をセット | BM35: String | BN35: 8 | BP35: =",`"&R35&"` "&AC35&" "&IF(AJ35="Y","NOT NULL","")&" COMMENT '"&D35&"'" -> ,`EVNT_END_TM` varchar(8) COMMENT '組合せ終了日' | BR35: =",`"&R35&"` "&AC35&" "&IF(AJ35="Y","NOT NULL","") -> ,`EVNT_END_TM` varchar(8) | BT35: =",`"&R35&"`" -> ,`EVNT_END_TM` | BV35: =",A.`"&R35&"` = B.`"&R35&"`" -> ,A.`EVNT_END_TM` = B.`EVNT_END_TM` | BX35: =",`"&R35&"`" -> ,`EVNT_END_TM` | BZ35: =",`"&R35&"`" -> ,`EVNT_END_TM`
A36: @11 | B36: 9 | D36: 企画区分 | R36: EVNT_TYP | AC36: {=_xlfn.SWITCH(BM36,"String","varchar("&BN36&")","Long","int","Integer","smallint","Double","decimal(9,2)","Currency","int")} -> smallint | AH36: 2 | AT36: ２：バンドルミックス ６：ペア | AZ36: ２をセット | BM36: Integer | BP36: =",`"&R36&"` "&AC36&" "&IF(AJ36="Y","NOT NULL","")&" COMMENT '"&D36&"'" -> ,`EVNT_TYP` smallint COMMENT '企画区分' | BR36: =",`"&R36&"` "&AC36&" "&IF(AJ36="Y","NOT NULL","") -> ,`EVNT_TYP` smallint | BT36: =",`"&R36&"`" -> ,`EVNT_TYP` | BV36: =",A.`"&R36&"` = B.`"&R36&"`" -> ,A.`EVNT_TYP` = B.`EVNT_TYP` | BX36: =",`"&R36&"`" -> ,`EVNT_TYP` | BZ36: =",`"&R36&"`" -> ,`EVNT_TYP`
A37: @12 | B37: 9 | D37: 企画予算 | R37: EVNT_BDGT | AC37: {=_xlfn.SWITCH(BM37,"String","varchar("&BN37&")","Long","int","Integer","smallint","Double","decimal(9,2)","Currency","int")} -> int | AT37: 現在未使用 ０固定 | AZ37: ０をセット | BM37: Currency | BP37: =",`"&R37&"` "&AC37&" "&IF(AJ37="Y","NOT NULL","")&" COMMENT '"&D37&"'" -> ,`EVNT_BDGT` int COMMENT '企画予算' | BR37: =",`"&R37&"` "&AC37&" "&IF(AJ37="Y","NOT NULL","") -> ,`EVNT_BDGT` int | BT37: =",`"&R37&"`" -> ,`EVNT_BDGT` | BV37: =",A.`"&R37&"` = B.`"&R37&"`" -> ,A.`EVNT_BDGT` = B.`EVNT_BDGT` | BX37: =",`"&R37&"`" -> ,`EVNT_BDGT` | BZ37: =",`"&R37&"`" -> ,`EVNT_BDGT`
A38: @13 | B38: 9 | D38: 組合せ自動削除日数 | R38: EVNT_DEL_DY | AC38: {=_xlfn.SWITCH(BM38,"String","varchar("&BN38&")","Long","int","Integer","smallint","Double","decimal(9,2)","Currency","int")} -> varchar(8) | AT38: 期間終了後の削除猶予期間 ００２－０９９ 未使用時はＮＵＬＬ | AZ38: ００７をセット | BM38: String | BN38: 8 | BP38: =",`"&R38&"` "&AC38&" "&IF(AJ38="Y","NOT NULL","")&" COMMENT '"&D38&"'" -> ,`EVNT_DEL_DY` varchar(8) COMMENT '組合せ自動削除日数' | BR38: =",`"&R38&"` "&AC38&" "&IF(AJ38="Y","NOT NULL","") -> ,`EVNT_DEL_DY` varchar(8) | BT38: =",`"&R38&"`" -> ,`EVNT_DEL_DY` | BV38: =",A.`"&R38&"` = B.`"&R38&"`" -> ,A.`EVNT_DEL_DY` = B.`EVNT_DEL_DY` | BX38: =",`"&R38&"`" -> ,`EVNT_DEL_DY` | BZ38: =",`"&R38&"`" -> ,`EVNT_DEL_DY`
A39: @14 | B39: 9 | D39: 組合せ優先区分 | R39: EVNT_SRC | AC39: {=_xlfn.SWITCH(BM39,"String","varchar("&BN39&")","Long","int","Integer","smallint","Double","decimal(9,2)","Currency","int")} -> smallint | AT39: 現在1固定 ０：店舗優先 １：本部優先 | AZ39: １をセット | BM39: Integer | BP39: =",`"&R39&"` "&AC39&" "&IF(AJ39="Y","NOT NULL","")&" COMMENT '"&D39&"'" -> ,`EVNT_SRC` smallint COMMENT '組合せ優先区分' | BR39: =",`"&R39&"` "&AC39&" "&IF(AJ39="Y","NOT NULL","") -> ,`EVNT_SRC` smallint | BT39: =",`"&R39&"`" -> ,`EVNT_SRC` | BV39: =",A.`"&R39&"` = B.`"&R39&"`" -> ,A.`EVNT_SRC` = B.`EVNT_SRC` | BX39: =",`"&R39&"`" -> ,`EVNT_SRC` | BZ39: =",`"&R39&"`" -> ,`EVNT_SRC`
A40: @15 | B40: 9 | D40: 組合せ保留フラグ | R40: EVNT_EXCL_FG | AC40: {=_xlfn.SWITCH(BM40,"String","varchar("&BN40&")","Long","int","Integer","smallint","Double","decimal(9,2)","Currency","int")} -> smallint | AT40: ０：保留しない １：保留する | AZ40: ０をセット | BM40: Integer | BP40: =",`"&R40&"` "&AC40&" "&IF(AJ40="Y","NOT NULL","")&" COMMENT '"&D40&"'" -> ,`EVNT_EXCL_FG` smallint COMMENT '組合せ保留フラグ' | BR40: =",`"&R40&"` "&AC40&" "&IF(AJ40="Y","NOT NULL","") -> ,`EVNT_EXCL_FG` smallint | BT40: =",`"&R40&"`" -> ,`EVNT_EXCL_FG` | BV40: =",A.`"&R40&"` = B.`"&R40&"`" -> ,A.`EVNT_EXCL_FG` = B.`EVNT_EXCL_FG` | BX40: =",`"&R40&"`" -> ,`EVNT_EXCL_FG` | BZ40: =",`"&R40&"`" -> ,`EVNT_EXCL_FG`
A41: @16 | B41: 9 | D41: タイムサービスフラグ | R41: TIME_SERVICE_FG | AC41: {=_xlfn.SWITCH(BM41,"String","varchar("&BN41&")","Long","int","Integer","smallint","Double","decimal(9,2)","Currency","int")} -> smallint | AT41: ０：期間 １：期間＆曜日 ２：期間&時間 ３：期間&時間&曜日 | AZ41: ０をセット | BM41: Integer | BP41: =",`"&R41&"` "&AC41&" "&IF(AJ41="Y","NOT NULL","")&" COMMENT '"&D41&"'" -> ,`TIME_SERVICE_FG` smallint COMMENT 'タイムサービスフラグ' | BR41: =",`"&R41&"` "&AC41&" "&IF(AJ41="Y","NOT NULL","") -> ,`TIME_SERVICE_FG` smallint | BT41: =",`"&R41&"`" -> ,`TIME_SERVICE_FG` | BV41: =",A.`"&R41&"` = B.`"&R41&"`" -> ,A.`TIME_SERVICE_FG` = B.`TIME_SERVICE_FG` | BX41: =",`"&R41&"`" -> ,`TIME_SERVICE_FG` | BZ41: =",`"&R41&"`" -> ,`TIME_SERVICE_FG`
A42: @17 | B42: 9 | D42: 月曜日除外フラグ | R42: MON_EXCL_FG | AC42: {=_xlfn.SWITCH(BM42,"String","varchar("&BN42&")","Long","int","Integer","smallint","Double","decimal(9,2)","Currency","int")} -> smallint | AT42: ０：除外しない １：除外する | AZ42: ０をセット | BM42: Integer | BP42: =",`"&R42&"` "&AC42&" "&IF(AJ42="Y","NOT NULL","")&" COMMENT '"&D42&"'" -> ,`MON_EXCL_FG` smallint COMMENT '月曜日除外フラグ' | BR42: =",`"&R42&"` "&AC42&" "&IF(AJ42="Y","NOT NULL","") -> ,`MON_EXCL_FG` smallint | BT42: =",`"&R42&"`" -> ,`MON_EXCL_FG` | BV42: =",A.`"&R42&"` = B.`"&R42&"`" -> ,A.`MON_EXCL_FG` = B.`MON_EXCL_FG` | BX42: =",`"&R42&"`" -> ,`MON_EXCL_FG` | BZ42: =",`"&R42&"`" -> ,`MON_EXCL_FG`
