Workbook

Sheet 表紙
A1: システム名 | K1: システム種別 | W1: DB定義書 | AP1: 作成者 | AT1: 作成日 | AY1: 更新者 | BC1: 更新日 | BH1: 版数
A2: 現金専用簡易セルフPOS | AP2: きよはら | AT2: 44652 | AY2: =LOOKUP(2,1/(改廃履歴!H11:H30000<>""),改廃履歴!H11:H30000) -> Thanh Nguyên | BC2: =LOOKUP(2,1/(改廃履歴!B11:B30000<>""),改廃履歴!B11:B30000) -> 45285 | BH2: =LOOKUP(2,1/(改廃履歴!O11:O30000<>""),改廃履歴!O11:O30000) -> 0.2
A4: 機能カテゴリ | H4: 共通 | U4: 項目 | AP4: 表紙
L16: 現金専用簡易セルフPOS 基本設計書
L24: =K2&"/"&H4&"/"&Z4 -> /共通/
Q44: 承認日 | AA44: 承認者 | AQ44: 版数

Sheet 改廃履歴
A1: システム名 | K1: システム種別 | W1: =IF(表紙!W1="","",表紙!W1) -> DB定義書 | AP1: 作成者 | AT1: 作成日 | AY1: 更新者 | BC1: 更新日 | BH1: 版数
A2: =IF(表紙!A2="","",表紙!A2) -> 現金専用簡易セルフPOS | K2: =IF(表紙!K2="","",表紙!K2) | AP2: =IF(表紙!AP2="","",表紙!AP2) -> きよはら | AT2: =IF(表紙!AT2="","",表紙!AT2) -> 44652 | AY2: =IF(表紙!AY2="","",表紙!AY2) -> Thanh Nguyên | BC2: =IF(表紙!BC2="","",表紙!BC2) -> 45285 | BH2: =IF(表紙!BH2="","",表紙!BH2) -> 0.2
A4: 機能カテゴリ | H4: =IF(表紙!H4="","",表紙!H4) -> 共通 | U4: 項目 | Z4: =IF(表紙!Z4="","",表紙!Z4) | AP4: 改廃履歴
B8: ■改廃履歴
B10: 更新日付 | H10: 更新者 | O10: 版数 | S10: 変更内容 | AX10: 承認日付 | BD10: 承認者
B11: 44652 | H11: きよはら | O11: 0.1 | S11: 新規作成
B13: 45285 | H13: Thanh Nguyên | O13: 0.2 | S13: プリセットメニューマスタに、プリセットボタンレイアウト名称を追加

Sheet DB一覧
A1: システム名 | K1: システム種別 | W1: =IF(表紙!W1="","",表紙!W1) -> DB定義書 | AP1: 作成者 | AT1: 作成日 | AY1: 更新者 | BC1: 更新日 | BH1: 版数
A2: =IF(表紙!A2="","",表紙!A2) -> 現金専用簡易セルフPOS | K2: =IF(表紙!K2="","",表紙!K2) | AP2: =IF(表紙!AP2="","",表紙!AP2) -> きよはら | AT2: =IF(表紙!AT2="","",表紙!AT2) -> 44652 | AY2: =IF(表紙!AY2="","",表紙!AY2) -> Thanh Nguyên | BC2: =IF(表紙!BC2="","",表紙!BC2) -> 45285 | BH2: =IF(表紙!BH2="","",表紙!BH2) -> 0.2
A4: 機能カテゴリ | H4: =IF(表紙!H4="","",表紙!H4) -> 共通 | U4: 項目 | Z4: =IF(表紙!Z4="","",表紙!Z4) | AP4: Sheet7
B7: ID | D7: 区分 | M7: 論理テーブル名 | AB7: 物理テーブル名 | AW7: 備考
D8: 2_7_設定機能 | M8: 機器接続情報 | AB8: Device_Connection_Information

Sheet ER
A1: システム名 | K1: システム種別 | W1: =IF(表紙!W1="","",表紙!W1) -> DB定義書 | AP1: 作成者 | AT1: 作成日 | AY1: 更新者 | BC1: 更新日 | BH1: 版数
A2: =IF(表紙!A2="","",表紙!A2) -> 現金専用簡易セルフPOS | K2: =IF(表紙!K2="","",表紙!K2) | AP2: =IF(表紙!AP2="","",表紙!AP2) -> きよはら | AT2: =IF(表紙!AT2="","",表紙!AT2) -> 44652 | AY2: =IF(表紙!AY2="","",表紙!AY2) -> Thanh Nguyên | BC2: =IF(表紙!BC2="","",表紙!BC2) -> 45285 | BH2: =IF(表紙!BH2="","",表紙!BH2) -> 0.2
A4: 機能カテゴリ | H4: =IF(表紙!H4="","",表紙!H4) -> 共通 | U4: 項目 | Z4: =IF(表紙!Z4="","",表紙!Z4) | AP4: ER

Sheet POSメニュー
A1: システム名 | K1: システム種別 | W1: =IF(表紙!W1="","",表紙!W1) -> DB定義書 | AP1: 作成者 | AT1: 作成日 | AY1: 更新者 | BC1: 更新日 | BH1: 版数
A2: =IF(表紙!A2="","",表紙!A2) -> 現金専用簡易セルフPOS | K2: =IF(表紙!K2="","",表紙!K2) | AP2: =IF(表紙!AP2="","",表紙!AP2) -> きよはら | AT2: =IF(表紙!AT2="","",表紙!AT2) -> 44652 | AY2: =IF(表紙!AY2="","",表紙!AY2) -> Thanh Nguyên | BC2: =IF(表紙!BC2="","",表紙!BC2) -> 45285 | BH2: =IF(表紙!BH2="","",表紙!BH2) -> 0.2
A4: 機能カテゴリ | H4: =IF(表紙!H4="","",表紙!H4) -> 共通 | U4: 項目 | Z4: =IF(表紙!Z4="","",表紙!Z4) | AP4: テンプレート
B7: ■テーブル情報
B8: スキーマ名 | Y8: RDBMS名
B9: 論理名 | G9: 機器接続情報 | Y9: バージョン
B10: 物理名
B11: 備考
B19: ■カラム情報 | BM19: ="DROP TABLE IF EXISTS `"&$G$8&"`.`"&$G$10&"`;" -> DROP TABLE IF EXISTS ``.``;
B20: No. | D20: 論理名 | R20: 物理名 | AC20: データ型 | AH20: PK | AJ20: Not Null | AM20: デフォルト | AT20: 備考 | BM20: ="CREATE TABLE `"&$G$8&"`.`"&$G$10&"` (" -> CREATE TABLE ``.`` ( | BN20: ="CREATE TABLE `TMP`.`"&G10&"` (" -> CREATE TABLE `TMP`.`` (
B21: 1 | D21: レコードID | R21: RECORD_ID | AC21: BIGINT | AH21: 1 | AJ21: Y | AM21: 自動追加 | BM21: ="`"&R21&"` "&AC21&" "&IF(AJ21="Y","NOT NULL","")&" AUTO_INCREMENT COMMENT '"&D21&IF(AT21="","","/"&AT21)&"'" -> `RECORD_ID` BIGINT NOT NULL AUTO_INCREMENT COMMENT 'レコードID' | BO21: =",A.`"&R21&"` = B.`"&R21&"`" -> ,A.`RECORD_ID` = B.`RECORD_ID` | BP21: =",`"&R21&"`" -> ,`RECORD_ID`
B22: 2 | D22: レコード作成日付 | R22: RECORD_CREATE_DATE | AC22: TIMESTAMP | AJ22: Y | AM22: CURRENT_DATE | BM22: =",`"&R22&"` "&AC22&" "&IF(AJ22="Y","NOT NULL","")&" COMMENT '"&D22&IF(AT22="","","/"&AT22)&"'" -> ,`RECORD_CREATE_DATE` TIMESTAMP NOT NULL COMMENT 'レコード作成日付' | BO22: =",A.`"&R22&"` = B.`"&R22&"`" -> ,A.`RECORD_CREATE_DATE` = B.`RECORD_CREATE_DATE` | BP22: =",`"&R22&"`" -> ,`RECORD_CREATE_DATE`
B23: 3 | D23: レコード作成時間 | R23: RECORD_CREATE_TIME | AC23: BIGINT | AJ23: Y | AM23: CURRENT_TIME | BM23: =",`"&R23&"` "&AC23&" "&IF(AJ23="Y","NOT NULL","")&" COMMENT '"&D23&IF(AT23="","","/"&AT23)&"'" -> ,`RECORD_CREATE_TIME` BIGINT NOT NULL COMMENT 'レコード作成時間' | BO23: =",A.`"&R23&"` = B.`"&R23&"`" -> ,A.`RECORD_CREATE_TIME` = B.`RECORD_CREATE_TIME` | BP23: =",`"&R23&"`" -> ,`RECORD_CREATE_TIME`
B24: 4 | D24: レコード更新日付 | R24: RECORD_UPDATE_DATE | AC24: TIMESTAMP | AJ24: Y | AM24: CURRENT_DATE | AT24: トリガーにより更新 | BM24: =",`"&R24&"` "&AC24&" "&IF(AJ24="Y","NOT NULL","")&" COMMENT '"&D24&IF(AT24="","","/"&AT24)&"'" -> ,`RECORD_UPDATE_DATE` TIMESTAMP NOT NULL COMMENT 'レコード更新日付/トリガーにより更新' | BO24: =",A.`"&R24&"` = B.`"&R24&"`" -> ,A.`RECORD_UPDATE_DATE` = B.`RECORD_UPDATE_DATE` | BP24: =",`"&R24&"`" -> ,`RECORD_UPDATE_DATE`
B25: 5 | D25: レコード更新時間 | R25: RECORD_UPDATE_TIME | AC25: BIGINT | AJ25: Y | AM25: CURRENT_TIME | AT25: トリガーにより更新 | BM25: =",`"&R25&"` "&AC25&" "&IF(AJ25="Y","NOT NULL","")&" COMMENT '"&D25&IF(AT25="","","/"&AT25)&"'" -> ,`RECORD_UPDATE_TIME` BIGINT NOT NULL COMMENT 'レコード更新時間/トリガーにより更新' | BO25: =",A.`"&R25&"` = B.`"&R25&"`" -> ,A.`RECORD_UPDATE_TIME` = B.`RECORD_UPDATE_TIME` | BP25: =",`"&R25&"`" -> ,`RECORD_UPDATE_TIME`
B26: 6 | D26: レコード無効フラグ | R26: RECORD_VOID_FLAG | AC26: BOOL | AJ26: Y | AM26: "" | AT26: true:有効 / false:無効 | BM26: =",`"&R26&"` "&AC26&" "&IF(AJ26="Y","NOT NULL","")&" COMMENT '"&D26&IF(AT26="","","/"&AT26)&"'" -> ,`RECORD_VOID_FLAG` BOOL NOT NULL COMMENT 'レコード無効フラグ/true:有効 / false:無効' | BN26: `CLASS` VARCHAR ( 1 ) NOT NULL COMMENT '処理区分', | BO26: =",A.`"&R26&"` = B.`"&R26&"`" -> ,A.`RECORD_VOID_FLAG` = B.`RECORD_VOID_FLAG` | BP26: =",`"&R26&"`" -> ,`RECORD_VOID_FLAG`
B27: 7 | D27: ボタン番号 | BM27: =",`"&R27&"` "&AC27&" "&IF(AJ27="Y","NOT NULL","")&" COMMENT '"&D27&IF(AT27="","","/"&AT27)&"'" -> ,`` COMMENT 'ボタン番号' | BN27: =",`"&R27&"` "&AC27&" "&IF(AJ27="Y","NOT NULL","")&" COMMENT '"&D27&"'" -> ,`` COMMENT 'ボタン番号' | BO27: =",A.`"&R27&"` = B.`"&R27&"`" -> ,A.`` = B.`` | BP27: =",`"&R27&"`" -> ,``
B28: 8 | D28: ラベル | BM28: =",`"&R28&"` "&AC28&" "&IF(AJ28="Y","NOT NULL","")&" COMMENT '"&D28&IF(AT28="","","/"&AT28)&"'" -> ,`` COMMENT 'ラベル' | BN28: =",`"&R28&"` "&AC28&" "&IF(AJ28="Y","NOT NULL","")&" COMMENT '"&D28&"'" -> ,`` COMMENT 'ラベル' | BO28: =",A.`"&R28&"` = B.`"&R28&"`" -> ,A.`` = B.`` | BP28: =",`"&R28&"`" -> ,``
B29: 9 | D29: 遷移先 | BM29: =",`"&R29&"` "&AC29&" "&IF(AJ29="Y","NOT NULL","")&" COMMENT '"&D29&IF(AT29="","","/"&AT29)&"'" -> ,`` COMMENT '遷移先' | BN29: =",`"&R29&"` "&AC29&" "&IF(AJ29="Y","NOT NULL","")&" COMMENT '"&D29&"'" -> ,`` COMMENT '遷移先' | BO29: =",A.`"&R29&"` = B.`"&R29&"`" -> ,A.`` = B.`` | BP29: =",`"&R29&"`" -> ,``
B30: 10 | D30: 活性化 | AT30: 1：開設時活性 / 2：非開設時活性 /3：常に活性 / 99：常に非活性 | BM30: =",`"&R30&"` "&AC30&" "&IF(AJ30="Y","NOT NULL","")&" COMMENT '"&D30&IF(AT30="","","/"&AT30)&"'" -> ,`` COMMENT '活性化/1：開設時活性 / 2：非開設時活性 /3：常に活性 / 99：常に非活性' | BN30: =",`"&R30&"` "&AC30&" "&IF(AJ30="Y","NOT NULL","")&" COMMENT '"&D30&"'" -> ,`` COMMENT '活性化' | BO30: =",A.`"&R30&"` = B.`"&R30&"`" -> ,A.`` = B.`` | BP30: =",`"&R30&"`" -> ,``
B31: 11 | BM31: =",`"&R31&"` "&AC31&" "&IF(AJ31="Y","NOT NULL","")&" COMMENT '"&D31&IF(AT31="","","/"&AT31)&"'" -> ,`` COMMENT '' | BN31: =",`"&R31&"` "&AC31&" "&IF(AJ31="Y","NOT NULL","")&" COMMENT '"&D31&"'" -> ,`` COMMENT '' | BO31: =",A.`"&R31&"` = B.`"&R31&"`" -> ,A.`` = B.`` | BP31: =",`"&R31&"`" -> ,``
B32: 12 | BM32: =",`"&R32&"` "&AC32&" "&IF(AJ32="Y","NOT NULL","")&" COMMENT '"&D32&IF(AT32="","","/"&AT32)&"'" -> ,`` COMMENT '' | BN32: =",`"&R32&"` "&AC32&" "&IF(AJ32="Y","NOT NULL","")&" COMMENT '"&D32&"'" -> ,`` COMMENT '' | BO32: =",A.`"&R32&"` = B.`"&R32&"`" -> ,A.`` = B.`` | BP32: =",`"&R32&"`" -> ,``
B33: 13 | BM33: =",`"&R33&"` "&AC33&" "&IF(AJ33="Y","NOT NULL","")&" COMMENT '"&D33&IF(AT33="","","/"&AT33)&"'" -> ,`` COMMENT '' | BN33: =",`"&R33&"` "&AC33&" "&IF(AJ33="Y","NOT NULL","")&" COMMENT '"&D33&"'" -> ,`` COMMENT '' | BO33: =",A.`"&R33&"` = B.`"&R33&"`" -> ,A.`` = B.`` | BP33: =",`"&R33&"`" -> ,``
BM34: =",`"&R34&"` "&AC34&" "&IF(AJ34="Y","NOT NULL","")&" COMMENT '"&D34&IF(AT34="","","/"&AT34)&"'" -> ,`` COMMENT '' | BN34: =",`"&R34&"` "&AC34&" "&IF(AJ34="Y","NOT NULL","")&" COMMENT '"&D34&"'" -> ,`` COMMENT '' | BO34: =",A.`"&R34&"` = B.`"&R34&"`" -> ,A.`` = B.`` | BP34: =",`"&R34&"`" -> ,``
BM35: =",`"&R35&"` "&AC35&" "&IF(AJ35="Y","NOT NULL","")&" COMMENT '"&D35&IF(AT35="","","/"&AT35)&"'" -> ,`` COMMENT '' | BN35: =",`"&R35&"` "&AC35&" "&IF(AJ35="Y","NOT NULL","")&" COMMENT '"&D35&"'" -> ,`` COMMENT '' | BO35: =",A.`"&R35&"` = B.`"&R35&"`" -> ,A.`` = B.`` | BP35: =",`"&R35&"`" -> ,``
B36: ■インデックス情報 | BM36: =",`"&R36&"` "&AC36&" "&IF(AJ36="Y","NOT NULL","")&" COMMENT '"&D36&IF(AT36="","","/"&AT36)&"'" -> ,`` COMMENT '' | BN36: =",`"&R36&"` "&AC36&" "&IF(AJ36="Y","NOT NULL","")&" COMMENT '"&D36&"'" -> ,`` COMMENT '' | BO36: =",A.`"&R36&"` = B.`"&R36&"`" -> ,A.`` = B.`` | BP36: =",`"&R36&"`" -> ,``
B37: No. | D37: Index名 | R37: カラム一覧 | AL37: プライマリキー | AP37: ユニーク | AT37: 備考 | BM37: =",`"&R37&"` "&AC37&" "&IF(AJ37="Y","NOT NULL","")&" COMMENT '"&D37&IF(AT37="","","/"&AT37)&"'" -> ,`カラム一覧` COMMENT 'Index名/備考' | BN37: =",`"&R37&"` "&AC37&" "&IF(AJ37="Y","NOT NULL","")&" COMMENT '"&D37&"'" -> ,`カラム一覧` COMMENT 'Index名' | BO37: =",A.`"&R37&"` = B.`"&R37&"`" -> ,A.`カラム一覧` = B.`カラム一覧` | BP37: =",`"&R37&"`" -> ,`カラム一覧`
B38: 1 | D38: PRIMARY | R38: =IF(_xlfn.XLOOKUP(1,AH:AH,R:R,"",0)="","","`"&_xlfn.XLOOKUP(1,AH:AH,R:R,"",0)&"`")&IF(_xlfn.XLOOKUP(2,AH:AH,R:R,"",0)="","",",`"&_xlfn.XLOOKUP(2,AH:AH,R:R,"",0)&"`")&IF(_xlfn.XLOOKUP(3,AH:AH,R:R,"",0)="","",",`"&_xlfn.XLOOKUP(3,AH:AH,R:R,"",0)&"`")&IF(_xlfn.XLOOKUP(4,AH:AH,R:R,"",0)="","",",`"&_xlfn.XLOOKUP(4,AH:AH,R:R,"",0)&"`")&IF(_xlfn.XLOOKUP(5,AH:AH,R:R,"",0)="","",",`"&_xlfn.XLOOKUP(5,AH:AH,R:R,"",0)&"`")&IF(_xlfn.XLOOKUP(6,AH:AH,R:R,"",0)="","",",`"&_xlfn.XLOOKUP(6,AH:AH,R:R,"",0)&"`")&IF(_xlfn.XLOOKUP(7,AH:AH,R:R,"",0)="","",",`"&_xlfn.XLOOKUP(7,AH:AH,R:R,"",0)&"`")&IF(_xlfn.XLOOKUP(8,AH:AH,R:R,"",0)="","",",`"&_xlfn.XLOOKUP(8,AH:AH,R:R,"",0)&"`") -> `RECORD_ID` | AL38: Y | AP38: Y | BM38: =" , PRIMARY KEY ("&IF(_xlfn.XLOOKUP(1,AH:AH,R:R,"",0)="","","`"&_xlfn.XLOOKUP(1,AH:AH,R:R,"",0)&"`")&IF(_xlfn.XLOOKUP(2,AH:AH,R:R,"",0)="","",",`"&_xlfn.XLOOKUP(2,AH:AH,R:R,"",0)&"`")&IF(_xlfn.XLOOKUP(3,AH:AH,R:R,"",0)="","",",`"&_xlfn.XLOOKUP(3,AH:AH,R:R,"",0)&"`")&IF(_xlfn.XLOOKUP(4,AH:AH,R:R,"",0)="","",",`"&_xlfn.XLOOKUP(4,AH:AH,R:R,"",0)&"`")&IF(_xlfn.XLOOKUP(5,AH:AH,R:R,"",0)="","",",`"&_xlfn.XLOOKUP(5,AH:AH,R:R,"",0)&"`")&IF(_xlfn.XLOOKUP(6,AH:AH,R:R,"",0)="","",",`"&_xlfn.XLOOKUP(6,AH:AH,R:R,"",0)&"`")&IF(_xlfn.XLOOKUP(7,AH:AH,R:R,"",0)="","",",`"&_xlfn.XLOOKUP(7,AH:AH,R:R,"",0)&"`")&IF(_xlfn.XLOOKUP(8,AH:AH,R:R,"",0)="","",",`"&_xlfn.XLOOKUP(8,AH:AH,R:R,"",0)&"`")&")," -> , PRIMARY KEY (`RECORD_ID`), | BN38: =BM38 -> , PRIMARY KEY (`RECORD_ID`), | BO38: =",A.`"&R38&"` = B.`"&R38&"`" -> ,A.``RECORD_ID`` = B.``RECORD_ID`` | BP38: =",`"&R38&"`" -> ,``RECORD_ID``
BM39: KEY `RECORD_ID` (`RECORD_ID`) | BO39: =",A.`"&R39&"` = B.`"&R39&"`" -> ,A.`` = B.`` | BP39: =",`"&R39&"`" -> ,``
BM40: =") ENGINE=InnoDB DEFAULT CHARSET=utf8 COMMENT = '"&$G$9&"';" -> ) ENGINE=InnoDB DEFAULT CHARSET=utf8 COMMENT = '機器接続情報'; | BN40: =") ENGINE=InnoDB DEFAULT CHARSET=utf8 COMMENT = '"&$G$9&"_TMP';" -> ) ENGINE=InnoDB DEFAULT CHARSET=utf8 COMMENT = '機器接続情報_TMP'; | BO40: =",A.`"&R40&"` = B.`"&R40&"`" -> ,A.`` = B.`` | BP40: =",`"&R40&"`" -> ,``
B41: トリガー情報 | BO41: =",A.`"&R41&"` = B.`"&R41&"`" -> ,A.`` = B.`` | BP41: =",`"&R41&"`" -> ,``
B42: No. | D42: トリガー名 | R42: イベント | U42: タイミング | Y42: 条件 | BM42: ="CREATE TRIGGER `"&G2&"_CR_Date_Time` BEFORE INSERT ON `"&G2&"` FOR EACH ROW SET NEW.record_create_date = CURRENT_DATE, NEW.record_create_time = CURRENT_TIME, NEW.record_update_date = CURRENT_DATE, NEW.record_update_time = CURRENT_TIME;" -> CREATE TRIGGER `_CR_Date_Time` BEFORE INSERT ON `` FOR EACH ROW SET NEW.record_create_date = CURRENT_DATE, NEW.record_create_time = CURRENT_TIME, NEW.record_update_date = CURRENT_DATE, NEW.record_update_time = CURRENT_TIME; | BO42: =",A.`"&R42&"` = B.`"&R42&"`" -> ,A.`イベント` = B.`イベント` | BP42: =",`"&R42&"`" -> ,`イベント`
B43: 1 | D43: =G10&"_"&R43&"_"&"trg" -> _update_trg | R43: update | U43: Before row | Y43: auto_updated_date | BM43: ="CREATE TRIGGER `"&G2&"_UP_Date_Time` BEFORE UPDATE ON `"&G2&"` FOR EACH ROW SET NEW.record_update_date = CURRENT_DATE, NEW.record_update_time = CURRENT_TIME;" -> CREATE TRIGGER `_UP_Date_Time` BEFORE UPDATE ON `` FOR EACH ROW SET NEW.record_update_date = CURRENT_DATE, NEW.record_update_time = CURRENT_TIME;
BM63: , PRIMARY KEY (`CompanyCode`,`StoreCode`,`ReceiptCouponCode`,`PrintFrom`,`MessagePosition`,`MessageLineNo`), | BN63: =BM63 -> , PRIMARY KEY (`CompanyCode`,`StoreCode`,`ReceiptCouponCode`,`PrintFrom`,`MessagePosition`,`MessageLineNo`), | BO63: =",A.`"&R63&"` = B.`"&R63&"`" -> ,A.`` = B.`` | BP63: =",`"&R63&"`" -> ,``
BM64: KEY `RECORD_ID` (`RECORD_ID`) | BO64: =",A.`"&R64&"` = B.`"&R64&"`" -> ,A.`` = B.`` | BP64: =",`"&R64&"`" -> ,``
BM65: ) ENGINE=InnoDB DEFAULT CHARSET=utf8; | BN65: =BM65 -> ) ENGINE=InnoDB DEFAULT CHARSET=utf8; | BO65: =",A.`"&R65&"` = B.`"&R65&"`" -> ,A.`` = B.`` | BP65: =",`"&R65&"`" -> ,``
BM66: ="CREATE TRIGGER `"&G10&"_CR_Date_Time` BEFORE INSERT ON `"&G10&"` FOR EACH ROW SET NEW.record_create_date = CURRENT_DATE, NEW.record_create_time = CURRENT_TIME, NEW.record_update_date = CURRENT_DATE, NEW.record_update_time = CURRENT_TIME;" -> CREATE TRIGGER `_CR_Date_Time` BEFORE INSERT ON `` FOR EACH ROW SET NEW.record_create_date = CURRENT_DATE, NEW.record_create_time = CURRENT_TIME, NEW.record_update_date = CURRENT_DATE, NEW.record_update_time = CURRENT_TIME;
BM67: ="CREATE TRIGGER `"&G10&"_UP_Date_Time` BEFORE UPDATE ON `"&G10&"` FOR EACH ROW SET NEW.record_update_date = CURRENT_DATE, NEW.record_update_time = CURRENT_TIME;" -> CREATE TRIGGER `_UP_Date_Time` BEFORE UPDATE ON `` FOR EACH ROW SET NEW.record_update_date = CURRENT_DATE, NEW.record_update_time = CURRENT_TIME;

Sheet 売上情報
A1: システム名 | K1: システム種別 | W1: =IF(表紙!W1="","",表紙!W1) -> DB定義書 | AP1: 作成者 | AT1: 作成日 | AY1: 更新者 | BC1: 更新日 | BH1: 版数
A2: =IF(表紙!A2="","",表紙!A2) -> 現金専用簡易セルフPOS | K2: =IF(表紙!K2="","",表紙!K2) | AP2: =IF(表紙!AP2="","",表紙!AP2) -> きよはら | AT2: =IF(表紙!AT2="","",表紙!AT2) -> 44652 | AY2: =IF(表紙!AY2="","",表紙!AY2) -> Thanh Nguyên | BC2: =IF(表紙!BC2="","",表紙!BC2) -> 45285 | BH2: =IF(表紙!BH2="","",表紙!BH2) -> 0.2
A4: 機能カテゴリ | H4: =IF(表紙!H4="","",表紙!H4) -> 共通 | U4: 項目 | Z4: =IF(表紙!Z4="","",表紙!Z4) | AP4: テンプレート
B7: ■テーブル情報
B8: スキーマ名 | Y8: RDBMS名
B9: 論理名 | G9: 売上情報 | Y9: バージョン
B10: 物理名 | G10: sales_details
B11: 備考
B19: ■カラム情報 | BM19: ="DROP TABLE IF EXISTS `"&$G$8&"`.`"&$G$10&"`;" -> DROP TABLE IF EXISTS ``.`sales_details`;
B20: No. | D20: 論理名 | R20: 物理名 | AC20: データ型 | AH20: PK | AJ20: Not Null | AM20: デフォルト | AT20: 備考 | BM20: ="CREATE TABLE `"&$G$8&"`.`"&$G$10&"` (" -> CREATE TABLE ``.`sales_details` ( | BN20: ="CREATE TABLE `TMP`.`"&G10&"` (" -> CREATE TABLE `TMP`.`sales_details` (
B21: 1 | D21: レコードID | R21: RECORD_ID | AC21: BIGINT | AJ21: Y | AM21: 自動追加 | BM21: ="`"&R21&"` "&AC21&" "&IF(AJ21="Y","NOT NULL","")&" AUTO_INCREMENT COMMENT '"&D21&IF(AT21="","","/"&AT21)&"'" -> `RECORD_ID` BIGINT NOT NULL AUTO_INCREMENT COMMENT 'レコードID' | BO21: =",A.`"&R21&"` = B.`"&R21&"`" -> ,A.`RECORD_ID` = B.`RECORD_ID` | BP21: =",`"&R21&"`" -> ,`RECORD_ID`
B22: 2 | D22: レコード作成日付 | R22: RECORD_CREATE_DATE | AC22: TIMESTAMP | AJ22: Y | AM22: CURRENT_DATE | BM22: =",`"&R22&"` "&AC22&" "&IF(AJ22="Y","NOT NULL","")&" COMMENT '"&D22&IF(AT22="","","/"&AT22)&"'" -> ,`RECORD_CREATE_DATE` TIMESTAMP NOT NULL COMMENT 'レコード作成日付' | BO22: =",A.`"&R22&"` = B.`"&R22&"`" -> ,A.`RECORD_CREATE_DATE` = B.`RECORD_CREATE_DATE` | BP22: =",`"&R22&"`" -> ,`RECORD_CREATE_DATE`
B23: 3 | D23: レコード作成時間 | R23: RECORD_CREATE_TIME | AC23: BIGINT | AJ23: Y | AM23: CURRENT_TIME | BM23: =",`"&R23&"` "&AC23&" "&IF(AJ23="Y","NOT NULL","")&" COMMENT '"&D23&IF(AT23="","","/"&AT23)&"'" -> ,`RECORD_CREATE_TIME` BIGINT NOT NULL COMMENT 'レコード作成時間' | BO23: =",A.`"&R23&"` = B.`"&R23&"`" -> ,A.`RECORD_CREATE_TIME` = B.`RECORD_CREATE_TIME` | BP23: =",`"&R23&"`" -> ,`RECORD_CREATE_TIME`
B24: 4 | D24: レコード更新日付 | R24: RECORD_UPDATE_DATE | AC24: TIMESTAMP | AJ24: Y | AM24: CURRENT_DATE | AT24: トリガーにより更新 | BM24: =",`"&R24&"` "&AC24&" "&IF(AJ24="Y","NOT NULL","")&" COMMENT '"&D24&IF(AT24="","","/"&AT24)&"'" -> ,`RECORD_UPDATE_DATE` TIMESTAMP NOT NULL COMMENT 'レコード更新日付/トリガーにより更新' | BO24: =",A.`"&R24&"` = B.`"&R24&"`" -> ,A.`RECORD_UPDATE_DATE` = B.`RECORD_UPDATE_DATE` | BP24: =",`"&R24&"`" -> ,`RECORD_UPDATE_DATE`
B25: 5 | D25: レコード更新時間 | R25: RECORD_UPDATE_TIME | AC25: BIGINT | AJ25: Y | AM25: CURRENT_TIME | AT25: トリガーにより更新 | BM25: =",`"&R25&"` "&AC25&" "&IF(AJ25="Y","NOT NULL","")&" COMMENT '"&D25&IF(AT25="","","/"&AT25)&"'" -> ,`RECORD_UPDATE_TIME` BIGINT NOT NULL COMMENT 'レコード更新時間/トリガーにより更新' | BO25: =",A.`"&R25&"` = B.`"&R25&"`" -> ,A.`RECORD_UPDATE_TIME` = B.`RECORD_UPDATE_TIME` | BP25: =",`"&R25&"`" -> ,`RECORD_UPDATE_TIME`
B26: 6 | D26: レコード無効フラグ | R26: RECORD_VOID_FLAG | AC26: BOOL | AJ26: Y | AM26: "" | AT26: true:有効 / false:無効 | BM26: =",`"&R26&"` "&AC26&" "&IF(AJ26="Y","NOT NULL","")&" COMMENT '"&D26&IF(AT26="","","/"&AT26)&"'" -> ,`RECORD_VOID_FLAG` BOOL NOT NULL COMMENT 'レコード無効フラグ/true:有効 / false:無効' | BN26: `CLASS` VARCHAR ( 1 ) NOT NULL COMMENT '処理区分', | BO26: =",A.`"&R26&"` = B.`"&R26&"`" -> ,A.`RECORD_VOID_FLAG` = B.`RECORD_VOID_FLAG` | BP26: =",`"&R26&"`" -> ,`RECORD_VOID_FLAG`
B27: 7 | D27: 企業コード | R27: company_code | AC27: char(3) | AH27: 1 | BM27: =",`"&R27&"` "&AC27&" "&IF(AJ27="Y","NOT NULL","")&" COMMENT '"&D27&IF(AT27="","","/"&AT27)&"'" -> ,`company_code` char(3) COMMENT '企業コード' | BN27: =",`"&R27&"` "&AC27&" "&IF(AJ27="Y","NOT NULL","")&" COMMENT '"&D27&"'" -> ,`company_code` char(3) COMMENT '企業コード' | BO27: =",A.`"&R27&"` = B.`"&R27&"`" -> ,A.`company_code` = B.`company_code` | BP27: =",`"&R27&"`" -> ,`company_code`
B28: 8 | D28: 店舗コード | R28: store_code | AC28: char(5) | AH28: 2 | BM28: =",`"&R28&"` "&AC28&" "&IF(AJ28="Y","NOT NULL","")&" COMMENT '"&D28&IF(AT28="","","/"&AT28)&"'" -> ,`store_code` char(5) COMMENT '店舗コード' | BN28: =",`"&R28&"` "&AC28&" "&IF(AJ28="Y","NOT NULL","")&" COMMENT '"&D28&"'" -> ,`store_code` char(5) COMMENT '店舗コード' | BO28: =",A.`"&R28&"` = B.`"&R28&"`" -> ,A.`store_code` = B.`store_code` | BP28: =",`"&R28&"`" -> ,`store_code`
B29: 9 | D29: レジ番号 | R29: instore_code | AC29: char(5) | AH29: 3 | BM29: =",`"&R29&"` "&AC29&" "&IF(AJ29="Y","NOT NULL","")&" COMMENT '"&D29&IF(AT29="","","/"&AT29)&"'" -> ,`instore_code` char(5) COMMENT 'レジ番号' | BN29: =",`"&R29&"` "&AC29&" "&IF(AJ29="Y","NOT NULL","")&" COMMENT '"&D29&"'" -> ,`instore_code` char(5) COMMENT 'レジ番号' | BO29: =",A.`"&R29&"` = B.`"&R29&"`" -> ,A.`instore_code` = B.`instore_code` | BP29: =",`"&R29&"`" -> ,`instore_code`
B30: 13 | D30: 取引確定日時<取引確定後> | R30: record_datetime | AC30: char(16) | BM30: =",`"&R30&"` "&AC30&" "&IF(AJ30="Y","NOT NULL","")&" COMMENT '"&D30&IF(AT30="","","/"&AT30)&"'" -> ,`record_datetime` char(16) COMMENT '取引確定日時<取引確定後>' | BN30: =",`"&R30&"` "&AC30&" "&IF(AJ30="Y","NOT NULL","")&" COMMENT '"&D30&"'" -> ,`record_datetime` char(16) COMMENT '取引確定日時<取引確定後>' | BO30: =",A.`"&R30&"` = B.`"&R30&"`" -> ,A.`record_datetime` = B.`record_datetime` | BP30: =",`"&R30&"`" -> ,`record_datetime`
B31: 14 | D31: ジャーナルNO<取引確定後> | R31: journal_no | AC31: char(10) | BM31: =",`"&R31&"` "&AC31&" "&IF(AJ31="Y","NOT NULL","")&" COMMENT '"&D31&IF(AT31="","","/"&AT31)&"'" -> ,`journal_no` char(10) COMMENT 'ジャーナルNO<取引確定後>' | BN31: =",`"&R31&"` "&AC31&" "&IF(AJ31="Y","NOT NULL","")&" COMMENT '"&D31&"'" -> ,`journal_no` char(10) COMMENT 'ジャーナルNO<取引確定後>' | BO31: =",A.`"&R31&"` = B.`"&R31&"`" -> ,A.`journal_no` = B.`journal_no` | BP31: =",`"&R31&"`" -> ,`journal_no`
B32: 15 | D32: レシートNO<取引確定後> | R32: receipt_no | AC32: char(10) | BM32: =",`"&R32&"` "&AC32&" "&IF(AJ32="Y","NOT NULL","")&" COMMENT '"&D32&IF(AT32="","","/"&AT32)&"'" -> ,`receipt_no` char(10) COMMENT 'レシートNO<取引確定後>' | BN32: =",`"&R32&"` "&AC32&" "&IF(AJ32="Y","NOT NULL","")&" COMMENT '"&D32&"'" -> ,`receipt_no` char(10) COMMENT 'レシートNO<取引確定後>' | BO32: =",A.`"&R32&"` = B.`"&R32&"`" -> ,A.`receipt_no` = B.`receipt_no` | BP32: =",`"&R32&"`" -> ,`receipt_no`
B33: 16 | D33: 年齢確認フラグ ( true : 確認済み ) | R33: confirm_age | AC33: bool | AT33: true : 確認済み | BM33: =",`"&R33&"` "&AC33&" "&IF(AJ33="Y","NOT NULL","")&" COMMENT '"&D33&IF(AT33="","","/"&AT33)&"'" -> ,`confirm_age` bool COMMENT '年齢確認フラグ ( true : 確認済み )/true : 確認済み' | BN33: =",`"&R33&"` "&AC33&" "&IF(AJ33="Y","NOT NULL","")&" COMMENT '"&D33&"'" -> ,`confirm_age` bool COMMENT '年齢確認フラグ ( true : 確認済み )' | BO33: =",A.`"&R33&"` = B.`"&R33&"`" -> ,A.`confirm_age` = B.`confirm_age` | BP33: =",`"&R33&"`" -> ,`confirm_age`
B34: 17 | D34: Scan&Go アカウントID | R34: account_id | AC34: string | BM34: =",`"&R34&"` "&AC34&" "&IF(AJ34="Y","NOT NULL","")&" COMMENT '"&D34&IF(AT34="","","/"&AT34)&"'" -> ,`account_id` string COMMENT 'Scan&Go アカウントID' | BN34: =",`"&R34&"` "&AC34&" "&IF(AJ34="Y","NOT NULL","")&" COMMENT '"&D34&"'" -> ,`account_id` string COMMENT 'Scan&Go アカウントID' | BO34: =",A.`"&R34&"` = B.`"&R34&"`" -> ,A.`account_id` = B.`account_id` | BP34: =",`"&R34&"`" -> ,`account_id`
B35: 18 | D35: Scan&Go アカウント名 | R35: account_name | AC35: string | BM35: =",`"&R35&"` "&AC35&" "&IF(AJ35="Y","NOT NULL","")&" COMMENT '"&D35&IF(AT35="","","/"&AT35)&"'" -> ,`account_name` string COMMENT 'Scan&Go アカウント名' | BN35: =",`"&R35&"` "&AC35&" "&IF(AJ35="Y","NOT NULL","")&" COMMENT '"&D35&"'" -> ,`account_name` string COMMENT 'Scan&Go アカウント名' | BO35: =",A.`"&R35&"` = B.`"&R35&"`" -> ,A.`account_name` = B.`account_name` | BP35: =",`"&R35&"`" -> ,`account_name`
B36: 19 | D36: 明細合計金額 | R36: item_total_price_fmt | AC36: string | BM36: =",`"&R36&"` "&AC36&" "&IF(AJ36="Y","NOT NULL","")&" COMMENT '"&D36&IF(AT36="","","/"&AT36)&"'" -> ,`item_total_price_fmt` string COMMENT '明細合計金額' | BN36: =",`"&R36&"` "&AC36&" "&IF(AJ36="Y","NOT NULL","")&" COMMENT '"&D36&"'" -> ,`item_total_price_fmt` string COMMENT '明細合計金額' | BO36: =",A.`"&R36&"` = B.`"&R36&"`" -> ,A.`item_total_price_fmt` = B.`item_total_price_fmt` | BP36: =",`"&R36&"`" -> ,`item_total_price_fmt`
B37: 20 | D37: まとめ値引金額 | R37: mm_discount_price_fmt | AC37: string | BM37: =",`"&R37&"` "&AC37&" "&IF(AJ37="Y","NOT NULL","")&" COMMENT '"&D37&IF(AT37="","","/"&AT37)&"'" -> ,`mm_discount_price_fmt` string COMMENT 'まとめ値引金額' | BN37: =",`"&R37&"` "&AC37&" "&IF(AJ37="Y","NOT NULL","")&" COMMENT '"&D37&"'" -> ,`mm_discount_price_fmt` string COMMENT 'まとめ値引金額' | BO37: =",A.`"&R37&"` = B.`"&R37&"`" -> ,A.`mm_discount_price_fmt` = B.`mm_discount_price_fmt` | BP37: =",`"&R37&"`" -> ,`mm_discount_price_fmt`
B38: 21 | D38: 小計金額 | R38: subtotal_price_fmt | AC38: string | BM38: =",`"&R38&"` "&AC38&" "&IF(AJ38="Y","NOT NULL","")&" COMMENT '"&D38&IF(AT38="","","/"&AT38)&"'" -> ,`subtotal_price_fmt` string COMMENT '小計金額' | BN38: =",`"&R38&"` "&AC38&" "&IF(AJ38="Y","NOT NULL","")&" COMMENT '"&D38&"'" -> ,`subtotal_price_fmt` string COMMENT '小計金額' | BO38: =",A.`"&R38&"` = B.`"&R38&"`" -> ,A.`subtotal_price_fmt` = B.`subtotal_price_fmt` | BP38: =",`"&R38&"`" -> ,`subtotal_price_fmt`
B39: 22 | D39: 小計値引金額 | R39: subtotal_discount_price_fmt | AC39: string | BM39: =",`"&R39&"` "&AC39&" "&IF(AJ39="Y","NOT NULL","")&" COMMENT '"&D39&IF(AT39="","","/"&AT39)&"'" -> ,`subtotal_discount_price_fmt` string COMMENT '小計値引金額' | BN39: =",`"&R39&"` "&AC39&" "&IF(AJ39="Y","NOT NULL","")&" COMMENT '"&D39&"'" -> ,`subtotal_discount_price_fmt` string COMMENT '小計値引金額' | BO39: =",A.`"&R39&"` = B.`"&R39&"`" -> ,A.`subtotal_discount_price_fmt` = B.`subtotal_discount_price_fmt` | BP39: =",`"&R39&"`" -> ,`subtotal_discount_price_fmt`
B40: 23 | D40: 外税合計 | R40: total_tax_excluded_fmt | AC40: string | BM40: =",`"&R40&"` "&AC40&" "&IF(AJ40="Y","NOT NULL","")&" COMMENT '"&D40&IF(AT40="","","/"&AT40)&"'" -> ,`total_tax_excluded_fmt` string COMMENT '外税合計' | BN40: =",`"&R40&"` "&AC40&" "&IF(AJ40="Y","NOT NULL","")&" COMMENT '"&D40&"'" -> ,`total_tax_excluded_fmt` string COMMENT '外税合計' | BO40: =",A.`"&R40&"` = B.`"&R40&"`" -> ,A.`total_tax_excluded_fmt` = B.`total_tax_excluded_fmt` | BP40: =",`"&R40&"`" -> ,`total_tax_excluded_fmt`
B41: 24 | D41: 合計金額 （=小計金額 - 小計値引金額 + 外税合計） | R41: total_price_fmt | AC41: string | BM41: =",`"&R41&"` "&AC41&" "&IF(AJ41="Y","NOT NULL","")&" COMMENT '"&D41&IF(AT41="","","/"&AT41)&"'" -> ,`total_price_fmt` string COMMENT '合計金額 （=小計金額 - 小計値引金額 + 外税合計）' | BN41: =",`"&R41&"` "&AC41&" "&IF(AJ41="Y","NOT NULL","")&" COMMENT '"&D41&"'" -> ,`total_price_fmt` string COMMENT '合計金額 （=小計金額 - 小計値引金額 + 外税合計）' | BO41: =",A.`"&R41&"` = B.`"&R41&"`" -> ,A.`total_price_fmt` = B.`total_price_fmt` | BP41: =",`"&R41&"`" -> ,`total_price_fmt`
B42: 25 | D42: 合計点数 | R42: total_quantity_fmt | AC42: string | BM42: =",`"&R42&"` "&AC42&" "&IF(AJ42="Y","NOT NULL","")&" COMMENT '"&D42&IF(AT42="","","/"&AT42)&"'" -> ,`total_quantity_fmt` string COMMENT '合計点数' | BN42: =",`"&R42&"` "&AC42&" "&IF(AJ42="Y","NOT NULL","")&" COMMENT '"&D42&"'" -> ,`total_quantity_fmt` string COMMENT '合計点数' | BO42: =",A.`"&R42&"` = B.`"&R42&"`" -> ,A.`total_quantity_fmt` = B.`total_quantity_fmt` | BP42: =",`"&R42&"`" -> ,`total_quantity_fmt`
B43: 26
B44: 27
B45: 28
B46: 29
B49: ■インデックス情報
B50: No. | D50: Index名 | R50: カラム一覧 | AL50: プライマリキー | AP50: ユニーク | AT50: 備考
B51: 1 | D51: PRIMARY | R51: =IF(_xlfn.XLOOKUP(1,AH:AH,R:R,"",0)="","","`"&_xlfn.XLOOKUP(1,AH:AH,R:R,"",0)&"`")&IF(_xlfn.XLOOKUP(2,AH:AH,R:R,"",0)="","",",`"&_xlfn.XLOOKUP(2,AH:AH,R:R,"",0)&"`")&IF(_xlfn.XLOOKUP(3,AH:AH,R:R,"",0)="","",",`"&_xlfn.XLOOKUP(3,AH:AH,R:R,"",0)&"`")&IF(_xlfn.XLOOKUP(4,AH:AH,R:R,"",0)="","",",`"&_xlfn.XLOOKUP(4,AH:AH,R:R,"",0)&"`")&IF(_xlfn.XLOOKUP(5,AH:AH,R:R,"",0)="","",",`"&_xlfn.XLOOKUP(5,AH:AH,R:R,"",0)&"`")&IF(_xlfn.XLOOKUP(6,AH:AH,R:R,"",0)="","",",`"&_xlfn.XLOOKUP(6,AH:AH,R:R,"",0)&"`")&IF(_xlfn.XLOOKUP(7,AH:AH,R:R,"",0)="","",",`"&_xlfn.XLOOKUP(7,AH:AH,R:R,"",0)&"`")&IF(_xlfn.XLOOKUP(8,AH:AH,R:R,"",0)="","",",`"&_xlfn.XLOOKUP(8,AH:AH,R:R,"",0)&"`") -> `company_code`,`store_code`,`instore_code` | AL51: Y | AP51: Y | BM51: =" , PRIMARY KEY ("&IF(_xlfn.XLOOKUP(1,AH:AH,R:R,"",0)="","","`"&_xlfn.XLOOKUP(1,AH:AH,R:R,"",0)&"`")&IF(_xlfn.XLOOKUP(2,AH:AH,R:R,"",0)="","",",`"&_xlfn.XLOOKUP(2,AH:AH,R:R,"",0)&"`")&IF(_xlfn.XLOOKUP(3,AH:AH,R:R,"",0)="","",",`"&_xlfn.XLOOKUP(3,AH:AH,R:R,"",0)&"`")&IF(_xlfn.XLOOKUP(4,AH:AH,R:R,"",0)="","",",`"&_xlfn.XLOOKUP(4,AH:AH,R:R,"",0)&"`")&IF(_xlfn.XLOOKUP(5,AH:AH,R:R,"",0)="","",",`"&_xlfn.XLOOKUP(5,AH:AH,R:R,"",0)&"`")&IF(_xlfn.XLOOKUP(6,AH:AH,R:R,"",0)="","",",`"&_xlfn.XLOOKUP(6,AH:AH,R:R,"",0)&"`")&IF(_xlfn.XLOOKUP(7,AH:AH,R:R,"",0)="","",",`"&_xlfn.XLOOKUP(7,AH:AH,R:R,"",0)&"`")&IF(_xlfn.XLOOKUP(8,AH:AH,R:R,"",0)="","",",`"&_xlfn.XLOOKUP(8,AH:AH,R:R,"",0)&"`")&")," -> , PRIMARY KEY (`company_code`,`store_code`,`instore_code`), | BN51: =BM51 -> , PRIMARY KEY (`company_code`,`store_code`,`instore_code`),
BM52: KEY `RECORD_ID` (`RECORD_ID`)
...

Sheet 売上情報(税)
A1: システム名 | K1: システム種別 | W1: =IF(表紙!W1="","",表紙!W1) -> DB定義書 | AP1: 作成者 | AT1: 作成日 | AY1: 更新者 | BC1: 更新日 | BH1: 版数
A2: =IF(表紙!A2="","",表紙!A2) -> 現金専用簡易セルフPOS | K2: =IF(表紙!K2="","",表紙!K2) | AP2: =IF(表紙!AP2="","",表紙!AP2) -> きよはら | AT2: =IF(表紙!AT2="","",表紙!AT2) -> 44652 | AY2: =IF(表紙!AY2="","",表紙!AY2) -> Thanh Nguyên | BC2: =IF(表紙!BC2="","",表紙!BC2) -> 45285 | BH2: =IF(表紙!BH2="","",表紙!BH2) -> 0.2
A4: 機能カテゴリ | H4: =IF(表紙!H4="","",表紙!H4) -> 共通 | U4: 項目 | Z4: =IF(表紙!Z4="","",表紙!Z4) | AP4: テンプレート
B7: ■テーブル情報
B8: スキーマ名 | Y8: RDBMS名
B9: 論理名 | G9: 売上情報明細 | Y9: バージョン
B10: 物理名 | G10: sales_details
B11: 備考
B19: ■カラム情報 | BM19: ="DROP TABLE IF EXISTS `"&$G$8&"`.`"&$G$10&"`;" -> DROP TABLE IF EXISTS ``.`sales_details`;
B20: No. | D20: 論理名 | R20: 物理名 | AC20: データ型 | AH20: PK | AJ20: Not Null | AM20: デフォルト | AT20: 備考 | BM20: ="CREATE TABLE `"&$G$8&"`.`"&$G$10&"` (" -> CREATE TABLE ``.`sales_details` ( | BN20: ="CREATE TABLE `TMP`.`"&G10&"` (" -> CREATE TABLE `TMP`.`sales_details` (
B21: 1 | D21: レコードID | R21: RECORD_ID | AC21: BIGINT | AJ21: Y | AM21: 自動追加 | BM21: ="`"&R21&"` "&AC21&" "&IF(AJ21="Y","NOT NULL","")&" AUTO_INCREMENT COMMENT '"&D21&IF(AT21="","","/"&AT21)&"'" -> `RECORD_ID` BIGINT NOT NULL AUTO_INCREMENT COMMENT 'レコードID' | BO21: =",A.`"&R21&"` = B.`"&R21&"`" -> ,A.`RECORD_ID` = B.`RECORD_ID` | BP21: =",`"&R21&"`" -> ,`RECORD_ID`
B22: 2 | D22: レコード作成日付 | R22: RECORD_CREATE_DATE | AC22: TIMESTAMP | AJ22: Y | AM22: CURRENT_DATE | BM22: =",`"&R22&"` "&AC22&" "&IF(AJ22="Y","NOT NULL","")&" COMMENT '"&D22&IF(AT22="","","/"&AT22)&"'" -> ,`RECORD_CREATE_DATE` TIMESTAMP NOT NULL COMMENT 'レコード作成日付' | BO22: =",A.`"&R22&"` = B.`"&R22&"`" -> ,A.`RECORD_CREATE_DATE` = B.`RECORD_CREATE_DATE` | BP22: =",`"&R22&"`" -> ,`RECORD_CREATE_DATE`
B23: 3 | D23: レコード作成時間 | R23: RECORD_CREATE_TIME | AC23: BIGINT | AJ23: Y | AM23: CURRENT_TIME | BM23: =",`"&R23&"` "&AC23&" "&IF(AJ23="Y","NOT NULL","")&" COMMENT '"&D23&IF(AT23="","","/"&AT23)&"'" -> ,`RECORD_CREATE_TIME` BIGINT NOT NULL COMMENT 'レコード作成時間' | BO23: =",A.`"&R23&"` = B.`"&R23&"`" -> ,A.`RECORD_CREATE_TIME` = B.`RECORD_CREATE_TIME` | BP23: =",`"&R23&"`" -> ,`RECORD_CREATE_TIME`
B24: 4 | D24: レコード更新日付 | R24: RECORD_UPDATE_DATE | AC24: TIMESTAMP | AJ24: Y | AM24: CURRENT_DATE | AT24: トリガーにより更新 | BM24: =",`"&R24&"` "&AC24&" "&IF(AJ24="Y","NOT NULL","")&" COMMENT '"&D24&IF(AT24="","","/"&AT24)&"'" -> ,`RECORD_UPDATE_DATE` TIMESTAMP NOT NULL COMMENT 'レコード更新日付/トリガーにより更新' | BO24: =",A.`"&R24&"` = B.`"&R24&"`" -> ,A.`RECORD_UPDATE_DATE` = B.`RECORD_UPDATE_DATE` | BP24: =",`"&R24&"`" -> ,`RECORD_UPDATE_DATE`
B25: 5 | D25: レコード更新時間 | R25: RECORD_UPDATE_TIME | AC25: BIGINT | AJ25: Y | AM25: CURRENT_TIME | AT25: トリガーにより更新 | BM25: =",`"&R25&"` "&AC25&" "&IF(AJ25="Y","NOT NULL","")&" COMMENT '"&D25&IF(AT25="","","/"&AT25)&"'" -> ,`RECORD_UPDATE_TIME` BIGINT NOT NULL COMMENT 'レコード更新時間/トリガーにより更新' | BO25: =",A.`"&R25&"` = B.`"&R25&"`" -> ,A.`RECORD_UPDATE_TIME` = B.`RECORD_UPDATE_TIME` | BP25: =",`"&R25&"`" -> ,`RECORD_UPDATE_TIME`
B26: 6 | D26: レコード無効フラグ | R26: RECORD_VOID_FLAG | AC26: BOOL | AJ26: Y | AM26: "" | AT26: true:有効 / false:無効 | BM26: =",`"&R26&"` "&AC26&" "&IF(AJ26="Y","NOT NULL","")&" COMMENT '"&D26&IF(AT26="","","/"&AT26)&"'" -> ,`RECORD_VOID_FLAG` BOOL NOT NULL COMMENT 'レコード無効フラグ/true:有効 / false:無効' | BN26: `CLASS` VARCHAR ( 1 ) NOT NULL COMMENT '処理区分', | BO26: =",A.`"&R26&"` = B.`"&R26&"`" -> ,A.`RECORD_VOID_FLAG` = B.`RECORD_VOID_FLAG` | BP26: =",`"&R26&"`" -> ,`RECORD_VOID_FLAG`
B27: 7 | D27: 企業コード | R27: company_code | AC27: char(3) | AH27: 1 | BM27: =",`"&R27&"` "&AC27&" "&IF(AJ27="Y","NOT NULL","")&" COMMENT '"&D27&IF(AT27="","","/"&AT27)&"'" -> ,`company_code` char(3) COMMENT '企業コード' | BN27: =",`"&R27&"` "&AC27&" "&IF(AJ27="Y","NOT NULL","")&" COMMENT '"&D27&"'" -> ,`company_code` char(3) COMMENT '企業コード' | BO27: =",A.`"&R27&"` = B.`"&R27&"`" -> ,A.`company_code` = B.`company_code` | BP27: =",`"&R27&"`" -> ,`company_code`
B28: 8 | D28: 店舗コード | R28: store_code | AC28: char(5) | AH28: 2 | BM28: =",`"&R28&"` "&AC28&" "&IF(AJ28="Y","NOT NULL","")&" COMMENT '"&D28&IF(AT28="","","/"&AT28)&"'" -> ,`store_code` char(5) COMMENT '店舗コード' | BN28: =",`"&R28&"` "&AC28&" "&IF(AJ28="Y","NOT NULL","")&" COMMENT '"&D28&"'" -> ,`store_code` char(5) COMMENT '店舗コード' | BO28: =",A.`"&R28&"` = B.`"&R28&"`" -> ,A.`store_code` = B.`store_code` | BP28: =",`"&R28&"`" -> ,`store_code`
B29: 9 | D29: レジ番号 | R29: instore_code | AC29: char(5) | AH29: 3 | BM29: =",`"&R29&"` "&AC29&" "&IF(AJ29="Y","NOT NULL","")&" COMMENT '"&D29&IF(AT29="","","/"&AT29)&"'" -> ,`instore_code` char(5) COMMENT 'レジ番号' | BN29: =",`"&R29&"` "&AC29&" "&IF(AJ29="Y","NOT NULL","")&" COMMENT '"&D29&"'" -> ,`instore_code` char(5) COMMENT 'レジ番号' | BO29: =",A.`"&R29&"` = B.`"&R29&"`" -> ,A.`instore_code` = B.`instore_code` | BP29: =",`"&R29&"`" -> ,`instore_code`
B30: 13 | D30: 取引確定日時<取引確定後> | R30: record_datetime | AC30: char(16) | BM30: =",`"&R30&"` "&AC30&" "&IF(AJ30="Y","NOT NULL","")&" COMMENT '"&D30&IF(AT30="","","/"&AT30)&"'" -> ,`record_datetime` char(16) COMMENT '取引確定日時<取引確定後>' | BN30: =",`"&R30&"` "&AC30&" "&IF(AJ30="Y","NOT NULL","")&" COMMENT '"&D30&"'" -> ,`record_datetime` char(16) COMMENT '取引確定日時<取引確定後>' | BO30: =",A.`"&R30&"` = B.`"&R30&"`" -> ,A.`record_datetime` = B.`record_datetime` | BP30: =",`"&R30&"`" -> ,`record_datetime`
B31: 14 | D31: ジャーナルNO<取引確定後> | R31: journal_no | AC31: char(10) | BM31: =",`"&R31&"` "&AC31&" "&IF(AJ31="Y","NOT NULL","")&" COMMENT '"&D31&IF(AT31="","","/"&AT31)&"'" -> ,`journal_no` char(10) COMMENT 'ジャーナルNO<取引確定後>' | BN31: =",`"&R31&"` "&AC31&" "&IF(AJ31="Y","NOT NULL","")&" COMMENT '"&D31&"'" -> ,`journal_no` char(10) COMMENT 'ジャーナルNO<取引確定後>' | BO31: =",A.`"&R31&"` = B.`"&R31&"`" -> ,A.`journal_no` = B.`journal_no` | BP31: =",`"&R31&"`" -> ,`journal_no`
B32: 15 | D32: レシートNO<取引確定後> | R32: receipt_no | AC32: char(10) | AH32: 4 | BM32: =",`"&R32&"` "&AC32&" "&IF(AJ32="Y","NOT NULL","")&" COMMENT '"&D32&IF(AT32="","","/"&AT32)&"'" -> ,`receipt_no` char(10) COMMENT 'レシートNO<取引確定後>' | BN32: =",`"&R32&"` "&AC32&" "&IF(AJ32="Y","NOT NULL","")&" COMMENT '"&D32&"'" -> ,`receipt_no` char(10) COMMENT 'レシートNO<取引確定後>' | BO32: =",A.`"&R32&"` = B.`"&R32&"`" -> ,A.`receipt_no` = B.`receipt_no` | BP32: =",`"&R32&"`" -> ,`receipt_no`
B33: 16 | D33: 明細行番号 | R33: item_no | AC33: string | AH33: 5 | AT33: true : 確認済み | BM33: =",`"&R33&"` "&AC33&" "&IF(AJ33="Y","NOT NULL","")&" COMMENT '"&D33&IF(AT33="","","/"&AT33)&"'" -> ,`item_no` string COMMENT '明細行番号/true : 確認済み' | BN33: =",`"&R33&"` "&AC33&" "&IF(AJ33="Y","NOT NULL","")&" COMMENT '"&D33&"'" -> ,`item_no` string COMMENT '明細行番号' | BO33: =",A.`"&R33&"` = B.`"&R33&"`" -> ,A.`item_no` = B.`item_no` | BP33: =",`"&R33&"`" -> ,`item_no`
B34: 17 | D34: 税種説明 (tax_exclude | tax_include | tax_exempt) | BM34: =",`"&R34&"` "&AC34&" "&IF(AJ34="Y","NOT NULL","")&" COMMENT '"&D34&IF(AT34="","","/"&AT34)&"'" -> ,`` COMMENT '税種説明 (tax_exclude | tax_include | tax_exempt)' | BN34: =",`"&R34&"` "&AC34&" "&IF(AJ34="Y","NOT NULL","")&" COMMENT '"&D34&"'" -> ,`` COMMENT '税種説明 (tax_exclude | tax_include | tax_exempt)' | BO34: =",A.`"&R34&"` = B.`"&R34&"`" -> ,A.`` = B.`` | BP34: =",`"&R34&"`" -> ,``
B35: 18 | D35: 税額 | BM35: =",`"&R35&"` "&AC35&" "&IF(AJ35="Y","NOT NULL","")&" COMMENT '"&D35&IF(AT35="","","/"&AT35)&"'" -> ,`` COMMENT '税額' | BN35: =",`"&R35&"` "&AC35&" "&IF(AJ35="Y","NOT NULL","")&" COMMENT '"&D35&"'" -> ,`` COMMENT '税額' | BO35: =",A.`"&R35&"` = B.`"&R35&"`" -> ,A.`` = B.`` | BP35: =",`"&R35&"`" -> ,``
B36: 19 | D36: 外対象金額 | BM36: =",`"&R36&"` "&AC36&" "&IF(AJ36="Y","NOT NULL","")&" COMMENT '"&D36&IF(AT36="","","/"&AT36)&"'" -> ,`` COMMENT '外対象金額' | BN36: =",`"&R36&"` "&AC36&" "&IF(AJ36="Y","NOT NULL","")&" COMMENT '"&D36&"'" -> ,`` COMMENT '外対象金額' | BO36: =",A.`"&R36&"` = B.`"&R36&"`" -> ,A.`` = B.`` | BP36: =",`"&R36&"`" -> ,``
B37: 20 | BM37: =",`"&R37&"` "&AC37&" "&IF(AJ37="Y","NOT NULL","")&" COMMENT '"&D37&IF(AT37="","","/"&AT37)&"'" -> ,`` COMMENT '' | BN37: =",`"&R37&"` "&AC37&" "&IF(AJ37="Y","NOT NULL","")&" COMMENT '"&D37&"'" -> ,`` COMMENT '' | BO37: =",A.`"&R37&"` = B.`"&R37&"`" -> ,A.`` = B.`` | BP37: =",`"&R37&"`" -> ,``
B38: 21 | BM38: =",`"&R38&"` "&AC38&" "&IF(AJ38="Y","NOT NULL","")&" COMMENT '"&D38&IF(AT38="","","/"&AT38)&"'" -> ,`` COMMENT '' | BN38: =",`"&R38&"` "&AC38&" "&IF(AJ38="Y","NOT NULL","")&" COMMENT '"&D38&"'" -> ,`` COMMENT '' | BO38: =",A.`"&R38&"` = B.`"&R38&"`" -> ,A.`` = B.`` | BP38: =",`"&R38&"`" -> ,``
B39: 22 | BM39: =",`"&R39&"` "&AC39&" "&IF(AJ39="Y","NOT NULL","")&" COMMENT '"&D39&IF(AT39="","","/"&AT39)&"'" -> ,`` COMMENT '' | BN39: =",`"&R39&"` "&AC39&" "&IF(AJ39="Y","NOT NULL","")&" COMMENT '"&D39&"'" -> ,`` COMMENT '' | BO39: =",A.`"&R39&"` = B.`"&R39&"`" -> ,A.`` = B.`` | BP39: =",`"&R39&"`" -> ,``
B40: 23 | BM40: =",`"&R40&"` "&AC40&" "&IF(AJ40="Y","NOT NULL","")&" COMMENT '"&D40&IF(AT40="","","/"&AT40)&"'" -> ,`` COMMENT '' | BN40: =",`"&R40&"` "&AC40&" "&IF(AJ40="Y","NOT NULL","")&" COMMENT '"&D40&"'" -> ,`` COMMENT '' | BO40: =",A.`"&R40&"` = B.`"&R40&"`" -> ,A.`` = B.`` | BP40: =",`"&R40&"`" -> ,``
B41: 24 | BM41: =",`"&R41&"` "&AC41&" "&IF(AJ41="Y","NOT NULL","")&" COMMENT '"&D41&IF(AT41="","","/"&AT41)&"'" -> ,`` COMMENT '' | BN41: =",`"&R41&"` "&AC41&" "&IF(AJ41="Y","NOT NULL","")&" COMMENT '"&D41&"'" -> ,`` COMMENT '' | BO41: =",A.`"&R41&"` = B.`"&R41&"`" -> ,A.`` = B.`` | BP41: =",`"&R41&"`" -> ,``
B42: 25 | BM42: =",`"&R42&"` "&AC42&" "&IF(AJ42="Y","NOT NULL","")&" COMMENT '"&D42&IF(AT42="","","/"&AT42)&"'" -> ,`` COMMENT '' | BN42: =",`"&R42&"` "&AC42&" "&IF(AJ42="Y","NOT NULL","")&" COMMENT '"&D42&"'" -> ,`` COMMENT '' | BO42: =",A.`"&R42&"` = B.`"&R42&"`" -> ,A.`` = B.`` | BP42: =",`"&R42&"`" -> ,``
B43: 26
B44: 27
B45: 28
B46: 29
B49: ■インデックス情報
B50: No. | D50: Index名 | R50: カラム一覧 | AL50: プライマリキー | AP50: ユニーク | AT50: 備考
B51: 1 | D51: PRIMARY | R51: =IF(_xlfn.XLOOKUP(1,AH:AH,R:R,"",0)="","","`"&_xlfn.XLOOKUP(1,AH:AH,R:R,"",0)&"`")&IF(_xlfn.XLOOKUP(2,AH:AH,R:R,"",0)="","",",`"&_xlfn.XLOOKUP(2,AH:AH,R:R,"",0)&"`")&IF(_xlfn.XLOOKUP(3,AH:AH,R:R,"",0)="","",",`"&_xlfn.XLOOKUP(3,AH:AH,R:R,"",0)&"`")&IF(_xlfn.XLOOKUP(4,AH:AH,R:R,"",0)="","",",`"&_xlfn.XLOOKUP(4,AH:AH,R:R,"",0)&"`")&IF(_xlfn.XLOOKUP(5,AH:AH,R:R,"",0)="","",",`"&_xlfn.XLOOKUP(5,AH:AH,R:R,"",0)&"`")&IF(_xlfn.XLOOKUP(6,AH:AH,R:R,"",0)="","",",`"&_xlfn.XLOOKUP(6,AH:AH,R:R,"",0)&"`")&IF(_xlfn.XLOOKUP(7,AH:AH,R:R,"",0)="","",",`"&_xlfn.XLOOKUP(7,AH:AH,R:R,"",0)&"`")&IF(_xlfn.XLOOKUP(8,AH:AH,R:R,"",0)="","",",`"&_xlfn.XLOOKUP(8,AH:AH,R:R,"",0)&"`") -> `company_code`,`store_code`,`instore_code`,`receipt_no`,`item_no` | AL51: Y | AP51: Y | BM51: =" , PRIMARY KEY ("&IF(_xlfn.XLOOKUP(1,AH:AH,R:R,"",0)="","","`"&_xlfn.XLOOKUP(1,AH:AH,R:R,"",0)&"`")&IF(_xlfn.XLOOKUP(2,AH:AH,R:R,"",0)="","",",`"&_xlfn.XLOOKUP(2,AH:AH,R:R,"",0)&"`")&IF(_xlfn.XLOOKUP(3,AH:AH,R:R,"",0)="","",",`"&_xlfn.XLOOKUP(3,AH:AH,R:R,"",0)&"`")&IF(_xlfn.XLOOKUP(4,AH:AH,R:R,"",0)="","",",`"&_xlfn.XLOOKUP(4,AH:AH,R:R,"",0)&"`")&IF(_xlfn.XLOOKUP(5,AH:AH,R:R,"",0)="","",",`"&_xlfn.XLOOKUP(5,AH:AH,R:R,"",0)&"`")&IF(_xlfn.XLOOKUP(6,AH:AH,R:R,"",0)="","",",`"&_xlfn.XLOOKUP(6,AH:AH,R:R,"",0)&"`")&IF(_xlfn.XLOOKUP(7,AH:AH,R:R,"",0)="","",",`"&_xlfn.XLOOKUP(7,AH:AH,R:R,"",0)&"`")&IF(_xlfn.XLOOKUP(8,AH:AH,R:R,"",0)="","",",`"&_xlfn.XLOOKUP(8,AH:AH,R:R,"",0)&"`")&")," -> , PRIMARY KEY (`company_code`,`store_code`,`instore_code`,`receipt_no`,`item_no`), | BN51: =BM51 -> , PRIMARY KEY (`company_code`,`store_code`,`instore_code`,`receipt_no`,`item_no`),
BM52: KEY `RECORD_ID` (`RECORD_ID`)
...

Sheet 売上情報(値引)
A1: システム名 | K1: システム種別 | W1: =IF(表紙!W1="","",表紙!W1) -> DB定義書 | AP1: 作成者 | AT1: 作成日 | AY1: 更新者 | BC1: 更新日 | BH1: 版数
A2: =IF(表紙!A2="","",表紙!A2) -> 現金専用簡易セルフPOS | K2: =IF(表紙!K2="","",表紙!K2) | AP2: =IF(表紙!AP2="","",表紙!AP2) -> きよはら | AT2: =IF(表紙!AT2="","",表紙!AT2) -> 44652 | AY2: =IF(表紙!AY2="","",表紙!AY2) -> Thanh Nguyên | BC2: =IF(表紙!BC2="","",表紙!BC2) -> 45285 | BH2: =IF(表紙!BH2="","",表紙!BH2) -> 0.2
A4: 機能カテゴリ | H4: =IF(表紙!H4="","",表紙!H4) -> 共通 | U4: 項目 | Z4: =IF(表紙!Z4="","",表紙!Z4) | AP4: テンプレート
B7: ■テーブル情報
B8: スキーマ名 | Y8: RDBMS名
B9: 論理名 | G9: 売上情報明細 | Y9: バージョン
B10: 物理名 | G10: sales_details
B11: 備考
B19: ■カラム情報 | BM19: ="DROP TABLE IF EXISTS `"&$G$8&"`.`"&$G$10&"`;" -> DROP TABLE IF EXISTS ``.`sales_details`;
B20: No. | D20: 論理名 | R20: 物理名 | AC20: データ型 | AH20: PK | AJ20: Not Null | AM20: デフォルト | AT20: 備考 | BM20: ="CREATE TABLE `"&$G$8&"`.`"&$G$10&"` (" -> CREATE TABLE ``.`sales_details` ( | BN20: ="CREATE TABLE `TMP`.`"&G10&"` (" -> CREATE TABLE `TMP`.`sales_details` (
B21: 1 | D21: レコードID | R21: RECORD_ID | AC21: BIGINT | AH21: Y | AJ21: Y | AM21: 自動追加 | BM21: ="`"&R21&"` "&AC21&" "&IF(AJ21="Y","NOT NULL","")&" AUTO_INCREMENT COMMENT '"&D21&IF(AT21="","","/"&AT21)&"'" -> `RECORD_ID` BIGINT NOT NULL AUTO_INCREMENT COMMENT 'レコードID' | BO21: =",A.`"&R21&"` = B.`"&R21&"`" -> ,A.`RECORD_ID` = B.`RECORD_ID` | BP21: =",`"&R21&"`" -> ,`RECORD_ID`
B22: 2 | D22: レコード作成日付 | R22: RECORD_CREATE_DATE | AC22: TIMESTAMP | AJ22: Y | AM22: CURRENT_DATE | BM22: =",`"&R22&"` "&AC22&" "&IF(AJ22="Y","NOT NULL","")&" COMMENT '"&D22&IF(AT22="","","/"&AT22)&"'" -> ,`RECORD_CREATE_DATE` TIMESTAMP NOT NULL COMMENT 'レコード作成日付' | BO22: =",A.`"&R22&"` = B.`"&R22&"`" -> ,A.`RECORD_CREATE_DATE` = B.`RECORD_CREATE_DATE` | BP22: =",`"&R22&"`" -> ,`RECORD_CREATE_DATE`
B23: 3 | D23: レコード作成時間 | R23: RECORD_CREATE_TIME | AC23: BIGINT | AJ23: Y | AM23: CURRENT_TIME | BM23: =",`"&R23&"` "&AC23&" "&IF(AJ23="Y","NOT NULL","")&" COMMENT '"&D23&IF(AT23="","","/"&AT23)&"'" -> ,`RECORD_CREATE_TIME` BIGINT NOT NULL COMMENT 'レコード作成時間' | BO23: =",A.`"&R23&"` = B.`"&R23&"`" -> ,A.`RECORD_CREATE_TIME` = B.`RECORD_CREATE_TIME` | BP23: =",`"&R23&"`" -> ,`RECORD_CREATE_TIME`
B24: 4 | D24: レコード更新日付 | R24: RECORD_UPDATE_DATE | AC24: TIMESTAMP | AJ24: Y | AM24: CURRENT_DATE | AT24: トリガーにより更新 | BM24: =",`"&R24&"` "&AC24&" "&IF(AJ24="Y","NOT NULL","")&" COMMENT '"&D24&IF(AT24="","","/"&AT24)&"'" -> ,`RECORD_UPDATE_DATE` TIMESTAMP NOT NULL COMMENT 'レコード更新日付/トリガーにより更新' | BO24: =",A.`"&R24&"` = B.`"&R24&"`" -> ,A.`RECORD_UPDATE_DATE` = B.`RECORD_UPDATE_DATE` | BP24: =",`"&R24&"`" -> ,`RECORD_UPDATE_DATE`
B25: 5 | D25: レコード更新時間 | R25: RECORD_UPDATE_TIME | AC25: BIGINT | AJ25: Y | AM25: CURRENT_TIME | AT25: トリガーにより更新 | BM25: =",`"&R25&"` "&AC25&" "&IF(AJ25="Y","NOT NULL","")&" COMMENT '"&D25&IF(AT25="","","/"&AT25)&"'" -> ,`RECORD_UPDATE_TIME` BIGINT NOT NULL COMMENT 'レコード更新時間/トリガーにより更新' | BO25: =",A.`"&R25&"` = B.`"&R25&"`" -> ,A.`RECORD_UPDATE_TIME` = B.`RECORD_UPDATE_TIME` | BP25: =",`"&R25&"`" -> ,`RECORD_UPDATE_TIME`
B26: 6 | D26: レコード無効フラグ | R26: RECORD_VOID_FLAG | AC26: BOOL | AJ26: Y | AM26: "" | AT26: true:有効 / false:無効 | BM26: =",`"&R26&"` "&AC26&" "&IF(AJ26="Y","NOT NULL","")&" COMMENT '"&D26&IF(AT26="","","/"&AT26)&"'" -> ,`RECORD_VOID_FLAG` BOOL NOT NULL COMMENT 'レコード無効フラグ/true:有効 / false:無効' | BN26: `CLASS` VARCHAR ( 1 ) NOT NULL COMMENT '処理区分', | BO26: =",A.`"&R26&"` = B.`"&R26&"`" -> ,A.`RECORD_VOID_FLAG` = B.`RECORD_VOID_FLAG` | BP26: =",`"&R26&"`" -> ,`RECORD_VOID_FLAG`
B27: 7 | D27: 企業コード | R27: company_code | AC27: char(3) | BM27: =",`"&R27&"` "&AC27&" "&IF(AJ27="Y","NOT NULL","")&" COMMENT '"&D27&IF(AT27="","","/"&AT27)&"'" -> ,`company_code` char(3) COMMENT '企業コード' | BN27: =",`"&R27&"` "&AC27&" "&IF(AJ27="Y","NOT NULL","")&" COMMENT '"&D27&"'" -> ,`company_code` char(3) COMMENT '企業コード' | BO27: =",A.`"&R27&"` = B.`"&R27&"`" -> ,A.`company_code` = B.`company_code` | BP27: =",`"&R27&"`" -> ,`company_code`
B28: 8 | D28: 店舗コード | R28: store_code | AC28: char(5) | BM28: =",`"&R28&"` "&AC28&" "&IF(AJ28="Y","NOT NULL","")&" COMMENT '"&D28&IF(AT28="","","/"&AT28)&"'" -> ,`store_code` char(5) COMMENT '店舗コード' | BN28: =",`"&R28&"` "&AC28&" "&IF(AJ28="Y","NOT NULL","")&" COMMENT '"&D28&"'" -> ,`store_code` char(5) COMMENT '店舗コード' | BO28: =",A.`"&R28&"` = B.`"&R28&"`" -> ,A.`store_code` = B.`store_code` | BP28: =",`"&R28&"`" -> ,`store_code`
B29: 9 | D29: レジ番号 | R29: instore_code | AC29: char(5) | BM29: =",`"&R29&"` "&AC29&" "&IF(AJ29="Y","NOT NULL","")&" COMMENT '"&D29&IF(AT29="","","/"&AT29)&"'" -> ,`instore_code` char(5) COMMENT 'レジ番号' | BN29: =",`"&R29&"` "&AC29&" "&IF(AJ29="Y","NOT NULL","")&" COMMENT '"&D29&"'" -> ,`instore_code` char(5) COMMENT 'レジ番号' | BO29: =",A.`"&R29&"` = B.`"&R29&"`" -> ,A.`instore_code` = B.`instore_code` | BP29: =",`"&R29&"`" -> ,`instore_code`
B30: 13 | D30: 取引確定日時<取引確定後> | R30: record_datetime | AC30: char(16) | BM30: =",`"&R30&"` "&AC30&" "&IF(AJ30="Y","NOT NULL","")&" COMMENT '"&D30&IF(AT30="","","/"&AT30)&"'" -> ,`record_datetime` char(16) COMMENT '取引確定日時<取引確定後>' | BN30: =",`"&R30&"` "&AC30&" "&IF(AJ30="Y","NOT NULL","")&" COMMENT '"&D30&"'" -> ,`record_datetime` char(16) COMMENT '取引確定日時<取引確定後>' | BO30: =",A.`"&R30&"` = B.`"&R30&"`" -> ,A.`record_datetime` = B.`record_datetime` | BP30: =",`"&R30&"`" -> ,`record_datetime`
B31: 14 | D31: ジャーナルNO<取引確定後> | R31: journal_no | AC31: char(10) | BM31: =",`"&R31&"` "&AC31&" "&IF(AJ31="Y","NOT NULL","")&" COMMENT '"&D31&IF(AT31="","","/"&AT31)&"'" -> ,`journal_no` char(10) COMMENT 'ジャーナルNO<取引確定後>' | BN31: =",`"&R31&"` "&AC31&" "&IF(AJ31="Y","NOT NULL","")&" COMMENT '"&D31&"'" -> ,`journal_no` char(10) COMMENT 'ジャーナルNO<取引確定後>' | BO31: =",A.`"&R31&"` = B.`"&R31&"`" -> ,A.`journal_no` = B.`journal_no` | BP31: =",`"&R31&"`" -> ,`journal_no`
B32: 15 | D32: レシートNO<取引確定後> | R32: receipt_no | AC32: char(10) | BM32: =",`"&R32&"` "&AC32&" "&IF(AJ32="Y","NOT NULL","")&" COMMENT '"&D32&IF(AT32="","","/"&AT32)&"'" -> ,`receipt_no` char(10) COMMENT 'レシートNO<取引確定後>' | BN32: =",`"&R32&"` "&AC32&" "&IF(AJ32="Y","NOT NULL","")&" COMMENT '"&D32&"'" -> ,`receipt_no` char(10) COMMENT 'レシートNO<取引確定後>' | BO32: =",A.`"&R32&"` = B.`"&R32&"`" -> ,A.`receipt_no` = B.`receipt_no` | BP32: =",`"&R32&"`" -> ,`receipt_no`
B33: 16 | D33: 明細行番号 | R33: item_no | AC33: string | AT33: true : 確認済み | BM33: =",`"&R33&"` "&AC33&" "&IF(AJ33="Y","NOT NULL","")&" COMMENT '"&D33&IF(AT33="","","/"&AT33)&"'" -> ,`item_no` string COMMENT '明細行番号/true : 確認済み' | BN33: =",`"&R33&"` "&AC33&" "&IF(AJ33="Y","NOT NULL","")&" COMMENT '"&D33&"'" -> ,`item_no` string COMMENT '明細行番号' | BO33: =",A.`"&R33&"` = B.`"&R33&"`" -> ,A.`item_no` = B.`item_no` | BP33: =",`"&R33&"`" -> ,`item_no`
B34: 17 | D34: Scan&Go アカウントID | R34: account_id | AC34: string | BM34: =",`"&R34&"` "&AC34&" "&IF(AJ34="Y","NOT NULL","")&" COMMENT '"&D34&IF(AT34="","","/"&AT34)&"'" -> ,`account_id` string COMMENT 'Scan&Go アカウントID' | BN34: =",`"&R34&"` "&AC34&" "&IF(AJ34="Y","NOT NULL","")&" COMMENT '"&D34&"'" -> ,`account_id` string COMMENT 'Scan&Go アカウントID' | BO34: =",A.`"&R34&"` = B.`"&R34&"`" -> ,A.`account_id` = B.`account_id` | BP34: =",`"&R34&"`" -> ,`account_id`
B35: 18 | D35: Scan&Go アカウント名 | R35: account_name | AC35: string | BM35: =",`"&R35&"` "&AC35&" "&IF(AJ35="Y","NOT NULL","")&" COMMENT '"&D35&IF(AT35="","","/"&AT35)&"'" -> ,`account_name` string COMMENT 'Scan&Go アカウント名' | BN35: =",`"&R35&"` "&AC35&" "&IF(AJ35="Y","NOT NULL","")&" COMMENT '"&D35&"'" -> ,`account_name` string COMMENT 'Scan&Go アカウント名' | BO35: =",A.`"&R35&"` = B.`"&R35&"`" -> ,A.`account_name` = B.`account_name` | BP35: =",`"&R35&"`" -> ,`account_name`
B36: 19 | D36: 明細合計金額 | R36: item_total_price_fmt | AC36: string | BM36: =",`"&R36&"` "&AC36&" "&IF(AJ36="Y","NOT NULL","")&" COMMENT '"&D36&IF(AT36="","","/"&AT36)&"'" -> ,`item_total_price_fmt` string COMMENT '明細合計金額' | BN36: =",`"&R36&"` "&AC36&" "&IF(AJ36="Y","NOT NULL","")&" COMMENT '"&D36&"'" -> ,`item_total_price_fmt` string COMMENT '明細合計金額' | BO36: =",A.`"&R36&"` = B.`"&R36&"`" -> ,A.`item_total_price_fmt` = B.`item_total_price_fmt` | BP36: =",`"&R36&"`" -> ,`item_total_price_fmt`
B37: 20 | D37: まとめ値引金額 | R37: mm_discount_price_fmt | AC37: string | BM37: =",`"&R37&"` "&AC37&" "&IF(AJ37="Y","NOT NULL","")&" COMMENT '"&D37&IF(AT37="","","/"&AT37)&"'" -> ,`mm_discount_price_fmt` string COMMENT 'まとめ値引金額' | BN37: =",`"&R37&"` "&AC37&" "&IF(AJ37="Y","NOT NULL","")&" COMMENT '"&D37&"'" -> ,`mm_discount_price_fmt` string COMMENT 'まとめ値引金額' | BO37: =",A.`"&R37&"` = B.`"&R37&"`" -> ,A.`mm_discount_price_fmt` = B.`mm_discount_price_fmt` | BP37: =",`"&R37&"`" -> ,`mm_discount_price_fmt`
B38: 21 | D38: 小計金額 | R38: subtotal_price_fmt | AC38: string | BM38: =",`"&R38&"` "&AC38&" "&IF(AJ38="Y","NOT NULL","")&" COMMENT '"&D38&IF(AT38="","","/"&AT38)&"'" -> ,`subtotal_price_fmt` string COMMENT '小計金額' | BN38: =",`"&R38&"` "&AC38&" "&IF(AJ38="Y","NOT NULL","")&" COMMENT '"&D38&"'" -> ,`subtotal_price_fmt` string COMMENT '小計金額' | BO38: =",A.`"&R38&"` = B.`"&R38&"`" -> ,A.`subtotal_price_fmt` = B.`subtotal_price_fmt` | BP38: =",`"&R38&"`" -> ,`subtotal_price_fmt`
B39: 22 | D39: 小計値引金額 | R39: subtotal_discount_price_fmt | AC39: string | BM39: =",`"&R39&"` "&AC39&" "&IF(AJ39="Y","NOT NULL","")&" COMMENT '"&D39&IF(AT39="","","/"&AT39)&"'" -> ,`subtotal_discount_price_fmt` string COMMENT '小計値引金額' | BN39: =",`"&R39&"` "&AC39&" "&IF(AJ39="Y","NOT NULL","")&" COMMENT '"&D39&"'" -> ,`subtotal_discount_price_fmt` string COMMENT '小計値引金額' | BO39: =",A.`"&R39&"` = B.`"&R39&"`" -> ,A.`subtotal_discount_price_fmt` = B.`subtotal_discount_price_fmt` | BP39: =",`"&R39&"`" -> ,`subtotal_discount_price_fmt`
B40: 23 | D40: 外税合計 | R40: total_tax_excluded_fmt | AC40: string | BM40: =",`"&R40&"` "&AC40&" "&IF(AJ40="Y","NOT NULL","")&" COMMENT '"&D40&IF(AT40="","","/"&AT40)&"'" -> ,`total_tax_excluded_fmt` string COMMENT '外税合計' | BN40: =",`"&R40&"` "&AC40&" "&IF(AJ40="Y","NOT NULL","")&" COMMENT '"&D40&"'" -> ,`total_tax_excluded_fmt` string COMMENT '外税合計' | BO40: =",A.`"&R40&"` = B.`"&R40&"`" -> ,A.`total_tax_excluded_fmt` = B.`total_tax_excluded_fmt` | BP40: =",`"&R40&"`" -> ,`total_tax_excluded_fmt`
B41: 24 | D41: 合計金額 （=小計金額 - 小計値引金額 + 外税合計） | R41: total_price_fmt | AC41: string | BM41: =",`"&R41&"` "&AC41&" "&IF(AJ41="Y","NOT NULL","")&" COMMENT '"&D41&IF(AT41="","","/"&AT41)&"'" -> ,`total_price_fmt` string COMMENT '合計金額 （=小計金額 - 小計値引金額 + 外税合計）' | BN41: =",`"&R41&"` "&AC41&" "&IF(AJ41="Y","NOT NULL","")&" COMMENT '"&D41&"'" -> ,`total_price_fmt` string COMMENT '合計金額 （=小計金額 - 小計値引金額 + 外税合計）' | BO41: =",A.`"&R41&"` = B.`"&R41&"`" -> ,A.`total_price_fmt` = B.`total_price_fmt` | BP41: =",`"&R41&"`" -> ,`total_price_fmt`
B42: 25 | D42: 合計点数 | R42: total_quantity_fmt | AC42: string | BM42: =",`"&R42&"` "&AC42&" "&IF(AJ42="Y","NOT NULL","")&" COMMENT '"&D42&IF(AT42="","","/"&AT42)&"'" -> ,`total_quantity_fmt` string COMMENT '合計点数' | BN42: =",`"&R42&"` "&AC42&" "&IF(AJ42="Y","NOT NULL","")&" COMMENT '"&D42&"'" -> ,`total_quantity_fmt` string COMMENT '合計点数' | BO42: =",A.`"&R42&"` = B.`"&R42&"`" -> ,A.`total_quantity_fmt` = B.`total_quantity_fmt` | BP42: =",`"&R42&"`" -> ,`total_quantity_fmt`
B43: 26
B44: 27
B45: 28
B46: 29
B49: ■インデックス情報
B50: No. | D50: Index名 | R50: カラム一覧 | AL50: プライマリキー | AP50: ユニーク | AT50: 備考
B51: 1 | D51: PRIMARY | R51: =IF(_xlfn.XLOOKUP(1,AH:AH,R:R,"",0)="","","`"&_xlfn.XLOOKUP(1,AH:AH,R:R,"",0)&"`")&IF(_xlfn.XLOOKUP(2,AH:AH,R:R,"",0)="","",",`"&_xlfn.XLOOKUP(2,AH:AH,R:R,"",0)&"`")&IF(_xlfn.XLOOKUP(3,AH:AH,R:R,"",0)="","",",`"&_xlfn.XLOOKUP(3,AH:AH,R:R,"",0)&"`")&IF(_xlfn.XLOOKUP(4,AH:AH,R:R,"",0)="","",",`"&_xlfn.XLOOKUP(4,AH:AH,R:R,"",0)&"`")&IF(_xlfn.XLOOKUP(5,AH:AH,R:R,"",0)="","",",`"&_xlfn.XLOOKUP(5,AH:AH,R:R,"",0)&"`")&IF(_xlfn.XLOOKUP(6,AH:AH,R:R,"",0)="","",",`"&_xlfn.XLOOKUP(6,AH:AH,R:R,"",0)&"`")&IF(_xlfn.XLOOKUP(7,AH:AH,R:R,"",0)="","",",`"&_xlfn.XLOOKUP(7,AH:AH,R:R,"",0)&"`")&IF(_xlfn.XLOOKUP(8,AH:AH,R:R,"",0)="","",",`"&_xlfn.XLOOKUP(8,AH:AH,R:R,"",0)&"`") | AL51: Y | AP51: Y | BM51: =" , PRIMARY KEY ("&IF(_xlfn.XLOOKUP(1,AH:AH,R:R,"",0)="","","`"&_xlfn.XLOOKUP(1,AH:AH,R:R,"",0)&"`")&IF(_xlfn.XLOOKUP(2,AH:AH,R:R,"",0)="","",",`"&_xlfn.XLOOKUP(2,AH:AH,R:R,"",0)&"`")&IF(_xlfn.XLOOKUP(3,AH:AH,R:R,"",0)="","",",`"&_xlfn.XLOOKUP(3,AH:AH,R:R,"",0)&"`")&IF(_xlfn.XLOOKUP(4,AH:AH,R:R,"",0)="","",",`"&_xlfn.XLOOKUP(4,AH:AH,R:R,"",0)&"`")&IF(_xlfn.XLOOKUP(5,AH:AH,R:R,"",0)="","",",`"&_xlfn.XLOOKUP(5,AH:AH,R:R,"",0)&"`")&IF(_xlfn.XLOOKUP(6,AH:AH,R:R,"",0)="","",",`"&_xlfn.XLOOKUP(6,AH:AH,R:R,"",0)&"`")&IF(_xlfn.XLOOKUP(7,AH:AH,R:R,"",0)="","",",`"&_xlfn.XLOOKUP(7,AH:AH,R:R,"",0)&"`")&IF(_xlfn.XLOOKUP(8,AH:AH,R:R,"",0)="","",",`"&_xlfn.XLOOKUP(8,AH:AH,R:R,"",0)&"`")&")," -> , PRIMARY KEY (), | BN51: =BM51 -> , PRIMARY KEY (),
BM52: KEY `RECORD_ID` (`RECORD_ID`)
...

Sheet 売上情報(支払)
A1: システム名 | K1: システム種別 | W1: =IF(表紙!W1="","",表紙!W1) -> DB定義書 | AP1: 作成者 | AT1: 作成日 | AY1: 更新者 | BC1: 更新日 | BH1: 版数
A2: =IF(表紙!A2="","",表紙!A2) -> 現金専用簡易セルフPOS | K2: =IF(表紙!K2="","",表紙!K2) | AP2: =IF(表紙!AP2="","",表紙!AP2) -> きよはら | AT2: =IF(表紙!AT2="","",表紙!AT2) -> 44652 | AY2: =IF(表紙!AY2="","",表紙!AY2) -> Thanh Nguyên | BC2: =IF(表紙!BC2="","",表紙!BC2) -> 45285 | BH2: =IF(表紙!BH2="","",表紙!BH2) -> 0.2
A4: 機能カテゴリ | H4: =IF(表紙!H4="","",表紙!H4) -> 共通 | U4: 項目 | Z4: =IF(表紙!Z4="","",表紙!Z4) | AP4: テンプレート
B7: ■テーブル情報
B8: スキーマ名 | Y8: RDBMS名
B9: 論理名 | G9: 売上情報明細 | Y9: バージョン
B10: 物理名 | G10: sales_details
B11: 備考
B19: ■カラム情報 | BM19: ="DROP TABLE IF EXISTS `"&$G$8&"`.`"&$G$10&"`;" -> DROP TABLE IF EXISTS ``.`sales_details`;
B20: No. | D20: 論理名 | R20: 物理名 | AC20: データ型 | AH20: PK | AJ20: Not Null | AM20: デフォルト | AT20: 備考 | BM20: ="CREATE TABLE `"&$G$8&"`.`"&$G$10&"` (" -> CREATE TABLE ``.`sales_details` ( | BN20: ="CREATE TABLE `TMP`.`"&G10&"` (" -> CREATE TABLE `TMP`.`sales_details` (
B21: 1 | D21: レコードID | R21: RECORD_ID | AC21: BIGINT | AH21: Y | AJ21: Y | AM21: 自動追加 | BM21: ="`"&R21&"` "&AC21&" "&IF(AJ21="Y","NOT NULL","")&" AUTO_INCREMENT COMMENT '"&D21&IF(AT21="","","/"&AT21)&"'" -> `RECORD_ID` BIGINT NOT NULL AUTO_INCREMENT COMMENT 'レコードID' | BO21: =",A.`"&R21&"` = B.`"&R21&"`" -> ,A.`RECORD_ID` = B.`RECORD_ID` | BP21: =",`"&R21&"`" -> ,`RECORD_ID`
B22: 2 | D22: レコード作成日付 | R22: RECORD_CREATE_DATE | AC22: TIMESTAMP | AJ22: Y | AM22: CURRENT_DATE | BM22: =",`"&R22&"` "&AC22&" "&IF(AJ22="Y","NOT NULL","")&" COMMENT '"&D22&IF(AT22="","","/"&AT22)&"'" -> ,`RECORD_CREATE_DATE` TIMESTAMP NOT NULL COMMENT 'レコード作成日付' | BO22: =",A.`"&R22&"` = B.`"&R22&"`" -> ,A.`RECORD_CREATE_DATE` = B.`RECORD_CREATE_DATE` | BP22: =",`"&R22&"`" -> ,`RECORD_CREATE_DATE`
B23: 3 | D23: レコード作成時間 | R23: RECORD_CREATE_TIME | AC23: BIGINT | AJ23: Y | AM23: CURRENT_TIME | BM23: =",`"&R23&"` "&AC23&" "&IF(AJ23="Y","NOT NULL","")&" COMMENT '"&D23&IF(AT23="","","/"&AT23)&"'" -> ,`RECORD_CREATE_TIME` BIGINT NOT NULL COMMENT 'レコード作成時間' | BO23: =",A.`"&R23&"` = B.`"&R23&"`" -> ,A.`RECORD_CREATE_TIME` = B.`RECORD_CREATE_TIME` | BP23: =",`"&R23&"`" -> ,`RECORD_CREATE_TIME`
B24: 4 | D24: レコード更新日付 | R24: RECORD_UPDATE_DATE | AC24: TIMESTAMP | AJ24: Y | AM24: CURRENT_DATE | AT24: トリガーにより更新 | BM24: =",`"&R24&"` "&AC24&" "&IF(AJ24="Y","NOT NULL","")&" COMMENT '"&D24&IF(AT24="","","/"&AT24)&"'" -> ,`RECORD_UPDATE_DATE` TIMESTAMP NOT NULL COMMENT 'レコード更新日付/トリガーにより更新' | BO24: =",A.`"&R24&"` = B.`"&R24&"`" -> ,A.`RECORD_UPDATE_DATE` = B.`RECORD_UPDATE_DATE` | BP24: =",`"&R24&"`" -> ,`RECORD_UPDATE_DATE`
B25: 5 | D25: レコード更新時間 | R25: RECORD_UPDATE_TIME | AC25: BIGINT | AJ25: Y | AM25: CURRENT_TIME | AT25: トリガーにより更新 | BM25: =",`"&R25&"` "&AC25&" "&IF(AJ25="Y","NOT NULL","")&" COMMENT '"&D25&IF(AT25="","","/"&AT25)&"'" -> ,`RECORD_UPDATE_TIME` BIGINT NOT NULL COMMENT 'レコード更新時間/トリガーにより更新' | BO25: =",A.`"&R25&"` = B.`"&R25&"`" -> ,A.`RECORD_UPDATE_TIME` = B.`RECORD_UPDATE_TIME` | BP25: =",`"&R25&"`" -> ,`RECORD_UPDATE_TIME`
B26: 6 | D26: レコード無効フラグ | R26: RECORD_VOID_FLAG | AC26: BOOL | AJ26: Y | AM26: "" | AT26: true:有効 / false:無効 | BM26: =",`"&R26&"` "&AC26&" "&IF(AJ26="Y","NOT NULL","")&" COMMENT '"&D26&IF(AT26="","","/"&AT26)&"'" -> ,`RECORD_VOID_FLAG` BOOL NOT NULL COMMENT 'レコード無効フラグ/true:有効 / false:無効' | BN26: `CLASS` VARCHAR ( 1 ) NOT NULL COMMENT '処理区分', | BO26: =",A.`"&R26&"` = B.`"&R26&"`" -> ,A.`RECORD_VOID_FLAG` = B.`RECORD_VOID_FLAG` | BP26: =",`"&R26&"`" -> ,`RECORD_VOID_FLAG`
B27: 7 | D27: 企業コード | R27: company_code | AC27: char(3) | BM27: =",`"&R27&"` "&AC27&" "&IF(AJ27="Y","NOT NULL","")&" COMMENT '"&D27&IF(AT27="","","/"&AT27)&"'" -> ,`company_code` char(3) COMMENT '企業コード' | BN27: =",`"&R27&"` "&AC27&" "&IF(AJ27="Y","NOT NULL","")&" COMMENT '"&D27&"'" -> ,`company_code` char(3) COMMENT '企業コード' | BO27: =",A.`"&R27&"` = B.`"&R27&"`" -> ,A.`company_code` = B.`company_code` | BP27: =",`"&R27&"`" -> ,`company_code`
B28: 8 | D28: 店舗コード | R28: store_code | AC28: char(5) | BM28: =",`"&R28&"` "&AC28&" "&IF(AJ28="Y","NOT NULL","")&" COMMENT '"&D28&IF(AT28="","","/"&AT28)&"'" -> ,`store_code` char(5) COMMENT '店舗コード' | BN28: =",`"&R28&"` "&AC28&" "&IF(AJ28="Y","NOT NULL","")&" COMMENT '"&D28&"'" -> ,`store_code` char(5) COMMENT '店舗コード' | BO28: =",A.`"&R28&"` = B.`"&R28&"`" -> ,A.`store_code` = B.`store_code` | BP28: =",`"&R28&"`" -> ,`store_code`
B29: 9 | D29: レジ番号 | R29: instore_code | AC29: char(5) | BM29: =",`"&R29&"` "&AC29&" "&IF(AJ29="Y","NOT NULL","")&" COMMENT '"&D29&IF(AT29="","","/"&AT29)&"'" -> ,`instore_code` char(5) COMMENT 'レジ番号' | BN29: =",`"&R29&"` "&AC29&" "&IF(AJ29="Y","NOT NULL","")&" COMMENT '"&D29&"'" -> ,`instore_code` char(5) COMMENT 'レジ番号' | BO29: =",A.`"&R29&"` = B.`"&R29&"`" -> ,A.`instore_code` = B.`instore_code` | BP29: =",`"&R29&"`" -> ,`instore_code`
B30: 13 | D30: 取引確定日時<取引確定後> | R30: record_datetime | AC30: char(16) | BM30: =",`"&R30&"` "&AC30&" "&IF(AJ30="Y","NOT NULL","")&" COMMENT '"&D30&IF(AT30="","","/"&AT30)&"'" -> ,`record_datetime` char(16) COMMENT '取引確定日時<取引確定後>' | BN30: =",`"&R30&"` "&AC30&" "&IF(AJ30="Y","NOT NULL","")&" COMMENT '"&D30&"'" -> ,`record_datetime` char(16) COMMENT '取引確定日時<取引確定後>' | BO30: =",A.`"&R30&"` = B.`"&R30&"`" -> ,A.`record_datetime` = B.`record_datetime` | BP30: =",`"&R30&"`" -> ,`record_datetime`
B31: 14 | D31: ジャーナルNO<取引確定後> | R31: journal_no | AC31: char(10) | BM31: =",`"&R31&"` "&AC31&" "&IF(AJ31="Y","NOT NULL","")&" COMMENT '"&D31&IF(AT31="","","/"&AT31)&"'" -> ,`journal_no` char(10) COMMENT 'ジャーナルNO<取引確定後>' | BN31: =",`"&R31&"` "&AC31&" "&IF(AJ31="Y","NOT NULL","")&" COMMENT '"&D31&"'" -> ,`journal_no` char(10) COMMENT 'ジャーナルNO<取引確定後>' | BO31: =",A.`"&R31&"` = B.`"&R31&"`" -> ,A.`journal_no` = B.`journal_no` | BP31: =",`"&R31&"`" -> ,`journal_no`
B32: 15 | D32: レシートNO<取引確定後> | R32: receipt_no | AC32: char(10) | BM32: =",`"&R32&"` "&AC32&" "&IF(AJ32="Y","NOT NULL","")&" COMMENT '"&D32&IF(AT32="","","/"&AT32)&"'" -> ,`receipt_no` char(10) COMMENT 'レシートNO<取引確定後>' | BN32: =",`"&R32&"` "&AC32&" "&IF(AJ32="Y","NOT NULL","")&" COMMENT '"&D32&"'" -> ,`receipt_no` char(10) COMMENT 'レシートNO<取引確定後>' | BO32: =",A.`"&R32&"` = B.`"&R32&"`" -> ,A.`receipt_no` = B.`receipt_no` | BP32: =",`"&R32&"`" -> ,`receipt_no`
B33: 16 | D33: 明細行番号 | R33: item_no | AC33: string | AT33: true : 確認済み | BM33: =",`"&R33&"` "&AC33&" "&IF(AJ33="Y","NOT NULL","")&" COMMENT '"&D33&IF(AT33="","","/"&AT33)&"'" -> ,`item_no` string COMMENT '明細行番号/true : 確認済み' | BN33: =",`"&R33&"` "&AC33&" "&IF(AJ33="Y","NOT NULL","")&" COMMENT '"&D33&"'" -> ,`item_no` string COMMENT '明細行番号' | BO33: =",A.`"&R33&"` = B.`"&R33&"`" -> ,A.`item_no` = B.`item_no` | BP33: =",`"&R33&"`" -> ,`item_no`
B34: 17 | BM34: =",`"&R34&"` "&AC34&" "&IF(AJ34="Y","NOT NULL","")&" COMMENT '"&D34&IF(AT34="","","/"&AT34)&"'" -> ,`` COMMENT '' | BN34: =",`"&R34&"` "&AC34&" "&IF(AJ34="Y","NOT NULL","")&" COMMENT '"&D34&"'" -> ,`` COMMENT '' | BO34: =",A.`"&R34&"` = B.`"&R34&"`" -> ,A.`` = B.`` | BP34: =",`"&R34&"`" -> ,``
B35: 18 | BM35: =",`"&R35&"` "&AC35&" "&IF(AJ35="Y","NOT NULL","")&" COMMENT '"&D35&IF(AT35="","","/"&AT35)&"'" -> ,`` COMMENT '' | BN35: =",`"&R35&"` "&AC35&" "&IF(AJ35="Y","NOT NULL","")&" COMMENT '"&D35&"'" -> ,`` COMMENT '' | BO35: =",A.`"&R35&"` = B.`"&R35&"`" -> ,A.`` = B.`` | BP35: =",`"&R35&"`" -> ,``
B36: 19 | BM36: =",`"&R36&"` "&AC36&" "&IF(AJ36="Y","NOT NULL","")&" COMMENT '"&D36&IF(AT36="","","/"&AT36)&"'" -> ,`` COMMENT '' | BN36: =",`"&R36&"` "&AC36&" "&IF(AJ36="Y","NOT NULL","")&" COMMENT '"&D36&"'" -> ,`` COMMENT '' | BO36: =",A.`"&R36&"` = B.`"&R36&"`" -> ,A.`` = B.`` | BP36: =",`"&R36&"`" -> ,``
B37: 20 | BM37: =",`"&R37&"` "&AC37&" "&IF(AJ37="Y","NOT NULL","")&" COMMENT '"&D37&IF(AT37="","","/"&AT37)&"'" -> ,`` COMMENT '' | BN37: =",`"&R37&"` "&AC37&" "&IF(AJ37="Y","NOT NULL","")&" COMMENT '"&D37&"'" -> ,`` COMMENT '' | BO37: =",A.`"&R37&"` = B.`"&R37&"`" -> ,A.`` = B.`` | BP37: =",`"&R37&"`" -> ,``
B38: 21 | BM38: =",`"&R38&"` "&AC38&" "&IF(AJ38="Y","NOT NULL","")&" COMMENT '"&D38&IF(AT38="","","/"&AT38)&"'" -> ,`` COMMENT '' | BN38: =",`"&R38&"` "&AC38&" "&IF(AJ38="Y","NOT NULL","")&" COMMENT '"&D38&"'" -> ,`` COMMENT '' | BO38: =",A.`"&R38&"` = B.`"&R38&"`" -> ,A.`` = B.`` | BP38: =",`"&R38&"`" -> ,``
B39: 22 | BM39: =",`"&R39&"` "&AC39&" "&IF(AJ39="Y","NOT NULL","")&" COMMENT '"&D39&IF(AT39="","","/"&AT39)&"'" -> ,`` COMMENT '' | BN39: =",`"&R39&"` "&AC39&" "&IF(AJ39="Y","NOT NULL","")&" COMMENT '"&D39&"'" -> ,`` COMMENT '' | BO39: =",A.`"&R39&"` = B.`"&R39&"`" -> ,A.`` = B.`` | BP39: =",`"&R39&"`" -> ,``
