Workbook

Sheet 表紙
A1: システム名 | K1: システム種別 | W1: 詳細設計書 | AP1: 作成者 | AT1: 作成日 | AY1: 更新者 | BC1: 更新日 | BH1: 版数
A2: POSサーバー | K2: POSサーバ | AP2: =改訂履歴!$H$11 -> TuyenNH | AT2: =改訂履歴!$B$11 -> 45460 | AY2: =LOOKUP(2,1/(改訂履歴!H11:H30000<>""),改訂履歴!H11:H30000) -> DuNT | BC2: =LOOKUP(2,1/(改訂履歴!B11:B30000<>""),改訂履歴!B11:B30000) -> 45545 | BH2: =LOOKUP(2,1/(改訂履歴!O11:O30000<>""),改訂履歴!O11:O30000) -> 0.13
A4: 機能カテゴリ | H4: AP4002 | U4: 項目 | Z4: API設計書 | AP4: {=RIGHT(CELL("filename",$A$1),LEN(CELL("filename",$A$1))-FIND("]",CELL("filename",$A$1)))} -> 表紙
L16: POSサーバーの詳細設計書
L24: =K2&"/"&H4&"/"&Z4 -> POSサーバ/AP4002/API設計書
Q44: 承認日 | AA44: 承認者 | AQ44: 版数

Sheet 改訂履歴
A1: システム名 | K1: システム種別 | W1: =IF(表紙!W1="","",表紙!W1) -> 詳細設計書 | AP1: 作成者 | AT1: 作成日 | AY1: 更新者 | BC1: 更新日 | BH1: 版数
A2: =IF(表紙!A2="","",表紙!A2) -> POSサーバー | K2: =IF(表紙!K2="","",表紙!K2) -> POSサーバ | AP2: =IF(表紙!AP2="","",表紙!AP2) -> TuyenNH | AT2: =IF(表紙!AT2="","",表紙!AT2) -> 45460 | AY2: =IF(表紙!AY2="","",表紙!AY2) -> DuNT | BC2: =IF(表紙!BC2="","",表紙!BC2) -> 45545 | BH2: =IF(表紙!BH2="","",表紙!BH2) -> 0.13
A4: 機能カテゴリー | H4: =IF(表紙!H4="","",表紙!H4) -> AP4002 | U4: 項目 | Z4: =IF(表紙!Z4="","",表紙!Z4) -> API設計書 | AP4: {=RIGHT(CELL("filename",$A$1),LEN(CELL("filename",$A$1))-FIND("]",CELL("filename",$A$1)))} -> 改訂履歴
B8: ■改訂履歴
B10: 更新日 | H10: 更新者 | O10: 版数 | S10: 更新内容 | AX10: 承認日 | BD10: 承認者
B11: 45460 | H11: TuyenNH | O11: 0.1 | S11: 新規
B13: 45482 | H13: AnhDD | O13: 0.11 | S13: operation_typeのバリデーションチェックを追加
B15: 45520 | H15: TuyenNH | O15: 0.12 | S15: AP4002
S16: 従業員名の新規作成・更新時に「,」のバリデーションチェックを削除する。
B17: 45545 | H17: DuNT | O17: 0.13 | S17: AP4002
S18: URLを変更し、従業員コードを7桁にする。

Sheet 処理フロー凡例
A1: システム名 | K1: システム種別 | W1: =IF(表紙!W1="","",表紙!W1) -> 詳細設計書 | AP1: 作成者 | AT1: 作成日 | AY1: 更新者 | BC1: 更新日 | BH1: 版数
A2: =IF(表紙!A2="","",表紙!A2) -> POSサーバー | K2: =IF(表紙!K2="","",表紙!K2) -> POSサーバ | AP2: =IF(表紙!AP2="","",表紙!AP2) -> TuyenNH | AT2: =IF(表紙!AT2="","",表紙!AT2) -> 45460 | AY2: =IF(表紙!AY2="","",表紙!AY2) -> DuNT | BC2: =IF(表紙!BC2="","",表紙!BC2) -> 45545 | BH2: =IF(表紙!BH2="","",表紙!BH2) -> 0.13
A4: 機能カテゴリ | H4: =IF(表紙!H4="","",表紙!H4) -> AP4002 | U4: 項目 | Z4: =IF(表紙!Z4="","",表紙!Z4) -> API設計書 | AP4: =MID(CELL("filename",A1),FIND("]",CELL("filename",A1))+1,255) -> 処理フロー凡例
B7: ●API処理フロー

Sheet AP4002
A1: システム名 | K1: システム種別 | W1: =IF(表紙!W1="","",表紙!W1) -> 詳細設計書 | AP1: 作成者 | AT1: 作成日 | AY1: 更新者 | BC1: 更新日 | BH1: 版数
A2: =IF(表紙!A2="","",表紙!A2) -> POSサーバー | K2: =IF(表紙!K2="","",表紙!K2) -> POSサーバ | AP2: =IF(表紙!AP2="","",表紙!AP2) -> TuyenNH | AT2: =IF(表紙!AT2="","",表紙!AT2) -> 45460 | AY2: =IF(表紙!AY2="","",表紙!AY2) -> DuNT | BC2: =IF(表紙!BC2="","",表紙!BC2) -> 45545 | BH2: =IF(表紙!BH2="","",表紙!BH2) -> 0.13
A4: 機能カテゴリ | H4: =IF(表紙!H4="","",表紙!H4) -> AP4002 | U4: 項目 | Z4: =IF(表紙!Z4="","",表紙!Z4) -> API設計書 | AP4: =MID(CELL("filename",A1),FIND("]",CELL("filename",A1))+1,255) -> AP4002
B7: 1. 概要
C9: 店舗で働く従業員情報を新規作成または編集する。
B11: 2. リクエスト
C13: 2.1 Request URL
C15: No. | E15: URL | AG15: HTTPメソッド | AQ15: 備考
C16: 1 | E16: api/v1/employees/maintenance | AG16: POST | AQ16: -
C18: 2. 2 Request Header
C20: No. | E20: ヘッダー | L20: 必須 | O20: 型 | S20: デフォルト値 | Z20: 項目説明 | AQ20: 備考
C21: 1 | E21: Authorization | L21: ○ | O21: String | S21: - | Z21: Api key | AQ21: 代表ユーザーを認証するAPIキー値 フォーマット："Bearer {api_key}"
C23: 2 | E23: Accept | L23: - | O23: String | S23: - | Z23: Accept | AQ23: サーバーが返却できるデータ種類情報を説明する。
C24: 3 | E24: Content-Type | L24: ○ | O24: String | S24: - | Z24: Content-Type | AQ24: 送信リクエストの本文情報のタイプを定義する。例: application/json, mutilpart/form-data. 転送データのタイプによって、content-typeが必須又は必須ではない。例： ・入力がjsonの場合、content-typeが必須であり、application/jsonの値を受け取る。
C31: 4 | E31: User-Agent | L31: - | O31: String | S31: - | Z31: User-Agent | AQ31: サーバーを呼び出すクライアントのアプリケーション/ソフトウェア/ブラウザを定義する。
C32: 5 | E32: Accept-Encoding | L32: - | O32: String | S32: - | Z32: Accept-Encoding | AQ32: データ暗号化アルゴリズムを定義する。サーバーから受信したデータに使用できる： zip、gzip、png、gif等
C34: 2.3 Query Parameter/ path parameter
C36: No. | E36: パラメータ | L36: 必須 | O36: 型 | S36: デフォルト値 | Z36: 項目説明 | AQ36: 備考
C37: なし
C39: 2.4 Request Body
C41: No. | E41: パラメータ | L41: 必須 | O41: 型 | S41: デフォルト値 | Z41: 項目説明 | AQ41: 備考
C42: 1 | E42: employee_masters | O42: Array | S42: - | Z42: - | AQ42: 従業員データリスト
C43: 2 | E43: record_id | O43: Bigint | S43: - | Z43: employee_master.record_id | AQ43: ・従業員を新規作成する場合、record_idをnullとして渡す。 ・従業員を編集する場合、該当するrecord_idを渡す。
C45: 3 | E45: selected_store | L45: ○ | O45: String | S45: - | Z45: employee_master.store_code | AQ45: ・メッセージ = MSG_VAL_001で入力必須のバリデーションチェック。その中 ：{0}が店舗である。
C46: 4 | E46: employee_code | L46: ○ | O46: String | S46: - | Z46: employee_master.code | AQ46: ・メッセージ = MSG_VAL_001で入力必須のバリデーションチェック。その中 ：{0}が「従業員コード」である。 ・メッセージ = MSG_VAL_006でバリデーションチェック：数字。その中： {0} が「従業員コード」である。 ・メッセージ=MSG_VAL_004でバリデーションチェック：最大7桁。その中：{0}が従業員コードであり、{1}が{7}である。
C48: 5 | E48: employee_name | L48: ○ | O48: String | S48: - | Z48: employee_master.name | AQ48: ・メッセージ = MSG_VAL_001で入力必須のバリデーションチェック。その中 ：{0}が「従業員名」である。 ・メッセージ=MSG_VAL_004でバリデーションチェック：最大50桁。その中：{0}が従業員名であり、{1}が{50}である。
C49: 6 | E49: description | O49: String | S49: - | Z49: employee_master.description | AQ49: ・メッセージ=MSG_VAL_004でバリデーションチェック：最大50桁。その中：{0}が従業区分員説明であり、{1}が{50}である。
C50: 7 | E50: operation_type | O50: Smallint | S50: - | Z50: - | AQ50: ・新規作成の場合、operation_typeを「1」として渡す。 ・編集の場合、operation_type を「2」として渡す。 ・削除の場合、operation_typeを「3」として渡す。 値が上記の3つの値以外の場合、メッセージ= MSG_VAL_019を返す。 * 備考： ・レコードを新規作成する=>作成されたレコードの削除：[employee_masters]従業員データリストからそのレコードを削除する。 レコードを更新する=> 編集されたレコードを削除する。operation_type = 3で渡す。 ・レコードを更新する => 編集されたレコードを削除する。 => レコードの削除をキャンセルする：operation_type = 2で渡し、編集内容を更新する。
C55: ※サンプル
C57: "employee_masters": [
C58: {
C59: "record_id": null,
C60: "selected_store": "09176",
C61: "employee_code": "002743",
C62: "employee_name": "Luvina",
C63: "description": "Test",
C64: "operation_type": 1
C65: }
C66: ]
B68: 3. レスポンス
...

Sheet 処理フロー
A1: システム名 | K1: システム種別 | W1: =IF(表紙!W1="","",表紙!W1) -> 詳細設計書 | AP1: 作成者 | AT1: 作成日 | AY1: 更新者 | BC1: 更新日 | BH1: 版数
A2: =IF(表紙!A2="","",表紙!A2) -> POSサーバー | K2: =IF(表紙!K2="","",表紙!K2) -> POSサーバ | AP2: =IF(表紙!AP2="","",表紙!AP2) -> TuyenNH | AT2: =IF(表紙!AT2="","",表紙!AT2) -> 45460 | AY2: =IF(表紙!AY2="","",表紙!AY2) -> DuNT | BC2: =IF(表紙!BC2="","",表紙!BC2) -> 45545 | BH2: =IF(表紙!BH2="","",表紙!BH2) -> 0.13
A4: 機能カテゴリ | H4: =IF(表紙!H4="","",表紙!H4) -> AP4002 | U4: 項目 | Z4: =IF(表紙!Z4="","",表紙!Z4) -> API設計書 | AP4: =MID(CELL("filename",A1),FIND("]",CELL("filename",A1))+1,255) -> 処理フロー

Sheet テンプレート
A1: システム名 | K1: システム種別 | W1: =IF(表紙!W1="","",表紙!W1) -> 詳細設計書 | AP1: 作成者 | AT1: 作成日 | AY1: 更新者 | BC1: 更新日 | BH1: 版数
A2: =IF(表紙!A2="","",表紙!A2) -> POSサーバー | K2: =IF(表紙!K2="","",表紙!K2) -> POSサーバ | AP2: =IF(表紙!AP2="","",表紙!AP2) -> TuyenNH | AT2: =IF(表紙!AT2="","",表紙!AT2) -> 45460 | AY2: =IF(表紙!AY2="","",表紙!AY2) -> DuNT | BC2: =IF(表紙!BC2="","",表紙!BC2) -> 45545 | BH2: =IF(表紙!BH2="","",表紙!BH2) -> 0.13
A4: 機能カテゴリ | H4: =IF(表紙!H4="","",表紙!H4) -> AP4002 | U4: 項目 | Z4: =IF(表紙!Z4="","",表紙!Z4) -> API設計書 | AP4: =MID(CELL("filename",A1),FIND("]",CELL("filename",A1))+1,255) -> テンプレート
