Workbook

Sheet 表紙
A1: システム名 | K1: システム種別 | W1: 詳細設計書 | AP1: 作成者 | AT1: 作成日 | AY1: 更新者 | BC1: 更新日 | BH1: 版数
A2: POSサーバー | K2: POSサーバー | AP2: =改訂履歴!$H$11 -> SonMNT | AT2: =改訂履歴!$B$11 -> 45462 | AY2: =LOOKUP(2,1/(改訂履歴!H11:H30000<>""),改訂履歴!H11:H30000) -> SonMNT | BC2: =LOOKUP(2,1/(改訂履歴!B11:B30000<>""),改訂履歴!B11:B30000) -> 45462 | BH2: =LOOKUP(2,1/(改訂履歴!O11:O30000<>""),改訂履歴!O11:O30000) -> 0.1
A4: 機能カテゴリ | H4: AP1001 | U4: 項目 | Z4: API設計書 | AP4: {=RIGHT(CELL("filename",$A$1),LEN(CELL("filename",$A$1))-FIND("]",CELL("filename",$A$1)))} -> 表紙
L16: POSサーバーの詳細設計書
L24: =K2&"/"&H4&"/"&Z4 -> POSサーバー/AP1001/API設計書
Q44: 承認日 | AA44: 承認者 | AQ44: 版数

Sheet 改訂履歴
A1: システム名 | K1: システム種別 | W1: =IF(表紙!W1="","",表紙!W1) -> 詳細設計書 | AP1: 作成者 | AT1: 作成日 | AY1: 更新者 | BC1: 更新日 | BH1: 版数
A2: =IF(表紙!A2="","",表紙!A2) -> POSサーバー | K2: =IF(表紙!K2="","",表紙!K2) -> POSサーバー | AP2: =IF(表紙!AP2="","",表紙!AP2) -> SonMNT | AT2: =IF(表紙!AT2="","",表紙!AT2) -> 45462 | AY2: =IF(表紙!AY2="","",表紙!AY2) -> SonMNT | BC2: =IF(表紙!BC2="","",表紙!BC2) -> 45462 | BH2: =IF(表紙!BH2="","",表紙!BH2) -> 0.1
A4: 機能カテゴリー | H4: =IF(表紙!H4="","",表紙!H4) -> AP1001 | U4: 項目 | Z4: =IF(表紙!Z4="","",表紙!Z4) -> API設計書 | AP4: {=RIGHT(CELL("filename",$A$1),LEN(CELL("filename",$A$1))-FIND("]",CELL("filename",$A$1)))} -> 改訂履歴
B8: ■改訂履歴
B10: 更新日 | H10: 更新者 | O10: 版数 | S10: 更新内容 | AX10: 承認日 | BD10: 承認者
B11: 45462 | H11: SonMNT | O11: 0.1 | S11: 新規作成

Sheet 処理フロー凡例
A1: システム名 | K1: システム種別 | W1: =IF(表紙!W1="","",表紙!W1) -> 詳細設計書 | AP1: 作成者 | AT1: 作成日 | AY1: 更新者 | BC1: 更新日 | BH1: 版数
A2: =IF(表紙!A2="","",表紙!A2) -> POSサーバー | K2: =IF(表紙!K2="","",表紙!K2) -> POSサーバー | AP2: =IF(表紙!AP2="","",表紙!AP2) -> SonMNT | AT2: =IF(表紙!AT2="","",表紙!AT2) -> 45462 | AY2: =IF(表紙!AY2="","",表紙!AY2) -> SonMNT | BC2: =IF(表紙!BC2="","",表紙!BC2) -> 45462 | BH2: =IF(表紙!BH2="","",表紙!BH2) -> 0.1
A4: 機能カテゴリ | H4: =IF(表紙!H4="","",表紙!H4) -> AP1001 | U4: 項目 | Z4: =IF(表紙!Z4="","",表紙!Z4) -> API設計書 | AP4: =MID(CELL("filename",A1),FIND("]",CELL("filename",A1))+1,255) -> 処理フロー凡例
B7: ●API処理フロー

Sheet AP1001
A1: システム名 | K1: システム種別 | W1: =IF(表紙!W1="","",表紙!W1) -> 詳細設計書 | AP1: 作成者 | AT1: 作成日 | AY1: 更新者 | BC1: 更新日 | BH1: 版数
A2: =IF(表紙!A2="","",表紙!A2) -> POSサーバー | K2: =IF(表紙!K2="","",表紙!K2) -> POSサーバー | AP2: =IF(表紙!AP2="","",表紙!AP2) -> SonMNT | AT2: =IF(表紙!AT2="","",表紙!AT2) -> 45462 | AY2: =IF(表紙!AY2="","",表紙!AY2) -> SonMNT | BC2: =IF(表紙!BC2="","",表紙!BC2) -> 45462 | BH2: =IF(表紙!BH2="","",表紙!BH2) -> 0.1
A4: 機能カテゴリ | H4: =IF(表紙!H4="","",表紙!H4) -> AP1001 | U4: 項目 | Z4: =IF(表紙!Z4="","",表紙!Z4) -> API設計書 | AP4: =MID(CELL("filename",A1),FIND("]",CELL("filename",A1))+1,255) -> AP1001
B7: 1. 概要
C9: 1つの店舗の一括プロモーション情報設定機能を実行する。
B11: 2. リクエスト
C13: 2.1 Request URL
C15: No. | E15: URL | AG15: HTTPメソッド | AQ15: 備考
C16: 1 | E16: api/v1/promotion_master/maintenance_promotion | AG16: POST | AQ16: -
C18: 2. 2 Request Header
C20: No. | E20: ヘッダー | L20: 必須 | O20: 型 | S20: デフォルト値 | Z20: 項目説明 | AQ20: 備考
C21: 1 | E21: Authorization | L21: ○ | O21: String | S21: - | Z21: Api key | AQ21: 代表ユーザーを認証するAPIキー値 フォーマット: "Bearer {api_key}"
C22: 2 | E22: Accept | L22: - | O22: String | S22: - | Z22: Accept | AQ22: サーバーが返却できるデータ種類情報を説明する。
C23: 3 | E23: Content-Type | L23: - | O23: String | S23: - | Z23: Content-Type | AQ23: 送信リクエストの本文情報のタイプを定義する。例: application/json, mutilpart/form-data. 転送データのタイプによって、content-typeが必須又は必須ではない。例： ・入力がjsonの場合、content-typeが必須であり、application/jsonの値を受け取る。
C26: 4 | E26: User-Agent | L26: - | O26: String | S26: - | Z26: User-Agent | AQ26: サーバーを呼び出すクライアントのアプリケーション/ソフトウェア/ブラウザを定義する。
C27: 5 | E27: Accept-Encoding | L27: - | O27: String | S27: - | Z27: Accept-Encoding | AQ27: データ暗号化アルゴリズムを定義する。サーバーから受信したデータに使用できる： zip、gzip、png、gif等
C30: 2.3 Query Parameter/ path parameter
C32: No. | E32: パラメータ | L32: 必須 | O32: 型 | S32: デフォルト値 | Z32: 項目説明 | AQ32: 備考
C33: なし
C35: 2.4 Request Body
C37: No. | E37: パラメータ | L37: 必須 | O37: 型 | S37: デフォルト値 | Z37: 項目説明 | AQ37: 備考
C38: 0 | E38: store_code | L38: ○ | O38: String | S38: - | Z38: promotion_master.store_code | AQ38: ・メッセージ = MSG_VAL_001で入力必須のバリデーションチェック。その中 ：{0}が店舗である。
C39: 1 | E39: promotions | L39: ○ | O39: Array | S39: - | Z39: - | AQ39: プロモーションレコード一覧
C40: 2 | E40: code | L40: ○ | O40: String | S40: - | Z40: promotion_master.code | AQ40: ・メッセージ = MSG_VAL_001で入力必須のバリデーションチェック。その中 ：{0}がプロモーションである。 ・メッセージ = MSG_VAL_006でバリデーションチェック：数字。その中： {0} がプロモーションである。 ・メッセージ = MSG_VAL_004でバリデーションチェック： 最大5文字。その中：{0}がプロモーションであり、{1}が{5}である。
C41: 3 | E41: operation_type | L41: ○ | O41: Smallint | S41: - | Z41: - | AQ41: ・3: 削除 ・2: 新規または更新
C42: 4 | E42: name | L42: ○ | O42: String | S42: - | Z42: promotion_master.name | AQ42: ・メッセージ = MSG_VAL_001で入力必須のバリデーションチェック。その中 ：{0}が名称である。 ・メッセージ = MSG_VAL_004でバリデーションチェック： 最大12文字。その中：{0}が名称であり、{1}が{12}である。 ・メッセージ = MSG_VAL_024でバリデーションチェック：全角文字。その中：{0}が名称である。
C43: 5 | E43: start_date_time | L43: ○ | O43: String | S43: - | Z43: promotion_master.start_date_time | AQ43: ・フォーマット: yyyy/mm/dd ・メッセージ = MSG_VAL_001で入力必須のバリデーションチェック。その中 ：{0}が開始日である。 ・不正な形式の日付のバリデーションチェック: エラーメッセージ：MSG_VAL_003（{0}が開始日である。）
C44: 6 | E44: end_date_time | L44: ○ | O44: String | S44: - | Z44: promotion_master.end_date_time | AQ44: ・フォーマット: yyyy/mm/dd ・メッセージ = MSG_VAL_001で入力必須のバリデーションチェック。その中 ：{0}が终了日である。 ・不正な形式の日付のバリデーションチェック: エラーメッセージ：MSG_VAL_003（{0}が终了日である。） ・ 開始日 > 终了日のバリデーションチェック：メッセージ = MSG_VAL_004（{0}：開始日, {1}：终了日）
C45: 7 | E45: start_time | L45: ○ | O45: String | S45: - | Z45: promotion_master.start_time | AQ45: ・形式： hh:ss ・メッセージ = MSG_VAL_001で入力必須のバリデーションチェック。その中 ：{0}が開始時刻である。 ・不正な形式の日付のバリデーションチェック: エラーメッセージ：MSG_VAL_003（{0}が開始時刻である。）
C46: 8 | E46: end_time | L46: ○ | O46: String | S46: - | Z46: promotion_master.end_time | AQ46: ・形式： hh:ss ・メッセージ = MSG_VAL_001で入力必須のバリデーションチェック。その中 ：{0}が終了時刻である。 ・不正な形式の日付のバリデーションチェック: エラーメッセージ：MSG_VAL_003（{0}が終了時刻である。） ・開始日 = 终了日の場合、開始時刻 > 終了時刻のバリデーションチェックを行う。メッセージ = MSG_VAL_004（{0}が開始時刻であり、{1}が終了時刻である。）
C49: ※サンプル
C51: {
C52: "store_code": "00090",
C53: "promotions": [
C54: {
C55: "code": "12345",
C56: "operation_type": 2,
C57: "name": "Ｈｅｌｌｏ",
C58: "type": 1,
C59: "start_date_time": "2024/06/29",
...

Sheet 処理フロー
A1: システム名 | K1: システム種別 | W1: =IF(表紙!W1="","",表紙!W1) -> 詳細設計書 | AP1: 作成者 | AT1: 作成日 | AY1: 更新者 | BC1: 更新日 | BH1: 版数
A2: =IF(表紙!A2="","",表紙!A2) -> POSサーバー | K2: =IF(表紙!K2="","",表紙!K2) -> POSサーバー | AP2: =IF(表紙!AP2="","",表紙!AP2) -> SonMNT | AT2: =IF(表紙!AT2="","",表紙!AT2) -> 45462 | AY2: =IF(表紙!AY2="","",表紙!AY2) -> SonMNT | BC2: =IF(表紙!BC2="","",表紙!BC2) -> 45462 | BH2: =IF(表紙!BH2="","",表紙!BH2) -> 0.1
A4: 機能カテゴリ | H4: =IF(表紙!H4="","",表紙!H4) -> AP1001 | U4: 項目 | Z4: =IF(表紙!Z4="","",表紙!Z4) -> API設計書 | AP4: =MID(CELL("filename",A1),FIND("]",CELL("filename",A1))+1,255) -> 処理フロー

Sheet テンプレート
A1: システム名 | K1: システム種別 | W1: =IF(表紙!W1="","",表紙!W1) -> 詳細設計書 | AP1: 作成者 | AT1: 作成日 | AY1: 更新者 | BC1: 更新日 | BH1: 版数
A2: =IF(表紙!A2="","",表紙!A2) -> POSサーバー | K2: =IF(表紙!K2="","",表紙!K2) -> POSサーバー | AP2: =IF(表紙!AP2="","",表紙!AP2) -> SonMNT | AT2: =IF(表紙!AT2="","",表紙!AT2) -> 45462 | AY2: =IF(表紙!AY2="","",表紙!AY2) -> SonMNT | BC2: =IF(表紙!BC2="","",表紙!BC2) -> 45462 | BH2: =IF(表紙!BH2="","",表紙!BH2) -> 0.1
A4: 機能カテゴリ | H4: =IF(表紙!H4="","",表紙!H4) -> AP1001 | U4: 項目 | Z4: =IF(表紙!Z4="","",表紙!Z4) -> API設計書 | AP4: =MID(CELL("filename",A1),FIND("]",CELL("filename",A1))+1,255) -> テンプレート
