Workbook

Sheet 表紙
A1: システム名 | K1: システム種別 | W1: 詳細設計書 | AP1: 作成者 | AT1: 作成日 | AY1: 更新者 | BC1: 更新日 | BH1: 版数
A2: POSサーバー | K2: POSサーバ | AP2: =改訂履歴!$H$11 -> TuyenNH | AT2: =改訂履歴!$B$11 -> 45544 | AY2: =LOOKUP(2,1/(改訂履歴!H11:H30000<>""),改訂履歴!H11:H30000) -> TuyenNH | BC2: =LOOKUP(2,1/(改訂履歴!B11:B30000<>""),改訂履歴!B11:B30000) -> 45596 | BH2: =LOOKUP(2,1/(改訂履歴!O11:O30000<>""),改訂履歴!O11:O30000) -> 0.11
A4: 機能カテゴリ | H4: AP0107 | U4: 項目 | Z4: API設計書 | AP4: {=RIGHT(CELL("filename",$A$1),LEN(CELL("filename",$A$1))-FIND("]",CELL("filename",$A$1)))} -> 表紙
L16: POSサーバーの詳細設計書
L24: =K2&"/"&H4&"/"&Z4 -> POSサーバ/AP0107/API設計書
Q44: 承認日 | AA44: 承認者 | AQ44: 版数

Sheet 改訂履歴
A1: システム名 | K1: システム種別 | W1: =IF(表紙!W1="","",表紙!W1) -> 詳細設計書 | AP1: 作成者 | AT1: 作成日 | AY1: 更新者 | BC1: 更新日 | BH1: 版数
A2: =IF(表紙!A2="","",表紙!A2) -> POSサーバー | K2: =IF(表紙!K2="","",表紙!K2) -> POSサーバ | AP2: =IF(表紙!AP2="","",表紙!AP2) -> TuyenNH | AT2: =IF(表紙!AT2="","",表紙!AT2) -> 45544 | AY2: =IF(表紙!AY2="","",表紙!AY2) -> TuyenNH | BC2: =IF(表紙!BC2="","",表紙!BC2) -> 45596 | BH2: =IF(表紙!BH2="","",表紙!BH2) -> 0.11
A4: 機能カテゴリ | H4: =IF(表紙!H4="","",表紙!H4) -> AP0107 | U4: 項目 | Z4: =IF(表紙!Z4="","",表紙!Z4) -> API設計書 | AP4: {=RIGHT(CELL("filename",$A$1),LEN(CELL("filename",$A$1))-FIND("]",CELL("filename",$A$1)))} -> 改訂履歴
B8: ■改訂履歴
B10: 更新日 | H10: 更新者 | O10: 版数 | S10: 更新内容 | AX10: 承認日 | BD10: 承認者
B11: 45544 | H11: TuyenNH | O11: 0.1 | S11: 新規
B13: 45596 | H13: TuyenNH | O13: 0.11 | S13: シート：[AP0107]、[処理フロー]
S14: ・「割引率」項目更新：最大2桁入力可能 （01～99） ・特売売価の適用期間がプロモーションの適用期間外であるかをバリデーションチェックを追加 ・タイムサービス = 1の場合の適用期間のバリデーションチェックを追加 ・CompanyCode、StoreCode、PromotionCode、ScheduleNo、TypeCode、ItemCodeのフィールドでレコード存在チェックを追加 ・新しいDB構造に基づいてフィールド名とテーブル名を変更

Sheet 処理フロー凡例
A1: システム名 | K1: システム種別 | W1: =IF(表紙!W1="","",表紙!W1) -> 詳細設計書 | AP1: 作成者 | AT1: 作成日 | AY1: 更新者 | BC1: 更新日 | BH1: 版数
A2: =IF(表紙!A2="","",表紙!A2) -> POSサーバー | K2: =IF(表紙!K2="","",表紙!K2) -> POSサーバ | AP2: =IF(表紙!AP2="","",表紙!AP2) -> TuyenNH | AT2: =IF(表紙!AT2="","",表紙!AT2) -> 45544 | AY2: =IF(表紙!AY2="","",表紙!AY2) -> TuyenNH | BC2: =IF(表紙!BC2="","",表紙!BC2) -> 45596 | BH2: =IF(表紙!BH2="","",表紙!BH2) -> 0.11
A4: 機能カテゴリ | H4: =IF(表紙!H4="","",表紙!H4) -> AP0107 | U4: 項目 | Z4: =IF(表紙!Z4="","",表紙!Z4) -> API設計書 | AP4: =MID(CELL("filename",A1),FIND("]",CELL("filename",A1))+1,255) -> 処理フロー凡例
B7: ●API処理フロー

Sheet AP0107
A1: システム名 | K1: システム種別 | W1: =IF(表紙!W1="","",表紙!W1) -> 詳細設計書 | AP1: 作成者 | AT1: 作成日 | AY1: 更新者 | BC1: 更新日 | BH1: 版数
A2: =IF(表紙!A2="","",表紙!A2) -> POSサーバー | K2: =IF(表紙!K2="","",表紙!K2) -> POSサーバ | AP2: =IF(表紙!AP2="","",表紙!AP2) -> TuyenNH | AT2: =IF(表紙!AT2="","",表紙!AT2) -> 45544 | AY2: =IF(表紙!AY2="","",表紙!AY2) -> TuyenNH | BC2: =IF(表紙!BC2="","",表紙!BC2) -> 45596 | BH2: =IF(表紙!BH2="","",表紙!BH2) -> 0.11
A4: 機能カテゴリ | H4: =IF(表紙!H4="","",表紙!H4) -> AP0107 | U4: 項目 | Z4: =IF(表紙!Z4="","",表紙!Z4) -> API設計書 | AP4: =MID(CELL("filename",A1),FIND("]",CELL("filename",A1))+1,255) -> AP0107
B7: 1. 概要
C9: 特売売価情報を新規作成・編集する。
C10: バリデーションチェックエラーが発生した場合、プログラムを停止し、該当するメッセージを返す。
B12: 2. リクエスト
C14: 2.1 Request URL
C16: No. | E16: URL | AG16: HTTPメソッド | AQ16: 備考
C17: 1 | E17: api/v1/special-prices/maintainance | AG17: POST | AQ17: -
C19: 2. 2 Request Header
C21: No. | E21: ヘッダー | L21: 必須 | O21: 型 | S21: デフォルト値 | Z21: 項目説明 | AQ21: 備考
C22: 1 | E22: Authorization | L22: ○ | O22: String | S22: - | Z22: Api key | AQ22: 代表ユーザーを認証するAPIキー値 フォーマット："Bearer {api_key}"
C24: 2 | E24: Accept | L24: - | O24: String | S24: - | Z24: Accept | AQ24: サーバーが返却できるデータ種類情報を説明する。
C25: 3 | E25: Content-Type | L25: ○ | O25: String | S25: application/json | Z25: Content-Type | AQ25: 送信リクエストの本文情報のタイプを定義する。例: application/json, mutilpart/form-data. 転送データのタイプによって、content-typeが必須又は必須ではない。例： ・入力がjsonの場合、content-typeが必須であり、application/jsonの値を受け取る。
C32: 4 | E32: User-Agent | L32: - | O32: String | S32: - | Z32: User-Agent | AQ32: サーバーを呼び出すクライアントのアプリケーション/ソフトウェア/ブラウザを定義する。
C33: 5 | E33: Accept-Encoding | L33: - | O33: String | S33: - | Z33: Accept-Encoding | AQ33: データ暗号化アルゴリズムを定義する。サーバーから受信したデータに使用できる： zip、gzip、png、gif等
C35: 2.3 Query Parameter/ path parameter
C37: No. | E37: パラメータ | L37: 必須 | O37: 型 | S37: デフォルト値 | Z37: 項目説明 | AQ37: 備考
C38: なし
C40: 2.4 Request Body
C42: No. | E42: パラメータ | L42: 必須 | O42: 型 | S42: デフォルト値 | Z42: 項目説明 | AQ42: 備考
C43: 1 | E43: special_price | O43: Array | S43: - | Z43: - | AQ43: 商品の緊急売価一覧
C44: 2 | E44: record_id | L44: - | O44: Bigint | S44: - | Z44: M_SpecialPrice.RECORD_ID | AQ44: ・緊急売価を新規作成する場合、record_idをnullとして渡す。 ・緊急売価を編集する場合、該当するrecord_idを渡す。
C46: 3 | E46: selected_store | L46: ○ | O46: String | S46: - | Z46: M_SpecialPrice.StoreCode | AQ46: バリデーションチェック：入力必須（メッセージ = MSG_VAL_001）
C47: 4 | E47: promotion_code | L47: ○ | O47: String | S47: - | Z47: M_SpecialPrice.PromotionCode | AQ47: ・バリデーションチェック：数字であること（メッセージ = MSG_VAL_006） ・バリデーションチェック：5桁未満の場合、 エラーメッセージ = MSG_VAL_002
C48: 5 | E48: status | L48: ○ | O48: Smallint | S48: - | Z48: M_SpecialPrice.Status | AQ48: 0:実施中 1: 中止
C49: 6 | E49: item_code | L49: ○ | O49: String | S49: - | Z49: M_SpecialPrice.ItemCode | AQ49: ・バリデーションチェック：入力必須（メッセージ = MSG_VAL_001） ・バリデーションチェック：最大13桁（メッセージ = MSG_VAL_002） ・バリデーションチェック：数字であること（メッセージ = MSG_VAL_006）
C50: 7 | E50: discount_method_code | L50: ○ | O50: decimal | S50: - | Z50: M_SpecialPrice.DiscountMethodCode | AQ50: ・画面から渡される値が「02：特売割引設定」である => DBに「02」として挿入する。 ・画面から渡される値が「03：特売売価設定」である => DBに「03」として挿入する。
C51: 8 | E51: special_price | L51: ○ | O51: decimal | S51: - | Z51: M_SpecialPrice.SpecialPrice M_SpecialPrice.DiscountValue | AQ51: ・バリデーションチェック：入力必須（メッセージ = MSG_VAL_001） ・discount_method_code = 02の場合、 ‣バリデーションチェック：最大2桁（メッセージ = MSG_VAL_002） ・discount_method_code = 03の場合、 ‣バリデーションチェック：最大6桁（メッセージ = MSG_VAL_002） ・バリデーションチェック：数字であること（メッセージ = MSG_VAL_006） ・バリデーションチェック：0より大きいこと（メッセージ = MSG_VAL_038） ・discount_method_code = 02の場合、M_SpecialPrice.DiscountValueフィールドに挿入する。 ・discount_method_code = 03の場合、M_SpecialPrice.SpecialPriceフィールドに挿入する。
C52: 9 | E52: type_code | L52: - | O52: String | S52: - | Z52: M_SpecialPrice.TypeCode | AQ52: ・画面から渡される値が「0：タイムサービス」である => DBに「01」として挿入する。 ・画面から渡される値が「1：期間特売」である => DBに「02」として挿入する。
C53: 10 | E53: start_date | L53: ○ | O53: String | S53: - | Z53: M_SpecialPrice.StartDateTime | AQ53: ・バリデーションチェック：入力必須（メッセージ = MSG_VAL_001） ・過去日のバリデーションチェック（メッセージ = MSG_VAL_037） ・バリデーションチェック：形式が不正な場合（「yyyy/mm/dd」ではない）、MSG_VAL_016を表示する。 ・バリデーションチェック： start_date_time > end_date_timeの場合、MSG_VAL_051を表示する。
C54: 11 | E54: end_date | L54: ○ | O54: String | S54: - | Z54: M_SpecialPrice.EndDateTime | AQ54: ・バリデーションチェック：入力必須（メッセージ = MSG_VAL_001） ・過去日のバリデーションチェック（メッセージ=MSG_VAL_022）。状態が「1（中止）」に更新された場合、過去日のバリデーションチェックを行わない。 ・バリデーションチェック：形式が不正な場合（「yyyy/mm/dd」ではない）、MSG_VAL_016を表示する。
C55: 12 | E55: start_time | L55: ○ | O55: String | S55: - | Z55: M_SpecialPrice.StartDateTime | AQ55: ・バリデーションチェック：入力必須（メッセージ = MSG_VAL_001） ・バリデーションチェック：形式が不正な場合（「hh:mm」ではない）、MSG_VAL_016を表示する。
C56: 13 | E56: end_time | L56: ○ | O56: String | S56: - | Z56: M_SpecialPrice.EndDateTime | AQ56: ・バリデーションチェック：入力必須（メッセージ = MSG_VAL_001） ・バリデーションチェック：形式が不正な場合（「hh:mm」ではない）、MSG_VAL_016を表示する。 ・type_code = 1かつstart_date < end_dateの場合、 ‣バリデーションチェック：start_time>=end_timeの場合、「MSG_VAL_051」エラーメッセージを表示する。 start_date = end_dateの場合、 ‣バリデーションチェック：start_time>=end_timeの場合、「MSG_VAL_051」エラーメッセージを表示する。 ・start_date = end_date = today()の場合、 ‣バリデーションチェック：end_time <= now()の場合、「MSG_VAL_022」エラーメッセージを表示する。
C59: ※サンプル
C61: special_price: [
C62: {
C63: "record_id": null,
C64: "selected_store": "09176",
...

Sheet 処理フロー
A1: システム名 | K1: システム種別 | W1: =IF(表紙!W1="","",表紙!W1) -> 詳細設計書 | AP1: 作成者 | AT1: 作成日 | AY1: 更新者 | BC1: 更新日 | BH1: 版数
A2: =IF(表紙!A2="","",表紙!A2) -> POSサーバー | K2: =IF(表紙!K2="","",表紙!K2) -> POSサーバ | AP2: =IF(表紙!AP2="","",表紙!AP2) -> TuyenNH | AT2: =IF(表紙!AT2="","",表紙!AT2) -> 45544 | AY2: =IF(表紙!AY2="","",表紙!AY2) -> TuyenNH | BC2: =IF(表紙!BC2="","",表紙!BC2) -> 45596 | BH2: =IF(表紙!BH2="","",表紙!BH2) -> 0.11
A4: 機能カテゴリ | H4: =IF(表紙!H4="","",表紙!H4) -> AP0107 | U4: 項目 | Z4: =IF(表紙!Z4="","",表紙!Z4) -> API設計書 | AP4: =MID(CELL("filename",A1),FIND("]",CELL("filename",A1))+1,255) -> 処理フロー

Sheet テンプレート
A1: システム名 | K1: システム種別 | W1: =IF(表紙!W1="","",表紙!W1) -> 詳細設計書 | AP1: 作成者 | AT1: 作成日 | AY1: 更新者 | BC1: 更新日 | BH1: 版数
A2: =IF(表紙!A2="","",表紙!A2) -> POSサーバー | K2: =IF(表紙!K2="","",表紙!K2) -> POSサーバ | AP2: =IF(表紙!AP2="","",表紙!AP2) -> TuyenNH | AT2: =IF(表紙!AT2="","",表紙!AT2) -> 45544 | AY2: =IF(表紙!AY2="","",表紙!AY2) -> TuyenNH | BC2: =IF(表紙!BC2="","",表紙!BC2) -> 45596 | BH2: =IF(表紙!BH2="","",表紙!BH2) -> 0.11
A4: 機能カテゴリ | H4: =IF(表紙!H4="","",表紙!H4) -> AP0107 | U4: 項目 | Z4: =IF(表紙!Z4="","",表紙!Z4) -> API設計書 | AP4: =MID(CELL("filename",A1),FIND("]",CELL("filename",A1))+1,255) -> テンプレート
