Workbook

Sheet 表紙
A1: システム名 | K1: システム種別 | W1: 詳細設計書 | AP1: 作成者 | AT1: 作成日 | AY1: 更新者 | BC1: 更新日 | BH1: 版数
A2: POSサーバー | K2: POSサーバー | AP2: =改訂履歴!$H$11 -> DuNT | AT2: =改訂履歴!$B$11 -> 45490 | AY2: =LOOKUP(2,1/(改訂履歴!H11:H30002<>""),改訂履歴!H11:H30002) -> DuNT | BC2: =LOOKUP(2,1/(改訂履歴!B11:B30002<>""),改訂履歴!B11:B30002) -> 45567 | BH2: =LOOKUP(2,1/(改訂履歴!O11:O30002<>""),改訂履歴!O11:O30002) -> 0.71
A4: 機能カテゴリ | H4: AP7102 | U4: 項目 | Z4: API設計書 | AP4: {=RIGHT(CELL("filename",$A$1),LEN(CELL("filename",$A$1))-FIND("]",CELL("filename",$A$1)))} -> 表紙
L16: POSサーバーの詳細設計書
L24: =K2&"/"&H4&"/"&Z4 -> POSサーバー/AP7102/API設計書
Q44: 承認日 | AA44: 承認者 | AQ44: 版数

Sheet 改訂履歴
A1: システム名 | K1: システム種別 | W1: =IF(表紙!W1="","",表紙!W1) -> 詳細設計書 | AP1: 作成者 | AT1: 作成日 | AY1: 更新者 | BC1: 更新日 | BH1: 版数
A2: =IF(表紙!A2="","",表紙!A2) -> POSサーバー | K2: =IF(表紙!K2="","",表紙!K2) -> POSサーバー | AP2: =IF(表紙!AP2="","",表紙!AP2) -> DuNT | AT2: =IF(表紙!AT2="","",表紙!AT2) -> 45490 | AY2: =IF(表紙!AY2="","",表紙!AY2) -> DuNT | BC2: =IF(表紙!BC2="","",表紙!BC2) -> 45567 | BH2: =IF(表紙!BH2="","",表紙!BH2) -> 0.71
A4: 機能カテゴリ | H4: =IF(表紙!H4="","",表紙!H4) -> AP7102 | U4: 項目 | Z4: =IF(表紙!Z4="","",表紙!Z4) -> API設計書 | AP4: {=RIGHT(CELL("filename",$A$1),LEN(CELL("filename",$A$1))-FIND("]",CELL("filename",$A$1)))} -> 改訂履歴
B8: ■改訂履歴
B10: 更新日 | H10: 更新者 | O10: 版数 | S10: 更新内容 | AX10: 承認日 | BD10: 承認者
B11: 45490 | H11: DuNT | O11: 0.1 | S11: 新規
B13: 45512 | H13: DuNT | O13: 0.2 | S13: AP7102シート
S14: ・url、MACアドレスのマッピングを更新する。 ・record_idを追加する。
B15: 45519 | H15: AnhDD | O15: 0.3 | S15: シート：AP7102、処理フロー
S16: 満たすリストが見つからないフィールドは空のリストを返す。
B17: 45525 | H17: DuNT | O17: 0.4 | S17: AP7102
S18: tenant_hierarchy_codeを追加する。
B19: 45547 | H19: DuNT | O19: 0.5 | S19: AP7102
S20: total_countを追加し、payment_type_codeを削除する。
B21: 45560 | H21: AnhDD | O21: 0.6 | S21: AP7102
S22: TypeNodeのデータ型をIntからstringに変更する。
B23: 45562 | H23: DuNT | O23: 0.61 | S23: AP7102
S24: レジ一覧のアイテム情報詳細を追加する。
B25: 45567 | H25: AnhDD | O25: 0.7 | S25: 23094_処理フロー：cash_machine_noの検索タイプをあいまい検索から正確な検索に変更する。
S26: 23094_AP7102: type_codeを削除する。
B27: 45567 | H27: DuNT | O27: 0.71 | S27: 処理フロー
S28: ドロップダウンプリセットレイアウト内のアイテムの重複を処理する。

Sheet 処理フロー凡例
A1: システム名 | K1: システム種別 | W1: =IF(表紙!W1="","",表紙!W1) -> 詳細設計書 | AP1: 作成者 | AT1: 作成日 | AY1: 更新者 | BC1: 更新日 | BH1: 版数
A2: =IF(表紙!A2="","",表紙!A2) -> POSサーバー | K2: =IF(表紙!K2="","",表紙!K2) -> POSサーバー | AP2: =IF(表紙!AP2="","",表紙!AP2) -> DuNT | AT2: =IF(表紙!AT2="","",表紙!AT2) -> 45490 | AY2: =IF(表紙!AY2="","",表紙!AY2) -> DuNT | BC2: =IF(表紙!BC2="","",表紙!BC2) -> 45567 | BH2: =IF(表紙!BH2="","",表紙!BH2) -> 0.71
A4: 機能カテゴリ | H4: =IF(表紙!H4="","",表紙!H4) -> AP7102 | U4: 項目 | Z4: =IF(表紙!Z4="","",表紙!Z4) -> API設計書 | AP4: =MID(CELL("filename",A1),FIND("]",CELL("filename",A1))+1,255) -> 処理フロー凡例
B7: ●API処理フロー

Sheet AP7102
A1: システム名 | K1: システム種別 | W1: =IF(表紙!W1="","",表紙!W1) -> 詳細設計書 | AP1: 作成者 | AT1: 作成日 | AY1: 更新者 | BC1: 更新日 | BH1: 版数
A2: =IF(表紙!A2="","",表紙!A2) -> POSサーバー | K2: =IF(表紙!K2="","",表紙!K2) -> POSサーバー | AP2: =IF(表紙!AP2="","",表紙!AP2) -> DuNT | AT2: =IF(表紙!AT2="","",表紙!AT2) -> 45490 | AY2: =IF(表紙!AY2="","",表紙!AY2) -> DuNT | BC2: =IF(表紙!BC2="","",表紙!BC2) -> 45567 | BH2: =IF(表紙!BH2="","",表紙!BH2) -> 0.71
A4: 機能カテゴリ | H4: =IF(表紙!H4="","",表紙!H4) -> AP7102 | U4: 項目 | Z4: =IF(表紙!Z4="","",表紙!Z4) -> API設計書 | AP4: =MID(CELL("filename",A1),FIND("]",CELL("filename",A1))+1,255) -> AP7102
B7: 1. 概要
C9: 対象店舗のレジ一覧を取得する。
B11: 2. リクエスト
C13: 2.1 Request URL
C15: No. | E15: URL | AG15: HTTPメソッド | AQ15: 備考
C16: 1 | E16: api/v1/cash-registers | AG16: GET
C18: 2. 2 Request Header
C20: No. | E20: ヘッダー | L20: 必須 | O20: 型 | S20: デフォルト値 | Z20: 項目説明 | AQ20: 備考
C21: 1 | E21: Authorization | L21: ○ | O21: String | S21: - | Z21: Api key | AQ21: 形式："Bearer {api_key}"
C22: 2 | E22: Accept | L22: - | O22: String | S22: - | Z22: Accept
C23: 3 | E23: Content-Type | L23: ○ | O23: String | S23: application/json | Z23: application/json
C24: 4 | E24: User-Agent | L24: - | O24: String | S24: - | Z24: User-Agent
C25: 5 | E25: Accept-Encoding | L25: - | O25: String | S25: - | Z25: Accept-Encoding
C28: 2.3 Query Parameter/ path parameter
C30: No. | E30: パラメータ | L30: 必須 | O30: 型 | S30: デフォルト値 | Z30: 項目説明 | AQ30: 備考
C31: 1 | E31: selected_store | L31: ○ | O31: List<String> | S31: - | Z31: Querry parameter: 対象店舗 | AQ31: 店舗コード：4桁。4桁以外の場合、エラーメッセージ = MSG_VAL_002
C32: =C31+1 -> 2 | E32: cash_machine_no | L32: - | O32: String | S32: - | Z32: Querry parameter: レジ番号 | AQ32: 最大15桁。桁数 > 15の場合、 エラーメッセージ = MSG_VAL_002
C33: =C32+1 -> 3 | E33: cash_machine_type | L33: - | O33: String | S33: - | Z33: Querry parameter: レジ種別 | AQ33: nullの場合、全て検索する。
C34: =C33+1 -> 4 | E34: node_type | L34: - | O34: String | S34: - | Z34: Querry parameter: ノード種別 | AQ34: nullの場合、全て検索する。
C35: =C34+1 -> 5 | E35: preset_layout_id | L35: - | O35: String | S35: - | Z35: Querry parameter: プリセットレイアウトコード | AQ35: nullの場合、全て検索する。
C36: =C35+1 -> 6 | E36: function_layout_id | L36: - | O36: String | S36: - | Z36: Querry parameter: ファンクションレイアウトコード | AQ36: nullの場合、全て検索する。
C37: =C36+1 -> 7 | E37: keyboard_layout_id | L37: - | O37: String | S37: - | Z37: Querry parameter: キーボードレイアウトコード | AQ37: nullの場合、全て検索する。
C39: 2.4 Request Body
D40: NA
B42: 3. レスポンス
C44: 3.1. 正常の場合のレスポンスフォーマット
C46: No. | E46: JSON name | L46: 型 | S46: 項目説明 | AC46: 備考
C47: 1 | E47: total_count | L47: Long | AC47: 検索できた総件数
C48: 2 | E48: items | L48: Array<CashMachine>
C49: 3 | E49: record_id | L49: BigInt | S49: CashRegisterMaster.RECORD_ID
C50: 4 | E50: store_code | L50: String | S50: StoreMaster.Code
C51: 5 | E51: store_name | L51: String | S51: StoreMaster.Name
C52: 6 | E52: code | L52: BigInt | S52: CashRegisterMaster.Code | AC52: レジコード
C53: 7 | E53: type_name | L53: String | S53: CashRegisterType.Name | AC53: レジ種別名称
C54: 8 | E54: type_node | L54: String | S54: CashRegisterMaster.TypeNode | AC54: ノード種別
C55: 8 | E55: type_node_name | L55: String | S55: CodeMaster.PropertyName MC7101 | AC55: ノード種別名称
C56: 9 | E56: button_layout_code | L56: String | S56: CashRegisterMaster.ButtonLayoutCode | AC56: プリセットレイアウトコード
...

Sheet 処理フロー
A1: システム名 | K1: システム種別 | W1: =IF(表紙!W1="","",表紙!W1) -> 詳細設計書 | AP1: 作成者 | AT1: 作成日 | AY1: 更新者 | BC1: 更新日 | BH1: 版数
A2: =IF(表紙!A2="","",表紙!A2) -> POSサーバー | K2: =IF(表紙!K2="","",表紙!K2) -> POSサーバー | AP2: =IF(表紙!AP2="","",表紙!AP2) -> DuNT | AT2: =IF(表紙!AT2="","",表紙!AT2) -> 45490 | AY2: =IF(表紙!AY2="","",表紙!AY2) -> DuNT | BC2: =IF(表紙!BC2="","",表紙!BC2) -> 45567 | BH2: =IF(表紙!BH2="","",表紙!BH2) -> 0.71
A4: 機能カテゴリ | H4: =IF(表紙!H4="","",表紙!H4) -> AP7102 | U4: 項目 | Z4: =IF(表紙!Z4="","",表紙!Z4) -> API設計書 | AP4: =MID(CELL("filename",A1),FIND("]",CELL("filename",A1))+1,255) -> 処理フロー

Sheet テンプレート
A1: システム名 | K1: システム種別 | W1: =IF(表紙!W1="","",表紙!W1) -> 詳細設計書 | AP1: 作成者 | AT1: 作成日 | AY1: 更新者 | BC1: 更新日 | BH1: 版数
A2: =IF(表紙!A2="","",表紙!A2) -> POSサーバー | K2: =IF(表紙!K2="","",表紙!K2) -> POSサーバー | AP2: =IF(表紙!AP2="","",表紙!AP2) -> DuNT | AT2: =IF(表紙!AT2="","",表紙!AT2) -> 45490 | AY2: =IF(表紙!AY2="","",表紙!AY2) -> DuNT | BC2: =IF(表紙!BC2="","",表紙!BC2) -> 45567 | BH2: =IF(表紙!BH2="","",表紙!BH2) -> 0.71
A4: 機能カテゴリ | H4: =IF(表紙!H4="","",表紙!H4) -> AP7102 | U4: 項目 | Z4: =IF(表紙!Z4="","",表紙!Z4) -> API設計書 | AP4: =MID(CELL("filename",A1),FIND("]",CELL("filename",A1))+1,255) -> テンプレート
