Workbook

Sheet 表紙
A1: POS Server2.0基本設計 | L1: 大分類 | V1: 中分類 | AF1: 小分類 | AP1: 作成者 | AU1: 作成日 | AZ1: 更新日
L2: 基本設計書 | V2: - | AF2: =RIGHT(CELL("filename",$A$2),LEN(CELL("filename",$A$2))-FIND("]",CELL("filename",$A$2))) -> #VALUE! | AP2: 山本 | AU2: 45803
D9: POS Server2.0 基本設計書
AV16: 版番 | AZ16: 0.1

Sheet 変更履歴
A1: =表紙!A1 -> POS Server2.0基本設計 | L1: 大分類 | V1: 中分類 | AF1: 小分類 | AP1: 作成者 | AU1: 作成日 | AZ1: 更新日
L2: =表紙!L2 -> 基本設計書 | V2: =表紙!V2 -> - | AF2: =RIGHT(CELL("filename",$A$2),LEN(CELL("filename",$A$2))-FIND("]",CELL("filename",$A$2))) -> #VALUE! | AP2: 山本 | AU2: 45803
B4: 発行日 | F4: 版 | I4: 変更箇所 | W4: 発行／改定内容 | BB4: 変更者
B5: 45803 | F5: 0.1 | W5: ドラフト版

Sheet 目次
A1: =表紙!A1 -> POS Server2.0基本設計 | L1: 大分類 | V1: 中分類 | AF1: 小分類 | AP1: 作成者 | AU1: 作成日 | AZ1: 更新日
L2: =表紙!L2 -> 基本設計書 | V2: =表紙!V2 -> - | AF2: =RIGHT(CELL("filename",$A$2),LEN(CELL("filename",$A$2))-FIND("]",CELL("filename",$A$2))) -> #VALUE! | AP2: 山本 | AU2: =表紙!AU2 -> 45803
B4: ０．はじめに | AH4: ６．ログ運用設計
C5: １．１．案件の目的 | AI5: ６．１ ログ運用方針
C6: １．２．本書の記述範囲 | AI6: ６．２ ログ運用
AI7: ６．３ ログ保管期間
B9: １．アカウント設計 | AH9: ７．バックアップ・リストア運用設計
C10: １．１．案件の目的 | AI10: ７．１ バックアップ・リストア運用方針
C11: １．２．本書の記述範囲 | AI11: ７．２ バックアップ運用
AI12: ７．３ リストア運用
B14: ２．システム構成 | AH14: ８．監視設計
C15: ２．１ 本環境構成 | AI15: ８．１ 監視方針
C16: ２．２ サービス一覧 | AI16: ８．２ 監視運用フロー
AI17: ８．３ 監視体制と役割
B18: ３．ネットワーク設計 | AI18: ８．４ 監視方式
C19: ３．１ XXX
AH20: ９．運用機能設計
B21: ４．可用性設計 | AI21: ９．１ 運用機能一覧
C22: ４．１ 可用性確保方式 | AI22: ９．２ 各運用機能方針
B24: ５．セキュリティ設計
C25: ５．１ セキュリティ方針
C26: ５．２ ネットワークセキュリティ
C27: ５．３ アクセス権限制御
C28: ５．４ セキュリティポリシー対応方針
C29: ５．５ SSLサーバ証明書

Sheet ０．はじめに
A1: =表紙!A1 -> POS Server2.0基本設計 | L1: 大分類 | V1: 中分類 | AF1: 小分類 | AP1: 作成者 | AU1: 作成日 | AZ1: 更新日
L2: =表紙!L2 -> 基本設計書 | V2: =表紙!V2 -> - | AF2: =RIGHT(CELL("filename",$A$2),LEN(CELL("filename",$A$2))-FIND("]",CELL("filename",$A$2))) -> #VALUE! | AP2: =表紙!AP2 -> 山本 | AU2: =表紙!AU2 -> 45803
A3: ０．はじめに
B5: ０．１．案件の目的
C7: （１）各屋号共通目的
E8: 既存の富士通のシステムを入れ替えたい。 | BF8: 各屋号に対してオンプレミス上にあるPOSデータを毎朝送信するシステムを作成する。
E9: →背景は？？？？ | BF9: 屋号単位で細かな要件は存在するが、共通機能を整理し標準化を行う。
BF10: 屋号で異なる要件が発生した場合は共通機能と異なる点を設計として残し、環境・運用をご提供する。
BF11: AWSリセラーではない為、提供環境はサービスとして顧客提供するものとする。
BF12: カスミは掲示板に表示する
BF13: いなげやはPOS機能にマスタデータを表示する
C16: （２）個別目的
E17: カスミ
F18: 既定のタイミングでマスタデータをUSMH網経由してISHISDA電子棚札に対してデータ送付すること。
F19: 電子棚札への送付は大きく以下、三つの送付タイミングとなる
G20: ・毎朝
G21: ・随時
G22: ・予約時間
E24: いなげや
F25: マスタデータをUSMH網を経由してPOSアプリ端末に送付すること
F26: POSアプリで収集したデータをUSMH網を経由してオンプレミス環境のScan＆Goに送付すること。
E28: MV
E31: マルエツ
B34: ０．２．本書の記述範囲
C35: 本書では、AWSに関する基本設計を記述範囲とする。
B37: ０．０．基本方針
C38: 利用するAWSとの責任分界点はAWSが提示している責任共有モデルに準じた実装とする。
C39: AWSのベストプラクティスに準じてシステム設計を行う。
C40: システムを実装するリージョンは東京リージョンを利用し、災対環境は考慮しない。
C41: USMH様網とAWS環境に構築するPOSサーバ 2.0間との通信は、
C42: 情報システム部が所管するAWS Direct Connect環境を利用した専用線網を利用し、通信を可能にする。
C43: 可用性を担保するため、マルチAZ構成でシステムを実装する。
C44: AWSサービス（CloudWatch、SNS等）を利用したシステム監視を実装する。
C45: インターネットアクセスから本システムにアクセスすることは原則禁止とし、本システムアクセスの場合はお客様提供のVPNを利用してアクセスを行う。
C46: スケーラビリティ、開発・保守䛾簡素化、コスト削減を最大化するために可能な限り、サーバレスでの構築を行う。
C47: 運用コスト・オペミス䛾リスク䛾軽減させるために、インフラはIaCで構築を行う。
C48: サービスダウンタイム軽減、障害未然防止するために、包括的䛺モニタリングを行う。
B50: ０．３．前提条件
C51: 本システムは2025年3月30日までに提供されたAWSサービスの仕様を基とする。
C52: 本システムのサービス提供中に、AWSによる仕様変更に伴い本書記載の設計と異なる動作が生じた場合は、都度協議の上で方式を見直す
...

Sheet １．アカウント設計
A1: =表紙!A1 -> POS Server2.0基本設計 | L1: 大分類 | V1: 中分類 | AF1: 小分類 | AP1: 作成者 | AU1: 作成日 | AZ1: 更新日
L2: =表紙!L2 -> 基本設計書 | V2: =表紙!V2 -> - | AF2: =RIGHT(CELL("filename",$A$2),LEN(CELL("filename",$A$2))-FIND("]",CELL("filename",$A$2))) -> #VALUE! | AP2: =表紙!AP2 -> 山本 | AU2: =表紙!AU2 -> 45803
B4: １．アカウント設計
D6: AWSアカウントについて以下に記載する。
B8: １．1．AWSアカウント
C10: （１） | F10: 方針
D11: ・AWSアカウントは、ルビナ社が発行したAWSアカウントを利用する。
D12: ・本番環境と開発環境でアカウントを分離する。
D13: ・各アカウントのルートユーザはルビナ社にて管理し、ルビナ社側で多要素認証（MFA）の設定を行う。
D14: ・AWSサポートプランは利用状況を加味し、適宜見直しをする。
C16: （２）AWSアカウント一覧
D17: 利用するAWSアカウントは以下の通り。
D19: # | F19: AWSアカウント | P19: 利用用途
D20: 1 | F20: スパイク環境アカウント | P20: スパイク環境を構築するAWSアカウント。既存のAndroidPoSアカウント上に構築する。
F21: （AndroidPoS）
D22: 2 | F22: 本番環境アカウント | P22: 本番サービスを提供するアカウント。
D23: 3 | F23: 開発環境アカウント | P23: ルビナ社にて検証に利用するアカウント。
C25: （３）AWSアカウント管理概要
D26: AWS環境におけるアカウントの管理概要は以下の通り。
B49: １．２．コスト配分
C51: （１）方針

Sheet ２．システム構成
A1: =表紙!A1 -> POS Server2.0基本設計 | L1: 大分類 | V1: 中分類 | AF1: 小分類 | AP1: 作成者 | AU1: 作成日 | AZ1: 更新日
L2: =表紙!L2 -> 基本設計書 | V2: =表紙!V2 -> - | AF2: =RIGHT(CELL("filename",$A$2),LEN(CELL("filename",$A$2))-FIND("]",CELL("filename",$A$2))) -> #VALUE! | AP2: 山本 | AU2: =表紙!AU2 -> 45803
B4: ２．システム構成
C6: （１）システム構成方針
D7: 本システムはアカウント単位で環境を分離する。
D8: AWS環境とオンプレミスを繋ぐDirectConectGatewayの接続上限が20VPCという制限があるため、屋号単位でのAWSアカウントは作成しない。
D9: 本番、開発環境において1アカウント１VPCで構成する。尚、屋号のNW分離についてはサブネットで分離する。
D10: 各屋号で共通で利用するリソース（VPCエンドポイント等）はコスト削減の観点で共通化する。
C12: VPC構成イメージ
C28: （２）各環境定義
D29: 各環境の定義は以下の通り。
D30: ＃ | E30: 環境 | J30: 用途
D31: 1 | E31: 本番環境 | J31: 本番サービスを提供する環境とする。
D32: 2 | E32: 開発環境 | J32: USMH様にて業務機能の検証を行う環境とする。
D33: 3 | E33: スパイク環境 | J33: ルビナ社にて検証を行う環境とする。
B35: ２．１ 環境構成
C36: 本環境の構成図は別紙1.構成図 シートを参照
B39: ２．２ サービス一覧
C40: 本環境で利用するAWSサービス一覧は以下のとおり。
C41: 利用サービス一覧 | P41: サービス説明 | AX41: 用途
C42: AWS Transfer Family for SFTP | P42: AWSの他のシステム、例えばS3アプリケーションなどと結合可能なアプリケーション転送に特化したサービス | AX42: マスタファイルをSFTPで入出力するために使用
C43: AWS Lambda | P43: AWSのイベントの受信、フィルタリング、変換、ルーティング、および配信を可能にするサービス | AX43: マスタファイルの変換処理や送信を行う
C44: Amazon EventBridge | P44: AWS、既存のシステム、または SaaS アプリケーション全体でイベント駆動型アプリケーションを大規模に構築するサービス | AX44: S3バケットにファイルが配置されたタイミングをトリガーとして、Lambdaを実行する
C45: AWS Step Functions | P45: 複数のAWSサービスを連携させ、ワークフローを簡単に構築・管理するためのサービス | AX45: ファイルを分散処理することで、処理の高速化を実現する
C46: Amazon S3 | P46: 高可用性のオブジェクトストレージ機能を提供するサービス | AX46: マスタファイルやトランファイルを保存する
C47: Application Load Balancer | P47: アプリケーション層でのトラフィックのルーティング、ロードバランシングを提供するサービス | AX47: 管理画面へのアクセスに対して、負荷分散をする
C48: Amazon Elastic Container Service (ECS) | P48: コンテナ化されたアプリケーションの管理とオーケストレーションを提供するサービス | AX48: POS用マスタファイルの作成や
C49: Amazon Elastic Container Registry （ECR） | P49: Kubernetesクラスターを簡単にデプロイ、管理、スケーリングするためのサービス | AX49: アプリケーションのイメージを保管する
C50: NAT Gateway | P50: プライベートサブネットからインターネットへ接続するための中継機能を提供し、アウトバウンドインターネットアクセスを許可するサービス | AX50: プライベートサブネットにあるECSのコンテナイメージをECRから取得するために使用
C51: Amazon Aurora | P51: 高いパフォーマンスと可用性を持つリレーショナルデータベースサービス | AX51: マスタ情報や集計情報をデータ保存する
C52: AWS Secrets Manager | P52: アプリケーションやサービスで必要な秘密情報（APIキーやパスワードなど）を安全に保存、管理、取得するサービス | AX52: SFTP通信をする際に必要な、SSH鍵を保管する

Sheet ３．ネットワーク設計
A1: =表紙!A1 -> POS Server2.0基本設計 | L1: 大分類 | V1: 中分類 | AF1: 小分類 | AP1: 作成者 | AU1: 作成日 | AZ1: 更新日
L2: =表紙!L2 -> 基本設計書 | V2: =表紙!V2 -> - | AF2: =RIGHT(CELL("filename",$A$2),LEN(CELL("filename",$A$2))-FIND("]",CELL("filename",$A$2))) -> #VALUE! | AP2: 山本 | AU2: 45803
B4: ３．ネットワーク設計
C6: （１） | E6: 全体方針
E7: ・1つの屋号で障害が発生しても、他の屋号に影響が出ないようにネットワークを屋号単位で分離したネットワーク構成とする。
E8: ・インターネットからのインバウンド接続は極力避け、可能な限りプライベート接続を行う。
E9: ・インターネットへのアウトバウンドについては利用用途を明確にする。
E10: ・AWSのグローバルリソースにアクセスする際は、可能な限りエンドポイントを利用しセキュアな通信を行う。
E11: ・共通領域以外は各屋号での通信は行わない。
B13: ３．１．仮想ネットワーク設計
C15: （１） | E15: 方針
E16: ・AWS環境のネットワークは、AWSの仮想ネットワークサービスであるVPC（Virtual Private Cloud）を用いる。
E17: ・AWS環境のネットワーク構成は、AWS内に閉じた通信先を用途毎にCommon Subnet、Public Subnet、Private Subnet、Protected Subnet
E18: 分割し、サブネットに対してAWSのルートテーブル機能を用いて通信先を制御する。
E19: ・共通で利用するエンドポイントについてはCommon Subnetを設計するが、作成は行わない。
E20: ・DBを配置しない屋号に対してもProtected Subnetを設計するが、作成は行わない。
E21: ・VPCサブネット間通信やVPC外部への通信経路制御は、ルートテーブル機能とセキュリティグループ機能、ネットワークACL機能を用いて実現する。
E22: ・通信元からの通信制御は基本的にセキュリティグループにて実施し、ネットワークACLでは特に制御を行わない。
E23: ・１VPCに屋号単位でサブネットを分割する。
C25: （２） | E25: 構成概要
E26: ネットワーク構成概要は以下の通り。
E27: ・スパイク環境環境
E86: ・開発環境
G88: 後でつくる
E92: ・本番環境
G94: 後でつくる
B98: ３．２．VPC／サブネット設計
C100: （１） | E100: VPC設計
E101: 各環境のVPCに割り当てるアドレス領域は以下の通り。
E103: # | G103: VPC | O103: VPC CIDR | W103: アカウント
E104: 1 | G104: スパイク環境 | W104: AndroidPosアカウント
E105: 2 | G105: 本番環境 | W105: 本番アカウント
E106: 3 | G106: 開発環境 | W106: 開発アカウント
C108: （２） | E108: サブネット設計
E109: サブネットは、用途毎に以下4つに分割する。
E111: ＃ | G111: サブネット | P111: 用途
E112: 1 | G112: Common Subnet | P112: 各屋号で共通で利用するエンドポイント等のリソースを設定するサブネット。
E114: 2 | G114: Public Subnet | P114: インターネットとの直接通信を許可とするサブネット。
E116: 3 | G116: Private Subnet | P116: インターネットから直接の通信を不可とし、アプリケーション機能、エンドポイントを設定するサブネット。
E118: 4 | G118: Protected Subnet | P118: インターネットからの通信を不可とし、Private Subnetからのみ通信を可能とするDB配置想定のサブネット。
...

Sheet ４．可用性設計
A1: =表紙!A1 -> POS Server2.0基本設計 | L1: 大分類 | V1: 中分類 | AF1: 小分類 | AP1: 作成者 | AU1: 作成日 | AZ1: 更新日
L2: =表紙!L2 -> 基本設計書 | V2: =表紙!V2 -> - | AF2: =RIGHT(CELL("filename",$A$2),LEN(CELL("filename",$A$2))-FIND("]",CELL("filename",$A$2))) -> #VALUE! | AP2: 山本 | AU2: =表紙!AU2 -> 45803
B4: ４．可用性設計
C6: （１） | E6: 全体方針
E7: ・本システムにて使用するAWSサービスについてAZ障害に耐えうる可用性確保のため、マルチAZ構成とする。
E8: ・一つのAZに障害発生が発生した場合でも業務継続できる設計とする。
E9: ・データ連携先のシステムの障害や各AWSコンポーネントの二重障害は対象外とする。
E10: ・AWSのサービス自体の可用性はAWSの公開するSLAを基準とする。
E11: ※AWS SLA：https://aws.amazon.com/jp/legal/service-level-agreements/
B13: ４．1．可用性確保方式
C15: （１） | E15: システムの可用性確保方式
E16: 以下の可用性確保方式によってシステム可用性を担保する。方式はAWSよって提供される可用性確保方式を利用するものとする。
E18: Ａ．マルチAZ方式
E19: 本システムではAWS 東京リージョン内で2つのAZを使用したマルチAZ構成とする。
E20: 以下のサービスにおいてマルチAZ方式を使用する。
E22: No | G22: AWSサービス | N22: 詳細
E23: 1 | G23: VPC | N23: AWS上の仮想ネットワーク。マルチAZ構成とする。
E24: 2 | G24: ALB | N24: HTTP/HTTPSトラフィックの負荷分散を行う。ALBは制約で2つ以上のAZに紐づける必要があり、WAFを使用するために必要。
N25: 単一障害対策のためにクロスゾーン負荷分散を有効にする。
N26: ターゲットグループを設定することでトラフィック先のリソースを指定できる。
N27: リスナールールを設定することで特定のプロトコルとポート番号を受けることができる。
E28: 3 | G28: VPCエンドポイント
G29: ECS
G30: とかとか
E33: B．業務停止時のデータ復旧
E34: 以下のサービスにおいて障害発生時に利用可能なバックアップからインスタンスを復元することで業務の継続を図る。
E36: No | G36: AWSサービス | N36: 詳細
E37: 1 | G37: Aurora MySQL | N37: AWS Backupにより日次でバックアップの取得を行う。
N38: ポイントインタイムリカバリ機能で可能な限り障害発生時点まで復旧できるようにする。
E40: C．オートスケーリング
E41: 以下のサービスにおいてリソース利用状況に応じて自動的に不足リソースを追加、削除することで、常に最適なリソースを確保し、負荷に対応し業務の継続を図る。
E43: No | G43: AWSサービス | N43: 詳細
E44: 1 | G44: ALB
G45: RDS
G46: ECS
C48: （２） | E48: システムの可用性確保方式詳細
E49: 可用性確保方式の動作について詳細を記載する。
E50: 要件を満たすため、本システムは次の方針で設計を行う。
E52: AZレベルの障害に対応できるようにするため、一部のAWSリソース(VPC、NLB、ALBなど)はマルチAZ構成で作成し、
E53: EC2やAurora PostgreSQLはシングルAZ構成で配置する。
...

Sheet ５．セキュリティ設計
A1: =表紙!A1 -> POS Server2.0基本設計 | L1: 大分類 | V1: 中分類 | AF1: 小分類 | AP1: 作成者 | AU1: 作成日 | AZ1: 更新日
L2: =表紙!L2 -> 基本設計書 | V2: =表紙!V2 -> - | AF2: =RIGHT(CELL("filename",$A$2),LEN(CELL("filename",$A$2))-FIND("]",CELL("filename",$A$2))) -> #VALUE! | AP2: 山本 | AU2: =表紙!AU2 -> 45803
B4: ５．セキュリティ設計
C6: （１） | E6: 全体方針
E7: AWSが提供する機能を利用することで、効率よくセキュリティの確保を行う。
E8: リリース時にAWSが提供する機能の脆弱性が出ていないことを確認すること。
E9: 定期的に脆弱性を確認し、脆弱性の対応を行うこと。
E10: 各リソース間の通信Portを明確にし、余計なPortの開放は行わない。
E11: 作成するユーザについては個人別に作成すること。共有ユーザは認めない。
E12: 利用するIAMユーザー用のポリシーについては、業務処理に最低限必要な権限を付与することで、セキュリティ的なリスクを回避する。
B14: ５．１ ネットワークセキュリティ
C15: （１） | E15: ユーザアクセス
E16: AWSリソースへの通信は暗号化されたセキュアな通信を行う。
C18: （２） | E18: システム間アクセス
E19: セキュリティグループによる制御を行う。送信元が絞れない場合は可能な限り小さいなサブネット帯を指定するものとする。
C21: （３） | E21: AWSサービス間通信
E22: セキュリティグループによる制御を行う。送信元が絞れない場合は可能な限り小さいなサブネット帯を指定するものとする。
B24: ５．２ データ保護
C25: （１） | E25: 方針
C28: （２） | E28: ユーザアクセス
E29: AWSリソースへの通信は暗号化されたセキュアな通信を行う。
C31: （２） | E31: システム間アクセス
E32: セキュリティグループによる制御を行う。送信元が絞れない場合は可能な限り小さいなサブネット帯を指定するものとする。
C34: （３） | E34: AWSサービス間通信
E35: セキュリティグループによる制御を行う。送信元が絞れない場合は可能な限り小さいなサブネット帯を指定するものとする。
C36: ユーザーからAWSリソースへの通信は暗号化されたセキュアな通信を行う。
B38: ５．３．アクセス管理
C40: （１）方針
D41: ・AWSリソースへのアクセス制御は、IAMの機能を利用して実現する。
D42: ・IAM以外にアクセス権が制御できるサービスについては設計方針を定める。
D43: ・IAMのユーザ、ポリシー、グループ、ロール機能に適切な権限を付与し、アクセスを制御する。
E45: # | G45: IAM機能 | M45: 利用用途
E46: 1 | G46: ユーザ | M46: AWS環境を運用する個人に対してアクセス権を付与する。
E47: 2 | G47: ポリシー | M47: ユーザ、グループ、ロールに対する権限を定義する。
E48: 3 | G48: グループ | M48: 役割に応じて、複数のユーザを所属させ、効率的なアクセス管理を実施する。
E49: 4 | G49: ロール | M49: AWSリソースやサービスに対して権限を付与し、アクセス管理を実施する。
D51: ・不正アクセスを防ぐため、AWSマネジメントコンソールへのログイン時はMFAを必須とする。
D52: ・アカウントを払い出された際に発行されるAWSアカウント管理者は、同等の権限を持つシステム管理グループを作成し、IAMユーザーを紐付けた後、
D53: セキュリティの観点から削除する。
C55: （２）IAM構成概要
...

Sheet ⇒大生整理中

Sheet ６．ログ運用設計
A1: =表紙!A1 -> POS Server2.0基本設計 | L1: 大分類 | V1: 中分類 | AF1: 小分類 | AP1: 作成者 | AU1: 作成日 | AZ1: 更新日
L2: =表紙!L2 -> 基本設計書 | V2: =表紙!V2 -> - | AF2: =RIGHT(CELL("filename",$A$2),LEN(CELL("filename",$A$2))-FIND("]",CELL("filename",$A$2))) -> #VALUE! | AP2: 山本 | AU2: =表紙!AU2 -> 45803
A4: ５．ログ運用設計
B6: ５．１ ログ運用方針
C7: システムの状態を収集してモニタリング、異常が発生していないか監視を行う必要がある。
C8: システムがどのように利用されているかを把握するための情報を集め、メトリクスやログの収集、監視や可視化を行う。
B11: ５．２ ログ運用
C12: 保管先がS3に指定されているサービスはS3に保管をし、Athenaでクエリ分析を行う。
C13: それ以外のログについては、CloudWatchLogsにてログ運用を行う。
C14: S3は標準クラスを使用し、ストレージクラスの移行は行わない。
C16: ログ運用が必要となる対象を以下に記載する。
C17: サービス名（ログ取得対象） | M17: ログ内容 | AJ17: ログデータ保管 | AQ17: ログデータ保管期間
C18: CloudFront | M18: セキュリティやアクセスの監査用ログを含む標準ログをS3へ出力する。 | AJ18: S3 | AQ18: 13ヶ月(400日)
C20: S3 | M20: バケットに対するリクエスト/アクセスの詳細を記録する。 | AJ20: S3 | AQ20: 13ヶ月(400日)
C22: Athena | M22: クエリの実行結果を記録する。 | AJ22: S3 | AQ22: 13ヶ月(400日)
C24: CloudTrail | M24: ユーザー、ロール、または AWS のサービスによって実行された | AJ24: S3 | AQ24: 13ヶ月(400日)
M25: アクションを記録する。
C26: Lambda | M26: Lambda実行に対する詳細なログを出力する。 | AJ26: CloudWatchLogs | AQ26: 13ヶ月(400日)
C28: WAF | M28: AWS WAF が AWS リソースからウェブリクエストを受信した時刻、 | AJ28: CloudWatchLogs | AQ28: 13ヶ月(400日)
M29: リクエストに関する詳細情報、およびリクエストが一致したルールに
M30: 関する詳細を含む。
C31: 注、サイト閉塞時に400日に関わらず全件削除となるが、利用者の要望に応じてサイト閉塞後もログのみを保管することが可能とする。
C32: 2024/12/9以降の環境についてはCI/CD削除対応後となるため、Lambdaのログは存在しない。
B35: ５．３ ログ保管期間経過後の対応
C36: 保管期間を超過したログについては、費用圧縮の観点から削除する。

Sheet ６．バックアップ・リストア設計
A1: =表紙!A1 -> POS Server2.0基本設計 | L1: 大分類 | V1: 中分類 | AF1: 小分類 | AP1: 作成者 | AU1: 作成日 | AZ1: 更新日
L2: =表紙!L2 -> 基本設計書 | V2: =表紙!V2 -> - | AF2: =RIGHT(CELL("filename",$A$2),LEN(CELL("filename",$A$2))-FIND("]",CELL("filename",$A$2))) -> #VALUE! | AP2: 山本 | AU2: =表紙!AU2 -> 45803
A4: ６．バックアップ・リストア運用設計
B6: ６．１ バックアップ・リストア運用方針
C7: AWSが提供する機能を利用することで、バックアップ・リストア運用を実現する。
B10: ６．２ バックアップ運用
C11: S3は耐久性を考慮し、バージョン管理によるバックアップは本環境では行わない。
C12: コンテンツのマスターデータ管理は、ページ製作ベンダーにて行う。
B15: ６．３ リストア運用
C16: リストア方法については別途ドキュメント「Webサイトリリース手順書」を参照。

Sheet ７．監視設計
A1: =表紙!A1 -> POS Server2.0基本設計 | L1: 大分類 | V1: 中分類 | AF1: 小分類 | AP1: 作成者 | AU1: 作成日 | AZ1: 更新日
L2: =表紙!L2 -> 基本設計書 | V2: =表紙!V2 -> - | AF2: =RIGHT(CELL("filename",$A$2),LEN(CELL("filename",$A$2))-FIND("]",CELL("filename",$A$2))) -> #VALUE! | AU2: =表紙!AU2 -> 45803
A4: ７．監視設計
B6: ７．１． 監視設計方針
C7: (1) 本章は、システム監視で必要な項目について記載する。
C8: (2) 監視には、クレスコ社のCreageサービス（CreageOpe+ Silver）を用いる。
C9: (3) 監視対象は本番用リソースのみとし、検証用リソースは監視対象外とする。
C10: (4) システムログの保管については、AWSのサービスを用いて保管を行う。
B12: ７．２． 監視運用フロー
C13: 障害発生時の監視運用フローを以下に示す。
B20: ７．３． 監視体制と役割
C21: 障害発生時の体制と役割および運用時間について以下に示す。
D23: 以下の監視はCreageOpe+監視チームが行う。
D24: NO | G24: 作業項目 | N24: 対応時間 | Y24: 作業内容
D25: 1 | G25: システム監視 | N25: 0:00 ～ 24:00 365日対応 | Y25: システムの常時監視を実施
B28: ７．４．監視方式
C29: 本システムでは、以下の方式にて検知及び対応を行う。
C30: 監視は、以下の3項目に分けて実施する。
D32: NO | F32: 監視の種別 | K32: 概要
D33: 1 | F33: 死活監視 | K33: 監視対象の応答を確認し、応答がない（または）場合はエラー検知する。
C36: ７．４．１．死活監視
D37: ７．４．１．１．URI監視
E38: 指定した URI に対して HTTPSリクエストを送信し、レスポンスが返ってくるか、またレスポンスの内容を監視する。
E39: 監視設定のパラメータは、監視周期、レスポンスタイムアウト(秒、回数)の設定が可能である。
E40: 指定パラメータ以内に応答がない場合アラートを通知する。
E41: 本環境では監視周期=3分、レスポンスタイムアウト=5秒で3回とする。
E44: (１) 目的
F45: 本番用の Web サイト(master.XXX.click)を外部から監視して、その URL の正常性、およびパフォーマンスを監視する。
E47: (２) 方式
F48: 下記方式で監視を行う。
G49: ・定期的にURLを監視し、異常があればアラートを発砲する。
H50: ※監視URLは、監視周期毎（1周期=3分）にチェックされ、HTTPステータスが指定のステータスコード以外の場合にエラーとする。応答がない場合は、タイムアウト（秒）で設定した時間まで待機します。
H51: ※タイムアウトで設定した時間を超えて応答がない場合、リトライで設定した回数分ステータスコードを繰り返し確認する。（リトライ3回であれば、合計4回ステータスコードを確認)
H52: リトライ数＋1回目の確認時に応答がない場合に警報として検知する。
F55: 破線部分の機能要求詳細は以下の通り。
G56: NO | I56: 実装方式 | P56: 監視方式 | X56: 監視内容 | AT56: 機能要求 | BN56: 備考
G57: 1 | I57: Creageサービス | P57: URI監視 | X57: URIの応答により正常性を判断する | AT57: 監視要件の指定はない為、最大3分以内に検知する。
E59: (３) 監視対象
F60: 本方式による監視対象は以下の通り。
G61: NO | I61: 環境 | O61: コンポーネント | V61: 備考
...

Sheet ８．運用機能設計
A1: =表紙!A1 -> POS Server2.0基本設計 | L1: 大分類 | V1: 中分類 | AF1: 小分類 | AP1: 作成者 | AU1: 作成日 | AZ1: 更新日
L2: =表紙!L2 -> 基本設計書 | V2: =表紙!V2 -> - | AF2: =RIGHT(CELL("filename",$A$2),LEN(CELL("filename",$A$2))-FIND("]",CELL("filename",$A$2))) -> #VALUE! | AU2: =表紙!AU2 -> 45803
A4: ８．運用機能設計
B6: ８．１ 本システムでの運用機能について
C7: 本環境における運用について記載を行う。
B10: ８．２ 本システムでの運用機能一覧
C11: 運用機能として実装するものは下記のとおり。
D12: No | F12: 運用 | M12: 機能 | Z12: 実装方式 | AQ12: 実施者 | AX12: 備考
D13: 1 | F13: サイト開設 | M13: ヒアリングシート | Z13: システム構築に必要となる情報のヒアリングシート | AQ13: XXX | AX13: ヒアリングシートに必要となる情報を提示予定
M14: AWSアカウント提供 | Z14: 手順により実装 | AQ14: XXX/YYY | AX14: XXXで用意するユーザーの構築手順は提供予定
M15: 環境構築・検証 | Z15: CloudFormationにより実装する | AQ15: クレスコ
D16: 2 | F16: サイト閉塞 | M16: 依頼受領 | Z16: ー | AQ16: XXX
M17: 環境破棄 | Z17: シェルスクリプトの実行により実装する。 | AQ17: クレスコ | AX17: 90日間の閉鎖後期間を保持しない。
M18: AWSアカウント削除 | Z18: ー | AQ18: XXX/YYY
D19: 3 | F19: コンテンツリリース | M19: リリース運用 | Z19: コンソールでのドラッグドロップ | AQ19: XXX/外部ベンダー | AX19: Admin権限には CI/CDによる実装も可とする。
M20: 検証用Webサイトの検証完了後の運用 | Z20: 手順書により実装 | AQ20: XXX
D21: 4 | F21: メンテナンス | M21: ログ確認運用 | Z21: 手順書を別途作成する | AQ21: XXX
M22: アクセス数確認運用 | Z22: 手順書を別途作成する | AQ22: XXX
C25: ８．２．１．サイト開設
D26: （１）ヒアリングシート
E27: エンドユーザーに対してヒアリングを行い、個別環境のカスタマイズを実施する。
E28: ヒアリングはヒアリングシートに基づいて行う。
E30: 構築に係わるヒアリング内容は以下のとおり。
E31: ヒアリング内容 | Y31: 備考
E32: 本番・検証用ドメイン名
E33: ドメイン登録情報
E34: 証明書の発行要否 | Y34: ※外部発行時はACMのコンソール上でインポートをする
D37: （２）AWSアカウント発行・ユーザー作成
E38: YYY社がAWSアカウントを設定後、XXX社が自社管理用Adminユーザー及びクレスコ用Adminユーザーを作成する。
E39: 作成されたユーザーを使用して、クレスコが環境構築を実施する。
E40: XXX用Vendor権限ユーザーの１個目はクレスコが作成する。
E41: XXX用Vendor権限ユーザーの２個目以降は必要に応じてXXXが作成する。
E42: 共用環境の場合、サブディレクトリへの制御ポリシー及び、グループ＆ユーザーをXXX が作成する。
D44: （３）環境構築・検証
E45: 構築用ユーザーを使用して、CloudFormationを実行する。
E46: CloudFormationのテンプレートは、ヒアリング内容に沿って編集する。
C49: ８．２．２．サイト閉塞
D50: （１）依頼受領
E51: エンドユーザーからサイト閉塞の依頼を受領し、クレスコ社へリソース削除の依頼をする。
D54: （２）環境破棄
...

Sheet 別紙1.構成図
A1: =表紙!A1 -> POS Server2.0基本設計 | L1: 大分類 | V1: 中分類 | AF1: 小分類 | AP1: 作成者 | AU1: 作成日 | AZ1: 更新日
L2: =表紙!L2 -> 基本設計書 | V2: =表紙!V2 -> - | AF2: =RIGHT(CELL("filename",$A$2),LEN(CELL("filename",$A$2))-FIND("]",CELL("filename",$A$2))) -> #VALUE! | AP2: =表紙!AP2 -> 山本 | AU2: =表紙!AU2 -> 45803
A3: 別紙1 | D3: 構成図
B4: 本構成で構築する環境は以下の通り。
D5: 本番環境
D20: 開発環境
D32: スパイク環境
