Workbook

Sheet 表紙
A1: システム名 | K1: システム種別 | W1: 詳細設計書 | AP1: 作成者 | AT1: 作成日 | AY1: 更新者 | BC1: 更新日 | BH1: 版数
A2: POSサーバー | K2: POSサーバー | AP2: =改訂履歴!$H$11 -> DuNT | AT2: =改訂履歴!$B$11 -> 45508 | AY2: =LOOKUP(2,1/(改訂履歴!H11:H30000<>""),改訂履歴!H11:H30000) -> DuNT | BC2: =LOOKUP(2,1/(改訂履歴!B11:B30000<>""),改訂履歴!B11:B30000) -> 45508 | BH2: =LOOKUP(2,1/(改訂履歴!O11:O30000<>""),改訂履歴!O11:O30000) -> 0.1
A4: 機能カテゴリ | H4: API_00_Common | U4: 項目 | Z4: API設計書 | AP4: {=RIGHT(CELL("filename",$A$1),LEN(CELL("filename",$A$1))-FIND("]",CELL("filename",$A$1)))} -> 表紙
L16: POSサーバーの詳細設計書
L24: =K2&"/"&H4&"/"&Z4 -> POSサーバー/API_00_Common/API設計書
Q44: 承認日 | AA44: 承認者 | AQ44: 版数

Sheet 改訂履歴
A1: システム名 | K1: システム種別 | W1: =IF(表紙!W1="","",表紙!W1) -> 詳細設計書 | AP1: 作成者 | AT1: 作成日 | AY1: 更新者 | BC1: 更新日 | BH1: 版数
A2: =IF(表紙!A2="","",表紙!A2) -> POSサーバー | K2: =IF(表紙!K2="","",表紙!K2) -> POSサーバー | AP2: =IF(表紙!AP2="","",表紙!AP2) -> DuNT | AT2: =IF(表紙!AT2="","",表紙!AT2) -> 45508 | AY2: =IF(表紙!AY2="","",表紙!AY2) -> DuNT | BC2: =IF(表紙!BC2="","",表紙!BC2) -> 45508 | BH2: =IF(表紙!BH2="","",表紙!BH2) -> 0.1
A4: 機能カテゴリー | H4: =IF(表紙!H4="","",表紙!H4) -> API_00_Common | U4: 項目 | Z4: =IF(表紙!Z4="","",表紙!Z4) -> API設計書 | AP4: {=RIGHT(CELL("filename",$A$1),LEN(CELL("filename",$A$1))-FIND("]",CELL("filename",$A$1)))} -> 改訂履歴
B8: ■改訂履歴
B10: 更新日 | H10: 更新者 | O10: 版数 | S10: 更新内容 | AX10: 承認日 | BD10: 承認者
B11: 45508 | H11: DuNT | O11: 0.1 | S11: 新規

Sheet 処理フロー凡例
A1: システム名 | K1: システム種別 | W1: =IF(表紙!W1="","",表紙!W1) -> 詳細設計書 | AP1: 作成者 | AT1: 作成日 | AY1: 更新者 | BC1: 更新日 | BH1: 版数
A2: =IF(表紙!A2="","",表紙!A2) -> POSサーバー | K2: =IF(表紙!K2="","",表紙!K2) -> POSサーバー | AP2: =IF(表紙!AP2="","",表紙!AP2) -> DuNT | AT2: =IF(表紙!AT2="","",表紙!AT2) -> 45508 | AY2: =IF(表紙!AY2="","",表紙!AY2) -> DuNT | BC2: =IF(表紙!BC2="","",表紙!BC2) -> 45508 | BH2: =IF(表紙!BH2="","",表紙!BH2) -> 0.1
A4: 機能カテゴリ | H4: =IF(表紙!H4="","",表紙!H4) -> API_00_Common | U4: 項目 | Z4: =IF(表紙!Z4="","",表紙!Z4) -> API設計書 | AP4: =MID(CELL("filename",A1),FIND("]",CELL("filename",A1))+1,255) -> 処理フロー凡例
B7: ●API処理フロー

Sheet ルール
A1: システム名 | K1: システム種別 | W1: =IF(表紙!W1="","",表紙!W1) -> 詳細設計書 | AP1: 作成者 | AT1: 作成日 | AY1: 更新者 | BC1: 更新日 | BH1: 版数
A2: =IF(表紙!A2="","",表紙!A2) -> POSサーバー | K2: =IF(表紙!K2="","",表紙!K2) -> POSサーバー | AP2: =IF(表紙!AP2="","",表紙!AP2) -> DuNT | AT2: =IF(表紙!AT2="","",表紙!AT2) -> 45508 | AY2: =IF(表紙!AY2="","",表紙!AY2) -> DuNT | BC2: =IF(表紙!BC2="","",表紙!BC2) -> 45508 | BH2: =IF(表紙!BH2="","",表紙!BH2) -> 0.1
A4: 機能カテゴリ | H4: =IF(表紙!H4="","",表紙!H4) -> API_00_Common | U4: 項目 | Z4: =IF(表紙!Z4="","",表紙!Z4) -> API設計書 | AP4: =MID(CELL("filename",A1),FIND("]",CELL("filename",A1))+1,255) -> ルール
B7: 1. 全てのAPIのパス
C8: ・先頭：api/v1/
C9: ・URLパラメータ：kebab-caseで命名
C10: ・小文字の文字列を使用する。

Sheet レスポンス共通
A1: システム名 | K1: システム種別 | W1: =IF(表紙!W1="","",表紙!W1) -> 詳細設計書 | AP1: 作成者 | AT1: 作成日 | AY1: 更新者 | BC1: 更新日 | BH1: 版数
A2: =IF(表紙!A2="","",表紙!A2) -> POSサーバー | K2: =IF(表紙!K2="","",表紙!K2) -> POSサーバー | AP2: =IF(表紙!AP2="","",表紙!AP2) -> DuNT | AT2: =IF(表紙!AT2="","",表紙!AT2) -> 45508 | AY2: =IF(表紙!AY2="","",表紙!AY2) -> DuNT | BC2: =IF(表紙!BC2="","",表紙!BC2) -> 45508 | BH2: =IF(表紙!BH2="","",表紙!BH2) -> 0.1
A4: 機能カテゴリ | H4: =IF(表紙!H4="","",表紙!H4) -> API_00_Common | U4: 項目 | Z4: =IF(表紙!Z4="","",表紙!Z4) -> API設計書 | AP4: =MID(CELL("filename",A1),FIND("]",CELL("filename",A1))+1,255) -> レスポンス共通
B7: APIレスポンス処理方針
B9: 概要:
C11: 1. 返却HTTPステータスコード
D13: 標準的なHTTPコードはクライアントの要求結果を伝えるために使用できる。以下の5つのタイプが含まれている。
E14: 1xx: 情報 – 転送プロトコルレベルでの情報伝達
E15: 2xx: 成功 - クライアントの要求が正常に受け入れられたことを示す。
E16: 3xx: リダイレクト - クライアントが要求を完了するために追加のアクションを実行する必要があることを示す。
E17: 4xx: クライアントエラー - クライアント側のエラーを示すステータスコードの種類
E18: 5xx: サーバーエラー –サーバーがこれらのエラーステータスコードについて担当する。
C20: No | E20: ステータス | H20: 名称 | O20: コンテンツ | AS20: エラーメッセージ
C21: 1 | E21: 200 | H21: OK | O21: 要求が成功した | AS21: ー
C22: 2 | E22: 201 | H22: Created | O22: データ挿入が成功した | AS22: ー
C23: 3 | E23: 202 | H23: Accepted | O23: 要求が実行されたが、完了していない（例：バッチを実行するAPI呼出など） | AS23: ー
C24: 4 | E24: 204 | H24: No Content | O24: 要求が成功したが、レスポンスに内容がない | AS24: ー
C25: 5 | E25: 301 | H25: Moved Permanently | O25: プログラムが完全に新しいURLに移動した | AS25: ー
C26: 6 | E26: 302 | H26: Found | O26: プログラムが一時的に別のURLに移動した。ブラウザは現在の要求には新しいURLを使用するが、将来の要求に元のURLを引き続き使用する。 | AS26: ー
C27: 7 | E27: 303 | H27: See Other | O27: 要求に対するレスポンスは、GETメソッドを使用して別のURLで見つけられる。通常はアクションが実行された後に使用される。 | AS27: ー
C28: 8 | E28: 304 | H28: Not Modified | O28: リソースは最後に要求された時から変更されていない。ブラウザはキャッシュ内のバックアップを使用できる。 | AS28: ー
C29: 9 | E29: 400 | H29: Bad Request | O29: クライアントの要求がサーバーによって理解されない（無効な構文のため） | AS29: MSG_ERR_011
C30: 10 | E30: 401 | H30: Unauthorized | O30: 要求には認証が必要であるが、認証情報が提供されていないか、情報が無効になる（例：無効なトークン、期限切れなど） | AS30: MSG_ERR_012
C31: 11 | E31: 403 | H31: Forbidden | O31: サーバーは要求を理解しているが、クライアントがアクセス権を持たないため実行を拒否する（アカウントが機能を実行する権限を持たない場合にエラー） | AS31: MSG_ERR_013
C32: 12 | E32: 404 | H32: Not Found | O32: サーバーが要求されたリソースを見つけられない (レコードが検索できないなど) | AS32: MSG_ERR_001
... C39: 18 | E39: 505 | H39: HTTP Version Not Supported | O39: サーバーが要求で使用されているHTTPプロトコルのバージョンをサポートしていない | AS39: MSG_ERR_018
C40: 参考資料：https://restfulapi.net/http-status-codes/
C42: 2. APIから返される情報のボディエリア
D44: 2.1 データ形式：Json
D46: 2.2 コンテンツ
E47: ▪成功した場合：Response code = 200、レスポンス形式が以下のように返す。
G49: No. | I49: JSON name | S49: 型 | W49: 項目名 | AG49: 備考
G50: 1 | I50: status | S50: String | W50: - | AG50: 成功・失敗 失敗の場合：例：CSVファイルの取込は成功したが、バリデーションチェックに失敗した行がある ->取込を実行しない。
G51: =G50+1 -> 2 | I51: data | S51: Object | W51: - | AG51: 各APIのレスポンスデータ
F53: {
G54: "status": "Success",
G55: "data": {
H56: //data object/list here
G57: }
F58: }
...

Sheet 権限共通
A1: システム名 | K1: システム種別 | W1: =IF(表紙!W1="","",表紙!W1) -> 詳細設計書 | AP1: 作成者 | AT1: 作成日 | AY1: 更新者 | BC1: 更新日 | BH1: 版数
A2: =IF(表紙!A2="","",表紙!A2) -> POSサーバー | K2: =IF(表紙!K2="","",表紙!K2) -> POSサーバー | AP2: =IF(表紙!AP2="","",表紙!AP2) -> DuNT | AT2: =IF(表紙!AT2="","",表紙!AT2) -> 45508 | AY2: =IF(表紙!AY2="","",表紙!AY2) -> DuNT | BC2: =IF(表紙!BC2="","",表紙!BC2) -> 45508 | BH2: =IF(表紙!BH2="","",表紙!BH2) -> 0.1
A4: 機能カテゴリ | H4: =IF(表紙!H4="","",表紙!H4) -> API_00_Common | U4: 項目 | Z4: =IF(表紙!Z4="","",表紙!Z4) -> API設計書 | AP4: =MID(CELL("filename",A1),FIND("]",CELL("filename",A1))+1,255) -> 権限共通
C8: 1. POSサーバーシステムの権限付与
D10: POSサーバーシステムのアカウントには、以下の2種類の権限がある。
E11: 1. システム権限を持つアカウント
F12: アカウントが所属する会社内の全ての店舗に関するデータを表示・設定（追加、編集、削除）できる。
E15: 2. システム権限を持たないアカウント
F16: ・権限が付与されたAPIのみ実行・使用できる。
G17: 権限が付与されたAPIのリスト。40_API設計_目次.xlsxをご参照ください。
F18: ・アカウントが所属する店舗に関するデータのみ表示・設定（追加、編集、削除）できる。
C21: 2. 処理

Sheet テンプレート
A1: システム名 | K1: システム種別 | W1: =IF(表紙!W1="","",表紙!W1) -> 詳細設計書 | AP1: 作成者 | AT1: 作成日 | AY1: 更新者 | BC1: 更新日 | BH1: 版数
A2: =IF(表紙!A2="","",表紙!A2) -> POSサーバー | K2: =IF(表紙!K2="","",表紙!K2) -> POSサーバー | AP2: =IF(表紙!AP2="","",表紙!AP2) -> DuNT | AT2: =IF(表紙!AT2="","",表紙!AT2) -> 45508 | AY2: =IF(表紙!AY2="","",表紙!AY2) -> DuNT | BC2: =IF(表紙!BC2="","",表紙!BC2) -> 45508 | BH2: =IF(表紙!BH2="","",表紙!BH2) -> 0.1
A4: 機能カテゴリ | H4: =IF(表紙!H4="","",表紙!H4) -> API_00_Common | U4: 項目 | Z4: =IF(表紙!Z4="","",表紙!Z4) -> API設計書 | AP4: =MID(CELL("filename",A1),FIND("]",CELL("filename",A1))+1,255) -> テンプレート
