Workbook
Name ____PFM2: #REF!
Name ____PFM21: #REF!
Name ____pfm3: #REF!
Name ___PFM2: #REF!
Name ___PFM21: #REF!
Name ___pfm3: #REF!
Name __PFM2: #REF!
Name __PFM21: #REF!
Name __pfm3: #REF!
Name _1Excel_BuiltIn__FilterDatabase_1: #REF!
Name _2Excel_BuiltIn__FilterDatabase_1_1: #REF!
Name _3Nagaoka_障害一覧_発生_改修: #REF!
Name _PFM2: #REF!
Name _PFM21: #REF!
Name _pfm3: #REF!
Name a: #REF!
Name aaa: #REF!
Name BASE: #REF!
Name BASE2: #REF!
Name bbb: #REF!
Name DISC_CLASS_LVL: #REF!
Name DISC_EXCEPTION: #REF!
Name DISC_EXCEPTION: #REF!
Name DISC_EXCEPTION: #REF!
Name DISC_STEP: #REF!
Name DISC_STEP: #REF!
Name DISC_STEP: #REF!
Name DISC_TARGET: #REF!
Name DISC_TARGET: #REF!
Name DISC_TARGET: #REF!
Name DS_KEYS: #REF!
Name DS_NM: #REF!
Name Grpリーダ: #REF!
Name HTML_Control_1: {"'表紙'!$A$1:$W$39"}
Name HTML_Control_1: {"'表紙'!$A$1:$W$39"}
Name HTML_Control_1: {"'表紙'!$A$1:$W$39"}
Name ITﾃｽﾄ基準: #REF!
Name ITﾃｽﾄ基準小計1: #REF!
Name ITﾃｽﾄ基準小計2: #REF!
Name ITﾃｽﾄ基準小計2ｺﾋﾟｰ: #REF!
Name ITﾃｽﾄ実績: #REF!
Name ITﾃｽﾄ実績小計1: #REF!
Name ＩＴﾃｽﾄ実績小計1ｺﾋﾟｰ: #REF!
Name ITﾃｽﾄ実績小計2: #REF!
Name IT障害基準: #REF!
Name IT障害基準小計1: #REF!
Name IT障害基準小計2: #REF!
Name IT障害実績: #REF!
Name IT障害実績小計1: #REF!
Name IT障害実績小計2: #REF!
Name KEYS: #REF!
Name NAMES: #REF!
Name NEC_KEYS: #REF!
Name PGﾃｽﾄ基準: #REF!
Name PGﾃｽﾄ基準小計1: #REF!
Name PGﾃｽﾄ基準小計2: #REF!
Name PGﾃｽﾄ実績: #REF!
Name PGﾃｽﾄ実績小計1: #REF!
Name PGﾃｽﾄ実績小計2: #REF!
Name PG障害基準: #REF!

Sheet 表紙
B3: U.S.M.Holdings様／いなげや様
H24: 1.13
G27: =MAX(改版履歴!C10:F226) -> 45709
F31: 富士通株式会社
D36: U.S.M.Holdings様／いなげや様 | J36: 富士通
D37: 承認 | F37: 承認 | H37: 承認 | J37: 承認 | L37: 確認 | N37: リーダー

Sheet 改版履歴
B2: TeamStore/M POSシステム | O2: システム名 | U2: 業務名 | AB2: 改版履歴 | AO2: 履歴 | AQ2: 改訂者 | AT2: 最新更新日 | AX2: 作成者 | BA2: 作成日
B3: UI設計書 | O3: トラン連携対応 | U3: トラン連携対応レイアウト | AO3: 1.12 | AQ3: 富士通 | AT3: =MAX(C10:F226) -> 45709 | AX3: 富士通 | BA3: 45460
C6: 改版履歴
C8: 日付 | G8: 版数 | I8: 章番号 | O8: 修正内容 | AZ8: 担当
C10: 45460 | G10: 0.1 | O10: 新規作成 | AZ10: 富士通
C12: 45462 | G12: 1 | O12: ＜2024/6/17 打合せ内容の反映＞ | AZ12: 富士通
O13: TRANS_HEADER
O14: No.20 取引合計額
O15: ・入金／出金の設定値を修正
O16: No.54 ポイント対象金額
O17: ・設定値を基本ポイント対象額に修正
O18: LN_LINK
O19: No.3 リンク明細番号
O20: ・説明文を修正
O21: LN_DISCOUNT
O22: No.7 ディスカウントＩＤ
O23: ・取得元マスタ項目の「１：小計額値引」を「１３：小計額値引」に修正
O24: No.15 企画No
... O49: (続く)
B52: TeamStore/M POSシステム | O52: システム名 | U52: 業務名 | AB52: 改版履歴 | AO52: 履歴 | AQ52: 改訂者 | AT52: 最新更新日 | AX52: 作成者 | BA52: 作成日
B53: UI設計書 | O53: トラン連携対応 | U53: トラン連携対応レイアウト | AO53: =AO3 -> 1.12 | AQ53: 富士通 | AT53: =AT3 -> 45709 | AX53: 富士通 | BA53: =BA3 -> 45460
C56: 改版履歴
C58: 日付 | G58: 版数 | I58: 章番号 | O58: 修正内容 | AZ58: 担当
C60: 45462 | G60: 1 | O60: (続き) | AZ60: 富士通
O61: LN_LINK
O62: No.4 リンクタイプ
O63: ・説明文を修正
O64: LN_DETAIL
O65: No.15 合計原価
O66: ・合計原価を設定に修正
O67: No.31 特売原価
O68: ・特売原価を設定（1個当たりの原価）を設定に修正
O69: No.32 スキャンコード（単品登録時）
O70: ・説明文に「部門登録の場合は””(空白)を設定する。」を追記
O71: No.40 ポイント倍率
O72: ・グレーアウト（連携なし）に修正
... O75: ・備考欄を「取引の外税対象金額を設定」に修正
C76: 45467 | G76: 1.1 | O76: ＜2024/6/19 打合せ内容の反映＞ | AZ76: 富士通
O77: 取引ログ作成時の注意事項
O78: 「⑥精算回数、精算通番について」を追加
...

Sheet 連携対象取引ログテーブル一覧
B2: TeamStore/M POSシステム | O2: システム名 | U2: 業務名 | AB2: トラン連携対象取引ログテーブル一覧 | AO2: 履歴 | AQ2: 改訂者 | AT2: 最新更新日 | AX2: 作成者 | BA2: 作成日
B3: UI設計書 | O3: トラン連携対応 | U3: トラン連携対応レイアウト | AO3: =改版履歴!AO3 -> 1.12 | AQ3: 富士通 | AT3: =改版履歴!AT3 -> 45709 | AX3: 富士通 | BA3: 45460
C6: トラン連携対象取引ログテーブル一覧
D8: № | E8: テーブル名 | O8: 名称 | Y8: データ作成元 | AE8: ファイル連携 | AI8: 補足説明
D9: 1 | E9: TRANS_HEADER | O9: 取引情報 | Y9: ignicaPOS | AE9: あり
D10: =OFFSET(D10,-1,0,1,1)+1 -> 2 | E10: LN_LINK | O10: 取引明細のリンク情報 | Y10: ignicaPOS | AE10: あり
D11: =OFFSET(D11,-1,0,1,1)+1 -> 3 | E11: LN_DETAIL | O11: 商品明細情報 | Y11: ignicaPOS | AE11: あり
D12: =OFFSET(D12,-1,0,1,1)+1 -> 4 | E12: LN_DISCOUNT | O12: 値引情報 | Y12: ignicaPOS | AE12: あり
D13: =OFFSET(D13,-1,0,1,1)+1 -> 5 | E13: TRANSACTION_TAX | O13: 取引の税情報 | Y13: ignicaPOS | AE13: あり
D14: =OFFSET(D14,-1,0,1,1)+1 -> 6 | E14: TRANSACTION_TENDER | O14: 取引の支払情報 | Y14: ignicaPOS | AE14: あり
D15: =OFFSET(D15,-1,0,1,1)+1 -> 7 | E15: GIFT_CERT_TENDER | O15: 現外支払情報 | Y15: ignicaPOS | AE15: あり
D16: =OFFSET(D16,-1,0,1,1)+1 -> 8 | E16: GSFD_PNT_TRANS_HEADER | O16: ポイント情報 | Y16: ignicaPOS | AE16: あり
D17: =OFFSET(D17,-1,0,1,1)+1 -> 9 | E17: MANUAL_PRICE | O17: 価格変更情報 | Y17: ignicaPOS、TS/M | AE17: あり | AI17: 特売の時はTS/Mで作成
D18: =OFFSET(D18,-1,0,1,1)+1 -> 10 | E18: GL_TRAN | O18: 支払情報 | Y18: ignicaPOS | AE18: あり
D19: =OFFSET(D19,-1,0,1,1)+1 -> 11 | E19: LOAN_PICKUP | O19: 入出金情報 | Y19: ignicaPOS | AE19: あり
D20: =OFFSET(D20,-1,0,1,1)+1 -> 12 | E20: TENDER_ON_HAND | O20: 支払状況 | Y20: TS/M | AE20: 無し
D21: =OFFSET(D21,-1,0,1,1)+1 -> 13 | E21: GSFD_PNT_KICK | O21: ポイント処理起動トリガテーブル | Y21: TS/M | AE21: 無し
D22: =OFFSET(D22,-1,0,1,1)+1 -> 14 | E22: GSFD_RPT_KICK | O22: 集計起動トリガテーブル | Y22: TS/M | AE22: 無し
D23: =OFFSET(D23,-1,0,1,1)+1 -> 15 | E23: TRANS_DG | O23: 顧客情報 | Y23: - | AE23: -
D24: =OFFSET(D24,-1,0,1,1)+1 -> 16 | E24: PLU_NOT_FOUND | O24: 緊急登録情報 | Y24: - | AE24: -
D25: =OFFSET(D25,-1,0,1,1)+1 -> 17 | E25: POST_VOID_TRAN | O25: 取消情報 | Y25: - | AE25: -
D26: =OFFSET(D26,-1,0,1,1)+1 -> 18 | E26: TENDER_COUNT | O26: 金種登録情報 | Y26: - | AE26: -
D27: =OFFSET(D27,-1,0,1,1)+1 -> 19 | E27: TENDER_CNT_DETAIL | O27: 金種登録詳細情報 | Y27: - | AE27: -

Sheet 取引ログテーブル関連図
B2: TeamStore/M POSシステム | E2: システム名 | K2: 業務名 | N2: 取引ログテーブル関連図 | X2: 履歴 | AA2: 改訂者 | AB2: 最新更新日 | AC2: 作成者 | AF2: 作成日
B3: UI設計書 | E3: トラン連携対応 | K3: トラン連携対応レイアウト | X3: =連携対象取引ログテーブル一覧!AO3 -> 1.12 | AA3: 富士通 | AB3: =連携対象取引ログテーブル一覧!AT3 -> 45709 | AC3: 富士通 | AF3: 45460
AB6: ：TRAN_IDのリンク (富士通側でトラン取込み後にリンク付け)
AB7: ：TRAN_LN_NBR (1取引内での通し番号(抜け/重複なし)、順不同)
AB8: ：TRAN_LN_NBRのリンク
C9: ※1取引に1レコードを作成(必須)
C10: TRANS_HEADER/取引情報 | AA10: ※値引数分のレコードを作成
C11: カラム名称 | D11: 日本語名称 | E11: 型 | F11: サイズ | G11: KEY | H11: 設定例 | K11: ※商品明細数分のレコードを作成 | S11: ※商品明細1レコードに対して複数(リンク数分)のレコードを作成 | AA11: LN_DISCOUNT/値引情報
C12: GSFD_ACCOUNT_ID | D12: アカウントID | E12: varchar | F12: 9 | K12: LN_DETAIL/商品明細情報 | S12: LN_LINK/取引明細のリンク情報 | AA12: カラム名称 | AB12: 日本語名称 | AC12: 型 | AD12: サイズ | AE12: KEY | AF12: 設定例
C13: GSFD_JOURNAL_NO | D13: ジャーナルNo. | E13: varchar | F13: 9 | K13: カラム名称 | L13: 日本語名称 | M13: 型 | N13: サイズ | O13: KEY | P13: 設定例 | S13: カラム名称 | T13: 日本語名称 | U13: 型 | V13: サイズ | W13: KEY | X13: 設定例 | AA13: TRAN_LN_NBR | AB13: 取引明細番号 | AC13: smallint | AE13: PK
C14: TRAN_ID | D14: 取引通番 | E14: int | G14: PK | K14: TRAN_ID | L14: 取引通番 | M14: int | O14: PK | S14: TRAN_ID | T14: 取引通番 | U14: int | W14: PK | AA14: TRAN_ID | AB14: 取引通番 | AC14: int | AE14: PK
C15: RGST_TRAN_NBR | D15: レジ内取引通番 | E15: smallint | K15: TRAN_LN_NBR | L15: 取引明細番号 | M15: smallint | O15: PK | S15: TRAN_LN_NBR | T15: 取引明細番号 | U15: smallint | W15: PK | AA15: STR_ID | AB15: 店舗番号 | AC15: int | AE15: PK
C16: TRAN_CD | D16: 取引コード | E16: smallint | H16: 1 | K16: STR_ID | L16: 店舗番号 | M16: int | O16: PK | S16: LINK_LN_NBR | T16: リンク明細番号 | U16: smallint | W16: PK | AA16: DISC_MTHD | AB16: ディスカウント方法 | AC16: smallint
D17: 1:売上 | K17: LOC_ID | L17: 商品在庫位置 | M17: varchar | N17: 12 | S17: LINK_TYPE | T17: リンクタイプ | U17: smallint | W17: PK | X17: 1 | AA17: DISC_AMT | AB17: ディスカウント金額 | AC17: Money
C18: STR_ID | D18: 店舗番号 | E18: int | G18: PK | K18: SCAN_TYP | L18: PLUタイプ | M18: smallint | T18: 1：値引 | AA18: DISC_VALUE | AB18: ディスカウント値 | AC18: float
C19: EMP_ID | D19: 従業員ＩＤ | E19: varchar | F19: 12 | L19: 2：UPC-A | S19: LINK_AMT | T19: リンク明細額 | U19: Money | AA19: DISC_ID | AB19: ディスカウントＩＤ | AC19: int
C20: RGST_ID | D20: レジスタID | E20: int | L20: 3：部門コード | S20: STR_ID | T20: 店舗番号 | U20: int | W20: PK | AA20: VOID_CD | AB20: 取消コード | AC20: smallint
C21: TILL_ID | D21: ティルID | E21: varchar | F21: 12 | L21: 4：EAN8、JAN8(NONPLU8) | S21: LINK_QTY | T21: リンクの数 | U21: float | AA21: DISC_ACCT | AB21: ディスカウント会計科目 | AC21: varchar | AD21: 24
C22: BUS_DT | D22: 営業日 | E22: datetime | L22: 5：EAN13、JAN13(NONPLU13)、新/旧書籍、新/旧雑誌 | AA22: DG_ID | AB22: ディスカウントグループＩＤ | AC22: varchar | AD22: 12
C23: TRAN_START_TS | D23: 取引開始時刻 | E23: datetime | L23: etc. | AA23: EVNT_ID | AB23: イベントコード | AC23: varchar | AD23: 6
C24: TRAN_END_DTTM | D24: 取引終了時刻 | E24: datetime | K24: PLU_ID | L24: 自社商品コード | M24: varchar | N24: 24 | AA24: DISC_CLSS_ID | AB24: ディスカウントクラスＩＤ | AC24: int
C25: OFFLN_FG | D25: オフライン判別 | E25: smallint | K25: SCAN_ID | L25: スキャンコード | M25: varchar | N25: 24 | AB25: ※値引コード一覧を参照
C26: TRNING_MDE_FG | D26: トレーニングモード | E26: smallint | K26: LN_ITM_CD | L26: 商品明細識別 | M26: smallint | AA26: … | AB26: …
C27: RNTRY_MDE_FG | D27: 再入力モード | E27: smallint | K27: MDSE_XREF_NO | L27: 商品分類番号 | M27: int | AA27: GSFD_EVNT_NBR | AB27: 企画コード | AC27: varchar | AD27: 7
C28: VOID_CD | D28: 取消コード | E28: smallint | K28: STR_HIER_ID | L28: 販売部門ID | M28: int | AA28: … | AB28: …
D29: 0：通常取引、1：取引中止 | K29: QTY | L29: 販売数量 | M29: float
C30: CUST_ID | D30: 顧客ID | E30: varchar | F30: 24 | K30: UOM | L30: 販売単位 | M30: varchar | N30: 4
C31: SHPR_ID | D31: 買い物客ID | E31: varchar | F31: 24 | K31: PRC_MTHD | L31: 価格算出方法 | M31: smallint | AA31: ※部門登録、価格手入力(PLU)、売価変更を行った場合にレコードを作成
C32: STAT | D32: ステータス | E32: smallint | K32: EXT_PRC | L32: 合価 | M32: Money | AA32: MANUAL_PRICE/価格変更情報
C33: TOT_AMT | D33: 取引合計額 | E33: money | K33: EXT_CST | L33: 合計原価 | M33: Money | AA33: カラム名称 | AB33: 日本語名称 | AC33: 型 | AD33: サイズ | AE33: KEY | AF33: 設定例
C34: … | D34: … | K34: RTL_PRC | L34: 小売価格 | M34: Money | AA34: TRAN_LN_NBR | AB34: 取引明細番号 | AC34: smallint | AE34: PK
K35: ENTRY_MTHD | L35: 登録方法 | M35: smallint | AA35: ORIG_PRC | AB35: 変更前価格 | AC35: money | AE35: PK
K36: COMM_EMP_ID | L36: 担当従業員ＩＤ | M36: varchar | N36: 12 | AA36: TRAN_ID | AB36: 取引通番 | AC36: int | AE36: PK
C37: ※1取引に1レコードを作成(ポイントカード登録がある場合のみ) | K37: … | L37: … | AA37: STR_ID | AB37: 店舗番号 | AC37: int | AE37: PK
C38: GSFD_PNT_TRANS_HEADER/ポイント情報 | K38: GSFD_SCAN_CODE | L38: スキャンコード（単品登録時） | M38: varchar | N38: 75 | AA38: AUTH_EMP_ID | AB38: 承認従業員ID | AC38: varchar | AD38: 12
C39: カラム名称 | D39: 日本語名称 | E39: 型 | F39: サイズ | G39: KEY | H39: 設定例 | K39: … | L39: … | AA39: OVRD_PRC | AB39: 変更価格 | AC39: money
C40: TRAN_ID | D40: 取引通番 | E40: int | G40: PK | K40: GSFD_TAX_TYPE | L40: 明細の税種別 | M40: smallint | AA40: … | AB40: …
C41: STR_ID | D41: 店舗番号 | E41: int | G41: PK | L41: 1：外税、2：内税、3：非課税
C42: RGST_TRAN_NBR | D42: POS取引通番 | E42: smallint | K42: … | L42: …
C43: RGST_ID | D43: POS番号 | E43: int | K43: GSFD_PLU_TAXBLTY_CD | L43: 明細の税種別コード | M43: smallint | AA43: ※取引に含まれる税種別コード分のレコードを作成
...

Sheet 取引ログテーブル関連図（補足説明）
B2: TeamStore/M POSシステム | E2: システム名 | K2: 業務名 | N2: 取引ログテーブル関連図（補足説明） | X2: 履歴 | AA2: 改訂者 | AB2: 最新更新日 | AC2: 作成者 | AF2: 作成日
B3: UI設計書 | E3: トラン連携対応 | K3: トラン連携対応レイアウト | X3: =連携対象取引ログテーブル一覧!AO3 -> 1.12 | AA3: 富士通 | AB3: =取引ログテーブル関連図!AB3 -> 45709 | AC3: 富士通 | AF3: 45460
AB6: ：TRAN_IDのリンク (富士通側でトラン取込み後にリンク付け)
J7: ※説明対象テーブルのみを抜粋 | AB7: ：TRAN_LN_NBR (1取引内での通し番号(抜け/重複なし)、順不同)
AB8: ：TRAN_LN_NBRのリンク
C10: TRANS_HEADER/取引情報
C11: カラム名称 | D11: 日本語名称 | E11: 型 | F11: サイズ | G11: KEY | H11: 設定例
C12: GSFD_ACCOUNT_ID | D12: アカウントID | E12: varchar | F12: 9 | K12: LN_DETAIL/商品明細情報 | S12: LN_LINK/取引明細のリンク情報
C13: GSFD_JOURNAL_NO | D13: ジャーナルNo. | E13: varchar | F13: 9 | K13: カラム名称 | L13: 日本語名称 | M13: 型 | N13: サイズ | O13: KEY | P13: 設定例 | S13: カラム名称 | T13: 日本語名称 | U13: 型 | V13: サイズ | W13: KEY | X13: 設定例
C14: TRAN_ID | D14: 取引通番 | E14: int | G14: PK | H14: 6079449 | K14: TRAN_ID | L14: 取引通番 | M14: int | O14: PK | P14: 6079449 | S14: TRAN_ID | T14: 取引通番 | U14: int | W14: PK | X14: 6079449
C15: RGST_TRAN_NBR | D15: レジ内取引通番 | E15: smallint | H15: 54 | K15: TRAN_LN_NBR | L15: 取引明細番号 | M15: smallint | O15: PK | P15: 1 | S15: TRAN_LN_NBR | T15: 取引明細番号 | U15: smallint | W15: PK | X15: 1
C16: TRAN_CD | D16: 取引コード | E16: smallint | H16: 1 | K16: STR_ID | L16: 店舗番号 | M16: int | O16: PK | P16: 200000 | S16: LINK_LN_NBR | T16: リンク明細番号 | U16: smallint | W16: PK | X16: 8
D17: 1:売上 | K17: LOC_ID | L17: 商品在庫位置 | M17: varchar | N17: 12 | S17: LINK_TYPE | T17: リンクタイプ | U17: smallint | W17: PK | X17: 1
C18: STR_ID | D18: 店舗番号 | E18: int | G18: PK | H18: 200000 | K18: SCAN_TYP | L18: PLUタイプ | M18: smallint | P18: 5 | S18: LINK_AMT | T18: リンク明細額 | U18: Money | X18: -113
C19: EMP_ID | D19: 従業員ＩＤ | E19: varchar | F19: 12 | H19: 1111111 | K19: PLU_ID | L19: 自社商品コード | M19: varchar | N19: 24 | P19: 0000010000001 | S19: STR_ID | T19: 店舗番号 | U19: int | W19: PK | X19: 200000
C20: RGST_ID | D20: レジスタID | E20: int | H20: 2 | K20: SCAN_ID | L20: スキャンコード | M20: varchar | N20: 24 | P20: 2162000001918 | S20: LINK_QTY | T20: リンクの数 | U20: float | X20: 1
C21: TILL_ID | D21: ティルID | E21: varchar | F21: 12 | K21: … | L21: …
C22: BUS_DT | D22: 営業日 | E22: datetime | H22: 45442 | K22: QTY | L22: 販売数量 | M22: float | P22: 1
C23: TRAN_START_TS | D23: 取引開始時刻 | E23: datetime | H23: 45442.85 | K23: … | L23: …
C24: TRAN_END_DTTM | D24: 取引終了時刻 | E24: datetime | H24: 45442.851 | K24: EXT_PRC | L24: 合価 | M24: Money | P24: 2248
C25: OFFLN_FG | D25: オフライン判別 | E25: smallint | K25: … | L25: …
C26: TRNING_MDE_FG | D26: トレーニングモード | E26: smallint | K26: RTL_PRC | L26: 小売価格 | M26: Money | P26: 2248
C27: RNTRY_MDE_FG | D27: 再入力モード | E27: smallint | K27: … | L27: … | AA27: LN_DISCOUNT/値引情報
C28: VOID_CD | D28: 取消コード | E28: smallint | H28: 0 | AA28: ※単品系：単品に対する値引はLN_DETAILと１：１でレコードを作成（例：マニュアル値引 10%割引)
D29: 0：通常取引、1：取引中止 | AA29: カラム名称 | AB29: 日本語名称 | AC29: 型 | AD29: サイズ | AE29: KEY | AF29: 設定例
C30: CUST_ID | D30: 顧客ID | E30: varchar | F30: 24 | H30: 2603000711365 | K30: カラム名称 | L30: 日本語名称 | M30: 型 | N30: サイズ | O30: KEY | P30: 設定例 | S30: カラム名称 | T30: 日本語名称 | U30: 型 | V30: サイズ | W30: KEY | X30: 設定例 | AA30: TRAN_LN_NBR | AB30: 取引明細番号 | AC30: smallint | AE30: PK | AF30: 4
C31: SHPR_ID | D31: 買い物客ID | E31: varchar | F31: 24 | K31: TRAN_ID | L31: 取引通番 | M31: int | O31: PK | P31: 6079449 | S31: TRAN_ID | T31: 取引通番 | U31: int | W31: PK | X31: 6079449 | AA31: TRAN_ID | AB31: 取引通番 | AC31: int | AE31: PFK | AF31: 6079449
C32: STAT | D32: ステータス | E32: smallint | K32: TRAN_LN_NBR | L32: 取引明細番号 | M32: smallint | O32: PK | P32: 3 | S32: TRAN_LN_NBR | T32: 取引明細番号 | U32: smallint | W32: PK | X32: 3 | AA32: STR_ID | AB32: 店舗番号 | AC32: int | AE32: PFK | AF32: 200000
C33: TOT_AMT | D33: 取引合計額 | E33: money | H33: 12000 | K33: STR_ID | L33: 店舗番号 | M33: int | O33: PK | P33: 200000 | S33: LINK_LN_NBR | T33: リンク明細番号 | U33: smallint | W33: PK | X33: 4 | AA33: DISC_MTHD | AB33: ディスカウント方法 | AC33: smallint | AF33: 2
C34: … | D34: … | K34: LOC_ID | L34: 商品在庫位置 | M34: varchar | N34: 12 | S34: LINK_TYPE | T34: リンクタイプ | U34: smallint | W34: PK | X34: 1 | AB34: 2：％値引
K35: SCAN_TYP | L35: PLUタイプ | M35: smallint | P35: 5 | S35: LINK_AMT | T35: リンク明細額 | U35: Money | X35: -684 | AA35: DISC_AMT | AB35: ディスカウント金額 | AC35: Money | AF35: -684
K36: PLU_ID | L36: 自社商品コード | M36: varchar | N36: 24 | P36: 0000010000002 | S36: STR_ID | T36: 店舗番号 | U36: int | W36: PK | X36: 200000 | AA36: DISC_VALUE | AB36: ディスカウント値 | AC36: float | AF36: 0.1
C37: 【説明例】 | K37: SCAN_ID | L37: スキャンコード | M37: varchar | N37: 24 | P37: 2162000001390 | S37: LINK_QTY | T37: リンクの数 | U37: float | X37: 3 | AA37: DISC_ID | AB37: ディスカウントＩＤ | AC37: int | AF37: 2
K38: … | L38: … | AA38: VOID_CD | AB38: 取消コード | AC38: smallint
K39: QTY | L39: 販売数量 | M39: float | P39: 3 | S39: カラム名称 | T39: 日本語名称 | U39: 型 | V39: サイズ | W39: KEY | X39: 設定例 | AA39: DISC_ACCT | AB39: ディスカウント会計科目 | AC39: varchar | AD39: 24
K40: … | L40: … | S40: TRAN_ID | T40: 取引通番 | U40: int | W40: PK | X40: 6079449 | AA40: DG_ID | AB40: ディスカウントグループＩＤ | AC40: varchar | AD40: 12
K41: EXT_PRC | L41: 合価 | M41: Money | P41: 6813 | S41: TRAN_LN_NBR | T41: 取引明細番号 | U41: smallint | W41: PK | X41: 3 | AA41: EVNT_ID | AB41: イベントコード | AC41: varchar | AD41: 6
K42: … | L42: … | S42: LINK_LN_NBR | T42: リンク明細番号 | U42: smallint | W42: PK | X42: 8 | AA42: DISC_CLSS_ID | AB42: ディスカウントクラスＩＤ | AC42: int | AF42: 91220
K43: RTL_PRC | L43: 小売価格 | M43: Money | P43: 2271 | S43: LINK_TYPE | T43: リンクタイプ | U43: smallint | W43: PK | X43: 1 | AB43: 91220：マニュアル値引
K44: … | L44: … | S44: LINK_AMT | T44: リンク明細額 | U44: Money | X44: -309 | AA44: … | AB44: …
...

Sheet 取引ログ作成時の注意事項
B2: TeamStore/M POSシステム | O2: システム名 | U2: 業務名 | AB2: 取引ログ作成時の注意事項 | AO2: 履歴 | AQ2: 改訂者 | AT2: 最新更新日 | AX2: 作成者 | BA2: 作成日
B3: UI設計書 | O3: トラン連携対応 | U3: トラン連携対応レイアウト | AO3: ='取引ログテーブル関連図（補足説明）'!X3 -> 1.12 | AQ3: 富士通 | AT3: ='取引ログテーブル関連図（補足説明）'!AB3 -> 45709 | AX3: 富士通 | BA3: 45460
C6: (1) | D6: 内税のリンク例 | BE6: (*1.5)
D8: 商品明細 | G8: 1個 | I8: \200 | J8: 内税10%商品(税抜価格：\182)
D9: 商品明細 | G9: 1個 | I9: \200 | J9: 内税8%商品(税抜価格：\186)
D10: 預金 | I10: \400
D12: 税種別（TAX_CD)
D13: 外税：１、内税：２、非課税：３、内税：９９
D15: 取引情報 | M15: 商品明細情報 | V15: 取引明細のリンク情報 | AE15: 取引の税情報
D16: TRSNS_HEADER | M16: LN_DETAIL | V16: LN_LINK | AE16: TRANSACTION_TAX | AM16: 内税10%のレコード
E17: TRAN_ID | J17: TS/Mで採番 | N17: TRAN_ID | S17: TS/Mで採番 | W17: TRAN_ID | AB17: TS/Mで採番 | AF17: TRAN_ID | AK17: TS/Mで採番
E18: TRAN_CD | J18: 1 | N18: TRAN_LN_NBR | S18: 1 | W18: TRAN_LN_NBR | AB18: 1 | AF18: TRAN_LN_NBR | AK18: 4
E19: TOT_AMT | J19: 400 | W19: LINK_LN_NBR | AB19: 4 | AF19: TAX_CD | AK19: 5(内税10%)
M20: 内税10%商品のレコード | W20: LINK_TYP | AB20: 3 | AF20: VAT_AMT | AK20: 18
V21: 内税のリンク情報 | AF21: VATABL_AMT | AK21: 182
AF22: TAXBLE_AMT | AK22: 200
V23: 取引明細のリンク情報
V24: LN_LINK
W25: TRAN_ID | AB25: TS/Mで採番
W26: TRAN_LN_NBR | AB26: 1 | AS26: 商品明細に紐づく税情報
W27: LINK_LN_NBR | AB27: 4 | AS27: ３つのリンクと1つの税情報を作成する。
W28: LINK_TYP | AB28: 9
V29: 内税額のリンク情報
V31: 取引明細のリンク情報
V32: LN_LINK
W33: TRAN_ID | AB33: TS/Mで採番
W34: TRAN_LN_NBR | AB34: 1
W35: LINK_LN_NBR | AB35: 4
W36: LINK_TYP | AB36: 10
V37: 内税商品額(税抜き)のリンク情報
V43: 取引明細のリンク情報 | AE43: 取引の税情報
V44: LN_LINK | AE44: TRANSACTION_TAX | AM44: 内税合計のレコード
W45: TRAN_ID | AB45: TS/Mで採番 | AF45: TRAN_ID | AK45: TS/Mで採番
W46: TRAN_LN_NBR | AB46: 1 | AF46: TRAN_LN_NBR | AK46: 5
W47: LINK_LN_NBR | AB47: 5 | AF47: TAX_CD | AK47: 99(内税) | AS47: 内税の合計情報
W48: LINK_TYP | AB48: 3 | AF48: VAT_AMT | AK48: 0 | AS48: (内税10%・内税8%の合計)
V49: 内税合計のレコードへのリンク | AF49: VATABL_AMT | AK49: 0
AF50: TAXBLE_AMT | AK50: 400
B56: TeamStore/M POSシステム | O56: システム名 | U56: 業務名 | AB56: 取引ログ作成時の注意事項 | AO56: 履歴 | AQ56: 改訂者 | AT56: 最新更新日 | AX56: 作成者 | BA56: 作成日
B57: UI設計書 | O57: トラン連携対応 | U57: トラン連携対応レイアウト | AO57: =AO$3 -> 1.12 | AQ57: 富士通 | AT57: =AT$3 -> 45709 | AX57: 富士通 | BA57: 45460
...

Sheet 取引ログ作成時の注意事項(税情報)
B1: TeamStore/M POSシステム | O1: システム名 | U1: 業務名 | AB1: 取引ログ作成時の注意事項（税情報） | AO1: 履歴 | AQ1: 改訂者 | AT1: 最新更新日 | AX1: 作成者 | BA1: 作成日 | BE1: *1.5 本ページ追加
B2: UI設計書 | O2: トラン連携対応 | U2: トラン連携対応レイアウト | AO2: =取引ログ作成時の注意事項!AO3 -> 1.12 | AQ2: 富士通 | AT2: =取引ログ作成時の注意事項!AT3 -> 45709 | AX2: 富士通 | BA2: 45581
C5: (1) | D5: 税情報 (複合パターン)
D7: [売上取引 登録明細]
D8: 明細No. | F8: 商品名 | I8: 個数 | J8: 単価 | K8: 明細内合計 | N8: 税種別 | P8: 税率 | S8: 備考
D9: 1 | F9: 商品Ａ | I9: 2個 | J9: 100 | K9: 200 | N9: 外税 | P9: 0.08
D10: 2 | F10: 商品Ｂ | I10: 2個 | J10: 95 | K10: 190 | N10: 外税 | P10: 0.08
D11: 3 | F11: 商品Ｃ | I11: 2個 | J11: 100 | K11: 200 | N11: 外税 | P11: 0.1
D12: 4 | F12: 商品Ａ | I12: 3個 | J12: 100 | K12: 300 | N12: 外税 | P12: 0.1 | S12: 商品Ａ(明細No.1と同じ商品)を登録して税率変更(8%→10%)
D13: 5 | F13: 商品Ｄ | I13: 2個 | J13: 100 | K13: 200 | N13: 内税 | P13: 0.08
D14: 6 | F14: 商品Ｅ | I14: 2個 | J14: 95 | K14: 190 | N14: 内税 | P14: 0.08
D15: 7 | F15: 商品Ｆ | I15: 2個 | J15: 100 | K15: 200 | N15: 内税 | P15: 0.1
D16: 8 | F16: 商品Ｄ | I16: 3個 | J16: 100 | K16: 300 | N16: 内税 | P16: 0.1 | S16: 商品Ｄ(明細No.5と同じ商品)を登録して税率変更(8%→10%)
D17: 9 | F17: 商品Ｇ | I17: 2個 | J17: 100 | K17: 200 | N17: 非課税 | P17: 0
D18: 10 | F18: 商品Ｈ | I18: 3個 | J18: 95 | K18: 285 | N18: 非課税 | P18: 0
D20: [税種別（TAX_CD)]
D21: 外税（８％）：１、内税（８％）：２、非課税：３、外税（１０％）：４、内税（１０％）：５、内税（合計）：９９
D23: [レコード関連図] ※税情報に関連する情報のみを抜粋
L25: 【商品明細情報(外税)】 | AF25: 【税情報(外税)】
D26: 取引情報 | M26: 商品明細情報：商品Ａ | W26: 取引明細のリンク情報 | AG26: 取引の税情報
D27: TRSNS_HEADER | M27: LN_DETAIL | W27: LN_LINK | AG27: TRANSACTION_TAX | AO27: 外税8%のレコード
E28: TRAN_ID | J28: TS/Mで採番 | N28: TRAN_ID | T28: TS/Mで採番 | X28: TRAN_ID | AC28: TS/Mで採番 | AH28: TRAN_ID | AM28: TS/Mで採番
E29: TRAN_CD | J29: 1 | N29: TRAN_LN_NBR | T29: 1 | X29: TRAN_LN_NBR | AC29: 1 | AH29: TRAN_LN_NBR | AM29: 2
N30: QTY | T30: 2 | X30: LINK_LN_NBR | AC30: 2 | AH30: TAX_CD | AM30: 1 | AN30: (外税8%) | AU30: 同じ税種別(TAX_CD)の商品明細は
N31: EXT_PRC | T31: 200 | X31: LINK_TYP | AC31: 3 | AD31: (税) | AH31: TAX_MODIF | AM31: 1 | AU31: １つの税情報にまとめる
N32: GSFD_TAX_TYPE | T32: 1 | U32: (外税) | X32: LINK_AMT | AC32: 0 | AH32: TAX_AMT | AM32: 31
N33: GSFD_TAX_AMT | T33: 16 | AH33: VAT_AMT | AM33: 0
N34: GSFD_SELLING_PRC | T34: 100 | AH34: VATABL_AMT | AM34: 0
N35: GSFD_PLU_TAXBLTY_CD | T35: 1 | AH35: TAXBLE_AMT | AM35: 390
M37: 商品明細情報：商品Ｂ | W37: 取引明細のリンク情報
M38: LN_DETAIL | W38: LN_LINK
N39: TRAN_ID | T39: TS/Mで採番 | X39: TRAN_ID | AC39: TS/Mで採番
N40: TRAN_LN_NBR | T40: 3 | X40: TRAN_LN_NBR | AC40: 3
N41: QTY | T41: 2 | X41: LINK_LN_NBR | AC41: 2
N42: EXT_PRC | T42: 190 | X42: LINK_TYP | AC42: 3 | AD42: (税)
N43: GSFD_TAX_TYPE | T43: 1 | U43: (外税) | X43: LINK_AMT | AC43: 0
N44: GSFD_TAX_AMT | T44: 15
N45: GSFD_SELLING_PRC | T45: 95
N46: GSFD_PLU_TAXBLTY_CD | T46: 1
M48: 商品明細情報：商品Ｃ | W48: 取引明細のリンク情報 | AG48: 取引の税情報
...

Sheet 取引ログ作成時の注意事項(支払情報)
B1: TeamStore/M POSシステム | O1: システム名 | U1: 業務名 | AB1: 取引ログ作成時の注意事項（支払情報） | AO1: 履歴 | AQ1: 改訂者 | AT1: 最新更新日 | AX1: 作成者 | BA1: 作成日 | BE1: *1.5 本ページ追加
B2: UI設計書 | O2: トラン連携対応 | U2: トラン連携対応レイアウト | AO2: ='取引ログ作成時の注意事項(税情報)'!AO2 -> 1.12 | AQ2: 富士通 | AT2: ='取引ログ作成時の注意事項(税情報)'!AT2 -> 45709 | AX2: 富士通 | BA2: 45581
C5: (1) | D5: 支払情報 (複合パターン)
D7: [売上取引]
D8: ・商品登録
E9: 明細No. | G9: 商品名 | J9: 個数 | K9: 単価 | L9: 明細内合計 | O9: 税種別 | Q9: 税率 | T9: 備考
E10: 1 | G10: 商品Ａ | J10: 30個 | K10: 100 | L10: 3000 | O10: 外税 | Q10: 0.08
D12: ・支払登録
E13: 明細No. | G13: 現外名 | J13: 枚数 | K13: 単価 | L13: 明細内合計 | N13: 現外コード | R13: 現外バーコード | V13: 備考
E14: 1 | G14: ギフト券 | J14: 1枚 | K14: 500 | L14: 500 | O14: 103 | R14: 4901231703028
E15: 2 | G15: ギフト券 | J15: 1枚 | K15: 100 | L15: 100 | O15: 103 | R15: 4991002950102
E16: 3 | G16: ご優待券 | J16: 5枚 | K16: 100 | L16: 500 | O16: 104 | R16: (無し) | V16: 値引扱い現外
E17: 4 | G17: 商品券 | J17: 2枚 | K17: 1000 | L17: 2000 | O17: 101 | R17: (無し) | V17: 支払取消(タッチ訂正) | AS17: ：ダミーレコード
D19: [レコード関連図] ※支払情報に関連する情報のみを抜粋
L21: 【商品明細】 | AF21: 【税情報】
D22: 取引情報 | M22: 商品明細情報：商品Ａ | W22: 取引明細のリンク情報 | AG22: 取引の税情報
D23: TRSNS_HEADER | M23: LN_DETAIL | W23: LN_LINK | AG23: TRANSACTION_TAX | AO23: 外税8%のレコード
E24: TRAN_ID | J24: TS/Mで採番 | N24: TRAN_ID | T24: TS/Mで採番 | X24: TRAN_ID | AC24: TS/Mで採番 | AH24: TRAN_ID | AM24: TS/Mで採番
E25: TRAN_CD | J25: 1 | N25: TRAN_LN_NBR | T25: 1 | X25: TRAN_LN_NBR | AC25: 1 | AH25: TRAN_LN_NBR | AM25: 2
N26: QTY | T26: 30 | X26: LINK_LN_NBR | AC26: 2 | AH26: TAX_CD | AM26: 1 | AN26: (外税8%)
N27: EXT_PRC | T27: 3000 | X27: LINK_TYP | AC27: 3 | AD27: (税) | AH27: TAX_MODIF | AM27: 1
N28: GSFD_TAX_TYPE | T28: 1 | U28: (外税) | X28: LINK_AMT | AC28: 0 | AH28: TAX_AMT | AM28: 240
N29: GSFD_TAX_AMT | T29: 240 | X29: LINK_QTY | AC29: 0 | AH29: VAT_AMT | AM29: 0
N30: GSFD_SELLING_PRC | T30: 100 | AH30: VATABL_AMT | AM30: 0
N31: GSFD_PLU_TAXBLTY_CD | T31: 1 | AH31: TAXBLE_AMT | AM31: 3000
L34: 【No.1 ギフト券】
M35: 取引の支払情報 | AG35: 取引の現外支払情報
M36: TRANSACTION_TENDER | AG36: GIFT_CERT_TENDER
N37: TRAN_LN_NBR | T37: 3 | AH37: TRAN_LN_NBR | AM37: 3
N38: TRAN_ID | T38: TS/Mで採番 | AH38: TRAN_ID | AM38: TS/Mで採番
N39: TND_CD | T39: 103 | W39: 取引明細のリンク情報 | AH39: GFT_CERT_AMT | AM39: -500
N40: AMT | T40: -500 | W40: LN_LINK
N41: TND_AMT | T41: -500 | X41: TRAN_ID | AC41: TS/Mで採番
N42: VOID_CD | T42: 18 | U42: (Dummy Void) | X42: TRAN_LN_NBR | AC42: 3
N43: GSFD_CHG_NON_CASH_AMT | T43: 0 | X43: LINK_LN_NBR | AC43: 4
N44: GSFD_GIFT_CERT_CNT | T44: 0 | X44: LINK_TYP | AC44: 6 | AD44: (訂正済み現外支払)
N45: GSFD_GIFT_BARCODE | T45: "" | X45: LINK_AMT | AC45: 0
X46: LINK_QTY | AC46: 0
AR47: 現外券支払を行った場合、ダミー支払レコードを作成
M48: 取引の支払情報 | AG48: 取引の現外支払情報
...

Sheet 取引ログ作成時の注意事項(値引併用)
B1: TeamStore/M POSシステム | O1: システム名 | U1: 業務名 | AB1: 取引ログ作成時の注意事項（値引併用） | AO1: 履歴 | AQ1: 改訂者 | AT1: 最新更新日 | AX1: 作成者 | BA1: 作成日 | BE1: *1.5 本ページ追加
B2: UI設計書 | O2: トラン連携対応 | U2: トラン連携対応レイアウト | AO2: ='取引ログ作成時の注意事項(支払情報)'!AO2 -> 1.12 | AQ2: 富士通 | AT2: ='取引ログ作成時の注意事項(支払情報)'!AT2 -> 45709 | AX2: 富士通 | BA2: 45588
C5: (1) | D5: 値引併用マトリクス
B61: TeamStore/M POSシステム | O61: システム名 | U61: 業務名 | AB61: =AB$1 -> 取引ログ作成時の注意事項（値引併用） | AO61: 履歴 | AQ61: 改訂者 | AT61: 最新更新日 | AX61: 作成者 | BA61: 作成日 | BE61: *1.5 本ページ追加
B62: UI設計書 | O62: トラン連携対応 | U62: トラン連携対応レイアウト | AO62: =AO$2 -> 1.12 | AQ62: =AQ$2 -> 富士通 | AT62: =AT$2 -> 45709 | AX62: 富士通 | BA62: 45588
C65: (2) | D65: ①マークダウンと②タイムサービスと③期間特売の併用
D67: ※価格計算：①マークダウンのみ有効
D69: [売上取引 登録明細]
D70: 明細No. | F70: 大分類 | H70: 中分類 | J70: 商品名 | O70: 標準価格 | R70: 個数 | U70: 備考
D71: 1 | F71: 0102 | H71: 010200 | J71: 商品Ａ | O71: 100 | R71: 1個
J72: 値引 | O72: 設定値 | R72: 値引方法 | U72: 補足情報
J73: ①マークダウン | O73: 99 | R73: 売価
I74: 無効→ | J74: ②タイムサービス | O74: 96 | R74: 売価
I75: 無効→ | J75: ③期間特売 | O75: 95 | R75: 売価 | U75: 当日緊急登録
I76: 無効→ | J76: ③期間特売 | O76: 94 | R76: 売価
D79: [レコード関連図] ※値引情報に関連する情報のみを抜粋
AG80: 【値引情報】
D81: 取引情報 | M81: 商品明細情報：商品Ａ | W81: 取引明細のリンク情報 | AH81: 取引明細の値引情報 (①マークダウン)
D82: TRSNS_HEADER | M82: LN_DETAIL | W82: LN_LINK | AH82: LN_DISCOUNT
E83: TRAN_ID | J83: TS/Mで採番 | N83: TRAN_ID | T83: TS/Mで採番 | X83: TRAN_ID | AC83: TS/Mで採番 | AI83: TRAN_ID | AN83: TS/Mで採番
E84: TRAN_CD | J84: 1 | N84: TRAN_LN_NBR | T84: 1 | X84: TRAN_LN_NBR | AC84: 1 | AI84: TRAN_LN_NBR | AN84: 5
N85: QTY | T85: 1 | X85: LINK_LN_NBR | AC85: 5 | AI85: DISC_MTHD | AN85: 6 | AP85: ６：売価変更値引
N86: EXT_PRC | T86: 99 | X86: LINK_TYP | AC86: 1 | AD86: (値引) | AI86: DISC_AMT | AN86: 0 | AP86: 特売・タイムサービス・マークダウンの場合は\0を設定
N87: RTL_PRC | T87: 100 | X87: LINK_AMT | AC87: 0 | AI87: DISC_VALUE | AN87: 99 | AP87: マークダウン売価
N88: GSFD_SELLING_PRC | T88: 99 | X88: LINK_QTY | AC88: 0 | AI88: DISC_CLSS_ID | AN88: 91111 | AP88: 91111: マークダウン
T89: EXT_PRCは、マークダウン売価×数量 | AI89: DISC_VALUE2 | AN89: 0
T90: GSFD_SELLING_PRCは、マークダウン売価
W92: 取引明細のリンク情報 | AH92: 取引明細の値引情報 (②タイムサービス)
W93: LN_LINK | AH93: LN_DISCOUNT
X94: TRAN_ID | AC94: TS/Mで採番 | AI94: TRAN_ID | AN94: TS/Mで採番
X95: TRAN_LN_NBR | AC95: 1 | AI95: TRAN_LN_NBR | AN95: 4
X96: LINK_LN_NBR | AC96: 4 | AI96: DISC_MTHD | AN96: 6 | AP96: ６：売価変更値引
X97: LINK_TYP | AC97: 1 | AD97: (値引) | AI97: DISC_AMT | AN97: 0 | AP97: 特売・タイムサービス・マークダウンの場合は\0を設定
X98: LINK_AMT | AC98: 0 | AI98: DISC_VALUE | AN98: 96 | AP98: タイムサービス売価
X99: LINK_QTY | AC99: 0 | AI99: DISC_CLSS_ID | AN99: 91121 | AP99: 91121: タイムサービス
AI100: DISC_VALUE2 | AN100: 0
W103: 取引明細のリンク情報 | AH103: 取引明細の値引情報 (③期間特売) | AP103: ※当日緊急登録した期間特売のみ生成
W104: LN_LINK | AH104: LN_DISCOUNT
X105: TRAN_ID | AC105: TS/Mで採番 | AI105: TRAN_ID | AN105: TS/Mで採番
X106: TRAN_LN_NBR | AC106: 1 | AI106: TRAN_LN_NBR | AN106: 3
...

Sheet TRANS_HEADER
A1: トラン連携ファイルレイアウト | C1: 対象テーブル：TRANS_HEADER 形式：TSV | P1: *1.5 「入金 中止」は、ignicaPOS側からトラン連携無し | R1: *1.5 「出金 中止」は、ignicaPOS側からトラン連携無し | T1: *1.5 「釣銭準備金 中止」は、ignicaPOS側からトラン連携無し | W1: *1.5 「中間回収 中止」は、ignicaPOS側からトラン連携無し | Z1: *1.5
A2: NO | B2: 項目 | H2: 説明 | I2: 取得元マスタ項目 | J2: 設定元 | K2: 一次開発 必須項目 | L2: ignicaPOS・Scan&Go設定値 | Y2: 備考
B3: カラム名称 | C3: 日本語名称 | D3: 型 | E3: サイズ | F3: NULL 許可 | G3: KEY | L3: 開局 | M3: 売上 | N3: 売上 中止 | O3: 入金 | P3: 入金 中止 | Q3: 出金 | R3: 出金 中止 | S3: 釣銭準備金 | T3: 釣銭準備金 中止 | U3: 釣銭補充 | V3: 中間回収 | W3: 中間回収 中止 | X3: 精算
A4: 1 | B4: GSFD_ACCOUNT_ID | C4: アカウントID | D4: varchar | E4: 9 | F4: ● | H4: アカウントID 先頭0埋めで9桁固定 | I4: - | J4: ignicaPOS | K4: 〇 | L4: 設定値：アカウントIDを設定 ignicaPOS 設定値：""(空) Scan&Go 設定値：""(空) | M4: 設定値：アカウントIDを設定 ignicaPOS 設定値：""(空) Scan&Go 設定値：アカウントID | N4: 設定値：アカウントIDを設定 ignicaPOS 設定値：""(空) Scan&Go 設定値：アカウントID | O4: 設定値：アカウントIDを設定 ignicaPOS 設定値：""(空) Scan&Go 設定値：""(空) | P4: 設定値：アカウントIDを設定 ignicaPOS 設定値：""(空) Scan&Go 設定値：""(空) | Q4: 設定値：アカウントIDを設定 ignicaPOS 設定値：""(空) Scan&Go 設定値：""(空) | R4: 設定値：アカウントIDを設定 ignicaPOS 設定値：""(空) Scan&Go 設定値：""(空) | S4: 設定値：アカウントIDを設定 ignicaPOS 設定値：""(空) Scan&Go 設定値：""(空) | T4: 設定値：アカウントIDを設定 ignicaPOS 設定値：""(空) Scan&Go 設定値：""(空) | U4: 設定値：アカウントIDを設定 ignicaPOS 設定値：""(空) Scan&Go 設定値：""(空) | V4: 設定値：アカウントIDを設定 ignicaPOS 設定値：""(空) Scan&Go 設定値：""(空) | W4: 設定値：アカウントIDを設定 ignicaPOS 設定値：""(空) Scan&Go 設定値：""(空) | X4: 設定値：アカウントIDを設定 ignicaPOS 設定値：""(空) Scan&Go 設定値：""(空) | Y4: Scan&Goの売上取引/売上中止取引のみ値を設定する
A5: =A4+1 -> 2 | B5: GSFD_JOURNAL_NO | C5: ジャーナルNo. | D5: varchar | E5: 9 | F5: ● | H5: ジャーナルNo. 先頭0埋めで9桁固定 | I5: - | J5: ignicaPOS | K5: 〇 | L5: 設定値：ジャーナルNo. ignicaPOS 設定値：""(空) Scan&Go 設定値：""(空) | M5: 設定値：ジャーナルNo. ignicaPOS 設定値：""(空) Scan&Go 設定値：ジャーナルNo. | N5: 設定値：ジャーナルNo. ignicaPOS 設定値：""(空) Scan&Go 設定値：ジャーナルNo. | O5: 設定値：ジャーナルNo. ignicaPOS 設定値：""(空) Scan&Go 設定値：""(空) | P5: 設定値：ジャーナルNo. ignicaPOS 設定値：""(空) Scan&Go 設定値：""(空) | Q5: 設定値：ジャーナルNo. ignicaPOS 設定値：""(空) Scan&Go 設定値：""(空) | R5: 設定値：ジャーナルNo. ignicaPOS 設定値：""(空) Scan&Go 設定値：""(空) | S5: 設定値：ジャーナルNo. ignicaPOS 設定値：""(空) Scan&Go 設定値：""(空) | T5: 設定値：ジャーナルNo. ignicaPOS 設定値：""(空) Scan&Go 設定値：""(空) | U5: 設定値：ジャーナルNo. ignicaPOS 設定値：""(空) Scan&Go 設定値：""(空) | V5: 設定値：ジャーナルNo. ignicaPOS 設定値：""(空) Scan&Go 設定値：""(空) | W5: 設定値：ジャーナルNo. ignicaPOS 設定値：""(空) Scan&Go 設定値：""(空) | X5: 設定値：ジャーナルNo. ignicaPOS 設定値：""(空) Scan&Go 設定値：""(空) | Y5: Scan&Goの売上取引/売上中止取引のみ値を設定する
A6: =A5+1 -> 3 | B6: TRAN_ID | C6: 取引通番 | D6: int | G6: PK | H6: 取引の識別子 | I6: - | J6: TS/M | K6: ● | L6: TSM側で設定となるため、設定不要（固定値） 設定値：""(空) | M6: TSM側で設定となるため、設定不要（固定値） 設定値：""(空) | N6: TSM側で設定となるため、設定不要（固定値） 設定値：""(空) | O6: TSM側で設定となるため、設定不要（固定値） 設定値：""(空) | P6: TSM側で設定となるため、設定不要（固定値） 設定値：""(空) | Q6: TSM側で設定となるため、設定不要（固定値） 設定値：""(空) | R6: TSM側で設定となるため、設定不要（固定値） 設定値：""(空) | S6: TSM側で設定となるため、設定不要（固定値） 設定値：""(空) | T6: TSM側で設定となるため、設定不要（固定値） 設定値：""(空) | U6: TSM側で設定となるため、設定不要（固定値） 設定値：""(空) | V6: TSM側で設定となるため、設定不要（固定値） 設定値：""(空) | W6: TSM側で設定となるため、設定不要（固定値） 設定値：""(空) | X6: TSM側で設定となるため、設定不要（固定値） 設定値：""(空)
A7: =A6+1 -> 4 | B7: RGST_TRAN_NBR | C7: レジ内取引通番 | D7: smallint | H7: レジスタ単位の取引通番 | I7: - | J7: ignicaPOS | K7: ◎ | L7: 設定値：取引通番を設定 | M7: 設定値：取引通番を設定 | N7: 設定値：取引通番を設定 | O7: 設定値：取引通番を設定 | P7: 設定値：取引通番を設定 | Q7: 設定値：取引通番を設定 | R7: 設定値：取引通番を設定 | S7: 設定値：取引通番を設定 | T7: 設定値：取引通番を設定 | U7: 設定値：取引通番を設定 | V7: 設定値：取引通番を設定 | W7: 設定値：取引通番を設定 | X7: 設定値：取引通番を設定 | Y7: POS番号単位での通し番号 (抜け/重複なし) 最大4桁(0001～9999)で、日またぎでサイクリック (日付が変わってもリセットしない) 本通番を用いて通番抜けチェックを行う ※レシート/ジャーナル印字は4桁固定(先頭0埋め)するが、トラン連携ファイルには数値として設定して先頭0埋めは不要 | Z7: *1.6
A8: =A7+1 -> 5 | B8: TRAN_CD | C8: 取引コード | D8: smallint | F8: ● | H8: 取引の種類を示します。 | I8: - | J8: ignicaPOS | K8: ◎ | L8: 設定値：31,37 開局 31：Terminal open 再開局 37：Terminal open | M8: 設定値：1 1：Item Sales | N8: 設定値：1 1：Item Sales | O8: 設定値：15 15：Payin | P8: 設定値：15 15：Payin | Q8: 設定値：16 16：PayOut | R8: 設定値：16 16：PayOut | S8: 設定値：11 11：Loan | T8: 設定値：11 11：Loan | U8: 設定値：14 14:Money Exchange | V8: 設定値：12 12：Pickup | W8: 設定値：12 12：Pickup | X8: 設定値：33 33：Terminal close
A9: =A8+1 -> 6 | B9: STR_ID | C9: 店舗番号 | D9: int | G9: PK | J9: ignicaPOS | K9: ◎ | L9: 設定値：店舗番号×10000 | M9: 設定値：店舗番号×10000 | N9: 設定値：店舗番号×10000 | O9: 設定値：店舗番号×10000 | P9: 設定値：店舗番号×10000 | Q9: 設定値：店舗番号×10000 | R9: 設定値：店舗番号×10000 | S9: 設定値：店舗番号×10000 | T9: 設定値：店舗番号×10000 | U9: 設定値：店舗番号×10000 | V9: 設定値：店舗番号×10000 | W9: 設定値：店舗番号×10000 | X9: 設定値：店舗番号×10000
A10: =A9+1 -> 7 | B10: EMP_ID | C10: 従業員コード | D10: varchar | E10: 12 | H10: 取引を入力した従業員 | I10: 担当者マスタ連携ファイル No.3 従業員コード | J10: ignicaPOS | K10: ◎ | L10: 設定値：従業員コード ignicaPOS 取引を行った従業員コード Scan&Go 集計対象とする従業員コード | M10: 設定値：従業員コード ignicaPOS ﾌﾙｾﾙﾌモードの場合 売上取引を集計対象とする従業員コード POSモードの場合 取引を行った従業員コード Scan&Go 売上取引を集計対象とする従業員コード | N10: 設定値：従業員コード ignicaPOS ﾌﾙｾﾙﾌモードの場合 売上取引を集計対象とする従業員コード POSモードの場合 取引を行った従業員コード Scan&Go 売上取引を集計対象とする従業員コード | O10: 設定値：従業員コード ignicaPOS 取引を行った従業員コード Scan&Go 集計対象とする従業員コード | P10: 設定値：従業員コード ignicaPOS 取引を行った従業員コード Scan&Go 集計対象とする従業員コード | Q10: 設定値：従業員コード ignicaPOS 取引を行った従業員コード Scan&Go 集計対象とする従業員コード | R10: 設定値：従業員コード ignicaPOS 取引を行った従業員コード Scan&Go 集計対象とする従業員コード | S10: 設定値：従業員コード ignicaPOS 取引を行った従業員コード Scan&Go 集計対象とする従業員コード | T10: 設定値：従業員コード ignicaPOS 取引を行った従業員コード Scan&Go 集計対象とする従業員コード | U10: 設定値：従業員コード ignicaPOS 取引を行った従業員コード Scan&Go 集計対象とする従業員コード | V10: 設定値：従業員コード ignicaPOS 取引を行った従業員コード Scan&Go 集計対象とする従業員コード | W10: 設定値：従業員コード ignicaPOS 取引を行った従業員コード Scan&Go 集計対象とする従業員コード | X10: 設定値：従業員コード ignicaPOS 取引を行った従業員コード Scan&Go 集計対象とする従業員コード | Z10: *1.0
A11: =A10+1 -> 8 | B11: RGST_ID | C11: レジスタID | D11: int | H11: 取引が発生したレジスタ | I11: - | J11: ignicaPOS | K11: ◎ | L11: 設定値：POS番号を設定 | M11: 設定値：POS番号を設定 | N11: 設定値：POS番号を設定 | O11: 設定値：POS番号を設定 | P11: 設定値：POS番号を設定 | Q11: 設定値：POS番号を設定 | R11: 設定値：POS番号を設定 | S11: 設定値：POS番号を設定 | T11: 設定値：POS番号を設定 | U11: 設定値：POS番号を設定 | V11: 設定値：POS番号を設定 | W11: 設定値：POS番号を設定 | X11: 設定値：POS番号を設定
A12: =A11+1 -> 9 | B12: TILL_ID | C12: ティルID | D12: varchar | E12: 12 | H12: 取引に関わるティル | I12: - | J12: TS/M | K12: ● | L12: TSM側で設定となるため、設定不要（固定値） 設定値：""(空) | M12: TSM側で設定となるため、設定不要（固定値） 設定値：""(空) | N12: TSM側で設定となるため、設定不要（固定値） 設定値：""(空) | O12: TSM側で設定となるため、設定不要（固定値） 設定値：""(空) | P12: TSM側で設定となるため、設定不要（固定値） 設定値：""(空) | Q12: TSM側で設定となるため、設定不要（固定値） 設定値：""(空) | R12: TSM側で設定となるため、設定不要（固定値） 設定値：""(空) | S12: TSM側で設定となるため、設定不要（固定値） 設定値：""(空) | T12: TSM側で設定となるため、設定不要（固定値） 設定値：""(空) | U12: TSM側で設定となるため、設定不要（固定値） 設定値：""(空) | V12: TSM側で設定となるため、設定不要（固定値） 設定値：""(空) | W12: TSM側で設定となるため、設定不要（固定値） 設定値：""(空) | X12: TSM側で設定となるため、設定不要（固定値） 設定値：""(空)
A13: =A12+1 -> 10 | B13: BUS_DT | C13: 営業日 | D13: datetime | H13: 取引が発生した営業日 | I13: - | J13: ignicaPOS | K13: ◎ | L13: 設定値：営業日を設定 9999-99-99 00:00:00.000 <例> 2021-02-04 00:00:00.000 | M13: 設定値：営業日を設定 9999-99-99 00:00:00.000 <例> 2021-02-04 00:00:00.000 | N13: 設定値：営業日を設定 9999-99-99 00:00:00.000 <例> 2021-02-04 00:00:00.000 | O13: 設定値：営業日を設定 9999-99-99 00:00:00.000 <例> 2021-02-04 00:00:00.000 | P13: 設定値：営業日を設定 9999-99-99 00:00:00.000 <例> 2021-02-04 00:00:00.000 | Q13: 設定値：営業日を設定 9999-99-99 00:00:00.000 <例> 2021-02-04 00:00:00.000 | R13: 設定値：営業日を設定 9999-99-99 00:00:00.000 <例> 2021-02-04 00:00:00.000 | S13: 設定値：営業日を設定 9999-99-99 00:00:00.000 <例> 2021-02-04 00:00:00.000 | T13: 設定値：営業日を設定 9999-99-99 00:00:00.000 <例> 2021-02-04 00:00:00.000 | U13: 設定値：営業日を設定 9999-99-99 00:00:00.000 <例> 2021-02-04 00:00:00.000 | V13: 設定値：営業日を設定 9999-99-99 00:00:00.000 <例> 2021-02-04 00:00:00.000 | W13: 設定値：営業日を設定 9999-99-99 00:00:00.000 <例> 2021-02-04 00:00:00.000 | X13: 設定値：営業日を設定 9999-99-99 00:00:00.000 <例> 2021-02-04 00:00:00.000 | Y13: 取引が発生した営業日を設定する。
A14: =A13+1 -> 11 | B14: TRAN_STRT_TS | C14: 取引開始時刻 | D14: datetime | I14: - | J14: ignicaPOS | K14: ◎ | L14: 設定値：取引開始時刻を設定 9999-99-99 99:99:99.000 <例> 2021-02-04 10:4:57.000 | M14: 設定値：取引開始時刻を設定 9999-99-99 99:99:99.000 <例> 2021-02-04 10:4:57.000 | N14: 設定値：取引開始時刻を設定 9999-99-99 99:99:99.000 <例> 2021-02-04 10:4:57.000 | O14: 設定値：取引開始時刻を設定 9999-99-99 99:99:99.000 <例> 2021-02-04 10:4:57.000 | P14: 設定値：取引開始時刻を設定 9999-99-99 99:99:99.000 <例> 2021-02-04 10:4:57.000 | Q14: 設定値：取引開始時刻を設定 9999-99-99 99:99:99.000 <例> 2021-02-04 10:4:57.000 | R14: 設定値：取引開始時刻を設定 9999-99-99 99:99:99.000 <例> 2021-02-04 10:4:57.000 | S14: 設定値：取引開始時刻を設定 9999-99-99 99:99:99.000 <例> 2021-02-04 10:4:57.000 | T14: 設定値：取引開始時刻を設定 9999-99-99 99:99:99.000 <例> 2021-02-04 10:4:57.000 | U14: 設定値：取引開始時刻を設定 9999-99-99 99:99:99.000 <例> 2021-02-04 10:4:57.000 | V14: 設定値：取引開始時刻を設定 9999-99-99 99:99:99.000 <例> 2021-02-04 10:4:57.000 | W14: 設定値：取引開始時刻を設定 9999-99-99 99:99:99.000 <例> 2021-02-04 10:4:57.000 | X14: 設定値：取引開始時刻を設定 9999-99-99 99:99:99.000 <例> 2021-02-04 10:4:57.000 | Y14: 取引開始時刻を持っていない場合は取引終了時刻を設定する。
A15: =A14+1 -> 12 | B15: TRAN_END_DTTM | C15: 取引終了時刻 | D15: datetime | F15: ● | I15: - | J15: ignicaPOS | K15: ◎ | L15: 設定値：取引終了時刻を設定 9999-99-99 99:99:99.000 <例> 2021-02-04 10:4:57.000 | M15: 設定値：取引終了時刻を設定 9999-99-99 99:99:99.000 <例> 2021-02-04 10:4:57.000 | N15: 設定値：取引終了時刻を設定 9999-99-99 99:99:99.000 <例> 2021-02-04 10:4:57.000 | O15: 設定値：取引終了時刻を設定 9999-99-99 99:99:99.000 <例> 2021-02-04 10:4:57.000 | P15: 設定値：取引終了時刻を設定 9999-99-99 99:99:99.000 <例> 2021-02-04 10:4:57.000 | Q15: 設定値：取引終了時刻を設定 9999-99-99 99:99:99.000 <例> 2021-02-04 10:4:57.000 | R15: 設定値：取引終了時刻を設定 9999-99-99 99:99:99.000 <例> 2021-02-04 10:4:57.000 | S15: 設定値：取引終了時刻を設定 9999-99-99 99:99:99.000 <例> 2021-02-04 10:4:57.000 | T15: 設定値：取引終了時刻を設定 9999-99-99 99:99:99.000 <例> 2021-02-04 10:4:57.000 | U15: 設定値：取引終了時刻を設定 9999-99-99 99:99:99.000 <例> 2021-02-04 10:4:57.000 | V15: 設定値：取引終了時刻を設定 9999-99-99 99:99:99.000 <例> 2021-02-04 10:4:57.000 | W15: 設定値：取引終了時刻を設定 9999-99-99 99:99:99.000 <例> 2021-02-04 10:4:57.000 | X15: 設定値：取引終了時刻を設定 9999-99-99 99:99:99.000 <例> 2021-02-04 10:4:57.000
A16: =A15+1 -> 13 | B16: OFFLN_FG | C16: オフライン判別 | D16: smallint | H16: オフラインフラグ | I16: - | J16: TS/M | K16: ● | L16: TSM側で設定となるため、設定不要（固定値） 設定値：""(空) | M16: TSM側で設定となるため、設定不要（固定値） 設定値：""(空) | N16: TSM側で設定となるため、設定不要（固定値） 設定値：""(空) | O16: TSM側で設定となるため、設定不要（固定値） 設定値：""(空) | P16: TSM側で設定となるため、設定不要（固定値） 設定値：""(空) | Q16: TSM側で設定となるため、設定不要（固定値） 設定値：""(空) | R16: TSM側で設定となるため、設定不要（固定値） 設定値：""(空) | S16: TSM側で設定となるため、設定不要（固定値） 設定値：""(空) | T16: TSM側で設定となるため、設定不要（固定値） 設定値：""(空) | U16: TSM側で設定となるため、設定不要（固定値） 設定値：""(空) | V16: TSM側で設定となるため、設定不要（固定値） 設定値：""(空) | W16: TSM側で設定となるため、設定不要（固定値） 設定値：""(空) | X16: TSM側で設定となるため、設定不要（固定値） 設定値：""(空)
A17: =A16+1 -> 14 | B17: TRNING_MDE_FG | C17: トレーニングモード | D17: smallint | H17: 練習モードフラグ ０：通常業務モード １：練習モード | I17: - | J17: TS/M | K17: ● | L17: TSM側で設定となるため、設定不要（固定値） 設定値：""(空) | M17: TSM側で設定となるため、設定不要（固定値） 設定値：""(空) | N17: TSM側で設定となるため、設定不要（固定値） 設定値：""(空) | O17: TSM側で設定となるため、設定不要（固定値） 設定値：""(空) | P17: TSM側で設定となるため、設定不要（固定値） 設定値：""(空) | Q17: TSM側で設定となるため、設定不要（固定値） 設定値：""(空) | R17: TSM側で設定となるため、設定不要（固定値） 設定値：""(空) | S17: TSM側で設定となるため、設定不要（固定値） 設定値：""(空) | T17: TSM側で設定となるため、設定不要（固定値） 設定値：""(空) | U17: TSM側で設定となるため、設定不要（固定値） 設定値：""(空) | V17: TSM側で設定となるため、設定不要（固定値） 設定値：""(空) | W17: TSM側で設定となるため、設定不要（固定値） 設定値：""(空) | X17: TSM側で設定となるため、設定不要（固定値） 設定値：""(空) | Y17: 練習モードは連携しない。
A18: =A17+1 -> 15 | B18: RNTRY_MDE_FG | C18: 再入力モード | D18: smallint | H18: TRUEの場合、取引が再エントリモードで記録されたことを示します。 | I18: - | J18: TS/M | K18: ● | L18: TSM側で設定となるため、設定不要（固定値） 設定値：""(空) | M18: TSM側で設定となるため、設定不要（固定値） 設定値：""(空) | N18: TSM側で設定となるため、設定不要（固定値） 設定値：""(空) | O18: TSM側で設定となるため、設定不要（固定値） 設定値：""(空) | P18: TSM側で設定となるため、設定不要（固定値） 設定値：""(空) | Q18: TSM側で設定となるため、設定不要（固定値） 設定値：""(空) | R18: TSM側で設定となるため、設定不要（固定値） 設定値：""(空) | S18: TSM側で設定となるため、設定不要（固定値） 設定値：""(空) | T18: TSM側で設定となるため、設定不要（固定値） 設定値：""(空) | U18: TSM側で設定となるため、設定不要（固定値） 設定値：""(空) | V18: TSM側で設定となるため、設定不要（固定値） 設定値：""(空) | W18: TSM側で設定となるため、設定不要（固定値） 設定値：""(空) | X18: TSM側で設定となるため、設定不要（固定値） 設定値：""(空)
A19: =A18+1 -> 16 | B19: VOID_CD | C19: 取消コード | D19: smallint | H19: 取引中止フラグ ０：通常取引 １：取引中止 | I19: - | J19: ignicaPOS | K19: ◎ | L19: 設定値：0 ０：通常取引 １：取引中止 | M19: 設定値：0 ０：通常取引 １：取引中止 | N19: 設定値：1 ０：通常取引 １：取引中止 | O19: 設定値：0 ０：通常取引 １：取引中止 | P19: 設定値：1 ０：通常取引 １：取引中止 | Q19: 設定値：0 ０：通常取引 １：取引中止 | R19: 設定値：1 ０：通常取引 １：取引中止 | S19: 設定値：0 ０：通常取引 １：取引中止 | T19: 設定値：1 ０：通常取引 １：取引中止 | U19: 設定値：0 ０：通常取引 １：取引中止 | V19: 設定値：0 ０：通常取引 １：取引中止 | W19: 設定値：1 ０：通常取引 １：取引中止 | X19: 設定値：0 ０：通常取引 １：取引中止
A20: =A19+1 -> 17 | B20: CUST_ID | C20: 顧客ID | D20: varchar | E20: 24 | F20: ● | H20: 取引に対応する顧客ＩＤを示します。 | I20: - | J20: ignicaPOS | K20: ◎ | L20: 設定値：""(空) | M20: 設定値：登録した顧客コード。プリンスポイント対象金額が存在する場合はプリンスポイント対象金額を設定 ※プリンスカードは次回開発 ※No.84 GSFD_CARD_ENTRY_TYPE=5の時はプリンスカードとして扱う 上記以外の場合は、""(空) | N20: 設定値：登録した顧客コード。プリンスポイント対象金額が存在する場合はプリンスポイント対象金額を設定 ※プリンスカードは次回開発 ※No.84 GSFD_CARD_ENTRY_TYPE=5の時はプリンスカードとして扱う 上記以外の場合は、""(空) | O20: 設定値：""(空) | P20: 設定値：""(空) | Q20: 設定値：""(空) | R20: 設定値：""(空) | S20: 設定値：""(空) | T20: 設定値：""(空) | U20: 設定値：""(空) | V20: 設定値：""(空) | W20: 設定値：""(空) | X20: 設定値：""(空)
A21: =A20+1 -> 18 | B21: SHPR_ID | C21: 買い物客ID | D21: varchar | E21: 24 | F21: ● | H21: 取引に対応する買い物客IDを示します。 | I21: - | J21: TS/M | K21: ● | L21: 設定不要(固定値) 設定値："" | M21: 設定不要(固定値) 設定値："" | N21: 設定不要(固定値) 設定値："" | O21: 設定不要(固定値) 設定値："" | P21: 設定不要(固定値) 設定値："" | Q21: 設定不要(固定値) 設定値："" | R21: 設定不要(固定値) 設定値："" | S21: 設定不要(固定値) 設定値："" | T21: 設定不要(固定値) 設定値："" | U21: 設定不要(固定値) 設定値："" | V21: 設定不要(固定値) 設定値："" | W21: 設定不要(固定値) 設定値："" | X21: 設定不要(固定値) 設定値："" | Y21: 未使用領域のため
A22: =A21+1 -> 19 | B22: STAT | C22: ステータス | D22: smallint | H22: 取引のステータス １：通常取引 ６：Ｓｕｓｐｅｎｄされた取引（保留取引） ７：ＰｏｓｔＶｏｉｄされた取引（通番打消） | I22: - | J22: TS/M | K22: ● | L22: 設定不要(固定値) 設定値："" | M22: 設定不要(固定値) 設定値："" | N22: 設定不要(固定値) 設定値："" | O22: 設定不要(固定値) 設定値："" | P22: 設定不要(固定値) 設定値："" | Q22: 設定不要(固定値) 設定値："" | R22: 設定不要(固定値) 設定値："" | S22: 設定不要(固定値) 設定値："" | T22: 設定不要(固定値) 設定値："" | U22: 設定不要(固定値) 設定値："" | V22: 設定不要(固定値) 設定値："" | W22: 設定不要(固定値) 設定値："" | X22: 設定不要(固定値) 設定値：""
A23: =A22+1 -> 20 | B23: TOT_AMT | C23: 取引合計額 | D23: money | F23: ● | H23: 取引合計額売上および入出金取引の合計金額。符号表記 （＋：売上、入金、出金打消 －：返品、打消、出金、入金打消 ） | I23: - | J23: ignicaPOS | K23: ◎ | L23: 設定値：0 | M23: 設定値：取引合計額を設定 | N23: 設定値：取引合計額を設定 | O23: 設定値：取引合計額を設定 | P23: 設定値：取引合計額を設定 | Q23: 設定値：取引合計額を設定 | R23: 設定値：取引合計額を設定 | S23: 設定値：0 | T23: 設定値：0 | U23: 設定値：0 | V23: 設定値：0 | W23: 設定値：0 | X23: 設定値：0 | Z23: *1.0
A24: =A23+1 -> 21 | B24: EMP_ID_DISC | C24: 割引購入した従業員ＩＤ | D24: varchar | E24: 12 | F24: ● | H24: 従業員ディスカウントを受ける従業員ＩＤ | I24: - | J24: TS/M | K24: ● | L24: 設定不要(固定値) 設定値：""(空) | M24: 設定不要(固定値) 設定値：""(空) | N24: 設定不要(固定値) 設定値：""(空) | O24: 設定不要(固定値) 設定値：""(空) | P24: 設定不要(固定値) 設定値：""(空) | Q24: 設定不要(固定値) 設定値：""(空) | R24: 設定不要(固定値) 設定値：""(空) | S24: 設定不要(固定値) 設定値：""(空) | T24: 設定不要(固定値) 設定値：""(空) | U24: 設定不要(固定値) 設定値：""(空) | V24: 設定不要(固定値) 設定値：""(空) | W24: 設定不要(固定値) 設定値：""(空) | X24: 設定不要(固定値) 設定値：""(空) | Y24: 未使用領域のため
A25: =A24+1 -> 22 | B25: LTILL_ID | C25: 論理ティルＩＤ | D25: varchar | E25: 12 | H25: 取引に対応する論理ティル | I25: - | J25: TS/M | K25: ● | L25: 設定不要(固定値) 設定値：""(空) | M25: 設定不要(固定値) 設定値：""(空) | N25: 設定不要(固定値) 設定値：""(空) | O25: 設定不要(固定値) 設定値：""(空) | P25: 設定不要(固定値) 設定値：""(空) | Q25: 設定不要(固定値) 設定値：""(空) | R25: 設定不要(固定値) 設定値：""(空) | S25: 設定不要(固定値) 設定値：""(空) | T25: 設定不要(固定値) 設定値：""(空) | U25: 設定不要(固定値) 設定値：""(空) | V25: 設定不要(固定値) 設定値：""(空) | W25: 設定不要(固定値) 設定値：""(空) | X25: 設定不要(固定値) 設定値：""(空)
A26: =A25+1 -> 23 | B26: REAS_CD | C26: 理由コード | D26: smallint | F26: ● | H26: 理由を記録する必要がある取引タイプの場合は、理由を示します。 | I26: - | J26: TS/M | K26: ● | L26: 設定不要(固定値) 設定値：""(空) | M26: 設定不要(固定値) 設定値：""(空) | N26: 設定不要(固定値) 設定値：""(空) | O26: 設定不要(固定値) 設定値：""(空) | P26: 設定不要(固定値) 設定値：""(空) | Q26: 設定不要(固定値) 設定値：""(空) | R26: 設定不要(固定値) 設定値：""(空) | S26: 設定不要(固定値) 設定値：""(空) | T26: 設定不要(固定値) 設定値：""(空) | U26: 設定不要(固定値) 設定値：""(空) | V26: 設定不要(固定値) 設定値：""(空) | W26: 設定不要(固定値) 設定値：""(空) | X26: 設定不要(固定値) 設定値：""(空) | Y26: 未使用領域のため
A27: =A26+1 -> 24 | B27: RAFT_RLSE | C27: RAFTリリース | D27: varchar | E27: 12 | F27: ● | H27: 取引を作成したRAFTのリリースを識別します。 | I27: - | J27: TS/M | K27: ● | L27: 設定不要(固定値) 設定値：""(空) | M27: 設定不要(固定値) 設定値：""(空) | N27: 設定不要(固定値) 設定値：""(空) | O27: 設定不要(固定値) 設定値：""(空) | P27: 設定不要(固定値) 設定値：""(空) | Q27: 設定不要(固定値) 設定値：""(空) | R27: 設定不要(固定値) 設定値：""(空) | S27: 設定不要(固定値) 設定値：""(空) | T27: 設定不要(固定値) 設定値：""(空) | U27: 設定不要(固定値) 設定値：""(空) | V27: 設定不要(固定値) 設定値：""(空) | W27: 設定不要(固定値) 設定値：""(空) | X27: 設定不要(固定値) 設定値：""(空) | Y27: 未使用領域のため
A28: =A27+1 -> 25 | B28: TRAN_GRP_ID | C28: 取引グループＩＤ | D28: int | F28: ● | H28: 取引に対応する取引グループの識別子 | I28: - | J28: TS/M | K28: ● | L28: 設定不要(固定値) 設定値：""(空) | M28: 設定不要(固定値) 設定値：""(空) | N28: 設定不要(固定値) 設定値：""(空) | O28: 設定不要(固定値) 設定値：""(空) | P28: 設定不要(固定値) 設定値：""(空) | Q28: 設定不要(固定値) 設定値：""(空) | R28: 設定不要(固定値) 設定値：""(空) | S28: 設定不要(固定値) 設定値：""(空) | T28: 設定不要(固定値) 設定値：""(空) | U28: 設定不要(固定値) 設定値：""(空) | V28: 設定不要(固定値) 設定値：""(空) | W28: 設定不要(固定値) 設定値：""(空) | X28: 設定不要(固定値) 設定値：""(空) | Y28: 未使用領域のため
A29: =A28+1 -> 26 | B29: POST_VOID_CD | C29: ポスト取消CD | D29: smallint | F29: ● | I29: - | J29: TS/M | K29: ● | L29: 設定不要(固定値) 設定値：""(空) | M29: 設定不要(固定値) 設定値：""(空) | N29: 設定不要(固定値) 設定値：""(空) | O29: 設定不要(固定値) 設定値：""(空) | P29: 設定不要(固定値) 設定値：""(空) | Q29: 設定不要(固定値) 設定値：""(空) | R29: 設定不要(固定値) 設定値：""(空) | S29: 設定不要(固定値) 設定値：""(空) | T29: 設定不要(固定値) 設定値：""(空) | U29: 設定不要(固定値) 設定値：""(空) | V29: 設定不要(固定値) 設定値：""(空) | W29: 設定不要(固定値) 設定値：""(空) | X29: 設定不要(固定値) 設定値：""(空) | Y29: 通番取消時：「1」が設定される ignicaPOS側から通番取消取引を連携しないため、設定不要
A30: =A29+1 -> 27 | B30: POST_VOID_REAS_CD | C30: ポスト取消理由CD | D30: smallint | F30: ● | I30: - | J30: TS/M | K30: ● | L30: 設定不要(固定値) 設定値：""(空) | M30: 設定不要(固定値) 設定値：""(空) | N30: 設定不要(固定値) 設定値：""(空) | O30: 設定不要(固定値) 設定値：""(空) | P30: 設定不要(固定値) 設定値：""(空) | Q30: 設定不要(固定値) 設定値：""(空) | R30: 設定不要(固定値) 設定値：""(空) | S30: 設定不要(固定値) 設定値：""(空) | T30: 設定不要(固定値) 設定値：""(空) | U30: 設定不要(固定値) 設定値：""(空) | V30: 設定不要(固定値) 設定値：""(空) | W30: 設定不要(固定値) 設定値：""(空) | X30: 設定不要(固定値) 設定値：""(空) | Y30: 通番取消時：「」が設定される ignicaPOS側から通番取消取引を連携しないため、設定不要
A31: =A30+1 -> 28 | B31: RGST_GRP_ID | C31: レジスタグループID | D31: smallint | F31: ● | I31: - | J31: TS/M | K31: ● | L31: 設定不要(固定値) 設定値：""(空) | M31: 設定不要(固定値) 設定値：""(空) | N31: 設定不要(固定値) 設定値：""(空) | O31: 設定不要(固定値) 設定値：""(空) | P31: 設定不要(固定値) 設定値：""(空) | Q31: 設定不要(固定値) 設定値：""(空) | R31: 設定不要(固定値) 設定値：""(空) | S31: 設定不要(固定値) 設定値：""(空) | T31: 設定不要(固定値) 設定値：""(空) | U31: 設定不要(固定値) 設定値：""(空) | V31: 設定不要(固定値) 設定値：""(空) | W31: 設定不要(固定値) 設定値：""(空) | X31: 設定不要(固定値) 設定値：""(空) | Y31: 未使用領域のため
A32: =A31+1 -> 29 | B32: LCL_TND_CD | C32: 現地支払CD | D32: smallint | F32: ● | I32: - | J32: TS/M | K32: ● | L32: 設定不要(固定値) 設定値：""(空) | M32: 設定不要(固定値) 設定値：""(空) | N32: 設定不要(固定値) 設定値：""(空) | O32: 設定不要(固定値) 設定値：""(空) | P32: 設定不要(固定値) 設定値：""(空) | Q32: 設定不要(固定値) 設定値：""(空) | R32: 設定不要(固定値) 設定値：""(空) | S32: 設定不要(固定値) 設定値：""(空) | T32: 設定不要(固定値) 設定値：""(空) | U32: 設定不要(固定値) 設定値：""(空) | V32: 設定不要(固定値) 設定値：""(空) | W32: 設定不要(固定値) 設定値：""(空) | X32: 設定不要(固定値) 設定値：""(空) | Y32: 未使用領域のため
A33: =A32+1 -> 30 | B33: GSFD_RCPT_TYPE | C33: 領収証発行種別 | D33: smallint | F33: ● | H33: １：領収証発行 ２：金額指定発行 | I33: - | J33: TS/M | K33: ● | L33: 設定不要(固定値) 設定値：""(空) | M33: 設定不要(固定値) 設定値：""(空) | N33: 設定不要(固定値) 設定値：""(空) | O33: 設定不要(固定値) 設定値：""(空) | P33: 設定不要(固定値) 設定値：""(空) | Q33: 設定不要(固定値) 設定値：""(空) | R33: 設定不要(固定値) 設定値：""(空) | S33: 設定不要(固定値) 設定値：""(空) | T33: 設定不要(固定値) 設定値：""(空) | U33: 設定不要(固定値) 設定値：""(空) | V33: 設定不要(固定値) 設定値：""(空) | W33: 設定不要(固定値) 設定値：""(空) | X33: 設定不要(固定値) 設定値：""(空) | Y33: 領収証取引を連携しないため、設定不要 集計もされない
A34: =A33+1 -> 31 | B34: GSFD_RCPT_INFO_ON_MEM_FG | C34: 領収証印字フラグ | D34: smallint | F34: ● | H34: 1：直前印字 | I34: - | J34: TS/M | K34: ● | L34: 設定不要(固定値) 設定値：""(空) | M34: 設定不要(固定値) 設定値：""(空) | N34: 設定不要(固定値) 設定値：""(空) | O34: 設定不要(固定値) 設定値：""(空) | P34: 設定不要(固定値) 設定値：""(空) | Q34: 設定不要(固定値) 設定値：""(空) | R34: 設定不要(固定値) 設定値：""(空) | S34: 設定不要(固定値) 設定値：""(空) | T34: 設定不要(固定値) 設定値：""(空) | U34: 設定不要(固定値) 設定値：""(空) | V34: 設定不要(固定値) 設定値：""(空) | W34: 設定不要(固定値) 設定値：""(空) | X34: 設定不要(固定値) 設定値：""(空) | Y34: 領収証取引を連携しないため、設定不要 集計もされない
A35: =A34+1 -> 32 | B35: GSFD_RCPT_RGST_TRAN_NBR | C35: 領収証発行対象取引通番 | D35: smallint | F35: ● | H35: 領収証発行対象取引通番 （通番指定時） | I35: - | J35: TS/M | K35: ● | L35: 設定不要(固定値) 設定値：""(空) | M35: 設定不要(固定値) 設定値：""(空) | N35: 設定不要(固定値) 設定値：""(空) | O35: 設定不要(固定値) 設定値：""(空) | P35: 設定不要(固定値) 設定値：""(空) | Q35: 設定不要(固定値) 設定値：""(空) | R35: 設定不要(固定値) 設定値：""(空) | S35: 設定不要(固定値) 設定値：""(空) | T35: 設定不要(固定値) 設定値：""(空) | U35: 設定不要(固定値) 設定値：""(空) | V35: 設定不要(固定値) 設定値：""(空) | W35: 設定不要(固定値) 設定値：""(空) | X35: 設定不要(固定値) 設定値：""(空) | Y35: 領収証取引を連携しないため、設定不要 集計もされない
A36: =A35+1 -> 33 | B36: GSFD_RCPT_RGST_ID | C36: 領収証発行対象ＰＯＳ通番 | D36: int | F36: ● | H36: 領収証発行対象POS番号 （通番指定時） | I36: - | J36: TS/M | K36: ● | L36: 設定不要(固定値) 設定値：""(空) | M36: 設定不要(固定値) 設定値：""(空) | N36: 設定不要(固定値) 設定値：""(空) | O36: 設定不要(固定値) 設定値：""(空) | P36: 設定不要(固定値) 設定値：""(空) | Q36: 設定不要(固定値) 設定値：""(空) | R36: 設定不要(固定値) 設定値：""(空) | S36: 設定不要(固定値) 設定値：""(空) | T36: 設定不要(固定値) 設定値：""(空) | U36: 設定不要(固定値) 設定値：""(空) | V36: 設定不要(固定値) 設定値：""(空) | W36: 設定不要(固定値) 設定値：""(空) | X36: 設定不要(固定値) 設定値：""(空) | Y36: 領収証取引を連携しないため、設定不要 集計もされない
A37: =A36+1 -> 34 | B37: GSFD_OFFCL_RCPT_AMT | C37: 領収証金額 | D37: money | F37: ● | H37: 領収書金額 | I37: - | J37: TS/M | K37: ● | L37: 設定不要(固定値) 設定値：""(空) | M37: 設定不要(固定値) 設定値：""(空) | N37: 設定不要(固定値) 設定値：""(空) | O37: 設定不要(固定値) 設定値：""(空) | P37: 設定不要(固定値) 設定値：""(空) | Q37: 設定不要(固定値) 設定値：""(空) | R37: 設定不要(固定値) 設定値：""(空) | S37: 設定不要(固定値) 設定値：""(空) | T37: 設定不要(固定値) 設定値：""(空) | U37: 設定不要(固定値) 設定値：""(空) | V37: 設定不要(固定値) 設定値：""(空) | W37: 設定不要(固定値) 設定値：""(空) | X37: 設定不要(固定値) 設定値：""(空) | Y37: 領収証取引を連携しないため、設定不要 集計もされない
A38: =A37+1 -> 35 | B38: GSFD_TRAN_TENDER_TS | C38: 小計キー押下日時 | D38: datetime | F38: ● | I38: - | J38: ignicaPOS | K38: ◎ | L38: 設定不要(固定値) 設定値： 1899-12-30 00:00:00.000 | M38: 設定値：取引終了日時を設定 9999-99-99 99:99:99.000 <例> 2021-02-04 10:45:44.000 | N38: 設定不要(固定値) 設定値： 1899-12-30 00:00:00.000 | O38: 設定不要(固定値) 設定値： 1899-12-30 00:00:00.000 | P38: 設定不要(固定値) 設定値： 1899-12-30 00:00:00.000 | Q38: 設定不要(固定値) 設定値： 1899-12-30 00:00:00.000 | R38: 設定不要(固定値) 設定値： 1899-12-30 00:00:00.000 | S38: 設定不要(固定値) 設定値： 1899-12-30 00:00:00.000 | T38: 設定不要(固定値) 設定値： 1899-12-30 00:00:00.000 | U38: 設定不要(固定値) 設定値： 1899-12-30 00:00:00.000 | V38: 設定不要(固定値) 設定値： 1899-12-30 00:00:00.000 | W38: 設定不要(固定値) 設定値： 1899-12-30 00:00:00.000 | X38: 設定不要(固定値) 設定値： 1899-12-30 00:00:00.000 | Y38: 担当者別の支払時間、登録時間の集計に使用 取引終了時刻しか持っていない場合は取引終了時刻を設定する。 | Z38: *1.9
A39: =A38+1 -> 36 | B39: GSFD_BILL_CNT | C39: 万券枚数 | D39: int | F39: ● | I39: - | J39: ignicaPOS | K39: ◎ | L39: 設定値：""(空) | M39: 設定値：取引で発生した万券枚数を設定 | N39: 設定値：取引で発生した万券枚数を設定 | O39: 設定値：取引で発生した万券枚数を設定 | P39: 設定値：取引で発生した万券枚数を設定 | Q39: 設定値：取引で発生した万券枚数を設定 | R39: 設定値：取引で発生した万券枚数を設定 | S39: 設定値：取引で発生した万券枚数を設定 | T39: 設定値：取引で発生した万券枚数を設定 | U39: 設定値：取引で発生した万券枚数を設定 | V39: 設定値：取引で発生した万券枚数を設定 | W39: 設定値：取引で発生した万券枚数を設定 | X39: 設定不要(固定値) 設定値：""(空)
A40: =A39+1 -> 37 | B40: GSFD_OFFCL_RCPT_CNT | C40: 領収証発行枚数 | D40: smallint | F40: ● | I40: - | J40: TS/M | K40: ● | L40: 設定不要(固定値) 設定値：""(空) | M40: 設定不要(固定値) 設定値：""(空) | N40: 設定不要(固定値) 設定値：""(空) | O40: 設定不要(固定値) 設定値：""(空) | P40: 設定不要(固定値) 設定値：""(空) | Q40: 設定不要(固定値) 設定値：""(空) | R40: 設定不要(固定値) 設定値：""(空) | S40: 設定不要(固定値) 設定値：""(空) | T40: 設定不要(固定値) 設定値：""(空) | U40: 設定不要(固定値) 設定値：""(空) | V40: 設定不要(固定値) 設定値：""(空) | W40: 設定不要(固定値) 設定値：""(空) | X40: 設定不要(固定値) 設定値：""(空) | Y40: ignicaPOS側から領収証取引を連携しないため、設定不要 領収証は無し
...

Sheet LN_LINK
A1: トラン連携ファイルレイアウト | C1: 対象テーブル：LN_LINK 形式：TSV
A2: NO | B2: 項目 | H2: 説明 | I2: 取得元マスタ項目 | J2: 設定元 | K2: 一次開発 必須項目 | L2: ignicaPOS・Scan&Go設定値 | N2: 備考
B3: カラム名称 | C3: 日本語名称 | D3: 型 | E3: サイズ | F3: NULL 許可 | G3: KEY | L3: 売上 | M3: 売上中止
A4: 1 | B4: TRAN_ID | C4: 取引通番 | D4: int | G4: PK | H4: 取引の識別子 | J4: TS/M | K4: ● | L4: TSM側で設定となるため、設定不要（固定値） 設定値：""(空) | M4: TSM側で設定となるため、設定不要（固定値） 設定値：""(空)
A5: 2 | B5: TRAN_LN_NBR | C5: 取引明細番号 | D5: smallint | G5: PK | H5: 取引の明細レベルに割当てられるライン番号 | I5: - | J5: ignicaPOS | K5: ◎ | L5: 設定値： リンク元となるLN_DETAILのTRAN_LN_NBR | M5: 設定値： リンク元となるLN_DETAILのTRAN_LN_NBR
A6: 3 | B6: LINK_LN_NBR | C6: リンク明細番号 | D6: smallint | G6: PK | H6: 取引内通番とリンクする内部管理番号（リンク先のTRAN_LN_NBRとなる） | I6: - | J6: ignicaPOS | K6: ◎ | L6: 設定値： リンク先となる下記テーブルのTRAN_LN_NBR ・LN_DISCOUNT ・TRANSACTION_TAX | M6: 設定値： リンク先となる下記テーブルのTRAN_LN_NBR ・LN_DISCOUNT ・TRANSACTION_TAX | O6: *1.0
A7: 4 | B7: LINK_TYP | C7: リンクタイプ | D7: smallint | G7: PK | H7: リンクのタイプまたは理由(税金、ディスカウントなど) 1：値引、 3：税、5：税(税率変更)、6：訂正済み現外支払、9：内税額、10：内税商品額(税抜き) | I7: - | J7: ignicaPOS | K7: ◎ | L7: 設定値：リンクのタイプまたは理由(税金、ディスカウントなど) | M7: 設定値：リンクのタイプまたは理由(税金、ディスカウントなど) | N7: 他の情報から、リンクテーブルを作成 | O7: *1.0
A8: 5 | B8: LINK_AMT | C8: リンク明細額 | D8: money | F8: ● | H8: このアイテムだけに適用される取引ディスカウントの金額等。 リンク先の金額。通番取消の場合、"0"が入る。値引の場合、値引額×数量の金額が入る。また、取引に対する値引（取引売価変更、小計値引等）が行われた場合は按分価格となる。 リンクタイプ=1：値引 値引額の明細按分額 リンクタイプ=9：内税 内税額の明細按分額 リンクタイプ=10：内税商品額(税抜き) 内税商品額(税抜き)の明細按分額 ※リンクタイプが1:値引の場合でも、特売・タイムサービス・マークダウンの場合は0を設定 | I8: - | J8: ignicaPOS | K8: ◎ | L8: 設定値： リンクタイプ=1：値引 値引額の明細按分額 リンクタイプ=9：内税 内税額の明細按分額 リンクタイプ=10：内税商品額(税抜き) 内税商品額(税抜き)の明細按分額 | M8: 設定値： リンクタイプ=1：値引 値引額の明細按分額 リンクタイプ=9：内税 内税額の明細按分額 リンクタイプ=10：内税商品額(税抜き) 内税商品額(税抜き)の明細按分額 | N8: 他の情報から、リンクテーブルを作成 | O8: *1.5,1.8
A9: 6 | B9: STR_ID | C9: 店舗番号 | D9: int | G9: PK | H9: 店舗番号 | I9: 店舗番号 | J9: ignicaPOS | K9: ◎ | L9: 設定値：店舗番号×10000 | M9: 設定値：店舗番号×10000
A10: 7 | B10: LINK_QTY | C10: リンクの数 | D10: float | F10: ● | H10: LinkTypeが1:値引の場合に数量を設定。 ※LinkTypeが1:値引の場合でも、特売・タイムサービス・マークダウンの場合は0を設定 | I10: - | J10: ignicaPOS | K10: ◎ | L10: 設定値：LinkTypeが1:値引の場合に数量を設定。 | M10: 設定値：LinkTypeが1:値引の場合に数量を設定。 | N10: 他の情報から、リンクテーブルを作成 | O10: *1.8

Sheet LN_DETAIL
A1: トラン連携ファイルレイアウト | C1: 対象テーブル：LN_DETAIL 形式：TSV
A2: NO | B2: 項目 | H2: 説明 | I2: 取得元マスタ項目 | J2: 設定元 | K2: 一次開発 必須項目 | L2: ignicaPOS・Scan&Go設定値 | N2: 備考
B3: カラム名称 | C3: 日本語名称 | D3: 型 | E3: サイズ | F3: NULL 許可 | G3: KEY | L3: 売上 | M3: 売上 中止
A4: 1 | B4: TRAN_ID | C4: 取引通番 | D4: int | G4: PK | H4: 取引の識別子 | I4: - | J4: TS/M | K4: ● | L4: TSM側で設定となるため、設定不要（固定値） 設定値：""(空) | M4: TSM側で設定となるため、設定不要（固定値） 設定値：""(空)
A5: =A4+1 -> 2 | B5: TRAN_LN_NBR | C5: 取引明細番号 | D5: smallint | G5: PK | H5: 取引の明細レベルに割当てられるライン番号 | I5: - | J5: ignicaPOS | K5: ◎ | L5: 設定値： 1取引内の下記テーブルのレコードの同一カラム名に通し番号を振る(番号が重複しなければ順不同で構わない) ・LN_DETAIL ・LN_DISCOUNT ・TRANSACTION_TAX ・TRANSACTION_TENDER | M5: 設定値： 1取引内の下記テーブルのレコードの同一カラム名に通し番号を振る(番号が重複しなければ順不同で構わない) ・LN_DETAIL ・LN_DISCOUNT ・TRANSACTION_TAX ・TRANSACTION_TENDER
A6: =A5+1 -> 3 | B6: STR_ID | C6: 店舗番号 | D6: int | G6: PK | H6: 店舗番号 | I6: 店舗番号 | J6: ignicaPOS | K6: ◎ | L6: 設定値：店舗番号×10000 | M6: 設定値：店舗番号×10000
A7: =A6+1 -> 4 | B7: LOC_ID | C7: 商品在庫位置 | D7: varchar | E7: 12 | F7: ● | H7: 販売／返品によって計算される在庫の位置 注：在庫が他の店舗または配送センター／倉庫にある場合、LOC_IDは他方店舗のロケーションになります。 | I7: - | J7: TS/M | K7: ● | L7: 設定不要(固定値) 設定値："" | M7: 設定不要(固定値) 設定値：""
A8: =A7+1 -> 5 | B8: SCAN_TYP | C8: PLUタイプ | D8: smallint | H8: 1：SKU 2：UPC-A 3：部門コード 4：EAN8、 JAN8 (NONPLU8) 5：EAN13、JAN13(NONPLU13) 新/旧書籍、新/旧雑誌 6：UPCE 7：ISBN100：KeyPLU、ShortCode 100：キーPLU 101：UPC-E | I8: 商品マスタ連携ファイル No.84 ＰＬＵタイプ | J8: ignicaPOS | K8: ◎ | L8: 設定値：商品マスタ連携ファイルから取得して設定 | M8: 設定値：商品マスタ連携ファイルから取得して設定
A9: =A8+1 -> 6 | B9: PLU_ID | C9: 自社商品コード | D9: varchar | E9: 24 | H9: 販売または返品された商品を表すPLU ＩＤ | I9: 商品マスタ連携ファイル No.2 自社商品コード | J9: ignicaPOS | K9: ◎ | L9: 設定値：商品マスタ連携ファイルから取得して設定 | M9: 設定値：商品マスタ連携ファイルから取得して設定
A10: =A9+1 -> 7 | B10: SCAN_ID | C10: スキャンコード | D10: varchar | E10: 24 | F10: ● | H10: 商品に付く数値の識別子で、通常はマシンで読取り可能なバーコードです。 | I10: 商品マスタ連携ファイル No.83 スキャンコード | J10: ignicaPOS | K10: ◎ | L10: 設定値：商品マスタ連携ファイルから取得して設定 | M10: 設定値：商品マスタ連携ファイルから取得して設定
A11: =A10+1 -> 8 | B11: LN_ITM_CD | C11: 商品明細識別 | D11: smallint | H11: 0：売上部門1：売上除外部門2：非商品部門3：非商品売上除外部門 明細種別 各ビットは ’１’で有意とする。 LSB ビット０：売上除外 ビット１：非商品 ビット２：返ビン ビット３：販売制限フラグ （酒類販売など） ビット４：特売（本部指示） ビット５：特売（店舗指示） ビット６：マークダウン ビット７：値引バーコード ビット８：緊急登録 ビット９：FSPクーポン値引バーコード ビット１０：値引除外 ビット１１：販売停止 ビット１２：販売証明書印刷指定 ビット１３：確認メッセージ出力商品 ビット１４：オフラインＰＬＵメンテフラグ（特売未反映フラグ） MSB ビット１５： | I11: 商品マスタ連携ファイルの「No.8 商品／非商品識別コード」に対して、下記のビットを立てる(ORする) ・マークダウン(一般)が採用された場合 ⇒ビット５：特売（店舗指示）＝32 および、ビット６：マークダウン＝64 ※32＋64＝96をORする ・タイムサービス(一般)、または、特売(一般)が採用された場合 ⇒ビット４：特売（本部指示）＝16 または、ビット５：特売（店舗指示）＝32 ※ビット４：特売（本部指示） or ビット５：特売（店舗指示）の判別方法 企画マスタ連携ファイルの「No.10 企画優先区分」を参照 ・企画優先区分=1(本部優先)の場合 ⇒ビット４：特売（本部指示）＝16 ・企画優先区分=0(店舗優先)の場合 ⇒ビット５：特売（店舗指示）＝32 ※ビット１０：値引除外は、POS操作で値引除外した場合に立てるフラグのため、ignica連携ではフラグ立ては不要 | J11: ignicaPOS | K11: ◎ | L11: 設定値：取得元マスタ項目を参照 | M11: 設定値：取得元マスタ項目を参照
A12: =A11+1 -> 9 | B12: MDSE_XREF_NO | C12: 商品分類番号 | D12: int | F12: ● | H12: 商品階層の最下層へのクロスリファレンス | I12: 商品マスタ連携ファイル No.91 内部商品分類番号 | J12: ignicaPOS | K12: ◎ | L12: 設定値：商品マスタ連携ファイルから取得して設定 | M12: 設定値：商品マスタ連携ファイルから取得して設定
A13: =A12+1 -> 10 | B13: STR_HIER_ID | C13: 販売部門ID | D13: int | F13: ● | H13: 商品を販売または返品する、店舗の販売部門 | I13: - | J13: TS/M | K13: ● | L13: 設定不要(固定値) 設定値：""(空) | M13: 設定不要(固定値) 設定値：""(空) | N13: 未使用領域の認識。
A14: =A13+1 -> 11 | B14: QTY | C14: 販売数量 | D14: float | H14: 単一の明細情報内の、販売または返品された商品の合計数量 | I14: - | J14: ignicaPOS | K14: ◎ | L14: 設定値：商品の数量 | M14: 設定値：商品の数量
A15: =A14+1 -> 12 | B15: UOM | C15: 販売単位 | D15: varchar | E15: 4 | F15: ● | H15: 明細の数量を計測する単位 | I15: - | J15: TS/M | K15: ● | L15: 設定不要(固定値) 設定値：""(空) | M15: 設定不要(固定値) 設定値：""(空) | N15: 未使用領域の認識。
A16: =A15+1 -> 13 | B16: PRC_MTHD | C16: 価格算出方法 | D16: smallint | H16: 合価を決定するために使用される値づけ方法 | I16: - | J16: TS/M | K16: ● | L16: 設定不要(固定値) 設定値：""(空) | M16: 設定不要(固定値) 設定値：""(空) | N16: 未使用領域の認識。
A17: =A16+1 -> 14 | B17: EXT_PRC | C17: 合価 | D17: money | H17: 販売価格（特売の場合は特売価格、売価変更時は売価変更後の価格、その他の場合は「商品マスタ連携ファイル No.22 売価」）× 数量の金額を設定する。 | I17: 商品マスタ連携ファイル No.22 売価 × 数量 | J17: ignicaPOS | K17: ◎ | L17: 設定値：明細情報に対して課される合計価格 | M17: 設定値：明細情報に対して課される合計価格
A18: =A17+1 -> 15 | B18: EXT_CST | C18: 合計原価 | D18: money | F18: ● | H18: 合計原価。商品原価×数量の金額が入る。 | I18: 商品マスタ連携ファイル No.23 単位原価 No.26 原価率フラグ | J18: ignicaPOS | K18: ◎ | L18: 設定値：合計原価を設定 | M18: 設定値：合計原価を設定 | O18: *1.0
A19: =A18+1 -> 16 | B19: RTL_PRC | C19: 売価 | D19: money | I19: 商品マスタ連携ファイル No.22 売価 | J19: ignicaPOS | K19: ◎ | L19: 設定値：売価を設定 | M19: 設定値：売価を設定
A20: =A19+1 -> 17 | B20: ENTRY_MTHD | C20: 登録方法 | D20: smallint | H20: POSでの商品識別メソッドを識別するコードで、通常はマニュアル入力かスキャンかを区別します。 １：キーボード入力 ２：スキャナ入力 | I20: - | J20: ignicaPOS | K20: ◎ | L20: 設定値：入力方法に従い設定 １：キーボード入力 ２：スキャナ入力 | M20: 設定値：入力方法に従い設定 １：キーボード入力 ２：スキャナ入力
A21: =A20+1 -> 18 | B21: COMM_EMP_ID | C21: 担当従業員ＩＤ | D21: varchar | E21: 12 | F21: ● | H21: 商品販売に携わった従業員 | I21: - | J21: TS/M | K21: ● | L21: 設定不要(固定値) 設定値：""(空) | M21: 設定不要(固定値) 設定値：""(空) | N21: 未使用領域の認識。
A22: =A21+1 -> 19 | B22: ITM_MVMT_FG | C22: 売上集計加算判別 | D22: smallint | H22: TRUEの場合、アイテムは集計されます。運用中の在庫管理の動きが意味をなさない明細情報については、この属性はFALSEにすることもできます。 | I22: - | J22: TS/M | K22: ● | L22: 設定不要(固定値) 設定値：""(空) | M22: 設定不要(固定値) 設定値：""(空) | N22: 未使用領域の認識。
A23: =A22+1 -> 20 | B23: VOID_CD | C23: 取消コード | D23: smallint | H23: 明細をボイドにする理由を記述する数値コード。値0は、その詳細がボイドになっていないことを示します。 | I23: - | J23: TS/M | K23: ● | L23: 設定不要(固定値) 設定値：""(空) | M23: 設定不要(固定値) 設定値：""(空) | N23: 訂正明細は連携しない。
A24: =A23+1 -> 21 | B24: EVNT_ID | C24: イベントID | D24: varchar | E24: 6 | H24: 売上げ明細が対応するイベントコードを識別します。 | I24: - | J24: TS/M | K24: ● | L24: 設定不要(固定値) 設定値：""(空) | M24: 設定不要(固定値) 設定値：""(空) | N24: 未使用領域の認識。
A25: =A24+1 -> 22 | B25: RTN_REAS_CD | C25: 返品理由コード | D25: smallint | H25: 顧客が示した商品を返品する理由です。 ０：通常明細、返品取消明細 １：返品明細 ２：取消明細 ※返品明細の判定には使用できない。→GSFD_RTN_REAS_CDを参照。 | I25: - | J25: TS/M | K25: ● | L25: 設定不要(固定値) 設定値：""(空) | M25: 設定不要(固定値) 設定値：""(空) | N25: いなげやでは、返品取引がないため０固定 ０：通常明細, １：返品明細
A26: =A25+1 -> 23 | B26: RCPT_PRSNT_FG | C26: レシート有無 | D26: smallint | H26: ブール値。TRUEは、返品がレシートと一緒に受け付けられたことを示します。 | I26: - | J26: TS/M | K26: ● | L26: 設定不要(固定値) 設定値：""(空) | M26: 設定不要(固定値) 設定値：""(空) | N26: 未使用領域の認識。
A27: =A26+1 -> 24 | B27: PKG_OPEN_FG | C27: パッケージの開封 | D27: smallint | H27: ブール値。TRUEは、返品されたアイテムのパッケージングが破られていたことを示します。 | I27: - | J27: TS/M | K27: ● | L27: 設定不要(固定値) 設定値：""(空) | M27: 設定不要(固定値) 設定値：""(空) | N27: 未使用領域の認識。
A28: =A27+1 -> 25 | B28: LN_ITM_TS | C28: 商品明細日時 | D28: datetime | H28: 商品詳細が入力された日付と時間 | I28: - | J28: ignicaPOS | K28: 〇 | L28: 設定値：取引開始時刻を設定 9999-99-99 99:99:99.000 <例> 2021-02-04 10:4:57.000 | M28: 設定値：取引開始時刻を設定 9999-99-99 99:99:99.000 <例> 2021-02-04 10:4:57.000 | N28: 取引開始時刻を持っていない場合は取引終了時刻を設定する。
A29: =A28+1 -> 26 | B29: FOR_QTY | C29: 組合せ販売数量 | D29: smallint | F29: ● | H29: これはスプリットプライスに使用され、ForPriceフィールドに対応する数量を表します。ユニットタイプアイテムにだけ適用でき、デフォルトは1です。 | I29: - | J29: TS/M | K29: ● | L29: TSM側で設定となるため、設定不要（固定値） 設定値：""(空) | M29: TSM側で設定となるため、設定不要（固定値） 設定値：""(空)
A30: =A29+1 -> 27 | B30: PERPET_INV_CD | C30: 永続在庫管理コード | D30: smallint | F30: ● | H30: アイテムの売上げ／返品によって手持ち在庫を更新する必要があるかどうかと、その更新方法を識別します。 | I30: - | J30: TS/M | K30: ● | L30: 設定不要(固定値) 設定値：""(空) | M30: 設定不要(固定値) 設定値：""(空) | N30: 未使用領域の認識。
A31: =A30+1 -> 28 | B31: DMGD_CD | C31: 損傷コード | D31: smallint | F31: ● | H31: 返品されたアイテムが損傷状態にあるかどうか、または最終処分のために特別な処理を必要とするかどうかを識別します。 例：修復不能な損傷状態、在庫から除く。最終処分にマネージャの評価が必要。販売フロアに配置する前にクリーニングおよびプレスが必要。供給者として、損傷の原因を示すRTVを作成。 | I31: - | J31: TS/M | K31: ● | L31: 設定不要(固定値) 設定値：""(空) | M31: 設定不要(固定値) 設定値：""(空) | N31: 未使用領域の認識。
A32: =A31+1 -> 29 | B32: PLU_QUAL_TYP | C32: PLU属性種別 | D32: int | F32: ● | H32: PLU属性種別 | I32: - | J32: TS/M | K32: ● | L32: 設定不要(固定値) 設定値：""(空) | M32: 設定不要(固定値) 設定値：""(空) | N32: 未使用領域の認識。
A33: =A32+1 -> 30 | B33: LOC_STR_ID | C33: 在庫店舗番号 | D33: int | F33: ● | H33: 販売されるべき在庫がある店舗／倉庫を識別します。販売店舗が在庫店舗と別の場合だけ設定します。 | I33: 店舗番号 | J33: ignicaPOS | K33: ◎ | L33: 設定値：店舗番号×10000 | M33: 設定値：店舗番号×10000
A34: =A33+1 -> 31 | B34: GSFD_EXT_PROMO_CST | C34: 特売原価 | D34: money | F34: ● | H34: 特売原価を設定（1個当たりの原価） ※マークダウンの場合は、0を設定 | I34: 特売マスタ連携ファイル No.19 特売原価 No35 原価率フラグ | J34: ignicaPOS | K34: ◎ | L34: 設定値：特売原価を設定 | M34: 設定値：特売原価を設定
A35: =A34+1 -> 32 | B35: GSFD_SCAN_CODE | C35: スキャンコード（単品登録時） | D35: varchar | E35: 75 | F35: ● | H35: スキャンコード(生データ)。スキャン登録を行った場合のみ値が入る。 入力コードをそのまま格納し、セミコロンで区切る。 多段バーコードの場合は各段がセミコロンで区切られる。 例）JAN13の場合“4903080109181;” 例）書籍二段コードの場合“9784095060217;1910582028004;” 部門登録の場合は””(空)を設定する。 | I35: - | J35: ignicaPOS | K35: ◎ | L35: 設定値：スキャンコード+";"(セミコロン) | M35: 設定値：スキャンコード+";"(セミコロン) | O35: *1.0*1.1
A36: =A35+1 -> 33 | B36: GSFD_DIFFERENCE_PRICE | C36: 会員価格と一般価格の差額 | D36: money | F36: ● | H36: 会員価格と一般価格の差額（合価） | I36: - | J36: TS/M | K36: ● | L36: 設定不要(固定値) 設定値：""(空) | M36: 設定不要(固定値) 設定値：""(空) | N36: 会員価格は未使用の認識
A37: =A36+1 -> 34 | B37: GSFD_ENTRY_OPERATOR | C37: 本明細を登録した担当者コード | D37: varchar | E37: 12 | F37: ● | I37: 担当者マスタ連携ファイル No.6 担当者コード | J37: ignicaPOS | K37: ◎ | L37: 設定値：本明細を登録した担当者番号 | M37: 設定値：本明細を登録した担当者番号
