Workbook

Sheet 表紙
A1: システム名 | K1: システム種別 | W1: 詳細設計書 | AP1: 作成者 | AT1: 作成日 | AY1: 更新者 | BC1: 更新日 | BH1: 版数
A2: POSサーバー | K2: POSサーバ | AP2: =改訂履歴!$H$11 -> DuNT | AT2: =改訂履歴!$B$11 -> 45477 | AY2: =LOOKUP(2,1/(改訂履歴!H11:H30000<>""),改訂履歴!H11:H30000) -> DuNT | BC2: =LOOKUP(2,1/(改訂履歴!B11:B30000<>""),改訂履歴!B11:B30000) -> 45504 | BH2: =LOOKUP(2,1/(改訂履歴!O11:O30000<>""),改訂履歴!O11:O30000) -> 0.2
A4: 機能カテゴリ | H4: AP1508 | U4: 項目 | Z4: API設計書 | AP4: {=RIGHT(CELL("filename",$A$1),LEN(CELL("filename",$A$1))-FIND("]",CELL("filename",$A$1)))} -> 表紙
L16: POSサーバーの詳細設計書
L24: =K2&"/"&H4&"/"&Z4 -> POSサーバ/AP1508/API設計書
Q44: 承認日 | AA44: 承認者 | AQ44: 版数

Sheet 改訂履歴
A1: システム名 | K1: システム種別 | W1: =IF(表紙!W1="","",表紙!W1) -> 詳細設計書 | AP1: 作成者 | AT1: 作成日 | AY1: 更新者 | BC1: 更新日 | BH1: 版数
A2: =IF(表紙!A2="","",表紙!A2) -> POSサーバー | K2: =IF(表紙!K2="","",表紙!K2) -> POSサーバ | AP2: =IF(表紙!AP2="","",表紙!AP2) -> DuNT | AT2: =IF(表紙!AT2="","",表紙!AT2) -> 45477 | AY2: =IF(表紙!AY2="","",表紙!AY2) -> DuNT | BC2: =IF(表紙!BC2="","",表紙!BC2) -> 45504 | BH2: =IF(表紙!BH2="","",表紙!BH2) -> 0.2
A4: 機能カテゴリー | H4: =IF(表紙!H4="","",表紙!H4) -> AP1508 | U4: 項目 | Z4: =IF(表紙!Z4="","",表紙!Z4) -> API設計書 | AP4: {=RIGHT(CELL("filename",$A$1),LEN(CELL("filename",$A$1))-FIND("]",CELL("filename",$A$1)))} -> 改訂履歴
B8: ■改訂履歴
B10: 更新日 | H10: 更新者 | O10: 版数 | S10: 更新内容 | AX10: 承認日 | BD10: 承認者
B11: 45477 | H11: DuNT | O11: 0.1 | S11: 新規
B13: 45504 | H13: DuNT | O13: 0.2 | S13: AP1508シート
S14: ・api urlを修正する。 ・is_display_on_cash_machine、is_display_on_customer_screenのフィールドを追加する。

Sheet 処理フロー凡例
A1: システム名 | K1: システム種別 | W1: =IF(表紙!W1="","",表紙!W1) -> 詳細設計書 | AP1: 作成者 | AT1: 作成日 | AY1: 更新者 | BC1: 更新日 | BH1: 版数
A2: =IF(表紙!A2="","",表紙!A2) -> POSサーバー | K2: =IF(表紙!K2="","",表紙!K2) -> POSサーバ | AP2: =IF(表紙!AP2="","",表紙!AP2) -> DuNT | AT2: =IF(表紙!AT2="","",表紙!AT2) -> 45477 | AY2: =IF(表紙!AY2="","",表紙!AY2) -> DuNT | BC2: =IF(表紙!BC2="","",表紙!BC2) -> 45504 | BH2: =IF(表紙!BH2="","",表紙!BH2) -> 0.2
A4: 機能カテゴリ | H4: =IF(表紙!H4="","",表紙!H4) -> AP1508 | U4: 項目 | Z4: =IF(表紙!Z4="","",表紙!Z4) -> API設計書 | AP4: =MID(CELL("filename",A1),FIND("]",CELL("filename",A1))+1,255) -> 処理フロー凡例
B7: ●API処理フロー

Sheet AP1508
A1: システム名 | K1: システム種別 | W1: =IF(表紙!W1="","",表紙!W1) -> 詳細設計書 | AP1: 作成者 | AT1: 作成日 | AY1: 更新者 | BC1: 更新日 | BH1: 版数
A2: =IF(表紙!A2="","",表紙!A2) -> POSサーバー | K2: =IF(表紙!K2="","",表紙!K2) -> POSサーバ | AP2: =IF(表紙!AP2="","",表紙!AP2) -> DuNT | AT2: =IF(表紙!AT2="","",表紙!AT2) -> 45477 | AY2: =IF(表紙!AY2="","",表紙!AY2) -> DuNT | BC2: =IF(表紙!BC2="","",表紙!BC2) -> 45504 | BH2: =IF(表紙!BH2="","",表紙!BH2) -> 0.2
A4: 機能カテゴリ | H4: =IF(表紙!H4="","",表紙!H4) -> AP1508 | U4: 項目 | Z4: =IF(表紙!Z4="","",表紙!Z4) -> API設計書 | AP4: =MID(CELL("filename",A1),FIND("]",CELL("filename",A1))+1,255) -> AP1508
B7: 1. 概要
C9: プリセットレイアウトを新規作成、編集、削除する。
B11: 2. リクエスト
C13: 2.1 Request URL
C15: No. | E15: URL | AG15: HTTPメソッド | AQ15: 備考
C16: 1 | E16: api/v1/preset/maintenance | AG16: POST | AQ16: -
C18: 2. 2 Request Header
C20: No. | E20: ヘッダー | L20: 必須 | O20: 型 | S20: デフォルト値 | Z20: 項目説明 | AQ20: 備考
C21: 1 | E21: Authorization | L21: ○ | O21: String | S21: - | Z21: Api key | AQ21: 代表ユーザーを認証するAPIキー値 フォーマット："Bearer {api_key}"
C23: 2 | E23: Accept | L23: - | O23: String | S23: - | Z23: Accept
C24: 3 | E24: Content-Type | L24: ○ | O24: String | S24: application/json | Z24: Content-Type
C25: 4 | E25: User-Agent | L25: - | O25: String | S25: - | Z25: User-Agent
C26: 5 | E26: Accept-Encoding | L26: - | O26: String | S26: - | Z26: Accept-Encoding
C28: 2.3 Query Parameter/ path parameter
C30: No. | E30: パラメータ | L30: 必須 | O30: 型 | S30: デフォルト値 | Z30: 項目説明 | AQ30: 備考
C31: なし
C33: 2.4 Request Body
C35: No. | E35: パラメータ | L35: 必須 | O35: 型 | S35: デフォルト値 | Z35: 項目説明 | AQ35: 備考
C36: 1 | E36: preset_menu | L36: - | O36: List<Menu> | S36: -
C37: 2 | E37: operation_type | L37: ○ | O37: Small Int | AQ37: ・新規作成の場合、operation_typeを「1」として渡す。 ・編集の場合、operation_type を「2」として渡す。 ・削除の場合、operation_typeを「3」として渡す。 上記以外の場合、エラーメッセージ = MSG_VAL_019
C38: 3 | E38: record_id | L38: - | O38: BigInt | S38: - | Z38: PresetMenuMaster.ID | AQ38: ・プリセットレイアウトを新規作成する場合、record_idをnullとして渡す。 ・プリセットレイアウトを編集する場合、該当するrecord_idを渡す。
C39: 4 | E39: store_code | L39: ○ | O39: String | S39: - | Z39: PresetMenuMaster.StoreCode | AQ39: バリデーションチェック：数字、4桁 バリデーションチェックNGの場合、エラーメッセージ = MSG_VAL_019
C40: 5 | E40: preset_layout_code | L40: ○ | O40: String | S40: - | Z40: PresetMenuMaster.ButtonLayoutCode | AQ40: バリデーションチェックの新規作成の場合： ・数字4桁 -> 数字ではない場合、エラーメッセージ = MSG_VAL_026、長さが4桁以外の場合、エラーメッセージ= MSG_VAL_002 ・プリセットレイアウトを新規作成する前に存在を確認する。存在した場合、エラーメッセージ = MSG_ERR_003
C41: 6 | E41: preset_layout_name | L41: ○ | O41: String | S41: - | Z41: PresetMenuMaster.ButtonLayoutName | AQ41: 最大半角50文字（全角25文字）。文字数 > 50の場合、 エラーメッセージ = MSG_VAL_002
C42: 7 | E42: booking_date | L42: ○ | O42: String | S42: - | Z42: PresetMenuMaster.ApplyDate | AQ42: バリデーションチェック：過去日不許可。フォーマット: yyyy/mm/dd 過去日の場合、エラーメッセージ = MSG_VAL_022
C43: 8 | E43: page_number | L43: - | O43: Int | S43: - | Z43: PresetMenuMaster.PageNumber
C44: 9 | E44: description | L44: - | O44: String | S44: - | Z44: PresetMenuMaster.Description | AQ44: 最大半角50文字（全角25文字）。文字数 > 50の場合、 エラーメッセージ = MSG_VAL_002
C45: 10 | E45: button_column_count | L45: - | O45: Int | S45: - | Z45: PresetMenuMaster.ButtonColumnCount
C46: 11 | E46: button_row_count | L46: - | O46: Int | S46: - | Z46: PresetMenuMaster.ButtonRowCount
C47: 12 | E47: is_display_on_cash_machine | L47: - | O47: Boolean | S47: - | Z47: PresetMenuMaster.IsDisplayOnCashMachine
C48: 13 | E48: is_display_on_customer_screen | L48: - | O48: Boolean | S48: - | Z48: PresetMenuMaster.IsDisplayOnCustomerScreen
C49: 14 | E49: style_key | L49: - | O49: String | S49: - | Z49: PresetMenuMaster.StyleKey
C50: 15 | E50: preset_menu_button | L50: - | O50: List<MenuButton> | S50: -
C51: 16 | E51: operation_type | L51: - | O51: Small Int | S51: - | AQ51: ・新規作成の場合、operation_typeを「1」として渡す。 ・編集の場合、operation_type を「2」として渡す。 ・削除の場合、operation_typeを「3」として渡す。 上記以外の場合、エラーメッセージ = MSG_VAL_019
C52: 17 | E52: record_id | L52: - | O52: BigInt | S52: - | Z52: PresetMenuButtonMaster.ID | AQ52: ・プリセットメニューボタンの新規作成の場合、record_idをnullとして渡す。 ・プリセットメニューボタンの編集の場合、該当するrecord_idを渡す。
C53: 18 | E53: store_code | L53: - | O53: String | S53: - | Z53: PresetMenuButtonMaster.StoreCode
C54: 19 | E54: preset_layout_code | L54: - | O54: String | S54: - | Z54: PresetMenuButtonMaster.ButtonLayoutCode
...

Sheet 処理フロー
A1: システム名 | K1: システム種別 | W1: =IF(表紙!W1="","",表紙!W1) -> 詳細設計書 | AP1: 作成者 | AT1: 作成日 | AY1: 更新者 | BC1: 更新日 | BH1: 版数
A2: =IF(表紙!A2="","",表紙!A2) -> POSサーバー | K2: =IF(表紙!K2="","",表紙!K2) -> POSサーバ | AP2: =IF(表紙!AP2="","",表紙!AP2) -> DuNT | AT2: =IF(表紙!AT2="","",表紙!AT2) -> 45477 | AY2: =IF(表紙!AY2="","",表紙!AY2) -> DuNT | BC2: =IF(表紙!BC2="","",表紙!BC2) -> 45504 | BH2: =IF(表紙!BH2="","",表紙!BH2) -> 0.2
A4: 機能カテゴリ | H4: =IF(表紙!H4="","",表紙!H4) -> AP1508 | U4: 項目 | Z4: =IF(表紙!Z4="","",表紙!Z4) -> API設計書 | AP4: =MID(CELL("filename",A1),FIND("]",CELL("filename",A1))+1,255) -> 処理フロー
B11: ▪プリセットメニューの追加・更新・削除処理
B106: ▪ 7. プリセットメニューボタンの追加・更新・削除処理

Sheet テンプレート
A1: システム名 | K1: システム種別 | W1: =IF(表紙!W1="","",表紙!W1) -> 詳細設計書 | AP1: 作成者 | AT1: 作成日 | AY1: 更新者 | BC1: 更新日 | BH1: 版数
A2: =IF(表紙!A2="","",表紙!A2) -> POSサーバー | K2: =IF(表紙!K2="","",表紙!K2) -> POSサーバ | AP2: =IF(表紙!AP2="","",表紙!AP2) -> DuNT | AT2: =IF(表紙!AT2="","",表紙!AT2) -> 45477 | AY2: =IF(表紙!AY2="","",表紙!AY2) -> DuNT | BC2: =IF(表紙!BC2="","",表紙!BC2) -> 45504 | BH2: =IF(表紙!BH2="","",表紙!BH2) -> 0.2
A4: 機能カテゴリ | H4: =IF(表紙!H4="","",表紙!H4) -> AP1508 | U4: 項目 | Z4: =IF(表紙!Z4="","",表紙!Z4) -> API設計書 | AP4: =MID(CELL("filename",A1),FIND("]",CELL("filename",A1))+1,255) -> テンプレート
