Workbook
Name ＤＢ名: #REF!
Name あああ: #REF!
Name タイトル: #REF!
Name テーブル名: #REF!
Name ヘダー部: #REF!
Name 更新日付: #REF!
Name 作成者: #REF!
Name 説明１: #REF!
Name 説明２: #REF!
Name 版: #REF!
Name 明細部: #REF!

Sheet 表紙

Sheet 変更履歴
B1: 変 更 履 歴
B3: 日付 | F3: 対象 | Q3: 内容
B4: 44130 | Q4: 初版
B5: 44138 | F5: 売価情報取得 | Q5: 現在売価を追加（カテゴリ割引）
F6: (補足)現在売価仕様 | Q6: カスミ様提供資料を追加
F7: (補足)時間帯速報 | Q7: カスミ様提供資料を追加
B8: 44153 | F8: 売価情報取得 | Q8: SHARPOPで必要な項目を追加
B9: 44155 | F9: 単品特売取得 | Q9: 「店舗開始時間」「店舗終了時間」を追加
F10: 売価情報取得、単品特売取得等 | Q10: 一部項目の型を数値から文字へ変更
B11: 44167 | F11: 売価情報取得ほか | Q11: 各金額の項目名に「(税抜)」を補足
F12: 廃棄情報取得、廃棄更新 | Q12: 「登録日時」を「更新日時」へ修正
B13: 44176 | F13: 各時間帯速報 | Q13: 業務情報(配列)の出力方法を変更
B14: 44189 | F14: 共通パラメータ | Q14: 共通パラメータにセッションIDを追加
F15: ログイン認証 | Q15: 業務情報にセッションIDを追加
F16: 売価情報取得 | Q16: パラメータ修正
F17: 企画区分取得 | Q17: 業務情報に企画開始日付、企画開始時刻、企画終了日付、企画終了時刻を追加
F18: プリセット廃棄一覧取得 | Q18: シーケンス番号追加
F19: 単品特売取得ほか | Q19: ソート順を修正

Sheet WebAPI一覧
A1: IF設計書 | K1: システム名 | S1: カスミ様PDAシステム | AC1: 作成者 | AG1: SANT | AM1: 作成日 | AQ1: 44130
K2: サブシステム名 | S2: POSメニュー | AC2: 更新者 | AM2: 更新日
B4: No | C4: URI | L4: API論理名 | R4: Method | T4: 処理概要 | AK4: 備考
B5: =ROW()-4 -> 1 | C5: =ログイン認証!$F$4 -> {hostURI}/login | L5: ログイン認証 | R5: =ログイン認証!$F$5 -> POST | T5: =ログイン認証!$AC$5 -> ログイン画面で認証を行う。
B6: =ROW()-4 -> 2 | C6: =ログアウト!$F$4 -> {hostURI}/logout | L6: ログアウト | R6: =ログアウト!$F$5 -> POST | T6: =ログアウト!$AC$5 -> ログアウトを行う。
B7: =ROW()-4 -> 3 | C7: =売価情報取得!$F$4 -> {hostURI}/price/select | L7: 売価情報取得 | R7: =売価情報取得!$F$5 -> POST | T7: =売価情報取得!$AC$5 -> PLUスキャン後の売価情報を取得する
B8: =ROW()-4 -> 4 | C8: =定番売価更新!$F$4 -> {hostURI}/pricechange/update | L8: 定番売価更新 | R8: =定番売価更新!$F$5 -> POST | T8: =定番売価更新!$AC$5 -> 定番売価の変更を行う。
B9: =ROW()-4 -> 5 | C9: =企画区分取得!$F$4 -> {hostURI}/plan/select | L9: 企画区分取得 | R9: =企画区分取得!$F$5 -> POST | T9: =企画区分取得!$AC$5 -> 企画区分のリストを取得する。
B10: =ROW()-4 -> 6 | C10: =単品特売取得!$F$4 -> {hostURI}/Itemsale/select | L10: 単品特売取得 | R10: =単品特売取得!$F$5 -> POST | T10: =単品特売取得!$AC$5 -> 単品特売一覧を取得する。
B11: =ROW()-4 -> 7 | C11: =単品特売更新!$F$4 -> {hostURI}/Itemsale/update | L11: 単品特売更新 | R11: =単品特売更新!$F$5 -> POST | T11: =単品特売更新!$AC$5 -> 単品特売設定の新規登録・更新を行う。
B12: =ROW()-4 -> 8 | C12: =緊急売価更新!$F$4 -> {hostURI}/emprice/update | L12: 緊急売価更新 | R12: =緊急売価更新!$F$5 -> POST | T12: =緊急売価更新!$AC$5 -> 緊急売価の変更を行う。
B13: =ROW()-4 -> 9 | C13: =グループ取得!$F$4 -> {hostURI}/group/select | L13: グループ取得 | R13: =グループ取得!$F$5 -> POST | T13: =グループ取得!$AC$5 -> グループのリストを取得する。
B14: =ROW()-4 -> 10 | C14: =プリセット商品取得!$F$4 -> {hostURI}/preset/select | L14: プリセット商品取得 | R14: =プリセット商品取得!$F$5 -> POST | T14: =プリセット商品取得!$AC$5 -> プリセット商品一覧を取得する。
B15: =ROW()-4 -> 11 | C15: =部門速報取得!$F$4 -> {hostURI}/flash/bumon/select | L15: 部門速報取得 | R15: =部門速報取得!$F$5 -> POST | T15: =部門速報取得!$AC$5 -> 部門速報を取得する。
B16: =ROW()-4 -> 12 | C16: =品群速報取得!$F$4 -> {hostURI}/flash/hingun/select | L16: 品群速報取得 | R16: =品群速報取得!$F$5 -> POST | T16: =品群速報取得!$AC$5 -> 品群速報を取得する。
B17: =ROW()-4 -> 13 | C17: =品種速報取得!$F$4 -> {hostURI}/flash/hinshu/select | L17: 品種速報取得 | R17: =品種速報取得!$F$5 -> POST | T17: =品種速報取得!$AC$5 -> 品種速報を取得する。
B18: =ROW()-4 -> 14 | C18: =分類速報取得!$F$4 -> {hostURI}/flash/bunrui/select | L18: 分類速報取得 | R18: =分類速報取得!$F$5 -> POST | T18: =分類速報取得!$AC$5 -> 分類速報を取得する。
B19: =ROW()-4 -> 15 | C19: =単品速報取得!$F$4 -> {hostURI}/flash/item/select | L19: 単品速報取得 | R19: =単品速報取得!$F$5 -> POST | T19: =単品速報取得!$AC$5 -> 単品速報を取得する。
B20: =ROW()-4 -> 16 | C20: =店舗時間帯速報取得!$F$4 -> {hostURI}/tmflash/ten/select | L20: 店舗時間帯速報取得 | R20: =店舗時間帯速報取得!$F$5 -> POST | T20: =店舗時間帯速報取得!$AC$5 -> 店舗時間帯速報を取得する。
B21: =ROW()-4 -> 17 | C21: =部門時間帯速報取得!$F$4 -> {hostURI}/tmflash/bumon/select | L21: 部門時間帯速報取得 | R21: =部門時間帯速報取得!$F$5 -> POST | T21: =部門時間帯速報取得!$AC$5 -> 部門時間帯速報を取得する。
B22: =ROW()-4 -> 18 | C22: =品群時間帯速報取得!$F$4 -> {hostURI}/tmflash/hingun/select | L22: 品群時間帯速報取得 | R22: =品群時間帯速報取得!$F$5 -> POST | T22: =品群時間帯速報取得!$AC$5 -> 品群時間帯速報を取得する。
B23: =ROW()-4 -> 19 | C23: =品種時間帯速報取得!$F$4 -> {hostURI}/tmflash/hinshu/select | L23: 品種時間帯速報取得 | R23: =品種時間帯速報取得!$F$5 -> POST | T23: =品種時間帯速報取得!$AC$5 -> 品種時間帯速報を取得する。
B24: =ROW()-4 -> 20 | C24: =分類時間帯速報取得!$F$4 -> {hostURI}/tmflash/bunrui/select | L24: 分類時間帯速報取得 | R24: =分類時間帯速報取得!$F$5 -> POST | T24: =分類時間帯速報取得!$AC$5 -> 分類時間帯速報を取得する。
B25: =ROW()-4 -> 21 | C25: =単品時間帯速報取得!$F$4 -> {hostURI}/tmflash/item/select | L25: 単品時間帯速報取得 | R25: =単品時間帯速報取得!$F$5 -> POST | T25: =単品時間帯速報取得!$AC$5 -> 単品時間帯速報を取得する。
B26: =ROW()-4 -> 22 | C26: ='単品速報取得(PLU指定)'!$F$4 -> {hostURI}/tmflash/plu/select | L26: 単品速報取得(PLU指定) | R26: ='単品速報取得(PLU指定)'!$F$5 -> POST | T26: ='単品速報取得(PLU指定)'!$AC$5 -> 単品速報（月・週・日・時間帯）を取得する。
B27: =ROW()-4 -> 23 | C27: =廃棄情報取得!$F$4 -> {hostURI}/haiki/select | L27: 廃棄情報取得 | R27: =廃棄情報取得!$F$5 -> POST | T27: =廃棄情報取得!$AC$5 -> 入力済の廃棄情報を取得する。（新規登録時は当APIはCallしない）
B28: =ROW()-4 -> 24 | C28: =廃棄更新!$F$4 -> {hostURI}/haiki/update | L28: 廃棄更新 | R28: =廃棄更新!$F$5 -> POST | T28: =廃棄更新!$AC$5 -> 廃棄商品の登録を行う。
B29: =ROW()-4 -> 25 | C29: =廃棄部門別一覧取得!$F$4 -> {hostURI}/haikibumon/select | L29: 廃棄部門別一覧取得 | R29: =廃棄部門別一覧取得!$F$5 -> POST | T29: =廃棄部門別一覧取得!$AC$5 -> 部門別の廃棄一覧を取得する。
B30: =ROW()-4 -> 26 | C30: =廃棄商品別一覧取得!$F$4 -> {hostURI}/haikiitem/select | L30: 廃棄商品別一覧取得 | R30: =廃棄商品別一覧取得!$F$5 -> POST | T30: =廃棄商品別一覧取得!$AC$5 -> 商品別の廃棄一覧を取得する。
B31: =ROW()-4 -> 27 | C31: =レジグループ取得!$F$4 -> {hostURI}/reggroup/select | L31: レジグループ取得 | R31: =レジグループ取得!$F$5 -> POST | T31: =レジグループ取得!$AC$5 -> グループのリストを取得する。
B32: =ROW()-4 -> 28 | C32: =タブ取得!$F$4 -> {hostURI}/regtab/select | L32: タブ取得 | R32: =タブ取得!$F$5 -> POST | T32: =タブ取得!$AC$5 -> レジグループのタブリストを取得する。
B33: =ROW()-4 -> 29 | C33: =プリセット廃棄一覧取得!$F$4 -> {hostURI}/presethaiki/select | L33: プリセット廃棄一覧取得 | R33: =プリセット廃棄一覧取得!$F$5 -> POST | T33: =プリセット廃棄一覧取得!$AC$5 -> プリセット廃棄一覧を取得する。

Sheet WebAPI補足事項
A1: IF設計書 | K1: システム名 | S1: カスミ様PDAシステム | AC1: 作成者 | AG1: SANT | AM1: 作成日 | AQ1: 44176
K2: サブシステム名 | S2: POSメニュー | AC2: 更新者 | AM2: 更新日
B4: ■WebAPI補足事項
C5: １）初期値
D6: ・各設計書に指定のない限り、下記を初期値前提とする。
E7: 文字型 | G7: ： | H7: 空白（"sample1":"")
E8: 数値型 | G8: ： | H8: ゼロ（"sample2":0)

Sheet 共通パラメータ
A1: IF設計書 | K1: システム名 | S1: カスミ様PDAシステム | AC1: 作成者 | AG1: SANT | AM1: 作成日 | AQ1: 44130
K2: サブシステム名 | S2: POSメニュー | AC2: 更新者 | AG2: SANT | AM2: 更新日 | AQ2: 44189
B4: URI | Y4: API名(論理)
B5: Method | Y5: 処理概要
B6: 引 数 | Y6: 戻り値
B7: オブジェクト名 | F7: － | M7: 形式 | Q7: JSON形式 | Y7: オブジェクト名 | AC7: － | AJ7: 形式 | AN7: JSON形式
B8: No. | C8: 項目名(○：必須) | I8: 項目ID | N8: 型 | Q8: 概要 | Y8: No. | Z8: 項目名 | AF8: 項目ID | AK8: 型 | AN8: 概要
B9: 1 | C9: 共通パラメータ | I9: comm_param | N9: object | Y9: 1 | Z9: HTTPヘッダー
B10: 2 | C10: ○ | D10: 店舗コード | I10: tencode | N10: 文字 | Y10: 2 | AA10: ステータスコード | AN10: ※下図参照
B11: 3 | C11: ○ | D11: 端末番号 | I11: termcode | N11: 文字 | Y11: 3 | Z11: HTTPボディー | AF11: result_info | AK11: object
B12: 4 | C12: ○ | D12: 従業員コード | I12: usercode | N12: 文字 | Y12: 4 | AA12: 結果コード | AF12: code | AK12: 数値 | AN12: ※1
B13: 5 | C13: ○ | D13: IPアドレス | I13: ipaddress | N13: 文字 | Q13: ドットデシマル形式 | Y13: 5 | AA13: メッセージ | AF13: message | AK13: 文字 | AN13: ※1
B14: 6 | C14: ○ | D14: アプリバージョン | I14: appversion | N14: 文字 | Q14: POSメニューバージョン | Y14: 6
B15: 7 | D15: セッションID | I15: sessionid | N15: 数値 | Q15: ※2 | Y15: 7
B16: 8 | Y16: 8
B17: 9 | Y17: 9
B18: 10 | Y18: 10
B19: 11 | Y19: 11
B20: 12 | Y20: 12
B21: 13 | Y21: 13
B22: 14 | Y22: 14
B23: 15 | Y23: 15
B24: 16 | Y24: 16
B25: 17 | Y25: 17
B26: 18 | Y26: 18
B27: 19 | Y27: 19
... B31: 23 | Y31: 23
B32: ◆備考◆
AG1048576: SANT

Sheet ログイン認証
A1: IF設計書 | K1: システム名 | S1: カスミ様PDAシステム | AC1: 作成者 | AG1: SANT | AM1: 作成日 | AQ1: 44130
K2: サブシステム名 | S2: POSメニュー | AC2: 更新者 | AG2: SANT | AM2: 更新日 | AQ2: 44189
B4: URI | F4: {hostURI}/login | Y4: API名(論理) | AC4: ログイン認証
B5: Method | F5: POST | Y5: 処理概要 | AC5: ログイン画面で認証を行う。
B6: 引 数 | Y6: 戻り値
B7: オブジェクト名 | F7: － | M7: 形式 | Q7: JSON形式 | Y7: オブジェクト名 | AC7: － | AJ7: 形式 | AN7: JSON形式
B8: No. | C8: 項目名(○：必須) | I8: 項目ID | N8: 型 | Q8: 概要 | Y8: No. | Z8: 項目名 | AF8: 項目ID | AK8: 型 | AN8: 概要
B9: 1 | C9: 共通パラメータ | Y9: 1 | Z9: 共通情報
B10: 2 | D10: ※共通パラメータ参照 | Y10: 2 | AA10: ※共通パラメータ参照
B11: 3 | C11: 業務パラメータ | I11: data_param | Y11: 3 | Z11: 業務情報 | AF11: result_data
B12: 4 | C12: ○ | D12: パスワード | I12: password | N12: 文字 | Y12: 4 | AA12: セッションID | AF12: sessionid | AK12: 数値 | AN12: タイムアウト管理する場合に使用
B13: 5 | Y13: 5
B14: 6 | Y14: 6
B15: 7 | Y15: 7
B16: 8 | Y16: 8
B17: 9 | Y17: 9
B18: 10 | Y18: 10
B19: 11 | Y19: 11
B20: 12 | Y20: 12
B21: 13 | Y21: 13
B22: 14 | Y22: 14
B23: 15 | Y23: 15
B24: 16 | Y24: 16
... B31: 23 | Y31: 23
B32: ◆備考◆

Sheet ログアウト
A1: IF設計書 | K1: システム名 | S1: カスミ様PDAシステム | AC1: 作成者 | AG1: SANT | AM1: 作成日 | AQ1: 44130
K2: サブシステム名 | S2: POSメニュー | AC2: 更新者 | AM2: 更新日
B4: URI | F4: {hostURI}/logout | Y4: API名(論理) | AC4: ログアウト
B5: Method | F5: POST | Y5: 処理概要 | AC5: ログアウトを行う。
B6: 引 数 | Y6: 戻り値
B7: オブジェクト名 | F7: － | M7: 形式 | Q7: JSON形式 | Y7: オブジェクト名 | AC7: － | AJ7: 形式 | AN7: JSON形式
B8: No. | C8: 項目名(○：必須) | I8: 項目ID | N8: 型 | Q8: 概要 | Y8: No. | Z8: 項目名 | AF8: 項目ID | AK8: 型 | AN8: 概要
B9: 1 | C9: 共通パラメータ | Y9: 1 | Z9: 共通情報
B10: 2 | D10: ※共通パラメータ参照 | Y10: 2 | AA10: ※共通パラメータ参照
B11: 3 | C11: 業務パラメータ | I11: data_param | Y11: 3 | Z11: 業務情報
B12: 4 | D12: ※無し | Y12: 4 | AA12: ※無し
B13: 5 | Y13: 5
B14: 6 | Y14: 6
B15: 7 | Y15: 7
B16: 8 | Y16: 8
B17: 9 | Y17: 9
B18: 10 | Y18: 10
B19: 11 | Y19: 11
B20: 12 | Y20: 12
B21: 13 | Y21: 13
B22: 14 | Y22: 14
B23: 15 | Y23: 15
B24: 16 | Y24: 16
... B31: 23 | Y31: 23
B32: ◆備考◆

Sheet 売価情報取得
A1: IF設計書 | K1: システム名 | S1: カスミ様PDAシステム | AC1: 作成者 | AG1: SANT | AM1: 作成日 | AQ1: 44130
K2: サブシステム名 | S2: POSメニュー | AC2: 更新者 | AG2: SANT | AM2: 更新日 | AQ2: 44189
B4: URI | F4: {hostURI}/price/select | Y4: API名(論理) | AC4: 売価情報取得
B5: Method | F5: POST | Y5: 処理概要 | AC5: PLUスキャン後の売価情報を取得する
B6: 引 数 | Y6: 戻り値
B7: オブジェクト名 | F7: － | M7: 形式 | Q7: JSON形式 | Y7: オブジェクト名 | AC7: － | AJ7: 形式 | AN7: JSON形式
B8: No. | C8: 項目名(○：必須) | I8: 項目ID | N8: 型 | Q8: 概要 | Y8: No. | Z8: 項目名 | AF8: 項目ID | AK8: 型 | AN8: 概要
B9: 1 | C9: 共通パラメータ | Y9: 1 | Z9: 共通情報
B10: 2 | D10: ※共通パラメータ参照 | Y10: 2 | AA10: ※共通パラメータ参照
B11: 3 | C11: 業務パラメータ | I11: data_param | Y11: 3 | Z11: 業務情報 | AF11: result_data
B12: 4 | C12: ○ | D12: PLUコード | I12: plucode | N12: 文字 | Y12: 4 | AA12: PLUコード | AF12: plucode | AK12: 文字
B13: 5 | C13: ○ | D13: 販売日付 | I13: saledate | N13: 文字 | Q13: ※1 | Y13: 5 | AA13: 商品コード | AF13: itemcode | AK13: 文字
B14: 6 | C14: ○ | D14: 販売時刻 | I14: saletime | N14: 文字 | Q14: ※2 | Y14: 6 | AA14: 部門コード | AF14: bumoncode | AK14: 文字 | AN14: 大分類
B15: 7 | Y15: 7 | AA15: 部門名 | AF15: bumonname | AK15: 文字
B16: 8 | Y16: 8 | AA16: 品群コード | AF16: hinguncode | AK16: 文字 | AN16: 中分類
B17: 9 | Y17: 9 | AA17: 品群名 | AF17: hingunname | AK17: 文字
B18: 10 | Y18: 10 | AA18: 品種コード | AF18: hinshucode | AK18: 文字 | AN18: 小分類
B19: 11 | Y19: 11 | AA19: 品種名 | AF19: hinshuname | AK19: 文字
B20: 12 | Y20: 12 | AA20: 分類コード | AF20: bunruicode | AK20: 文字
B21: 13 | Y21: 13 | AA21: 分類名 | AF21: bunruiname | AK21: 文字
B22: 14 | Y22: 14 | AA22: 商品名 | AF22: itemname | AK22: 文字
B23: 15 | Y23: 15 | AA23: レシート名 | AF23: receiptname | AK23: 文字
B24: 16 | Y24: 16 | AA24: メーカー名 | AF24: makername | AK24: 文字 | AN24: ※SHARPOP同様に「企画単位」を返却下さい。
B25: 17 | Y25: 17 | AA25: 仕入先コード | AF25: purchasingcode | AK25: 文字
B26: 18 | Y26: 18 | AA26: 内容量 | AF26: capacity | AK26: 文字
B27: 19 | Y27: 19 | AA27: ﾕﾆｯﾄ単位(規格単位) | AF27: unit | AK27: 文字 | AN27: 例）本
B28: 20 | Y28: 20 | AA28: ﾕﾆｯﾄ数 | AF28: unitnumber | AK28: 文字
B29: 21 | Y29: 21 | AA29: 保存単位 | AF29: storageunit | AK29: 文字
B30: 22 | Y30: 22 | AA30: 賞味期限単位 | AF30: sell​​byunit | AK30: 文字
B31: 23 | Y31: 23 | AA31: 発注入数 | AF31: orderquantity | AK31: 文字
B32: 24 | Y32: 24 | AA32: 発注単位 | AF32: orderunit | AK32: 文字
B33: 25 | Y33: 25 | AA33: 棚番 | AF33: shelfno | AK33: 文字
B34: 26 | Y34: 26 | AA34: 企画コード | AF34: planningcode | AK34: 文字
B35: 27 | Y35: 27 | AA35: 企画名 | AF35: planningname | AK35: 文字
B36: 28 | Y36: 28 | AA36: 特売開始日 | AF36: salestartdate | AK36: 文字 | AN36: yyyymmdd形式
B37: 29 | Y37: 29 | AA37: 特売開始時刻 | AF37: salestarttime | AK37: 文字 | AN37: hhmmss形式
B38: 28 | Y38: 28 | AA38: 特売終了日 | AF38: saleenddate | AK38: 文字 | AN38: yyyymmdd形式
B39: 29 | Y39: 29 | AA39: 特売終了時刻 | AF39: saleendtime | AK39: 文字 | AN39: hhmmss形式
B40: 30 | Y40: 30 | AA40: 現在売価(税抜) | AF40: currentprice1 | AK40: 文字 | AN40: カテゴリ割引を加味した現在売価を返却 ※2
B41: 31 | Y41: 31 | AA41: 現在売価(税込) | AF41: currentpriceintax1 | AK41: 文字 | AN41: 〃
...

Sheet (補足)現在売価仕様
A1: 「現在売価」編集仕様
B3: 編集先 | D3: マスタ条件
B4: 画面 | C4: 項目 | D4: カテゴリ値引なし | E4: カテゴリ値引 | F4: 特売設定 | G4: 特売設定＋カテゴリ値引 | H4: 緊急売価変更 | I4: 緊急売価変更＋カテゴリ値引 | J4: 特売設定＋緊急売価変更 | K4: 特売設定＋カテゴリ値引＋緊急売価変更
B5: スキャンチェック | C5: 売価入力方式 | D5: 「一般売価」
C6: 現在売価 | D6: 定番売価 | E6: 定番売価－カテゴリ値引 | F6: 特売売価 | G6: 特売－カテゴリ値引 | H6: 緊急売価 | I6: 緊急売価－カテゴリ値引 | J6: 緊急売価 | K6: 緊急売価－カテゴリ値引
B7: １７８売価変更 | C7: 売価入力方式 | D7: 「一般売価」
C8: 現在売価 | D8: 定番売価 | E8: 定番売価－カテゴリ値引 | F8: 特売売価 | G8: 特売－カテゴリ値引 | H8: 緊急売価 | I8: 緊急売価－カテゴリ値引 | J8: 緊急売価 | K8: 緊急売価－カテゴリ値引
B9: 緊急売価変更 | C9: 売価入力方式 | D9: 「一般売価」
C10: 現在売価 | D10: 定番売価 | E10: 定番売価－カテゴリ値引 | F10: 特売売価 | G10: 特売－カテゴリ値引 | H10: 緊急売価 | I10: 緊急売価－カテゴリ値引 | J10: 緊急売価 | K10: 緊急売価－カテゴリ値引
B11: 単品特売設定 | C11: 現在売価 | D11: 「現在売価」なし
B12: 単品速報 | C12: 現在売価 | D12: 定番売価 | E12: 定番売価－カテゴリ値引 | F12: 特売売価 | G12: 特売－カテゴリ値引 | H12: 緊急売価 | I12: 緊急売価－カテゴリ値引 | J12: 緊急売価 | K12: 緊急売価－カテゴリ値引
B13: ＰＯＰ印刷 | C13: 印字売価 | D13: 定番売価 | E13: 定番売価－カテゴリ値引 | F13: 特売売価 | G13: 特売－カテゴリ値引 | H13: 緊急売価 | I13: 緊急売価－カテゴリ値引 | J13: 緊急売価 | K13: 緊急売価－カテゴリ値引
C14: 印字売価補足 | D14: 「通常」 | E14: 「通常」 | F14: 「特売」 | G14: 「特売」 | H14: 「緊急」 | I14: 「緊急」 | J14: 「緊急」 | K14: 「緊急」
B15: 廃棄入力 | C15: 売価入力方式 | D15: 「一般売価」
C16: 現在売価 | D16: 定番売価 | E16: 定番売価－カテゴリ値引 | F16: 特売売価 | G16: 特売－カテゴリ値引 | H16: 緊急売価 | I16: 緊急売価－カテゴリ値引 | J16: 緊急売価 | K16: 緊急売価－カテゴリ値引
B17: まとめ値引ラベル発行 | C17: 現在売価 | D17: 定番売価 | E17: 定番売価 | F17: 特売金額 | G17: 特売金額 | H17: 緊急売価 | I17: 緊急売価－カテゴリ値引 | J17: 緊急売価 | K17: 緊急売価
B18: プリセット売変 | C18: 現在売価
B19: プリセット廃棄 | C19: 現在売価
A22: プリセット売変
B23: ミックスマッチ設定時に現在売価金額の前に「Ｍ」表示
B24: ※ミックスマッチ設定解除を行っても当日は「Ｍ」が消えないが。翌日には消える。

Sheet 定番売価更新
A1: IF設計書 | K1: システム名 | S1: カスミ様PDAシステム | AC1: 作成者 | AG1: SANT | AM1: 作成日 | AQ1: 44130
K2: サブシステム名 | S2: POSメニュー | AC2: 更新者 | AG2: SANT | AM2: 更新日 | AQ2: 44189
B4: URI | F4: {hostURI}/pricechange/update | Y4: API名(論理) | AC4: 定番売価更新
B5: Method | F5: POST | Y5: 処理概要 | AC5: 定番売価の変更を行う。
B6: 引 数 | Y6: 戻り値
B7: オブジェクト名 | F7: － | M7: 形式 | Q7: JSON形式 | Y7: オブジェクト名 | AC7: － | AJ7: 形式 | AN7: JSON形式
B8: No. | C8: 項目名(○：必須) | I8: 項目ID | N8: 型 | Q8: 概要 | Y8: No. | Z8: 項目名 | AF8: 項目ID | AK8: 型 | AN8: 概要
B9: 1 | C9: 共通パラメータ | Y9: 1 | Z9: 共通情報
B10: 2 | D10: ※共通パラメータ参照 | Y10: 2 | AA10: ※共通パラメータ参照
B11: 3 | C11: 業務パラメータ | I11: data_param | Y11: 3
B12: 4 | C12: ○ | D12: PLUコード | I12: plucode | N12: 文字 | Q12: APIから取得したPLUコードをセット | Y12: 4
B13: 5 | C13: ○ | D13: 定番売価(税抜) | I13: classicprice | N13: 数値 | Y13: 5
B14: 6 | Y14: 6
B15: 7 | Y15: 7
B16: 8 | Y16: 8
B17: 9 | Y17: 9
B18: 10 | Y18: 10
B19: 11 | Y19: 11
B20: 12 | Y20: 12
B21: 13 | Y21: 13
B22: 14 | Y22: 14
B23: 15 | Y23: 15
B24: 16 | Y24: 16
B25: 17 | Y25: 17
... B31: 23 | Y31: 23
B32: ◆備考◆

Sheet 特売区分取得
A1: IF設計書 | K1: システム名 | S1: カスミ様PDAシステム | AC1: 作成者 | AG1: SANT | AM1: 作成日 | AQ1: 44130
K2: サブシステム名 | S2: POSメニュー | AC2: 更新者 | AM2: 更新日
B4: URI | Y4: API名(論理) | AC4: 特売区分取得
B5: Method | Y5: 処理概要 | AC5: 特売区分のリストを取得する。
B6: 引 数 | Y6: 戻り値
B7: オブジェクト名 | F7: － | M7: 形式 | Q7: JSON形式 | Y7: オブジェクト名 | AC7: － | AJ7: 形式 | AN7: JSON形式
B8: No. | C8: 項目名(○：必須) | I8: 項目ID | N8: 型 | Q8: 概要 | Y8: No. | Z8: 項目名 | AF8: 項目ID | AK8: 型 | AN8: 概要
B9: 1 | Y9: 1
B10: 2 | Y10: 2
B11: 3 | I11: data_param | Y11: 3
B12: 4 | Y12: 4
B13: 5 | Y13: 5
B14: 6 | Y14: 6
B15: 7 | Y15: 7
B16: 8 | Y16: 8
B17: 9 | Y17: 9
B18: 10 | Y18: 10
B19: 11 | Y19: 11
B20: 12 | Y20: 12
B21: 13 | Y21: 13
B22: 14 | W22: , | Y22: 14
B23: 15 | Y23: 15
B24: 16 | Y24: 16
B25: 17 | Y25: 17
B26: 18 | Y26: 18
B27: 19 | Y27: 19
B28: 20 | Y28: 20
B29: 21 | Y29: 21
B30: 22 | Y30: 22
B31: 23 | Y31: 23
B32: ◆備考◆

Sheet 企画区分取得
A1: IF設計書 | K1: システム名 | S1: カスミ様PDAシステム | AC1: 作成者 | AG1: SANT | AM1: 作成日 | AQ1: 44130
K2: サブシステム名 | S2: POSメニュー | AC2: 更新者 | AG2: SANT | AM2: 更新日 | AQ2: 44189
B4: URI | F4: {hostURI}/plan/select | Y4: API名(論理) | AC4: 企画区分取得
B5: Method | F5: POST | Y5: 処理概要 | AC5: 企画区分のリストを取得する。
B6: 引 数 | Y6: 戻り値
B7: オブジェクト名 | F7: － | M7: 形式 | Q7: JSON形式 | Y7: オブジェクト名 | AC7: － | AJ7: 形式 | AN7: JSON形式
B8: No. | C8: 項目名(○：必須) | I8: 項目ID | N8: 型 | Q8: 概要 | Y8: No. | Z8: 項目名 | AF8: 項目ID | AK8: 型 | AN8: 概要
B9: 1 | C9: 共通パラメータ | Y9: 1 | Z9: 共通情報
B10: 2 | D10: ※共通パラメータ参照 | Y10: 2 | AA10: ※共通パラメータ参照
B11: 3 | C11: 業務パラメータ | I11: data_param | Y11: 3 | Z11: 業務情報(配列) | AF11: result_list | AN11: ソート順：※1
B12: 4 | C12: 〇 | D12: PLUコード | I12: plucode | N12: 文字 | Q12: APIから取得したPLUコードをセット | Y12: 4 | AA12: 企画コード | AF12: plancode | AK12: 文字
B13: 5 | Y13: 5 | AA13: 企画名 | AF13: planname | AK13: 文字
B14: 6 | Y14: 6 | AA14: 企画開始日付 | AF14: planstartdate | AK14: 文字 | AN14: yyyymmdd形式
B15: 7 | Y15: 7 | AA15: 企画開始時刻 | AF15: planstarttime | AK15: 文字 | AN15: hhmmss形式
B16: 8 | Y16: 8 | AA16: 企画開始日付 | AF16: planenddate | AK16: 文字 | AN16: yyyymmdd形式
B17: 9 | Y17: 9 | AA17: 企画開始時刻 | AF17: planendtime | AK17: 文字 | AN17: hhmmss形式
B18: 10 | Y18: 10
B19: 11 | Y19: 11
B20: 12 | Y20: 12
B21: 13 | Y21: 13
B22: 14 | Y22: 14
B23: 15 | Y23: 15
B24: 16 | Y24: 16
B25: 17 | Y25: 17
B26: 18 | Y26: 18
B27: 19 | Y27: 19
B28: 20 | Y28: 20
B29: 21 | Y29: 21
... B31: 23 | Y31: 23
B32: ◆備考◆

Sheet 単品特売取得
A1: IF設計書 | K1: システム名 | S1: カスミ様PDAシステム | AC1: 作成者 | AG1: SANT | AM1: 作成日 | AQ1: 44130
K2: サブシステム名 | S2: POSメニュー | AC2: 更新者 | AG2: SANT | AM2: 更新日 | AQ2: 44189
B4: URI | F4: {hostURI}/Itemsale/select | Y4: API名(論理) | AC4: 単品特売取得
B5: Method | F5: POST | Y5: 処理概要 | AC5: 単品特売一覧を取得する。
B6: 引 数 | Y6: 戻り値
B7: オブジェクト名 | F7: － | M7: 形式 | Q7: JSON形式 | Y7: オブジェクト名 | AC7: － | AJ7: 形式 | AN7: JSON形式
B8: No. | C8: 項目名(○：必須) | I8: 項目ID | N8: 型 | Q8: 概要 | Y8: No. | Z8: 項目名 | AF8: 項目ID | AK8: 型 | AN8: 概要
B9: 1 | C9: 共通パラメータ | Y9: 1 | Z9: 共通情報
B10: 2 | D10: ※共通パラメータ参照 | Y10: 2 | AA10: ※共通パラメータ参照
B11: 3 | C11: 業務パラメータ | I11: data_param | Y11: 3 | Z11: 業務情報 | AF11: result_data
B12: 4 | C12: ○ | D12: PLUコード | I12: plucode | N12: 文字 | Q12: APIから取得したPLUコードをセット | Y12: 4 | AA12: PLUコード | AF12: plucode | AK12: 文字
B13: 5 | Y13: 5 | AA13: 商品コード | AF13: itemcode | AK13: 文字
B14: 6 | Y14: 6 | AA14: 商品名 | AF14: itemname | AK14: 文字
B15: 7 | Y15: 7 | AA15: レシート名 | AF15: receiptname | AK15: 文字
B16: 8 | Y16: 8 | AA16: 定番売価(税抜) | AF16: classicprice | AK16: 文字
B17: 9 | Y17: 9 | AA17: 店舗開始時刻 | AF17: storestarttime | AK17: 文字 | AN17: hhmmss形式
B18: 10 | Y18: 10 | AA18: 店舗終了時刻 | AF18: storeendtime | AK18: 文字 | AN18: hhmmss形式
B19: 11 | Y19: 11 | Z19: 業務情報(配列) | AF19: result_list | AN19: ソート順：※2
B20: 12 | Y20: 12 | AA20: 企画コード | AF20: plancode | AK20: 文字
B21: 13 | Y21: 13 | AA21: 企画名 | AF21: planname | AK21: 文字
B22: 14 | Y22: 14 | AA22: 特売区分 | AF22: saleclass | AK22: 数値 | AN22: 1:単品特売(円) 2:単品特売(割引)
B23: 15 | Y23: 15 | AA23: 有効フラグ | AF23: effectflg | AK23: 数値 | AN23: 0：無効 1：有効
B24: 16 | Y24: 16 | AA24: 開始日付 | AF24: startdate | AK24: 文字 | AN24: yyyymmdd形式
B25: 17 | Y25: 17 | AA25: 開始時刻 | AF25: starttime | AK25: 文字 | AN25: hhmmss形式
B26: 18 | Y26: 18 | AA26: 終了日付 | AF26: enddate | AK26: 文字 | AN26: yyyymmdd形式
B27: 19 | Y27: 19 | AA27: 終了時刻 | AF27: endtime | AK27: 文字 | AN27: hhmmss形式
B28: 20 | Y28: 20 | AA28: 特売売価(税抜) | AF28: saleprice | AK28: 文字 | AN28: ※1
B29: 21 | Y29: 21 | AA29: 特売割引率 | AF29: salerate | AK29: 数値 | AN29: ※1
B30: 22 | Y30: 22 | AA30: 中断フラグ | AF30: suspensionflg | AK30: 数値 | AN30: 0：通常 1：中断
B31: 23 | Y31: 23 | AA31: タイムフラグ | AF31: timeflg | AK31: 数値 | AN31: 0：通常 1：ﾀｲﾑｾｰﾙ
B32: ◆備考◆

Sheet 単品特売更新
A1: IF設計書 | K1: システム名 | S1: カスミ様PDAシステム | AC1: 作成者 | AG1: SANT | AM1: 作成日 | AQ1: 44130
K2: サブシステム名 | S2: POSメニュー | AC2: 更新者 | AG2: SANT | AM2: 更新日 | AQ2: 44189
B4: URI | F4: {hostURI}/Itemsale/update | Y4: API名(論理) | AC4: 単品特売更新
B5: Method | F5: POST | Y5: 処理概要 | AC5: 単品特売設定の新規登録・更新を行う。
B6: 引 数 | Y6: 戻り値
B7: オブジェクト名 | F7: － | M7: 形式 | Q7: JSON形式 | Y7: オブジェクト名 | AC7: － | AJ7: 形式 | AN7: JSON形式
B8: No. | C8: 項目名(○：必須) | I8: 項目ID | N8: 型 | Q8: 概要 | Y8: No. | Z8: 項目名 | AF8: 項目ID | AK8: 型 | AN8: 概要
B9: 1 | C9: 共通パラメータ | Y9: 1 | Z9: 共通情報
B10: 2 | D10: ※共通パラメータ参照 | Y10: 2 | AA10: ※共通パラメータ参照
B11: 3 | C11: 業務パラメータ | I11: data_param | Y11: 3
B12: 4 | C12: ○ | D12: PLUコード | I12: plucode | N12: 文字 | Q12: APIから取得したPLUコードをセット | Y12: 4
B13: 5 | C13: ○ | D13: 特売区分 | I13: saleclass | N13: 数値 | Q13: 1:単品特売(円) 2:単品特売(割引) | Y13: 5
B14: 6 | C14: ○ | D14: 企画コード | I14: plancode | N14: 文字 | Y14: 6
B15: 7 | C15: ○ | D15: 開始日付 | I15: startdate | N15: 文字 | Q15: yyyymmdd形式 | Y15: 7
B16: 8 | C16: ○ | D16: 開始時刻 | I16: starttime | N16: 文字 | Q16: hhmmss形式 | Y16: 8
B17: 9 | C17: ○ | D17: 終了日付 | I17: enddate | N17: 文字 | Q17: yyyymmdd形式 | Y17: 9
B18: 10 | C18: ○ | D18: 終了時刻 | I18: endtime | N18: 文字 | Q18: hhmmss形式 | Y18: 10
B19: 11 | C19: ○ | D19: 中断フラグ | I19: suspensionflg | N19: 数値 | Q19: 0：通常 1：中断 | Y19: 11
B20: 12 | C20: ○ | D20: タイムフラグ | I20: timeflg | N20: 数値 | Q20: 0：通常 1：ﾀｲﾑｾｰﾙ | Y20: 12
B21: 13 | D21: 特売売価(税抜) | I21: saleprice | N21: 数値 | Q21: ※1 | Y21: 13
B22: 14 | D22: 特売割引率 | I22: salerate | N22: 数値 | Q22: ※2 | Y22: 14
B23: 15 | Y23: 15
B24: 16 | Y24: 16
B25: 17 | Y25: 17
B26: 18 | Y26: 18
B27: 19 | Y27: 19
B28: 20 | Y28: 20
B29: 21 | Y29: 21
B30: 22 | Y30: 22
B31: 23 | Y31: 23
B32: ◆備考◆

Sheet 緊急売価更新
A1: IF設計書 | K1: システム名 | S1: カスミ様PDAシステム | AC1: 作成者 | AG1: SANT | AM1: 作成日 | AQ1: 44130
K2: サブシステム名 | S2: POSメニュー | AC2: 更新者 | AG2: SANT | AM2: 更新日 | AQ2: 44189
B4: URI | F4: {hostURI}/emprice/update | Y4: API名(論理) | AC4: 緊急売価更新
B5: Method | F5: POST | Y5: 処理概要 | AC5: 緊急売価の変更を行う。
B6: 引 数 | Y6: 戻り値
B7: オブジェクト名 | F7: － | M7: 形式 | Q7: JSON形式 | Y7: オブジェクト名 | AC7: － | AJ7: 形式 | AN7: JSON形式
B8: No. | C8: 項目名(○：必須) | I8: 項目ID | N8: 型 | Q8: 概要 | Y8: No. | Z8: 項目名 | AF8: 項目ID | AK8: 型 | AN8: 概要
B9: 1 | C9: 共通パラメータ | Y9: 1 | Z9: 共通情報
B10: 2 | D10: ※共通パラメータ参照 | Y10: 2 | AA10: ※共通パラメータ参照
B11: 3 | C11: 業務パラメータ | I11: data_param | Y11: 3
B12: 4 | C12: ○ | D12: PLUコード | I12: plucode | N12: 文字 | Q12: APIから取得したPLUコードをセット | Y12: 4
B13: 5 | C13: ○ | D13: 緊急売価(税抜) | I13: emerprice | N13: 数値 | Y13: 5
B14: 6 | C14: ○ | D14: 中断フラグ | I14: suspensionflg | N14: 数値 | Q14: 0：通常 1：中断 | Y14: 6
B15: 7 | Y15: 7
B16: 8 | Y16: 8
B17: 9 | Y17: 9
B18: 10 | Y18: 10
B19: 11 | Y19: 11
B20: 12 | Y20: 12
B21: 13 | Y21: 13
B22: 14 | Y22: 14
B23: 15 | Y23: 15
B24: 16 | Y24: 16
B25: 17 | Y25: 17
B26: 18 | Y26: 18
... B31: 23 | Y31: 23
B32: ◆備考◆

Sheet グループ取得
A1: IF設計書 | K1: システム名 | S1: カスミ様PDAシステム | AC1: 作成者 | AG1: SANT | AM1: 作成日 | AQ1: 44130
K2: サブシステム名 | S2: POSメニュー | AC2: 更新者 | AM2: 更新日
B4: URI | F4: {hostURI}/group/select | Y4: API名(論理) | AC4: グループ取得
B5: Method | F5: POST | Y5: 処理概要 | AC5: グループのリストを取得する。
B6: 引 数 | Y6: 戻り値
B7: オブジェクト名 | F7: － | M7: 形式 | Q7: JSON形式 | Y7: オブジェクト名 | AC7: － | AJ7: 形式 | AN7: JSON形式
B8: No. | C8: 項目名(○：必須) | I8: 項目ID | N8: 型 | Q8: 概要 | Y8: No. | Z8: 項目名 | AF8: 項目ID | AK8: 型 | AN8: 概要
B9: 1 | C9: 共通パラメータ | Y9: 1 | Z9: 共通情報
B10: 2 | D10: ※共通パラメータ参照 | Y10: 2 | AA10: ※共通パラメータ参照
B11: 3 | C11: 業務パラメータ | I11: data_param | Y11: 3 | Z11: 業務情報(配列) | AF11: result_list | AN11: ソート順：グループコード(昇順)
B12: 4 | D12: ※無し | Y12: 4 | AA12: グループコード | AF12: groupcode | AK12: 文字
B13: 5 | Y13: 5 | AA13: グループ名 | AF13: groupname | AK13: 文字
B14: 6 | Y14: 6
B15: 7 | Y15: 7
B16: 8 | Y16: 8
B17: 9 | Y17: 9
B18: 10 | Y18: 10
B19: 11 | Y19: 11
B20: 12 | Y20: 12
B21: 13 | Y21: 13
B22: 14 | Y22: 14
B23: 15 | Y23: 15
B24: 16 | Y24: 16
B25: 17 | Y25: 17
... B31: 23 | Y31: 23
B32: ◆備考◆

Sheet プリセット商品取得
A1: IF設計書 | K1: システム名 | S1: カスミ様PDAシステム | AC1: 作成者 | AG1: SANT | AM1: 作成日 | AQ1: 44130
K2: サブシステム名 | S2: POSメニュー | AC2: 更新者 | AG2: SANT | AM2: 更新日 | AQ2: 44189
B4: URI | F4: {hostURI}/preset/select | Y4: API名(論理) | AC4: プリセット商品取得
B5: Method | F5: POST | Y5: 処理概要 | AC5: プリセット商品一覧を取得する。
B6: 引 数 | Y6: 戻り値
B7: オブジェクト名 | F7: － | M7: 形式 | Q7: JSON形式 | Y7: オブジェクト名 | AC7: － | AJ7: 形式 | AN7: JSON形式
B8: No. | C8: 項目名(○：必須) | I8: 項目ID | N8: 型 | Q8: 概要 | Y8: No. | Z8: 項目名 | AF8: 項目ID | AK8: 型 | AN8: 概要
B9: 1 | C9: 共通パラメータ | Y9: 1 | Z9: 共通情報
B10: 2 | D10: ※共通パラメータ参照 | Y10: 2 | AA10: ※共通パラメータ参照
B11: 3 | C11: 業務パラメータ | I11: data_param | Y11: 3 | Z11: 業務情報(配列) | AF11: result_list | AN11: ソート順：PLUコードの昇順
B12: 4 | C12: ○ | D12: グループコード | I12: groupcode | N12: 文字 | Y12: 4 | AA12: PLUコード | AF12: plucode | AK12: 文字
B13: 5 | Y13: 5 | AA13: 商品名 | AF13: itemname | AK13: 文字
B14: 6 | Y14: 6 | AA14: 現在売価(税抜) | AF14: currentprice | AK14: 文字 | AN14: ※「(補足)現在売価仕様ｼｰﾄ」を参照
B15: 7 | Y15: 7 | AA15: ＭＭフラグ | AF15: mmflg | AK15: 数値 | AN15: 0：無 1：有 ※1
B16: 8 | Y16: 8
B17: 9 | Y17: 9
B18: 10 | Y18: 10
B19: 11 | Y19: 11
B20: 12 | Y20: 12
B21: 13 | Y21: 13
B22: 14 | Y22: 14
B23: 15 | Y23: 15
B24: 16 | Y24: 16
B25: 17 | Y25: 17
B26: 18 | Y26: 18
B27: 19 | Y27: 19
... B31: 23 | Y31: 23
B32: ◆備考◆

Sheet 部門速報取得
A1: IF設計書 | K1: システム名 | S1: カスミ様PDAシステム | AC1: 作成者 | AG1: SANT | AM1: 作成日 | AQ1: 44130
K2: サブシステム名 | S2: POSメニュー | AC2: 更新者 | AG2: SANT | AM2: 更新日 | AQ2: 44189
B4: URI | F4: {hostURI}/flash/bumon/select | Y4: API名(論理) | AC4: 部門速報取得
B5: Method | F5: POST | Y5: 処理概要 | AC5: 部門速報を取得する。
B6: 引 数 | Y6: 戻り値
B7: オブジェクト名 | F7: － | M7: 形式 | Q7: JSON形式 | Y7: オブジェクト名 | AC7: － | AJ7: 形式 | AN7: JSON形式
B8: No. | C8: 項目名(○：必須) | I8: 項目ID | N8: 型 | Q8: 概要 | Y8: No. | Z8: 項目名 | AF8: 項目ID | AK8: 型 | AN8: 概要
B9: 1 | C9: 共通パラメータ | Y9: 1 | Z9: 共通情報
B10: 2 | D10: ※共通パラメータ参照 | Y10: 2 | AA10: ※共通パラメータ参照
B11: 3 | C11: 業務パラメータ | I11: data_param | Y11: 3 | Z11: 業務情報 | AF11: result_data
B12: 4 | C12: ○ | D12: 検索日付 | I12: searchdate | N12: 文字 | Q12: yyyymmdd形式 | Y12: 4 | AA12: 売上金額(税抜) | AF12: salesamount | AK12: 数値 | AN12: 対象期間の店舗合計
B13: 5 | Y13: 5 | AA13: 点数 | AF13: score | AK13: 数値 | AN13: 〃
B14: 6 | Y14: 6 | AA14: 予算額 | AF14: budgetamount | AK14: 数値 | AN14: 〃
B15: 7 | Y15: 7 | AA15: 来店客数 | AF15: customers | AK15: 数値 | AN15: 対象期間の店舗来店客数計
B16: 8 | Y16: 8 | Z16: 業務情報(配列) | AF16: result_list | AN16: ソート順：部門コードの昇順
B17: 9 | Y17: 9 | AA17: 部門コード | AF17: bumoncode | AK17: 文字 | AN17: ※1
B18: 10 | Y18: 10 | AA18: 部門名 | AF18: bumonname | AK18: 文字
B19: 11 | Y19: 11 | AA19: 売上金額(税抜) | AF19: salesamount | AK19: 数値
B20: 12 | Y20: 12 | AA20: 点数 | AF20: score | AK20: 数値
B21: 13 | Y21: 13 | AA21: 客数 | AF21: customers | AK21: 数値
B22: 14 | Y22: 14
B23: 15 | Y23: 15
B24: 16 | Y24: 16
B25: 17 | Y25: 17
B26: 18 | Y26: 18
B27: 19 | Y27: 19
B28: 20 | Y28: 20
B29: 21 | Y29: 21
B30: 22 | Y30: 22
B31: 23 | Y31: 23
B32: 24 | Y32: 24
B33: ◆備考◆

Sheet 品群速報取得
A1: IF設計書 | K1: システム名 | S1: カスミ様PDAシステム | AC1: 作成者 | AG1: SANT | AM1: 作成日 | AQ1: 44130
K2: サブシステム名 | S2: POSメニュー | AC2: 更新者 | AG2: SANT | AM2: 更新日 | AQ2: 44189
B4: URI | F4: {hostURI}/flash/hingun/select | Y4: API名(論理) | AC4: 品群速報取得
B5: Method | F5: POST | Y5: 処理概要 | AC5: 品群速報を取得する。
B6: 引 数 | Y6: 戻り値
B7: オブジェクト名 | F7: － | M7: 形式 | Q7: JSON形式 | Y7: オブジェクト名 | AC7: － | AJ7: 形式 | AN7: JSON形式
B8: No. | C8: 項目名(○：必須) | I8: 項目ID | N8: 型 | Q8: 概要 | Y8: No. | Z8: 項目名 | AF8: 項目ID | AK8: 型 | AN8: 概要
B9: 1 | C9: 共通パラメータ | Y9: 1 | Z9: 共通情報
B10: 2 | D10: ※共通パラメータ参照 | Y10: 2 | AA10: ※共通パラメータ参照
B11: 3 | C11: 業務パラメータ | I11: data_param | Y11: 3 | Z11: 業務情報 | AF11: result_data
B12: 4 | C12: ○ | D12: 部門コード | I12: bumoncode | N12: 文字 | Y12: 4 | AA12: 売上金額(税抜) | AF12: salesamount | AK12: 数値 | AN12: 選択部門の対象期間合計
B13: 5 | C13: ○ | D13: 検索日付 | I13: searchdate | N13: 文字 | Q13: yyyymmdd形式 | Y13: 5 | AA13: 点数 | AF13: score | AK13: 数値 | AN13: 〃
B14: 6 | Y14: 6 | AA14: 予算額 | AF14: budgetamount | AK14: 数値 | AN14: 〃
B15: 7 | Y15: 7 | AA15: 客数 | AF15: customers | AK15: 数値 | AN15: 〃
B16: 8 | Y16: 8 | AA16: 来店客数 | AF16: visitcustomers | AK16: 数値 | AN16: 対象期間の店舗来店客数計
B17: 9 | Y17: 9 | Z17: 業務情報(配列) | AF17: result_list | AN17: ソート順：品群コードの昇順
B18: 10 | Y18: 10 | AA18: 品群コード | AF18: hinguncode | AK18: 文字 | AN18: ※1
B19: 11 | Y19: 11 | AA19: 品群名 | AF19: hingunname | AK19: 文字
B20: 12 | Y20: 12 | AA20: 売上金額(税抜) | AF20: salesamount | AK20: 数値
B21: 13 | Y21: 13 | AA21: 点数 | AF21: score | AK21: 数値
B22: 14 | Y22: 14 | AA22: 客数 | AF22: customers | AK22: 数値
B23: 15 | Y23: 15
B24: 16 | Y24: 16
B25: 14 | Y25: 14
B26: 15 | Y26: 15
B27: 16 | Y27: 16
B28: 19 | Y28: 19
B29: 20 | Y29: 20
B30: 21 | Y30: 21
B31: 22 | Y31: 22
B32: 23 | Y32: 23
B33: ◆備考◆

Sheet 品種速報取得
A1: IF設計書 | K1: システム名 | S1: カスミ様PDAシステム | AC1: 作成者 | AG1: SANT | AM1: 作成日 | AQ1: 44130
K2: サブシステム名 | S2: POSメニュー | AC2: 更新者 | AG2: SANT | AM2: 更新日 | AQ2: 44189
B4: URI | F4: {hostURI}/flash/hinshu/select | Y4: API名(論理) | AC4: 品種速報取得
B5: Method | F5: POST | Y5: 処理概要 | AC5: 品種速報を取得する。
B6: 引 数 | Y6: 戻り値
B7: オブジェクト名 | F7: － | M7: 形式 | Q7: JSON形式 | Y7: オブジェクト名 | AC7: － | AJ7: 形式 | AN7: JSON形式
B8: No. | C8: 項目名(○：必須) | I8: 項目ID | N8: 型 | Q8: 概要 | Y8: No. | Z8: 項目名 | AF8: 項目ID | AK8: 型 | AN8: 概要
B9: 1 | C9: 共通パラメータ | Y9: 1 | Z9: 共通情報
B10: 2 | D10: ※共通パラメータ参照 | Y10: 2 | AA10: ※共通パラメータ参照
B11: 3 | C11: 業務パラメータ | I11: data_param | Y11: 3 | Z11: 業務情報 | AF11: result_data
B12: 4 | C12: ○ | D12: 部門コード | I12: bumoncode | N12: 文字 | Y12: 4 | AA12: 売上金額(税抜) | AF12: salesamount | AK12: 数値 | AN12: 選択品群の対象期間合計
B13: 5 | C13: ○ | D13: 品群コード | I13: hinguncode | N13: 文字 | Y13: 5 | AA13: 点数 | AF13: score | AK13: 数値 | AN13: 〃
B14: 6 | C14: ○ | D14: 検索日付 | I14: searchdate | N14: 文字 | Q14: yyyymmdd形式 | Y14: 6 | AA14: 予算額 | AF14: budgetamount | AK14: 数値 | AN14: ※固定値ゼロ
B15: 7 | Y15: 7 | AA15: 客数 | AF15: customers | AK15: 数値 | AN15: 〃
B16: 8 | Y16: 8 | AA16: 来店客数 | AF16: visitcustomers | AK16: 数値 | AN16: 対象期間の店舗来店客数計
B17: 9 | Y17: 9 | Z17: 業務情報(配列) | AF17: result_list | AN17: ソート順：品種コードの昇順
B18: 10 | Y18: 10 | AA18: 品種コード | AF18: hinshucode | AK18: 文字 | AN18: ※1
B19: 11 | Y19: 11 | AA19: 品種名 | AF19: hinshuname | AK19: 文字
B20: 12 | Y20: 12 | AA20: 売上金額(税抜) | AF20: salesamount | AK20: 数値
B21: 13 | Y21: 13 | AA21: 点数 | AF21: score | AK21: 数値
B22: 14 | Y22: 14 | AA22: 客数 | AF22: customers | AK22: 数値
B23: 15 | Y23: 15
B24: 16 | Y24: 16
B25: 17 | Y25: 17
B26: 18 | Y26: 18
B27: 19 | Y27: 19
B28: 20 | Y28: 20
B29: 21 | Y29: 21
B30: 22 | Y30: 22
B31: 23 | Y31: 23
B32: ◆備考◆

Sheet 分類速報取得
A1: IF設計書 | K1: システム名 | S1: カスミ様PDAシステム | AC1: 作成者 | AG1: SANT | AM1: 作成日 | AQ1: 44130
K2: サブシステム名 | S2: POSメニュー | AC2: 更新者 | AG2: SANT | AM2: 更新日 | AQ2: 44189
B4: URI | F4: {hostURI}/flash/bunrui/select | Y4: API名(論理) | AC4: 分類速報取得
B5: Method | F5: POST | Y5: 処理概要 | AC5: 分類速報を取得する。
B6: 引 数 | Y6: 戻り値
B7: オブジェクト名 | F7: － | M7: 形式 | Q7: JSON形式 | Y7: オブジェクト名 | AC7: － | AJ7: 形式 | AN7: JSON形式
B8: No. | C8: 項目名(○：必須) | I8: 項目ID | N8: 型 | Q8: 概要 | Y8: No. | Z8: 項目名 | AF8: 項目ID | AK8: 型 | AN8: 概要
B9: 1 | C9: 共通パラメータ | Y9: 1 | Z9: 共通情報
B10: 2 | D10: ※共通パラメータ参照 | Y10: 2 | AA10: ※共通パラメータ参照
B11: 3 | C11: 業務パラメータ | I11: data_param | Y11: 3 | Z11: 業務情報 | AF11: result_data
B12: 4 | C12: ○ | D12: 部門コード | I12: bumoncode | N12: 文字 | Y12: 4 | AA12: 売上金額(税抜) | AF12: salesamount | AK12: 数値 | AN12: 選択品種の対象期間合計
B13: 5 | C13: ○ | D13: 品群コード | I13: hinguncode | N13: 文字 | Y13: 5 | AA13: 点数 | AF13: score | AK13: 数値 | AN13: 〃
B14: 6 | C14: ○ | D14: 品種コード | I14: hinshucode | N14: 文字 | Y14: 6 | AA14: 予算額 | AF14: budgetamount | AK14: 数値 | AN14: ※固定値ゼロ
B15: 7 | C15: ○ | D15: 検索日付 | I15: searchdate | N15: 文字 | Q15: yyyymmdd形式 | Y15: 7 | AA15: 客数 | AF15: customers | AK15: 数値 | AN15: 〃
B16: 8 | Y16: 8 | AA16: 来店客数 | AF16: visitcustomers | AK16: 数値 | AN16: 対象期間の店舗来店客数計
B17: 9 | Y17: 9 | Z17: 業務情報(配列) | AF17: result_list | AN17: ソート順：分類コードの昇順
B18: 10 | Y18: 10 | AA18: 分類コード | AF18: bunruicode | AK18: 文字 | AN18: ※1
B19: 11 | Y19: 11 | AA19: 分類名 | AF19: bunruiname | AK19: 文字
B20: 12 | Y20: 12 | AA20: 売上金額(税抜) | AF20: salesamount | AK20: 数値
B21: 13 | Y21: 13 | AA21: 点数 | AF21: score | AK21: 数値
B22: 14 | Y22: 14 | AA22: 客数 | AF22: customers | AK22: 数値
B23: 15 | Y23: 15
B24: 16 | Y24: 16
B25: 17 | Y25: 17
B26: 18 | Y26: 18
B27: 19 | Y27: 19
B28: 20 | Y28: 20
B29: 21 | Y29: 21
B30: 22 | Y30: 22
B31: 23 | Y31: 23
B32: ◆備考◆

Sheet 単品速報取得
A1: IF設計書 | K1: システム名 | S1: カスミ様PDAシステム | AC1: 作成者 | AG1: SANT | AM1: 作成日 | AQ1: 44130
K2: サブシステム名 | S2: POSメニュー | AC2: 更新者 | AG2: SANT | AM2: 更新日 | AQ2: 44189
B4: URI | F4: {hostURI}/flash/item/select | Y4: API名(論理) | AC4: 単品速報取得
B5: Method | F5: POST | Y5: 処理概要 | AC5: 単品速報を取得する。
B6: 引 数 | Y6: 戻り値
B7: オブジェクト名 | F7: － | M7: 形式 | Q7: JSON形式 | Y7: オブジェクト名 | AC7: － | AJ7: 形式 | AN7: JSON形式
B8: No. | C8: 項目名(○：必須) | I8: 項目ID | N8: 型 | Q8: 概要 | Y8: No. | Z8: 項目名 | AF8: 項目ID | AK8: 型 | AN8: 概要
B9: 1 | C9: 共通パラメータ | Y9: 1 | Z9: 共通情報
B10: 2 | D10: ※共通パラメータ参照 | Y10: 2 | AA10: ※共通パラメータ参照
B11: 3 | C11: 業務パラメータ | I11: data_param | Y11: 3 | Z11: 業務情報 | AF11: result_data
B12: 4 | C12: ○ | D12: 部門コード | I12: bumoncode | N12: 文字 | Y12: 4 | AA12: 売上金額(税抜) | AF12: salesamount | AK12: 数値 | AN12: 選択分類の対象期間合計
B13: 5 | C13: ○ | D13: 品群コード | I13: hinguncode | N13: 文字 | Y13: 5 | AA13: 点数 | AF13: score | AK13: 数値 | AN13: 〃
B14: 6 | C14: ○ | D14: 品種コード | I14: hinshucode | N14: 文字 | Y14: 6 | AA14: 客数 | AF14: customers | AK14: 数値 | AN14: 〃
B15: 7 | C15: ○ | D15: 分類コード | I15: bunruicode | N15: 文字 | Y15: 7 | AA15: 来店客数 | AF15: visitcustomers | AK15: 数値 | AN15: 対象期間の店舗来店客数計
B16: 8 | C16: ○ | D16: 検索日付 | I16: searchdate | N16: 文字 | Q16: yyyymmdd形式 | Y16: 8 | Z16: 業務情報(配列) | AF16: result_list | AN16: ソート順：PLUコードの昇順
B17: 9 | Y17: 9 | AA17: PLUコード | AF17: plucode | AK17: 文字 | AN17: ※1
B18: 10 | Y18: 10 | AA18: 商品名 | AF18: itemname | AK18: 文字
B19: 11 | Y19: 11 | AA19: 売上金額(税抜) | AF19: salesamount | AK19: 数値
B20: 12 | Y20: 12 | AA20: 点数 | AF20: score | AK20: 数値
B21: 13 | Y21: 13 | AA21: 客数 | AF21: customers | AK21: 数値
B22: 14 | Y22: 14
B23: 15 | Y23: 15
B24: 16 | Y24: 16
B25: 17 | Y25: 17
B26: 18 | Y26: 18
B27: 19 | Y27: 19
B28: 20 | Y28: 20
B29: 21 | Y29: 21
B30: 22 | Y30: 22
B31: 23 | Y31: 23
B32: ◆備考◆

Sheet 店舗時間帯速報取得
A1: IF設計書 | K1: システム名 | S1: カスミ様PDAシステム | AC1: 作成者 | AG1: SANT | AM1: 作成日 | AQ1: 44130
K2: サブシステム名 | S2: POSメニュー | AC2: 更新者 | AG2: SANT | AM2: 更新日 | AQ2: 44176
B4: URI | F4: {hostURI}/tmflash/ten/select | Y4: API名(論理) | AC4: 店舗時間帯速報取得
B5: Method | F5: POST | Y5: 処理概要 | AC5: 店舗時間帯速報を取得する。
B6: 引 数 | Y6: 戻り値
B7: オブジェクト名 | F7: － | M7: 形式 | Q7: JSON形式 | Y7: オブジェクト名 | AC7: － | AJ7: 形式 | AN7: JSON形式
B8: No. | C8: 項目名(○：必須) | I8: 項目ID | N8: 型 | Q8: 概要 | Y8: No. | Z8: 項目名 | AF8: 項目ID | AK8: 型 | AN8: 概要
B9: 1 | C9: 共通パラメータ | Y9: 1 | Z9: 共通情報
B10: 2 | D10: ※共通パラメータ参照 | Y10: 2 | AA10: ※共通パラメータ参照
B11: 3 | C11: 業務パラメータ | I11: data_param | Y11: 3 | Z11: 業務情報 | AF11: result_data
B12: 4 | C12: ○ | D12: 検索日付 | I12: searchdate | N12: 文字 | Q12: yyyymmdd形式 | Y12: 4 | AA12: 売上金額(税抜) | AF12: salesamount | AK12: 数値 | AN12: 対象期間の店舗合計
B13: 5 | Y13: 5 | AA13: 点数 | AF13: score | AK13: 数値 | AN13: 〃
B14: 6 | Y14: 6 | AA14: 予算額 | AF14: budgetamount | AK14: 数値 | AN14: 〃
B15: 7 | Y15: 7 | AA15: 来店客数 | AF15: customers | AK15: 数値 | AN15: 対象期間の店舗来店客数計
B16: 8 | Y16: 8 | Z16: 業務情報(配列) | AF16: result_list | AN16: ※1
B17: 9 | Y17: 9 | AA17: 登録時間 | AF17: time | AK17: 文字 | AN17: hhmm形式
B18: 10 | Y18: 10 | AA18: 売上金額(税抜) | AF18: salesamount | AK18: 数値
B19: 11 | Y19: 11 | AA19: 点数 | AF19: score | AK19: 数値
B20: 12 | Y20: 12 | AA20: 客数 | AF20: customers | AK20: 数値
B21: 13 | Y21: 13
B22: 14 | Y22: 14
B23: 15 | Y23: 15
B24: 16 | Y24: 16
B25: 17 | Y25: 17
B26: 18 | Y26: 18
B27: 19 | Y27: 19
B28: 20 | Y28: 20
B29: 21 | Y29: 21
B30: 22 | Y30: 22
B31: 23 | Y31: 23
B32: ◆備考◆

Sheet 部門時間帯速報取得
A1: IF設計書 | K1: システム名 | S1: カスミ様PDAシステム | AC1: 作成者 | AG1: SANT | AM1: 作成日 | AQ1: 44130
K2: サブシステム名 | S2: POSメニュー | AC2: 更新者 | AG2: SANT | AM2: 更新日 | AQ2: 44176
B4: URI | F4: {hostURI}/tmflash/bumon/select | Y4: API名(論理) | AC4: 部門時間帯速報取得
B5: Method | F5: POST | Y5: 処理概要 | AC5: 部門時間帯速報を取得する。
B6: 引 数 | Y6: 戻り値
B7: オブジェクト名 | F7: － | M7: 形式 | Q7: JSON形式 | Y7: オブジェクト名 | AC7: － | AJ7: 形式 | AN7: JSON形式
B8: No. | C8: 項目名(○：必須) | I8: 項目ID | N8: 型 | Q8: 概要 | Y8: No. | Z8: 項目名 | AF8: 項目ID | AK8: 型 | AN8: 概要
B9: 1 | C9: 共通パラメータ | Y9: 1 | Z9: 共通情報
B10: 2 | D10: ※共通パラメータ参照 | Y10: 2 | AA10: ※共通パラメータ参照
B11: 3 | C11: 業務パラメータ | I11: data_param | Y11: 3 | Z11: 業務情報 | AF11: result_data
B12: 4 | C12: ○ | D12: 部門コード | I12: bumoncode | N12: 文字 | Y12: 4 | AA12: 売上金額(税抜) | AF12: salesamount | AK12: 数値 | AN12: 対象期間の部門合計
B13: 5 | C13: ○ | D13: 検索日付 | I13: searchdate | N13: 文字 | Q13: yyyymmdd形式 | Y13: 5 | AA13: 点数 | AF13: score | AK13: 数値 | AN13: 〃
B14: 6 | Y14: 6 | AA14: 予算額 | AF14: budgetamount | AK14: 数値 | AN14: 〃
B15: 7 | Y15: 7 | AA15: 客数 | AF15: customers | AK15: 数値 | AN15: 〃
B16: 8 | Y16: 8 | AA16: 来店客数 | AF16: visitcustomers | AK16: 数値 | AN16: 対象期間の店舗来店客数計
B17: 9 | Y17: 9 | Z17: 業務情報(配列) | AF17: result_list | AN17: ※1
B18: 10 | Y18: 10 | AA18: 登録時間 | AF18: time | AK18: 文字 | AN18: hhmm形式
B19: 11 | Y19: 11 | AA19: 売上金額(税抜) | AF19: salesamount | AK19: 数値
B20: 12 | Y20: 12 | AA20: 点数 | AF20: score | AK20: 数値
B21: 13 | Y21: 13 | AA21: 客数 | AF21: customers | AK21: 数値
B22: 14 | Y22: 14
B23: 15 | Y23: 15
B24: 16 | Y24: 16
B25: 17 | Y25: 17
B26: 18 | Y26: 18
B27: 19 | Y27: 19
B28: 20 | Y28: 20
B29: 21 | Y29: 21
B30: 22 | Y30: 22
B31: 23 | Y31: 23
B32: ◆備考◆

Sheet 品群時間帯速報取得
A1: IF設計書 | K1: システム名 | S1: カスミ様PDAシステム | AC1: 作成者 | AG1: SANT | AM1: 作成日 | AQ1: 44130
K2: サブシステム名 | S2: POSメニュー | AC2: 更新者 | AG2: SANT | AM2: 更新日 | AQ2: 44176
B4: URI | F4: {hostURI}/tmflash/hingun/select | Y4: API名(論理) | AC4: 品群時間帯速報取得
B5: Method | F5: POST | Y5: 処理概要 | AC5: 品群時間帯速報を取得する。
B6: 引 数 | Y6: 戻り値
B7: オブジェクト名 | F7: － | M7: 形式 | Q7: JSON形式 | Y7: オブジェクト名 | AC7: － | AJ7: 形式 | AN7: JSON形式
B8: No. | C8: 項目名(○：必須) | I8: 項目ID | N8: 型 | Q8: 概要 | Y8: No. | Z8: 項目名 | AF8: 項目ID | AK8: 型 | AN8: 概要
B9: 1 | C9: 共通パラメータ | Y9: 1 | Z9: 共通情報
B10: 2 | D10: ※共通パラメータ参照 | Y10: 2 | AA10: ※共通パラメータ参照
B11: 3 | C11: 業務パラメータ | I11: data_param | Y11: 3 | Z11: 業務情報 | AF11: result_data
B12: 4 | C12: ○ | D12: 部門コード | I12: bumoncode | N12: 文字 | Y12: 4 | AA12: 売上金額(税抜) | AF12: salesamount | AK12: 数値 | AN12: 対象期間の品群合計
B13: 5 | C13: ○ | D13: 品群コード | I13: hinguncode | N13: 文字 | Y13: 5 | AA13: 点数 | AF13: score | AK13: 数値 | AN13: 〃
B14: 6 | C14: ○ | D14: 検索日付 | I14: searchdate | N14: 文字 | Q14: yyyymmdd形式 | Y14: 6 | AA14: 予算額 | AF14: budgetamount | AK14: 数値 | AN14: ※固定値ゼロ
B15: 7 | Y15: 7 | AA15: 客数 | AF15: customers | AK15: 数値 | AN15: 〃
B16: 8 | Y16: 8 | AA16: 来店客数 | AF16: visitcustomers | AK16: 数値 | AN16: 対象期間の店舗来店客数計
B17: 9 | Y17: 9 | Z17: 業務情報(配列) | AF17: result_list | AN17: ※1
B18: 10 | Y18: 10 | AA18: 登録時間 | AF18: time | AK18: 文字 | AN18: hhmm形式
B19: 11 | Y19: 11 | AA19: 売上金額(税抜) | AF19: salesamount | AK19: 数値
B20: 12 | Y20: 12 | AA20: 点数 | AF20: score | AK20: 数値
B21: 13 | Y21: 13 | AA21: 客数 | AF21: customers | AK21: 数値
B22: 14 | Y22: 14
B23: 15 | Y23: 15
B24: 16 | Y24: 16
B25: 17 | Y25: 17
B26: 18 | Y26: 18
B27: 19 | Y27: 19
B28: 20 | Y28: 20
B29: 21 | Y29: 21
B30: 22 | Y30: 22
B31: 23 | Y31: 23
B32: ◆備考◆

Sheet 品種時間帯速報取得
A1: IF設計書 | K1: システム名 | S1: カスミ様PDAシステム | AC1: 作成者 | AG1: SANT | AM1: 作成日 | AQ1: 44130
K2: サブシステム名 | S2: POSメニュー | AC2: 更新者 | AG2: SANT | AM2: 更新日 | AQ2: 44176
B4: URI | F4: {hostURI}/tmflash/hinshu/select | Y4: API名(論理) | AC4: 品種時間帯速報取得
B5: Method | F5: POST | Y5: 処理概要 | AC5: 品種時間帯速報を取得する。
B6: 引 数 | Y6: 戻り値
B7: オブジェクト名 | F7: － | M7: 形式 | Q7: JSON形式 | Y7: オブジェクト名 | AC7: － | AJ7: 形式 | AN7: JSON形式
B8: No. | C8: 項目名(○：必須) | I8: 項目ID | N8: 型 | Q8: 概要 | Y8: No. | Z8: 項目名 | AF8: 項目ID | AK8: 型 | AN8: 概要
B9: 1 | C9: 共通パラメータ | Y9: 1 | Z9: 共通情報
B10: 2 | D10: ※共通パラメータ参照 | Y10: 2 | AA10: ※共通パラメータ参照
B11: 3 | C11: 業務パラメータ | I11: data_param | Y11: 3 | Z11: 業務情報 | AF11: result_data
B12: 4 | C12: ○ | D12: 部門コード | I12: bumoncode | N12: 文字 | Y12: 4 | AA12: 売上金額(税抜) | AF12: salesamount | AK12: 数値 | AN12: 対象期間の品種合計
B13: 5 | C13: ○ | D13: 品群コード | I13: hinguncode | N13: 文字 | Y13: 5 | AA13: 点数 | AF13: score | AK13: 数値 | AN13: 〃
B14: 6 | C14: ○ | D14: 品種コード | I14: hinshucode | N14: 文字 | Y14: 6 | AA14: 予算額 | AF14: budgetamount | AK14: 数値 | AN14: ※固定値ゼロ
B15: 7 | C15: ○ | D15: 検索日付 | I15: searchdate | N15: 文字 | Q15: yyyymmdd形式 | Y15: 7 | AA15: 客数 | AF15: customers | AK15: 数値 | AN15: 〃
B16: 8 | Y16: 8 | AA16: 来店客数 | AF16: visitcustomers | AK16: 数値 | AN16: 対象期間の店舗来店客数計
B17: 9 | Y17: 9 | Z17: 業務情報(配列) | AF17: result_list | AN17: ※1
B18: 10 | Y18: 10 | AA18: 登録時間 | AF18: time | AK18: 文字 | AN18: hhmm形式
B19: 11 | Y19: 11 | AA19: 売上金額(税抜) | AF19: salesamount | AK19: 数値
B20: 12 | Y20: 12 | AA20: 点数 | AF20: score | AK20: 数値
B21: 13 | Y21: 13 | AA21: 客数 | AF21: customers | AK21: 数値
B22: 14 | Y22: 14
B23: 15 | Y23: 15
B24: 16 | Y24: 16
B25: 17 | Y25: 17
B26: 18 | Y26: 18
B27: 19 | Y27: 19
B28: 20 | Y28: 20
B29: 21 | Y29: 21
B30: 22 | Y30: 22
B31: 23 | Y31: 23
B32: ◆備考◆

Sheet 分類時間帯速報取得
A1: IF設計書 | K1: システム名 | S1: カスミ様PDAシステム | AC1: 作成者 | AG1: SANT | AM1: 作成日 | AQ1: 44130
K2: サブシステム名 | S2: POSメニュー | AC2: 更新者 | AG2: SANT | AM2: 更新日 | AQ2: 44176
B4: URI | F4: {hostURI}/tmflash/bunrui/select | Y4: API名(論理) | AC4: 分類時間帯速報取得
B5: Method | F5: POST | Y5: 処理概要 | AC5: 分類時間帯速報を取得する。
B6: 引 数 | Y6: 戻り値
B7: オブジェクト名 | F7: － | M7: 形式 | Q7: JSON形式 | Y7: オブジェクト名 | AC7: － | AJ7: 形式 | AN7: JSON形式
B8: No. | C8: 項目名(○：必須) | I8: 項目ID | N8: 型 | Q8: 概要 | Y8: No. | Z8: 項目名 | AF8: 項目ID | AK8: 型 | AN8: 概要
B9: 1 | C9: 共通パラメータ | Y9: 1 | Z9: 共通情報
B10: 2 | D10: ※共通パラメータ参照 | Y10: 2 | AA10: ※共通パラメータ参照
B11: 3 | C11: 業務パラメータ | I11: data_param | Y11: 3 | Z11: 業務情報 | AF11: result_data
B12: 4 | C12: ○ | D12: 部門コード | I12: bumoncode | N12: 文字 | Y12: 4 | AA12: 売上金額(税抜) | AF12: salesamount | AK12: 数値 | AN12: 対象期間の分類合計
B13: 5 | C13: ○ | D13: 品群コード | I13: hinguncode | N13: 文字 | Y13: 5 | AA13: 点数 | AF13: score | AK13: 数値 | AN13: 〃
B14: 6 | C14: ○ | D14: 品種コード | I14: hinshucode | N14: 文字 | Y14: 6 | AA14: 客数 | AF14: customers | AK14: 数値 | AN14: 〃
B15: 7 | C15: ○ | D15: 分類コード | I15: bunruicode | N15: 文字 | Y15: 7 | AA15: 来店客数 | AF15: visitcustomers | AK15: 数値 | AN15: 対象期間の店舗来店客数計
B16: 8 | C16: ○ | D16: 検索日付 | I16: searchdate | N16: 文字 | Q16: yyyymmdd形式 | Y16: 8 | Z16: 業務情報(配列) | AF16: result_list | AN16: ※1
B17: 9 | Y17: 9 | AA17: 登録時間 | AF17: time | AK17: 文字 | AN17: hhmm形式
B18: 10 | Y18: 10 | AA18: 売上金額(税抜) | AF18: salesamount | AK18: 数値
B19: 11 | Y19: 11 | AA19: 点数 | AF19: score | AK19: 数値
B20: 12 | Y20: 12 | AA20: 客数 | AF20: customers | AK20: 数値
B21: 13 | Y21: 13
B22: 14 | Y22: 14
B23: 15 | Y23: 15
B24: 16 | Y24: 16
B25: 17 | Y25: 17
B26: 18 | Y26: 18
B27: 19 | Y27: 19
B28: 20 | Y28: 20
B29: 21 | Y29: 21
B30: 22 | Y30: 22
B31: 23 | Y31: 23
B32: ◆備考◆

Sheet 単品時間帯速報取得
A1: IF設計書 | K1: システム名 | S1: カスミ様PDAシステム | AC1: 作成者 | AG1: SANT | AM1: 作成日 | AQ1: 44130
K2: サブシステム名 | S2: POSメニュー | AC2: 更新者 | AG2: SANT | AM2: 更新日 | AQ2: 44176
B4: URI | F4: {hostURI}/tmflash/item/select | Y4: API名(論理) | AC4: 単品時間帯速報取得
B5: Method | F5: POST | Y5: 処理概要 | AC5: 単品時間帯速報を取得する。
B6: 引 数 | Y6: 戻り値
B7: オブジェクト名 | F7: － | M7: 形式 | Q7: JSON形式 | Y7: オブジェクト名 | AC7: － | AJ7: 形式 | AN7: JSON形式
B8: No. | C8: 項目名(○：必須) | I8: 項目ID | N8: 型 | Q8: 概要 | Y8: No. | Z8: 項目名 | AF8: 項目ID | AK8: 型 | AN8: 概要
B9: 1 | C9: 共通パラメータ | Y9: 1 | Z9: 共通情報
B10: 2 | D10: ※共通パラメータ参照 | Y10: 2 | AA10: ※共通パラメータ参照
B11: 3 | C11: 業務パラメータ | I11: data_param | Y11: 3 | Z11: 業務情報 | AF11: result_data
B12: 4 | C12: ○ | D12: PLUコード | I12: plucode | N12: 文字 | Y12: 4 | AA12: 売上金額(税抜) | AF12: salesamount | AK12: 数値 | AN12: 対象期間の商品合計
B13: 5 | C13: ○ | D13: 検索日付 | I13: searchdate | N13: 文字 | Q13: yyyymmdd形式 | Y13: 5 | AA13: 点数 | AF13: score | AK13: 数値 | AN13: 〃
B14: 6 | Y14: 6 | AA14: 客数 | AF14: customers | AK14: 数値 | AN14: 〃
B15: 7 | Y15: 7 | AA15: 来店客数 | AF15: visitcustomers | AK15: 数値 | AN15: 対象期間の店舗来店客数計
B16: 8 | Y16: 8 | Z16: 業務情報(配列) | AF16: result_list | AN16: ※1
B17: 9 | Y17: 9 | AA17: 登録時間 | AF17: time | AK17: 文字 | AN17: hhmm形式
B18: 10 | Y18: 10 | AA18: 売上金額(税抜) | AF18: salesamount | AK18: 数値
B19: 11 | Y19: 11 | AA19: 点数 | AF19: score | AK19: 数値
B20: 12 | Y20: 12 | AA20: 客数 | AF20: customers | AK20: 数値
B21: 13 | Y21: 13
B22: 14 | Y22: 14
B23: 15 | Y23: 15
B24: 16 | Y24: 16
B25: 17 | Y25: 17
B26: 18 | Y26: 18
B27: 19 | Y27: 19
B28: 20 | Y28: 20
B29: 21 | Y29: 21
B30: 22 | Y30: 22
B31: 23 | Y31: 23
B32: ◆備考◆

Sheet 単品速報取得(PLU指定)
A1: IF設計書 | K1: システム名 | S1: カスミ様PDAシステム | AC1: 作成者 | AG1: SANT | AM1: 作成日 | AQ1: 44130
K2: サブシステム名 | S2: POSメニュー | AC2: 更新者 | AG2: SANT | AM2: 更新日 | AQ2: 44176
B4: URI | F4: {hostURI}/tmflash/plu/select | Y4: API名(論理) | AC4: 単品速報取得
B5: Method | F5: POST | Y5: 処理概要 | AC5: 単品速報（月・週・日・時間帯）を取得する。
B6: 引 数 | Y6: 戻り値
B7: オブジェクト名 | F7: － | M7: 形式 | Q7: JSON形式 | Y7: オブジェクト名 | AC7: － | AJ7: 形式 | AN7: JSON形式
B8: No. | C8: 項目名(○：必須) | I8: 項目ID | N8: 型 | Q8: 概要 | Y8: No. | Z8: 項目名 | AF8: 項目ID | AK8: 型 | AN8: 概要
B9: 1 | C9: 共通パラメータ | Y9: 1 | Z9: 共通情報
B10: 2 | D10: ※共通パラメータ参照 | Y10: 2 | AA10: ※共通パラメータ参照
B11: 3 | C11: 業務パラメータ | I11: data_param | Y11: 3 | Z11: 業務情報(配列) | AF11: result_list
B12: 4 | C12: ○ | D12: PLUコード | I12: plucode | N12: 文字 | Y12: 4 | AA12: 日時 | AF12: datetime | AK12: 文字 | AN12: ※3
B13: 5 | C13: ○ | D13: 検索モード | I13: searchmode | N13: 数値 | Q13: ※1 | Y13: 5 | AA13: 売上金額(税抜) | AF13: salesamount | AK13: 数値
B14: 6 | D14: 検索日付 | I14: searchdate | N14: 文字 | Q14: ※2 | Y14: 6 | AA14: 点数 | AF14: score | AK14: 数値
B15: 7 | Y15: 7 | AA15: 客数 | AF15: customers | AK15: 数値
B16: 8 | Y16: 8
B17: 9 | W17: , | Y17: 9
B18: 10 | Y18: 10
B19: 11 | Y19: 11
B20: 12 | Y20: 12
B21: 13 | Y21: 13
B22: 14 | Y22: 14
B23: 15 | Y23: 15
B24: 16 | Y24: 16
B25: 17 | Y25: 17
B26: 18 | Y26: 18
B27: 19 | Y27: 19
B28: 20 | Y28: 20
B29: 21 | Y29: 21
... B31: 23 | Y31: 23
B32: ◆備考◆

Sheet 廃棄情報取得
A1: IF設計書 | K1: システム名 | S1: カスミ様PDAシステム | AC1: 作成者 | AG1: SANT | AM1: 作成日 | AQ1: 44130
K2: サブシステム名 | S2: POSメニュー | AC2: 更新者 | AG2: SANT | AM2: 更新日 | AQ2: 44167
B4: URI | F4: {hostURI}/haiki/select | Y4: API名(論理) | AC4: 廃棄情報取得
B5: Method | F5: POST | Y5: 処理概要 | AC5: 入力済の廃棄情報を取得する。（新規登録時は当APIはCallしない）
B6: 引 数 | Y6: 戻り値
B7: オブジェクト名 | F7: － | M7: 形式 | Q7: JSON形式 | Y7: オブジェクト名 | AC7: － | AJ7: 形式 | AN7: JSON形式
B8: No. | C8: 項目名(○：必須) | I8: 項目ID | N8: 型 | Q8: 概要 | Y8: No. | Z8: 項目名 | AF8: 項目ID | AK8: 型 | AN8: 概要
B9: 1 | C9: 共通パラメータ | Y9: 1 | Z9: 共通情報
B10: 2 | D10: ※共通パラメータ参照 | Y10: 2 | AA10: ※共通パラメータ参照
B11: 3 | C11: 業務パラメータ | I11: data_param | Y11: 3 | Z11: 業務情報 | AF11: result_data
B12: 4 | C12: ○ | D12: PLUコード | I12: plucode | N12: 文字 | Y12: 4 | AA12: 廃棄単価 | AF12: price | AK12: 数値
B13: 5 | C13: ○ | D13: 更新日時 | I13: adddate | N13: 文字 | Q13: yyyymmddhhmmss形式 | Y13: 5 | AA13: 入力点数 | AF13: score | AK13: 数値
B14: 6 | Y14: 6
B15: 7 | Y15: 7
B16: 8 | Y16: 8
B17: 9 | Y17: 9
B18: 10 | Y18: 10
B19: 11 | Y19: 11
B20: 12 | Y20: 12
B21: 13 | Y21: 13
B22: 14 | Y22: 14
B23: 15 | Y23: 15
B24: 16 | Y24: 16
B25: 17 | Y25: 17
... B31: 23 | Y31: 23
B32: ◆備考◆

Sheet 廃棄更新
A1: IF設計書 | K1: システム名 | S1: カスミ様PDAシステム | AC1: 作成者 | AG1: SANT | AM1: 作成日 | AQ1: 44130
K2: サブシステム名 | S2: POSメニュー | AC2: 更新者 | AG2: SANT | AM2: 更新日 | AQ2: 44167
B4: URI | F4: {hostURI}/haiki/update | Y4: API名(論理) | AC4: 廃棄更新
B5: Method | F5: POST | Y5: 処理概要 | AC5: 廃棄商品の登録を行う。
B6: 引 数 | Y6: 戻り値
B7: オブジェクト名 | F7: － | M7: 形式 | Q7: JSON形式 | Y7: オブジェクト名 | AC7: － | AJ7: 形式 | AN7: JSON形式
B8: No. | C8: 項目名(○：必須) | I8: 項目ID | N8: 型 | Q8: 概要 | Y8: No. | Z8: 項目名 | AF8: 項目ID | AK8: 型 | AN8: 概要
B9: 1 | C9: 共通パラメータ | Y9: 1 | Z9: 共通情報
B10: 2 | D10: ※共通パラメータ参照 | Y10: 2 | AA10: ※共通パラメータ参照
B11: 3 | C11: 業務パラメータ | I11: data_param | Y11: 3 | Z11: 業務情報 | AF11: result_data
B12: 4 | C12: 〇 | D12: PLUコード | I12: plucode | N12: 文字 | Y12: 4 | AA12: 更新日時 | AF12: adddate | AK12: 文字 | AN12: ※1
B13: 5 | C13: 〇 | D13: 廃棄単価 | I13: price | N13: 数値 | Y13: 5
B14: 6 | C14: 〇 | D14: 点数 | I14: score | N14: 数値 | Y14: 6
B15: 7 | D15: 更新日時 | I15: adddate | N15: 文字 | Q15: ※1 | Y15: 7
B16: 8 | Y16: 8
B17: 9 | Y17: 9
B18: 10 | Y18: 10
B19: 11 | Y19: 11
B20: 12 | Y20: 12
B21: 13 | Y21: 13
B22: 14 | Y22: 14
B23: 15 | Y23: 15
B24: 16 | Y24: 16
B25: 17 | Y25: 17
B26: 18 | Y26: 18
B27: 19 | Y27: 19
... B31: 23 | Y31: 23
B32: ◆備考◆

Sheet 廃棄部門別一覧取得
A1: IF設計書 | K1: システム名 | S1: カスミ様PDAシステム | AC1: 作成者 | AG1: SANT | AM1: 作成日 | AQ1: 44130
K2: サブシステム名 | S2: POSメニュー | AC2: 更新者 | AG2: SANT | AM2: 更新日 | AQ2: 44167
B4: URI | F4: {hostURI}/haikibumon/select | Y4: API名(論理) | AC4: 廃棄部門別一覧取得
B5: Method | F5: POST | Y5: 処理概要 | AC5: 部門別の廃棄一覧を取得する。
B6: 引 数 | Y6: 戻り値
B7: オブジェクト名 | F7: － | M7: 形式 | Q7: JSON形式 | Y7: オブジェクト名 | AC7: － | AJ7: 形式 | AN7: JSON形式
B8: No. | C8: 項目名(○：必須) | I8: 項目ID | N8: 型 | Q8: 概要 | Y8: No. | Z8: 項目名 | AF8: 項目ID | AK8: 型 | AN8: 概要
B9: 1 | C9: 共通パラメータ | Y9: 1 | Z9: 共通情報
B10: 2 | D10: ※共通パラメータ参照 | Y10: 2 | AA10: ※共通パラメータ参照
B11: 3 | C11: 業務パラメータ | I11: data_param | Y11: 3 | Z11: 業務情報(配列) | AF11: result_list | AN11: ソート順：部門コード(昇順)
B12: 4 | D12: ※無し | Y12: 4 | AA12: 部門コード | AF12: bumoncode | AK12: 文字
B13: 5 | Y13: 5 | AA13: 部門名 | AF13: bumonname | AK13: 文字
B14: 6 | Y14: 6 | AA14: 廃棄金額(税抜) | AF14: amount | AK14: 数値
B15: 7 | Y15: 7 | AA15: 廃棄点数 | AF15: score | AK15: 数値
B16: 8 | Y16: 8
B17: 9 | Y17: 9
B18: 10 | Y18: 10
B19: 11 | Y19: 11
B20: 12 | Y20: 12
B21: 13 | Y21: 13
B22: 14 | Y22: 14
B23: 15 | Y23: 15
B24: 16 | Y24: 16
B25: 17 | Y25: 17
B26: 18 | Y26: 18
B27: 19 | Y27: 19
... B31: 23 | Y31: 23
B32: ◆備考◆

Sheet 廃棄商品別一覧取得
A1: IF設計書 | K1: システム名 | S1: カスミ様PDAシステム | AC1: 作成者 | AG1: SANT | AM1: 作成日 | AQ1: 44130
K2: サブシステム名 | S2: POSメニュー | AC2: 更新者 | AG2: SANT | AM2: 更新日 | AQ2: 44167
B4: URI | F4: {hostURI}/haikiitem/select | Y4: API名(論理) | AC4: 廃棄商品別一覧取得
B5: Method | F5: POST | Y5: 処理概要 | AC5: 商品別の廃棄一覧を取得する。
B6: 引 数 | Y6: 戻り値
B7: オブジェクト名 | F7: － | M7: 形式 | Q7: JSON形式 | Y7: オブジェクト名 | AC7: － | AJ7: 形式 | AN7: JSON形式
B8: No. | C8: 項目名(○：必須) | I8: 項目ID | N8: 型 | Q8: 概要 | Y8: No. | Z8: 項目名 | AF8: 項目ID | AK8: 型 | AN8: 概要
B9: 1 | C9: 共通パラメータ | Y9: 1 | Z9: 共通情報
B10: 2 | D10: ※共通パラメータ参照 | Y10: 2 | AA10: ※共通パラメータ参照
B11: 3 | C11: 業務パラメータ | I11: data_param | Y11: 3 | Z11: 業務情報(配列) | AF11: result_list | AN11: ソート順：登録日時(昇順)
B12: 4 | C12: 〇 | D12: 部門コード | I12: bumoncode | N12: 文字 | Y12: 4 | AA12: PLUコード | AF12: plucode | AK12: 文字
B13: 5 | Y13: 5 | AA13: 商品名 | AF13: itemname | AK13: 文字
B14: 6 | Y14: 6 | AA14: 廃棄金額(税抜) | AF14: price | AK14: 数値
B15: 7 | Y15: 7 | AA15: 廃棄点数 | AF15: score | AK15: 数値
B16: 8 | Y16: 8 | AA16: 入力従業員コード | AF16: usercode | AK16: 文字
B17: 9 | Y17: 9 | AA17: 登録日時 | AF17: adddate | AK17: 文字 | AN17: yyyymmddhhmmss形式
B18: 10 | Y18: 10 | AA18: 更新日時 | AF18: upddate | AK18: 文字 | AN18: ※2
B19: 11 | Y19: 11
B20: 12 | Y20: 12
B21: 13 | Y21: 13
B22: 14 | Y22: 14
B23: 15 | Y23: 15
B24: 16 | Y24: 16
B25: 17 | Y25: 17
B26: 18 | Y26: 18
B27: 19 | Y27: 19
B28: 20 | Y28: 20
B29: 21 | Y29: 21
B30: 22 | Y30: 22
B31: 23 | Y31: 23
B32: ◆備考◆

Sheet レジグループ取得
A1: IF設計書 | K1: システム名 | S1: カスミ様PDAシステム | AC1: 作成者 | AG1: SANT | AM1: 作成日 | AQ1: 44130
K2: サブシステム名 | S2: POSメニュー | AC2: 更新者 | AM2: 更新日
B4: URI | F4: {hostURI}/reggroup/select | Y4: API名(論理) | AC4: レジグループ取得
B5: Method | F5: POST | Y5: 処理概要 | AC5: グループのリストを取得する。
B6: 引 数 | Y6: 戻り値
B7: オブジェクト名 | F7: － | M7: 形式 | Q7: JSON形式 | Y7: オブジェクト名 | AC7: － | AJ7: 形式 | AN7: JSON形式
B8: No. | C8: 項目名 | I8: 項目ID | N8: 型 | Q8: 概要 | Y8: No. | Z8: 項目名 | AF8: 項目ID | AK8: 型 | AN8: 概要
B9: 1 | C9: 共通パラメータ | Y9: 1 | Z9: 共通情報
B10: 2 | D10: ※共通パラメータ参照 | Y10: 2 | AA10: ※共通パラメータ参照
B11: 3 | C11: 業務パラメータ | I11: data_param | Y11: 3 | Z11: 業務情報(配列) | AF11: result_list | AN11: ソート順：グループコード(昇順)
B12: 4 | D12: ※無し | Y12: 4 | AA12: グループコード | AF12: groupcode | AK12: 文字
B13: 5 | Y13: 5 | AA13: グループ名 | AF13: groupname | AK13: 文字
B14: 6 | Y14: 6
B15: 7 | Y15: 7
B16: 8 | Y16: 8
B17: 9 | Y17: 9
B18: 10 | Y18: 10
B19: 11 | Y19: 11
B20: 12 | Y20: 12
B21: 13 | Y21: 13
B22: 14 | Y22: 14
B23: 15 | Y23: 15
B24: 16 | Y24: 16
B25: 17 | Y25: 17
... B31: 23 | Y31: 23
B32: ◆備考◆

Sheet タブ取得
A1: IF設計書 | K1: システム名 | S1: カスミ様PDAシステム | AC1: 作成者 | AG1: SANT | AM1: 作成日 | AQ1: 44130
K2: サブシステム名 | S2: POSメニュー | AC2: 更新者 | AM2: 更新日
B4: URI | F4: {hostURI}/regtab/select | Y4: API名(論理) | AC4: タブ取得
B5: Method | F5: POST | Y5: 処理概要 | AC5: レジグループのタブリストを取得する。
B6: 引 数 | Y6: 戻り値
B7: オブジェクト名 | F7: － | M7: 形式 | Q7: JSON形式 | Y7: オブジェクト名 | AC7: － | AJ7: 形式 | AN7: JSON形式
B8: No. | C8: 項目名 | I8: 項目ID | N8: 型 | Q8: 概要 | Y8: No. | Z8: 項目名 | AF8: 項目ID | AK8: 型 | AN8: 概要
B9: 1 | C9: 共通パラメータ | Y9: 1 | Z9: 共通情報
B10: 2 | D10: ※共通パラメータ参照 | Y10: 2 | AA10: ※共通パラメータ参照
B11: 3 | C11: 業務パラメータ | I11: data_param | Y11: 3 | Z11: 業務情報(配列) | AF11: result_list | AN11: ソート順：タブコード(昇順)
B12: 4 | D12: ※無し | Y12: 4 | AA12: タブコード | AF12: tabcode | AK12: 文字
B13: 5 | Y13: 5 | AA13: タブ名 | AF13: tabname | AK13: 文字
B14: 6 | Y14: 6
B15: 7 | Y15: 7
B16: 8 | Y16: 8
B17: 9 | Y17: 9
B18: 10 | Y18: 10
B19: 11 | Y19: 11
B20: 12 | Y20: 12
B21: 13 | Y21: 13
B22: 14 | Y22: 14
B23: 15 | Y23: 15
B24: 16 | Y24: 16
B25: 17 | Y25: 17
... B31: 23 | Y31: 23
B32: ◆備考◆

Sheet プリセット廃棄一覧取得
A1: IF設計書 | K1: システム名 | S1: カスミ様PDAシステム | AC1: 作成者 | AG1: SANT | AM1: 作成日 | AQ1: 44130
K2: サブシステム名 | S2: POSメニュー | AC2: 更新者 | AG2: SANT | AM2: 更新日 | AQ2: 44189
B4: URI | F4: {hostURI}/presethaiki/select | Y4: API名(論理) | AC4: プリセット廃棄一覧取得
B5: Method | F5: POST | Y5: 処理概要 | AC5: プリセット廃棄一覧を取得する。
B6: 引 数 | Y6: 戻り値
B7: オブジェクト名 | F7: － | M7: 形式 | Q7: JSON形式 | Y7: オブジェクト名 | AC7: － | AJ7: 形式 | AN7: JSON形式
B8: No. | C8: 項目名(○：必須) | I8: 項目ID | N8: 型 | Q8: 概要 | Y8: No. | Z8: 項目名 | AF8: 項目ID | AK8: 型 | AN8: 概要
B9: 1 | C9: 共通パラメータ | Y9: 1 | Z9: 共通情報
B10: 2 | D10: ※共通パラメータ参照 | Y10: 2 | AA10: ※共通パラメータ参照
B11: 3 | C11: 業務パラメータ | I11: data_param | Y11: 3 | Z11: 業務情報(配列) | AF11: result_list | AN11: ソート順：シーケンス番号
B12: 4 | C12: 〇 | D12: グループコード | I12: groupcode | N12: 文字 | Y12: 4 | AA12: PLUコード | AF12: plucode | AK12: 文字
B13: 5 | C13: 〇 | D13: タブコード | I13: tabcode | N13: 文字 | Y13: 5 | AA13: 商品名 | AF13: itemname | AK13: 文字
B14: 6 | Y14: 6 | AA14: 現在売価(税抜) | AF14: currentprice | AK14: 文字 | AN14: 設定されていない場合は空白値を返却 ※「(補足)現在売価仕様ｼｰﾄ」を参照
B15: 7 | Y15: 7 | AA15: ＭＭフラグ | AF15: mmflg | AK15: 数値 | AN15: 0：無 1：有 ※1
B16: 8 | Y16: 8 | AA16: シーケンス番号 | AF16: seq | AK16: 数値 | AN16: ※2
B17: 9 | Y17: 9
B18: 10 | Y18: 10
B19: 11 | Y19: 11
B20: 12 | Y20: 12
B21: 13 | Y21: 13
B22: 14 | Y22: 14
B23: 15 | Y23: 15
B24: 16 | Y24: 16
B25: 17 | Y25: 17
B26: 18 | Y26: 18
B27: 19 | Y27: 19
B28: 20 | Y28: 20
... B31: 23 | Y31: 23
B32: ◆備考◆
