Workbook

Sheet 表紙
A1: システム名 | K1: システム種別 | W1: 概要設計 | AP1: 作成者 | AT1: 作成日 | AY1: 更新者 | BC1: 更新日 | BH1: 版数
A2: POSサーバ | K2: 全般 | AP2: Huy Nguyen | AT2: =改廃履歴!$B$11 -> 45532 | BH2: =LOOKUP(2,1/(改廃履歴!O11:O30000<>""),改廃履歴!O11:O30000) -> 0.31
A4: 機能カテゴリ | H4: 機能一覧 | U4: 項目 | Z4: いなげや様向け | AP4: {=RIGHT(CELL("filename",$A$1),LEN(CELL("filename",$A$1))-FIND("]",CELL("filename",$A$1)))} -> #VALUE!
L16: 現金専用簡易セルフPOS 基本設計書
L24: =K2&"/"&H4&"/"&Z4 -> 全般/機能一覧/いなげや様向け
Q44: 承認日 | AA44: 承認者 | AQ44: 版数

Sheet 改廃履歴
A1: システム名 | K1: システム種別 | W1: =IF(表紙!W1="","",表紙!W1) -> 概要設計 | AP1: 作成者 | AT1: 作成日 | AY1: 更新者 | BC1: 更新日 | BH1: 版数
A2: =IF(表紙!A2="","",表紙!A2) -> POSサーバ | K2: =IF(表紙!K2="","",表紙!K2) -> 全般 | AP2: =IF(表紙!AP2="","",表紙!AP2) -> Huy Nguyen | AT2: =IF(表紙!AT2="","",表紙!AT2) -> 45532 | AY2: =IF(表紙!AY2="","",表紙!AY2) | BC2: =IF(表紙!BC2="","",表紙!BC2) | BH2: =IF(表紙!BH2="","",表紙!BH2) -> 0.31
A4: 機能カテゴリ | H4: =IF(表紙!H4="","",表紙!H4) -> 機能一覧 | U4: 項目 | Z4: =IF(表紙!Z4="","",表紙!Z4) -> いなげや様向け | AP4: {=RIGHT(CELL("filename",$A$1),LEN(CELL("filename",$A$1))-FIND("]",CELL("filename",$A$1)))} -> #VALUE!
B8: ■改廃履歴
B10: 更新日付 | H10: 更新者 | O10: 版数 | S10: 変更内容 | AX10: 承認日付 | BD10: 承認者
B11: 45532 | H11: Huy Nguyen | O11: 0.1 | S11: 初版作成
B13: 45769 | H13: Thanh Nguyên | O13: 0.3 | S13: 機能一覧（POSサーバ2.0）シートを大幅更新
B15: 45770 | H15: Thanh Nguyên | O15: 0.31 | S15: 追記

Sheet 全体構成
A1: システム名 | K1: システム種別 | W1: =IF(表紙!W1="","",表紙!W1) -> 概要設計 | AP1: 作成者 | AT1: 作成日 | AY1: 更新者 | BC1: 更新日 | BH1: 版数
A2: =IF(表紙!A2="","",表紙!A2) -> POSサーバ | K2: =IF(表紙!K2="","",表紙!K2) -> 全般 | AP2: =IF(表紙!AP2="","",表紙!AP2) -> Huy Nguyen | AT2: =IF(表紙!AT2="","",表紙!AT2) -> 45532 | AY2: =IF(表紙!AY2="","",表紙!AY2) | BC2: =IF(表紙!BC2="","",表紙!BC2) | BH2: =IF(表紙!BH2="","",表紙!BH2) -> 0.31
A4: 機能カテゴリ | H4: =IF(表紙!H4="","",表紙!H4) -> 機能一覧 | U4: 項目 | Z4: =IF(表紙!Z4="","",表紙!Z4) -> いなげや様向け | AP4: {=RIGHT(CELL("filename",$A$1),LEN(CELL("filename",$A$1))-FIND("]",CELL("filename",$A$1)))} -> #VALUE!

Sheet 機能一覧（POSサーバ2.0）
B1: 〇：対象 △：開発中 -：未着手 ×：想定外
W5: MM | X5: =X6/20 -> 36.915 | Y5: =Y6/20 -> 2.0825 | Z5: =Z6/20 -> 43.4625 | AA5: =AA6/20 -> 49.1435 | AB5: =AB6/20 -> 14.381 | AC5: =AC6/20 -> 14.381 | AD5: =AD6/20 -> 160.3655 | AE5: =AD5*1.15 -> 184.42032 | AF5: =AE5*350000 -> 64547114
B6: 機能概要 | H6: 説明 | I6: いなげや | J6: カスミ | M6: 重複 | N6: 20_画面設計 | O6: 画面ID | P6: 30_機能設計 | Q6: 機能ID | R6: 40_API設計 | S6: APIID | T6: DB設計 | U6: DB_ID | W6: MD | X6: =SUMIF($W$7:$W$529,"*",X$7:X$529) -> 738.3 | Y6: =SUMIF($W$7:$W$529,"*",Y$7:Y$529) -> 41.65 | Z6: =SUMIF($W$7:$W$529,"*",Z$7:Z$529) -> 869.25 | AA6: =SUMIF($W$7:$W$529,"*",AA$7:AA$529) -> 982.87 | AB6: =SUMIF($W$7:$W$529,"*",AB$7:AB$529) -> 287.62 | AC6: =SUMIF($W$7:$W$529,"*",AC$7:AC$529) -> 287.62 | AD6: =SUMIF($W$7:$W$529,"*",AD$7:AD$529) -> 3207.31
J7: 電子棚札 | K7: LABO | L7: 筑波大学 | W7: 難易度 | X7: 設計 | Y7: モック | Z7: Code | AA7: FT | AB7: IT | AC7: PT | AD7: 合計
B8: 00_インフラ | X8: =SUM(X9:X30) -> 160.66 | Y8: =SUM(Y9:Y30) -> 0 | Z8: =SUM(Z9:Z30) -> 189 | AA8: =SUM(AA9:AA30) -> 213.58 | AB8: =SUM(AB9:AB30) -> 62.38 | AC8: =SUM(AC9:AC30) -> 62.38 | AD8: =SUM(AD9:AD30) -> 688 | AE8: =AD8/20 -> 34.4 | AF8: =AE8*350000 -> 12040000
B9: AWS構築 | X9: =_xlfn.XLOOKUP(W9,マスタ!A:A,マスタ!C:C,0)*M9 -> 0 | Y9: =IF(N9="",0,_xlfn.XLOOKUP(W9,マスタ!A:A,マスタ!D:D,0)*M9) -> 0 | Z9: =_xlfn.XLOOKUP(W9,マスタ!A:A,マスタ!E:E,0)*M9 -> 0 | AA9: =_xlfn.XLOOKUP(W9,マスタ!A:A,マスタ!F:F,0)*M9 -> 0 | AB9: =_xlfn.XLOOKUP(W9,マスタ!A:A,マスタ!G:G,0)*M9 -> 0 | AC9: =_xlfn.XLOOKUP(W9,マスタ!A:A,マスタ!H:H,0)*M9 -> 0 | AD9: =SUM(X9:AC9) -> 0
C10: ステージング環境構築 | X10: =_xlfn.XLOOKUP(W10,マスタ!A:A,マスタ!C:C,0)*M10 -> 0 | Y10: =IF(N10="",0,_xlfn.XLOOKUP(W10,マスタ!A:A,マスタ!D:D,0)*M10) -> 0 | Z10: =_xlfn.XLOOKUP(W10,マスタ!A:A,マスタ!E:E,0)*M10 -> 0 | AA10: =_xlfn.XLOOKUP(W10,マスタ!A:A,マスタ!F:F,0)*M10 -> 0 | AB10: =_xlfn.XLOOKUP(W10,マスタ!A:A,マスタ!G:G,0)*M10 -> 0 | AC10: =_xlfn.XLOOKUP(W10,マスタ!A:A,マスタ!H:H,0)*M10 -> 0 | AD10: =SUM(X10:AC10) -> 0
D11: フェーズ１：外部連携(マスタ) | I11: 〇 | J11: 〇 | K11: 〇 | L11: 〇 | M11: 2 | W11: 複雑 | X11: =_xlfn.XLOOKUP(W11,マスタ!A:A,マスタ!C:C,0)*M11 -> 5.96 | Y11: =IF(N11="",0,_xlfn.XLOOKUP(W11,マスタ!A:A,マスタ!D:D,0)*M11) -> 0 | Z11: =_xlfn.XLOOKUP(W11,マスタ!A:A,マスタ!E:E,0)*M11 -> 7 | AA11: =_xlfn.XLOOKUP(W11,マスタ!A:A,マスタ!F:F,0)*M11 -> 7.92 | AB11: =_xlfn.XLOOKUP(W11,マスタ!A:A,マスタ!G:G,0)*M11 -> 2.32 | AC11: =_xlfn.XLOOKUP(W11,マスタ!A:A,マスタ!H:H,0)*M11 -> 2.32 | AD11: =SUM(X11:AC11) -> 25.52
D12: フェーズ２：POSアプリ反映 | I12: 〇 | J12: 〇 | K12: 〇 | L12: 〇 | M12: 2 | W12: より複雑 | X12: =_xlfn.XLOOKUP(W12,マスタ!A:A,マスタ!C:C,0)*M12 -> 11.9 | Y12: =IF(N12="",0,_xlfn.XLOOKUP(W12,マスタ!A:A,マスタ!D:D,0)*M12) -> 0 | Z12: =_xlfn.XLOOKUP(W12,マスタ!A:A,マスタ!E:E,0)*M12 -> 14 | AA12: =_xlfn.XLOOKUP(W12,マスタ!A:A,マスタ!F:F,0)*M12 -> 15.82 | AB12: =_xlfn.XLOOKUP(W12,マスタ!A:A,マスタ!G:G,0)*M12 -> 4.62 | AC12: =_xlfn.XLOOKUP(W12,マスタ!A:A,マスタ!H:H,0)*M12 -> 4.62 | AD12: =SUM(X12:AC12) -> 50.96
D13: フェーズ３：POSアプリ実績連携 | I13: 〇 | J13: 〇 | K13: 〇 | L13: 〇 | M13: 2 | W13: より複雑 | X13: =_xlfn.XLOOKUP(W13,マスタ!A:A,マスタ!C:C,0)*M13 -> 11.9 | Y13: =IF(N13="",0,_xlfn.XLOOKUP(W13,マスタ!A:A,マスタ!D:D,0)*M13) -> 0 | Z13: =_xlfn.XLOOKUP(W13,マスタ!A:A,マスタ!E:E,0)*M13 -> 14 | AA13: =_xlfn.XLOOKUP(W13,マスタ!A:A,マスタ!F:F,0)*M13 -> 15.82 | AB13: =_xlfn.XLOOKUP(W13,マスタ!A:A,マスタ!G:G,0)*M13 -> 4.62 | AC13: =_xlfn.XLOOKUP(W13,マスタ!A:A,マスタ!H:H,0)*M13 -> 4.62 | AD13: =SUM(X13:AC13) -> 50.96
D14: フェーズ４：各種集計 | I14: 〇 | J14: 〇 | K14: 〇 | L14: 〇 | M14: 2 | W14: より複雑 | X14: =_xlfn.XLOOKUP(W14,マスタ!A:A,マスタ!C:C,0)*M14 -> 11.9 | Y14: =IF(N14="",0,_xlfn.XLOOKUP(W14,マスタ!A:A,マスタ!D:D,0)*M14) -> 0 | Z14: =_xlfn.XLOOKUP(W14,マスタ!A:A,マスタ!E:E,0)*M14 -> 14 | AA14: =_xlfn.XLOOKUP(W14,マスタ!A:A,マスタ!F:F,0)*M14 -> 15.82 | AB14: =_xlfn.XLOOKUP(W14,マスタ!A:A,マスタ!G:G,0)*M14 -> 4.62 | AC14: =_xlfn.XLOOKUP(W14,マスタ!A:A,マスタ!H:H,0)*M14 -> 4.62 | AD14: =SUM(X14:AC14) -> 50.96
D15: フェーズ５：外部連携(実績) | I15: 〇 | J15: 〇 | K15: 〇 | L15: 〇 | M15: 2 | W15: より複雑 | X15: =_xlfn.XLOOKUP(W15,マスタ!A:A,マスタ!C:C,0)*M15 -> 11.9 | Y15: =IF(N15="",0,_xlfn.XLOOKUP(W15,マスタ!A:A,マスタ!D:D,0)*M15) -> 0 | Z15: =_xlfn.XLOOKUP(W15,マスタ!A:A,マスタ!E:E,0)*M15 -> 14 | AA15: =_xlfn.XLOOKUP(W15,マスタ!A:A,マスタ!F:F,0)*M15 -> 15.82 | AB15: =_xlfn.XLOOKUP(W15,マスタ!A:A,マスタ!G:G,0)*M15 -> 4.62 | AC15: =_xlfn.XLOOKUP(W15,マスタ!A:A,マスタ!H:H,0)*M15 -> 4.62 | AD15: =SUM(X15:AC15) -> 50.96
D16: フェーズ６：監視環境構築 | I16: 〇 | J16: 〇 | K16: 〇 | L16: 〇 | M16: 2 | W16: より複雑 | X16: =_xlfn.XLOOKUP(W16,マスタ!A:A,マスタ!C:C,0)*M16 -> 11.9 | Y16: =IF(N16="",0,_xlfn.XLOOKUP(W16,マスタ!A:A,マスタ!D:D,0)*M16) -> 0 | Z16: =_xlfn.XLOOKUP(W16,マスタ!A:A,マスタ!E:E,0)*M16 -> 14 | AA16: =_xlfn.XLOOKUP(W16,マスタ!A:A,マスタ!F:F,0)*M16 -> 15.82 | AB16: =_xlfn.XLOOKUP(W16,マスタ!A:A,マスタ!G:G,0)*M16 -> 4.62 | AC16: =_xlfn.XLOOKUP(W16,マスタ!A:A,マスタ!H:H,0)*M16 -> 4.62 | AD16: =SUM(X16:AC16) -> 50.96
D17: フェーズ７：負荷試験 | I17: 〇 | J17: 〇 | K17: 〇 | L17: 〇 | M17: 2 | W17: より複雑 | X17: =_xlfn.XLOOKUP(W17,マスタ!A:A,マスタ!C:C,0)*M17 -> 11.9 | Y17: =IF(N17="",0,_xlfn.XLOOKUP(W17,マスタ!A:A,マスタ!D:D,0)*M17) -> 0 | Z17: =_xlfn.XLOOKUP(W17,マスタ!A:A,マスタ!E:E,0)*M17 -> 14 | AA17: =_xlfn.XLOOKUP(W17,マスタ!A:A,マスタ!F:F,0)*M17 -> 15.82 | AB17: =_xlfn.XLOOKUP(W17,マスタ!A:A,マスタ!G:G,0)*M17 -> 4.62 | AC17: =_xlfn.XLOOKUP(W17,マスタ!A:A,マスタ!H:H,0)*M17 -> 4.62 | AD17: =SUM(X17:AC17) -> 50.96
C18: 本番環境構築 | X18: =_xlfn.XLOOKUP(W18,マスタ!A:A,マスタ!C:C,0)*M18 -> 0 | Y18: =IF(N18="",0,_xlfn.XLOOKUP(W18,マスタ!A:A,マスタ!D:D,0)*M18) -> 0 | Z18: =_xlfn.XLOOKUP(W18,マスタ!A:A,マスタ!E:E,0)*M18 -> 0 | AA18: =_xlfn.XLOOKUP(W18,マスタ!A:A,マスタ!F:F,0)*M18 -> 0 | AB18: =_xlfn.XLOOKUP(W18,マスタ!A:A,マスタ!G:G,0)*M18 -> 0 | AC18: =_xlfn.XLOOKUP(W18,マスタ!A:A,マスタ!H:H,0)*M18 -> 0 | AD18: =SUM(X18:AC18) -> 0
D19: フェーズ１：01_外部連携(マスタ) | I19: 〇 | J19: 〇 | K19: 〇 | L19: 〇 | M19: 2 | W19: より複雑 | X19: =_xlfn.XLOOKUP(W19,マスタ!A:A,マスタ!C:C,0)*M19 -> 11.9 | Y19: =IF(N19="",0,_xlfn.XLOOKUP(W19,マスタ!A:A,マスタ!D:D,0)*M19) -> 0 | Z19: =_xlfn.XLOOKUP(W19,マスタ!A:A,マスタ!E:E,0)*M19 -> 14 | AA19: =_xlfn.XLOOKUP(W19,マスタ!A:A,マスタ!F:F,0)*M19 -> 15.82 | AB19: =_xlfn.XLOOKUP(W19,マスタ!A:A,マスタ!G:G,0)*M19 -> 4.62 | AC19: =_xlfn.XLOOKUP(W19,マスタ!A:A,マスタ!H:H,0)*M19 -> 4.62 | AD19: =SUM(X19:AC19) -> 50.96
D20: フェーズ２：POSアプリ反映 | I20: 〇 | J20: 〇 | K20: 〇 | L20: 〇 | M20: 2 | W20: より複雑 | X20: =_xlfn.XLOOKUP(W20,マスタ!A:A,マスタ!C:C,0)*M20 -> 11.9 | Y20: =IF(N20="",0,_xlfn.XLOOKUP(W20,マスタ!A:A,マスタ!D:D,0)*M20) -> 0 | Z20: =_xlfn.XLOOKUP(W20,マスタ!A:A,マスタ!E:E,0)*M20 -> 14 | AA20: =_xlfn.XLOOKUP(W20,マスタ!A:A,マスタ!F:F,0)*M20 -> 15.82 | AB20: =_xlfn.XLOOKUP(W20,マスタ!A:A,マスタ!G:G,0)*M20 -> 4.62 | AC20: =_xlfn.XLOOKUP(W20,マスタ!A:A,マスタ!H:H,0)*M20 -> 4.62 | AD20: =SUM(X20:AC20) -> 50.96
D21: フェーズ３：POSアプリ実績連携 | I21: 〇 | J21: 〇 | K21: 〇 | L21: 〇 | M21: 2 | W21: より複雑 | X21: =_xlfn.XLOOKUP(W21,マスタ!A:A,マスタ!C:C,0)*M21 -> 11.9 | Y21: =IF(N21="",0,_xlfn.XLOOKUP(W21,マスタ!A:A,マスタ!D:D,0)*M21) -> 0 | Z21: =_xlfn.XLOOKUP(W21,マスタ!A:A,マスタ!E:E,0)*M21 -> 14 | AA21: =_xlfn.XLOOKUP(W21,マスタ!A:A,マスタ!F:F,0)*M21 -> 15.82 | AB21: =_xlfn.XLOOKUP(W21,マスタ!A:A,マスタ!G:G,0)*M21 -> 4.62 | AC21: =_xlfn.XLOOKUP(W21,マスタ!A:A,マスタ!H:H,0)*M21 -> 4.62 | AD21: =SUM(X21:AC21) -> 50.96
D22: フェーズ４：各種集計 | I22: 〇 | J22: 〇 | K22: 〇 | L22: 〇 | M22: 2 | W22: より複雑 | X22: =_xlfn.XLOOKUP(W22,マスタ!A:A,マスタ!C:C,0)*M22 -> 11.9 | Y22: =IF(N22="",0,_xlfn.XLOOKUP(W22,マスタ!A:A,マスタ!D:D,0)*M22) -> 0 | Z22: =_xlfn.XLOOKUP(W22,マスタ!A:A,マスタ!E:E,0)*M22 -> 14 | AA22: =_xlfn.XLOOKUP(W22,マスタ!A:A,マスタ!F:F,0)*M22 -> 15.82 | AB22: =_xlfn.XLOOKUP(W22,マスタ!A:A,マスタ!G:G,0)*M22 -> 4.62 | AC22: =_xlfn.XLOOKUP(W22,マスタ!A:A,マスタ!H:H,0)*M22 -> 4.62 | AD22: =SUM(X22:AC22) -> 50.96
D23: フェーズ５：外部連携(実績) | I23: 〇 | J23: 〇 | K23: 〇 | L23: 〇 | M23: 2 | W23: より複雑 | X23: =_xlfn.XLOOKUP(W23,マスタ!A:A,マスタ!C:C,0)*M23 -> 11.9 | Y23: =IF(N23="",0,_xlfn.XLOOKUP(W23,マスタ!A:A,マスタ!D:D,0)*M23) -> 0 | Z23: =_xlfn.XLOOKUP(W23,マスタ!A:A,マスタ!E:E,0)*M23 -> 14 | AA23: =_xlfn.XLOOKUP(W23,マスタ!A:A,マスタ!F:F,0)*M23 -> 15.82 | AB23: =_xlfn.XLOOKUP(W23,マスタ!A:A,マスタ!G:G,0)*M23 -> 4.62 | AC23: =_xlfn.XLOOKUP(W23,マスタ!A:A,マスタ!H:H,0)*M23 -> 4.62 | AD23: =SUM(X23:AC23) -> 50.96
D24: フェーズ６：監視環境構築 | I24: 〇 | J24: 〇 | K24: 〇 | L24: 〇 | M24: 2 | W24: より複雑 | X24: =_xlfn.XLOOKUP(W24,マスタ!A:A,マスタ!C:C,0)*M24 -> 11.9 | Y24: =IF(N24="",0,_xlfn.XLOOKUP(W24,マスタ!A:A,マスタ!D:D,0)*M24) -> 0 | Z24: =_xlfn.XLOOKUP(W24,マスタ!A:A,マスタ!E:E,0)*M24 -> 14 | AA24: =_xlfn.XLOOKUP(W24,マスタ!A:A,マスタ!F:F,0)*M24 -> 15.82 | AB24: =_xlfn.XLOOKUP(W24,マスタ!A:A,マスタ!G:G,0)*M24 -> 4.62 | AC24: =_xlfn.XLOOKUP(W24,マスタ!A:A,マスタ!H:H,0)*M24 -> 4.62 | AD24: =SUM(X24:AC24) -> 50.96
D25: フェーズ７：負荷試験 | I25: 〇 | J25: 〇 | K25: 〇 | L25: 〇 | M25: 2 | W25: より複雑 | X25: =_xlfn.XLOOKUP(W25,マスタ!A:A,マスタ!C:C,0)*M25 -> 11.9 | Y25: =IF(N25="",0,_xlfn.XLOOKUP(W25,マスタ!A:A,マスタ!D:D,0)*M25) -> 0 | Z25: =_xlfn.XLOOKUP(W25,マスタ!A:A,マスタ!E:E,0)*M25 -> 14 | AA25: =_xlfn.XLOOKUP(W25,マスタ!A:A,マスタ!F:F,0)*M25 -> 15.82 | AB25: =_xlfn.XLOOKUP(W25,マスタ!A:A,マスタ!G:G,0)*M25 -> 4.62 | AC25: =_xlfn.XLOOKUP(W25,マスタ!A:A,マスタ!H:H,0)*M25 -> 4.62 | AD25: =SUM(X25:AC25) -> 50.96
B26: ネットワーク構築 | X26: =_xlfn.XLOOKUP(W26,マスタ!A:A,マスタ!C:C,0)*M26 -> 0 | Y26: =IF(N26="",0,_xlfn.XLOOKUP(W26,マスタ!A:A,マスタ!D:D,0)*M26) -> 0 | Z26: =_xlfn.XLOOKUP(W26,マスタ!A:A,マスタ!E:E,0)*M26 -> 0 | AA26: =_xlfn.XLOOKUP(W26,マスタ!A:A,マスタ!F:F,0)*M26 -> 0 | AB26: =_xlfn.XLOOKUP(W26,マスタ!A:A,マスタ!G:G,0)*M26 -> 0 | AC26: =_xlfn.XLOOKUP(W26,マスタ!A:A,マスタ!H:H,0)*M26 -> 0 | AD26: =SUM(X26:AC26) -> 0
C27: カスミ→いなげや | H27: いなげやPOSをKTCでのテストのため（Satsfa,カード決済など。） | I27: △ | J27: ー | K27: ー | L27: ー | M27: 0 | W27: より複雑 | X27: =_xlfn.XLOOKUP(W27,マスタ!A:A,マスタ!C:C,0)*M27 -> 0 | Y27: =IF(N27="",0,_xlfn.XLOOKUP(W27,マスタ!A:A,マスタ!D:D,0)*M27) -> 0 | Z27: =_xlfn.XLOOKUP(W27,マスタ!A:A,マスタ!E:E,0)*M27 -> 0 | AA27: =_xlfn.XLOOKUP(W27,マスタ!A:A,マスタ!F:F,0)*M27 -> 0 | AB27: =_xlfn.XLOOKUP(W27,マスタ!A:A,マスタ!G:G,0)*M27 -> 0 | AC27: =_xlfn.XLOOKUP(W27,マスタ!A:A,マスタ!H:H,0)*M27 -> 0 | AD27: =SUM(X27:AC27) -> 0
C28: いなげや→AFS | H28: いなげや様でのWAONチャージ、決済のため | I28: 〇 | J28: ー | K28: ー | L28: ー | M28: 0 | W28: より複雑 | X28: =_xlfn.XLOOKUP(W28,マスタ!A:A,マスタ!C:C,0)*M28 -> 0 | Y28: =IF(N28="",0,_xlfn.XLOOKUP(W28,マスタ!A:A,マスタ!D:D,0)*M28) -> 0 | Z28: =_xlfn.XLOOKUP(W28,マスタ!A:A,マスタ!E:E,0)*M28 -> 0 | AA28: =_xlfn.XLOOKUP(W28,マスタ!A:A,マスタ!F:F,0)*M28 -> 0 | AB28: =_xlfn.XLOOKUP(W28,マスタ!A:A,マスタ!G:G,0)*M28 -> 0 | AC28: =_xlfn.XLOOKUP(W28,マスタ!A:A,マスタ!H:H,0)*M28 -> 0 | AD28: =SUM(X28:AC28) -> 0
C29: Luvina→AFS | H29: カスミ様カード決済、WAONチャージ等 | I29: 〇 | J29: 〇 | K29: 〇 | L29: 〇 | M29: 0 | W29: より複雑 | X29: =_xlfn.XLOOKUP(W29,マスタ!A:A,マスタ!C:C,0)*M29 -> 0 | Y29: =IF(N29="",0,_xlfn.XLOOKUP(W29,マスタ!A:A,マスタ!D:D,0)*M29) -> 0 | Z29: =_xlfn.XLOOKUP(W29,マスタ!A:A,マスタ!E:E,0)*M29 -> 0 | AA29: =_xlfn.XLOOKUP(W29,マスタ!A:A,マスタ!F:F,0)*M29 -> 0 | AB29: =_xlfn.XLOOKUP(W29,マスタ!A:A,マスタ!G:G,0)*M29 -> 0 | AC29: =_xlfn.XLOOKUP(W29,マスタ!A:A,マスタ!H:H,0)*M29 -> 0 | AD29: =SUM(X29:AC29) -> 0
C30: Luvina→VD | H30: ignicaPOINTチャージ、決済 | I30: 〇 | J30: 〇 | K30: 〇 | L30: 〇 | M30: 0 | W30: より複雑 | X30: =_xlfn.XLOOKUP(W30,マスタ!A:A,マスタ!C:C,0)*M30 -> 0 | Y30: =IF(N30="",0,_xlfn.XLOOKUP(W30,マスタ!A:A,マスタ!D:D,0)*M30) -> 0 | Z30: =_xlfn.XLOOKUP(W30,マスタ!A:A,マスタ!E:E,0)*M30 -> 0 | AA30: =_xlfn.XLOOKUP(W30,マスタ!A:A,マスタ!F:F,0)*M30 -> 0 | AB30: =_xlfn.XLOOKUP(W30,マスタ!A:A,マスタ!G:G,0)*M30 -> 0 | AC30: =_xlfn.XLOOKUP(W30,マスタ!A:A,マスタ!H:H,0)*M30 -> 0 | AD30: =SUM(X30:AC30) -> 0
B31: 01_ファイルコピー | X31: =SUM(X32:X33) -> 0 | Y31: =SUM(Y32:Y33) -> 0 | Z31: =SUM(Z32:Z33) -> 0 | AA31: =SUM(AA32:AA33) -> 0 | AB31: =SUM(AB32:AB33) -> 0 | AC31: =SUM(AC32:AC33) -> 0 | AD31: =SUM(AD32:AD33) -> 0 | AE31: =AD31/20 -> 0 | AF31: =AE31*350000 -> 0
B32: Scan&GoServerより、いなげやマスタ連携 | I32: 〇 | K32: ー | L32: ー | M32: 0 | W32: 複雑 | X32: =_xlfn.XLOOKUP(W32,マスタ!A:A,マスタ!C:C,0)*M32 -> 0 | Y32: =IF(N32="",0,_xlfn.XLOOKUP(W32,マスタ!A:A,マスタ!D:D,0)*M32) -> 0 | Z32: =_xlfn.XLOOKUP(W32,マスタ!A:A,マスタ!E:E,0)*M32 -> 0 | AA32: =_xlfn.XLOOKUP(W32,マスタ!A:A,マスタ!F:F,0)*M32 -> 0 | AB32: =_xlfn.XLOOKUP(W32,マスタ!A:A,マスタ!G:G,0)*M32 -> 0 | AC32: =_xlfn.XLOOKUP(W32,マスタ!A:A,マスタ!H:H,0)*M32 -> 0 | AD32: =SUM(X32:AC32) -> 0
B33: 01_BIPROGY様により、マスタファイルの送信先追加 | I33: ー | K33: 〇 | L33: 〇 | M33: 0 | W33: 複雑 | X33: =_xlfn.XLOOKUP(W33,マスタ!A:A,マスタ!C:C,0)*M33 -> 0 | Y33: =IF(N33="",0,_xlfn.XLOOKUP(W33,マスタ!A:A,マスタ!D:D,0)*M33) -> 0 | Z33: =_xlfn.XLOOKUP(W33,マスタ!A:A,マスタ!E:E,0)*M33 -> 0 | AA33: =_xlfn.XLOOKUP(W33,マスタ!A:A,マスタ!F:F,0)*M33 -> 0 | AB33: =_xlfn.XLOOKUP(W33,マスタ!A:A,マスタ!G:G,0)*M33 -> 0 | AC33: =_xlfn.XLOOKUP(W33,マスタ!A:A,マスタ!H:H,0)*M33 -> 0 | AD33: =SUM(X33:AC33) -> 0
B34: 02_外部連携(マスタ) | X34: =SUM(X35:X168) -> 101 | Y34: =SUM(Y35:Y168) -> 5.24 | Z34: =SUM(Z35:Z168) -> 119.28 | AA34: =SUM(AA35:AA168) -> 134.64 | AB34: =SUM(AB35:AB168) -> 39.72 | AC34: =SUM(AC35:AC168) -> 39.72 | AD34: =SUM(AD35:AD168) -> 439.6 | AE34: =AD34/20 -> 21.98 | AF34: =AE34*350000 -> 7693000
B35: 00_sftpサーバー設定 | H35: ファイル受信用にSFTPサーバーの構築 | X35: =_xlfn.XLOOKUP(W35,マスタ!A:A,マスタ!C:C,0)*M35 -> 0 | Y35: =IF(N35="",0,_xlfn.XLOOKUP(W35,マスタ!A:A,マスタ!D:D,0)*M35) -> 0 | Z35: =_xlfn.XLOOKUP(W35,マスタ!A:A,マスタ!E:E,0)*M35 -> 0 | AA35: =_xlfn.XLOOKUP(W35,マスタ!A:A,マスタ!F:F,0)*M35 -> 0 | AB35: =_xlfn.XLOOKUP(W35,マスタ!A:A,マスタ!G:G,0)*M35 -> 0 | AC35: =_xlfn.XLOOKUP(W35,マスタ!A:A,マスタ!H:H,0)*M35 -> 0 | AD35: =SUM(X35:AC35) -> 0
C36: 01_BIPROGY
D37: ディレクトリ作成 | I37: ー | J37: 〇 | K37: 〇 | L37: 〇 | M37: 1 | W37: 簡単 | X37: =_xlfn.XLOOKUP(W37,マスタ!A:A,マスタ!C:C,0)*M37 -> 0.99 | Y37: =IF(N37="",0,_xlfn.XLOOKUP(W37,マスタ!A:A,マスタ!D:D,0)*M37) -> 0 | Z37: =_xlfn.XLOOKUP(W37,マスタ!A:A,マスタ!E:E,0)*M37 -> 1.17 | AA37: =_xlfn.XLOOKUP(W37,マスタ!A:A,マスタ!F:F,0)*M37 -> 1.32 | AB37: =_xlfn.XLOOKUP(W37,マスタ!A:A,マスタ!G:G,0)*M37 -> 0.39 | AC37: =_xlfn.XLOOKUP(W37,マスタ!A:A,マスタ!H:H,0)*M37 -> 0.39 | AD37: =SUM(X37:AC37) -> 4.26
D38: アカウント作成(秘密キー含む) | I38: ー | J38: 〇 | K38: 〇 | L38: 〇 | M38: 1 | W38: 簡単 | X38: =_xlfn.XLOOKUP(W38,マスタ!A:A,マスタ!C:C,0)*M38 -> 0.99 | Y38: =IF(N38="",0,_xlfn.XLOOKUP(W38,マスタ!A:A,マスタ!D:D,0)*M38) -> 0 | Z38: =_xlfn.XLOOKUP(W38,マスタ!A:A,マスタ!E:E,0)*M38 -> 1.17 | AA38: =_xlfn.XLOOKUP(W38,マスタ!A:A,マスタ!F:F,0)*M38 -> 1.32 | AB38: =_xlfn.XLOOKUP(W38,マスタ!A:A,マスタ!G:G,0)*M38 -> 0.39 | AC38: =_xlfn.XLOOKUP(W38,マスタ!A:A,マスタ!H:H,0)*M38 -> 0.39 | AD38: =SUM(X38:AC38) -> 4.26
C39: 31_Scan&Go(カスミ)
D40: ディレクトリ作成 | I40: ー | J40: 〇 | K40: 〇 | L40: 〇 | M40: 1 | W40: 簡単 | X40: =_xlfn.XLOOKUP(W40,マスタ!A:A,マスタ!C:C,0)*M40 -> 0.99 | Y40: =IF(N40="",0,_xlfn.XLOOKUP(W40,マスタ!A:A,マスタ!D:D,0)*M40) -> 0 | Z40: =_xlfn.XLOOKUP(W40,マスタ!A:A,マスタ!E:E,0)*M40 -> 1.17 | AA40: =_xlfn.XLOOKUP(W40,マスタ!A:A,マスタ!F:F,0)*M40 -> 1.32 | AB40: =_xlfn.XLOOKUP(W40,マスタ!A:A,マスタ!G:G,0)*M40 -> 0.39 | AC40: =_xlfn.XLOOKUP(W40,マスタ!A:A,マスタ!H:H,0)*M40 -> 0.39 | AD40: =SUM(X40:AC40) -> 4.26
D41: アカウント作成(秘密キー含む) | I41: ー | J41: 〇 | K41: 〇 | L41: 〇 | M41: 1 | W41: 簡単 | X41: =_xlfn.XLOOKUP(W41,マスタ!A:A,マスタ!C:C,0)*M41 -> 0.99 | Y41: =IF(N41="",0,_xlfn.XLOOKUP(W41,マスタ!A:A,マスタ!D:D,0)*M41) -> 0 | Z41: =_xlfn.XLOOKUP(W41,マスタ!A:A,マスタ!E:E,0)*M41 -> 1.17 | AA41: =_xlfn.XLOOKUP(W41,マスタ!A:A,マスタ!F:F,0)*M41 -> 1.32 | AB41: =_xlfn.XLOOKUP(W41,マスタ!A:A,マスタ!G:G,0)*M41 -> 0.39 | AC41: =_xlfn.XLOOKUP(W41,マスタ!A:A,マスタ!H:H,0)*M41 -> 0.39 | AD41: =SUM(X41:AC41) -> 4.26
C42: 32_Scan&Go(いなげや)
D43: ディレクトリ作成 | I43: 〇 | J43: ー | K43: ー | L43: ー | M43: 1 | W43: 簡単 | X43: =_xlfn.XLOOKUP(W43,マスタ!A:A,マスタ!C:C,0)*M43 -> 0.99 | Y43: =IF(N43="",0,_xlfn.XLOOKUP(W43,マスタ!A:A,マスタ!D:D,0)*M43) -> 0 | Z43: =_xlfn.XLOOKUP(W43,マスタ!A:A,マスタ!E:E,0)*M43 -> 1.17 | AA43: =_xlfn.XLOOKUP(W43,マスタ!A:A,マスタ!F:F,0)*M43 -> 1.32 | AB43: =_xlfn.XLOOKUP(W43,マスタ!A:A,マスタ!G:G,0)*M43 -> 0.39 | AC43: =_xlfn.XLOOKUP(W43,マスタ!A:A,マスタ!H:H,0)*M43 -> 0.39 | AD43: =SUM(X43:AC43) -> 4.26
...

Sheet データ連携先
B2: ※カスミ | D2: ID | E2: PASS | G2: 転送手段 | H2: ディレクトリ | I2: ファイル名 | K2: タイミング | L2: ステータス
B3: 11 | C3: BIPROGY株式会社 | F3: INPUT | H3: /IN_BIPROGY/Master/GHPLUM/ | I3: ＰＬＵメンテ | J3: GHPLUM.CSV | K3: 日次マスタ：21時30分 | L3: 青柳さんにお願い
I4: 企画メンテ | J4: GHEVENTM.CSV | K4: 日次マスタ：21時30分
I5: 組合せメンテ | J5: GHBUNDLEM.CSV | K5: 日次マスタ：21時30分
I6: 特売メンテ | J6: GHDISCOUNTM.CSV | K6: 日次マスタ：21時30分
I7: 商品階層メンテデータ | J7: GMMDSEM.CSV | K7: 日次マスタ：21時30分
I8: 商品ポイント加算 | J8: GHPLUPOINT.CSV | K8: 日次マスタ：21時30分
I9: POPマスター(商品情報) | J9: P001 | K9: 日次マスタ：21時30分
I10: 棚番マスタ(P003)(出力もとはシャープどうする？) | J10: P003 | K10: 日次マスタ：22時
I11: 予算 | J11: plbc9176.s01 | K11: 月次マスタ（予算マスタ）：18時00分 月末日マイナス+5
F12: OUTPU | H12: /OUT_BIPROGY/Result/{店舗番号} | I12: 情報系時間帯実績 | J12: PLUFLASH_YYYYMMDD.CSV | K12: ・前日分：AM７時５分にGETする。※過去７日分まで取込可能
K13: ・毎時：９時～２４時に毎時５分にGETする。
H14: /OUT_BIPROGY/Result/ | I14: 単品別売上合計 | J14: GHPLUSUM.CSV | K14: 日次データは [テーブル名].CSVを作成する。2時00分迄 日次データは [テーブル名].CSVを作成する。2時15分 受信開始 レジ精算は、2時に間に合わなかった場合は7時に差分だけ送る。
I15: 単品別売上値引 | J15: GHPLUDISC.CSV
I16: 特売実施実績 | J16: KDISCRESULT.CSV
I17: 廃棄実施実績 | J17: KSCRAPSND.CSV
I18: レジ精算データ | J18: KSTORECLOSE.CSV
I19: 店内使用（経費） | J19: GHPLUTASTE.CSV
B20: 12 | C20: 株式会社アイネス | F20: INPUT | G20: ー | H20: ー | K20: ー
F21: OUTPU | G21: PUT | I21: スマートPOSクレジット対応_IFファイル (スーパーストリーム) | J21: 00100_店番前ゼロ4桁+00_YYYYMMDDHHMMSS.CSV | K21: 3時00分受信開始
H22: {アイネス様FTPサーバー}/posvinx | I22: POS分析：POSデータ(ｲｸﾞﾆｶﾏﾈｰ支払情報アリ）タイトル | J22: YYYYMMDD_店番前ゼロ6桁_ts.tar.gz | K22: 3時00分受信開始
I23: POS分析：POSデータ(ｲｸﾞﾆｶﾏﾈｰ支払情報ナシ）明細この中にWAONポイント
I24: POS分析：WAONポイントデータクレジット | J24: 圧縮
B25: 13 | C25: 株式会社ソフテック | F25: INPUT
F26: OUTPU
B27: 14 | C27: イオンフィナンシャルサービス株式会社 (GC企画) | F27: INPUT
F28: OUTPU | H28: 売上確定累積データ(IC対応) | I28: 売上確定累積データ(IC対応) | J28: Ruriic.dat
B29: 15 | C29: シャープマーケティングジャパン株式会社 | F29: INPUT | I29: 棚番マスタ(P003) | J29: P003 | K29: 日次マスタ：21時30分
F30: OUTPU | I30: 店舗マスタ | J30: RM_STRMyyyyMMddHHmmsssss.tsv | K30: マスター更新は、日中の差分更新、夜間のメンテナンス処理時の２通りあります。 AM 03:00 ～ 06:00 は メンテナンス時間帯となります。SHARPOPサーバーの再起動を行うため、差分更新用のファイルの配置をしないようにお願いいたします。
I31: 大分類(部門)マスタ | J31: RM_MGRMyyyyMMddHHmmsssss.tsv
I32: 中分類(品群)マスタ | J32: RM_MIDMyyyyMMddHHmmsssss.tsv
I33: 小分類(品種)マスタ | J33: RM_MNRMyyyyMMddHHmmsssss.tsv
I34: 分類マスタ | J34: RM_DIVMyyyyMMddHHmmsssss.tsv
I35: 消費税率マスタ | J35: RM_SZEIyyyyMMddHHmmsssss.txt
I36: 大分類別消費税率マスタ | J36: RM_DAIZyyyyMMddHHmmsssss.tsv
I37: 産地マスタ | J37: RM_SANMyyyyMMddHHmmsssss.tsv
B38: 16 | C38: 株式会社 イシダ | F38: INPUT | G38: ー | H38: ー
F39: OUTPU | G39: ？ | H39: /OUT_ISHIDA/{店舗番号} | I39: 商品マスタ送信 | J39: [店舗番号下3桁]＋[固定 "000"3桁]＋[年月日8桁]＋[時刻6桁]SHOHIN.TXT | K39: ■全件 新店時のみ ■差分 毎朝5:00頃
I40: 売価送信(一括) | J40: [店舗番号下3桁]＋[固定 "000"3桁]＋[年月日8桁]＋[時刻6桁]ESLDATA.TXT | K40: ■全件 毎朝5:30頃 ■差分 日中
I41: 売価送信(更新)
...

Sheet マスタ
A1: ー | C1: 設計 | D1: モック | E1: Code | F1: FT | G1: IT | H1: PT
A2: より簡単 | B2: Rất Dễ | C2: 0.5 | D2: 0.15 | E2: 0.58 | F2: 0.66 | G2: 0.19 | H2: 0.19
A3: 簡単 | B3: Dễ | C3: 0.99 | D3: 0.29 | E3: 1.17 | F3: 1.32 | G3: 0.39 | H3: 0.39
A4: 普通 | B4: Trung bình | C4: 1.98 | D4: 0.58 | E4: 2.33 | F4: 2.64 | G4: 0.77 | H4: 0.77
A5: 複雑 | B5: Khó | C5: 2.98 | D5: 0.88 | E5: 3.5 | F5: 3.96 | G5: 1.16 | H5: 1.16
A6: より複雑 | B6: Rất khó | C6: 5.95 | D6: 1.75 | E6: 7 | F6: 7.91 | G6: 2.31 | H6: 2.31
A8: 【重複】より簡単 | B8: Rất Dễ | C8: 0.5 | D8: 0.15 | E8: 0.58 | F8: 0.66 | G8: 0.19 | H8: 0.19
A9: 【重複】簡単 | B9: Dễ | C9: 0.99 | D9: 0.29 | E9: 1.17 | F9: 1.32 | G9: 0.39 | H9: 0.39
A10: 【重複】普通 | B10: Trung bình | C10: 1.98 | D10: 0.58 | E10: 2.33 | F10: 2.64 | G10: 0.77 | H10: 0.77
A11: 【重複】複雑 | B11: Khó | C11: 2.98 | D11: 0.88 | E11: 3.5 | F11: 3.96 | G11: 1.16 | H11: 1.16
A12: 【重複】より複雑 | B12: Rất khó | C12: 5.95 | D12: 1.75 | E12: 7 | F12: 7.91 | G12: 2.31 | H12: 2.31

Sheet 機能一覧（POSサーバー）
B1: 〇：対象 △：開発中 -：未着手 ×：想定外 | U1: 行高さ調整
B3: 機能概要 | E3: 残工数 （人月） | F3: POSサーバ | T3: 進捗
F4: 1.5 いなげや | M4: 2.0 カスミ・いなげや
F6: 設計 | H6: 製造 | I6: 試験 | J6: 修正・ 調整 | K6: 完了予定 | L6: 完了実績 | M6: 設計 | O6: 製造 | P6: 試験 | Q6: 修正・ 調整 | R6: 完了予定 | S6: 完了実績
F7: 基本 | G7: 詳細 | M7: 基本 | N7: 詳細
B8: インフラ | U8: =REPT("a"&CHAR(10)&"b",INT(LENB(SUBSTITUTE(T8,CHAR(10),""))/70))
C9: AWS構築 | D9: ステージング環境構築 | E9: 0 | F9: 〇 8/14 | H9: 〇 8/21 | I9: 〇 | J9: 〇 | K9: 2024年9月 | L9: 45566 | M9: 〇 8/14 | O9: 〇 8/21 | P9: 〇 | Q9: 〇 | R9: 2024年9月 | S9: 45566 | T9: 構築済み・9月第1週までに検証作業を完成させる 10月中からS＆Gのマスタと同じようデータベースの構成を見直し
D10: 本番環境構築 | F10: - | H10: - | I10: - | J10: - | K10: - | L10: - | M10: - | O10: - | P10: - | Q10: - | R10: - | S10: - | T10: 構築作業未着手 | U10: =REPT("a"&CHAR(10)&"b",INT(LENB(SUBSTITUTE(T10,CHAR(10),""))/70))
B11: ログイン・ログアウト | U11: =REPT("a"&CHAR(10)&"b",INT(LENB(SUBSTITUTE(T11,CHAR(10),""))/70))
B12: X0 | C12: ログイン機能 | D12: アカウントID、パスワードでシステムにログインを行う。 | E12: 0 | F12: 〇 6/11 | G12: △ 12月 | H12: 〇 8/16 | I12: 〇 | J12: △ | K12: 2024年9月 | L12: 2024年9月 | M12: 〇 6/11 | N12: △ 12月 | O12: 〇 8/16 | P12: 〇 | Q12: △ | R12: 2024年9月 | S12: 45536 | T12: 詳細設計指摘対応中 | U12: =REPT("a"&CHAR(10)&"b",INT(LENB(SUBSTITUTE(T12,CHAR(10),""))/70))
B13: メニュー | U13: =REPT("a"&CHAR(10)&"b",INT(LENB(SUBSTITUTE(T13,CHAR(10),""))/70))
B14: X1 | C14: メニュー機能 | D14: 機能一覧を表示する。 | E14: 0 | F14: 〇 7/26 | G14: △ 11/14 | H14: 〇 8/16 | I14: 〇 ９/13 | J14: △ | K14: 2024年9月 | L14: 45566 | M14: 〇 7/26 | N14: △ 11/14 | O14: 〇 8/16 | P14: 〇 ９/13 | Q14: △ | R14: 2024年9月 | S14: 45566 | T14: 自社での詳細設計が完了。カスミ様確認待ち | U14: =REPT("a"&CHAR(10)&"b",INT(LENB(SUBSTITUTE(T14,CHAR(10),""))/70))
B15: プリセット系 | U15: =REPT("a"&CHAR(10)&"b",INT(LENB(SUBSTITUTE(T15,CHAR(10),""))/70))
B16: 15 | C16: タッチメニュー設定 | D16: タッチメニュー設定機能により、次のことが可能になる。 ・店舗のレイアウトプリセットを管理する。 ‣ビジネスレイアウト一覧を見る。 ‣1種類のビジネスレイアウトの詳細を見る。 ‣ビジネスレイアウトを検索する。 ・店舗のビジネスレイアウトを設定する。 ‣新規作成 ‣編集 ‣削除 ‣コピー ・1種類のビジネスレイアウトの詳細を設定する。 ‣ ビジネスレイアウトのレイアウトプリセットの変更：名称、色など ‣ボタンレイアウトプリセットを変更する。 ●色、イメージ、名称、サイズ、有効・無効など ●ボタンレイアウトプリセットの機能：商品、クーポン、割引など | E16: 0 | F16: △ 7/19 | G16: △ 11/9 | H16: 〇 ９/13 | I16: 〇 | J16: 〇 | K16: 2024年9月 | L16: 45597 | M16: △ 7/19 | N16: △ 11/19 | O16: 〇 ９/13 | P16: 〇 | Q16: 〇 | R16: 2024年9月 | S16: 45597 | T16: 自社での詳細設計が完了。カスミ様確認待ち | U16: =REPT("a"&CHAR(10)&"b",INT(LENB(SUBSTITUTE(T16,CHAR(10),""))/70))
B17: 62 | C17: 画像アップロード | D17: 画像アップロード機能では次のことが可能になる。 店舗のプリセット画像、レシートロゴを説明する画像を管理する。 ・現存説明画像の一覧を閲覧する。 ・説明画像を追加する。 ・現存説明画像を削除する。 | E17: 0 | F17: △ | G17: △ | H17: × | I17: × | J17: × | K17: × | L17: × | M17: △ | N17: △ | O17: - | P17: - | Q17: - | R17: 45689 | S17: - | T17: 基本設計指摘対応中 | U17: =REPT("a"&CHAR(10)&"b",INT(LENB(SUBSTITUTE(T17,CHAR(10),""))/70))
B18: ジャーナル系 | U18: =REPT("a"&CHAR(10)&"b",INT(LENB(SUBSTITUTE(T18,CHAR(10),""))/70))
B19: 21 | C19: ジャーナル検索 | D19: 開始・終了日、開始・終了時刻の時間帯、最大検索件数によりジャーナル一覧を検索する。 また、レシートNo.、担当者、任意文字列（キーワード）からも検索できる。 検索結果取得後、選択されたレシートのイメージ一覧を表示でき、印刷できる。 | E19: 2.5 | F19: 〇 10/01 | G19: 〇 11/15 | H19: 〇 | I19: 〇 | J19: △ | K19: 2024年9月 | L19: 45597 | M19: △ 8/23 | N19: 〇 11/15 | O19: 〇 | P19: 〇 | Q19: △ | R19: 2024年9月 | S19: 45597 | T19: 自社での詳細設計が完了。カスミ様確認待ち | U19: =REPT("a"&CHAR(10)&"b",INT(LENB(SUBSTITUTE(T19,CHAR(10),""))/70))
B20: レジ系・釣銭機関連 | U20: =REPT("a"&CHAR(10)&"b",INT(LENB(SUBSTITUTE(T20,CHAR(10),""))/70))
B21: 33 | C21: 釣銭機状況照会 | D21: 釣銭機状況照会機能では次のことが可能になる。 ・¥1, ¥5, ¥10, ¥50, ¥100, ¥500, ¥1000, ¥2000, ¥5000, ¥10000の金種の保留枚数に応じて各レジの残額と補充額を閲覧する ・各レジの補充金額情報をpdfファイルで出力する。 | E21: 0.68 | F21: △ 8/19 | G21: △ 8/19 | H21: 〇 | I21: 〇 | J21: △ | K21: 45597 | L21: 45597 | M21: △ 8/19 | N21: △ 8/19 | O21: 〇 | P21: 〇 | Q21: △ | R21: 45597 | S21: 45597 | T21: ` | U21: =REPT("a"&CHAR(10)&"b",INT(LENB(SUBSTITUTE(T21,CHAR(10),""))/70))
B22: 71 | C22: レジマスタ設定 | D22: レジマスタ設定機能では次のことが可能になる。 レジのマスタ情報を表示する。 レジのマスタ情報を追加・編集・削除する。 レジのマスタ情報をCSVファイルで取込・出力。 | E22: 0 | F22: △ 8/23 | G22: △ 11/6 | H22: 〇 | I22: △ | J22: △ | K22: 45536 | L22: 45597 | M22: △ 8/23 | N22: △ | O22: 〇 | P22: △ | Q22: △ | R22: 45536 | S22: 45597 | T22: 仕様変更により基本設計・詳細設計更新中 | U22: =REPT("a"&CHAR(10)&"b",INT(LENB(SUBSTITUTE(T22,CHAR(10),""))/70))
B23: 取引系 | U23: =REPT("a"&CHAR(10)&"b",INT(LENB(SUBSTITUTE(T23,CHAR(10),""))/70))
B24: 16 | C24: 保留_保留解除 | D24: レジ操作で、保留_保留解除作業を行う。 | E24: 0 | F24: △ | G24: - | H24: - | I24: - | J24: - | K24: × | L24: × | M24: △ | N24: - | O24: - | P24: - | Q24: - | R24: 未定 | S24: - | U24: =REPT("a"&CHAR(10)&"b",INT(LENB(SUBSTITUTE(T24,CHAR(10),""))/70))
B25: 商品系 | T25: 商品マスタの登録内容が不明 | U25: =REPT("a"&CHAR(10)&"b",INT(LENB(SUBSTITUTE(T25,CHAR(10),""))/70))
B26: 01 | C26: 商品管理 | D26: 商品管理機能は、 ・商品情報詳細をビューする。 ・1, 7, 8 定番売価変更が可能 ・当日の緊急売価を変更する。 ・特売売価設定を新規作成・編集する ・ミックスマッチ新規・編集機能 | E26: 5.52 | F26: △ 09/25 | G26: △ 12月 | H26: - | I26: - | J26: - | K26: × | L26: × | M26: 〇 7/24 | N26: 12月 | O26: - | P26: - | Q26: - | R26: 45627 | S26: - | T26: 削除機能についてカスミ様は検討中 | U26: =REPT("a"&CHAR(10)&"b",INT(LENB(SUBSTITUTE(T26,CHAR(10),""))/70))
B27: 02 | C27: 緊急売価変更 | D27: 緊急売価変更機能により、次のことが可能になる。 ・複数商品の緊急売価を同時に変更する。（変更日のみ店舗適用） ・変更日が過ぎると、緊急売価が無効になり、クリアする必要がある。 | E27: 0.41 | F27: 〇 7/29 | G27: △ 12月 | H27: - | I27: - | J27: - | K27: × | L27: × | M27: 〇 7/29 | N27: 12月 | O27: △ | P27: - | Q27: - | R27: 45627 | S27: - | U27: =REPT("a"&CHAR(10)&"b",INT(LENB(SUBSTITUTE(T27,CHAR(10),""))/70))
B28: 03 | C28: 店舗特売入力 | D28: 特売マスタ売価設定機能 ・商品コード、PLU入力を行い、登録情報の閲覧や、特売売価の変更を行う。 ・商品の特売売価設定または割引設定を行う。 ・夜間バッチを使用して特売売価を削除し、過去の特売割引を行う。 ・終了日が7日以前の特売情報を削除する。 ・当日の商品情報がない特売マスタを削除する。 ・当日の商品情報がないプロモーション情報を削除する。 | E28: 0 | F28: 〇 10/6 | G28: △ 12月 | H28: - | I28: - | J28: - | K28: × | L28: × | M28: 〇 | N28: △ 12月 | O28: 〇 | P28: 〇 | Q28: △ | R28: 45597 | S28: - | U28: =REPT("a"&CHAR(10)&"b",INT(LENB(SUBSTITUTE(T28,CHAR(10),""))/70))
B29: 04 | C29: 商品採用店舗確認 | D29: 商品採用店舗確認機能では次のことが可能になる。 ・PLUコード*を入力して、どのスーパーに商品があるか確認する。 ・「カスミ」又は「ウエルシア」の売上計算が必要な情報は編集可能。 | E29: 1.1 | F29: 〇 5/30 | G29: △ | H29: - | I29: - | J29: - | K29: × | L29: × | M29: 〇 5/30 | N29: △ | O29: - | P29: - | Q29: - | R29: 45717 | S29: - | U29: =REPT("a"&CHAR(10)&"b",INT(LENB(SUBSTITUTE(T29,CHAR(10),""))/70))
B30: 05 | C30: ミックスマッチ設定 | D30: ミックスマッチ設定機能 ・ミックスマッチ情報を設定する。 ‣新規作成 ‣修正 ‣削除：夜間バッチを使用して過去のミックスマッチ情報を削除する。 ●終了日が7日前のミックスマッチ情報を削除する。 ●現時点での商品情報がないミックスマッチ情報を削除する。 ●現時点でのプロモーション情報がないミックスマッチ情報を削除する。 ・商品コード、PLU入力を行い、登録情報の閲覧や、売価の変更を行う。 ・プロモーションコードに紐づけられたミックスマッチコードに従って商品を設定する。1 つのミックスマッチコードで複数の商品設定が可能 ・ミックスマッチの有効期間はプロモーション期間内のみ設定可能 ・ミックスマッチ設定を行う場合、商品の数量と売価を入力する必要がある。10つのミックスマッチオプション設定可能 ・売価、割引、値引によるミックスマッチ設定可能 | E30: 0.85 | F30: △ 8/2 | G30: △ 12月 | H30: - | I30: - | J30: - | K30: × | L30: × | M30: △ 8/2 | N30: 12月 | O30: 〇 | P30: - | Q30: - | R30: 45627 | S30: - | U30: =REPT("a"&CHAR(10)&"b",INT(LENB(SUBSTITUTE(T30,CHAR(10),""))/70))
B31: 06 | C31: 1, 7, 8 定番売価変更 | D31: 1, 7, 8 定番変更機能により次のことが可能になる。 ・1、7、8部門の各商品の定番売価を毎日変更する。売価は当日以降のみ変更可能。 ・定番売価変更履歴を日付・部門別に検索する。 ・ 売価変更金額は当日のみ有効、売価変更が最優先になる。 ・毎日バッチを実行して定番売価を更新する。 | E31: 0.31 | F31: 〇 10/14 | G31: △ 12月 | H31: - | I31: - | J31: - | K31: × | L31: × | M31: △ 8/2 | N31: 12月 | O31: - | P31: - | Q31: - | R31: 45627 | S31: - | T31: 詳細設計指摘あり | U31: =REPT("a"&CHAR(10)&"b",INT(LENB(SUBSTITUTE(T31,CHAR(10),""))/70))
B32: 07 | C32: セットマッチ設定 | D32: セットマッチ設定機能 ・セットマッチ情報を設定する。 ‣新規作成 ‣修正 ・削除：夜間実行セットマッチを削除するバッチ、または画面上で削除するバッチがある。 ・プロモーションコードに紐づけられたセットマッチコードに従って商品を設定する。1つのセットマッチコードで複数の設定が可能。 ・セットマッチの有効期間はプロモーション期間内のみ設定可能。 ・セットマッチ設定時にセットマッチの1つ製品グループの購入対象商品数を入力する必要がある。 ・売価、割引、値引によるセットマッチ設定可能。 | E32: 1.47 | F32: 〇 8/8 | G32: - | H32: - | I32: - | J32: - | K32: × | L32: × | M32: △ | N32: 6月 | O32: - | P32: - | Q32: - | R32: 45809 | S32: - | U32: =REPT("a"&CHAR(10)&"b",INT(LENB(SUBSTITUTE(T32,CHAR(10),""))/70))
B33: プリセット系 | U33: =REPT("a"&CHAR(10)&"b",INT(LENB(SUBSTITUTE(T33,CHAR(10),""))/70))
B34: 18 | C34: 小計タッチメニュー設定 | E34: 1.47 | F34: △ | G34: - | H34: - | I34: - | J34: - | K34: × | L34: × | M34: △ | N34: 2月 | O34: - | P34: - | Q34: - | R34: 45717 | S34: - | T34: 自社での基本設計が完了。カスミ様確認待ち | U34: =REPT("a"&CHAR(10)&"b",INT(LENB(SUBSTITUTE(T34,CHAR(10),""))/70))
B35: レジ系・釣銭機関連 | U35: =REPT("a"&CHAR(10)&"b",INT(LENB(SUBSTITUTE(T35,CHAR(10),""))/70))
B36: 20 | C36: レジ精算入力 | D36: レジ精算入力機能では次のことが可能になる。 ・店舗のレジの状態を表示する。 ・選択した日付ごとにより店舗全体の売上が出力可能 ‣ログインユーザーが管理者ユーザーの場合、62日以内選択可能 ‣ログインユーザーが管理者ユーザーではない場合、当日から直近3日選択可能 ・レジごとの詳細売上を表示して実際で金額が編集可能 ・レジが精算を忘れた場合、POSサーバーがバッチを使用して自動的に精算する。 | E36: 2.04 | F36: 〇 11/28 | G36: - | H36: - | I36: - | J36: - | K36: × | L36: × | M36: 〇 11/28 | N36: 4月 | O36: - | P36: - | Q36: - | R36: 45778 | S36: - | T36: 自社での基本設計が完了。カスミ様確認待ち | U36: =REPT("a"&CHAR(10)&"b",INT(LENB(SUBSTITUTE(T36,CHAR(10),""))/70))
B37: 81 | C37: 釣銭機警告設定 | D37: 釣銭機警告設定機能では次のことが可能になる。 ・釣銭機の補充警告を設定する。 ・釣銭機の回収警告を設定する。 | E37: 0.8 | F37: 〇 7/23 | G37: - | H37: - | I37: - | J37: - | K37: × | L37: × | M37: 〇 7/23 | N37: 1月 | O37: - | P37: - | Q37: - | R37: 2025年2月 | S37: -
B38: 73 | C38: レジ状況照会 | D38: レジ状況照会機能では次のことが可能になる。 ・日別（過去・未来の日も選択可能）に1つ又は複数の店舗のレジ状況照会一覧 とステータス(全通常と全異常）を検索して表示する。 ・各レジの状況詳細を以下のように閲覧する。状態, 営業日、営業回数、開設回数、担当者、ダウンロードマスターバージョン、反映済マスターパージョンなど | E38: 2.04 | F38: △ | G38: - | H38: - | I38: - | J38: - | K38: × | L38: × | M38: △ | N38: 2月 | O38: - | P38: - | Q38: - | R38: 2025年2月 | S38: - | T38: 基本設計指摘あり | U38: =REPT("a"&CHAR(10)&"b",INT(LENB(SUBSTITUTE(T38,CHAR(10),""))/70))
T39: 商品マスタの登録内容が不明 | U39: =REPT("a"&CHAR(10)&"b",INT(LENB(SUBSTITUTE(T39,CHAR(10),""))/70))
B40: 08 | C40: カテゴリ値引・割引設定 | D40: カテゴリ値引/割引設定機能によりカテゴリ値引・割引の新規作成・更新・削除が可能 カテゴリ階層は次の通りである。 01:部門 02.品群 03.品種 04.分類 | E40: 2.04 | F40: 〇 10/22 | G40: - | H40: - | I40: - | J40: - | K40: × | L40: × | M40: △ | N40: 12月 | O40: - | P40: - | Q40: - | R40: 45627 | S40: - | U40: =REPT("a"&CHAR(10)&"b",INT(LENB(SUBSTITUTE(T40,CHAR(10),""))/70))
B41: 10 | C41: プロモーションメンテ | D41: プロモーションメンテには次のことが可能になる。 ・プロモーション検索 ・プロモーション情報表示 ・プロモーション設定編集 ・プロモーション新規作成 ・プロモーション削除 ・毎晩バッチ処理により、終了日が現在日より7日以上前のプロモーションコードを削除する。 | E41: 0 | F41: 〇 7/31 | G41: △ 12月 | H41: - | I41: - | J41: - | K41: × | L41: × | M41: 〇 7/31 | N41: 12月 | O41: - | P41: - | Q41: - | R41: 45627 | S41: - | U41: =REPT("a"&CHAR(10)&"b",INT(LENB(SUBSTITUTE(T41,CHAR(10),""))/70))
B42: 22 | C42: クレジット小計割引設定 | D42: クレジット小計割引設定機能では次のことが可能になる。 ・クレジットカードで支払う時の毎週又は毎月の割引を閲覧、設定する。 ・その後の全ての月に適用される。 ・バッチを実行してクレジット小計割引日を設定する。 ・会社のクレジットカードを使用してその会社の店舗で購入した顧客に直接割引を適用する。 | E42: 0.8 | F42: 〇 6/13 | G42: - | H42: - | I42: - | J42: - | K42: × | L42: × | M42: 〇 6/13 | N42: 2月 | O42: - | P42: - | Q42: - | R42: 45689 | S42: - | U42: =REPT("a"&CHAR(10)&"b",INT(LENB(SUBSTITUTE(T42,CHAR(10),""))/70))
...

Sheet テンプレート
A1: システム名 | K1: システム種別 | W1: =IF(表紙!W1="","",表紙!W1) -> 概要設計 | AP1: 作成者 | AT1: 作成日 | AY1: 更新者 | BC1: 更新日 | BH1: 版数
A2: =IF(表紙!A2="","",表紙!A2) -> POSサーバ | K2: =IF(表紙!K2="","",表紙!K2) -> 全般 | AP2: =IF(表紙!AP2="","",表紙!AP2) -> Huy Nguyen | AT2: =IF(表紙!AT2="","",表紙!AT2) -> 45532 | AY2: =IF(表紙!AY2="","",表紙!AY2) | BC2: =IF(表紙!BC2="","",表紙!BC2) | BH2: =IF(表紙!BH2="","",表紙!BH2) -> 0.31
A4: 機能カテゴリ | H4: =IF(表紙!H4="","",表紙!H4) -> 機能一覧 | U4: 項目 | Z4: =IF(表紙!Z4="","",表紙!Z4) -> いなげや様向け | AP4: {=RIGHT(CELL("filename",$A$1),LEN(CELL("filename",$A$1))-FIND("]",CELL("filename",$A$1)))} -> #VALUE!
