Workbook

Sheet 表紙
A1: XXX基本設計 | L1: 大分類 | V1: 中分類 | AF1: 小分類 | AP1: 作成者 | AU1: 作成日 | AZ1: 更新日
L2: 基本設計書 | V2: - | AF2: =RIGHT(CELL("filename",$A$2),LEN(CELL("filename",$A$2))-FIND("]",CELL("filename",$A$2))) -> #VALUE! | AU2: 45078 | AZ2: 45635
D9: XXX 基本設計書
AV16: 版番 | AZ16: 1.2

Sheet 変更履歴
A1: =表紙!A1 -> XXX基本設計 | L1: 大分類 | V1: 中分類 | AF1: 小分類 | AP1: 作成者 | AU1: 作成日 | AZ1: 更新日
L2: =表紙!L2 -> 基本設計書 | V2: =表紙!V2 -> - | AF2: =RIGHT(CELL("filename",$A$2),LEN(CELL("filename",$A$2))-FIND("]",CELL("filename",$A$2))) -> #VALUE! | AU2: =表紙!AU2 -> 45078 | AZ2: 45635
B4: 発行日 | F4: 版 | I4: 変更箇所 | W4: 発行／改定内容 | BB4: 変更者
B5: =表紙!AU2 -> 45078 | F5: 1.00 | W5: 初版発行
B6: 45082 | F6: 1.01 | I6: 別紙１．構成図 | W6: 環境名を「顧客A環境⇒個別環境A」に変更 | BB6: クレスコ
B7: 45082 | F7: 1.01 | I7: ８．運用機能設計 | W7: アクセス数確認運用を追記 | BB7: クレスコ
B8: 45086 | F8: 1.02 | I8: ８．運用機能設計 | W8: ログ保管期限要件を削除 | BB8: クレスコ
B9: 45099 | F9: 1.03 | I9: ４．セキュリティ設計 | W9: パスワード期限を追記 | BB9: クレスコ
B10: 45099 | F10: 1.03 | I10: ８．運用機能設計 | W10: 「c.リリース先バケット」に言語の限定について追記 | BB10: クレスコ
B11: 45105 | F11: 1.04 | I11: ８．運用機能設計 | W11: 「c.リリース先バケット」にファイル形式の限定について追記 | BB11: クレスコ
B12: 45467 | F12: 1.1 | I12: ２．システム構成 | W12: ドメイン運用に テンプレート環境 という文言を追記 | BB12: クレスコ
B13: 45467 | F13: 1.1 | I13: ３．可用性設計 | W13: ３．２項以降を削除 | BB13: クレスコ
B14: 45467 | F14: 1.1 | I14: ４．セキュリティ設計 | W14: IAMグループの改訂、OV証明書について追記 | BB14: クレスコ
B15: 45467 | F15: 1.1 | I15: ４．セキュリティ設計 | W15: 初期パスワード強制変更、２要素認証強制化について追記 | BB15: クレスコ
B16: 45467 | F16: 1.1 | I16: ６．バックアップ・リストア設計 | W16: コンテンツデータ管理について追記 | BB16: クレスコ
B17: 45467 | F17: 1.1 | I17: ８．運用機能設計 | W17: 環境破棄、リリース運用に関する改訂 | BB17: クレスコ
... B25: 45635 | F25: 1.2 | I25: 別紙1.構成図 | W25: CodeCommit廃止対応後の構成を追加 | BB25: クレスコ

Sheet 目次
A1: =表紙!A1 -> XXX基本設計 | L1: 大分類 | V1: 中分類 | AF1: 小分類 | AP1: 作成者 | AU1: 作成日 | AZ1: 更新日
L2: =表紙!L2 -> 基本設計書 | V2: =表紙!V2 -> - | AF2: =RIGHT(CELL("filename",$A$2),LEN(CELL("filename",$A$2))-FIND("]",CELL("filename",$A$2))) -> #VALUE! | AU2: =表紙!AU2 -> 45078
B4: １．はじめに | AH4: ５．ログ運用設計
C5: １．１．案件の目的 | AI5: ５．１ ログ運用方針
C6: １．２．本書の記述範囲 | AI6: ５．２ ログ運用
AI7: ５．３ ログ保管期間
B8: ２．システム構成
C9: ２．１ 本環境構成 | AH9: ６．バックアップ・リストア運用設計
C10: ２．２ 通信経路 | AI10: ６．１ バックアップ・リストア運用方針
C11: ２．３ ドメイン運用 | AI11: ６．２ バックアップ運用
C12: ２．４ サービス一覧 | AI12: ６．３ リストア運用
B14: ３．可用性設計 | AH14: ７．監視設計
C15: ３．１ 可用性方針 | AI15: ７．１ 監視方針
AI16: ７．２ 監視運用フロー
B17: ４．セキュリティ設計 | AI17: ７．３ 監視体制と役割
C18: ４．１ セキュリティ方針 | AI18: ７．４ 監視方式
C19: ４．２ ネットワークセキュリティ
C20: ４．３ アクセス権限制御 | AH20: ８．運用機能設計
C21: ４．４ セキュリティポリシー対応方針 | AI21: ８．１ 運用機能一覧
C22: ４．５ SSLサーバ証明書 | AI22: ８．２ 各運用機能方針

Sheet １．はじめに
A1: =表紙!A1 -> XXX基本設計 | L1: 大分類 | V1: 中分類 | AF1: 小分類 | AP1: 作成者 | AU1: 作成日 | AZ1: 更新日
L2: =表紙!L2 -> 基本設計書 | V2: =表紙!V2 -> - | AF2: =RIGHT(CELL("filename",$A$2),LEN(CELL("filename",$A$2))-FIND("]",CELL("filename",$A$2))) -> #VALUE! | AP2: =表紙!AP2 -> 0 | AU2: =表紙!AU2 -> 45078
A3: １．はじめに
B5: １．１．案件の目的
C6: 各屋号に対してオンプレミス上にあるPOSデータを毎朝送信するシステムを作成する。
C7: 屋号単位で細かな要件は存在するが、共通機能を整理し標準化をお香。
C9: 二次構築では、AWS構成及び、XXX利用者様向けの標準化した環境・運用をご提供する。
B11: １．２．本書の記述範囲
C12: 本書では、AWSに関する基本設計を記述範囲とする。
C13: 尚、本書では、特に記載の無い限り、初期構築のテンプレート環境を対象とした記載とする。

Sheet ２．システム構成
A1: =表紙!A1 -> XXX基本設計 | L1: 大分類 | V1: 中分類 | AF1: 小分類 | AP1: 作成者 | AU1: 作成日 | AZ1: 更新日
L2: =表紙!L2 -> 基本設計書 | V2: =表紙!V2 -> - | AF2: =RIGHT(CELL("filename",$A$2),LEN(CELL("filename",$A$2))-FIND("]",CELL("filename",$A$2))) -> #VALUE! | AU2: =表紙!AU2 -> 45078 | AZ2: 45635
A4: ２．システム構成
B5: 本システムは同一アカウントに本番・検証のリソースを構築する。
B6: (1) 本番用リソースは、本番サービスを提供する環境とする。
B7: (2) 検証用リソースは、XXX社にて業務機能の検証を行う環境とする。
B8: (3) 本環境は、AWS東京リージョンに構築を行う。なお、CloudFrontに設定をするサービスはバージニア北部リージョンに構築を行う。
B11: ２．１ 環境構成
C12: 本環境の構成図は別紙1.構成図 シートを参照
B15: ２．２ 通信経路
C16: 通信経路については下記のとおり
C17: 通信方法 | H17: 対象
C18: HTTPS | H18: 一般ユーザー⇒Route53⇒CloudFront
C19: HTTPS | H19: システム管理者⇒CodeCommit | T19: ※CodeCommitは後述のAdmin権限以外は使用不可とする。2024/12/9以降の環境についてはCI/CD削除対応後となるため、CodeCommitへの通信経路は存在しない。
C20: AWS内部通信 | H20: その他のサービス間通信
B23: ２．３ ドメイン運用（テンプレート環境）
C24: 本環境におけるドメイン運用について以下のとおりとする。
C26: Route53にて、新規ドメインを発行する。
C27: 発行するドメインは「XXX.link」とする。
C28: ドメインは1年毎の自動更新を行う。
C30: Webサイト用のドメインはサブドメインで運用する。
C32: 本番・検証用のホストゾーン及びドメインは下記のとおり
C33: ホストゾーン | H33: 対象 | R33: ドメイン名
C34: パブリック | H34: 顧客向け本番用Webサイト | R34: master.XXX.link
C35: パブリック | H35: リリース前検証用Webサイト | R35: stg.XXX.link
B38: ２．４ サービス一覧
C39: 本環境で利用するAWSサービス一覧は以下のとおり。
C40: 利用サービス一覧 | P40: サービス説明 | AX40: 用途
C41: AWS Transfer Family for SFTP | P41: AWSの他のシステム、例えばS3アプリケーションなどと結合可能なアプリケーション転送に特化したサービス | AX41: マスタファイルをSFTPで入出力するために使用
C42: AWS Lambda | P42: AWSのイベントの受信、フィルタリング、変換、ルーティング、および配信を可能にするサービス | AX42: マスタファイルの変換処理や送信を行う
C43: Amazon EventBridge | P43: AWS、既存のシステム、または SaaS アプリケーション全体でイベント駆動型アプリケーションを大規模に構築するサービス | AX43: S3バケットにファイルが配置されたタイミングをトリガーとして、Lambdaを実行する
C44: AWS Step Functions | P44: 複数のAWSサービスを連携させ、ワークフローを簡単に構築・管理するためのサービス | AX44: ファイルを分散処理することで、処理の高速化を実現する
C45: Amazon S3 | P45: 高可用性のオブジェクトストレージ機能を提供するサービス | AX45: マスタファイルやトランファイルを保存する
C46: Application Load Balancer | P46: アプリケーション層でのトラフィックのルーティング、ロードバランシングを提供するサービス | AX46: 管理画面へのアクセスに対して、負荷分散をする
C47: Amazon Elastic Container Service (ECS) | P47: コンテナ化されたアプリケーションの管理とオーケストレーションを提供するサービス | AX47: POS用マスタファイルの作成や
C48: Amazon Elastic Container Registry （ECR） | P48: Kubernetesクラスターを簡単にデプロイ、管理、スケーリングするためのサービス | AX48: アプリケーションのイメージを保管する
C49: NAT Gateway | P49: プライベートサブネットからインターネットへ接続するための中継機能を提供し、アウトバウンドインターネットアクセスを許可するサービス | AX49: プライベートサブネットにあるECSのコンテナイメージをECRから取得するために使用
C50: Amazon Aurora | P50: 高いパフォーマンスと可用性を持つリレーショナルデータベースサービス | AX50: マスタ情報や集計情報をデータ保存する
C51: AWS Secrets Manager | P51: アプリケーションやサービスで必要な秘密情報（APIキーやパスワードなど）を安全に保存、管理、取得するサービス | AX51: SFTP通信をする際に必要な、SSH鍵を保管する

Sheet ３．可用性設計
A1: =表紙!A1 -> XXX基本設計 | L1: 大分類 | V1: 中分類 | AF1: 小分類 | AP1: 作成者 | AU1: 作成日 | AZ1: 更新日
L2: =表紙!L2 -> 基本設計書 | V2: =表紙!V2 -> - | AF2: =RIGHT(CELL("filename",$A$2),LEN(CELL("filename",$A$2))-FIND("]",CELL("filename",$A$2))) -> #VALUE! | AU2: =表紙!AU2 -> 45078 | AZ2: 45467
A4: ３．可用性設計
B6: ３．１ 可用性方針
C7: 本環境はAWSのマネージドサービスを使用し、サービスダウンの対応はAWSが行う。
C8: 以上のことから、可用性を考慮した構築は不要とする。

Sheet ４．セキュリティ設計
A1: =表紙!A1 -> XXX基本設計 | L1: 大分類 | V1: 中分類 | AF1: 小分類 | AP1: 作成者 | AU1: 作成日 | AZ1: 更新日
L2: =表紙!L2 -> 基本設計書 | V2: =表紙!V2 -> - | AF2: =RIGHT(CELL("filename",$A$2),LEN(CELL("filename",$A$2))-FIND("]",CELL("filename",$A$2))) -> #VALUE! | AU2: =表紙!AU2 -> 45078 | AZ2: 45635
A4: ４．セキュリティ設計
B6: ４．１ セキュリティ方針
C7: AWSアカウントの発行はYYY社が行い、顧客毎にAWSアカウントを分けて運用する。
C8: 利用するIAMユーザー用のポリシーについては、業務処理に最低限必要な権限を付与することで、セキュリティ的なリスクを回避する。
C9: AWSが提供する機能を利用することで、効率よくセキュリティの確保を行う。
C10: 当プラットフォーム環境は サーバーレス構成の為 ウイルス対策ソフトは導入せず S3へのファイルアップ時に事前のウイルススキャンを必須とすることでウイルス感染リスクを排除する。
B13: ４．２ ネットワークセキュリティ
C14: ユーザーからAWSリソースへの通信をHTTPSにすることで、暗号化されたセキュアな通信を行う。
B17: ４．３ アクセス権限制御
C18: IAMはAWSManagedPolicyを利用するものとする。
C20: ４．３．１ AWS環境へのログインについて
D21: AWS環境へのログインについては、共通のユーザーは使用せず、個人単位のログインとする。
C24: ４．３．２ IAMユーザー
D25: IAMユーザーの発行について記載する。
D27: IAMユーザーは、個人単位に払い出す。
D28: 付与する権限については、所属するグループの権限に準ずる。
D29: パスワードの有効期限は40日とする。
D30: パスワードポリシーは以下の通りとする。
D31: ・8文字以上とする。
D32: ・大文字 (A～Z) を少なくとも 1 つ含める。
D33: ・小文字 (a～z) を少なくとも 1 つ含める。
D34: ・数字を少なくとも 1 つ含める。
D35: ・英数字以外の文字 (! @ # $ % ^ & * ( ) _ + - = [ ] { } | ') を少なくとも 1 つ含める。
C38: ４．３．3 IAMグループ
D39: IAMグループの作成について記載する。
D41: IAMグループに付与するIAMポリシーは以下のとおり。
D42: IAMグループ | Q42: 役割 | AQ42: 付与権限
D43: AdminGroup | Q43: クレスコ及びXXXの管理ユーザーが所属するグループ | AQ43: AdministratorAccess管理ポリシー
D44: VendorGroup（専用環境/標準版を使用の場合） | Q44: 上記以外のベンダーが所属するグループ（XXXの作業時もこちらを使用） | AQ44: ファイルアップロード、削除、CloudFrontキャッシュ削除のみ
D45: 個別Group（共用環境/簡易版を使用の場合） | Q45: 上記以外のベンダーが所属するグループ（XXXの作業時もこちらを使用） | AQ45: ファイルアップロード、削除、CloudFrontキャッシュ削除のみ
C48: ４．３．4 IAMポリシー
D49: AWSManagedPolicyを利用することを基本とし、必要に応じて権限を絞り込んだポリシーを作成するものとする。
D50: IAMポリシーは、後述のIAMロールで利用する。
D51: 2024/12/9以降の環境についてはCI/CD削除対応後となるため、以下の全てのIAMポリシーを使用/構築しない。
D53: IAMロールに対するIAMポリシーは以下のとおり。
D54: IAMロールは、AWSリソースに対して割り当てる権限であり、その権限には、IAMグループに割りあてるポリシーとは別のものを使用する。
D55: IAMポリシー | X55: 用途
D56: AWSCodeCommitFullAccess | X56: CodeCommitへの実行権限
...

Sheet ５．ログ運用設計
A1: =表紙!A1 -> XXX基本設計 | L1: 大分類 | V1: 中分類 | AF1: 小分類 | AP1: 作成者 | AU1: 作成日 | AZ1: 更新日
L2: =表紙!L2 -> 基本設計書 | V2: =表紙!V2 -> - | AF2: =RIGHT(CELL("filename",$A$2),LEN(CELL("filename",$A$2))-FIND("]",CELL("filename",$A$2))) -> #VALUE! | AU2: =表紙!AU2 -> 45078 | AZ2: 45635
A4: ５．ログ運用設計
B6: ５．１ ログ運用方針
C7: システムの状態を収集してモニタリング、異常が発生していないか監視を行う必要がある。
C8: システムがどのように利用されているかを把握するための情報を集め、メトリクスやログの収集、監視や可視化を行う。
B11: ５．２ ログ運用
C12: 保管先がS3に指定されているサービスはS3に保管をし、Athenaでクエリ分析を行う。
C13: それ以外のログについては、CloudWatchLogsにてログ運用を行う。
C14: S3は標準クラスを使用し、ストレージクラスの移行は行わない。
C16: ログ運用が必要となる対象を以下に記載する。
C17: サービス名（ログ取得対象） | M17: ログ内容 | AJ17: ログデータ保管 | AQ17: ログデータ保管期間
C18: CloudFront | M18: セキュリティやアクセスの監査用ログを含む標準ログをS3へ出力する。 | AJ18: S3 | AQ18: 13ヶ月(400日)
C20: S3 | M20: バケットに対するリクエスト/アクセスの詳細を記録する。 | AJ20: S3 | AQ20: 13ヶ月(400日)
C22: Athena | M22: クエリの実行結果を記録する。 | AJ22: S3 | AQ22: 13ヶ月(400日)
C24: CloudTrail | M24: ユーザー、ロール、または AWS のサービスによって実行された | AJ24: S3 | AQ24: 13ヶ月(400日)
M25: アクションを記録する。
C26: Lambda | M26: Lambda実行に対する詳細なログを出力する。 | AJ26: CloudWatchLogs | AQ26: 13ヶ月(400日)
C28: WAF | M28: AWS WAF が AWS リソースからウェブリクエストを受信した時刻、 | AJ28: CloudWatchLogs | AQ28: 13ヶ月(400日)
M29: リクエストに関する詳細情報、およびリクエストが一致したルールに
M30: 関する詳細を含む。
C31: 注、サイト閉塞時に400日に関わらず全件削除となるが、利用者の要望に応じてサイト閉塞後もログのみを保管することが可能とする。
C32: 2024/12/9以降の環境についてはCI/CD削除対応後となるため、Lambdaのログは存在しない。
B35: ５．３ ログ保管期間経過後の対応
C36: 保管期間を超過したログについては、費用圧縮の観点から削除する。

Sheet ６．バックアップ・リストア設計
A1: =表紙!A1 -> XXX基本設計 | L1: 大分類 | V1: 中分類 | AF1: 小分類 | AP1: 作成者 | AU1: 作成日 | AZ1: 更新日
L2: =表紙!L2 -> 基本設計書 | V2: =表紙!V2 -> - | AF2: =RIGHT(CELL("filename",$A$2),LEN(CELL("filename",$A$2))-FIND("]",CELL("filename",$A$2))) -> #VALUE! | AU2: =表紙!AU2 -> 45078 | AZ2: 45467
A4: ６．バックアップ・リストア運用設計
B6: ６．１ バックアップ・リストア運用方針
C7: AWSが提供する機能を利用することで、バックアップ・リストア運用を実現する。
B10: ６．２ バックアップ運用
C11: S3は耐久性を考慮し、バージョン管理によるバックアップは本環境では行わない。
C12: コンテンツのマスターデータ管理は、ページ製作ベンダーにて行う。
B15: ６．３ リストア運用
C16: リストア方法については別途ドキュメント「Webサイトリリース手順書」を参照。

Sheet ７．監視設計
A1: =表紙!A1 -> XXX基本設計 | L1: 大分類 | V1: 中分類 | AF1: 小分類 | AP1: 作成者 | AU1: 作成日 | AZ1: 更新日
L2: =表紙!L2 -> 基本設計書 | V2: =表紙!V2 -> - | AF2: =RIGHT(CELL("filename",$A$2),LEN(CELL("filename",$A$2))-FIND("]",CELL("filename",$A$2))) -> #VALUE! | AU2: =表紙!AU2 -> 45078
A4: ７．監視設計
B6: ７．１． 監視設計方針
C7: (1) 本章は、システム監視で必要な項目について記載する。
C8: (2) 監視には、クレスコ社のCreageサービス（CreageOpe+ Silver）を用いる。
C9: (3) 監視対象は本番用リソースのみとし、検証用リソースは監視対象外とする。
C10: (4) システムログの保管については、AWSのサービスを用いて保管を行う。
B12: ７．２． 監視運用フロー
C13: 障害発生時の監視運用フローを以下に示す。
B20: ７．３． 監視体制と役割
C21: 障害発生時の体制と役割および運用時間について以下に示す。
D23: 以下の監視はCreageOpe+監視チームが行う。
D24: NO | G24: 作業項目 | N24: 対応時間 | Y24: 作業内容
D25: 1 | G25: システム監視 | N25: 0:00 ～ 24:00 365日対応 | Y25: システムの常時監視を実施
B28: ７．４．監視方式
C29: 本システムでは、以下の方式にて検知及び対応を行う。
C30: 監視は、以下の3項目に分けて実施する。
D32: NO | F32: 監視の種別 | K32: 概要
D33: 1 | F33: 死活監視 | K33: 監視対象の応答を確認し、応答がない（または）場合はエラー検知する。
C36: ７．４．１．死活監視
D37: ７．４．１．１．URI監視
E38: 指定した URI に対して HTTPSリクエストを送信し、レスポンスが返ってくるか、またレスポンスの内容を監視する。
E39: 監視設定のパラメータは、監視周期、レスポンスタイムアウト(秒、回数)の設定が可能である。
E40: 指定パラメータ以内に応答がない場合アラートを通知する。
E41: 本環境では監視周期=3分、レスポンスタイムアウト=5秒で3回とする。
E44: (１) 目的
F45: 本番用の Web サイト(master.XXX.click)を外部から監視して、その URL の正常性、およびパフォーマンスを監視する。
E47: (２) 方式
F48: 下記方式で監視を行う。
G49: ・定期的にURLを監視し、異常があればアラートを発砲する。
H50: ※監視URLは、監視周期毎（1周期=3分）にチェックされ、HTTPステータスが指定のステータスコード以外の場合にエラーとする。応答がない場合は、タイムアウト（秒）で設定した時間まで待機します。
H51: ※タイムアウトで設定した時間を超えて応答がない場合、リトライで設定した回数分ステータスコードを繰り返し確認する。（リトライ3回であれば、合計4回ステータスコードを確認)
H52: リトライ数＋1回目の確認時に応答がない場合に警報として検知する。
F55: 破線部分の機能要求詳細は以下の通り。
G56: NO | I56: 実装方式 | P56: 監視方式 | X56: 監視内容 | AT56: 機能要求 | BN56: 備考
G57: 1 | I57: Creageサービス | P57: URI監視 | X57: URIの応答により正常性を判断する | AT57: 監視要件の指定はない為、最大3分以内に検知する。
E59: (３) 監視対象
F60: 本方式による監視対象は以下の通り。
G61: NO | I61: 環境 | O61: コンポーネント | V61: 備考
...

Sheet ８．運用機能設計
A1: =表紙!A1 -> XXX基本設計 | L1: 大分類 | V1: 中分類 | AF1: 小分類 | AP1: 作成者 | AU1: 作成日 | AZ1: 更新日
L2: =表紙!L2 -> 基本設計書 | V2: =表紙!V2 -> - | AF2: =RIGHT(CELL("filename",$A$2),LEN(CELL("filename",$A$2))-FIND("]",CELL("filename",$A$2))) -> #VALUE! | AU2: =表紙!AU2 -> 45078 | AZ2: 45474
A4: ８．運用機能設計
B6: ８．１ 本システムでの運用機能について
C7: 本環境における運用について記載を行う。
B10: ８．２ 本システムでの運用機能一覧
C11: 運用機能として実装するものは下記のとおり。
D12: No | F12: 運用 | M12: 機能 | Z12: 実装方式 | AQ12: 実施者 | AX12: 備考
D13: 1 | F13: サイト開設 | M13: ヒアリングシート | Z13: システム構築に必要となる情報のヒアリングシート | AQ13: XXX | AX13: ヒアリングシートに必要となる情報を提示予定
M14: AWSアカウント提供 | Z14: 手順により実装 | AQ14: XXX/YYY | AX14: XXXで用意するユーザーの構築手順は提供予定
M15: 環境構築・検証 | Z15: CloudFormationにより実装する | AQ15: クレスコ
D16: 2 | F16: サイト閉塞 | M16: 依頼受領 | Z16: ー | AQ16: XXX
M17: 環境破棄 | Z17: シェルスクリプトの実行により実装する。 | AQ17: クレスコ | AX17: 90日間の閉鎖後期間を保持しない。
M18: AWSアカウント削除 | Z18: ー | AQ18: XXX/YYY
D19: 3 | F19: コンテンツリリース | M19: リリース運用 | Z19: コンソールでのドラッグドロップ | AQ19: XXX/外部ベンダー | AX19: Admin権限には CI/CDによる実装も可とする。
M20: 検証用Webサイトの検証完了後の運用 | Z20: 手順書により実装 | AQ20: XXX
D21: 4 | F21: メンテナンス | M21: ログ確認運用 | Z21: 手順書を別途作成する | AQ21: XXX
M22: アクセス数確認運用 | Z22: 手順書を別途作成する | AQ22: XXX
C25: ８．２．１．サイト開設
D26: （１）ヒアリングシート
E27: エンドユーザーに対してヒアリングを行い、個別環境のカスタマイズを実施する。
E28: ヒアリングはヒアリングシートに基づいて行う。
E30: 構築に係わるヒアリング内容は以下のとおり。
E31: ヒアリング内容 | Y31: 備考
E32: 本番・検証用ドメイン名
E33: ドメイン登録情報
E34: 証明書の発行要否 | Y34: ※外部発行時はACMのコンソール上でインポートをする
D37: （２）AWSアカウント発行・ユーザー作成
E38: YYY社がAWSアカウントを設定後、XXX社が自社管理用Adminユーザー及びクレスコ用Adminユーザーを作成する。
E39: 作成されたユーザーを使用して、クレスコが環境構築を実施する。
E40: XXX用Vendor権限ユーザーの１個目はクレスコが作成する。
E41: XXX用Vendor権限ユーザーの２個目以降は必要に応じてXXXが作成する。
E42: 共用環境の場合、サブディレクトリへの制御ポリシー及び、グループ＆ユーザーをXXX が作成する。
D44: （３）環境構築・検証
E45: 構築用ユーザーを使用して、CloudFormationを実行する。
E46: CloudFormationのテンプレートは、ヒアリング内容に沿って編集する。
C49: ８．２．２．サイト閉塞
D50: （１）依頼受領
E51: エンドユーザーからサイト閉塞の依頼を受領し、クレスコ社へリソース削除の依頼をする。
D54: （２）環境破棄
...

Sheet 別紙1.構成図
A1: =表紙!A1 -> XXX基本設計 | L1: 大分類 | V1: 中分類 | AF1: 小分類 | AP1: 作成者 | AU1: 作成日 | AZ1: 更新日
L2: =表紙!L2 -> 基本設計書 | V2: =表紙!V2 -> - | AF2: =RIGHT(CELL("filename",$A$2),LEN(CELL("filename",$A$2))-FIND("]",CELL("filename",$A$2))) -> #VALUE! | AP2: =表紙!AP2 -> 0 | AU2: =表紙!AU2 -> 45078 | AZ2: 45635
A3: 別紙1 | D3: 構成図
B4: 本構成で構築する環境は以下の通り。
C6: ■CI/CDでデプロイする場合
C31: ■ベンダー様が手動でS3にデプロイする場合
C57: ■2024/12/9以降CI/CD削除対応後の構成
