Workbook
Name _1Nagaoka_障害一覧_発生_改修: #REF!
Name _2Nagaoka_障害一覧_発生_改修: #REF!
Name _2Nagaoka_障害一覧_発生_改修: #REF!
Name _2Nagaoka_障害一覧_発生_改修: #REF!
Name _2Nagaoka_障害一覧_発生_改修: #REF!
Name _2Nagaoka_障害一覧_発生_改修: #REF!
Name _2Nagaoka_障害一覧_発生_改修: #REF!
Name _2Nagaoka_障害一覧_発生_改修: #REF!
Name _2Nagaoka_障害一覧_発生_改修: #REF!
Name _2Nagaoka_障害一覧_発生_改修: #REF!
Name _3Nagaoka_障害一覧_発生_改修: #REF!
Name _ctb１: '[1]現行DB一覧2(CT)'!$A$2:$E$220
Name _PFM2: [2]pfm002!$D$314:$D$316
Name _PFM21: [2]pfm002!$D$314:$D$316
Name _pfm3: #REF!
Name _pfm3: #REF!
Name _pfm3: #REF!
Name _pfm3: #REF!
Name _pfm3: #REF!
Name _pfm3: #REF!
Name _pfm3: #REF!
Name _pfm3: #REF!
Name _pfm3: #REF!
Name _pfm3: #REF!
Name _pfm3: #REF!
Name a: #REF!
Name DISC_CLASS_LVL: [3]DISC_CLASS_LVL!#REF!
Name DISC_CLASS_LVL: [3]DISC_CLASS_LVL!#REF!
Name DISC_CLASS_LVL: [3]DISC_CLASS_LVL!#REF!
Name DISC_CLASS_LVL: [3]DISC_CLASS_LVL!#REF!
Name DISC_CLASS_LVL: [3]DISC_CLASS_LVL!#REF!
Name DISC_CLASS_LVL: [3]DISC_CLASS_LVL!#REF!
Name DISC_CLASS_LVL: [3]DISC_CLASS_LVL!#REF!
Name DISC_CLASS_LVL: [3]DISC_CLASS_LVL!#REF!
Name DISC_CLASS_LVL: [3]DISC_CLASS_LVL!#REF!
Name DISC_CLASS_LVL: [3]DISC_CLASS_LVL!#REF!
Name DISC_EXCEPTION: #REF!
Name DISC_EXCEPTION: #REF!
Name DISC_EXCEPTION: #REF!
Name DISC_EXCEPTION: #REF!
Name DISC_EXCEPTION: #REF!
Name DISC_EXCEPTION: #REF!
Name DISC_EXCEPTION: #REF!
Name DISC_EXCEPTION: #REF!
Name DISC_EXCEPTION: #REF!
Name DISC_EXCEPTION: #REF!
Name DISC_EXCEPTION: #REF!
Name DISC_STEP: #REF!
Name DISC_STEP: #REF!
Name DISC_STEP: #REF!
Name DISC_STEP: #REF!
Name DISC_STEP: #REF!
Name DISC_STEP: #REF!
Name DISC_STEP: #REF!
Name DISC_STEP: #REF!
Name DISC_STEP: #REF!
Name DISC_STEP: #REF!
Name DISC_STEP: #REF!
Name DISC_TARGET: #REF!
Name DISC_TARGET: #REF!

Sheet 集計
C2: 予定項目数 | D2: 実績項目数 | E2: 残項目数 | F2: 完了率
B3: パッケージ系 | C3: =パッケージ系!$D$109 -> 130 | D3: =パッケージ系!$D$107 -> 0 | E3: =C3-D3 -> 130 | F3: =D3/C3 -> 0
B4: パッケージ系 (SS) | C4: ='パッケージ系 (SS)'!$D$109 -> 111 | D4: ='パッケージ系 (SS)'!$D$107 -> 0 | E4: =C4-D4 -> 111 | F4: =D4/C4 -> 0
B5: SPS系 | E5: =C5-D5 -> 0 | F5: =D5/C5 -> #DIV/0! | G5: ???
B6: パッケージ系 (PS) | C6: ='パッケージ系 (PS)'!$D$109 -> 128 | D6: ='パッケージ系 (PS)'!$D$107 -> 0 | E6: =C6-D6 -> 128 | F6: =D6/C6 -> 0
B7: サーバ系 | C7: 56 | D7: 56 | E7: =C7-D7 -> 0 | F7: =D7/C7 -> 1
B8: Win10対応_POS | C8: =Win10対応_POS!$D$94 -> 204 | D8: =Win10対応_POS!$D$92 -> 0 | E8: =C8-D8 -> 204 | F8: =D8/C8 -> 0
B9: Win10対応_SS | C9: =Win10対応_SS!$D$76 -> 47 | D9: =Win10対応_SS!$D$74 -> 0 | E9: =C9-D9 -> 47 | F9: =D9/C9 -> 0
B10: Win10対応_PS | C10: =Win10対応_PS!$D$76 -> 159 | D10: =Win10対応_PS!$D$74 -> 0 | E10: =C10-D10 -> 159 | F10: =D10/C10 -> 0
B11: Win10対応_フルセルフ | C11: =Win10対応_フルセルフ!$D$77 -> 184 | D11: =Win10対応_フルセルフ!$D$75 -> 0 | E11: =C11-D11 -> 184 | F11: =D11/C11 -> 0
B12: Win10対応_サーバ | C12: =Win10対応_サーバ!$D$25 -> 32 | D12: =Win10対応_サーバ!$D$23 -> 0 | E12: =C12-D12 -> 32 | F12: =D12/C12 -> 0
B13: 合計 | C13: =SUM(C3:C12) -> 1051 | D13: =SUM(D3:D12) -> 56 | E13: =SUM(E3:E12) -> 995 | F13: =D13/C13 -> 0.053282588

Sheet ST仕様書表紙
C4: TeamStore/M
C7: システムテスト仕様書兼完了報告書
C9: リグレッション（定型確認）
E15: 第１．７版 ２０２４年９月１３日
F26: 富士通株式会社
B27: GCSBG Retail事業本部 リテールチェーン事業部

Sheet 改版履歴
B2: TeamStore/M POSシステム | O2: システム名 | U2: 業務名 | Z2: リグレッションテスト
O3: TeamStore/M
C6: 改版履歴
C8: 日付 | G8: 版数 | I8: 章番号 | L8: 修正内容 | AM8: 担当
C10: 43650 | G10: 1 | L10: 新規作成 | AM10: 富士通
C12: 44225 | G12: 1.1 | L12: レイアウト変更 | AM12: 富士通
C14: 44229 | G14: 1.2 | L14: 標準PTFベースアップ項目追記 | AM14: 富士通
C16: 44230 | G16: 1.3 | L16: 項目精査実施 | AM16: 富士通
C18: 44245 | G18: 1.4 | L18: とくし丸リグレッションシート作成 | AM18: 富士通
C20: 44909 | G20: 1.5 | L20: Windows10対応シート作成 | AM20: 富士通
C22: 44970 | G22: 1.6 | L22: フルセルフシート作成 | AM22: 富士通
C24: 45548 | G24: 1.7 | L24: 交通系電子マネー項目追加 | AM24: 富士通

Sheet パッケージ系
B1: いなげや様 パッケージ リグレッションテスト仕様書
B2: 大分類 | C2: 中分類 | D2: 小分類 | E2: テスト項目 | H2: POS | Q2: チェック日付 | T2: 担当 | U2: 備考
E3: No | F3: POS操作 | G3: 結果 | H3: 動作 | I3: DB | J3: ｶｽﾀﾏ | K3: 画面 | L3: ﾚｼｰﾄ | M3: ｼﾞｬｰﾅﾙ | N3: 音声 | O3: ﾛｸﾞ | P3: 小型 LCD | Q3: OK | R3: NG | S3: 修正 OK
B4: 適用確認 | C4: リモメン | D4: PTFLOG | E4: =ROW()-3 -> 1 | F4: ログ確認 対象POS C:\GSFD直下 | G4: PTFLOGを開き、エラーが出力されていないこと | H4: ー | I4: ー | J4: ー | K4: ー | L4: ー | M4: ー | N4: ー | O4: □ | P4: ー
D5: PTFLOG2 | E5: =ROW()-3 -> 2 | F5: ログ確認 対象POS C:\GSFD直下 | G5: PTFLOG2を開き、エラーが出力されていないこと | H5: ー | I5: ー | J5: ー | K5: ー | L5: ー | M5: ー | N5: ー | O5: □ | P5: ー
C6: 外付けPTF適用 | D6: CTKYLOG | E6: =ROW()-3 -> 3 | F6: ログ確認 対象POS C:\CTKY直下 | G6: CTKYLOGを開き、エラーが出力されていないこと | H6: ー | I6: ー | J6: ー | K6: ー | L6: ー | M6: ー | N6: ー | O6: ー | P6: ー | U6: SSVで確認
D7: CTKYLOG2 | E7: =ROW()-3 -> 4 | F7: ログ確認 対象POS C:\CTKY直下 | G7: CTKYLOG2を開き、エラーが出力されていないこと | H7: ー | I7: ー | J7: ー | K7: ー | L7: ー | M7: ー | N7: ー | O7: ー | P7: ー | U7: SSVで確認
B8: 開局 | D8: 正常開局 | E8: =ROW()-3 -> 5 | G8: 正常に開局されること。決済端末が待機画面になること。 | H8: ー | I8: ー | J8: ー | K8: □ | L8: ー | M8: ー | N8: ー | O8: ー | P8: ー
D9: キーレイアウト | E9: =ROW()-3 -> 6 | G9: キーレイアウト反映の確認 （サーバのテストで、機能キーとプリセットの変更を行い反映されることを確認する） | H9: □ | I9: ー | J9: ー | K9: □ | L9: ー | M9: ー | N9: ー | O9: ー | P9: ー
C10: レシート | D10: さんにち割引 | E10: =ROW()-3 -> 7 | G10: 「さんにち割引」が表示されていること 対象日付が表示されていること | H10: ー | I10: ー | J10: ー | K10: ー | L10: □ | M10: □ | N10: ー | O10: ー | P10: ー
B11: OPキー | C11: 売上 | D11: 部門入力 | E11: =ROW()-3 -> 8 | F11: 動作確認 部門コード クラスボタン | G11: 部門コードを手入力して登録し、正常に登録できることを確認 | H11: □ | I11: ー | J11: ー | K11: □ | L11: ー | M11: ー | N11: ー | O11: ー | P11: ー
D12: フル部門キー登録 | E12: =ROW()-3 -> 9 | F12: プリセットは電子多項目で 登録されているボタン ・部門 フル部門キーはフルの部門キー | G12: プリセットで登録してあるフル部門キーを使用して登録し、 正常に登録できることを確認 | H12: □ | I12: ー | J12: ー | K12: □ | L12: ー | M12: ー | N12: ー | O12: ー | P12: ー
D13: 特売 | E13: =ROW()-3 -> 10 | G13: サーバで特売を登録し、正常にPOSに反映すること（リアルメンテ確認） | H13: □ | I13: ー | J13: ー | K13: □ | L13: ー | M13: ー | N13: ー | O13: ー | P13: ー
D14: キーPLU | E14: =ROW()-3 -> 11 | F14: 商品JANコードを入力しPLUボタン | G14: 正常に売上登録できること | H14: ー | I14: ー | J14: ー | K14: ー | L14: ー | M14: ー | N14: ー | O14: ー | P14: ー | U14: 運用未使用
D15: 保留 | E15: =ROW()-3 -> 12 | G15: 正常に取引を保留できること | H15: □ | I15: ー | J15: ー | K15: ー | L15: ー | M15: ー | N15: ー | O15: ー | P15: ー
D16: 復元 | E16: =ROW()-3 -> 13 | G16: 保留した取引を復元でき、追加で商品登録できること | H16: □ | I16: ー | J16: ー | K16: ー | L16: ー | M16: ー | N16: ー | O16: ー | P16: ー
D17: 乗算登録 | E17: =ROW()-3 -> 14 | G17: 乗算登録が正しくできること（前・後が正しく動作すること） | H17: □ | I17: ー | J17: ー | K17: ー | L17: ー | M17: ー | N17: ー | O17: ー | P17: ー
D18: 値引操作 | E18: =ROW()-3 -> 15 | G18: マニュアル値引が正しく動作すること（前・後が正しく動作すること） | H18: □ | I18: ー | J18: ー | K18: ー | L18: ー | M18: ー | N18: ー | O18: ー | P18: ー
E19: =ROW()-3 -> 16 | G19: 2人制時、明細一覧画面にて、マニュアル値引が正しく動作すること | H19: ー | I19: ー | J19: ー | K19: ー | L19: ー | M19: ー | N19: ー | O19: ー | P19: ー | U19: 電子多項目無し
E20: =ROW()-3 -> 17 | G20: 売価変更が正しくできること | H20: □ | I20: ー | J20: ー | K20: □ | L20: ー | M20: ー | N20: ー | O20: ー | P20: ー
D21: 訂正 | E21: =ROW()-3 -> 18 | G21: 指定訂正／直前訂正が正しくできること | H21: □ | I21: ー | J21: ー | K21: □ | L21: ー | M21: ー | N21: ー | O21: ー | P21: ー
D22: 現外券 | E22: =ROW()-3 -> 19 | F22: 商品券（支払い一覧にて選択） | G22: 現外券での支払い登録が正常にできること | H22: □ | I22: ー | J22: ー | K22: □ | L22: ー | M22: ー | N22: ー | O22: ー | P22: ー
D23: 再登録 | E23: =ROW()-3 -> 20 | G23: 再登録後、再度商品登録できること | H23: □ | I23: ー | J23: ー | K23: ー | L23: ー | M23: ー | N23: ー | O23: ー | P23: ー
D24: レシート印字 | E24: =ROW()-3 -> 21 | G24: 「今回ポイント **p」が表示されること | H24: ー | I24: ー | J24: ー | K24: ー | L24: □ | M24: □ | N24: ー | O24: ー | P24: ー
E25: =ROW()-3 -> 22 | G25: 「現在ポイント **p」が表示されること | H25: ー | I25: ー | J25: ー | K25: ー | L25: □ | M25: □ | N25: ー | O25: ー | P25: ー
E26: =ROW()-3 -> 23 | G26: 今回ポイント、現在ポイントのみ表示されること | H26: ー | I26: ー | J26: ー | K26: ー | L26: □ | M26: □ | N26: ー | O26: ー | P26: ー
D27: レシート印字（クレジット） | E27: =ROW()-3 -> 24 | G27: クレジットレシートのクレジット会社名が正しく印字されること | H27: ー | I27: ー | J27: ー | K27: ー | L27: □ | M27: □ | N27: ー | O27: ー | P27: ー
C28: デバイス | D28: 固定スキャナ | E28: =ROW()-3 -> 25 | G28: 商品登録できること | H28: ー | I28: ー | J28: ー | K28: ー | L28: ー | M28: ー | N28: ー | O28: ー | P28: ー | U28: 固定スキャナ無し
D29: タッチスキャナ | E29: =ROW()-3 -> 26 | G29: 商品登録できること | H29: □ | I29: ー | J29: ー | K29: ー | L29: ー | M29: ー | N29: ー | O29: ー | P29: ー
D30: IC決済端末 | E30: =ROW()-3 -> 27 | G30: カードの読み込みができること（ＩＣあり・ＩＣなし） | H30: □ | I30: ー | J30: ー | K30: ー | L30: ー | M30: ー | N30: ー | O30: ー | P30: ー
E31: =ROW()-3 -> 28 | G31: Vカード会員宣言ができること | H31: □ | I31: ー | J31: ー | K31: ー | L31: ー | M31: ー | N31: ー | O31: ー | P31: ー
D32: MSR（カードリーダ） | E32: =ROW()-3 -> 29 | G32: カードの読取できないこと | H32: ー | I32: ー | J32: ー | K32: ー | L32: ー | M32: ー | N32: ー | O32: ー | P32: ー | U32: MSR部がハード的に埋め込まれている
D33: MSR2（カードリーダ） | E33: =ROW()-3 -> 30 | G33: カードの読取できないこと（電子多項目横） | H33: ー | I33: ー | J33: ー | K33: ー | L33: ー | M33: ー | N33: ー | O33: ー | P33: ー | U33: 電子多項目無し
D34: メインキー | E34: =ROW()-3 -> 31 | G34: 動作すること | H34: □ | I34: ー | J34: ー | K34: ー | L34: ー | M34: ー | N34: ー | O34: ー | P34: ー
D35: ファンクションキー | E35: =ROW()-3 -> 32 | G35: 動作すること | H35: □ | I35: ー | J35: ー | K35: ー | L35: ー | M35: ー | N35: ー | O35: ー | P35: ー
D36: 電子多項目 物理キー | E36: =ROW()-3 -> 33 | G36: 動作すること | H36: ー | I36: ー | J36: ー | K36: ー | L36: ー | M36: ー | N36: ー | O36: ー | P36: ー | U36: 電子多項目無し
D37: 電子多項目 電子キー | E37: =ROW()-3 -> 34 | G37: 動作すること | H37: ー | I37: ー | J37: ー | K37: ー | L37: ー | M37: ー | N37: ー | O37: ー | P37: ー | U37: 電子多項目無し
D38: 単品一覧 | E38: =ROW()-3 -> 35 | G38: 登録できること | H38: □ | I38: ー | J38: ー | K38: □ | L38: ー | M38: ー | N38: ー | O38: ー | P38: ー
C39: バーコード | D39: JANコード 13桁/8桁 | E39: =ROW()-3 -> 36 | G39: 登録できること | H39: □ | I39: ー | J39: ー | K39: ー | L39: ー | M39: ー | N39: ー | O39: ー | P39: ー
D40: NON－PLUコード | E40: =ROW()-3 -> 37 | F40: 02から始まるバーコード 肉魚量売りバーコード バーコード後ろ下2桁から値段となる。 | G40: 登録できること | H40: □ | I40: ー | J40: ー | K40: ー | L40: ー | M40: ー | N40: ー | O40: ー | P40: ー
...

Sheet パッケージ系 (SS)
B1: いなげや様 パッケージ リグレッションテスト仕様書
B2: 大分類 | C2: 中分類 | D2: 小分類 | E2: テスト項目 | H2: SS | Q2: チェック日付 | T2: 担当 | U2: 備考
E3: No | F3: POS操作 | G3: 結果 | H3: 動作 | I3: DB | J3: ｶｽﾀﾏ | K3: 画面 | L3: ﾚｼｰﾄ | M3: ｼﾞｬｰﾅﾙ | N3: 音声 | O3: ﾛｸﾞ | P3: 小型 LCD | Q3: OK | R3: NG | S3: 修正 OK
B4: 適用確認 | C4: リモメン | D4: PTFLOG | E4: =ROW()-3 -> 1 | F4: ログ確認 対象POS C:\GSFD直下 | G4: PTFLOGを開き、エラーが出力されていないこと | H4: ー | I4: ー | J4: ー | K4: ー | L4: ー | M4: ー | N4: ー | O4: □ | P4: ー
D5: PTFLOG2 | E5: =ROW()-3 -> 2 | F5: ログ確認 対象POS C:\GSFD直下 | G5: PTFLOG2を開き、エラーが出力されていないこと | H5: ー | I5: ー | J5: ー | K5: ー | L5: ー | M5: ー | N5: ー | O5: □ | P5: ー
C6: 外付けPTF適用 | D6: CTKYLOG | E6: =ROW()-3 -> 3 | F6: ログ確認 対象POS C:\CTKY直下 | G6: CTKYLOGを開き、エラーが出力されていないこと | H6: ー | I6: ー | J6: ー | K6: ー | L6: ー | M6: ー | N6: ー | O6: ー | P6: ー | U6: SSVで確認
D7: CTKYLOG2 | E7: =ROW()-3 -> 4 | F7: ログ確認 対象POS C:\CTKY直下 | G7: CTKYLOG2を開き、エラーが出力されていないこと | H7: ー | I7: ー | J7: ー | K7: ー | L7: ー | M7: ー | N7: ー | O7: ー | P7: ー | U7: SSVで確認
B8: 開局 | D8: 正常開局 | E8: =ROW()-3 -> 5 | G8: 正常に開局されること | H8: ー | I8: ー | J8: ー | K8: □ | L8: ー | M8: ー | N8: ー | O8: ー | P8: ー
D9: キーレイアウト | E9: =ROW()-3 -> 6 | G9: キーレイアウト反映の確認 （サーバのテストで、機能キーとプリセットの変更を行い反映されることを確認する） | H9: □ | I9: ー | J9: ー | K9: □ | L9: ー | M9: ー | N9: ー | O9: ー | P9: ー
C10: レシート | D10: さんにち割引 | E10: =ROW()-3 -> 7 | G10: 「さんにち割引」が表示されていること 対象日付が表示されていること | H10: ー | I10: ー | J10: ー | K10: ー | L10: □ | M10: □ | N10: ー | O10: ー | P10: ー
B11: OPキー | C11: 売上 | D11: 部門入力 | E11: =ROW()-3 -> 8 | F11: 動作確認 部門コード クラスボタン | G11: 部門コードを手入力して登録し、正常に登録できることを確認 | H11: □ | I11: ー | J11: ー | K11: □ | L11: ー | M11: ー | N11: ー | O11: ー | P11: ー
D12: フル部門キー登録 | E12: =ROW()-3 -> 9 | F12: プリセットは電子多項目で 登録されているボタン ・部門 フル部門キーはフルの部門キー | G12: プリセットで登録してあるフル部門キーを使用して登録し、 正常に登録できることを確認 | H12: □ | I12: ー | J12: ー | K12: □ | L12: ー | M12: ー | N12: ー | O12: ー | P12: ー
D13: 特売 | E13: =ROW()-3 -> 10 | G13: サーバで特売を登録し、正常にPOSに反映すること（リアルメンテ確認） | H13: □ | I13: ー | J13: ー | K13: □ | L13: ー | M13: ー | N13: ー | O13: ー | P13: ー
D14: キーPLU | E14: =ROW()-3 -> 11 | F14: 商品JANコードを入力しPLUボタン | G14: 正常に売上登録できること | H14: ー | I14: ー | J14: ー | K14: ー | L14: ー | M14: ー | N14: ー | O14: ー | P14: ー | U14: 運用未使用
D15: 保留 | E15: =ROW()-3 -> 12 | G15: 正常に取引を保留できること | H15: □ | I15: ー | J15: ー | K15: ー | L15: ー | M15: ー | N15: ー | O15: ー | P15: ー
D16: 復元 | E16: =ROW()-3 -> 13 | G16: 保留した取引を復元でき、追加で商品登録できること | H16: □ | I16: ー | J16: ー | K16: ー | L16: ー | M16: ー | N16: ー | O16: ー | P16: ー
D17: 乗算登録 | E17: =ROW()-3 -> 14 | G17: 乗算登録が正しくできること（前・後が正しく動作すること） | H17: □ | I17: ー | J17: ー | K17: ー | L17: ー | M17: ー | N17: ー | O17: ー | P17: ー
D18: 値引操作 | E18: =ROW()-3 -> 15 | G18: マニュアル値引が正しく動作すること（前・後が正しく動作すること） | H18: □ | I18: ー | J18: ー | K18: ー | L18: ー | M18: ー | N18: ー | O18: ー | P18: ー
E19: =ROW()-3 -> 16 | G19: 2人制時、明細一覧画面にて、マニュアル値引が正しく動作すること | H19: ー | I19: ー | J19: ー | K19: ー | L19: ー | M19: ー | N19: ー | O19: ー | P19: ー | U19: 2人制運用なし
E20: =ROW()-3 -> 17 | G20: 売価変更が正しくできること | H20: □ | I20: ー | J20: ー | K20: □ | L20: ー | M20: ー | N20: ー | O20: ー | P20: ー
D21: 訂正 | E21: =ROW()-3 -> 18 | G21: 指定訂正／直前訂正が正しくできること | H21: □ | I21: ー | J21: ー | K21: □ | L21: ー | M21: ー | N21: ー | O21: ー | P21: ー
D22: 現外券 | E22: =ROW()-3 -> 19 | F22: 商品券（支払い一覧にて選択） | G22: 現外券での支払い登録が正常にできること | H22: □ | I22: ー | J22: ー | K22: □ | L22: ー | M22: ー | N22: ー | O22: ー | P22: ー
D23: 再登録 | E23: =ROW()-3 -> 20 | G23: 再登録後、再度商品登録できること | H23: □ | I23: ー | J23: ー | K23: ー | L23: ー | M23: ー | N23: ー | O23: ー | P23: ー
D24: レシート印字 | E24: =ROW()-3 -> 21 | G24: 「今回ポイント **p」が表示されること | H24: ー | I24: ー | J24: ー | K24: ー | L24: □ | M24: □ | N24: ー | O24: ー | P24: ー
E25: =ROW()-3 -> 22 | G25: 「現在ポイント **p」が表示されること | H25: ー | I25: ー | J25: ー | K25: ー | L25: □ | M25: □ | N25: ー | O25: ー | P25: ー
E26: =ROW()-3 -> 23 | G26: 今回ポイント、現在ポイントのみ表示されること | H26: ー | I26: ー | J26: ー | K26: ー | L26: □ | M26: □ | N26: ー | O26: ー | P26: ー
D27: レシート印字（クレジット） | E27: =ROW()-3 -> 24 | G27: クレジットレシートのクレジット会社名が正しく印字されること | H27: ー | I27: ー | J27: ー | K27: ー | L27: ー | M27: ー | N27: ー | O27: ー | P27: ー | U27: 決済端末未接続
C28: デバイス | D28: 固定スキャナ | E28: =ROW()-3 -> 25 | G28: 商品登録できること | H28: □ | I28: ー | J28: ー | K28: ー | L28: ー | M28: ー | N28: ー | O28: ー | P28: ー
D29: タッチスキャナ | E29: =ROW()-3 -> 26 | G29: 商品登録できること | H29: □ | I29: ー | J29: ー | K29: ー | L29: ー | M29: ー | N29: ー | O29: ー | P29: ー
D30: IC決済端末 | E30: =ROW()-3 -> 27 | G30: カードの読み込みができること（ＩＣあり・ＩＣなし） | H30: ー | I30: ー | J30: ー | K30: ー | L30: ー | M30: ー | N30: ー | O30: ー | P30: ー
E31: =ROW()-3 -> 28 | G31: Vカード会員宣言ができること | H31: ー | I31: ー | J31: ー | K31: ー | L31: ー | M31: ー | N31: ー | O31: ー | P31: ー
D32: MSR（カードリーダ） | E32: =ROW()-3 -> 29 | G32: カードの読取できないこと | H32: ー | I32: ー | J32: ー | K32: ー | L32: ー | M32: ー | N32: ー | O32: ー | P32: ー | U32: MSR設置なし
D33: MSR2（カードリーダ） | E33: =ROW()-3 -> 30 | G33: カードの読取できないこと（電子多項目横） | H33: ー | I33: ー | J33: ー | K33: ー | L33: ー | M33: ー | N33: ー | O33: ー | P33: ー | U33: MSR設置なし
D34: メインキー | E34: =ROW()-3 -> 31 | G34: 動作すること | H34: □ | I34: ー | J34: ー | K34: ー | L34: ー | M34: ー | N34: ー | O34: ー | P34: ー
D35: ファンクションキー | E35: =ROW()-3 -> 32 | G35: 動作すること | H35: □ | I35: ー | J35: ー | K35: ー | L35: ー | M35: ー | N35: ー | O35: ー | P35: ー
D36: 電子多項目 物理キー | E36: =ROW()-3 -> 33 | G36: 動作すること | H36: □ | I36: ー | J36: ー | K36: ー | L36: ー | M36: ー | N36: ー | O36: ー | P36: ー
D37: 電子多項目 電子キー | E37: =ROW()-3 -> 34 | G37: 動作すること | H37: □ | I37: ー | J37: ー | K37: ー | L37: ー | M37: ー | N37: ー | O37: ー | P37: ー
D38: 単品一覧 | E38: =ROW()-3 -> 35 | G38: 登録できること | H38: □ | I38: ー | J38: ー | K38: □ | L38: ー | M38: ー | N38: ー | O38: ー | P38: ー
C39: バーコード | D39: JANコード 13桁/8桁 | E39: =ROW()-3 -> 36 | G39: 登録できること | H39: □ | I39: ー | J39: ー | K39: ー | L39: ー | M39: ー | N39: ー | O39: ー | P39: ー
D40: NON－PLUコード | E40: =ROW()-3 -> 37 | F40: 02から始まるバーコード 肉魚量売りバーコード バーコード後ろ下2桁から値段となる。 | G40: 登録できること | H40: □ | I40: ー | J40: ー | K40: ー | L40: ー | M40: ー | N40: ー | O40: ー | P40: ー
...

Sheet パッケージ系 (PS)
B1: いなげや様 パッケージ リグレッションテスト仕様書
B2: 大分類 | C2: 中分類 | D2: 小分類 | E2: テスト項目 | H2: PS | Q2: チェック日付 | T2: 担当 | U2: 備考
E3: No | F3: POS操作 | G3: 結果 | H3: 動作 | I3: DB | J3: ｶｽﾀﾏ | K3: 画面 | L3: ﾚｼｰﾄ | M3: ｼﾞｬｰﾅﾙ | N3: 音声 | O3: ﾛｸﾞ | P3: 小型 LCD | Q3: OK | R3: NG | S3: 修正 OK
B4: 適用確認 | C4: リモメン | D4: PTFLOG | E4: =ROW()-3 -> 1 | F4: ログ確認 対象POS C:\GSFD直下 | G4: PTFLOGを開き、エラーが出力されていないこと | H4: ー | I4: ー | J4: ー | K4: ー | L4: ー | M4: ー | N4: ー | O4: □ | P4: ー
D5: PTFLOG2 | E5: =ROW()-3 -> 2 | F5: ログ確認 対象POS C:\GSFD直下 | G5: PTFLOG2を開き、エラーが出力されていないこと | H5: ー | I5: ー | J5: ー | K5: ー | L5: ー | M5: ー | N5: ー | O5: □ | P5: ー
C6: 外付けPTF適用 | D6: CTKYLOG | E6: =ROW()-3 -> 3 | F6: ログ確認 対象POS C:\CTKY直下 | G6: CTKYLOGを開き、エラーが出力されていないこと | H6: ー | I6: ー | J6: ー | K6: ー | L6: ー | M6: ー | N6: ー | O6: ー | P6: ー
D7: CTKYLOG2 | E7: =ROW()-3 -> 4 | F7: ログ確認 対象POS C:\CTKY直下 | G7: CTKYLOG2を開き、エラーが出力されていないこと | H7: ー | I7: ー | J7: ー | K7: ー | L7: ー | M7: ー | N7: ー | O7: ー | P7: ー
B8: 開局 | D8: 正常開局 | E8: =ROW()-3 -> 5 | G8: 正常に開局されること。決済端末が待機画面になること。 | H8: ー | I8: ー | J8: ー | K8: □ | L8: ー | M8: ー | N8: ー | O8: ー | P8: ー
D9: キーレイアウト | E9: =ROW()-3 -> 6 | G9: キーレイアウト反映の確認 （サーバのテストで、機能キーとプリセットの変更を行い反映されることを確認する） | H9: □ | I9: ー | J9: ー | K9: □ | L9: ー | M9: ー | N9: ー | O9: ー | P9: ー
C10: レシート | D10: さんにち割引 | E10: =ROW()-3 -> 7 | G10: 「さんにち割引」が表示されていること 対象日付が表示されていること | H10: ー | I10: ー | J10: ー | K10: ー | L10: □ | M10: □ | N10: ー | O10: ー | P10: ー
B11: OPキー | C11: 売上 | D11: 部門入力 | E11: =ROW()-3 -> 8 | F11: 動作確認 部門コード クラスボタン | G11: 部門コードを手入力して登録し、正常に登録できることを確認 | H11: □ | I11: ー | J11: ー | K11: □ | L11: ー | M11: ー | N11: ー | O11: ー | P11: ー
D12: フル部門キー登録 | E12: =ROW()-3 -> 9 | F12: プリセットは電子多項目で 登録されているボタン ・部門 フル部門キーはフルの部門キー | G12: プリセットで登録してあるフル部門キーを使用して登録し、 正常に登録できることを確認 | H12: □ | I12: ー | J12: ー | K12: □ | L12: ー | M12: ー | N12: ー | O12: ー | P12: ー
D13: 特売 | E13: =ROW()-3 -> 10 | G13: サーバで特売を登録し、正常にPOSに反映すること（リアルメンテ確認） | H13: □ | I13: ー | J13: ー | K13: □ | L13: ー | M13: ー | N13: ー | O13: ー | P13: ー
D14: キーPLU | E14: =ROW()-3 -> 11 | F14: 商品JANコードを入力しPLUボタン | G14: 正常に売上登録できること | H14: ー | I14: ー | J14: ー | K14: ー | L14: ー | M14: ー | N14: ー | O14: ー | P14: ー | U14: 運用で未使用
D15: 保留 | E15: =ROW()-3 -> 12 | G15: 正常に取引を保留できること | H15: ー | I15: ー | J15: ー | K15: ー | L15: ー | M15: ー | N15: ー | O15: ー | P15: ー | U15: 保留・復元キーなし
D16: 復元 | E16: =ROW()-3 -> 13 | G16: 保留した取引を復元でき、追加で商品登録できること | H16: ー | I16: ー | J16: ー | K16: ー | L16: ー | M16: ー | N16: ー | O16: ー | P16: ー | U16: 保留取引が復元できない（保留取引がある場合、OPモード「クローズ」、Zモード「精算」「保守」「閉局」操作不可）
D17: 乗算登録 | E17: =ROW()-3 -> 14 | G17: 乗算登録が正しくできること（前・後が正しく動作すること） | H17: □ | I17: ー | J17: ー | K17: ー | L17: ー | M17: ー | N17: ー | O17: ー | P17: ー
D18: 値引操作 | E18: =ROW()-3 -> 15 | G18: マニュアル値引が正しく動作すること（前・後が正しく動作すること） | H18: ー | I18: ー | J18: ー | K18: ー | L18: ー | M18: ー | N18: ー | O18: ー | P18: ー | U18: マニュアル値引ボタンなし
E19: =ROW()-3 -> 16 | G19: 2人制時、明細一覧画面にて、マニュアル値引が正しく動作すること | H19: ー | I19: ー | J19: ー | K19: ー | L19: ー | M19: ー | N19: ー | O19: ー | P19: ー | U19: マニュアル値引ボタンなし
E20: =ROW()-3 -> 17 | G20: 売価変更が正しくできること | H20: □ | I20: ー | J20: ー | K20: □ | L20: ー | M20: ー | N20: ー | O20: ー | P20: ー
D21: 訂正 | E21: =ROW()-3 -> 18 | G21: 指定訂正／直前訂正が正しくできること | H21: □ | I21: ー | J21: ー | K21: □ | L21: ー | M21: ー | N21: ー | O21: ー | P21: ー
D22: 現外券 | E22: =ROW()-3 -> 19 | F22: 商品券（支払い一覧にて選択） | G22: 現外券での支払い登録が正常にできること | H22: □ | I22: ー | J22: ー | K22: □ | L22: ー | M22: ー | N22: ー | O22: ー | P22: ー
D23: 再登録 | E23: =ROW()-3 -> 20 | G23: 再登録後、再度商品登録できること | H23: □ | I23: ー | J23: ー | K23: ー | L23: ー | M23: ー | N23: ー | O23: ー | P23: ー
D24: レシート印字 | E24: =ROW()-3 -> 21 | G24: 「今回ポイント **p」が表示されること | H24: ー | I24: ー | J24: ー | K24: ー | L24: □ | M24: □ | N24: ー | O24: ー | P24: ー
E25: =ROW()-3 -> 22 | G25: 「現在ポイント **p」が表示されること | H25: ー | I25: ー | J25: ー | K25: ー | L25: □ | M25: □ | N25: ー | O25: ー | P25: ー
E26: =ROW()-3 -> 23 | G26: 今回ポイント、現在ポイントのみ表示されること | H26: ー | I26: ー | J26: ー | K26: ー | L26: □ | M26: □ | N26: ー | O26: ー | P26: ー
D27: レシート印字（クレジット） | E27: =ROW()-3 -> 24 | G27: クレジットレシートのクレジット会社名印字が正しく印字されること | H27: ー | I27: ー | J27: ー | K27: ー | L27: □ | M27: □ | N27: ー | O27: ー | P27: ー
C28: デバイス | D28: 固定スキャナ | E28: =ROW()-3 -> 25 | G28: 商品登録できること | H28: □ | I28: ー | J28: ー | K28: ー | L28: ー | M28: ー | N28: ー | O28: ー | P28: ー
D29: タッチスキャナ | E29: =ROW()-3 -> 26 | G29: 商品登録できること | H29: ー | I29: ー | J29: ー | K29: ー | L29: ー | M29: ー | N29: ー | O29: ー | P29: ー | U29: PSタッチスキャナ接続なし
D30: IC決済端末 | E30: =ROW()-3 -> 27 | G30: カードの読み込みができること（ＩＣあり・ＩＣなし） | H30: □ | I30: ー | J30: ー | K30: ー | L30: ー | M30: ー | N30: ー | O30: ー | P30: ー
E31: =ROW()-3 -> 28 | G31: Vカード会員宣言ができること | H31: □ | I31: ー | J31: ー | K31: ー | L31: ー | M31: ー | N31: ー | O31: ー | P31: ー
D32: MSR（カードリーダ） | E32: =ROW()-3 -> 29 | G32: カードの読取できないこと | H32: ー | I32: ー | J32: ー | K32: ー | L32: ー | M32: ー | N32: ー | O32: ー | P32: ー
D33: MSR2（カードリーダ） | E33: =ROW()-3 -> 30 | G33: カードの読取できないこと（電子多項目横） | H33: ー | I33: ー | J33: ー | K33: ー | L33: ー | M33: ー | N33: ー | O33: ー | P33: ー
D34: メインキー | E34: =ROW()-3 -> 31 | G34: 動作すること | H34: ー | I34: ー | J34: ー | K34: ー | L34: ー | M34: ー | N34: ー | O34: ー | P34: ー
D35: ファンクションキー | E35: =ROW()-3 -> 32 | G35: 動作すること | H35: □ | I35: ー | J35: ー | K35: ー | L35: ー | M35: ー | N35: ー | O35: ー | P35: ー
D36: 電子多項目 物理キー | E36: =ROW()-3 -> 33 | G36: 動作すること | H36: ー | I36: ー | J36: ー | K36: ー | L36: ー | M36: ー | N36: ー | O36: ー | P36: ー
D37: 電子多項目 電子キー | E37: =ROW()-3 -> 34 | G37: 動作すること | H37: ー | I37: ー | J37: ー | K37: ー | L37: ー | M37: ー | N37: ー | O37: ー | P37: ー
D38: 単品一覧 | E38: =ROW()-3 -> 35 | G38: 登録できること | H38: □ | I38: ー | J38: ー | K38: □ | L38: ー | M38: ー | N38: ー | O38: ー | P38: ー
C39: バーコード | D39: JANコード 13桁/8桁 | E39: =ROW()-3 -> 36 | G39: 登録できること | H39: □ | I39: ー | J39: ー | K39: ー | L39: ー | M39: ー | N39: ー | O39: ー | P39: ー
D40: NON－PLUコード | E40: =ROW()-3 -> 37 | F40: 02から始まるバーコード 肉魚量売りバーコード バーコード後ろ下2桁から値段となる。 | G40: 登録できること | H40: □ | I40: ー | J40: ー | K40: ー | L40: ー | M40: ー | N40: ー | O40: ー | P40: ー
...

Sheet サーバ系
B1: いなげや様 サーバ リグレッションテスト仕様書 | X1: 更新日：
B2: NO | C2: 大分類 | D2: 中分類 | E2: 小分類 | F2: テスト項目 | G2: 確認項目 | U2: 確認日 | V2: 担当者 | W2: 結果 | X2: 備考
G3: 画面 | H3: ｶｽﾀﾏ ﾃﾞｨｽ ﾌﾟﾚｲ | I3: 多項目 ｵﾍﾟﾚｰﾀ | J3: 多項目 ｶｽﾀﾏ | K3: ﾚｼｰﾄ | L3: ｼﾞｬｰﾅﾙ | M3: ﾄﾞﾛｱ | N3: ﾚﾎﾟｰﾄ | O3: KB操作 | P3: ﾌｧﾝｸｼｮﾝ 操作 | Q3: 集計 | R3: ﾌｧｲﾙ ﾚｲｱｳﾄ | S3: 帳票 | T3: ﾛｸﾞ
B4: =ROW()-3 -> 1 | C4: 適用確認 | D4: リモメン | E4: PTFLOG | F4: PTFLOGを開き、エラーが出力されていないこと | T4: ○ | X4: エラーという文言がでているとは限らない。 リモメン適用した個所だけ確認しおかしい文言がないか確認する。
B5: =ROW()-3 -> 2 | C5: 適用確認 | D5: リモメン | E5: PTFLOG2 | F5: PTFLOG2を開き、エラーが出力されていないこと | T5: ○ | X5: エラーという文言がでているとは限らない。 リモメン適用した個所だけ確認しおかしい文言がないか確認する。
B6: =ROW()-3 -> 3 | C6: 適用確認 | D6: 外付け適用 | E6: CTKYLOG | F6: CTKYLOGを開き、エラーが出力されていないこと | T6: ○ | X6: エラーという文言がでているとは限らない。 外付け適用した個所だけ確認しおかしい文言がないか確認する。
B7: =ROW()-3 -> 4 | C7: 適用確認 | D7: 外付け適用 | E7: CTKYLOG2 | F7: CTKYLOG2を開き、エラーが出力されていないこと | T7: ○ | X7: エラーという文言がでているとは限らない。 外付け適用した個所だけ確認しおかしい文言がないか確認する。
B8: =ROW()-3 -> 5 | C8: 適用確認 | D8: PTF戻し | E8: Restore | F8: PTF戻しを行えること
B9: =ROW()-3 -> 6 | C9: 開店 | D9: 開局処理 | F9: 開局処理が正常に行われること | G9: ○
B10: =ROW()-3 -> 7 | C10: 閉店 | D10: 閉局処理 | F10: 閉局処理が正常に行われること | G10: ○
B11: =ROW()-3 -> 8 | C11: 運用 | D11: 店舗状態管理 | E11: POS稼動状況確認 | F11: POSの現在の稼動状況が正しく表示されていること（稼働中／精算済等） | G11: ○
B12: =ROW()-3 -> 9 | C12: 店舗 | D12: 設定・照会 | E12: 担当者マスタ設定 | F12: 担当者の新規登録ができ、POSに反映すること | G12: ○ | X12: 店舗⇒設定・照会⇒担当者マスタ設定 ⇒従業員コードポップアップをキャンセル ⇒追加⇒担当者情報を入力※従業員コードは適当（番号を入力）
B13: =ROW()-3 -> 10 | C13: 店舗 | D13: 各種リスト出力 | E13: 担当者マスタ出力 | F13: 画面が正しく表示されること （プリンタがある環境の場合、正しく印刷できることを確認する） | G13: □ | S13: □ | X13: 担当者マスタ設定が出力されればOK
B14: =ROW()-3 -> 11 | C14: 店舗 | D14: 売変 | E14: 山積・企画設定 特売単品 | F14: 特売の設定ができ、POSに反映すること | G14: ○ | X14: 企画を適当に登録。 特売単品で商品を登録。
B15: =ROW()-3 -> 12 | C15: 店舗 | D15: 売変 | E15: 山積・企画設定 組合せグループ | F15: バンドル設定ができ、POSに反映すること | G15: □ | X15: 同一商品複数個で値引
B16: =ROW()-3 -> 13 | C16: 店舗 | D16: 売変 | E16: 山積・企画設定 組合せグループ | F16: ミックス販売設定ができ、POSに反映すること | G16: □ | X16: 不同商品複数個で値引
B17: =ROW()-3 -> 14 | C17: 店舗 | D17: 売変 | E17: 自動値引設定 | F17: 部門階層自動値引の設定ができ、POSに反映すること | G17: ○ | X17: 自動値引きする商品を選ぶ⇒店舗⇒売変⇒自動値引き設定 分類No. 開始日 終了日 大分類 中分類 値引き情報⇒更新
B18: =ROW()-3 -> 15 | C18: 店舗 | D18: 売変 | E18: 青果・単品グループ設定 | F18: 単品グループを新規登録でき、単品グループ単品の登録ができること | G18: ○ | X18: 野菜等、グループ設定し帳票出力に使っていた。 単品グループへの登録後は、「システム管理」→「設定・照会」→「商品管理」→「設定情報出力」→「単品グループ」→「印刷」
B19: =ROW()-3 -> 16 | C19: 店舗 | D19: 設定・照会 | E19: 電子多項目設定 | F19: 電子多項目の設定ができ、POSに反映すること | G19: ○ | X19: スキャンコードを先に入力しないと画像割り付けができない 何回か取引すると割り付けられる
B20: =ROW()-3 -> 17 | C20: 店舗 | D20: 設定・照会 | E20: 営業中メンテナンス | F20: 但し書の設定変更ができ、POSに反映すること （ｺﾏｰｼｬﾙﾒｯｾｰｼﾞについては、POS系テスト項目で確認） | G20: ○
B21: =ROW()-3 -> 18 | C21: 店舗 | D21: 設定・照会 | E21: お知らせメッセージメンテナンス | F21: お知らせメッセージの設定変更ができ、POSに反映すること | G21: ○
B22: =ROW()-3 -> 19 | C22: 店舗 | D22: 設定・照会 | E22: 電子ジャーナル照会 | F22: 画面が表示されること／設定操作が可能であること | G22: ○
B23: =ROW()-3 -> 20 | C23: 店舗 | D23: 設定・照会 | E23: 電子ジャーナル照会 (F3)詳細 | F23: 詳細検索条件を入力して、検索ができること | G23: ○
B24: =ROW()-3 -> 21 | C24: 店舗 | D24: 設定・照会 | E24: 電子ジャーナル照会 (F11)ﾃｷｽﾄ | F24: テキスト出力ができること | G24: ○
B25: =ROW()-3 -> 22 | C25: 店舗 | D25: 売上速報 | E25: 部門実績フラッシュ(速報) | F25: 売上登録した内容が正しく集計されていること | N25: △
B26: =ROW()-3 -> 23 | C26: 店舗 | D26: データ活用 | E26: 商品階層別 商品階層別速報 | F26: 売上登録した内容が正しく集計されていること | N26: △
B27: =ROW()-3 -> 24 | C27: 店舗 | D27: データ活用 | E27: 担当者別 担当者別速報 | F27: 売上登録した内容が正しく集計されていること | N27: △
B28: =ROW()-3 -> 25 | C28: 店舗 | D28: データ活用 | E28: 取引別 取引別速報 | F28: 売上登録した内容が正しく集計されていること | N28: △
B29: =ROW()-3 -> 26 | C29: 店舗 | D29: データ活用 | E29: 単品別 単品別速報 | F29: 売上登録した内容が正しく集計されていること | N29: △
B30: =ROW()-3 -> 27 | C30: 店舗 | D30: データ活用 | E30: 商品階層別 商品階層別時間帯別速報 | F30: 売上登録した内容が正しく集計されていること | N30: △
B31: =ROW()-3 -> 28 | C31: 店舗 | D31: データ活用 | E31: 商品階層別 商品階層別日報 | F31: 前日売上登録した内容が正しく集計されていること | N31: △
B32: =ROW()-3 -> 29 | C32: 店舗 | D32: データ活用 | E32: 担当者別 担当者別日報 | F32: 前日売上登録した内容が正しく集計されていること | N32: △
B33: =ROW()-3 -> 30 | C33: 店舗 | D33: データ活用 | E33: 取引別 取引別日報 | F33: 前日売上登録した内容が正しく集計されていること | N33: △
B34: =ROW()-3 -> 31 | C34: 店舗 | D34: データ活用 | E34: 単品別 単品別日報 | F34: 前日売上登録した内容が正しく集計されていること | N34: △ | X34: 単品別日別レポートなし 単品別日別日報ならあったので それで前日売上登録を確認した
B35: =ROW()-3 -> 32 | C35: 店舗 | D35: データ活用 | E35: 商品階層別 商品階層別時間帯別日報 | F35: 前日売上登録した内容が正しく集計されていること | N35: △
B36: =ROW()-3 -> 33 | C36: 店舗 | D36: データ活用 | E36: 商品階層別 商品階層別月報 | F36: 売上登録した内容が正しく集計されていること | N36: △
B37: =ROW()-3 -> 34 | C37: 店舗 | D37: データ活用 | E37: 商品階層別 商品階層別日別月報 | F37: 売上登録した内容が正しく集計されていること | N37: △
B38: =ROW()-3 -> 35 | C38: 店舗 | D38: データ活用 | E38: 単品別 単品別月報 | F38: 売上登録した内容が正しく集計されていること | N38: △
B39: =ROW()-3 -> 36 | C39: 店舗 | D39: 釣銭機レポート | E39: 釣銭機在高レポート | F39: 釣銭機在高内容が表示されること | N39: △ | S39: △ | X39: 店舗⇒釣銭機レポート
B40: =ROW()-3 -> 37 | C40: 店舗 | D40: 釣銭機レポート | E40: 釣銭機在高レポート | F40: 「あふれ」列が存在すること（最右列） | N40: △ | S40: △ | X40: 店舗⇒釣銭機レポート
...

Sheet Win10対応_POS
B1: いなげや様 Win10対応（POS/SS/PS/CS） リグレッションテスト仕様書
B2: 大分類 | C2: 中分類 | D2: 小分類 | E2: テスト項目 | H2: POS | Q2: チェック日付 | T2: 担当 | U2: 備考
E3: No | F3: POS操作 | G3: 結果 | H3: 動作 | I3: DB | J3: ｶｽﾀﾏ | K3: 画面 | L3: ﾚｼｰﾄ | M3: ｼﾞｬｰﾅﾙ | N3: 音声 | O3: ﾛｸﾞ | P3: 小型 LCD | Q3: OK | R3: NG | S3: 修正 OK
B4: 決済端末 | C4: 開局 | E4: =ROW()-3 -> 1 | F4: 開局処理 | G4: 正常に開局されること。決済端末が待機画面になること。 | H4: ー | I4: ー | J4: ー | K4: ー | L4: ー | M4: ー | N4: ー | O4: ー | P4: ー | U4: パッケージ系にて実施
B5: （通常操作） | C5: 会員番号登録 | D5: Vカード | E5: =ROW()-3 -> 2 | F5: Vカードで会員登録 | G5: 正常に会員登録できること | H5: □ | I5: ー | J5: ー | K5: ー | L5: □ | M5: □ | N5: ー | O5: ー | P5: ー
C6: 支払い操作 | D6: 会員宣言：なし Vカード支払い（IC） | E6: =ROW()-3 -> 3 | F6: VカードをICで読み込み | G6: 正常に支払いが完了し売上登録できること | H6: □ | I6: ー | J6: ー | K6: ー | L6: □ | M6: □ | N6: ー | O6: ー | P6: ー | U6: 売上登録できないこと
D7: 会員宣言：なし 他クレ支払い（IC） | E7: =ROW()-3 -> 4 | F7: 他クレカードをICで読み込み | G7: 正常に支払いが完了し売上登録できること | H7: □ | I7: ー | J7: ー | K7: ー | L7: □ | M7: □ | N7: ー | O7: ー | P7: ー
D8: 会員宣言：なし 他クレ支払い（MSR） | E8: =ROW()-3 -> 5 | F8: 他クレカードをMSRで読み込み | G8: 正常に支払いが完了し売上登録できること | H8: □ | I8: ー | J8: ー | K8: ー | L8: □ | M8: □ | N8: ー | O8: ー | P8: ー
D9: 会員宣言：ingカード（ﾀｯﾁｽｷｬﾅ） Vカード支払い（IC） | E9: =ROW()-3 -> 6 | F9: VカードをICで読み込み | G9: 正常に支払いが完了し売上登録できること | H9: □ | I9: ー | J9: ー | K9: ー | L9: □ | M9: □ | N9: ー | O9: ー | P9: ー
D10: 会員宣言：ingカード（手入力） 他クレ支払い（IC） | E10: =ROW()-3 -> 7 | F10: 他クレカードをICで読み込み | G10: 正常に支払いが完了し売上登録できること | H10: □ | I10: ー | J10: ー | K10: ー | L10: □ | M10: □ | N10: ー | O10: ー | P10: ー
D11: 会員宣言：ingカード（ﾀｯﾁｽｷｬﾅ） 他クレ支払い（MSR） | E11: =ROW()-3 -> 8 | F11: 他クレカードをMSRで読み込み | G11: 正常に支払いが完了し売上登録できること | H11: □ | I11: ー | J11: ー | K11: ー | L11: □ | M11: □ | N11: ー | O11: ー | P11: ー
D12: 会員宣言：Vカード Vカード支払い（IC） | E12: =ROW()-3 -> 9 | F12: VカードをICで読み込み | G12: 正常に支払いが完了し売上登録できること | H12: □ | I12: ー | J12: ー | K12: ー | L12: □ | M12: □ | N12: ー | O12: ー | P12: ー
D13: 会員宣言：Vカード 他クレ支払い（IC） | E13: =ROW()-3 -> 10 | F13: 他クレカードをICで読み込み | G13: 正常に支払いが完了し売上登録できること | H13: □ | I13: ー | J13: ー | K13: ー | L13: □ | M13: □ | N13: ー | O13: ー | P13: ー
D14: 会員宣言：Vカード 他クレ支払い（MSR） | E14: =ROW()-3 -> 11 | F14: 他クレカードをMSRで読み込み | G14: 正常に支払いが完了し売上登録できること | H14: □ | I14: ー | J14: ー | K14: ー | L14: □ | M14: □ | N14: ー | O14: ー | P14: ー
C15: 通番取消 | D15: 元取引：会員宣言なし Vカード支払い | E15: =ROW()-3 -> 12 | F15: 元取引と同じVカードをICで読み込み | G15: 正常に取消処理が完了すること | H15: ー | I15: ー | J15: ー | K15: ー | L15: ー | M15: ー | N15: ー | O15: ー | P15: ー | U15: 売上登録不可
D16: 元取引：ingカードで会員宣言 Vカード支払い | E16: =ROW()-3 -> 13 | F16: 元取引と同じVカードをMSRで読み込み | G16: 正常に取消処理が完了すること | H16: □ | I16: ー | J16: ー | K16: ー | L16: □ | M16: □ | N16: ー | O16: ー | P16: ー
D17: 元取引：Vカードで会員宣言 Vカード支払い | E17: =ROW()-3 -> 14 | F17: 元取引と同じVカードをICで読み込み | G17: 正常に取消処理が完了すること | H17: □ | I17: ー | J17: ー | K17: ー | L17: □ | M17: □ | N17: ー | O17: ー | P17: ー
D18: 元取引：会員宣言なし 他クレ支払い | E18: =ROW()-3 -> 15 | F18: 元取引と同じ他クレカードをMSRで読み込み | G18: 正常に取消処理が完了すること | H18: □ | I18: ー | J18: ー | K18: ー | L18: □ | M18: □ | N18: ー | O18: ー | P18: ー
D19: 元取引がingカードで会員宣言 他クレ支払い | E19: =ROW()-3 -> 16 | F19: 元取引と同じ他クレカードをICで読み込み | G19: 正常に取消処理が完了すること | H19: □ | I19: ー | J19: ー | K19: ー | L19: □ | M19: □ | N19: ー | O19: ー | P19: ー
D20: 元取引がVカードで会員宣言 他クレ支払い | E20: =ROW()-3 -> 17 | F20: 元取引と同じ他クレカードをMSRで読み込み | G20: 正常に取消処理が完了すること | H20: □ | I20: ー | J20: ー | K20: ー | L20: □ | M20: □ | N20: ー | O20: ー | P20: ー
C21: 通番修正 | D21: 元取引がVカード支払い | E21: =ROW()-3 -> 18 | F21: 元取引と同じVカードで通番取消、同じVカードで支払い | G21: 元取引の取消処理と修正後の取引が正常に完了すること | H21: □ | I21: ー | J21: ー | K21: ー | L21: □ | M21: □ | N21: ー | O21: ー | P21: ー
E22: =ROW()-3 -> 19 | F22: 元取引と同じVカードで通番取消、他クレカードで支払い | G22: 元取引の取消処理と修正後の取引が正常に完了すること | H22: □ | I22: ー | J22: ー | K22: ー | L22: □ | M22: □ | N22: ー | O22: ー | P22: ー
E23: =ROW()-3 -> 20 | F23: 元取引と同じVカードで通番取消、現金で支払い | G23: 元取引の取消処理と修正後の取引が正常に完了すること | H23: □ | I23: ー | J23: ー | K23: ー | L23: □ | M23: □ | N23: ー | O23: ー | P23: ー
D24: 元取引が他クレ支払い | E24: =ROW()-3 -> 21 | F24: 元取引と同じ他クレで通番取消、同じカードで支払い | G24: 元取引の取消処理と修正後の取引が正常に完了すること | H24: □ | I24: ー | J24: ー | K24: ー | L24: □ | M24: □ | N24: ー | O24: ー | P24: ー
E25: =ROW()-3 -> 22 | F25: 元取引と同じ他クレで通番取消、Vカードで支払い | G25: 元取引の取消処理と修正後の取引が正常に完了すること | H25: □ | I25: ー | J25: ー | K25: ー | L25: □ | M25: □ | N25: ー | O25: ー | P25: ー | U25: 会員宣言必要
E26: =ROW()-3 -> 23 | F26: 元取引と同じ他クレで通番取消、現金で支払い | G26: 元取引の取消処理と修正後の取引が正常に完了すること | H26: □ | I26: ー | J26: ー | K26: ー | L26: □ | M26: □ | N26: ー | O26: ー | P26: ー
B27: 練習モード | C27: 会員番号登録 | D27: Vカード | E27: =ROW()-3 -> 24 | F27: Vカードで会員登録 | G27: 正常に会員登録できること | H27: □ | I27: ー | J27: ー | K27: ー | L27: □ | M27: □ | N27: ー | O27: ー | P27: ー
C28: 支払い操作 | D28: 会員宣言：なし Vカード支払い（IC） | E28: =ROW()-3 -> 25 | F28: VカードをICで読み込み | G28: 練習：正常に支払いが完了し売上登録できること | H28: ー | I28: ー | J28: ー | K28: ー | L28: ー | M28: ー | N28: ー | O28: ー | P28: ー | U28: 会員宣言なしVカード支払不可
D29: 会員宣言：なし 他クレ支払い（IC） | E29: =ROW()-3 -> 26 | F29: 他クレカードをICで読み込み | G29: 練習：正常に支払いが完了し売上登録できること | H29: □ | I29: ー | J29: ー | K29: ー | L29: □ | M29: □ | N29: ー | O29: ー | P29: ー
D30: 会員宣言：なし 他クレ支払い（MSR） | E30: =ROW()-3 -> 27 | F30: 他クレカードをMSRで読み込み | G30: 練習：正常に支払いが完了し売上登録できること | H30: □ | I30: ー | J30: ー | K30: ー | L30: □ | M30: □ | N30: ー | O30: ー | P30: ー
D31: 会員宣言：ingカード（ﾀｯﾁｽｷｬﾅ） Vカード支払い（IC） | E31: =ROW()-3 -> 28 | F31: VカードをICで読み込み | G31: 練習：正常に支払いが完了し売上登録できること | H31: □ | I31: ー | J31: ー | K31: ー | L31: □ | M31: □ | N31: ー | O31: ー | P31: ー
D32: 会員宣言：ingカード（手入力） 他クレ支払い（IC） | E32: =ROW()-3 -> 29 | F32: 他クレカードをICで読み込み | G32: 練習：正常に支払いが完了し売上登録できること | H32: □ | I32: ー | J32: ー | K32: ー | L32: □ | M32: □ | N32: ー | O32: ー | P32: ー
D33: 会員宣言：ingカード（ﾀｯﾁｽｷｬﾅ） 他クレ支払い（MSR） | E33: =ROW()-3 -> 30 | F33: 他クレカードをMSRで読み込み | G33: 練習：正常に支払いが完了し売上登録できること | H33: □ | I33: ー | J33: ー | K33: ー | L33: □ | M33: □ | N33: ー | O33: ー | P33: ー
D34: 会員宣言：Vカード Vカード支払い（IC） | E34: =ROW()-3 -> 31 | F34: VカードをICで読み込み | G34: 練習：正常に支払いが完了し売上登録できること | H34: □ | I34: ー | J34: ー | K34: ー | L34: □ | M34: □ | N34: ー | O34: ー | P34: ー
D35: 会員宣言：Vカード 他クレ支払い（IC） | E35: =ROW()-3 -> 32 | F35: 他クレカードをICで読み込み | G35: 練習：正常に支払いが完了し売上登録できること | H35: □ | I35: ー | J35: ー | K35: ー | L35: □ | M35: □ | N35: ー | O35: ー | P35: ー
D36: 会員宣言：Vカード 他クレ支払い（MSR） | E36: =ROW()-3 -> 33 | F36: 他クレカードをMSRで読み込み | G36: 練習：正常に支払いが完了し売上登録できること | H36: □ | I36: ー | J36: ー | K36: ー | L36: □ | M36: □ | N36: ー | O36: ー | P36: ー
C37: 通番取消 | D37: 元取引：会員宣言なし Vカード支払い | E37: =ROW()-3 -> 34 | F37: 元取引と同じVカードをICで読み込み | G37: 練習：正常に取消処理が完了すること | H37: ー | I37: ー | J37: ー | K37: ー | L37: ー | M37: ー | N37: ー | O37: ー | P37: ー | U37: 会員宣言なしVカード支払不可
D38: 元取引：ingカードで会員宣言 Vカード支払い | E38: =ROW()-3 -> 35 | F38: 元取引と同じVカードをMSRで読み込み | G38: 練習：正常に取消処理が完了すること | H38: □ | I38: ー | J38: ー | K38: ー | L38: □ | M38: □ | N38: ー | O38: ー | P38: ー
D39: 元取引：会員宣言なし 他クレ支払い | E39: =ROW()-3 -> 36 | F39: 元取引と同じ他クレカードをMSRで読み込み | G39: 練習：正常に取消処理が完了すること | H39: □ | I39: ー | J39: ー | K39: ー | L39: □ | M39: □ | N39: ー | O39: ー | P39: ー
D40: 元取引がVカードで会員宣言 他クレ支払い | E40: =ROW()-3 -> 37 | F40: 元取引と同じ他クレカードをMSRで読み込み | G40: 練習：正常に取消処理が完了すること | H40: □ | I40: ー | J40: ー | K40: ー | L40: □ | M40: □ | N40: ー | O40: ー | P40: ー
...

Sheet Win10対応_SS
B1: いなげや様 Win10対応（POS/SS/PS/CS） リグレッションテスト仕様書
B2: 大分類 | C2: 中分類 | D2: 小分類 | E2: テスト項目 | H2: SS | Q2: チェック日付 | T2: 担当 | U2: 備考
E3: No | F3: POS操作 | G3: 結果 | H3: 動作 | I3: DB | J3: ｶｽﾀﾏ | K3: 画面 | L3: ﾚｼｰﾄ | M3: ｼﾞｬｰﾅﾙ | N3: 音声 | O3: ﾛｸﾞ | P3: 小型 LCD | Q3: OK | R3: NG | S3: 修正 OK
B4: 決済端末 | C4: 開局 | E4: =ROW()-3 -> 1 | F4: 開局処理 | G4: 正常に開局されること。決済端末が待機画面になること。 | H4: ー | I4: ー | J4: ー | K4: ー | L4: ー | M4: ー | N4: ー | O4: ー | P4: ー | U4: 決済端末接続なし
B5: （通常操作） | C5: 会員番号登録 | D5: Vカード | E5: =ROW()-3 -> 2 | F5: Vカードで会員登録 | G5: 正常に会員登録できること | H5: ー | I5: ー | J5: ー | K5: ー | L5: ー | M5: ー | N5: ー | O5: ー | P5: ー
C6: 支払い操作 | D6: 会員宣言：なし Vカード支払い（IC） | E6: =ROW()-3 -> 3 | F6: VカードをICで読み込み | G6: 正常に支払いが完了し売上登録できること | H6: ー | I6: ー | J6: ー | K6: ー | L6: ー | M6: ー | N6: ー | O6: ー | P6: ー | U6: 会員宣言ない場合Vカード支払不可
D7: 会員宣言：なし 他クレ支払い（IC） | E7: =ROW()-3 -> 4 | F7: 他クレカードをICで読み込み | G7: 正常に支払いが完了し売上登録できること | H7: ー | I7: ー | J7: ー | K7: ー | L7: ー | M7: ー | N7: ー | O7: ー | P7: ー
D8: 会員宣言：ingカード（ﾀｯﾁｽｷｬﾅ） 他クレ支払い（MSR） | E8: =ROW()-3 -> 5 | F8: 他クレカードをMSRで読み込み | G8: 正常に支払いが完了し売上登録できること | H8: ー | I8: ー | J8: ー | K8: ー | L8: ー | M8: ー | N8: ー | O8: ー | P8: ー
D9: 会員宣言：Vカード Vカード支払い（IC） | E9: =ROW()-3 -> 6 | F9: VカードをICで読み込み | G9: 正常に支払いが完了し売上登録できること | H9: ー | I9: ー | J9: ー | K9: ー | L9: ー | M9: ー | N9: ー | O9: ー | P9: ー
D10: 会員宣言：Vカード 他クレ支払い（MSR） | E10: =ROW()-3 -> 7 | F10: 他クレカードをMSRで読み込み | G10: 正常に支払いが完了し売上登録できること | H10: ー | I10: ー | J10: ー | K10: ー | L10: ー | M10: ー | N10: ー | O10: ー | P10: ー
C11: 通番取消 | D11: 会員宣言：なし Vカード支払い（IC） | E11: =ROW()-3 -> 8 | F11: 元取引と同じVカードをICで読み込み | G11: 正常に取消処理が完了すること | H11: ー | I11: ー | J11: ー | K11: ー | L11: ー | M11: ー | N11: ー | O11: ー | P11: ー | U11: 会員宣言ない場合Vカード支払不可
D12: 会員宣言：なし 他クレ支払い（IC） | E12: =ROW()-3 -> 9 | F12: 元取引と同じ他クレカードをICで読み込み | G12: 正常に取消処理が完了すること | H12: ー | I12: ー | J12: ー | K12: ー | L12: ー | M12: ー | N12: ー | O12: ー | P12: ー
D13: 会員宣言：ingカード（ﾀｯﾁｽｷｬﾅ） 他クレ支払い（MSR） | E13: =ROW()-3 -> 10 | F13: 元取引と同じ他クレカードをMSRで読み込み | G13: 正常に取消処理が完了すること | H13: ー | I13: ー | J13: ー | K13: ー | L13: ー | M13: ー | N13: ー | O13: ー | P13: ー
D14: 会員宣言：Vカード Vカード支払い（IC） | E14: =ROW()-3 -> 11 | F14: 元取引と同じVカードをICで読み込み | G14: 正常に取消処理が完了すること | H14: ー | I14: ー | J14: ー | K14: ー | L14: ー | M14: ー | N14: ー | O14: ー | P14: ー
D15: 会員宣言：Vカード 他クレ支払い（MSR） | E15: =ROW()-3 -> 12 | F15: 元取引と同じ他クレカードをMSRで読み込み | G15: 正常に取消処理が完了すること | H15: ー | I15: ー | J15: ー | K15: ー | L15: ー | M15: ー | N15: ー | O15: ー | P15: ー
C16: 通番修正 | D16: 元取引がVカード支払い | E16: =ROW()-3 -> 13 | F16: 元取引と同じVカードで通番取消、同じVカードで支払い | G16: 元取引の取消処理と修正後の取引が正常に完了すること | H16: ー | I16: ー | J16: ー | K16: ー | L16: ー | M16: ー | N16: ー | O16: ー | P16: ー
E17: =ROW()-3 -> 14 | F17: 元取引と同じVカードで通番取消、他クレカードで支払い | G17: 元取引の取消処理と修正後の取引が正常に完了すること | H17: ー | I17: ー | J17: ー | K17: ー | L17: ー | M17: ー | N17: ー | O17: ー | P17: ー
E18: =ROW()-3 -> 15 | F18: 元取引と同じVカードで通番取消、現金で支払い | G18: 元取引の取消処理と修正後の取引が正常に完了すること | H18: ー | I18: ー | J18: ー | K18: ー | L18: ー | M18: ー | N18: ー | O18: ー | P18: ー | U18: SS現金支払不可
D19: 元取引が他クレ支払い | E19: =ROW()-3 -> 16 | F19: 元取引と同じ他クレで通番取消、同じカードで支払い | G19: 元取引の取消処理と修正後の取引が正常に完了すること | H19: ー | I19: ー | J19: ー | K19: ー | L19: ー | M19: ー | N19: ー | O19: ー | P19: ー
E20: =ROW()-3 -> 17 | F20: 元取引と同じ他クレで通番取消、Vカードで支払い | G20: 元取引の取消処理と修正後の取引が正常に完了すること | H20: ー | I20: ー | J20: ー | K20: ー | L20: ー | M20: ー | N20: ー | O20: ー | P20: ー
E21: =ROW()-3 -> 18 | F21: 元取引と同じ他クレで通番取消、現金で支払い | G21: 元取引の取消処理と修正後の取引が正常に完了すること | H21: ー | I21: ー | J21: ー | K21: ー | L21: ー | M21: ー | N21: ー | O21: ー | P21: ー | U21: SS現金支払不可
B22: 練習モード | C22: 会員番号登録 | D22: Vカード | E22: =ROW()-3 -> 19 | F22: Vカードで会員登録 | G22: 正常に会員登録できること | H22: ー | I22: ー | J22: ー | K22: ー | L22: ー | M22: ー | N22: ー | O22: ー | P22: ー
C23: 支払い操作 | D23: 会員宣言：なし Vカード支払い（IC） | E23: =ROW()-3 -> 20 | F23: VカードをICで読み込み | G23: 練習：正常に支払いが完了し売上登録できること | H23: ー | I23: ー | J23: ー | K23: ー | L23: ー | M23: ー | N23: ー | O23: ー | P23: ー | U23: 会員宣言ない場合Vカード支払不可
D24: 会員宣言：ingカード（ﾀｯﾁｽｷｬﾅ） Vカード支払い（IC） | E24: =ROW()-3 -> 21 | F24: VカードをICで読み込み | G24: 練習：正常に支払いが完了し売上登録できること | H24: ー | I24: ー | J24: ー | K24: ー | L24: ー | M24: ー | N24: ー | O24: ー | P24: ー
D25: 会員宣言：ingカード（ﾀｯﾁｽｷｬﾅ） 他クレ支払い（MSR） | E25: =ROW()-3 -> 22 | F25: 他クレカードをMSRで読み込み | G25: 練習：正常に支払いが完了し売上登録できること | H25: ー | I25: ー | J25: ー | K25: ー | L25: ー | M25: ー | N25: ー | O25: ー | P25: ー
D26: 会員宣言：Vカード Vカード支払い（IC） | E26: =ROW()-3 -> 23 | F26: VカードをICで読み込み | G26: 練習：正常に支払いが完了し売上登録できること | H26: ー | I26: ー | J26: ー | K26: ー | L26: ー | M26: ー | N26: ー | O26: ー | P26: ー
D27: 会員宣言：Vカード 他クレ支払い（MSR） | E27: =ROW()-3 -> 24 | F27: 他クレカードをMSRで読み込み | G27: 練習：正常に支払いが完了し売上登録できること | H27: ー | I27: ー | J27: ー | K27: ー | L27: ー | M27: ー | N27: ー | O27: ー | P27: ー
C28: 通番取消 | D28: 元取引：会員宣言なし Vカード支払い | E28: =ROW()-3 -> 25 | F28: 元取引と同じVカードをICで読み込み | G28: 練習：正常に取消処理が完了すること | H28: ー | I28: ー | J28: ー | K28: ー | L28: ー | M28: ー | N28: ー | O28: ー | P28: ー | U28: 会員宣言ない場合Vカード支払不可
D29: 元取引：ingカードで会員宣言 Vカード支払い | E29: =ROW()-3 -> 26 | F29: 元取引と同じVカードをMSRで読み込み | G29: 練習：正常に取消処理が完了すること | H29: ー | I29: ー | J29: ー | K29: ー | L29: ー | M29: ー | N29: ー | O29: ー | P29: ー
D30: 元取引：会員宣言なし 他クレ支払い | E30: =ROW()-3 -> 27 | F30: 元取引と同じ他クレカードをMSRで読み込み | G30: 練習：正常に取消処理が完了すること | H30: ー | I30: ー | J30: ー | K30: ー | L30: ー | M30: ー | N30: ー | O30: ー | P30: ー
D31: 元取引がVカードで会員宣言 他クレ支払い | E31: =ROW()-3 -> 28 | F31: 元取引と同じ他クレカードをMSRで読み込み | G31: 練習：正常に取消処理が完了すること | H31: ー | I31: ー | J31: ー | K31: ー | L31: ー | M31: ー | N31: ー | O31: ー | P31: ー
C32: 通番修正 | D32: 元取引がVカード支払い | E32: =ROW()-3 -> 29 | F32: 元取引と同じVカードで通番取消、同じVカードで支払い | G32: 練習：元取引の取消処理と修正後の取引が正常に完了すること | H32: ー | I32: ー | J32: ー | K32: ー | L32: ー | M32: ー | N32: ー | O32: ー | P32: ー
E33: =ROW()-3 -> 30 | F33: 元取引と同じVカードで通番取消、他クレカードで支払い | G33: 練習：元取引の取消処理と修正後の取引が正常に完了すること | H33: ー | I33: ー | J33: ー | K33: ー | L33: ー | M33: ー | N33: ー | O33: ー | P33: ー
D34: 元取引が他クレ支払い | E34: =ROW()-3 -> 31 | F34: 元取引と同じ他クレで通番取消、Vカードで支払い | G34: 練習：元取引の取消処理と修正後の取引が正常に完了すること | H34: ー | I34: ー | J34: ー | K34: ー | L34: ー | M34: ー | N34: ー | O34: ー | P34: ー | U34: 元取引もしくは修正後支払のどちらかで会員宣言が必要
E35: =ROW()-3 -> 32 | F35: 元取引と同じ他クレで通番取消、現金で支払い | G35: 練習：元取引の取消処理と修正後の取引が正常に完了すること | H35: ー | I35: ー | J35: ー | K35: ー | L35: ー | M35: ー | N35: ー | O35: ー | P35: ー | U35: SS現金支払不可
B36: Satisfa | C36: 開局 | E36: =ROW()-3 -> 33 | F36: 開局処理 | G36: POS開局時にエラーが発生しないこと | H36: □ | I36: ー | J36: ー | K36: □ | L36: □ | M36: □ | N36: ー | O36: □ | P36: ー
C37: 会員番号登録 | D37: Vカード | E37: =ROW()-3 -> 34 | F37: Vカードで会員登録 | G37: 正常に会員登録できること。現在ポイントが正しく表示されること | H37: ー | I37: ー | J37: ー | K37: ー | L37: ー | M37: ー | N37: ー | O37: ー | P37: ー
D38: ingfanカード | E38: =ROW()-3 -> 35 | F38: ingfan会員バーコードで会員登録 | G38: 正常に会員登録できること。現在ポイントが正しく表示されること | H38: □ | I38: ー | J38: ー | K38: ー | L38: □ | M38: □ | N38: ー | O38: □ | P38: ー
D39: 手入力 | E39: =ROW()-3 -> 36 | F39: 手入力で会員登録 | G39: 正常に会員登録できること。現在ポイントが正しく表示されること | H39: □ | I39: ー | J39: ー | K39: ー | L39: □ | M39: □ | N39: ー | O39: □ | P39: ー
C40: ポイント付与 | D40: Vカード | E40: =ROW()-3 -> 37 | F40: Vカードで会員登録 | G40: 正常に取引が完了すること。今回ポイントが正しく付与されること | H40: ー | I40: ー | J40: ー | K40: ー | L40: ー | M40: ー | N40: ー | O40: ー | P40: ー
...

Sheet Win10対応_PS
B1: いなげや様 Win10対応（POS/SS/PS/CS） リグレッションテスト仕様書
B2: 大分類 | C2: 中分類 | D2: 小分類 | E2: テスト項目 | H2: PS | Q2: チェック日付 | T2: 担当 | U2: 備考
E3: No | F3: POS操作 | G3: 結果 | H3: 動作 | I3: DB | J3: ｶｽﾀﾏ | K3: 画面 | L3: ﾚｼｰﾄ | M3: ｼﾞｬｰﾅﾙ | N3: 音声 | O3: ﾛｸﾞ | P3: 小型 LCD | Q3: OK | R3: NG | S3: 修正 OK
B4: 決済端末 | C4: 開局 | E4: =ROW()-3 -> 1 | F4: 開局処理 | G4: 正常に開局されること。決済端末が待機画面になること。 | H4: ー | I4: ー | J4: ー | K4: ー | L4: ー | M4: ー | N4: ー | O4: ー | P4: ー | U4: パッケージ系(PS)で実施
B5: （通常操作） | C5: 会員番号登録 | D5: Vカード | E5: =ROW()-3 -> 2 | F5: Vカードで会員登録 | G5: 正常に会員登録できること | H5: □ | I5: ー | J5: ー | K5: □ | L5: □ | M5: □ | N5: ー | O5: ー | P5: ー
C6: 支払い操作 | D6: 会員宣言：なし Vカード支払い（IC） | E6: =ROW()-3 -> 3 | F6: VカードをICで読み込み | G6: 正常に支払いが完了し売上登録できること | H6: ー | I6: ー | J6: ー | K6: ー | L6: ー | M6: ー | N6: ー | O6: ー | P6: ー | U6: 会員宣言ない場合Vカード支払不可
D7: 会員宣言：なし 他クレ支払い（IC） | E7: =ROW()-3 -> 4 | F7: 他クレカードをICで読み込み | G7: 正常に支払いが完了し売上登録できること | H7: □ | I7: ー | J7: ー | K7: ー | L7: □ | M7: □ | N7: ー | O7: ー | P7: ー
D8: 会員宣言：ingカード（固定ｶﾒﾗｽｷｬﾅ） 他クレ支払い（MSR） | E8: =ROW()-3 -> 5 | F8: 他クレカードをMSRで読み込み | G8: 正常に支払いが完了し売上登録できること | H8: □ | I8: ー | J8: ー | K8: ー | L8: □ | M8: □ | N8: ー | O8: ー | P8: ー
D9: 会員宣言：Vカード Vカード支払い（IC） | E9: =ROW()-3 -> 6 | F9: VカードをICで読み込み | G9: 正常に支払いが完了し売上登録できること | H9: □ | I9: ー | J9: ー | K9: ー | L9: □ | M9: □ | N9: ー | O9: ー | P9: ー | U9: 蒲田環境VカードIC支払不可、VカードMS支払
D10: 会員宣言：Vカード 他クレ支払い（MSR） | E10: =ROW()-3 -> 7 | F10: 他クレカードをMSRで読み込み | G10: 正常に支払いが完了し売上登録できること | H10: □ | I10: ー | J10: ー | K10: ー | L10: □ | M10: □ | N10: ー | O10: ー | P10: ー
C11: 通番取消 | D11: 会員宣言：なし Vカード支払い（IC） | E11: =ROW()-3 -> 8 | F11: 元取引と同じVカードをICで読み込み | G11: 正常に取消処理が完了すること | H11: ー | I11: ー | J11: ー | K11: ー | L11: ー | M11: ー | N11: ー | O11: ー | P11: ー | U11: 会員宣言ない場合Vカード支払不可
D12: 会員宣言：なし 他クレ支払い（IC） | E12: =ROW()-3 -> 9 | F12: 元取引と同じ他クレカードをICで読み込み | G12: 正常に取消処理が完了すること | H12: □ | I12: ー | J12: ー | K12: ー | L12: □ | M12: □ | N12: ー | O12: ー | P12: ー
D13: 会員宣言：ingカード（固定ｶﾒﾗｽｷｬﾅ） 他クレ支払い（MSR） | E13: =ROW()-3 -> 10 | F13: 元取引と同じ他クレカードをMSRで読み込み | G13: 正常に取消処理が完了すること | H13: □ | I13: ー | J13: ー | K13: ー | L13: □ | M13: □ | N13: ー | O13: ー | P13: ー
D14: 会員宣言：Vカード Vカード支払い（IC） | E14: =ROW()-3 -> 11 | F14: 元取引と同じVカードをICで読み込み | G14: 正常に取消処理が完了すること | H14: □ | I14: ー | J14: ー | K14: ー | L14: □ | M14: □ | N14: ー | O14: ー | P14: ー
D15: 会員宣言：Vカード 他クレ支払い（MSR） | E15: =ROW()-3 -> 12 | F15: 元取引と同じ他クレカードをMSRで読み込み | G15: 正常に取消処理が完了すること | H15: □ | I15: ー | J15: ー | K15: ー | L15: □ | M15: □ | N15: ー | O15: ー | P15: ー
C16: 通番修正 | D16: 元取引がVカード支払い | E16: =ROW()-3 -> 13 | F16: 元取引と同じVカードで通番取消、同じVカードで支払い | G16: 元取引の取消処理と修正後の取引が正常に完了すること | H16: □ | I16: ー | J16: ー | K16: ー | L16: □ | M16: □ | N16: ー | O16: ー | P16: ー
E17: =ROW()-3 -> 14 | F17: 元取引と同じVカードで通番取消、他クレカードで支払い | G17: 元取引の取消処理と修正後の取引が正常に完了すること | H17: □ | I17: ー | J17: ー | K17: ー | L17: □ | M17: □ | N17: ー | O17: ー | P17: ー
E18: =ROW()-3 -> 15 | F18: 元取引と同じVカードで通番取消、現金で支払い | G18: 元取引の取消処理と修正後の取引が正常に完了すること | H18: □ | I18: ー | J18: ー | K18: ー | L18: □ | M18: □ | N18: ー | O18: ー | P18: ー
D19: 元取引が他クレ支払い | E19: =ROW()-3 -> 16 | F19: 元取引と同じ他クレで通番取消、同じカードで支払い | G19: 元取引の取消処理と修正後の取引が正常に完了すること | H19: □ | I19: ー | J19: ー | K19: ー | L19: □ | M19: □ | N19: ー | O19: ー | P19: ー
E20: =ROW()-3 -> 17 | F20: 元取引と同じ他クレで通番取消、Vカードで支払い | G20: 元取引の取消処理と修正後の取引が正常に完了すること | H20: □ | I20: ー | J20: ー | K20: ー | L20: □ | M20: □ | N20: ー | O20: ー | P20: ー
E21: =ROW()-3 -> 18 | F21: 元取引と同じ他クレで通番取消、現金で支払い | G21: 元取引の取消処理と修正後の取引が正常に完了すること | H21: □ | I21: ー | J21: ー | K21: ー | L21: □ | M21: □ | N21: ー | O21: ー | P21: ー
B22: 練習モード | C22: 会員番号登録 | D22: Vカード | E22: =ROW()-3 -> 19 | F22: Vカードで会員登録 | G22: 正常に会員登録できること | H22: □ | I22: ー | J22: ー | K22: ー | L22: □ | M22: □ | N22: ー | O22: ー | P22: ー
C23: 支払い操作 | D23: 会員宣言：なし Vカード支払い（IC） | E23: =ROW()-3 -> 20 | F23: VカードをICで読み込み | G23: 練習：正常に支払いが完了し売上登録できること | H23: ー | I23: ー | J23: ー | K23: ー | L23: ー | M23: ー | N23: ー | O23: ー | P23: ー | U23: 会員宣言ない場合Vカード支払不可
D24: 会員宣言：ingカード（ﾀｯﾁｽｷｬﾅ） Vカード支払い（IC） | E24: =ROW()-3 -> 21 | F24: VカードをICで読み込み | G24: 練習：正常に支払いが完了し売上登録できること | H24: ー | I24: ー | J24: ー | K24: ー | L24: ー | M24: ー | N24: ー | O24: ー | P24: ー | U24: ペイメントモードではfanカード宣言Ｖカード支払不可
D25: 会員宣言：ingカード（ﾀｯﾁｽｷｬﾅ） 他クレ支払い（MSR） | E25: =ROW()-3 -> 22 | F25: 他クレカードをMSRで読み込み | G25: 練習：正常に支払いが完了し売上登録できること | H25: □ | I25: ー | J25: ー | K25: ー | L25: □ | M25: □ | N25: ー | O25: ー | P25: ー
D26: 会員宣言：Vカード Vカード支払い（IC） | E26: =ROW()-3 -> 23 | F26: VカードをICで読み込み | G26: 練習：正常に支払いが完了し売上登録できること | H26: □ | I26: ー | J26: ー | K26: ー | L26: □ | M26: □ | N26: ー | O26: ー | P26: ー
D27: 会員宣言：Vカード 他クレ支払い（MSR） | E27: =ROW()-3 -> 24 | F27: 他クレカードをMSRで読み込み | G27: 練習：正常に支払いが完了し売上登録できること | H27: □ | I27: ー | J27: ー | K27: ー | L27: □ | M27: □ | N27: ー | O27: ー | P27: ー
C28: 通番取消 | D28: 元取引：会員宣言なし Vカード支払い | E28: =ROW()-3 -> 25 | F28: 元取引と同じVカードをICで読み込み | G28: 練習：正常に取消処理が完了すること | H28: ー | I28: ー | J28: ー | K28: ー | L28: ー | M28: ー | N28: ー | O28: ー | P28: ー | U28: 会員宣言ない場合Vカード支払不可
D29: 元取引：ingカードで会員宣言 Vカード支払い | E29: =ROW()-3 -> 26 | F29: 元取引と同じVカードをMSRで読み込み | G29: 練習：正常に取消処理が完了すること | H29: ー | I29: ー | J29: ー | K29: ー | L29: ー | M29: ー | N29: ー | O29: ー | P29: ー
D30: 元取引：会員宣言なし 他クレ支払い | E30: =ROW()-3 -> 27 | F30: 元取引と同じ他クレカードをMSRで読み込み | G30: 練習：正常に取消処理が完了すること | H30: □ | I30: ー | J30: ー | K30: ー | L30: □ | M30: □ | N30: ー | O30: ー | P30: ー
D31: 元取引がVカードで会員宣言 他クレ支払い | E31: =ROW()-3 -> 28 | F31: 元取引と同じ他クレカードをMSRで読み込み | G31: 練習：正常に取消処理が完了すること | H31: □ | I31: ー | J31: ー | K31: ー | L31: □ | M31: □ | N31: ー | O31: ー | P31: ー
C32: 通番修正 | D32: 元取引がVカード支払い | E32: =ROW()-3 -> 29 | F32: 元取引と同じVカードで通番取消、同じVカードで支払い | G32: 練習：元取引の取消処理と修正後の取引が正常に完了すること | H32: □ | I32: ー | J32: ー | K32: ー | L32: □ | M32: □ | N32: ー | O32: ー | P32: ー
E33: =ROW()-3 -> 30 | F33: 元取引と同じVカードで通番取消、他クレカードで支払い | G33: 練習：元取引の取消処理と修正後の取引が正常に完了すること | H33: □ | I33: ー | J33: ー | K33: ー | L33: □ | M33: □ | N33: ー | O33: ー | P33: ー
D34: 元取引が他クレ支払い | E34: =ROW()-3 -> 31 | F34: 元取引と同じ他クレで通番取消、Vカードで支払い | G34: 練習：元取引の取消処理と修正後の取引が正常に完了すること | H34: □ | I34: ー | J34: ー | K34: ー | L34: □ | M34: □ | N34: ー | O34: ー | P34: ー
E35: =ROW()-3 -> 32 | F35: 元取引と同じ他クレで通番取消、現金で支払い | G35: 練習：元取引の取消処理と修正後の取引が正常に完了すること | H35: □ | I35: ー | J35: ー | K35: ー | L35: □ | M35: □ | N35: ー | O35: ー | P35: ー
B36: Satisfa | C36: 開局 | E36: =ROW()-3 -> 33 | F36: 開局処理 | G36: POS開局時にエラーが発生しないこと | H36: □ | I36: ー | J36: ー | K36: ー | L36: ー | M36: ー | N36: ー | O36: □ | P36: ー
C37: 会員番号登録 | D37: Vカード | E37: =ROW()-3 -> 34 | F37: Vカードで会員登録 | G37: 正常に会員登録できること。現在ポイントが正しく表示されること | H37: □ | I37: ー | J37: ー | K37: ー | L37: □ | M37: □ | N37: ー | O37: □ | P37: ー
D38: ingfanカード | E38: =ROW()-3 -> 35 | F38: ingfan会員バーコードで会員登録 | G38: 正常に会員登録できること。現在ポイントが正しく表示されること | H38: □ | I38: ー | J38: ー | K38: ー | L38: □ | M38: □ | N38: ー | O38: □ | P38: ー
D39: 手入力 | E39: =ROW()-3 -> 36 | F39: 手入力で会員登録 | G39: 正常に会員登録できること。現在ポイントが正しく表示されること | H39: □ | I39: ー | J39: ー | K39: ー | L39: □ | M39: □ | N39: ー | O39: □ | P39: ー | U39: POSモード手入力可
C40: ポイント付与 | D40: Vカード | E40: =ROW()-3 -> 37 | F40: Vカードで会員登録 | G40: 正常に取引が完了すること。今回ポイントが正しく付与されること | H40: □ | I40: ー | J40: ー | K40: ー | L40: □ | M40: □ | N40: ー | O40: □ | P40: ー
...

Sheet Win10対応_フルセルフ
B1: いなげや様 Win10対応（POS/SS/PS/CS） リグレッションテスト仕様書
B2: 大分類 | C2: 中分類 | D2: 小分類 | E2: テスト項目 | H2: CS | Q2: チェック日付 | T2: 担当 | U2: 備考
E3: No | F3: POS操作 | G3: 結果 | H3: 動作 | I3: DB | J3: ｶｽﾀﾏ | K3: 画面 | L3: ﾚｼｰﾄ | M3: ｼﾞｬｰﾅﾙ | N3: 音声 | O3: ﾛｸﾞ | P3: 小型 LCD | Q3: OK | R3: NG | S3: 修正 OK
B4: フルセルフ | C4: 開局 | E4: =ROW()-3 -> 1 | F4: 開局処理 | G4: 正常に開局されること。決済端末が待機画面になること。 | H4: □ | I4: ー | J4: ー | K4: □ | L4: □ | M4: □ | N4: ー | O4: ー | P4: ー
B5: （通常操作） | C5: 会員番号登録 | D5: Vカード | E5: =ROW()-3 -> 2 | F5: Vカードで会員登録 | G5: 正常に会員登録できること | H5: □ | I5: ー | J5: ー | K5: □ | L5: □ | M5: □ | N5: ー | O5: ー | P5: ー
C6: 支払い操作 | D6: 会員宣言：なし Vカード支払い（IC） | E6: =ROW()-3 -> 3 | F6: VカードをICで読み込み | G6: 正常に支払いが完了し売上登録できること | H6: ー | I6: ー | J6: ー | K6: ー | L6: ー | M6: ー | N6: ー | O6: ー | P6: ー | U6: 会員宣言ない場合Vカード支払不可
D7: 会員宣言：なし 他クレ支払い（IC） | E7: =ROW()-3 -> 4 | F7: 他クレカードをICで読み込み | G7: 正常に支払いが完了し売上登録できること | H7: □ | I7: ー | J7: ー | K7: ー | L7: □ | M7: □ | N7: ー | O7: ー | P7: ー
D8: 会員宣言：ingカード（ﾀｯﾁｽｷｬﾅ） 他クレ支払い（MSR） | E8: =ROW()-3 -> 5 | F8: 他クレカードをMSRで読み込み | G8: 正常に支払いが完了し売上登録できること | H8: □ | I8: ー | J8: ー | K8: ー | L8: □ | M8: □ | N8: ー | O8: ー | P8: ー
D9: 会員宣言：Vカード Vカード支払い（IC） | E9: =ROW()-3 -> 6 | F9: VカードをICで読み込み | G9: 正常に支払いが完了し売上登録できること | H9: □ | I9: ー | J9: ー | K9: ー | L9: □ | M9: □ | N9: ー | O9: ー | P9: ー | U9: 蒲田環境VカードIC支払不可、VカードMS支払
D10: 会員宣言：Vカード 他クレ支払い（MSR） | E10: =ROW()-3 -> 7 | F10: 他クレカードをMSRで読み込み | G10: 正常に支払いが完了し売上登録できること | H10: □ | I10: ー | J10: ー | K10: ー | L10: □ | M10: □ | N10: ー | O10: ー | P10: ー
C11: 通番取消 | D11: 会員宣言：なし Vカード支払い（IC） | E11: =ROW()-3 -> 8 | F11: 元取引と同じVカードをICで読み込み | G11: 正常に取消処理が完了すること | H11: ー | I11: ー | J11: ー | K11: ー | L11: ー | M11: ー | N11: ー | O11: ー | P11: ー | U11: 会員宣言ない場合Vカード支払不可
D12: 会員宣言：なし 他クレ支払い（IC） | E12: =ROW()-3 -> 9 | F12: 元取引と同じ他クレカードをICで読み込み | G12: 正常に取消処理が完了すること | H12: □ | I12: ー | J12: ー | K12: ー | L12: □ | M12: □ | N12: ー | O12: ー | P12: ー
D13: 会員宣言：ingカード（ﾀｯﾁｽｷｬﾅ） 他クレ支払い（MSR） | E13: =ROW()-3 -> 10 | F13: 元取引と同じ他クレカードをMSRで読み込み | G13: 正常に取消処理が完了すること | H13: □ | I13: ー | J13: ー | K13: ー | L13: □ | M13: □ | N13: ー | O13: ー | P13: ー
D14: 会員宣言：Vカード Vカード支払い（IC） | E14: =ROW()-3 -> 11 | F14: 元取引と同じVカードをICで読み込み | G14: 正常に取消処理が完了すること | H14: □ | I14: ー | J14: ー | K14: ー | L14: □ | M14: □ | N14: ー | O14: ー | P14: ー | U14: 蒲田環境のVカードはIC支払はできないがIC取消は可
D15: 会員宣言：Vカード 他クレ支払い（MSR） | E15: =ROW()-3 -> 12 | F15: 元取引と同じ他クレカードをMSRで読み込み | G15: 正常に取消処理が完了すること | H15: □ | I15: ー | J15: ー | K15: ー | L15: □ | M15: □ | N15: ー | O15: ー | P15: ー
C16: 通番修正 | D16: 元取引がVカード支払い | E16: =ROW()-3 -> 13 | F16: 元取引と同じVカードで通番取消、同じVカードで支払い | G16: 元取引の取消処理と修正後の取引が正常に完了すること | H16: □ | I16: ー | J16: ー | K16: ー | L16: □ | M16: □ | N16: ー | O16: ー | P16: ー
E17: =ROW()-3 -> 14 | F17: 元取引と同じVカードで通番取消、他クレカードで支払い | G17: 元取引の取消処理と修正後の取引が正常に完了すること | H17: □ | I17: ー | J17: ー | K17: ー | L17: □ | M17: □ | N17: ー | O17: ー | P17: ー
E18: =ROW()-3 -> 15 | F18: 元取引と同じVカードで通番取消、現金で支払い | G18: 元取引の取消処理と修正後の取引が正常に完了すること | H18: □ | I18: ー | J18: ー | K18: ー | L18: □ | M18: □ | N18: ー | O18: ー | P18: ー
D19: 元取引が他クレ支払い | E19: =ROW()-3 -> 16 | F19: 元取引と同じ他クレで通番取消、同じカードで支払い | G19: 元取引の取消処理と修正後の取引が正常に完了すること | H19: □ | I19: ー | J19: ー | K19: ー | L19: □ | M19: □ | N19: ー | O19: ー | P19: ー
E20: =ROW()-3 -> 17 | F20: 元取引と同じ他クレで通番取消、Vカードで支払い | G20: 元取引の取消処理と修正後の取引が正常に完了すること | H20: □ | I20: ー | J20: ー | K20: ー | L20: □ | M20: □ | N20: ー | O20: ー | P20: ー
E21: =ROW()-3 -> 18 | F21: 元取引と同じ他クレで通番取消、現金で支払い | G21: 元取引の取消処理と修正後の取引が正常に完了すること | H21: □ | I21: ー | J21: ー | K21: ー | L21: □ | M21: □ | N21: ー | O21: ー | P21: ー
B22: 練習モード | C22: 会員番号登録 | D22: Vカード | E22: =ROW()-3 -> 19 | F22: Vカードで会員登録 | G22: 正常に会員登録できること | H22: □ | I22: ー | J22: ー | K22: □ | L22: □ | M22: □ | N22: ー | O22: ー | P22: ー
C23: 支払い操作 | D23: 会員宣言：なし Vカード支払い（IC） | E23: =ROW()-3 -> 20 | F23: VカードをICで読み込み | G23: 練習：正常に支払いが完了し売上登録できること | H23: ー | I23: ー | J23: ー | K23: ー | L23: ー | M23: ー | N23: ー | O23: ー | P23: ー | U23: 会員宣言ない場合Vカード支払不可
D24: 会員宣言：ingカード（ﾀｯﾁｽｷｬﾅ） Vカード支払い（IC） | E24: =ROW()-3 -> 21 | F24: VカードをICで読み込み | G24: 練習：正常に支払いが完了し売上登録できること | H24: ー | I24: ー | J24: ー | K24: ー | L24: ー | M24: ー | N24: ー | O24: ー | P24: ー | U24: (練習)ペイメントモードではfanカード宣言Ｖカード支払不可
D25: 会員宣言：ingカード（ﾀｯﾁｽｷｬﾅ） 他クレ支払い（MSR） | E25: =ROW()-3 -> 22 | F25: 他クレカードをMSRで読み込み | G25: 練習：正常に支払いが完了し売上登録できること | H25: □ | I25: ー | J25: ー | K25: ー | L25: □ | M25: □ | N25: ー | O25: ー | P25: ー
D26: 会員宣言：Vカード Vカード支払い（IC） | E26: =ROW()-3 -> 23 | F26: VカードをICで読み込み | G26: 練習：正常に支払いが完了し売上登録できること | H26: □ | I26: ー | J26: ー | K26: ー | L26: □ | M26: □ | N26: ー | O26: ー | P26: ー
D27: 会員宣言：Vカード 他クレ支払い（MSR） | E27: =ROW()-3 -> 24 | F27: 他クレカードをMSRで読み込み | G27: 練習：正常に支払いが完了し売上登録できること | H27: □ | I27: ー | J27: ー | K27: ー | L27: □ | M27: □ | N27: ー | O27: ー | P27: ー
C28: 通番取消 | D28: 元取引：会員宣言なし Vカード支払い | E28: =ROW()-3 -> 25 | F28: 元取引と同じVカードをICで読み込み | G28: 練習：正常に取消処理が完了すること | H28: ー | I28: ー | J28: ー | K28: ー | L28: ー | M28: ー | N28: ー | O28: ー | P28: ー | U28: 会員宣言ない場合Vカード支払不可
D29: 元取引：ingカードで会員宣言 Vカード支払い | E29: =ROW()-3 -> 26 | F29: 元取引と同じVカードをMSRで読み込み | G29: 練習：正常に取消処理が完了すること | H29: ー | I29: ー | J29: ー | K29: ー | L29: ー | M29: ー | N29: ー | O29: ー | P29: ー | U29: (練習)ペイメントモードではfanカード宣言Ｖカード支払不可
D30: 元取引：会員宣言なし 他クレ支払い | E30: =ROW()-3 -> 27 | F30: 元取引と同じ他クレカードをMSRで読み込み | G30: 練習：正常に取消処理が完了すること | H30: □ | I30: ー | J30: ー | K30: ー | L30: □ | M30: □ | N30: ー | O30: ー | P30: ー
D31: 元取引がVカードで会員宣言 他クレ支払い | E31: =ROW()-3 -> 28 | F31: 元取引と同じ他クレカードをMSRで読み込み | G31: 練習：正常に取消処理が完了すること | H31: □ | I31: ー | J31: ー | K31: ー | L31: □ | M31: □ | N31: ー | O31: ー | P31: ー
C32: 通番修正 | D32: 元取引がVカード支払い | E32: =ROW()-3 -> 29 | F32: 元取引と同じVカードで通番取消、同じVカードで支払い | G32: 練習：元取引の取消処理と修正後の取引が正常に完了すること | H32: □ | I32: ー | J32: ー | K32: ー | L32: □ | M32: □ | N32: ー | O32: ー | P32: ー
E33: =ROW()-3 -> 30 | F33: 元取引と同じVカードで通番取消、他クレカードで支払い | G33: 練習：元取引の取消処理と修正後の取引が正常に完了すること | H33: □ | I33: ー | J33: ー | K33: ー | L33: □ | M33: □ | N33: ー | O33: ー | P33: ー
D34: 元取引が他クレ支払い | E34: =ROW()-3 -> 31 | F34: 元取引と同じ他クレで通番取消、Vカードで支払い | G34: 練習：元取引の取消処理と修正後の取引が正常に完了すること | H34: □ | I34: ー | J34: ー | K34: ー | L34: □ | M34: □ | N34: ー | O34: ー | P34: ー
E35: =ROW()-3 -> 32 | F35: 元取引と同じ他クレで通番取消、現金で支払い | G35: 練習：元取引の取消処理と修正後の取引が正常に完了すること | H35: □ | I35: ー | J35: ー | K35: ー | L35: □ | M35: □ | N35: ー | O35: ー | P35: ー
B36: Satisfa | C36: 開局 | E36: =ROW()-3 -> 33 | F36: 開局処理 | G36: POS開局時にエラーが発生しないこと | H36: □ | I36: ー | J36: ー | K36: ー | L36: ー | M36: ー | N36: ー | O36: □ | P36: ー
C37: 会員番号登録 | D37: Vカード | E37: =ROW()-3 -> 34 | F37: Vカードで会員登録 | G37: 正常に会員登録できること。現在ポイントが正しく表示されること | H37: □ | I37: ー | J37: ー | K37: ー | L37: □ | M37: □ | N37: ー | O37: □ | P37: ー
D38: ingfanカード | E38: =ROW()-3 -> 35 | F38: ingfan会員バーコードで会員登録 | G38: 正常に会員登録できること。現在ポイントが正しく表示されること | H38: □ | I38: ー | J38: ー | K38: ー | L38: □ | M38: □ | N38: ー | O38: □ | P38: ー
D39: 手入力 | E39: =ROW()-3 -> 36 | F39: 手入力で会員登録 | G39: 正常に会員登録できること。現在ポイントが正しく表示されること | H39: □ | I39: ー | J39: ー | K39: ー | L39: □ | M39: □ | N39: ー | O39: □ | P39: ー | U39: POSモードで手入力可能
C40: ポイント付与 | D40: Vカード | E40: =ROW()-3 -> 37 | F40: Vカードで会員登録 | G40: 正常に取引が完了すること。今回ポイントが正しく付与されること | H40: □ | I40: ー | J40: ー | K40: ー | L40: □ | M40: □ | N40: ー | O40: □ | P40: ー
...

Sheet Win10対応_キャッシュレス
B1: いなげや様 Win10対応（POS/SS/PS/CS） リグレッションテスト仕様書
B2: 大分類 | C2: 中分類 | D2: 小分類 | E2: テスト項目 | H2: CS | Q2: チェック日付 | T2: 担当 | U2: 備考
E3: No | F3: POS操作 | G3: 結果 | H3: 動作 | I3: DB | J3: ｶｽﾀﾏ | K3: 画面 | L3: ﾚｼｰﾄ | M3: ｼﾞｬｰﾅﾙ | N3: 音声 | O3: ﾛｸﾞ | P3: 小型 LCD | Q3: OK | R3: NG | S3: 修正 OK
B4: フルセルフ | C4: 開局 | E4: =ROW()-3 -> 1 | F4: 開局処理 | G4: 正常に開局されること。決済端末が待機画面になること。 | H4: □ | I4: ー | J4: ー | K4: □ | L4: □ | M4: □ | N4: ー | O4: ー | P4: ー
B5: （通常操作） | C5: 会員番号登録 | D5: Vカード | E5: =ROW()-3 -> 2 | F5: Vカードで会員登録 | G5: 正常に会員登録できること | H5: □ | I5: ー | J5: ー | K5: □ | L5: □ | M5: □ | N5: ー | O5: ー | P5: ー
C6: 支払い操作 | D6: 会員宣言：なし Vカード支払い（IC） | E6: =ROW()-3 -> 3 | F6: VカードをICで読み込み | G6: 正常に支払いが完了し売上登録できること | H6: ー | I6: ー | J6: ー | K6: ー | L6: ー | M6: ー | N6: ー | O6: ー | P6: ー | U6: 会員宣言ない場合Vカード支払不可
D7: 会員宣言：なし 他クレ支払い（IC） | E7: =ROW()-3 -> 4 | F7: 他クレカードをICで読み込み | G7: 正常に支払いが完了し売上登録できること | H7: □ | I7: ー | J7: ー | K7: ー | L7: □ | M7: □ | N7: ー | O7: ー | P7: ー
D8: 会員宣言：ingカード（ﾀｯﾁｽｷｬﾅ） 他クレ支払い（MSR） | E8: =ROW()-3 -> 5 | F8: 他クレカードをMSRで読み込み | G8: 正常に支払いが完了し売上登録できること | H8: □ | I8: ー | J8: ー | K8: ー | L8: □ | M8: □ | N8: ー | O8: ー | P8: ー
D9: 会員宣言：Vカード Vカード支払い（IC） | E9: =ROW()-3 -> 6 | F9: VカードをICで読み込み | G9: 正常に支払いが完了し売上登録できること | H9: □ | I9: ー | J9: ー | K9: ー | L9: □ | M9: □ | N9: ー | O9: ー | P9: ー | U9: 蒲田環境VカードIC支払不可、VカードMS支払
D10: 会員宣言：Vカード 他クレ支払い（MSR） | E10: =ROW()-3 -> 7 | F10: 他クレカードをMSRで読み込み | G10: 正常に支払いが完了し売上登録できること | H10: □ | I10: ー | J10: ー | K10: ー | L10: □ | M10: □ | N10: ー | O10: ー | P10: ー
C11: 通番取消 | D11: 会員宣言：なし Vカード支払い（IC） | E11: =ROW()-3 -> 8 | F11: 元取引と同じVカードをICで読み込み | G11: 正常に取消処理が完了すること | H11: ー | I11: ー | J11: ー | K11: ー | L11: ー | M11: ー | N11: ー | O11: ー | P11: ー | U11: 会員宣言ない場合Vカード支払不可
D12: 会員宣言：なし 他クレ支払い（IC） | E12: =ROW()-3 -> 9 | F12: 元取引と同じ他クレカードをICで読み込み | G12: 正常に取消処理が完了すること | H12: □ | I12: ー | J12: ー | K12: ー | L12: □ | M12: □ | N12: ー | O12: ー | P12: ー
D13: 会員宣言：ingカード（ﾀｯﾁｽｷｬﾅ） 他クレ支払い（MSR） | E13: =ROW()-3 -> 10 | F13: 元取引と同じ他クレカードをMSRで読み込み | G13: 正常に取消処理が完了すること | H13: □ | I13: ー | J13: ー | K13: ー | L13: □ | M13: □ | N13: ー | O13: ー | P13: ー
D14: 会員宣言：Vカード Vカード支払い（IC） | E14: =ROW()-3 -> 11 | F14: 元取引と同じVカードをICで読み込み | G14: 正常に取消処理が完了すること | H14: □ | I14: ー | J14: ー | K14: ー | L14: □ | M14: □ | N14: ー | O14: ー | P14: ー | U14: 蒲田環境のVカードはIC支払はできないがIC取消は可
D15: 会員宣言：Vカード 他クレ支払い（MSR） | E15: =ROW()-3 -> 12 | F15: 元取引と同じ他クレカードをMSRで読み込み | G15: 正常に取消処理が完了すること | H15: □ | I15: ー | J15: ー | K15: ー | L15: □ | M15: □ | N15: ー | O15: ー | P15: ー
C16: 通番修正 | D16: 元取引がVカード支払い | E16: =ROW()-3 -> 13 | F16: 元取引と同じVカードで通番取消、同じVカードで支払い | G16: 元取引の取消処理と修正後の取引が正常に完了すること | H16: □ | I16: ー | J16: ー | K16: ー | L16: □ | M16: □ | N16: ー | O16: ー | P16: ー
E17: =ROW()-3 -> 14 | F17: 元取引と同じVカードで通番取消、他クレカードで支払い | G17: 元取引の取消処理と修正後の取引が正常に完了すること | H17: □ | I17: ー | J17: ー | K17: ー | L17: □ | M17: □ | N17: ー | O17: ー | P17: ー
E18: =ROW()-3 -> 15 | F18: 元取引と同じVカードで通番取消、現金で支払い | G18: 元取引の取消処理と修正後の取引が正常に完了すること | H18: □ | I18: ー | J18: ー | K18: ー | L18: □ | M18: □ | N18: ー | O18: ー | P18: ー
D19: 元取引が他クレ支払い | E19: =ROW()-3 -> 16 | F19: 元取引と同じ他クレで通番取消、同じカードで支払い | G19: 元取引の取消処理と修正後の取引が正常に完了すること | H19: □ | I19: ー | J19: ー | K19: ー | L19: □ | M19: □ | N19: ー | O19: ー | P19: ー
E20: =ROW()-3 -> 17 | F20: 元取引と同じ他クレで通番取消、Vカードで支払い | G20: 元取引の取消処理と修正後の取引が正常に完了すること | H20: □ | I20: ー | J20: ー | K20: ー | L20: □ | M20: □ | N20: ー | O20: ー | P20: ー
E21: =ROW()-3 -> 18 | F21: 元取引と同じ他クレで通番取消、現金で支払い | G21: 元取引の取消処理と修正後の取引が正常に完了すること | H21: □ | I21: ー | J21: ー | K21: ー | L21: □ | M21: □ | N21: ー | O21: ー | P21: ー
B22: 練習モード | C22: 会員番号登録 | D22: Vカード | E22: =ROW()-3 -> 19 | F22: Vカードで会員登録 | G22: 正常に会員登録できること | H22: □ | I22: ー | J22: ー | K22: □ | L22: □ | M22: □ | N22: ー | O22: ー | P22: ー
C23: 支払い操作 | D23: 会員宣言：なし Vカード支払い（IC） | E23: =ROW()-3 -> 20 | F23: VカードをICで読み込み | G23: 練習：正常に支払いが完了し売上登録できること | H23: ー | I23: ー | J23: ー | K23: ー | L23: ー | M23: ー | N23: ー | O23: ー | P23: ー | U23: 会員宣言ない場合Vカード支払不可
D24: 会員宣言：ingカード（ﾀｯﾁｽｷｬﾅ） Vカード支払い（IC） | E24: =ROW()-3 -> 21 | F24: VカードをICで読み込み | G24: 練習：正常に支払いが完了し売上登録できること | H24: ー | I24: ー | J24: ー | K24: ー | L24: ー | M24: ー | N24: ー | O24: ー | P24: ー | U24: (練習)ペイメントモードではfanカード宣言Ｖカード支払不可
D25: 会員宣言：ingカード（ﾀｯﾁｽｷｬﾅ） 他クレ支払い（MSR） | E25: =ROW()-3 -> 22 | F25: 他クレカードをMSRで読み込み | G25: 練習：正常に支払いが完了し売上登録できること | H25: □ | I25: ー | J25: ー | K25: ー | L25: □ | M25: □ | N25: ー | O25: ー | P25: ー
D26: 会員宣言：Vカード Vカード支払い（IC） | E26: =ROW()-3 -> 23 | F26: VカードをICで読み込み | G26: 練習：正常に支払いが完了し売上登録できること | H26: □ | I26: ー | J26: ー | K26: ー | L26: □ | M26: □ | N26: ー | O26: ー | P26: ー
D27: 会員宣言：Vカード 他クレ支払い（MSR） | E27: =ROW()-3 -> 24 | F27: 他クレカードをMSRで読み込み | G27: 練習：正常に支払いが完了し売上登録できること | H27: □ | I27: ー | J27: ー | K27: ー | L27: □ | M27: □ | N27: ー | O27: ー | P27: ー
C28: 通番取消 | D28: 元取引：会員宣言なし Vカード支払い | E28: =ROW()-3 -> 25 | F28: 元取引と同じVカードをICで読み込み | G28: 練習：正常に取消処理が完了すること | H28: ー | I28: ー | J28: ー | K28: ー | L28: ー | M28: ー | N28: ー | O28: ー | P28: ー | U28: 会員宣言ない場合Vカード支払不可
D29: 元取引：ingカードで会員宣言 Vカード支払い | E29: =ROW()-3 -> 26 | F29: 元取引と同じVカードをMSRで読み込み | G29: 練習：正常に取消処理が完了すること | H29: ー | I29: ー | J29: ー | K29: ー | L29: ー | M29: ー | N29: ー | O29: ー | P29: ー | U29: (練習)ペイメントモードではfanカード宣言Ｖカード支払不可
D30: 元取引：会員宣言なし 他クレ支払い | E30: =ROW()-3 -> 27 | F30: 元取引と同じ他クレカードをMSRで読み込み | G30: 練習：正常に取消処理が完了すること | H30: □ | I30: ー | J30: ー | K30: ー | L30: □ | M30: □ | N30: ー | O30: ー | P30: ー
