Workbook

Sheet ‎表紙
A1: システム名 | K1: システム種別 | W1: 詳細設計書 | AP1: 作成者 | AT1: 作成日 | AY1: 更新者 | BC1: 更新日 | BH1: 版数
A2: POSサーバー | K2: POSサーバー | AP2: =改訂履歴!$H$11 -> LoiLV | AT2: =改訂履歴!$B$11 -> 45467 | AY2: =LOOKUP(2,1/(改訂履歴!H11:H30000<>""),改訂履歴!H11:H30000) -> SonNH | BC2: =LOOKUP(2,1/(改訂履歴!B11:B30000<>""),改訂履歴!B11:B30000) -> 45811 | BH2: =LOOKUP(2,1/(改訂履歴!O11:O30000<>""),改訂履歴!O11:O30000) -> 0.13
A4: 機能カテゴリ | H4: APX001 | U4: 項目 | Z4: API設計書 | AP4: {=RIGHT(CELL("filename",$A$1),LEN(CELL("filename",$A$1))-FIND("]",CELL("filename",$A$1)))} -> ‎表紙
L16: POSサーバーの基本設計書
L24: =K2&"/"&H4&"/"&Z4 -> POSサーバー/APX001/API設計書
Q44: 承認日 | AA44: 承認者 | AQ44: 版数

Sheet 改訂履歴
A1: システム名 | K1: システム種別 | W1: 詳細設計書 | AP1: 作成者 | AT1: 作成日 | AY1: 更新者 | BC1: 更新日 | BH1: 版数
A2: POSサーバー | K2: POSサーバー | AP2: LoiLV | AT2: 45467 | AY2: SonNH | BC2: 45811 | BH2: 0.13
A4: 機能カテゴリ | H4: APX001 | U4: 項目 | Z4: API設計書 | AP4: {=RIGHT(CELL("filename",$A$1),LEN(CELL("filename",$A$1))-FIND("]",CELL("filename",$A$1)))} -> 改訂履歴
B8: ■改訂履歴
B10: 更新日 | H10: 更新者 | O10: 版数 | S10: 更新内容 | AX10: 承認日 | BD10: 承認者
B11: 45467 | H11: LoiLV | O11: 0.1 | S11: 新規
B13: 45483 | H13: AnhDD | O13: 0.11 | S13: アクセストークンの有効期限修正
B15: 45799 | H15: AnhTTP | O15: 0.12 | S15: DB snake_caseマッピング更新
S16: master_codesからロール取得処理更新
B17: 45803 | H17: LoiLV | O17: 0.12 | S17: パーミッションロジック修正
B19: 45811 | H19: SonNH | O19: 0.13 | S19: 処理フローシート：terminal更新ロジックを更新

Sheet 処理フロー凡例
A1: システム名 | K1: システム種別 | W1: 詳細設計書 | AP1: 作成者 | AT1: 作成日 | AY1: 更新者 | BC1: 更新日 | BH1: 版数
A2: POSサーバー | K2: POSサーバー | AP2: LoiLV | AT2: 45467 | AY2: SonNH | BC2: 45811 | BH2: 0.13
A4: 機能カテゴリ | H4: APX001 | U4: 項目 | Z4: API設計書 | AP4: =MID(CELL("filename",A1),FIND("]",CELL("filename",A1))+1,255) -> 処理フロー凡例
B7: ●API処理フロー

Sheet APX001
A1: システム名 | K1: システム種別 | W1: 詳細設計書 | AP1: 作成者 | AT1: 作成日 | AY1: 更新者 | BC1: 更新日 | BH1: 版数
A2: POSサーバー | K2: POSサーバー | AP2: LoiLV | AT2: 45467 | AY2: SonNH | BC2: 45811 | BH2: 0.13
A4: 機能カテゴリ | H4: APX001 | U4: 項目 | Z4: API設計書 | AP4: =MID(CELL("filename",A1),FIND("]",CELL("filename",A1))+1,255) -> APX001
B7: 1. 概要
C9: ユーザーログインを実行する。
B11: 2. リクエスト
C13: 2.1 Request URL
C15: No. | E15: URL | AG15: HTTPメソッド | AQ15: 備考
C16: 1 | E16: api/v1/auth/login | AG16: POST | AQ16: -
C18: 2. 2 Request Header
C20: No. | E20: ヘッダー | L20: 必須 | O20: 型 | S20: デフォルト値 | Z20: 項目説明 | AQ20: 備考
C21: 1 | E21: Accept | L21: - | O21: String | S21: - | Z21: Accept | AQ21: サーバーが返却できるデータ種類情報を説明する。
C22: 2 | E22: Content-Type | L22: - | O22: String | S22: - | Z22: Content-Type | AQ22: 送信リクエストの本文情報のタイプを定義する。例: application/json, mutilpart/form-data. 転送データのタイプによって、content-typeが必須又は必須ではない。例： ・入力がjsonの場合、content-typeが必須であり、application/jsonの値を受け取る。
C25: 3 | E25: User-Agent | L25: - | O25: String | S25: - | Z25: User-Agent | AQ25: サーバーを呼び出すクライアントのアプリケーション/ソフトウェア/ブラウザを定義する。
C26: 4 | E26: Accept-Encoding | L26: - | O26: String | S26: - | Z26: Accept-Encoding | AQ26: データ暗号化アルゴリズムを定義する。サーバーから受信したデータに使用できる： zip、gzip、png、gif等
C29: 2.3 Query Parameter/ path parameter
D31: NA
C33: 2.4 Request Body
C35: No. | E35: パラメータ | L35: 必須 | O35: 型 | S35: デフォルト値 | Z35: 項目説明 | AQ35: 備考
C36: 1 | E36: company_code | L36: ○ | O36: string | S36: - | Z36: ログインユーザーが所属する企業コード | AQ36: 100: カスミ, 800：いなげや
C37: =C36+1 -> 2 | E37: user_name | L37: ○ | O37: string | S37: - | Z37: ログイン名 | AQ37: 入力バリデーションチェック：MSG_VAL_001。その中、{0}がuser_nameである。
C38: =C37+1 -> 3 | E38: password | L38: ○ | O38: string | S38: - | Z38: パスワード | AQ38: 入力バリデーションチェック：MSG_VAL_001。その中、{0}がpasswordである。
B41: 3. レスポンス
C43: 3.1. 正常の場合のレスポンスフォーマット
C45: No. | E45: JSON name | L45: 型 | S45: 項目説明 | AC45: 備考
C46: 1 | E46: access_token | L46: string | S46: access token | AC46: 有効期限： 5分
C47: =C46+1 -> 2 | E47: refresh_token | L47: string | S47: refresh token | AC47: 有効期限：1日
C48: 3 | E48: user_detail | L48: Object | S48: ユーザー詳細情報 | AC48: -
C49: =C48+1 -> 4 | E49: user_name | L49: string | S49: ユーザーログイン名 | AC49: -
C50: =C49+1 -> 5 | E50: name | L50: string | S50: 表示に使用されるユーザー名 | AC50: -
C51: =C50+1 -> 6 | E51: role_code | L51: string | S51: ユーザーロールコード | AC51: 3つのユーザーロールがある： ・00: System administrator (企業の全て店舗にアクセスする権限) ・01 : Headquarters user (複数の店舗にアクセスする権限) ・02 : Store user (1つの店舗のみにアクセスする権限)
C52: =C51+1 -> 7 | E52: role_name | L52: string | S52: ユーザーロール名 | AC52: -
C53: =C52+1 -> 8 | E53: company_code | L53: string | S53: 企業コード | AC53: 100: カスミ, 800：いなげや companies.company_code
C54: =C53+1 -> 9 | E54: company_name | L54: string | S54: 会社名 | AC54: 100: カスミ, 800：いなげや companies.company_name
C55: =C54+1 -> 10 | E55: store_code | L55: string | S55: 店舗コード | AC55: stores.store_code
C56: =C55+1 -> 11 | E56: store_name | L56: string | S56: 企業コード | AC56: stores.ten_name
C57: =C56+1 -> 12 | E57: permissions | L57: List<Object> | S57: アクセス可能権限一覧 | AC57: -
C58: =C57+1 -> 13 | E58: code | L58: string | S58: パーミッションコード | AC58: 01 - 99: 01～99の機能に該当する。 値が変更された場合、メインメニュー画面上のコード値と画面の配置位置も連動して変更される。
C59: =C58+1 -> 14 | E59: name | L59: json string | S59: 表示名（日本語／英語） | AC59: メインメニュー画面上に表示される画面名
C60: =C59+1 -> 15 | E60: alias_name | L60: string | S60: フロントエンド画面とのキーのマッピング | AC60: 01～99の各機能に該当する画面のURLパス キー
...

Sheet 処理フロー
A1: システム名 | K1: システム種別 | W1: 詳細設計書 | AP1: 作成者 | AT1: 作成日 | AY1: 更新者 | BC1: 更新日 | BH1: 版数
A2: POSサーバー | K2: POSサーバー | AP2: LoiLV | AT2: 45467 | AY2: SonNH | BC2: 45811 | BH2: 0.13
A4: 機能カテゴリ | H4: APX001 | U4: 項目 | Z4: API設計書 | AP4: =MID(CELL("filename",A1),FIND("]",CELL("filename",A1))+1,255) -> 処理フロー

Sheet キーマッピング
A1: システム名 | K1: システム種別 | W1: 詳細設計書 | AP1: 作成者 | AT1: 作成日 | AY1: 更新者 | BC1: 更新日 | BH1: 版数
A2: POSサーバー | K2: POSサーバー | AP2: LoiLV | AT2: 45467 | AY2: SonNH | BC2: 45811 | BH2: 0.13
A4: 機能カテゴリ | H4: APX001 | U4: 項目 | Z4: API設計書 | AP4: =MID(CELL("filename",A1),FIND("]",CELL("filename",A1))+1,255) -> キーマッピング
G9: 画面コード | N9: alias_name | W9: メニューコード
W10: いなげや 800 | Z10: カスミ 100
G11: SC0101 | N11: product-management | W11: 01 | Z11: 01
G12: SC0201 | N12: price-change | W12: 02 | Z12: 02
G13: SC0301 | N13: special-promotion | W13: 03 | Z13: 03
G14: SC0501 | N14: mix-match | W14: 05 | Z14: 05
G15: SC0601 | N15: standard-price | W15: 06 | Z15: 06
G16: SC0801 | N16: master-category | W16: 08 | Z16: 08
G17: SC1001 | N17: promotion-maintenance | W17: 10 | Z17: 10
G18: SC1101 | N18: sales-report | W18: 11 | Z18: 11
G19: SC1201 | N19: product-report | W19: 12 | Z19: 12
G20: SC1401 | N20: sales-tenant-report | W20: 14 | Z20: 14
G21: SC1501 | N21: preset-setting | W21: 15 | Z21: 15
G22: SC1901 | N22: price-change-explanations | W22: 19 | Z22: 19
G23: SC2001 | N23: register-settlement | W23: 20 | Z23: 20
G24: SC2101 | N24: search-journal | W24: 21 | Z24: 21
G25: SC2201 | N25: subtotal-discount-settings | W25: 22 | Z25: 22
G26: SC2801 | N26: receipt-coupon-setting | W26: 28 | Z26: 28
G27: SC2901 | N27: check-time-instores | W27: 29 | Z27: 29
G28: SC3101 | N28: instores-report | W28: 31 | Z28: 31
... G42: SC8001 | N42: master-redistribution | W42: 80 | Z42: 80
G43: SC8101 | N43: setup-alert-payment-machine | Z43: 81
G44: SC8201 | N44: master-stores | W44: 82 | Z44: 82
G45: SC9601 | N45: category-discount-receipt-coupon-settings | W45: 96 | Z45: 96
G46: SC9901 | N46: master-company-settings | W46: 99 | Z46: 99
