Workbook

Sheet Overview
A2: ステータス | C2: Mô tả trạng thái của task・タスクの状態
A3: Backlog | B3: 対応準備中 | C3: Chuẩn bị bị làm | D3: 対応準備中
A4: Doing | B4: 対応中 | C4: Đang thực hiện làm | D4: 対応中
A5: Review | B5: レビュー中 | C5: Reviewer đang thực hiện review | D5: レビュー中（レビュアー対応中）
A6: Test | B6: テスト中 | C6: Tester đang thực hiện test | D6: テスト中（テスター対応中）
A7: Spike | B7: 開発環境にデプロイ済み | C7: Chức năng được triển khai trên môi trường nội bộ | D7: 開発環境にデプロイ済み
A8: Staging | B8: Staging環境にデプロイ済み | C8: Chức năng được triển khai trên môi trường kiểm thử staging | D8: Staging環境にデプロイ済み
A9: Product | B9: 本番環境にデプロイ済み | C9: Chức năng được triển khai trên môi trường sản xuất production | D9: 本番環境にデプロイ済み
A10: Confirm | B10: 確認 | C10: Nhận xác nhận từ khách hàng hoặc Mr.K | D10: 顧客またはMr.Kからの確認取得済み
A11: Done | B11: 完了 | C11: Task được hoàn thành đã qua code, test, review, qua Mr.K | D11: コード・テスト・レビュー・Mr.K確認まで完了済み

Sheet Reports_JP
A1: No | B1: Weekly | C1: Environment | D1: Category | E1: Task | L1: Status | M1: %Done | N1: Effort MD | O1: Start Date | P1: End Date | Q1: Note
A2: 1 | B2: 2025/09/15 ~ 09/19 | C2: Ishida | D2: 新開発 | E2: 【Design】価格変更機能の開発 | L2: =INDEX(Overview!$B$3:$B$11,MATCH(Reports_VN!L2,Overview!$A$3:$A$11,0)) -> 完了 | M2: 1 | N2: 5 | O2: 45905 | P2: 45916 | Q2: 設計の修正およびレビューを実施
A3: 2 | E3: 【Web】価格変更機能の開発 | L3: =INDEX(Overview!$B$3:$B$11,MATCH(Reports_VN!L3,Overview!$A$3:$A$11,0)) -> 完了 | M3: 1 | N3: 10 | O3: 45908 | P3: 45918 | Q3: 今週、Mr.Kのレイアウトを確認・修正
A4: =A3+1 -> 3 | E4: 【Server】価格変更機能の開発 | L4: =INDEX(Overview!$B$3:$B$11,MATCH(Reports_VN!L4,Overview!$A$3:$A$11,0)) -> 完了 | M4: 1 | N4: 10 | O4: 45908 | P4: 45917 | Q4: 今週、各種不具合の確認とレビューを実施
A5: =A4+1 -> 4 | E5: 【Deploy】価格変更機能の開発 | L5: =INDEX(Overview!$B$3:$B$11,MATCH(Reports_VN!L5,Overview!$A$3:$A$11,0)) -> Staging環境にデプロイ済み | M5: 0.8 | N5: 6 | O5: 45917 | P5: 45922 | Q5: Spike環境へのデプロイ：完了（Done） Staging環境でのテストを実施中
A6: =A5+1 -> 5 | D6: モニタリング | E6: 【モニタリング】毎日システムを確認 今週はシステムに関する問題は発生しませんでした。 | L6: =INDEX(Overview!$B$3:$B$11,MATCH(Reports_VN!L6,Overview!$A$3:$A$11,0)) -> 完了 | N6: 5 | O6: 45915 | P6: 45919 | Q6: インポート／エクスポートされたレコードの確認、処理速度やシステムの動作速度を検証 → 本番運用中に発生し得る問題を早期に検知することが目的
A7: =A6+1 -> 6 | D7: 調査 | E7: 【調査】システムの統計を監視・調査、目的：システムの状態を監視できるようにする - No45: 統計方法の修正：完 - システム監視に関する資料：レビュー中 | L7: =INDEX(Overview!$B$3:$B$11,MATCH(Reports_VN!L7,Overview!$A$3:$A$11,0)) -> レビュー中 | M7: 0.9 | N7: 3 | O7: 45915 | P7: 45919
A8: =A7+1 -> 7 | D8: 調査 | E8: 【調査】Ishidaシステムの割引種類（Mix-Match、Category）の調査 | L8: =INDEX(Overview!$B$3:$B$11,MATCH(Reports_VN!L8,Overview!$A$3:$A$11,0)) -> 対応中 | M8: 0.2 | N8: 7 | O8: 45917 | P8: 45926
A9: =A8+1 -> 8 | D9: サポート | E9: 店舗にてお客様サポート対応（An2NBおよびMaiTTTが対応） | L9: =INDEX(Overview!$B$3:$B$11,MATCH(Reports_VN!L9,Overview!$A$3:$A$11,0)) -> 完了 | M9: 1 | N9: =6*2 -> 12 | O9: 45910 | P9: 45915 | Q9: 日本での出張
A10: =A9+1 -> 9 | D10: フィードバック | E10: 毎週、顧客からの発生事項（Issue、QAなど）に対応 QA対応：No83、No85、No86 → 対応済 | L10: =INDEX(Overview!$B$3:$B$11,MATCH(Reports_VN!L10,Overview!$A$3:$A$11,0)) -> 完了 | N10: 7 | O10: 45915 | P10: 45919
A11: =A10+1 -> 10 | C11: POS-Android | D11: POS-Android | E11: 【調査】現在稼働中のPOS-Androidアプリのサーバー調査（AWSへの展開準備） | L11: =INDEX(Overview!$B$3:$B$11,MATCH(Reports_VN!L11,Overview!$A$3:$A$11,0)) -> 対応中 | M11: 0.5 | N11: 5 | O11: 45917 | P11: 45924 | Q11: 旧サーバーをAWSへ移行する目的
B12: 2025/09/22 ~ 09/26 | E12: Không xuất data special_del | O12: 45919
A13: =A11+1 -> 11 | C13: Ishida | D13: 新開発 | E13: 【Deploy】価格変更機能の開発 | L13: =INDEX(Overview!$B$3:$B$11,MATCH(Reports_VN!L14,Overview!$A$3:$A$11,0)) -> Staging環境にデプロイ済み | M13: 0.8 | N13: 6 | O13: 45917 | P13: 45922 | Q13: Spike環境およびStaging環境へのデプロイは完了。 現在、Staging環境でテストを実施中。
A14: =A13+1 -> 12 | D14: 新開発 | E14: Phát triển chức năng đăng ký user | L14: Backlog | N14: 10 | O14: 45922 | P14: 45925
A15: =A14+1 -> 13 | D15: モニタリング | E15: 【モニタリング】毎日システムを確認 | L15: =INDEX(Overview!$B$3:$B$11,MATCH(Reports_VN!L16,Overview!$A$3:$A$11,0)) -> 対応準備中 | N15: 5 | O15: 45922 | P15: 45926 | Q15: 検証用の調査を実施しました：完了 インポート／エクスポートされたレコードの確認、処理速度およびシステムの稼働速度を検証中。 → システム稼働中に発生する問題を早期に検出することを目的とする。
A16: =A15+1 -> 14 | D16: 調査 | E16: 【調査】Ishidaシステムの価格種類（Mix-Match、Category）の調査 | L16: =INDEX(Overview!$B$3:$B$11,MATCH(Reports_VN!L17,Overview!$A$3:$A$11,0)) -> 対応中 | M16: 0.2 | N16: 7 | O16: 45917 | P16: 45926
A17: =A16+1 -> 15 | D17: フィードバック | E17: 顧客からの発生事項（Issue、QAなど）への対応 | L17: =INDEX(Overview!$B$3:$B$11,MATCH(Reports_VN!L18,Overview!$A$3:$A$11,0)) -> 対応準備中 | N17: 7 | O17: 45922 | P17: 45926
A18: =A17+1 -> 16 | D18: 新開発 | E18: 【Web】No45に関連する統計機能の開発 | L18: =INDEX(Overview!$B$3:$B$11,MATCH(Reports_VN!L19,Overview!$A$3:$A$11,0)) -> #N/A | O18: 45922 | P18: 45926
A19: =A18+1 -> 17 | E19: 【Server】No45に関連する統計機能の開発 | L19: =INDEX(Overview!$B$3:$B$11,MATCH(Reports_VN!L20,Overview!$A$3:$A$11,0)) -> #N/A | O19: 45922 | P19: 45926
A20: =A19+1 -> 18 | C20: POS-Android | D20: POS-Android | E20: 【調査】現在稼働中のPOS-Androidアプリのサーバー調査（AWSへの展開準備） | L20: =INDEX(Overview!$B$3:$B$11,MATCH(Reports_VN!L21,Overview!$A$3:$A$11,0)) -> 対応中 | M20: 0.5 | N20: 5 | O20: 45917 | P20: 45925 | Q20: 旧サーバーをAWSへ移行する目的

Sheet Reports_VN
A1: No | B1: Weekly | C1: Environment | D1: Category | E1: Task | L1: Status | M1: %Done | N1: Effort MD | O1: Start Date | P1: End Date | Q1: Note
A2: 1 | B2: 2025/09/15 ~ 09/19 | C2: Ishida | D2: Phát triển mới | E2: [Design]Phát triển chức năng thay đổi giá | L2: Done | M2: 1 | N2: 5 | O2: 45905 | P2: 45916 | Q2: Chỉnh sửa và rà soát lại thiết kế
A3: 2 | E3: [Web]Phát triển chức năng thay đổi giá | L3: Done | M3: 1 | N3: 10 | O3: 45908 | P3: 45918 | Q3: Trong tuần kiểm tra và sửa layout của Mr.K
A4: =A3+1 -> 3 | E4: [Server]Phát triển chức năng thay đổi giá | L4: Done | M4: 1 | N4: 10 | O4: 45908 | P4: 45917 | Q4: Trong tuần kiểm tra và rà soát các lỗi
A5: =A4+1 -> 4 | E5: [Deploy]Phát triển chức năng thay đổi giá | L5: Staging | M5: 0.8 | N5: 6 | O5: 45917 | P5: 45922 | Q5: Đã triển khai lên môi trường spike : Done Đang thực hiện test trên môi trường staging
A6: =A5+1 -> 5 | D6: Monitoring | E6: [Monitoring] Hàng ngày kiểm tra hệ thống Trong tuần không phát hiện các vấn đề về hệ thống | L6: Done | N6: 5 | O6: 45915 | P6: 45919 | Q6: Kiểm tra các bản ghi import/ export, tốc độ xử lý các bản ghi, tốc độ chạy của hệ thống -> mục đích để phát hiện sớm các vấn đề của hệ thống khi đang chạy
A7: =A6+1 -> 6 | D7: Điều tra | E7: Điều tra giám sát thống kê hệ thống, mục đích để có thể giám sát hệ thống - No45: Chỉnh sửa cách thức thống kê: Done - Tài liệu điều tra giám sát hệ thống: Review | L7: Review | M7: 0.9 | N7: 3 | O7: 45915 | P7: 45919
A8: =A7+1 -> 7 | D8: Điều tra | E8: Điều tra các loại giảm giá của hệ thống ishida (Mix-Match, Category) | L8: Doing | M8: 0.2 | N8: 7 | O8: 45917 | P8: 45926
A9: =A8+1 -> 8 | D9: Support | E9: Hỗi trợ khách hàng ở tại cửa hàng, có An2NB và MaiTTT | L9: Done | M9: 1 | N9: =6*2 -> 12 | O9: 45910 | P9: 45915 | Q9: Công tác ở Nhật Bản
A10: =A9+1 -> 9 | D10: Feedbacks | E10: Hàng tuần đối ứng các phát sinh từ khách hàng như là các issues, QA Trả lời QA từ khách hàng No83, No85, No86: Đã closed | L10: Done | N10: 7 | O10: 45915 | P10: 45919
A11: =A10+1 -> 10 | C11: POS-Android | D11: POS-Android | E11: Điều tra các server app pos-android đang chạy để triển khai lên AWS | L11: Doing | M11: 0.5 | N11: 5 | O11: 45917 | P11: 45924 | Q11: Mục đích để triển khai server cũ lên AWS
B12: 2025/09/22 ~ 09/26 | C12: Ishida | D12: CR | E12: Input giá không có thì không export giá | L12: Test | M12: 0.75 | P12: 45925 | Q12: 4h báo cáo lại kết quả cho Mr.K Nếu không có gì thay đổi thì lịch 25/9 xong môi trường spike
D13: FixBug | E13: No 77. Trạng thái bản ghi là xóa đang chưa gửi đúng trạng thái | L13: Spike | M13: 1 | Q13: Đã tạo evidence môi trường spke Sau khi trao đổi export giá gửi lại giải pháp
A14: =A11+1 -> 11 | D14: Phát triển mới | E14: [Deploy]Phát triển chức năng thay đổi giá | L14: Staging | M14: 1 | N14: 6 | O14: 45917 | P14: 45922 | Q14: Đã triển khai lên môi trường spike và staging Đang thực hiện test trên môi trường staging
A15: =A14+1 -> 12 | D15: Phát triển mới | E15: Phát triển chức năng đăng ký user | L15: Spike | M15: 1 | N15: 10 | O15: 45922 | P15: 45925
A16: =A15+1 -> 13 | D16: Monitoring | E16: [Monitoring] Hàng ngày kiểm tra hệ thống | L16: Backlog | N16: 5 | O16: 45922 | P16: 45926
A17: =A16+1 -> 14 | D17: Điều tra | E17: Điều tra để tạo chương trình kiểm tra gia tự động | L17: Doing | M17: 0.5 | N17: 7 | O17: 45917 | P17: 45926
A18: =A17+1 -> 15 | D18: Feedbacks | E18: Đối ứng các phát sinh từ khách hàng như là các issues, QA | L18: Backlog | N18: 7 | O18: 45922 | P18: 45926
A19: =A18+1 -> 16 | E19: Sửa để chỉ sử dụng DB Kasumi
A20: =A19+1 -> 17
A21: =A20+1 -> 18 | C21: POS-Android | D21: POS-Android | E21: Điều tra các server app pos-android đang chạy để triển khai lên AWS | L21: Doing | M21: 0.5 | N21: 5 | O21: 45917 | P21: 45924 | Q21: Mục đích để triển khai server cũ lên AWS

Sheet HopKH
A1: Ngày họp | B1: Tên cuộc họp | C1: Thành viên tham gia họp | D1: Chi tiết về cuộc họp | E1: Đánh giá
A2: 45930 | B2: Họp hàng tuần thứ 3,5 | D2: 1. 電子棚札
D3: • Tài liệu yêu cầu & thiết kế: thời hạn lùi từ 30/9 → 3/10. | E3: BK làm
D4: • File P001 (200MB): gửi thất bại → Tanaka-san xác nhận không ảnh hưởng production.
D5: • Lỗi hiển thị tên sản phẩm (文字化け): nguyên nhân do “tên sản phẩm Kana” → Tanaka-san đang xác nhận.
D6: • Thay đổi layout (dự kiến họp 3/10 với các bên liên quan): | E6: Chưa chốt để làm, mới chỉ trao đổi
D7: 1. Góc trái dưới: hiển thị JAN code thay cho Product code.
D8: 2. Thêm hiển thị số kệ (棚番号).
D9: 3. Góc phải dưới: thay 部門–部門 cho format hiện tại (部門–8桁商品コード).
D10: • Tự động kiểm tra master: đang phát triển, cần điều chỉnh lịch. | E10: BK Báo cho KH đang phát triển
D11: • Alert mail khi có lỗi: đang phát triển, cần điều chỉnh lịch.
D13: 2. Gift Card
D14: • Yêu cầu phải qua credit server của AFS → Ando-san đang xác nhận.
D15: • Estimate: chưa nộp vì thiếu spec (server ban ngày chưa rõ item gửi/đích đến, chưa có tài liệu; đang chờ AFS trả lời).
D16: • Communication method: chưa rõ, đã gửi mail cho AFS từ 16/9 → vẫn chờ phản hồi.
D17: • Phát triển màn hình terminal Gift Card: cần xác nhận với Aoyagi-san về việc có thể tiến hành hay không (màn hình gồm chức năng đăng ký số thẻ & nhập số tiền sử dụng).
A19: 45933 | B19: Hop định kỳ Ishida | D19: ■Nội dung chính
D20: - Cuộc họp hôm nay xem lại tình hình vận hành 1 tháng của cửa hàng 253,
D21: xác định vấn đề và bàn kế hoạch triển khai tiếp theo.
D22: - Có 1 vài sự cố như nhãn hỏng, thiếu nhãn,..
D23: - Yêu cầu hiển thị mã JAN trên ESL để quét đặt hàng. Sau khi hoàn tất giải pháp ở cửa hàng này
D24: sẽ nhân rộng sang cửa hàng khác.
D25: - Ngoài ra bác Sasaki có trình bày 1 vài chức năng dự kiến mong muốn phát triển trong tương lai.
D26: 👉️Em có tổng hợp ở file bên dưới:
D27: https://svn.luvina.net/svn/prjs_pos_system/40_management/44_meeting/Biên bản họp KH/MM_20251003.xlsx
D29: ■Action: ※ Phía Luvina chưa nhận được thông báo chính thức phần việc cần làm
D30: - Murai (Ishida): Thăm cửa hàng, kiểm tra ESL & vấn đề phát sinh.
D31: - Team Hệ thống & Ishida: Thay mã OCR → JAN trên ESL.
D32: - Aoyagi: Xác nhận phê duyệt từ bộ phận hàng hóa; thiết lập họp định kỳ hàng tháng. (1 lần/ tháng)
... D35: - Team Hệ thống: Đồng bộ hiển thị mã sản phẩm với nhãn tại trung tâm.
A37: 45937 | B37: Họp hàng tuần thứ 3,5 | D37: ✅ Nhãn kệ điện tử (ESL)
D38: - Tài liệu yêu cầu/thiết kế: Đang cập nhật, dự kiến hoàn tất lại vào 07/10 (đã qua 2 lần sửa). -> Mr.K gửi cho Mr.Sasaki confirm
D39: - Lỗi gửi file P001 (200MB): Gửi thất bại → cần xác nhận lại với anh Tanaka xem có ảnh hưởng hệ thống chính không.
D40: - Lỗi hiển thị tên sản phẩm: Nghi ngờ do trường Kana → chờ xác nhận từ BiProj Tanaka, có thể cần sửa logic chương trình.
D41: - Mã sản phẩm: Đã thêm JAN code. Cần bổ sung mã định danh sản phẩm và chuyển sang mã 8 ký tự → chờ báo giá từ team Ishida.
D42: - Tự động xác nhận master + gửi mail lỗi: Đang phát triển, cần cập nhật lại timeline.
D43: - List bug:
D44: + 1&2: gửi lại scenario cho Mr.Sasaki để xác nhận
D45: + 3: Mr.Sasaki cần confirm lại với Mr.Ando
D47: 🎁 Gift Card
...

Sheet Memo
A1: Date | B1: Contents
A2: 45931

Sheet Sheet1
A1: Ngày 2/10
