Workbook

Sheet 表紙
A1: システム名 | K1: システム種別 | W1: 基本設計書 | AP1: 作成者 | AT1: 作成日 | AY1: 更新者 | BC1: 更新日 | BH1: 版数
A2: ignica POS | K2: POSサーバー | AP2: =改訂履歴!$H$11 -> DuNT | AT2: =改訂履歴!$B$11 -> 45391 | AY2: =LOOKUP(2,1/(改訂履歴!H11:H29992<>""),改訂履歴!H11:H29992) -> AnhTTP | BC2: =LOOKUP(2,1/(改訂履歴!B11:B29992<>""),改訂履歴!B11:B29992) -> 45637 | BH2: =LOOKUP(2,1/(改訂履歴!O11:O29992<>""),改訂履歴!O11:O29992) -> 0.74
A4: 機能カテゴリ | H4: 00_共通 | U4: 項目 | Z4: 概要設計 | AP4: {=RIGHT(CELL("filename",$A$1),LEN(CELL("filename",$A$1))-FIND("]",CELL("filename",$A$1)))} -> 表紙
L16: 現金専用セルフPOS_基本設計書
L24: =K2&"/"&H4&"/"&Z4 -> POSサーバー/00_共通/概要設計
Q44: 承認日 | AA44: 承認者 | AQ44: 版数

Sheet 改訂履歴
A1: システム名 | K1: システム種別 | W1: =IF(表紙!W1="","",表紙!W1) -> 基本設計書 | AP1: 作成者 | AT1: 作成日 | AY1: 更新者 | BC1: 更新日 | BH1: 版数
A2: =IF(表紙!A2="","",表紙!A2) -> ignica POS | K2: =IF(表紙!K2="","",表紙!K2) -> POSサーバー | AP2: =IF(表紙!AP2="","",表紙!AP2) -> DuNT | AT2: =IF(表紙!AT2="","",表紙!AT2) -> 45391 | AY2: =IF(表紙!AY2="","",表紙!AY2) -> AnhTTP | BC2: =IF(表紙!BC2="","",表紙!BC2) -> 45637 | BH2: =IF(表紙!BH2="","",表紙!BH2) -> 0.74
A4: 機能カテゴリ | H4: =IF(表紙!H4="","",表紙!H4) -> 00_共通 | U4: 項目 | Z4: =IF(表紙!Z4="","",表紙!Z4) -> 概要設計 | AP4: {=RIGHT(CELL("filename",$A$1),LEN(CELL("filename",$A$1))-FIND("]",CELL("filename",$A$1)))} -> 改訂履歴
B8: ■改訂履歴
B10: 更新日 | H10: 更新者 | O10: 版数 | S10: 更新内容 | AX10: 承認日 | BD10: 承認者
B11: 45391 | H11: DuNT | O11: 0.1 | S11: 作成
B13: 45415 | H13: TuyenNH | O13: 0.2 | S13: ページングエリアの新規追加
B15: 45434 | H15: LoiLV | O15: 0.21 | S15: ページング、フォントの更新
B17: 45490 | H17: TinNH | O17: 0.3 | S17: コメントによる更新
B19: 45504 | H19: TinNH | O19: 0.4 | S19: コメントによる更新
S20: ・JANコード入力共通更新、画面に従う一覧制限、【PLUコード切替】ボタン、数値項目のバリデーションチェック
S21: ・ボタン有効化情報を更新し、更新を確定し、出力可能とする。
B22: 45504 | H22: DuNT | O22: 0.5 | S22: 店舗共通を更新する。
S23: 日付と時刻の形式共通を追加する。
S24: 画面設計シートを削除する-> 画面設計書、共通機能設計書を作成する。
B25: 45523 | H25: DuNT | O25: 0.6 | S25: 以下の説明を更新する。テキストが長すぎる場合、「…」を表示するように説明を更新する
B27: 45523 | H27: DuNT | O27: 0.7 | S27: 機能概要：ページング共通説明
B29: 45590 | H29: DuNT | O29: 0.71 | S29: マウスを使用しない入力共通項目
B31: 45610 | H31: AnhTTP | O31: 0.72 | S31: マウスを使用しない入力共通項目
B33: 45618 | H33: TinNH | O33: 0.73 | S33: 店舗選択タブに関連する内容更新
B35: 45637 | H35: AnhTTP | O35: 0.74 | S35: 項目調整共通更新
S36: 数値表示共通更新

Sheet 指摘履歴資料補足1
A1: 店舗検索時には前回検索内容を表示する。全件表示で１店舗のみ選択した場合に指定した店舗表示
B3: 選択時【佐和店】
B19: 再選択時【佐和店】 | I19: NG

Sheet 業務フロー
A1: システム名 | K1: システム種別 | W1: =IF(表紙!W1="","",表紙!W1) -> 基本設計書 | AP1: 作成者 | AT1: 作成日 | AY1: 更新者 | BC1: 更新日 | BH1: 版数
A2: =IF(表紙!A2="","",表紙!A2) -> ignica POS | K2: =IF(表紙!K2="","",表紙!K2) -> POSサーバー | AP2: =IF(表紙!AP2="","",表紙!AP2) -> DuNT | AT2: =IF(表紙!AT2="","",表紙!AT2) -> 45391 | AY2: =IF(表紙!AY2="","",表紙!AY2) -> AnhTTP | BC2: =IF(表紙!BC2="","",表紙!BC2) -> 45637 | BH2: =IF(表紙!BH2="","",表紙!BH2) -> 0.74
A4: 機能カテゴリ | H4: =IF(表紙!H4="","",表紙!H4) -> 00_共通 | U4: 項目 | Z4: =IF(表紙!Z4="","",表紙!Z4) -> 概要設計 | AP4: {=RIGHT(CELL("filename",$A$1),LEN(CELL("filename",$A$1))-FIND("]",CELL("filename",$A$1)))} -> 業務フロー
B7: ●1_自動釣銭機
B22: ●1_レジ周辺機器
B42: ●外部連携

Sheet 機能概要
A1: システム名 | K1: システム種別 | W1: =IF(表紙!W1="","",表紙!W1) -> 基本設計書 | AP1: 作成者 | AT1: 作成日 | AY1: 更新者 | BC1: 更新日 | BH1: 版数
A2: =IF(表紙!A2="","",表紙!A2) -> ignica POS | K2: =IF(表紙!K2="","",表紙!K2) -> POSサーバー | AP2: =IF(表紙!AP2="","",表紙!AP2) -> DuNT | AT2: =IF(表紙!AT2="","",表紙!AT2) -> 45391 | AY2: =IF(表紙!AY2="","",表紙!AY2) -> AnhTTP | BC2: =IF(表紙!BC2="","",表紙!BC2) -> 45637 | BH2: =IF(表紙!BH2="","",表紙!BH2) -> 0.74
A4: 機能カテゴリ | H4: =IF(表紙!H4="","",表紙!H4) -> 00_共通 | U4: 項目 | Z4: =IF(表紙!Z4="","",表紙!Z4) -> 概要設計 | AP4: {=RIGHT(CELL("filename",$A$1),LEN(CELL("filename",$A$1))-FIND("]",CELL("filename",$A$1)))} -> 機能概要
B7: ●共通機能
BM8: =IF(BM7=50,1,BM7+1) -> 1
B9: CM0001_共通ヘッダー | BM9: =IF(BM8=50,1,BM8+1) -> 2
BM10: =IF(BM9=50,1,BM9+1) -> 3
BM11: =IF(BM10=50,1,BM10+1) -> 4
BM12: =IF(BM11=50,1,BM11+1) -> 5
BM13: =IF(BM12=50,1,BM12+1) -> 6
BM14: =IF(BM13=50,1,BM13+1) -> 7
BM15: =IF(BM14=50,1,BM14+1) -> 8
BM16: =IF(BM15=50,1,BM15+1) -> 9
BM17: =IF(BM16=50,1,BM16+1) -> 10
BM18: =IF(BM17=50,1,BM17+1) -> 11
BM19: =IF(BM18=50,1,BM18+1) -> 12
BM20: =IF(BM19=50,1,BM19+1) -> 13
BM21: =IF(BM20=50,1,BM20+1) -> 14
... BM52: =IF(BM51=50,1,BM51+1) -> 45
B53: CM0002_店舗選択共通 | BM53: =IF(BM52=50,1,BM52+1) -> 46
BM54: =IF(BM53=50,1,BM53+1) -> 47
BM55: =IF(BM54=50,1,BM54+1) -> 48
BM56: =IF(BM55=50,1,BM55+1) -> 49
BM57: =IF(BM56=50,1,BM56+1) -> 50
BM58: =IF(BM57=50,1,BM57+1) -> 1
BM59: =IF(BM58=50,1,BM58+1) -> 2
BM60: =IF(BM59=50,1,BM59+1) -> 3
BM61: =IF(BM60=50,1,BM60+1) -> 4
BM62: =IF(BM61=50,1,BM61+1) -> 5
BM63: =IF(BM62=50,1,BM62+1) -> 6
BM64: =IF(BM63=50,1,BM63+1) -> 7
BM65: =IF(BM64=50,1,BM64+1) -> 8
... BM104: =IF(BM103=50,1,BM103+1) -> 47
B105: 店舗一覧表示フロー分類表 | BM105: =IF(BM104=50,1,BM104+1) -> 48
BM106: =IF(BM105=50,1,BM105+1) -> 49
F107: 1つの店舗選択可能 | AM107: 複数の店舗選択可能 | BM107: =IF(BM106=50,1,BM106+1) -> 50
B108: 01.商品管理 | AD108: 15. タッチメニュー | BM108: =IF(BM107=50,1,BM107+1) -> 1
B109: 02_緊急売価変更 | AD109: 28 レシートクーポン設定 | BM109: =IF(BM108=50,1,BM108+1) -> 2
B110: 03_店舗特売入力 | AD110: 31_レジ別速報/日報 | BM110: =IF(BM109=50,1,BM109+1) -> 3
B111: 04_商品採用店舗確認 | AD111: 40_従業員設定 | BM111: =IF(BM110=50,1,BM110+1) -> 4
...

Sheet 画面共通
A1: システム名 | K1: システム種別 | W1: =IF(表紙!W1="","",表紙!W1) -> 基本設計書 | AP1: 作成者 | AT1: 作成日 | AY1: 更新者 | BC1: 更新日 | BH1: 版数
A2: =IF(表紙!A2="","",表紙!A2) -> ignica POS | K2: =IF(表紙!K2="","",表紙!K2) -> POSサーバー | AP2: =IF(表紙!AP2="","",表紙!AP2) -> DuNT | AT2: =IF(表紙!AT2="","",表紙!AT2) -> 45391 | AY2: =IF(表紙!AY2="","",表紙!AY2) -> AnhTTP | BC2: =IF(表紙!BC2="","",表紙!BC2) -> 45637 | BH2: =IF(表紙!BH2="","",表紙!BH2) -> 0.74
A4: 機能カテゴリ | H4: =IF(表紙!H4="","",表紙!H4) -> 00_共通 | U4: 項目 | Z4: =IF(表紙!Z4="","",表紙!Z4) -> 概要設計 | AP4: {=RIGHT(CELL("filename",$A$1),LEN(CELL("filename",$A$1))-FIND("]",CELL("filename",$A$1)))} -> 画面共通
B7: 1. フォント
C8: ・フォントサイズ：Noto Sans CJK JP
C9: ・サイズ：
D10: 標準フォントサイズ：24 | L10: 画面サイズが1280までの場合のレスポンシブフォントサイズ：16
D11: ヘッダーフォントサイズ：36
B12: 2. 共通アクション：
C13: ・ヘッダーのxボタンをクリックするか、xボタンをタッチしてブラウザのタブを閉じるか、xボタンをタッチしてブラウザを閉じるか、右クリックでブラウザを閉じると、
C14: => 画面を終了すると、変更されたデータが保存していない場合は、閉じる確認モーダルを表示する。
C15: ・保存確認モーダル、一時削除確認モーダル、保存成功モーダルを削除する。
C16: ・「クリア」ボタンをタッチすると、各画面の通知モーダルを削除する。
C17: ・削除ボタンをタッチしてDB(サーバー)の削除を行う場合、削除確認モーダルが必要となる。「はい」ボタンをタッチすると、削除API呼出を行う。
C18: ・エリア部分を削除し、店舗一覧選択のみを残す。
C19: ・デフォルトでは [確定]ボタンを無効にし、画面上でデータが変更された場合にのみ有効にする。
C20: ・PLU: 共通13桁。PLUに子JAN入力時は親JANを表示する 。
C21: ・商品コード、PLU入力がある場合、【PLUコード切替】ボタンを付ける。タッチすると、【商品コード切替】ボタンに切り替える。※初期値はPLU入力とする。
C22: ・数値項目は数値以外入力不可とし、入力時のチェックは行わない。
C23: ・S&G連携データを出力可能とする。
C24: ・システムの共通表示日付形式：yy/MM/dd。yyyyMMdd又はyyMMdd形式での入力可能とする。その後、yy/MM/dd形式に変換する。
... C30: ・一覧表示画面に対しては：
D31: +新規作成されたアイテム：全ての新規情報を赤色で表示する。
D32: +更新されたアイテム：編集された情報を以下の形式で表示する。
F33: 古い情報
F35: 新しい情報
D36: +削除されたアイテム：削除された行を赤い取り消し線で表示する。
C37: ・削除としてマークされたアイテムを削除すると、その削除マークを解除し、赤い取り消し線を削除し、アイテムの初期状態に復元する。
B39: ■項目調整共通
C40: ・項目タイトル、通常テキスト項目値、ドロップダウン項目など: 左揃え
C41: ・コード項目(純粋な数字形式、「0」追加なし)、金額、商品数、客数、割合など: 右揃え
C42: ・固定文字数の項目（入力が不足している場合に「0」を追加)：左揃え
C43: ・日付、月の項目: 左揃え
C44: ・ボタン内のテキスト: 中央揃え
C45: ・リストのヘッダー: 中央揃え
C46: ・状態・有効項目（テキスト形式）：中央揃え
B49: ■マスタ更新共通
C50: ・印刷時に営業日が変更された場合、営業日が変更された勧告モーダルを表示し、印刷すると変更された日付ではなく、古いデータを印刷する。
C51: ・検索時間が長すぎる場合、検索を続行するかの表示モーダルが必要である。
B53: ■マスタ更新共通
...

Sheet テンプレート
A1: システム名 | K1: システム種別 | W1: =IF(表紙!W1="","",表紙!W1) -> 基本設計書 | AP1: 作成者 | AT1: 作成日 | AY1: 更新者 | BC1: 更新日 | BH1: 版数
A2: =IF(表紙!A2="","",表紙!A2) -> ignica POS | K2: =IF(表紙!K2="","",表紙!K2) -> POSサーバー | AP2: =IF(表紙!AP2="","",表紙!AP2) -> DuNT | AT2: =IF(表紙!AT2="","",表紙!AT2) -> 45391 | AY2: =IF(表紙!AY2="","",表紙!AY2) -> AnhTTP | BC2: =IF(表紙!BC2="","",表紙!BC2) -> 45637 | BH2: =IF(表紙!BH2="","",表紙!BH2) -> 0.74
A4: 機能カテゴリ | H4: =IF(表紙!H4="","",表紙!H4) -> 00_共通 | U4: 項目 | Z4: =IF(表紙!Z4="","",表紙!Z4) -> 概要設計 | AP4: {=RIGHT(CELL("filename",$A$1),LEN(CELL("filename",$A$1))-FIND("]",CELL("filename",$A$1)))} -> テンプレート
