Workbook

Sheet 表紙
A1: システム名 | K1: システム種別 | W1: 基本設計書 | AP1: 作成者 | AT1: 作成日 | AY1: 更新者 | BC1: 更新日 | BH1: 版数
A2: POSサーバー | K2: POSサーバ | AP2: =改訂履歴!$H$11 -> SonMNT | AT2: =改訂履歴!$B$11 -> 45418 | AY2: =LOOKUP(2,1/(改訂履歴!H11:H30000<>""),改訂履歴!H11:H30000) -> TinNH | BC2: =LOOKUP(2,1/(改訂履歴!B11:B30000<>""),改訂履歴!B11:B30000) -> 45504 | BH2: =LOOKUP(2,1/(改訂履歴!O11:O30000<>""),改訂履歴!O11:O30000) -> 0.6
A4: 機能カテゴリ | H4: 10_プロモーションメンテ | U4: 項目 | Z4: 概要設計 | AP4: {=RIGHT(CELL("filename",$A$1),LEN(CELL("filename",$A$1))-FIND("]",CELL("filename",$A$1)))} -> 表紙
L16: POSサーバーの基本設計書
L24: =K2&"/"&H4&"/"&Z4 -> POSサーバ/10_プロモーションメンテ/概要設計
Q44: 承認日 | AA44: 承認者 | AQ44: 版数

Sheet 改訂履歴
A1: システム名 | K1: システム種別 | W1: =IF(表紙!W1="","",表紙!W1) -> 基本設計書 | AP1: 作成者 | AT1: 作成日 | AY1: 更新者 | BC1: 更新日 | BH1: 版数
A2: =IF(表紙!A2="","",表紙!A2) -> POSサーバー | K2: =IF(表紙!K2="","",表紙!K2) -> POSサーバ | AP2: =IF(表紙!AP2="","",表紙!AP2) -> SonMNT | AT2: =IF(表紙!AT2="","",表紙!AT2) -> 45418 | AY2: =IF(表紙!AY2="","",表紙!AY2) -> TinNH | BC2: =IF(表紙!BC2="","",表紙!BC2) -> 45504 | BH2: =IF(表紙!BH2="","",表紙!BH2) -> 0.6
A4: 機能カテゴリー | H4: =IF(表紙!H4="","",表紙!H4) -> 10_プロモーションメンテ | U4: 項目 | Z4: =IF(表紙!Z4="","",表紙!Z4) -> 概要設計 | AP4: {=RIGHT(CELL("filename",$A$1),LEN(CELL("filename",$A$1))-FIND("]",CELL("filename",$A$1)))} -> 改訂履歴
B8: ■改訂履歴
B10: 更新日 | H10: 更新者 | O10: 版数 | S10: 更新内容 | AX10: 承認日 | BD10: 承認者
B11: 45418 | H11: SonMNT | O11: 0.1 | S11: 新規作成
B13: 45429 | H13: SonMNT | O13: 0.2 | S13: 定例会議議事録による更新
B15: 45448 | H15: KSM | O15: 0.3 | S15: コメントによる更新
B17: 45453 | H17: SonMNT | O17: 0.4 | S17: コメントによる更新
B19: 45489 | H19: TuyenNH | O19: 0.5 | S19: 【次頁】、【前頁】、【先頭行】、【最終行】ボタンの追加
S20: 機能概要シート
B21: 45504 | H21: TinNH | O21: 0.6 | S21: 機能概要
S22: ・午後7時にバッチ実行について ・特売売価使用確認と日時変換を追加

Sheet 業務フロー
A1: システム名 | K1: システム種別 | W1: =IF(表紙!W1="","",表紙!W1) -> 基本設計書 | AP1: 作成者 | AT1: 作成日 | AY1: 更新者 | BC1: 更新日 | BH1: 版数
A2: =IF(表紙!A2="","",表紙!A2) -> POSサーバー | K2: =IF(表紙!K2="","",表紙!K2) -> POSサーバ | AP2: =IF(表紙!AP2="","",表紙!AP2) -> SonMNT | AT2: 45084 | AY2: =IF(表紙!AY2="","",表紙!AY2) -> TinNH | BC2: =IF(表紙!BC2="","",表紙!BC2) -> 45504 | BH2: =IF(表紙!BH2="","",表紙!BH2) -> 0.6
A4: 機能カテゴリー | H4: =IF(表紙!H4="","",表紙!H4) -> 10_プロモーションメンテ | U4: 項目 | Z4: =IF(表紙!Z4="","",表紙!Z4) -> 概要設計 | AP4: {=RIGHT(CELL("filename",$A$1),LEN(CELL("filename",$A$1))-FIND("]",CELL("filename",$A$1)))} -> 業務フロー
B7: ●1_自動釣銭機
B22: ●1_レジ周辺機器
B42: ●外部連携

Sheet 指摘履歴
A1: システム名 | K1: システム種別 | W1: 基本設計書 | AP1: 作成者 | AT1: 作成日 | AY1: 更新者 | BC1: 更新日 | BH1: 版数
A2: POSサーバー | K2: POSサーバ | AP2: カスミ | AT2: 45495 | AY2: 佐々木 | BC2: 45495
A4: 機能カテゴリー | H4: 10_プロモーションメンテ | U4: 項目 | Z4: 概要設計 | AP4: {=RIGHT(CELL("filename",$A$1),LEN(CELL("filename",$A$1))-FIND("]",CELL("filename",$A$1)))} -> 指摘履歴
B8: ■改訂履歴
B10: 更新日 | H10: 更新者 | O10: 版数 | S10: 更新内容 | AX10: 承認日 | BD10: 承認者
B11: 45495 | H11: カスミ 佐々木 | S11: 機能概要
S12: ・手動削除に加えて、終了日が現在日より7日以上前のプロモーションが毎日午後7時に実行されるバッチによって削除される。 ＝＞毎日午後7時（営業中）にバッチを起動する意図を教えて下さい。
B13: 45495 | H13: カスミ 佐々木 | S13: 機能概要
S14: ・現在のプロモーションが状態が有効になるミックスマッチ又は特売売価に使用されているかを確認する。 +使用されている場合、 プロモーションの開始日時 <= ミックスマッチの開始日時、終了日時 >= ミックスマッチの終了日時を確認する。 ＝＞特売設定とのチェックがされていません。
B15: 45495 | H15: カスミ 佐々木 | S15: 機能概要
S16: ・日付直入力「YYYYMMDD」入力を「YYYY/MM/DD」に編集する。
B17: 45495 | H17: カスミ 佐々木 | S17: 機能概要
S18: ・時間直入力「HHMM」入力を「HH:MM」に編集する。

Sheet 機能概要説明
A1: システム名 | K1: システム種別 | W1: =IF(表紙!W1="","",表紙!W1) -> 基本設計書 | AP1: 作成者 | AT1: 作成日 | AY1: 更新者 | BC1: 更新日 | BH1: 版数
A2: =IF(表紙!A2="","",表紙!A2) -> POSサーバー | K2: =IF(表紙!K2="","",表紙!K2) -> POSサーバ | AP2: =IF(表紙!AP2="","",表紙!AP2) -> SonMNT | AT2: =IF(表紙!AT2="","",表紙!AT2) -> 45418 | AY2: =IF(表紙!AY2="","",表紙!AY2) -> TinNH | BC2: =IF(表紙!BC2="","",表紙!BC2) -> 45504 | BH2: =IF(表紙!BH2="","",表紙!BH2) -> 0.6
A4: 機能カテゴリ | H4: =IF(表紙!H4="","",表紙!H4) -> 10_プロモーションメンテ | U4: 項目 | Z4: =IF(表紙!Z4="","",表紙!Z4) -> 概要設計 | AP4: {=RIGHT(CELL("filename",$A$1),LEN(CELL("filename",$A$1))-FIND("]",CELL("filename",$A$1)))} -> 機能概要説明
C7: プロモーションメンテには次のことが可能になる。 | BM7: =IF(BM6=50,1,BM6+1) -> 1
D8: ・プロモーション検索 | BM8: =IF(BM7=50,1,BM7+1) -> 2
D9: ・プロモーション情報表示 | BM9: =IF(BM8=50,1,BM8+1) -> 3
D10: ・プロモーション設定編集 | BM10: =IF(BM9=50,1,BM9+1) -> 4
D11: ・プロモーション新規作成 | BM11: =IF(BM10=50,1,BM10+1) -> 5
D12: ・プロモーション削除 | BM12: =IF(BM11=50,1,BM11+1) -> 6
D13: ・毎晩バッチ処理により、終了日が現在日より7日以上前のプロモーションコードを削除する。 | BM13: =IF(BM12=50,1,BM12+1) -> 7
BM14: =IF(BM13=50,1,BM13+1) -> 8
BM15: =IF(BM14=50,1,BM14+1) -> 9
BM16: =IF(BM15=50,1,BM15+1) -> 10
BM17: =IF(BM16=50,1,BM16+1) -> 11
BM18: =IF(BM17=50,1,BM17+1) -> 12
BM19: =IF(BM18=50,1,BM18+1) -> 13
BM20: =IF(BM19=50,1,BM19+1) -> 14
BM21: =IF(BM20=50,1,BM20+1) -> 15
BM22: =IF(BM21=50,1,BM21+1) -> 16
BM23: =IF(BM22=50,1,BM22+1) -> 17
BM24: =IF(BM23=50,1,BM23+1) -> 18
BM25: =IF(BM24=50,1,BM24+1) -> 19
... BM57: =IF(BM56=50,1,BM56+1) -> 1

Sheet 機能概要
A1: システム名 | K1: システム種別 | W1: =IF(表紙!W1="","",表紙!W1) -> 基本設計書 | AP1: 作成者 | AT1: 作成日 | AY1: 更新者 | BC1: 更新日 | BH1: 版数
A2: =IF(表紙!A2="","",表紙!A2) -> POSサーバー | K2: =IF(表紙!K2="","",表紙!K2) -> POSサーバ | AP2: =IF(表紙!AP2="","",表紙!AP2) -> SonMNT | AT2: =IF(表紙!AT2="","",表紙!AT2) -> 45418 | AY2: =IF(表紙!AY2="","",表紙!AY2) -> TinNH | BC2: =IF(表紙!BC2="","",表紙!BC2) -> 45504 | BH2: =IF(表紙!BH2="","",表紙!BH2) -> 0.6
A4: 機能カテゴリ | H4: =IF(表紙!H4="","",表紙!H4) -> 10_プロモーションメンテ | U4: 項目 | Z4: =IF(表紙!Z4="","",表紙!Z4) -> 概要設計 | AP4: {=RIGHT(CELL("filename",$A$1),LEN(CELL("filename",$A$1))-FIND("]",CELL("filename",$A$1)))} -> 機能概要
B7: 10_プロモーションメンテ
BM8: =IF(BM7=50,1,BM7+1) -> 1
BM9: =IF(BM8=50,1,BM8+1) -> 2
BM10: =IF(BM9=50,1,BM9+1) -> 3
BM11: =IF(BM10=50,1,BM10+1) -> 4
BM12: =IF(BM11=50,1,BM11+1) -> 5
BM13: =IF(BM12=50,1,BM12+1) -> 6
BM14: =IF(BM13=50,1,BM13+1) -> 7
BM15: =IF(BM14=50,1,BM14+1) -> 8 | EL15: イメージ新規追加
B16: FC1001_店舗選択機能 | BM16: =IF(BM15=50,1,BM15+1) -> 9 | CX16: イメージ新規追加
BM17: =IF(BM16=50,1,BM16+1) -> 10
BM18: =IF(BM17=50,1,BM17+1) -> 11
BM19: =IF(BM18=50,1,BM18+1) -> 12
BM20: =IF(BM19=50,1,BM19+1) -> 13
BM21: =IF(BM20=50,1,BM20+1) -> 14
BM22: =IF(BM21=50,1,BM21+1) -> 15
BM23: =IF(BM22=50,1,BM22+1) -> 16
BM24: =IF(BM23=50,1,BM23+1) -> 17
BM25: =IF(BM24=50,1,BM24+1) -> 18
BM26: =IF(BM25=50,1,BM25+1) -> 19
BM27: =IF(BM26=50,1,BM26+1) -> 20
BM28: =IF(BM27=50,1,BM27+1) -> 21
... BM36: =IF(BM35=50,1,BM35+1) -> 29
B37: FC1002_プロモーション検索と修正機能 | BM37: =IF(BM36=50,1,BM36+1) -> 30
BM38: =IF(BM37=50,1,BM37+1) -> 31
BM39: =IF(BM38=50,1,BM38+1) -> 32
BM40: =IF(BM39=50,1,BM39+1) -> 33
BM41: =IF(BM40=50,1,BM40+1) -> 34 | BO41: 【次頁】、【前頁】、【先頭行】、【最終行】の追加後のレイアウト
BM42: =IF(BM41=50,1,BM41+1) -> 35
BM43: =IF(BM42=50,1,BM42+1) -> 36
BM44: =IF(BM43=50,1,BM43+1) -> 37
BM45: =IF(BM44=50,1,BM44+1) -> 38
BM46: =IF(BM45=50,1,BM45+1) -> 39
BM47: =IF(BM46=50,1,BM46+1) -> 40
BM48: =IF(BM47=50,1,BM47+1) -> 41
BM49: =IF(BM48=50,1,BM48+1) -> 42
BM50: =IF(BM49=50,1,BM49+1) -> 43
...

Sheet 画面設計書
A1: システム名 | K1: システム種別 | W1: =IF(表紙!W1="","",表紙!W1) -> 基本設計書 | AP1: 作成者 | AT1: 作成日 | AY1: 更新者 | BC1: 更新日 | BH1: 版数
A2: =IF(表紙!A2="","",表紙!A2) -> POSサーバー | K2: =IF(表紙!K2="","",表紙!K2) -> POSサーバ | AP2: =IF(表紙!AP2="","",表紙!AP2) -> SonMNT | AT2: =IF(表紙!AT2="","",表紙!AT2) -> 45418 | AY2: =IF(表紙!AY2="","",表紙!AY2) -> TinNH | BC2: =IF(表紙!BC2="","",表紙!BC2) -> 45504 | BH2: =IF(表紙!BH2="","",表紙!BH2) -> 0.6
A4: 機能カテゴリ | H4: =IF(表紙!H4="","",表紙!H4) -> 10_プロモーションメンテ | U4: 項目 | Z4: =IF(表紙!Z4="","",表紙!Z4) -> 概要設計 | AP4: =MID(CELL("filename",A1),FIND("]",CELL("filename",A1))+1,255) -> 画面設計書
B7: ■ログイン画面のイメージ
B35: ■画面項目定義
B37: 画面項目ID | D37: 項目 | K37: タイプ | N37: I/O | O37: 多言語対象 | P37: 出力 | AR37: インプット | BC37: 備考
P38: マッピングデータ | X38: 初期値 | AA38: 表示コントロール | AI38: Control enable | AR38: 必須 | AS38: 数字 | AT38: 文字 | AU38: マッピングデータ
P39: API名 | T39: 項目 | AU39: API名 | AY39: 項目
B40: 1 | K40: テキスト | N40: － | O40: ● | P40: － | T40: － | X40: Android POS Control | AA40: ー | AI40: － | AR40: － | AS40: ー | AT40: ー | AU40: － | AY40: ー
B41: 2 | K41: テキスト | N41: O | O41: ● | P41: － | T41: － | X41: User ID | AA41: ー | AI41: ー | AR41: － | AS41: ー | AT41: ー | AU41: － | AY41: ー
B42: 3 | K42: テキスト | N42: I | O42: － | P42: － | X42: － | AA42: ー | AI42: ー | AR42: － | AS42: ー | AT42: ー | AU42: － | AY42: ー
B43: 4 | K43: テキスト | N43: O | O43: ● | P43: － | T43: － | X43: Password | AA43: ー | AI43: ー | AR43: － | AS43: ー | AT43: ー | AU43: － | AY43: ー
B44: 5 | K44: EditText | N44: I | O44: － | P44: － | T44: － | X44: － | AA44: ー | AI44: ー | AR44: － | AS44: ー | AT44: ー | AU44: － | AY44: ー
B45: 6 | K45: ボタン | N45: I | O45: ● | P45: － | T45: － | X45: Login | AA45: ー | AI45: 有効 | AR45: － | AS45: ー | AT45: ー | AU45: － | AY45: ー | BC45: Login-01/EmployeeMaster

Sheet テンプレート
A1: システム名 | K1: システム種別 | W1: =IF(表紙!W1="","",表紙!W1) -> 基本設計書 | AP1: 作成者 | AT1: 作成日 | AY1: 更新者 | BC1: 更新日 | BH1: 版数
A2: =IF(表紙!A2="","",表紙!A2) -> POSサーバー | K2: =IF(表紙!K2="","",表紙!K2) -> POSサーバ | AP2: =IF(表紙!AP2="","",表紙!AP2) -> SonMNT | AT2: =IF(表紙!AT2="","",表紙!AT2) -> 45418 | AY2: =IF(表紙!AY2="","",表紙!AY2) -> TinNH | BC2: =IF(表紙!BC2="","",表紙!BC2) -> 45504 | BH2: =IF(表紙!BH2="","",表紙!BH2) -> 0.6
A4: 機能カテゴリ | H4: =IF(表紙!H4="","",表紙!H4) -> 10_プロモーションメンテ | U4: 項目 | Z4: =IF(表紙!Z4="","",表紙!Z4) -> 概要設計 | AP4: =MID(CELL("filename",A1),FIND("]",CELL("filename",A1))+1,255) -> テンプレート
AX12: `
