Workbook

Sheet 表紙
A1: システム名 | K1: システム種別 | W1: 基本設計書 | AP1: 作成者 | AT1: 作成日 | AY1: 更新者 | BC1: 更新日 | BH1: 版数
A2: POSサーバー | K2: POSサーバー | AP2: =改訂履歴!$H$11 -> TuyenNH | AT2: =改訂履歴!$B$11 -> 45427 | AY2: =LOOKUP(2,1/(改訂履歴!H11:H30000<>""),改訂履歴!H11:H30000) -> TuyenNH | BC2: =LOOKUP(2,1/(改訂履歴!B11:B30000<>""),改訂履歴!B11:B30000) -> 45523 | BH2: =LOOKUP(2,1/(改訂履歴!O11:O30000<>""),改訂履歴!O11:O30000) -> 0.14
A4: 機能カテゴリ | H4: 26 取扱設定マスタ設定(Welcia) | U4: 項目 | Z4: 概要設計書 | AP4: {=RIGHT(CELL("filename",$A$1),LEN(CELL("filename",$A$1))-FIND("]",CELL("filename",$A$1)))} -> 表紙
L16: POSサーバーの基本設計書
L24: =K2&"/"&H4&"/"&Z4 -> POSサーバー/26 取扱設定マスタ設定(Welcia)/概要設計書
Q44: 承認日 | AA44: 承認者 | AQ44: 版数

Sheet 改訂履歴
A1: システム名 | K1: システム種別 | W1: =IF(表紙!W1="","",表紙!W1) -> 基本設計書 | AP1: 作成者 | AT1: 作成日 | AY1: 更新者 | BC1: 更新日 | BH1: 版数
A2: =IF(表紙!A2="","",表紙!A2) -> POSサーバー | K2: =IF(表紙!K2="","",表紙!K2) -> POSサーバー | AP2: =IF(表紙!AP2="","",表紙!AP2) -> TuyenNH | AT2: =IF(表紙!AT2="","",表紙!AT2) -> 45427 | AY2: =IF(表紙!AY2="","",表紙!AY2) -> TuyenNH | BC2: =IF(表紙!BC2="","",表紙!BC2) -> 45523 | BH2: =IF(表紙!BH2="","",表紙!BH2) -> 0.14
A4: 機能カテゴリ | H4: =IF(表紙!H4="","",表紙!H4) -> 26 取扱設定マスタ設定(Welcia) | U4: 項目 | Z4: =IF(表紙!Z4="","",表紙!Z4) -> 概要設計書 | AP4: {=RIGHT(CELL("filename",$A$1),LEN(CELL("filename",$A$1))-FIND("]",CELL("filename",$A$1)))} -> 改訂履歴
B8: ■改訂履歴
B10: 更新日 | H10: 更新者 | O10: 版数 | S10: 更新内容 | AX10: 承認日 | BD10: 承認者
B11: 45427 | H11: TuyenNH | O11: 0.1 | S11: 新規作成
B13: 45436 | H13: TuyenNH | O13: 0.11 | S13: 2024年5月23日のコメントによる更新
B15: 45449 | H15: TuyenNH | O15: 0.12 | S15: 2024年06月04日のフロー25のコメントによる更新
B17: 45453 | H17: TuyenNH | O17: 0.13 | S17: 2024年06月04日のフロー25のコメントによる更新
B19: 45523 | H19: TuyenNH | O19: 0.14 | S19: シート：機能概要、取扱有無と下位階層も同設定の詳細
S20: 1. 取扱有無の表示を以下のように更新する： 有:●、無: 〇 2. MD2501_商品部門編集モダールを削除する。 3. 小分類レコード：「下位階層も同設定」に設定ボタンも表示する。

Sheet 業務フロー凡例
A1: システム名 | K1: システム種別 | W1: =IF(表紙!W1="","",表紙!W1) -> 基本設計書 | AP1: 作成者 | AT1: 作成日 | AY1: 更新者 | BC1: 更新日 | BH1: 版数
A2: =IF(表紙!A2="","",表紙!A2) -> POSサーバー | K2: =IF(表紙!K2="","",表紙!K2) -> POSサーバー | AP2: =IF(表紙!AP2="","",表紙!AP2) -> TuyenNH | AT2: 45084 | AY2: =IF(表紙!AY2="","",表紙!AY2) -> TuyenNH | BC2: =IF(表紙!BC2="","",表紙!BC2) -> 45523 | BH2: =IF(表紙!BH2="","",表紙!BH2) -> 0.14
A4: 機能カテゴリ | H4: =IF(表紙!H4="","",表紙!H4) -> 26 取扱設定マスタ設定(Welcia) | U4: 項目 | Z4: =IF(表紙!Z4="","",表紙!Z4) -> 概要設計書 | AP4: {=RIGHT(CELL("filename",$A$1),LEN(CELL("filename",$A$1))-FIND("]",CELL("filename",$A$1)))} -> 業務フロー凡例
B7: ●1_レジ内
B22: ●1_レジ周辺機器
B42: ●外部連携

Sheet 機能概要説明
A1: システム名 | K1: システム種別 | W1: =IF(表紙!W1="","",表紙!W1) -> 基本設計書 | AP1: 作成者 | AT1: 作成日 | AY1: 更新者 | BC1: 更新日 | BH1: 版数
A2: =IF(表紙!A2="","",表紙!A2) -> POSサーバー | K2: =IF(表紙!K2="","",表紙!K2) -> POSサーバー | AP2: =IF(表紙!AP2="","",表紙!AP2) -> TuyenNH | AT2: =IF(表紙!AT2="","",表紙!AT2) -> 45427 | AY2: =IF(表紙!AY2="","",表紙!AY2) -> TuyenNH | BC2: =IF(表紙!BC2="","",表紙!BC2) -> 45523 | BH2: =IF(表紙!BH2="","",表紙!BH2) -> 0.14
A4: 機能カテゴリ | H4: =IF(表紙!H4="","",表紙!H4) -> 26 取扱設定マスタ設定(Welcia) | U4: 項目 | Z4: =IF(表紙!Z4="","",表紙!Z4) -> 概要設計書 | AP4: {=RIGHT(CELL("filename",$A$1),LEN(CELL("filename",$A$1))-FIND("]",CELL("filename",$A$1)))} -> 機能概要説明
C7: 取扱設定マスタ設定(Welcia)では次のことが可能になる。 | BM7: =IF(BM6=50,1,BM6+1) -> 1
D8: ・各レベルに分類された分類一覧を閲覧する。 | BM8: =IF(BM7=50,1,BM7+1) -> 2
D9: ・以下のように分類の取扱有無を設定する。 有、無 | BM9: =IF(BM8=50,1,BM8+1) -> 3
D10: ・以下のように分類の医薬品有無を設定する。 有、無
D11: ・この設定は分類に関連する画面、機能に適用される。 | BM11: =IF(BM9=50,1,BM9+1) -> 4
D12: ・Welcia連携店舗のみが対象となる。 | BM12: =IF(BM11=50,1,BM11+1) -> 5
BM13: =IF(BM12=50,1,BM12+1) -> 6
BM14: =IF(BM13=50,1,BM13+1) -> 7
BM15: =IF(BM14=50,1,BM14+1) -> 8
BM16: =IF(BM15=50,1,BM15+1) -> 9
BM17: =IF(BM16=50,1,BM16+1) -> 10
BM18: =IF(BM17=50,1,BM17+1) -> 11
BM19: =IF(BM18=50,1,BM18+1) -> 12
BM20: =IF(BM19=50,1,BM19+1) -> 13
BM21: =IF(BM20=50,1,BM20+1) -> 14
BM22: =IF(BM21=50,1,BM21+1) -> 15
BM23: =IF(BM22=50,1,BM22+1) -> 16
BM24: =IF(BM23=50,1,BM23+1) -> 17
... BM58: =IF(BM57=50,1,BM57+1) -> 1

Sheet 機能概要
A1: システム名 | K1: システム種別 | W1: =IF(表紙!W1="","",表紙!W1) -> 基本設計書 | AP1: 作成者 | AT1: 作成日 | AY1: 更新者 | BC1: 更新日 | BH1: 版数
A2: =IF(表紙!A2="","",表紙!A2) -> POSサーバー | K2: =IF(表紙!K2="","",表紙!K2) -> POSサーバー | AP2: =IF(表紙!AP2="","",表紙!AP2) -> TuyenNH | AT2: =IF(表紙!AT2="","",表紙!AT2) -> 45427 | AY2: =IF(表紙!AY2="","",表紙!AY2) -> TuyenNH | BC2: =IF(表紙!BC2="","",表紙!BC2) -> 45523 | BH2: =IF(表紙!BH2="","",表紙!BH2) -> 0.14
A4: 機能カテゴリ | H4: =IF(表紙!H4="","",表紙!H4) -> 26 取扱設定マスタ設定(Welcia) | U4: 項目 | Z4: =IF(表紙!Z4="","",表紙!Z4) -> 概要設計書 | AP4: {=RIGHT(CELL("filename",$A$1),LEN(CELL("filename",$A$1))-FIND("]",CELL("filename",$A$1)))} -> 機能概要
B7: 12_単品速報/日報
BM8: =IF(BM7=50,1,BM7+1) -> 1
BM9: =IF(BM8=50,1,BM8+1) -> 2
BM10: =IF(BM9=50,1,BM9+1) -> 3
BM11: =IF(BM10=50,1,BM10+1) -> 4
BM12: =IF(BM11=50,1,BM11+1) -> 5
BM13: =IF(BM12=50,1,BM12+1) -> 6
BM14: =IF(BM13=50,1,BM13+1) -> 7
BM15: =IF(BM14=50,1,BM14+1) -> 8
BM16: =IF(BM15=50,1,BM15+1) -> 9
BM17: =IF(BM16=50,1,BM16+1) -> 10
BM18: =IF(BM17=50,1,BM17+1) -> 11
BM19: =IF(BM18=50,1,BM18+1) -> 12
... BM60: =IF(BM59=50,1,BM59+1) -> 3
BM61: =IF(BM60=50,1,BM60+1) -> 4 | BO61: 編集後のレイアウト
BM62: =IF(BM61=50,1,BM61+1) -> 5
BM63: =IF(BM62=50,1,BM62+1) -> 6
BM64: =IF(BM63=50,1,BM63+1) -> 7
BM65: =IF(BM64=50,1,BM64+1) -> 8
BM66: =IF(BM65=50,1,BM65+1) -> 9
BM67: =IF(BM66=50,1,BM66+1) -> 10
BM68: =IF(BM67=50,1,BM67+1) -> 11
BM69: =IF(BM68=50,1,BM68+1) -> 12
BM70: =IF(BM69=50,1,BM69+1) -> 13
BM71: =IF(BM70=50,1,BM70+1) -> 14
BM72: =IF(BM71=50,1,BM71+1) -> 15
BM73: =IF(BM72=50,1,BM72+1) -> 16
BM74: =IF(BM73=50,1,BM73+1) -> 17
BM75: =IF(BM74=50,1,BM74+1) -> 18 | BO75: 古いレイアウト
BM76: =IF(BM75=50,1,BM75+1) -> 19
BM77: =IF(BM76=50,1,BM76+1) -> 20
BM78: =IF(BM77=50,1,BM77+1) -> 21
BM79: =IF(BM78=50,1,BM78+1) -> 22
BM80: =IF(BM79=50,1,BM79+1) -> 23
BM81: =IF(BM80=50,1,BM80+1) -> 24
BM82: =IF(BM81=50,1,BM81+1) -> 25
BM83: =IF(BM82=50,1,BM82+1) -> 26
...

Sheet 画面設計書
A1: システム名 | K1: システム種別 | W1: =IF(表紙!W1="","",表紙!W1) -> 基本設計書 | AP1: 作成者 | AT1: 作成日 | AY1: 更新者 | BC1: 更新日 | BH1: 版数
A2: =IF(表紙!A2="","",表紙!A2) -> POSサーバー | K2: =IF(表紙!K2="","",表紙!K2) -> POSサーバー | AP2: =IF(表紙!AP2="","",表紙!AP2) -> TuyenNH | AT2: =IF(表紙!AT2="","",表紙!AT2) -> 45427 | AY2: =IF(表紙!AY2="","",表紙!AY2) -> TuyenNH | BC2: =IF(表紙!BC2="","",表紙!BC2) -> 45523 | BH2: =IF(表紙!BH2="","",表紙!BH2) -> 0.14
A4: 機能カテゴリ | H4: =IF(表紙!H4="","",表紙!H4) -> 26 取扱設定マスタ設定(Welcia) | U4: 項目 | Z4: =IF(表紙!Z4="","",表紙!Z4) -> 概要設計書 | AP4: =MID(CELL("filename",A1),FIND("]",CELL("filename",A1))+1,255) -> 画面設計書
B7: ■ログイン画面のイメージ
B35: ■画面項目定義
B37: 画面項目ID | D37: 項目 | K37: タイプ | N37: I/O | O37: 多言語対象 | P37: アウトプット | AR37: インプット | BC37: 備考
P38: マッピングデータ | X38: 初期値 | AA38: 表示コントロール | AI38: Control enable | AR38: 必須 | AS38: 数字 | AT38: 文字 | AU38: マッピングデータ
P39: API名 | T39: 項目 | AU39: API名 | AY39: 項目
B40: 1 | K40: テキスト | N40: － | O40: ● | P40: － | T40: － | X40: Android POS Control | AA40: ー | AI40: － | AR40: － | AS40: ー | AT40: ー | AU40: － | AY40: ー
B41: 2 | K41: テキスト | N41: O | O41: ● | P41: － | T41: － | X41: User ID | AA41: ー | AI41: ー | AR41: － | AS41: ー | AT41: ー | AU41: － | AY41: ー
B42: 3 | K42: テキスト | N42: I | O42: － | P42: － | X42: － | AA42: ー | AI42: ー | AR42: － | AS42: ー | AT42: ー | AU42: － | AY42: ー
B43: 4 | K43: テキスト | N43: O | O43: ● | P43: － | T43: － | X43: Password | AA43: ー | AI43: ー | AR43: － | AS43: ー | AT43: ー | AU43: － | AY43: ー
B44: 5 | K44: EditText | N44: I | O44: － | P44: － | T44: － | X44: － | AA44: ー | AI44: ー | AR44: － | AS44: ー | AT44: ー | AU44: － | AY44: ー
B45: 6 | K45: ボタン | N45: I | O45: ● | P45: － | T45: － | X45: Login | AA45: ー | AI45: Enable | AR45: － | AS45: ー | AT45: ー | AU45: － | AY45: ー | BC45: Login-01/EmployeeMaster

Sheet 取扱有無と下位階層も同設定の詳細
A1: システム名 | K1: システム種別 | W1: =IF(表紙!W1="","",表紙!W1) -> 基本設計書 | AP1: 作成者 | AT1: 作成日 | AY1: 更新者 | BC1: 更新日 | BH1: 版数
A2: =IF(表紙!A2="","",表紙!A2) -> POSサーバー | K2: =IF(表紙!K2="","",表紙!K2) -> POSサーバー | AP2: =IF(表紙!AP2="","",表紙!AP2) -> TuyenNH | AT2: =IF(表紙!AT2="","",表紙!AT2) -> 45427 | AY2: =IF(表紙!AY2="","",表紙!AY2) -> TuyenNH | BC2: =IF(表紙!BC2="","",表紙!BC2) -> 45523 | BH2: =IF(表紙!BH2="","",表紙!BH2) -> 0.14
A4: 機能カテゴリ | H4: =IF(表紙!H4="","",表紙!H4) -> 26 取扱設定マスタ設定(Welcia) | U4: 項目 | Z4: =IF(表紙!Z4="","",表紙!Z4) -> 概要設計書 | AP4: =MID(CELL("filename",A1),FIND("]",CELL("filename",A1))+1,255) -> 取扱有無と下位階層も同設定の詳細
B7: 取扱有無と下位階層も同設定の詳細説明
C9: 取扱有無と下位階層も同設定のボタン状態を変更する。
D10: ・取扱有無は取扱設定マスタ編集モダールを使用して 各レコードの「下位階層も同設定」項目にある四角ボタンをタッチすることで変更可能変更可能。
D11: ・下位階層も同設定:
E12: +大分類、中分類、と小分類のレコードに白四角ボタン又は黒四角ボタンを表示する。
E13: +小分類のレコードに「-」を表示する。
D14: ・下位階層も同設定の黒四角の意味：
E15: +大分類のレコードで：
F16: 中分類と小分類のレコードの取扱有無が大分類に従う。
E17: +中分類のレコードで:
F18: 小分類のレコードの取扱有無が中分類に従う。
F19: 中分類の取扱有無が大分類に従う。
E20: +小分類のレコードで：
F21: 小分類のレコードの取扱有無が中分類に従う。
D22: ・下位階層も同設定の白四角の意味：
E23: +大分類のレコードで：
F24: 中分類と小分類のレコードの取扱有無が大分類に従わない。
E25: +中分類のレコードで:
F26: 小分類のレコードの取扱有無が中分類に従わない。
F27: 中分類の取扱有無が大分類に従わない。
E28: +小分類のレコードで：
F29: 小分類のレコードの取扱有無が中分類に従わない。
D30: 1. 大分類の取扱有無を設定する。
E31: ・設定した大分類の取扱有無を表示し、下位階層も同設定には白い四角ボタンを表示する。
E32: ・白い四角ボタンをタッチする。
F33: +上記の大分類に属している中分類と小分類の全てレコードの取扱有無は大分類の取扱有無に従う。
F34: +全て中分類のレコードの位階層も同設定には黒い四角ボタンを表示し、小分類レコードの位階層も同設定には「-」を表示する。
F36: 大分類 | J36: 中分類 | P36: 小分類 | T36: 取扱有無 | W36: 下位階層も同設定 | AE36: 大分類 | AI36: 中分類 | AO36: 小分類 | AS36: 取扱有無 | AV36: 下位階層も同設定
F37: Big-1 | J37: - | P37: - | AE37: Big-1 | AI37: - | AO37: - | AS37: 有
F38: Big-1 | J38: Medium-1 | P38: - | AE38: Big-1 | AI38: Medium-1 | AO38: -
F39: Big-1 | J39: Medium-1 | P39: Small-1 | AE39: Big-1 | AI39: Medium-1 | AO39: Small-1
F40: Big-1 | J40: Medium-1 | P40: Small-2 | AE40: Big-1 | AI40: Medium-1 | AO40: Small-2
F41: Big-1 | J41: Medium-1 | P41: Small-3 | AE41: Big-1 | AI41: Medium-1 | AO41: Small-3
F42: Big-1 | J42: Medium-2 | P42: - | AE42: Big-1 | AI42: Medium-2 | AO42: -
F43: Big-1 | J43: Medium-2 | P43: Small-4 | AE43: Big-1 | AI43: Medium-2 | AO43: Small-4
F44: Big-1 | J44: Medium-2 | P44: Small-5 | AE44: Big-1 | AI44: Medium-2 | AO44: Small-5
F45: Big-1 | J45: Medium-2 | P45: Small-6 | AE45: Big-1 | AI45: Medium-2 | AO45: Small-6
...

Sheet テンプレート
A1: システム名 | K1: システム種別 | W1: =IF(表紙!W1="","",表紙!W1) -> 基本設計書 | AP1: 作成者 | AT1: 作成日 | AY1: 更新者 | BC1: 更新日 | BH1: 版数
A2: =IF(表紙!A2="","",表紙!A2) -> POSサーバー | K2: =IF(表紙!K2="","",表紙!K2) -> POSサーバー | AP2: =IF(表紙!AP2="","",表紙!AP2) -> TuyenNH | AT2: =IF(表紙!AT2="","",表紙!AT2) -> 45427 | AY2: =IF(表紙!AY2="","",表紙!AY2) -> TuyenNH | BC2: =IF(表紙!BC2="","",表紙!BC2) -> 45523 | BH2: =IF(表紙!BH2="","",表紙!BH2) -> 0.14
A4: 機能カテゴリ | H4: =IF(表紙!H4="","",表紙!H4) -> 26 取扱設定マスタ設定(Welcia) | U4: 項目 | Z4: =IF(表紙!Z4="","",表紙!Z4) -> 概要設計書 | AP4: =MID(CELL("filename",A1),FIND("]",CELL("filename",A1))+1,255) -> テンプレート
AX12: `
