Workbook

Sheet 表紙
A1: システム名 | K1: システム種別 | W1: 基本設計書 | AP1: 作成者 | AT1: 作成日 | AY1: 更新者 | BC1: 更新日 | BH1: 版数
A2: POSサーバ | K2: POSサーバ | AP2: =改訂履歴!$H$11 -> Kiyohara | AT2: =改訂履歴!$B$11 -> 45336 | AY2: =LOOKUP(2,1/(改訂履歴!H11:H30000<>""),改訂履歴!H11:H30000) -> DuNT | BC2: =LOOKUP(2,1/(改訂履歴!B11:B30000<>""),改訂履歴!B11:B30000) -> 45517 | BH2: =LOOKUP(2,1/(改訂履歴!O11:O30000<>""),改訂履歴!O11:O30000) -> 0.26
A4: 機能カテゴリー | H4: 15_タッチメニュー設定 | U4: 項目 | Z4: 概要設計 | AP4: {=RIGHT(CELL("filename",$A$1),LEN(CELL("filename",$A$1))-FIND("]",CELL("filename",$A$1)))} -> 表紙
L16: POSサーバーの基本設計書
L24: =K2&"/"&H4&"/"&Z4 -> POSサーバ/15_タッチメニュー設定/概要設計
Q44: 承認日 | AA44: 承認者 | AQ44: 版数

Sheet 改訂履歴
A1: システム名 | K1: システム種別 | W1: =IF(表紙!W1="","",表紙!W1) -> 基本設計書 | AP1: 作成者 | AT1: 作成日 | AY1: 更新者 | BC1: 更新日 | BH1: 版数
A2: =IF(表紙!A2="","",表紙!A2) -> POSサーバ | K2: =IF(表紙!K2="","",表紙!K2) -> POSサーバ | AP2: =IF(表紙!AP2="","",表紙!AP2) -> Kiyohara | AT2: =IF(表紙!AT2="","",表紙!AT2) -> 45336 | AY2: =IF(表紙!AY2="","",表紙!AY2) -> DuNT | BC2: =IF(表紙!BC2="","",表紙!BC2) -> 45517 | BH2: =IF(表紙!BH2="","",表紙!BH2) -> 0.26
A4: 機能カテゴリー | H4: =IF(表紙!H4="","",表紙!H4) -> 15_タッチメニュー設定 | U4: 項目 | Z4: =IF(表紙!Z4="","",表紙!Z4) -> 概要設計 | AP4: {=RIGHT(CELL("filename",$A$1),LEN(CELL("filename",$A$1))-FIND("]",CELL("filename",$A$1)))} -> 改訂履歴
B8: ■改訂履歴
B10: 更新日 | H10: 更新者 | O10: 版数 | S10: 更新内容 | AX10: 承認日 | BD10: 承認者
B11: 45336 | H11: Kiyohara | O11: 0.1 | S11: 新規
B13: 45391 | H13: DuNT | O13: 0.2 | S13: 更新
B15: 45399 | H15: DuNT | O15: 0.21 | S15: 2024/04/17の定例会後の更新
B17: 45407 | H17: DuNT | O17: 0.22 | S17: 2024/04/24の定例会後の更新
S18: 機能概要説明シートの追加
B19: 45419 | H19: DuNT | O19: 0.23 | S19: 2024/05/02の定例会後の更新
B21: 45474 | H21: DuNT | O21: 0.24 | S21: 最大10つプリセットメニュー。位置を変更するためにドラッグ＆ドロップを許可する。
S22: チェックボックス：無効
B23: 45504 | H23: DuNT | O23: 0.25 | S23: 機能概要
S24: 店舗選択モーダルを削除し、画像を変更する。 【プリセット設定】画面で、 ・タブキーは8を10に作成できるようにする ・「レジ画面表示」と「客用画面表示」のチェックボックスを追加
B25: 45517 | H25: DuNT | O25: 0.26 | S25: SC1502：バリデーションチェックAPI
S26: SC1501：コピーAPI、バリデーションチェックAPI、プリセットレイアウトコード自動生成APIを追加する。

Sheet 業務フロー
A1: システム名 | K1: システム種別 | W1: =IF(表紙!W1="","",表紙!W1) -> 基本設計書 | AP1: 作成者 | AT1: 作成日 | AY1: 更新者 | BC1: 更新日 | BH1: 版数
A2: =IF(表紙!A2="","",表紙!A2) -> POSサーバ | K2: =IF(表紙!K2="","",表紙!K2) -> POSサーバ | AP2: =IF(表紙!AP2="","",表紙!AP2) -> Kiyohara | AT2: =IF(表紙!AT2="","",表紙!AT2) -> 45336 | AY2: =IF(表紙!AY2="","",表紙!AY2) -> DuNT | BC2: =IF(表紙!BC2="","",表紙!BC2) -> 45517 | BH2: =IF(表紙!BH2="","",表紙!BH2) -> 0.26
A4: 機能カテゴリー | H4: =IF(表紙!H4="","",表紙!H4) -> 15_タッチメニュー設定 | U4: 項目 | Z4: =IF(表紙!Z4="","",表紙!Z4) -> 概要設計 | AP4: {=RIGHT(CELL("filename",$A$1),LEN(CELL("filename",$A$1))-FIND("]",CELL("filename",$A$1)))} -> 業務フロー
B7: ●1_自動釣銭機
B22: ●1_レジ周辺機器
B42: ●外部連携

Sheet 機能概要説明
A1: システム名 | K1: システム種別 | W1: =IF(表紙!W1="","",表紙!W1) -> 基本設計書 | AP1: 作成者 | AT1: 作成日 | AY1: 更新者 | BC1: 更新日 | BH1: 版数
A2: =IF(表紙!A2="","",表紙!A2) -> POSサーバ | K2: =IF(表紙!K2="","",表紙!K2) -> POSサーバ | AP2: =IF(表紙!AP2="","",表紙!AP2) -> Kiyohara | AT2: =IF(表紙!AT2="","",表紙!AT2) -> 45336 | AY2: =IF(表紙!AY2="","",表紙!AY2) -> DuNT | BC2: =IF(表紙!BC2="","",表紙!BC2) -> 45517 | BH2: =IF(表紙!BH2="","",表紙!BH2) -> 0.26
A4: 機能カテゴリ | H4: =IF(表紙!H4="","",表紙!H4) -> 15_タッチメニュー設定 | U4: 項目 | Z4: =IF(表紙!Z4="","",表紙!Z4) -> 概要設計 | AP4: {=RIGHT(CELL("filename",$A$1),LEN(CELL("filename",$A$1))-FIND("]",CELL("filename",$A$1)))} -> 機能概要説明
B7: タッチメニュー設定機能により、次のことが可能になる。
C8: ・店舗のレイアウトプリセットを管理する。
D9: ‣ビジネスレイアウト一覧を見る。
D10: ‣1種類のビジネスレイアウトの詳細を見る。
D11: ‣ビジネスレイアウトを検索する。
C12: ・店舗のビジネスレイアウトを設定する。
D13: ‣新規作成
D14: ‣編集
D15: ‣削除
D16: ‣コピー
C17: ・1種類のビジネスレイアウトの詳細を設定する。
D18: ‣ ビジネスレイアウトのレイアウトプリセットの変更：名称、色など
D19: ‣ボタンレイアウトプリセットを変更する。
E20: ●色、イメージ、名称、サイズ、有効・無効など
E21: ●ボタンレイアウトプリセットの機能：商品、クーポン、割引、支払画面の順番・アクション・テキストボタンなど

Sheet 機能概要
A1: システム名 | K1: システム種別 | W1: =IF(表紙!W1="","",表紙!W1) -> 基本設計書 | AP1: 作成者 | AT1: 作成日 | AY1: 更新者 | BC1: 更新日 | BH1: 版数
A2: =IF(表紙!A2="","",表紙!A2) -> POSサーバ | K2: =IF(表紙!K2="","",表紙!K2) -> POSサーバ | AP2: =IF(表紙!AP2="","",表紙!AP2) -> Kiyohara | AT2: =IF(表紙!AT2="","",表紙!AT2) -> 45336 | AY2: =IF(表紙!AY2="","",表紙!AY2) -> DuNT | BC2: =IF(表紙!BC2="","",表紙!BC2) -> 45517 | BH2: =IF(表紙!BH2="","",表紙!BH2) -> 0.26
A4: 機能カテゴリ | H4: =IF(表紙!H4="","",表紙!H4) -> 15_タッチメニュー設定 | U4: 項目 | Z4: =IF(表紙!Z4="","",表紙!Z4) -> 概要設計 | AP4: {=RIGHT(CELL("filename",$A$1),LEN(CELL("filename",$A$1))-FIND("]",CELL("filename",$A$1)))} -> 機能概要
BM6: =IF(BM5=50,1,BM5+1) -> 1
B7: ●15_タッチメニュー設定 | BM7: =IF(BM6=50,1,BM6+1) -> 2
BM8: =IF(BM7=50,1,BM7+1) -> 3
BM9: =IF(BM8=50,1,BM8+1) -> 4
BM10: =IF(BM9=50,1,BM9+1) -> 5
BM11: =IF(BM10=50,1,BM10+1) -> 6
BM12: =IF(BM11=50,1,BM11+1) -> 7
BM13: =IF(BM12=50,1,BM12+1) -> 8
BM14: =IF(BM13=50,1,BM13+1) -> 9
BM15: =IF(BM14=50,1,BM14+1) -> 10
B16: FC1501_タッチメニュー設定機能グループ | BM16: =IF(BM15=50,1,BM15+1) -> 11
BM17: =IF(BM16=50,1,BM16+1) -> 12
BM18: =IF(BM17=50,1,BM17+1) -> 13
BM19: =IF(BM18=50,1,BM18+1) -> 14
BM20: =IF(BM19=50,1,BM19+1) -> 15
BM21: =IF(BM20=50,1,BM20+1) -> 16
BM22: =IF(BM21=50,1,BM21+1) -> 17
BM23: =IF(BM22=50,1,BM22+1) -> 18
BM24: =IF(BM23=50,1,BM23+1) -> 19
BM25: =IF(BM24=50,1,BM24+1) -> 20
BM26: =IF(BM25=50,1,BM25+1) -> 21
BM27: =IF(BM26=50,1,BM26+1) -> 22
BM28: =IF(BM27=50,1,BM27+1) -> 23
... BM70: =IF(BM69=50,1,BM69+1) -> 15
B71: FC1502_プリセットレイアウト編集機能グループ | BM71: =IF(BM70=50,1,BM70+1) -> 16
BM72: =IF(BM71=50,1,BM71+1) -> 17
BM73: =IF(BM72=50,1,BM72+1) -> 18
BM74: =IF(BM73=50,1,BM73+1) -> 19
BM75: =IF(BM74=50,1,BM74+1) -> 20
BM76: =IF(BM75=50,1,BM75+1) -> 21
BM77: =IF(BM76=50,1,BM76+1) -> 22
BM78: =IF(BM77=50,1,BM77+1) -> 23
BM79: =IF(BM78=50,1,BM78+1) -> 24
BM80: =IF(BM79=50,1,BM79+1) -> 25
BM81: =IF(BM80=50,1,BM80+1) -> 26
BM82: =IF(BM81=50,1,BM81+1) -> 27
BM83: =IF(BM82=50,1,BM82+1) -> 28
...

Sheet テンプレート
A1: システム名 | K1: システム種別 | W1: =IF(表紙!W1="","",表紙!W1) -> 基本設計書 | AP1: 作成者 | AT1: 作成日 | AY1: 更新者 | BC1: 更新日 | BH1: 版数
A2: =IF(表紙!A2="","",表紙!A2) -> POSサーバ | K2: =IF(表紙!K2="","",表紙!K2) -> POSサーバ | AP2: =IF(表紙!AP2="","",表紙!AP2) -> Kiyohara | AT2: =IF(表紙!AT2="","",表紙!AT2) -> 45336 | AY2: =IF(表紙!AY2="","",表紙!AY2) -> DuNT | BC2: =IF(表紙!BC2="","",表紙!BC2) -> 45517 | BH2: =IF(表紙!BH2="","",表紙!BH2) -> 0.26
A4: 機能カテゴリ | H4: =IF(表紙!H4="","",表紙!H4) -> 15_タッチメニュー設定 | U4: 項目 | Z4: =IF(表紙!Z4="","",表紙!Z4) -> 概要設計 | AP4: {=RIGHT(CELL("filename",$A$1),LEN(CELL("filename",$A$1))-FIND("]",CELL("filename",$A$1)))} -> テンプレート
