Workbook

Sheet 表紙
A1: システム名 | K1: システム種別 | W1: 基本設計書 | AP1: 作成者 | AT1: 作成日 | AY1: 更新者 | BC1: 更新日 | BH1: 版数
A2: POSサーバー | K2: POSサーバ | AP2: =改訂履歴!$H$11 -> LoiLV | AT2: =改訂履歴!$B$11 -> 45460 | AY2: =LOOKUP(2,1/(改訂履歴!H11:H30000<>""),改訂履歴!H11:H30000) -> AnhNM | BC2: =LOOKUP(2,1/(改訂履歴!B11:B30000<>""),改訂履歴!B11:B30000) -> 45583 | BH2: =LOOKUP(2,1/(改訂履歴!O11:O30000<>""),改訂履歴!O11:O30000) -> 0.4
A4: 機能カテゴリ | H4: 29_レジ別時間帯別点検 | U4: 項目 | Z4: 概要設計 | AP4: {=RIGHT(CELL("filename",$A$1),LEN(CELL("filename",$A$1))-FIND("]",CELL("filename",$A$1)))} -> 表紙
L16: POSサーバーの基本設計書
L24: =K2&"/"&H4&"/"&Z4 -> POSサーバ/29_レジ別時間帯別点検/概要設計
Q44: 承認日 | AA44: 承認者 | AQ44: 版数

Sheet 改訂履歴
A1: システム名 | K1: システム種別 | W1: =IF(表紙!W1="","",表紙!W1) -> 基本設計書 | AP1: 作成者 | AT1: 作成日 | AY1: 更新者 | BC1: 更新日 | BH1: 版数
A2: =IF(表紙!A2="","",表紙!A2) -> POSサーバー | K2: =IF(表紙!K2="","",表紙!K2) -> POSサーバ | AP2: =IF(表紙!AP2="","",表紙!AP2) -> LoiLV | AT2: =IF(表紙!AT2="","",表紙!AT2) -> 45460 | AY2: =IF(表紙!AY2="","",表紙!AY2) -> AnhNM | BC2: =IF(表紙!BC2="","",表紙!BC2) -> 45583 | BH2: =IF(表紙!BH2="","",表紙!BH2) -> 0.4
A4: 機能カテゴリー | H4: =IF(表紙!H4="","",表紙!H4) -> 29_レジ別時間帯別点検 | U4: 項目 | Z4: =IF(表紙!Z4="","",表紙!Z4) -> 概要設計 | AP4: {=RIGHT(CELL("filename",$A$1),LEN(CELL("filename",$A$1))-FIND("]",CELL("filename",$A$1)))} -> 改訂履歴
B8: ■改訂履歴
B10: 更新日 | H10: 更新者 | O10: 版数 | S10: 更新内容 | AX10: 承認日 | BD10: 承認者
B11: 45460 | H11: LoiLV | O11: 0.1 | S11: 新規
B13: 45531 | H13: DuNT | O13: 0.2 | S13: 機能概要
S14: 店舗選択モーダルを削除する。 2024年08月16日のご指摘により更新
B15: 45552 | H15: DuNT | O15: 0.3 | S15: 機能概要
S16: 検索時に結果を画面に表示するようにする 構成比を画面で表示するようにする
B17: 45573 | H17: AnhNM | O17: 0.4 | S17: 機能概要
S18: 客数構成比を画面で表示するようにする グラフの記載を削除
B19: 45583 | H19: AnhNM | O19: 0.4 | S19: 機能概要
S20: ・【クリップボード】シートを削除 ・営業日は開始日～終了日で検索可能 ・CSV出力機能を追加 ・レジ別時間帯別実績について

Sheet 指摘履歴
A1: システム名 | K1: システム種別 | W1: 基本設計書 | AP1: 作成者 | AT1: 作成日 | AY1: 更新者 | BC1: 更新日 | BH1: 版数
A2: POSサーバー | K2: POSサーバー | AP2: カスミ | AT2: 45520 | AY2: 佐々木 | BC2: 45520
A4: 機能カテゴリ | H4: 29_レジ別時間帯別点検 | U4: 項目 | Z4: 概要設計書 | AP4: 指摘履歴
B8: ■改訂履歴
B10: 更新日 | H10: 更新者 | O10: 版数 | S10: 更新内容 | AX10: 確認日 | BD10: 確認者
B11: 45520 | H11: カスミ 佐々木 | S11: 機能概要
S12: 検索時に結果を画面に表示する。QA73内容が反映されていない。
B13: 45520 | H13: カスミ 佐々木 | S13: 機能概要
S14: 時間帯内での【構成比】表示を行う。
B15: 45520 | H15: カスミ 佐々木 | S15: 機能概要 | AX15: 45537 | BD15: 佐々木
S16: 【日報】選択時は前日日付けをセットする。

Sheet 業務フロー
A1: システム名 | K1: システム種別 | W1: =IF(表紙!W1="","",表紙!W1) -> 基本設計書 | AP1: 作成者 | AT1: 作成日 | AY1: 更新者 | BC1: 更新日 | BH1: 版数
A2: =IF(表紙!A2="","",表紙!A2) -> POSサーバー | K2: =IF(表紙!K2="","",表紙!K2) -> POSサーバ | AP2: =IF(表紙!AP2="","",表紙!AP2) -> LoiLV | AT2: 45084 | AY2: =IF(表紙!AY2="","",表紙!AY2) -> AnhNM | BC2: =IF(表紙!BC2="","",表紙!BC2) -> 45583 | BH2: =IF(表紙!BH2="","",表紙!BH2) -> 0.4
A4: 機能カテゴリー | H4: =IF(表紙!H4="","",表紙!H4) -> 29_レジ別時間帯別点検 | U4: 項目 | Z4: =IF(表紙!Z4="","",表紙!Z4) -> 概要設計 | AP4: {=RIGHT(CELL("filename",$A$1),LEN(CELL("filename",$A$1))-FIND("]",CELL("filename",$A$1)))} -> 業務フロー
B7: ●1_自動釣銭機
B22: ●1_レジ周辺機器
B42: ●外部連携

Sheet 機能概要説明
A1: システム名 | K1: システム種別 | W1: =IF(表紙!W1="","",表紙!W1) -> 基本設計書 | AP1: 作成者 | AT1: 作成日 | AY1: 更新者 | BC1: 更新日 | BH1: 版数
A2: =IF(表紙!A2="","",表紙!A2) -> POSサーバー | K2: =IF(表紙!K2="","",表紙!K2) -> POSサーバ | AP2: =IF(表紙!AP2="","",表紙!AP2) -> LoiLV | AT2: =IF(表紙!AT2="","",表紙!AT2) -> 45460 | AY2: =IF(表紙!AY2="","",表紙!AY2) -> AnhNM | BC2: =IF(表紙!BC2="","",表紙!BC2) -> 45583 | BH2: =IF(表紙!BH2="","",表紙!BH2) -> 0.4
A4: 機能カテゴリ | H4: =IF(表紙!H4="","",表紙!H4) -> 29_レジ別時間帯別点検 | U4: 項目 | Z4: =IF(表紙!Z4="","",表紙!Z4) -> 概要設計 | AP4: {=RIGHT(CELL("filename",$A$1),LEN(CELL("filename",$A$1))-FIND("]",CELL("filename",$A$1)))} -> 機能概要説明
C7: レジ別時間帯別点検機能では次のことが可能になる。 | BM7: =IF(BM6=50,1,BM6+1) -> 1
D8: ・各時間帯に従って店舗の各レジの日報を印刷する。レポート情報には以下が含まれている。 | BM8: =IF(BM7=50,1,BM7+1) -> 2
E9: ‣営業日の各時間帯に従う各レジの客数、点数、金額 | BM9: =IF(BM8=50,1,BM8+1) -> 3
E10: ‣各レジの1営業日の総客数、総点数、総金額 | BM10: =IF(BM9=50,1,BM9+1) -> 4
BM11: =IF(BM10=50,1,BM10+1) -> 5
BM12: =IF(BM11=50,1,BM11+1) -> 6
BM13: =IF(BM12=50,1,BM12+1) -> 7
BM14: =IF(BM13=50,1,BM13+1) -> 8
BM15: =IF(BM14=50,1,BM14+1) -> 9
BM16: =IF(BM15=50,1,BM15+1) -> 10
BM17: =IF(BM16=50,1,BM16+1) -> 11
BM18: =IF(BM17=50,1,BM17+1) -> 12
BM19: =IF(BM18=50,1,BM18+1) -> 13
BM20: =IF(BM19=50,1,BM19+1) -> 14
BM21: =IF(BM20=50,1,BM20+1) -> 15
BM22: =IF(BM21=50,1,BM21+1) -> 16
... BM57: =IF(BM56=50,1,BM56+1) -> 1

Sheet 機能概要
A1: システム名 | K1: システム種別 | W1: =IF(表紙!W1="","",表紙!W1) -> 基本設計書 | AP1: 作成者 | AT1: 作成日 | AY1: 更新者 | BC1: 更新日 | BH1: 版数
A2: =IF(表紙!A2="","",表紙!A2) -> POSサーバー | K2: =IF(表紙!K2="","",表紙!K2) -> POSサーバ | AP2: =IF(表紙!AP2="","",表紙!AP2) -> LoiLV | AT2: =IF(表紙!AT2="","",表紙!AT2) -> 45460 | AY2: =IF(表紙!AY2="","",表紙!AY2) -> AnhNM | BC2: =IF(表紙!BC2="","",表紙!BC2) -> 45583 | BH2: =IF(表紙!BH2="","",表紙!BH2) -> 0.4
A4: 機能カテゴリ | H4: =IF(表紙!H4="","",表紙!H4) -> 29_レジ別時間帯別点検 | U4: 項目 | Z4: =IF(表紙!Z4="","",表紙!Z4) -> 概要設計 | AP4: {=RIGHT(CELL("filename",$A$1),LEN(CELL("filename",$A$1))-FIND("]",CELL("filename",$A$1)))} -> 機能概要
B7: 29_レジ別時間帯別点検
BM8: =IF(BM7=50,1,BM7+1) -> 1
BM9: =IF(BM8=50,1,BM8+1) -> 2
BM10: =IF(BM9=50,1,BM9+1) -> 3
BM11: =IF(BM10=50,1,BM10+1) -> 4
BM12: =IF(BM11=50,1,BM11+1) -> 5
BM13: =IF(BM12=50,1,BM12+1) -> 6
BM14: =IF(BM13=50,1,BM13+1) -> 7
BM15: =IF(BM14=50,1,BM14+1) -> 8
BM16: =IF(BM15=50,1,BM15+1) -> 9
BM17: =IF(BM16=50,1,BM16+1) -> 10
BM18: =IF(BM17=50,1,BM17+1) -> 11
BM19: =IF(BM18=50,1,BM18+1) -> 12
... BM23: =IF(BM22=50,1,BM22+1) -> 16
BM24: =IF(BM23=50,1,BM23+1) -> 17 | BO24: SC2901_レジ別時間帯別点検画面
BM25: =IF(BM24=50,1,BM24+1) -> 18
BM26: =IF(BM25=50,1,BM25+1) -> 19
BM27: =IF(BM26=50,1,BM26+1) -> 20
BM28: =IF(BM27=50,1,BM27+1) -> 21
BM29: =IF(BM28=50,1,BM28+1) -> 22
BM30: =IF(BM29=50,1,BM29+1) -> 23
BM31: =IF(BM30=50,1,BM30+1) -> 24
BM32: =IF(BM31=50,1,BM31+1) -> 25
BM33: =IF(BM32=50,1,BM32+1) -> 26
BM34: =IF(BM33=50,1,BM33+1) -> 27
BM35: =IF(BM34=50,1,BM34+1) -> 28
BM36: =IF(BM35=50,1,BM35+1) -> 29
... BM53: =IF(BM52=50,1,BM52+1) -> 46
BM54: =IF(BM53=50,1,BM53+1) -> 47 | BO54: PR2901_時間帯別レジ日報
BM55: =IF(BM54=50,1,BM54+1) -> 48
BM56: =IF(BM55=50,1,BM55+1) -> 49
BM57: =IF(BM56=50,1,BM56+1) -> 50
BM58: =IF(BM57=50,1,BM57+1) -> 1
BM59: =IF(BM58=50,1,BM58+1) -> 2
BM60: =IF(BM59=50,1,BM59+1) -> 3
BM61: =IF(BM60=50,1,BM60+1) -> 4
BM62: =IF(BM61=50,1,BM61+1) -> 5
...

Sheet レジ別時間他別客数構成比
B1: 合計 | D1: 190 | F1: 301 | H1: 302 | J1: 303 | L1: 304 | N1: 305 | P1: 306 | R1: 307 | T1: 308 | V1: 309 | X1: 320 | Z1: 401
B2: 構成比 | C2: 客数 | D2: 構成比 | E2: 客数 | F2: 構成比 | G2: 客数 | H2: 構成比 | I2: 客数 | J2: 構成比 | K2: 客数 | L2: 構成比 | M2: 客数 | N2: 構成比 | O2: 客数 | P2: 構成比 | Q2: 客数 | R2: 構成比 | S2: 客数 | T2: 構成比 | U2: 客数 | V2: 構成比 | W2: 客数 | X2: 構成比 | Y2: 客数 | Z2: 構成比 | AA2: 客数
A3: 合計 | B3: =D3+H3+J3+L3+N3+P3+R3+T3+V3+X3+Z3 -> 100 | C3: =E3+G3+I3+K3+M3+O3+Q3+S3+U3+W3+Y3+AA3 -> 1626 | D3: =E3/AB3*100 -> 3.5670357 | E3: 58 | F3: =G3/AD3*100 -> 0 | G3: 0 | H3: =I3/AF3*100 -> 7.99508 | I3: 130 | J3: =K3/AH3*100 -> 20.664207 | K3: 336 | L3: =M3/AJ3*100 -> 8.1795818 | M3: 133 | N3: =O3/AL3*100 -> 7.3800738 | O3: 120 | P3: =Q3/AN3*100 -> 13.345633 | Q3: 217 | R3: =S3/AP3*100 -> 12.300123 | S3: 200 | T3: =U3/AR3*100 -> 10.639606 | U3: 173 | V3: =W3/AT3*100 -> 12.853629 | W3: 209 | X3: =Y3/AV3*100 -> 0.86100861 | Y3: 14 | Z3: =AA3/AX3*100 -> 2.2140221 | AA3: 36 | AB3: 1626 | AC3: 1626 | AD3: 1626 | AE3: 1626 | AF3: 1626 | AG3: 1626 | AH3: 1626 | AI3: 1626 | AJ3: 1626 | AK3: 1626 | AL3: 1626 | AM3: 1626 | AN3: 1626 | AO3: 1626 | AP3: 1626 | AQ3: 1626 | AR3: 1626 | AS3: 1626 | AT3: 1626 | AU3: 1626 | AV3: 1626 | AW3: 1626 | AX3: 1626 | AY3: 1626 | AZ3: 1626
A4: 8時 | B4: =D4+H4+J4+L4+N4+P4+R4+T4+V4+X4+Z4 -> 0 | C4: =E4+G4+I4+K4+M4+O4+Q4+S4+U4+W4+Y4+AA4 -> 0 | D4: 0 | E4: 0 | F4: 0 | G4: 0 | H4: 0 | I4: 0 | J4: 0 | K4: 0 | L4: 0 | M4: 0 | N4: 0 | O4: 0 | P4: 0 | Q4: 0 | R4: 0 | S4: 0 | T4: 0 | U4: 0 | V4: 0 | W4: 0 | X4: 0 | Y4: 0 | Z4: 0 | AA4: 0 | AB4: 0 | AC4: 0 | AD4: 0 | AE4: 0 | AF4: 0 | AG4: 0 | AH4: 0 | AI4: 0 | AJ4: 0 | AK4: 0 | AL4: 0 | AM4: 0 | AN4: 0 | AO4: 0 | AP4: 0 | AQ4: 0 | AR4: 0 | AS4: 0 | AT4: 0 | AU4: 0 | AV4: 0 | AW4: 0 | AX4: 0 | AY4: 0 | AZ4: 0
A5: 9時 | B5: =D5+H5+J5+L5+N5+P5+R5+T5+V5+X5+Z5 -> 100 | C5: =E5+G5+I5+K5+M5+O5+Q5+S5+U5+W5+Y5+AA5 -> 86 | D5: =E5/AB5*100 -> 0 | E5: 0 | F5: 0 | G5: 0 | H5: 0 | I5: 0 | J5: =K5/AH5*100 -> 26.744186 | K5: 23 | L5: =M5/AJ5*100 -> 6.9767442 | M5: 6 | N5: =O5/AL5*100 -> 6.9767442 | O5: 6 | P5: =Q5/AN5*100 -> 13.953488 | Q5: 12 | R5: =S5/AP5*100 -> 16.27907 | S5: 14 | T5: =U5/AR5*100 -> 9.3023256 | U5: 8 | V5: =W5/AT5*100 -> 17.44186 | W5: 15 | X5: =Y5/AV5*100 -> 2.3255814 | Y5: 2 | Z5: 0 | AA5: 0 | AB5: 86 | AC5: 86 | AD5: 86 | AE5: 86 | AF5: 86 | AG5: 86 | AH5: 86 | AI5: 86 | AJ5: 86 | AK5: 86 | AL5: 86 | AM5: 86 | AN5: 86 | AO5: 86 | AP5: 86 | AQ5: 86 | AR5: 86 | AS5: 86 | AT5: 86 | AU5: 86 | AV5: 86 | AW5: 86 | AX5: 86 | AY5: 86 | AZ5: 86
A6: 10時 | B6: =D6+H6+J6+L6+N6+P6+R6+T6+V6+X6+Z6 -> 100 | C6: =E6+G6+I6+K6+M6+O6+Q6+S6+U6+W6+Y6+AA6 -> 157 | D6: =E6/AB6*100 -> 2.5477707 | E6: 4 | F6: =G6/AD6*100 -> 0 | G6: 0 | H6: =I6/AF6*100 -> 12.101911 | I6: 19 | J6: =K6/AH6*100 -> 18.471338 | K6: 29 | L6: =M6/AJ6*100 -> 9.5541401 | M6: 15 | N6: =O6/AL6*100 -> 8.2802548 | O6: 13 | P6: =Q6/AN6*100 -> 15.286624 | Q6: 24 | R6: =S6/AP6*100 -> 11.464968 | S6: 18 | T6: =U6/AR6*100 -> 8.2802548 | U6: 13 | V6: =W6/AT6*100 -> 10.191083 | W6: 16 | X6: =Y6/AV6*100 -> 0.63694268 | Y6: 1 | Z6: =AA6/AX6*100 -> 3.1847134 | AA6: 5 | AB6: 157 | AC6: 157 | AD6: 157 | AE6: 157 | AF6: 157 | AG6: 157 | AH6: 157 | AI6: 157 | AJ6: 157 | AK6: 157 | AL6: 157 | AM6: 157 | AN6: 157 | AO6: 157 | AP6: 157 | AQ6: 157 | AR6: 157 | AS6: 157 | AT6: 157 | AU6: 157 | AV6: 157 | AW6: 157 | AX6: 157 | AY6: 157 | AZ6: 157
A7: 11時 | B7: =D7+H7+J7+L7+N7+P7+R7+T7+V7+X7+Z7 -> 100 | C7: =E7+G7+I7+K7+M7+O7+Q7+S7+U7+W7+Y7+AA7 -> 188 | D7: =E7/AB7*100 -> 3.7234043 | E7: 7 | F7: =G7/AD7*100 -> 0 | G7: 0 | H7: =I7/AF7*100 -> 12.234043 | I7: 23 | J7: =K7/AH7*100 -> 16.489362 | K7: 31 | L7: =M7/AJ7*100 -> 7.4468085 | M7: 14 | N7: =O7/AL7*100 -> 7.4468085 | O7: 14 | P7: =Q7/AN7*100 -> 10.638298 | Q7: 20 | R7: =S7/AP7*100 -> 12.234043 | S7: 23 | T7: =U7/AR7*100 -> 12.234043 | U7: 23 | V7: =W7/AT7*100 -> 11.170213 | W7: 21 | X7: =Y7/AV7*100 -> 1.0638298 | Y7: 2 | Z7: =AA7/AX7*100 -> 5.3191489 | AA7: 10 | AB7: 188 | AC7: 188 | AD7: 188 | AE7: 188 | AF7: 188 | AG7: 188 | AH7: 188 | AI7: 188 | AJ7: 188 | AK7: 188 | AL7: 188 | AM7: 188 | AN7: 188 | AO7: 188 | AP7: 188 | AQ7: 188 | AR7: 188 | AS7: 188 | AT7: 188 | AU7: 188 | AV7: 188 | AW7: 188 | AX7: 188 | AY7: 188 | AZ7: 188
A8: 12時 | B8: =D8+H8+J8+L8+N8+P8+R8+T8+V8+X8+Z8 -> 100 | C8: =E8+G8+I8+K8+M8+O8+Q8+S8+U8+W8+Y8+AA8 -> 153 | D8: =E8/AB8*100 -> 3.2679739 | E8: 5 | F8: =G8/AD8*100 -> 0 | G8: 0 | H8: =I8/AF8*100 -> 4.5751634 | I8: 7 | J8: =K8/AH8*100 -> 24.836601 | K8: 38 | L8: =M8/AJ8*100 -> 9.8039216 | M8: 15 | N8: =O8/AL8*100 -> 7.8431373 | O8: 12 | P8: =Q8/AN8*100 -> 14.379085 | Q8: 22 | R8: =S8/AP8*100 -> 12.418301 | S8: 19 | T8: =U8/AR8*100 -> 9.1503268 | U8: 14 | V8: =W8/AT8*100 -> 13.071895 | W8: 20 | X8: =Y8/AV8*100 -> 0 | Y8: 0 | Z8: =AA8/AX8*100 -> 0.65359477 | AA8: 1 | AB8: 153 | AC8: 153 | AD8: 153 | AE8: 153 | AF8: 153 | AG8: 153 | AH8: 153 | AI8: 153 | AJ8: 153 | AK8: 153 | AL8: 153 | AM8: 153 | AN8: 153 | AO8: 153 | AP8: 153 | AQ8: 153 | AR8: 153 | AS8: 153 | AT8: 153 | AU8: 153 | AV8: 153 | AW8: 153 | AX8: 153 | AY8: 153 | AZ8: 153
A9: 13時 | B9: =D9+H9+J9+L9+N9+P9+R9+T9+V9+X9+Z9 -> 100 | C9: =E9+G9+I9+K9+M9+O9+Q9+S9+U9+W9+Y9+AA9 -> 106 | D9: =E9/AB9*100 -> 2.8301887 | E9: 3 | F9: =G9/AD9*100 -> 0 | G9: 0 | H9: =I9/AF9*100 -> 1.8867925 | I9: 2 | J9: =K9/AH9*100 -> 25.471698 | K9: 27 | L9: =M9/AJ9*100 -> 6.6037736 | M9: 7 | N9: =O9/AL9*100 -> 6.6037736 | O9: 7 | P9: =Q9/AN9*100 -> 14.150943 | Q9: 15 | R9: =S9/AP9*100 -> 14.150943 | S9: 15 | T9: =U9/AR9*100 -> 8.490566 | U9: 9 | V9: =W9/AT9*100 -> 14.150943 | W9: 15 | X9: =Y9/AV9*100 -> 0.94339623 | Y9: 1 | Z9: =AA9/AX9*100 -> 4.7169811 | AA9: 5 | AB9: 106 | AC9: 106 | AD9: 106 | AE9: 106 | AF9: 106 | AG9: 106 | AH9: 106 | AI9: 106 | AJ9: 106 | AK9: 106 | AL9: 106 | AM9: 106 | AN9: 106 | AO9: 106 | AP9: 106 | AQ9: 106 | AR9: 106 | AS9: 106 | AT9: 106 | AU9: 106 | AV9: 106 | AW9: 106 | AX9: 106 | AY9: 106 | AZ9: 106
A10: 14時 | B10: =D10+H10+J10+L10+N10+P10+R10+T10+V10+X10+Z10 -> 100 | C10: =E10+G10+I10+K10+M10+O10+Q10+S10+U10+W10+Y10+AA10 -> 122 | D10: =E10/AB10*100 -> 4.9180328 | E10: 6 | F10: =G10/AD10*100 -> 0 | G10: 0 | H10: =I10/AF10*100 -> 4.0983607 | I10: 5 | J10: =K10/AH10*100 -> 24.590164 | K10: 30 | L10: =M10/AJ10*100 -> 8.1967213 | M10: 10 | N10: =O10/AL10*100 -> 7.3770492 | O10: 9 | P10: =Q10/AN10*100 -> 13.934426 | Q10: 17 | R10: =S10/AP10*100 -> 11.47541 | S10: 14 | T10: =U10/AR10*100 -> 9.0163934 | U10: 11 | V10: =W10/AT10*100 -> 11.47541 | W10: 14 | X10: =Y10/AV10*100 -> 1.6393443 | Y10: 2 | Z10: =AA10/AX10*100 -> 3.2786885 | AA10: 4 | AB10: 122 | AC10: 122 | AD10: 122 | AE10: 122 | AF10: 122 | AG10: 122 | AH10: 122 | AI10: 122 | AJ10: 122 | AK10: 122 | AL10: 122 | AM10: 122 | AN10: 122 | AO10: 122 | AP10: 122 | AQ10: 122 | AR10: 122 | AS10: 122 | AT10: 122 | AU10: 122 | AV10: 122 | AW10: 122 | AX10: 122 | AY10: 122 | AZ10: 122
A11: 15時 | B11: =D11+H11+J11+L11+N11+P11+R11+T11+V11+X11+Z11 -> 100 | C11: =E11+G11+I11+K11+M11+O11+Q11+S11+U11+W11+Y11+AA11 -> 126 | D11: =E11/AB11*100 -> 2.3809524 | E11: 3 | F11: =G11/AD11*100 -> 0 | G11: 0 | H11: =I11/AF11*100 -> 9.5238095 | I11: 12 | J11: =K11/AH11*100 -> 15.079365 | K11: 19 | L11: =M11/AJ11*100 -> 6.3492063 | M11: 8 | N11: =O11/AL11*100 -> 7.9365079 | O11: 10 | P11: =Q11/AN11*100 -> 12.698413 | Q11: 16 | R11: =S11/AP11*100 -> 12.698413 | S11: 16 | T11: =U11/AR11*100 -> 12.698413 | U11: 16 | V11: =W11/AT11*100 -> 11.904762 | W11: 15 | X11: =Y11/AV11*100 -> 0 | Y11: 0 | Z11: =AA11/AX11*100 -> 8.7301587 | AA11: 11 | AB11: 126 | AC11: 126 | AD11: 126 | AE11: 126 | AF11: 126 | AG11: 126 | AH11: 126 | AI11: 126 | AJ11: 126 | AK11: 126 | AL11: 126 | AM11: 126 | AN11: 126 | AO11: 126 | AP11: 126 | AQ11: 126 | AR11: 126 | AS11: 126 | AT11: 126 | AU11: 126 | AV11: 126 | AW11: 126 | AX11: 126 | AY11: 126 | AZ11: 126
A12: 16時 | B12: =D12+H12+J12+L12+N12+P12+R12+T12+V12+X12+Z12 -> 100 | C12: =E12+G12+I12+K12+M12+O12+Q12+S12+U12+W12+Y12+AA12 -> 196 | D12: =E12/AB12*100 -> 4.5918367 | E12: 9 | F12: =G12/AD12*100 -> 0 | G12: 0 | H12: =I12/AF12*100 -> 11.734694 | I12: 23 | J12: =K12/AH12*100 -> 20.918367 | K12: 41 | L12: =M12/AJ12*100 -> 8.1632653 | M12: 16 | N12: =O12/AL12*100 -> 6.6326531 | O12: 13 | P12: =Q12/AN12*100 -> 11.22449 | Q12: 22 | R12: =S12/AP12*100 -> 10.714286 | S12: 21 | T12: =U12/AR12*100 -> 11.734694 | U12: 23 | V12: =W12/AT12*100 -> 13.77551 | W12: 27 | X12: =Y12/AV12*100 -> 0.51020408 | Y12: 1 | Z12: =AA12/AX12*100 -> 0 | AA12: 0 | AB12: 196 | AC12: 196 | AD12: 196 | AE12: 196 | AF12: 196 | AG12: 196 | AH12: 196 | AI12: 196 | AJ12: 196 | AK12: 196 | AL12: 196 | AM12: 196 | AN12: 196 | AO12: 196 | AP12: 196 | AQ12: 196 | AR12: 196 | AS12: 196 | AT12: 196 | AU12: 196 | AV12: 196 | AW12: 196 | AX12: 196 | AY12: 196 | AZ12: 196
A13: 17時 | B13: =D13+H13+J13+L13+N13+P13+R13+T13+V13+X13+Z13 -> 100 | C13: =E13+G13+I13+K13+M13+O13+Q13+S13+U13+W13+Y13+AA13 -> 189 | D13: =E13/AB13*100 -> 4.7619048 | E13: 9 | F13: =G13/AD13*100 -> 0 | G13: 0 | H13: =I13/AF13*100 -> 16.402116 | I13: 31 | J13: =K13/AH13*100 -> 19.047619 | K13: 36 | L13: =M13/AJ13*100 -> 6.8783069 | M13: 13 | N13: =O13/AL13*100 -> 7.9365079 | O13: 15 | P13: =Q13/AN13*100 -> 11.111111 | Q13: 21 | R13: =S13/AP13*100 -> 11.640212 | S13: 22 | T13: =U13/AR13*100 -> 8.994709 | U13: 17 | V13: =W13/AT13*100 -> 11.111111 | W13: 21 | X13: =Y13/AV13*100 -> 2.1164021 | Y13: 4 | Z13: =AA13/AX13*100 -> 0 | AA13: 0 | AB13: 189 | AC13: 189 | AD13: 189 | AE13: 189 | AF13: 189 | AG13: 189 | AH13: 189 | AI13: 189 | AJ13: 189 | AK13: 189 | AL13: 189 | AM13: 189 | AN13: 189 | AO13: 189 | AP13: 189 | AQ13: 189 | AR13: 189 | AS13: 189 | AT13: 189 | AU13: 189 | AV13: 189 | AW13: 189 | AX13: 189 | AY13: 189 | AZ13: 189
A14: 18時 | B14: =D14+H14+J14+L14+N14+P14+R14+T14+V14+X14+Z14 -> 100 | C14: =E14+G14+I14+K14+M14+O14+Q14+S14+U14+W14+Y14+AA14 -> 139 | D14: =E14/AB14*100 -> 5.0359712 | E14: 7 | F14: =G14/AD14*100 -> 0 | G14: 0 | H14: =I14/AF14*100 -> 4.3165468 | I14: 6 | J14: =K14/AH14*100 -> 25.899281 | K14: 36 | L14: =M14/AJ14*100 -> 10.071942 | M14: 14 | N14: =O14/AL14*100 -> 9.352518 | O14: 13 | P14: =Q14/AN14*100 -> 15.827338 | Q14: 22 | R14: =S14/AP14*100 -> 10.071942 | S14: 14 | T14: =U14/AR14*100 -> 10.071942 | U14: 14 | V14: =W14/AT14*100 -> 8.6330935 | W14: 12 | X14: =Y14/AV14*100 -> 0.71942446 | Y14: 1 | Z14: =AA14/AX14*100 -> 0 | AA14: 0 | AB14: 139 | AC14: 139 | AD14: 139 | AE14: 139 | AF14: 139 | AG14: 139 | AH14: 139 | AI14: 139 | AJ14: 139 | AK14: 139 | AL14: 139 | AM14: 139 | AN14: 139 | AO14: 139 | AP14: 139 | AQ14: 139 | AR14: 139 | AS14: 139 | AT14: 139 | AU14: 139 | AV14: 139 | AW14: 139 | AX14: 139 | AY14: 139 | AZ14: 139
A15: 19時 | B15: =D15+H15+J15+L15+N15+P15+R15+T15+V15+X15+Z15 -> 100 | C15: =E15+G15+I15+K15+M15+O15+Q15+S15+U15+W15+Y15+AA15 -> 91 | D15: =E15/AB15*100 -> 4.3956044 | E15: 4 | F15: =G15/AD15*100 -> 0 | G15: 0 | H15: =I15/AF15*100 -> 2.1978022 | I15: 2 | J15: =K15/AH15*100 -> 28.571429 | K15: 26 | L15: =M15/AJ15*100 -> 7.6923077 | M15: 7 | N15: =O15/AL15*100 -> 5.4945055 | O15: 5 | P15: =Q15/AN15*100 -> 12.087912 | Q15: 11 | R15: =S15/AP15*100 -> 14.285714 | S15: 13 | T15: =U15/AR15*100 -> 9.8901099 | U15: 9 | V15: =W15/AT15*100 -> 15.384615 | W15: 14 | X15: =Y15/AV15*100 -> 0 | Y15: 0 | Z15: =AA15/AX15*100 -> 0 | AA15: 0 | AB15: 91 | AC15: 91 | AD15: 91 | AE15: 91 | AF15: 91 | AG15: 91 | AH15: 91 | AI15: 91 | AJ15: 91 | AK15: 91 | AL15: 91 | AM15: 91 | AN15: 91 | AO15: 91 | AP15: 91 | AQ15: 91 | AR15: 91 | AS15: 91 | AT15: 91 | AU15: 91 | AV15: 91 | AW15: 91 | AX15: 91 | AY15: 91 | AZ15: 91
A16: 20時 | B16: =D16+H16+J16+L16+N16+P16+R16+T16+V16+X16+Z16 -> 100 | C16: =E16+G16+I16+K16+M16+O16+Q16+S16+U16+W16+Y16+AA16 -> 46 | D16: =E16/AB16*100 -> 2.173913 | E16: 1 | F16: =G16/AD16*100 -> 0 | G16: 0 | H16: =I16/AF16*100 -> 0 | I16: 0 | J16: =K16/AH16*100 -> 0 | K16: 0 | L16: =M16/AJ16*100 -> 13.043478 | M16: 6 | N16: =O16/AL16*100 -> 4.3478261 | O16: 2 | P16: =Q16/AN16*100 -> 17.391304 | Q16: 8 | R16: =S16/AP16*100 -> 15.217391 | S16: 7 | T16: =U16/AR16*100 -> 23.913043 | U16: 11 | V16: =W16/AT16*100 -> 23.913043 | W16: 11 | X16: =Y16/AV16*100 -> 0 | Y16: 0 | Z16: =AA16/AX16*100 -> 0 | AA16: 0 | AB16: 46 | AC16: 46 | AD16: 46 | AE16: 46 | AF16: 46 | AG16: 46 | AH16: 46 | AI16: 46 | AJ16: 46 | AK16: 46 | AL16: 46 | AM16: 46 | AN16: 46 | AO16: 46 | AP16: 46 | AQ16: 46 | AR16: 46 | AS16: 46 | AT16: 46 | AU16: 46 | AV16: 46 | AW16: 46 | AX16: 46 | AY16: 46 | AZ16: 46
A17: 21時 | B17: =D17+H17+J17+L17+N17+P17+R17+T17+V17+X17+Z17 -> 100 | C17: =E17+G17+I17+K17+M17+O17+Q17+S17+U17+W17+Y17+AA17 -> 26 | D17: =E17/AB17*100 -> 0 | E17: 0 | F17: 0 | G17: 0 | H17: 0 | I17: 0 | J17: 0 | K17: 0 | L17: =M17/AJ17*100 -> 7.6923077 | M17: 2 | N17: =O17/AL17*100 -> 3.8461538 | O17: 1 | P17: =Q17/AN17*100 -> 26.923077 | Q17: 7 | R17: =S17/AP17*100 -> 15.384615 | S17: 4 | T17: =U17/AR17*100 -> 15.384615 | U17: 4 | V17: =W17/AT17*100 -> 30.769231 | W17: 8 | X17: =Y17/AV17*100 -> 0 | Y17: 0 | Z17: 0 | AA17: 0 | AB17: 26 | AC17: 26 | AD17: 26 | AE17: 26 | AF17: 26 | AG17: 26 | AH17: 26 | AI17: 26 | AJ17: 26 | AK17: 26 | AL17: 26 | AM17: 26 | AN17: 26 | AO17: 26 | AP17: 26 | AQ17: 26 | AR17: 26 | AS17: 26 | AT17: 26 | AU17: 26 | AV17: 26 | AW17: 26 | AX17: 26 | AY17: 26 | AZ17: 26
A18: 22時 | B18: =D18+H18+J18+L18+N18+P18+R18+T18+V18+X18+Z18 -> 0 | C18: =E18+G18+I18+K18+M18+O18+Q18+S18+U18+W18+Y18+AA18 -> 0 | D18: 0 | E18: 0 | F18: 0 | G18: 0 | H18: 0 | I18: 0 | J18: 0 | K18: 0 | L18: 0 | M18: 0 | N18: 0 | O18: 0 | P18: 0 | Q18: 0 | R18: 0 | S18: 0 | T18: 0 | U18: 0 | V18: 0 | W18: 0 | X18: 0 | Y18: 0 | Z18: 0 | AA18: 0 | AB18: 0 | AC18: 0 | AD18: 0 | AE18: 0 | AF18: 0 | AG18: 0 | AH18: 0 | AI18: 0 | AJ18: 0 | AK18: 0 | AL18: 0 | AM18: 0 | AN18: 0 | AO18: 0 | AP18: 0 | AQ18: 0 | AR18: 0 | AS18: 0 | AT18: 0 | AU18: 0 | AV18: 0 | AW18: 0 | AX18: 0 | AY18: 0 | AZ18: 0
A19: 23時 | B19: =D19+H19+J19+L19+N19+P19+R19+T19+V19+X19+Z19 -> 0 | C19: =E19+G19+I19+K19+M19+O19+Q19+S19+U19+W19+Y19+AA19 -> 0 | D19: 0 | E19: 0 | F19: 0 | G19: 0 | H19: 0 | I19: 0 | J19: 0 | K19: 0 | L19: 0 | M19: 0 | N19: 0 | O19: 0 | P19: 0 | Q19: 0 | R19: 0 | S19: 0 | T19: 0 | U19: 0 | V19: 0 | W19: 0 | X19: 0 | Y19: 0 | Z19: 0 | AA19: 0 | AB19: 0 | AC19: 0 | AD19: 0 | AE19: 0 | AF19: 0 | AG19: 0 | AH19: 0 | AI19: 0 | AJ19: 0 | AK19: 0 | AL19: 0 | AM19: 0 | AN19: 0 | AO19: 0 | AP19: 0 | AQ19: 0 | AR19: 0 | AS19: 0 | AT19: 0 | AU19: 0 | AV19: 0 | AW19: 0 | AX19: 0 | AY19: 0 | AZ19: 0
A20: 24時 | B20: =D20+H20+J20+L20+N20+P20+R20+T20+V20+X20+Z20 -> 0 | C20: =E20+G20+I20+K20+M20+O20+Q20+S20+U20+W20+Y20+AA20 -> 0 | D20: 0 | E20: 0 | F20: 0 | G20: 0 | H20: 0 | I20: 0 | J20: 0 | K20: 0 | L20: 0 | M20: 0 | N20: 0 | O20: 0 | P20: 0 | Q20: 0 | R20: 0 | S20: 0 | T20: 0 | U20: 0 | V20: 0 | W20: 0 | X20: 0 | Y20: 0 | Z20: 0 | AA20: 0 | AB20: 0 | AC20: 0 | AD20: 0 | AE20: 0 | AF20: 0 | AG20: 0 | AH20: 0 | AI20: 0 | AJ20: 0 | AK20: 0 | AL20: 0 | AM20: 0 | AN20: 0 | AO20: 0 | AP20: 0 | AQ20: 0 | AR20: 0 | AS20: 0 | AT20: 0 | AU20: 0 | AV20: 0 | AW20: 0 | AX20: 0 | AY20: 0 | AZ20: 0

Sheet 画面設計書
A1: システム名 | K1: システム種別 | W1: =IF(表紙!W1="","",表紙!W1) -> 基本設計書 | AP1: 作成者 | AT1: 作成日 | AY1: 更新者 | BC1: 更新日 | BH1: 版数
A2: =IF(表紙!A2="","",表紙!A2) -> POSサーバー | K2: =IF(表紙!K2="","",表紙!K2) -> POSサーバ | AP2: =IF(表紙!AP2="","",表紙!AP2) -> LoiLV | AT2: =IF(表紙!AT2="","",表紙!AT2) -> 45460 | AY2: =IF(表紙!AY2="","",表紙!AY2) -> AnhNM | BC2: =IF(表紙!BC2="","",表紙!BC2) -> 45583 | BH2: =IF(表紙!BH2="","",表紙!BH2) -> 0.4
A4: 機能カテゴリ | H4: =IF(表紙!H4="","",表紙!H4) -> 29_レジ別時間帯別点検 | U4: 項目 | Z4: =IF(表紙!Z4="","",表紙!Z4) -> 概要設計 | AP4: =MID(CELL("filename",A1),FIND("]",CELL("filename",A1))+1,255) -> 画面設計書
B7: ■ログイン画面のイメージ
B35: ■画面項目定義
B37: 画面項目ID | D37: 項目 | K37: タイプ | N37: I/O | O37: 多言語対象 | P37: 出力 | AR37: インプット | BC37: 備考
P38: マッピングデータ | X38: 初期値 | AA38: 表示コントロール | AI38: Control enable | AR38: 必須 | AS38: 数字 | AT38: 桁 | AU38: マッピングデータ
P39: API名 | T39: 項目 | AU39: API名 | AY39: 項目
B40: 1 | K40: テキスト | N40: － | O40: ● | P40: － | T40: － | X40: Android POS Control | AA40: ー | AI40: － | AR40: － | AS40: ー | AT40: ー | AU40: － | AY40: ー
B41: 2 | K41: テキスト | N41: O | O41: ● | P41: － | T41: － | X41: User ID | AA41: ー | AI41: ー | AR41: － | AS41: ー | AT41: ー | AU41: － | AY41: ー
B42: 3 | K42: テキスト | N42: I | O42: － | P42: － | X42: － | AA42: ー | AI42: ー | AR42: － | AS42: ー | AT42: ー | AU42: － | AY42: ー
B43: 4 | K43: テキスト | N43: O | O43: ● | P43: － | T43: － | X43: Password | AA43: ー | AI43: ー | AR43: － | AS43: ー | AT43: ー | AU43: － | AY43: ー
B44: 5 | K44: EditText | N44: I | O44: － | P44: － | T44: － | X44: － | AA44: ー | AI44: ー | AR44: － | AS44: ー | AT44: ー | AU44: － | AY44: ー
B45: 6 | K45: ボタン | N45: I | O45: ● | P45: － | T45: － | X45: Login | AA45: ー | AI45: 有効 | AR45: － | AS45: ー | AT45: ー | AU45: － | AY45: ー | BC45: Login-01/EmployeeMaster

Sheet テンプレート
A1: システム名 | K1: システム種別 | W1: =IF(表紙!W1="","",表紙!W1) -> 基本設計書 | AP1: 作成者 | AT1: 作成日 | AY1: 更新者 | BC1: 更新日 | BH1: 版数
A2: =IF(表紙!A2="","",表紙!A2) -> POSサーバー | K2: =IF(表紙!K2="","",表紙!K2) -> POSサーバ | AP2: =IF(表紙!AP2="","",表紙!AP2) -> LoiLV | AT2: =IF(表紙!AT2="","",表紙!AT2) -> 45460 | AY2: =IF(表紙!AY2="","",表紙!AY2) -> AnhNM | BC2: =IF(表紙!BC2="","",表紙!BC2) -> 45583 | BH2: =IF(表紙!BH2="","",表紙!BH2) -> 0.4
A4: 機能カテゴリ | H4: =IF(表紙!H4="","",表紙!H4) -> 29_レジ別時間帯別点検 | U4: 項目 | Z4: =IF(表紙!Z4="","",表紙!Z4) -> 概要設計 | AP4: =MID(CELL("filename",A1),FIND("]",CELL("filename",A1))+1,255) -> テンプレート
AX12: `
