Workbook

Sheet 表紙
A1: システム名 | K1: システム種別 | W1: 基本設計書 | AP1: 作成者 | AT1: 作成日 | AY1: 更新者 | BC1: 更新日 | BH1: 版数
A2: POSサーバー | K2: POSサーバ | AP2: =改訂履歴!$H$11 -> SonMNT | AT2: =改訂履歴!$B$11 -> 45477 | AY2: =LOOKUP(2,1/(改訂履歴!H11:H30000<>""),改訂履歴!H11:H30000) -> SonMNT | BC2: =LOOKUP(2,1/(改訂履歴!B11:B30000<>""),改訂履歴!B11:B30000) -> 45477 | BH2: =LOOKUP(2,1/(改訂履歴!O11:O30000<>""),改訂履歴!O11:O30000) -> 0.1
A4: 機能カテゴリ | H4: 95_セットマッチ設定 | U4: 項目 | Z4: 概要設計 | AP4: {=RIGHT(CELL("filename",$A$1),LEN(CELL("filename",$A$1))-FIND("]",CELL("filename",$A$1)))} -> 表紙
L16: POSサーバーの基本設計書
L24: =K2&"/"&H4&"/"&Z4 -> POSサーバ/95_セットマッチ設定/概要設計
Q44: 承認日 | AA44: 承認者 | AQ44: 版数

Sheet 改訂履歴
A1: システム名 | K1: システム種別 | W1: =IF(表紙!W1="","",表紙!W1) -> 基本設計書 | AP1: 作成者 | AT1: 作成日 | AY1: 更新者 | BC1: 更新日 | BH1: 版数
A2: =IF(表紙!A2="","",表紙!A2) -> POSサーバー | K2: =IF(表紙!K2="","",表紙!K2) -> POSサーバ | AP2: =IF(表紙!AP2="","",表紙!AP2) -> SonMNT | AT2: =IF(表紙!AT2="","",表紙!AT2) -> 45477 | AY2: =IF(表紙!AY2="","",表紙!AY2) -> SonMNT | BC2: =IF(表紙!BC2="","",表紙!BC2) -> 45477 | BH2: =IF(表紙!BH2="","",表紙!BH2) -> 0.1
A4: 機能カテゴリー | H4: =IF(表紙!H4="","",表紙!H4) -> 95_セットマッチ設定 | U4: 項目 | Z4: =IF(表紙!Z4="","",表紙!Z4) -> 概要設計 | AP4: {=RIGHT(CELL("filename",$A$1),LEN(CELL("filename",$A$1))-FIND("]",CELL("filename",$A$1)))} -> 改訂履歴
B8: ■改訂履歴
B10: 更新日 | H10: 更新者 | O10: 版数 | S10: 更新内容 | AX10: 承認日 | BD10: 承認者
B11: 45477 | H11: SonMNT | O11: 0.1 | S11: 新規作成

Sheet 業務フロー
A1: システム名 | K1: システム種別 | W1: =IF(表紙!W1="","",表紙!W1) -> 基本設計書 | AP1: 作成者 | AT1: 作成日 | AY1: 更新者 | BC1: 更新日 | BH1: 版数
A2: =IF(表紙!A2="","",表紙!A2) -> POSサーバー | K2: =IF(表紙!K2="","",表紙!K2) -> POSサーバ | AP2: =IF(表紙!AP2="","",表紙!AP2) -> SonMNT | AT2: 45084 | AY2: =IF(表紙!AY2="","",表紙!AY2) -> SonMNT | BC2: =IF(表紙!BC2="","",表紙!BC2) -> 45477 | BH2: =IF(表紙!BH2="","",表紙!BH2) -> 0.1
A4: 機能カテゴリー | H4: =IF(表紙!H4="","",表紙!H4) -> 95_セットマッチ設定 | U4: 項目 | Z4: =IF(表紙!Z4="","",表紙!Z4) -> 概要設計 | AP4: {=RIGHT(CELL("filename",$A$1),LEN(CELL("filename",$A$1))-FIND("]",CELL("filename",$A$1)))} -> 業務フロー
B7: ●1_自動釣銭機
B22: ●1_レジ周辺機器
B42: ●外部連携

Sheet 機能概要説明
A1: システム名 | K1: システム種別 | W1: =IF(表紙!W1="","",表紙!W1) -> 基本設計書 | AP1: 作成者 | AT1: 作成日 | AY1: 更新者 | BC1: 更新日 | BH1: 版数
A2: =IF(表紙!A2="","",表紙!A2) -> POSサーバー | K2: =IF(表紙!K2="","",表紙!K2) -> POSサーバ | AP2: =IF(表紙!AP2="","",表紙!AP2) -> SonMNT | AT2: =IF(表紙!AT2="","",表紙!AT2) -> 45477 | AY2: =IF(表紙!AY2="","",表紙!AY2) -> SonMNT | BC2: =IF(表紙!BC2="","",表紙!BC2) -> 45477 | BH2: =IF(表紙!BH2="","",表紙!BH2) -> 0.1
A4: 機能カテゴリ | H4: =IF(表紙!H4="","",表紙!H4) -> 95_セットマッチ設定 | U4: 項目 | Z4: =IF(表紙!Z4="","",表紙!Z4) -> 概要設計 | AP4: {=RIGHT(CELL("filename",$A$1),LEN(CELL("filename",$A$1))-FIND("]",CELL("filename",$A$1)))} -> 機能概要説明
C7: セットマッチ設定機能 | BM7: =IF(BM6=50,1,BM6+1) -> 1
D8: ・セットマッチ情報を設定する。 | BM8: =IF(BM7=50,1,BM7+1) -> 2
E9: ‣新規作成 | BM9: =IF(BM8=50,1,BM8+1) -> 3
E10: ‣修正 | BM10: =IF(BM9=50,1,BM9+1) -> 4
E11: ・削除：夜間実行セットマッチを削除するバッチ、または画面上で削除するバッチがある。 | BM11: =IF(BM10=50,1,BM10+1) -> 5
D12: ・プロモーションコードに紐づけられたセットマッチコードに従って商品を設定する。1つのセットマッチコードで複数の設定が可能。 | BM12: =IF(BM11=50,1,BM11+1) -> 6
D13: ・セットマッチの有効期間はプロモーション期間内のみ設定可能。 | BM13: =IF(BM12=50,1,BM12+1) -> 7
D14: ・セットマッチ設定時にセットマッチの1つ製品グループの購入対象商品数を入力する必要がある。 | BM14: =IF(BM13=50,1,BM13+1) -> 8
D15: ・売価、割引、値引によるセットマッチ設定可能。 | BM15: =IF(BM14=50,1,BM14+1) -> 9
BM16: =IF(BM15=50,1,BM15+1) -> 10
BM17: =IF(BM16=50,1,BM16+1) -> 11
BM18: =IF(BM17=50,1,BM17+1) -> 12
BM19: =IF(BM18=50,1,BM18+1) -> 13
BM20: =IF(BM19=50,1,BM19+1) -> 14
BM21: =IF(BM20=50,1,BM20+1) -> 15
BM22: =IF(BM21=50,1,BM21+1) -> 16
BM23: =IF(BM22=50,1,BM22+1) -> 17
BM24: =IF(BM23=50,1,BM23+1) -> 18
BM25: =IF(BM24=50,1,BM24+1) -> 19
BM26: =IF(BM25=50,1,BM25+1) -> 20
BM27: =IF(BM26=50,1,BM26+1) -> 21
... BM59: =IF(BM58=50,1,BM58+1) -> 3

Sheet 機能概要
A1: システム名 | K1: システム種別 | W1: =IF(表紙!W1="","",表紙!W1) -> 基本設計書 | AP1: 作成者 | AT1: 作成日 | AY1: 更新者 | BC1: 更新日 | BH1: 版数
A2: =IF(表紙!A2="","",表紙!A2) -> POSサーバー | K2: =IF(表紙!K2="","",表紙!K2) -> POSサーバ | AP2: =IF(表紙!AP2="","",表紙!AP2) -> SonMNT | AT2: =IF(表紙!AT2="","",表紙!AT2) -> 45477 | AY2: =IF(表紙!AY2="","",表紙!AY2) -> SonMNT | BC2: =IF(表紙!BC2="","",表紙!BC2) -> 45477 | BH2: =IF(表紙!BH2="","",表紙!BH2) -> 0.1
A4: 機能カテゴリ | H4: =IF(表紙!H4="","",表紙!H4) -> 95_セットマッチ設定 | U4: 項目 | Z4: =IF(表紙!Z4="","",表紙!Z4) -> 概要設計 | AP4: {=RIGHT(CELL("filename",$A$1),LEN(CELL("filename",$A$1))-FIND("]",CELL("filename",$A$1)))} -> 機能概要
B7: 95_セットマッチ設定
BM8: =IF(BM7=50,1,BM7+1) -> 1
BM9: =IF(BM8=50,1,BM8+1) -> 2
BM10: =IF(BM9=50,1,BM9+1) -> 3
BM11: =IF(BM10=50,1,BM10+1) -> 4
BM12: =IF(BM11=50,1,BM11+1) -> 5
BM13: =IF(BM12=50,1,BM12+1) -> 6
BM14: =IF(BM13=50,1,BM13+1) -> 7
BM15: =IF(BM14=50,1,BM14+1) -> 8
BM16: =IF(BM15=50,1,BM15+1) -> 9
BM17: =IF(BM16=50,1,BM16+1) -> 10
BM18: =IF(BM17=50,1,BM17+1) -> 11
BM19: =IF(BM18=50,1,BM18+1) -> 12
... BM90: =IF(BM89=50,1,BM89+1) -> 33
B91: プロモーション情報検索機能 | BM91: =IF(BM90=50,1,BM90+1) -> 34
BM92: =IF(BM91=50,1,BM91+1) -> 35
BM93: =IF(BM92=50,1,BM92+1) -> 36
BM94: =IF(BM93=50,1,BM93+1) -> 37
BM95: =IF(BM94=50,1,BM94+1) -> 38
BM96: =IF(BM95=50,1,BM95+1) -> 39
BM97: =IF(BM96=50,1,BM96+1) -> 40
BM98: =IF(BM97=50,1,BM97+1) -> 41
BM99: =IF(BM98=50,1,BM98+1) -> 42
BM100: =IF(BM99=50,1,BM99+1) -> 43
BM101: =IF(BM100=50,1,BM100+1) -> 44
BM102: =IF(BM101=50,1,BM101+1) -> 45
BM103: =IF(BM102=50,1,BM102+1) -> 46
... BM119: =IF(BM118=50,1,BM118+1) -> 12
B120: セットマッチ情報検索機能 | BM120: =IF(BM119=50,1,BM119+1) -> 13
BM121: =IF(BM120=50,1,BM120+1) -> 14
BM122: =IF(BM121=50,1,BM121+1) -> 15
BM123: =IF(BM122=50,1,BM122+1) -> 16
BM124: =IF(BM123=50,1,BM123+1) -> 17
BM125: =IF(BM124=50,1,BM124+1) -> 18
BM126: =IF(BM125=50,1,BM125+1) -> 19
BM127: =IF(BM126=50,1,BM126+1) -> 20
BM128: =IF(BM127=50,1,BM127+1) -> 21
...

Sheet 画面設計書
A1: システム名 | K1: システム種別 | W1: =IF(表紙!W1="","",表紙!W1) -> 基本設計書 | AP1: 作成者 | AT1: 作成日 | AY1: 更新者 | BC1: 更新日 | BH1: 版数
A2: =IF(表紙!A2="","",表紙!A2) -> POSサーバー | K2: =IF(表紙!K2="","",表紙!K2) -> POSサーバ | AP2: =IF(表紙!AP2="","",表紙!AP2) -> SonMNT | AT2: =IF(表紙!AT2="","",表紙!AT2) -> 45477 | AY2: =IF(表紙!AY2="","",表紙!AY2) -> SonMNT | BC2: =IF(表紙!BC2="","",表紙!BC2) -> 45477 | BH2: =IF(表紙!BH2="","",表紙!BH2) -> 0.1
A4: 機能カテゴリ | H4: =IF(表紙!H4="","",表紙!H4) -> 95_セットマッチ設定 | U4: 項目 | Z4: =IF(表紙!Z4="","",表紙!Z4) -> 概要設計 | AP4: =MID(CELL("filename",A1),FIND("]",CELL("filename",A1))+1,255) -> 画面設計書
B7: ■ログイン画面のイメージ
B35: ■画面項目定義
B37: 画面項目ID | D37: 項目 | K37: Type | N37: I/O | O37: 多言語対象 | P37: 出力 | AR37: インプット | BC37: 備考
P38: マッピングデータ | X38: 初期値 | AA38: 表示コントロール | AI38: Control enable | AR38: 必須 | AS38: 数字 | AT38: 文字 | AU38: マッピングデータ
P39: API名 | T39: 項目 | AU39: API名 | AY39: 項目
B40: 1 | K40: テキスト | N40: － | O40: ● | P40: － | T40: － | X40: Android POS Control | AA40: ー | AI40: － | AR40: － | AS40: ー | AT40: ー | AU40: － | AY40: ー
B41: 2 | K41: テキスト | N41: O | O41: ● | P41: － | T41: － | X41: User ID | AA41: ー | AI41: ー | AR41: － | AS41: ー | AT41: ー | AU41: － | AY41: ー
B42: 3 | K42: テキスト | N42: I | O42: － | P42: － | X42: － | AA42: ー | AI42: ー | AR42: － | AS42: ー | AT42: ー | AU42: － | AY42: ー
B43: 4 | K43: テキスト | N43: O | O43: ● | P43: － | T43: － | X43: Password | AA43: ー | AI43: ー | AR43: － | AS43: ー | AT43: ー | AU43: － | AY43: ー
B44: 5 | K44: EditText | N44: I | O44: － | P44: － | T44: － | X44: － | AA44: ー | AI44: ー | AR44: － | AS44: ー | AT44: ー | AU44: － | AY44: ー
B45: 6 | K45: ボタン | N45: I | O45: ● | P45: － | T45: － | X45: Login | AA45: ー | AI45: Enable | AR45: － | AS45: ー | AT45: ー | AU45: － | AY45: ー | BC45: Login-01/EmployeeMaster

Sheet テンプレート
A1: システム名 | K1: システム種別 | W1: =IF(表紙!W1="","",表紙!W1) -> 基本設計書 | AP1: 作成者 | AT1: 作成日 | AY1: 更新者 | BC1: 更新日 | BH1: 版数
A2: =IF(表紙!A2="","",表紙!A2) -> POSサーバー | K2: =IF(表紙!K2="","",表紙!K2) -> POSサーバ | AP2: =IF(表紙!AP2="","",表紙!AP2) -> SonMNT | AT2: =IF(表紙!AT2="","",表紙!AT2) -> 45477 | AY2: =IF(表紙!AY2="","",表紙!AY2) -> SonMNT | BC2: =IF(表紙!BC2="","",表紙!BC2) -> 45477 | BH2: =IF(表紙!BH2="","",表紙!BH2) -> 0.1
A4: 機能カテゴリ | H4: =IF(表紙!H4="","",表紙!H4) -> 95_セットマッチ設定 | U4: 項目 | Z4: =IF(表紙!Z4="","",表紙!Z4) -> 概要設計 | AP4: =MID(CELL("filename",A1),FIND("]",CELL("filename",A1))+1,255) -> テンプレート
AX12: `
