Workbook

Sheet 表紙
A1: システム名 | K1: システム種別 | W1: 基本設計書 | AP1: 作成者 | AT1: 作成日 | AY1: 更新者 | BC1: 更新日 | BH1: 版数
A2: POSサーバー | K2: POSサーバー | AP2: =改訂履歴!$H$11 -> DuNT | AT2: =改訂履歴!$B$11 -> 45435 | AY2: =LOOKUP(2,1/(改訂履歴!H11:H30000<>""),改訂履歴!H11:H30000) -> LoiLV | BC2: =LOOKUP(2,1/(改訂履歴!B11:B30000<>""),改訂履歴!B11:B30000) -> 45446 | BH2: =LOOKUP(2,1/(改訂履歴!O11:O30000<>""),改訂履歴!O11:O30000) -> 0.2
A4: 機能カテゴリ | H4: 39_WAONポイントN倍設定 | U4: 項目 | Z4: 概要設計書 | AP4: {=RIGHT(CELL("filename",$A$1),LEN(CELL("filename",$A$1))-FIND("]",CELL("filename",$A$1)))} -> 表紙
L16: POSサーバーの基本設計書
L24: =K2&"/"&H4&"/"&Z4 -> POSサーバー/39_WAONポイントN倍設定/概要設計書
Q44: 承認日 | AA44: 承認者 | AQ44: 版数

Sheet 改訂履歴
A1: システム名 | K1: システム種別 | W1: =IF(表紙!W1="","",表紙!W1) -> 基本設計書 | AP1: 作成者 | AT1: 作成日 | AY1: 更新者 | BC1: 更新日 | BH1: 版数
A2: =IF(表紙!A2="","",表紙!A2) -> POSサーバー | K2: =IF(表紙!K2="","",表紙!K2) -> POSサーバー | AP2: =IF(表紙!AP2="","",表紙!AP2) -> DuNT | AT2: =IF(表紙!AT2="","",表紙!AT2) -> 45435 | AY2: =IF(表紙!AY2="","",表紙!AY2) -> LoiLV | BC2: =IF(表紙!BC2="","",表紙!BC2) -> 45446 | BH2: =IF(表紙!BH2="","",表紙!BH2) -> 0.2
A4: 機能カテゴリ | H4: =IF(表紙!H4="","",表紙!H4) -> 39_WAONポイントN倍設定 | U4: 項目 | Z4: =IF(表紙!Z4="","",表紙!Z4) -> 概要設計書 | AP4: {=RIGHT(CELL("filename",$A$1),LEN(CELL("filename",$A$1))-FIND("]",CELL("filename",$A$1)))} -> 改訂履歴
B8: ■改訂履歴
B10: 更新日 | H10: 更新者 | O10: 版数 | S10: 更新内容 | AX10: 承認日 | BD10: 承認者
B11: 45435 | H11: DuNT | O11: 0.1 | S11: 新規作成
B13: 45446 | H13: LoiLV | O13: 0.2 | S13: 2024年5月30日のコメントによる更新

Sheet 業務フロー凡例
A1: システム名 | K1: システム種別 | W1: =IF(表紙!W1="","",表紙!W1) -> 基本設計書 | AP1: 作成者 | AT1: 作成日 | AY1: 更新者 | BC1: 更新日 | BH1: 版数
A2: =IF(表紙!A2="","",表紙!A2) -> POSサーバー | K2: =IF(表紙!K2="","",表紙!K2) -> POSサーバー | AP2: =IF(表紙!AP2="","",表紙!AP2) -> DuNT | AT2: 45084 | AY2: =IF(表紙!AY2="","",表紙!AY2) -> LoiLV | BC2: =IF(表紙!BC2="","",表紙!BC2) -> 45446 | BH2: =IF(表紙!BH2="","",表紙!BH2) -> 0.2
A4: 機能カテゴリ | H4: =IF(表紙!H4="","",表紙!H4) -> 39_WAONポイントN倍設定 | U4: 項目 | Z4: =IF(表紙!Z4="","",表紙!Z4) -> 概要設計書 | AP4: {=RIGHT(CELL("filename",$A$1),LEN(CELL("filename",$A$1))-FIND("]",CELL("filename",$A$1)))} -> 業務フロー凡例
B7: ●1_レジ内
B22: ●1_レジ周辺機器
B42: ●外部連携

Sheet 機能概要説明
A1: システム名 | K1: システム種別 | W1: =IF(表紙!W1="","",表紙!W1) -> 基本設計書 | AP1: 作成者 | AT1: 作成日 | AY1: 更新者 | BC1: 更新日 | BH1: 版数
A2: =IF(表紙!A2="","",表紙!A2) -> POSサーバー | K2: =IF(表紙!K2="","",表紙!K2) -> POSサーバー | AP2: =IF(表紙!AP2="","",表紙!AP2) -> DuNT | AT2: =IF(表紙!AT2="","",表紙!AT2) -> 45435 | AY2: =IF(表紙!AY2="","",表紙!AY2) -> LoiLV | BC2: =IF(表紙!BC2="","",表紙!BC2) -> 45446 | BH2: =IF(表紙!BH2="","",表紙!BH2) -> 0.2
A4: 機能カテゴリ | H4: =IF(表紙!H4="","",表紙!H4) -> 39_WAONポイントN倍設定 | U4: 項目 | Z4: =IF(表紙!Z4="","",表紙!Z4) -> 概要設計書 | AP4: {=RIGHT(CELL("filename",$A$1),LEN(CELL("filename",$A$1))-FIND("]",CELL("filename",$A$1)))} -> 機能概要説明
BM7: =IF(BM6=50,1,BM6+1) -> 1
B8: システム権限を持つアカウントのみがこの機能を使用する権利を持っている。 | BM8: =IF(BM7=50,1,BM7+1) -> 2
B9: WAONカード利用200円(税込)ごとにWAONポイントN倍設定 | BM9: =IF(BM8=50,1,BM8+1) -> 3
BM10: =IF(BM9=50,1,BM9+1) -> 4
BM11: =IF(BM10=50,1,BM10+1) -> 5
BM12: =IF(BM11=50,1,BM11+1) -> 6
BM13: =IF(BM12=50,1,BM12+1) -> 7
BM14: =IF(BM13=50,1,BM13+1) -> 8
BM15: =IF(BM14=50,1,BM14+1) -> 9
BM16: =IF(BM15=50,1,BM15+1) -> 10
BM17: =IF(BM16=50,1,BM16+1) -> 11
BM18: =IF(BM17=50,1,BM17+1) -> 12
BM19: =IF(BM18=50,1,BM18+1) -> 13
BM20: =IF(BM19=50,1,BM19+1) -> 14
BM21: =IF(BM20=50,1,BM20+1) -> 15
... BM57: =IF(BM56=50,1,BM56+1) -> 1

Sheet 機能概要
A1: システム名 | K1: システム種別 | W1: =IF(表紙!W1="","",表紙!W1) -> 基本設計書 | AP1: 作成者 | AT1: 作成日 | AY1: 更新者 | BC1: 更新日 | BH1: 版数
A2: =IF(表紙!A2="","",表紙!A2) -> POSサーバー | K2: =IF(表紙!K2="","",表紙!K2) -> POSサーバー | AP2: =IF(表紙!AP2="","",表紙!AP2) -> DuNT | AT2: =IF(表紙!AT2="","",表紙!AT2) -> 45435 | AY2: =IF(表紙!AY2="","",表紙!AY2) -> LoiLV | BC2: =IF(表紙!BC2="","",表紙!BC2) -> 45446 | BH2: =IF(表紙!BH2="","",表紙!BH2) -> 0.2
A4: 機能カテゴリ | H4: =IF(表紙!H4="","",表紙!H4) -> 39_WAONポイントN倍設定 | U4: 項目 | Z4: =IF(表紙!Z4="","",表紙!Z4) -> 概要設計書 | AP4: {=RIGHT(CELL("filename",$A$1),LEN(CELL("filename",$A$1))-FIND("]",CELL("filename",$A$1)))} -> 機能概要
B7: 39_WAONポイントN倍設定
BM8: =IF(BM7=50,1,BM7+1) -> 1
BM9: =IF(BM8=50,1,BM8+1) -> 2
BM10: =IF(BM9=50,1,BM9+1) -> 3
BM11: =IF(BM10=50,1,BM10+1) -> 4
BM12: =IF(BM11=50,1,BM11+1) -> 5
BM13: =IF(BM12=50,1,BM12+1) -> 6
BM14: =IF(BM13=50,1,BM13+1) -> 7
BM15: =IF(BM14=50,1,BM14+1) -> 8
BM16: =IF(BM15=50,1,BM15+1) -> 9
BM17: =IF(BM16=50,1,BM16+1) -> 10
BM18: =IF(BM17=50,1,BM17+1) -> 11
BM19: =IF(BM18=50,1,BM18+1) -> 12
... BM21: =IF(BM20=50,1,BM20+1) -> 14
BM23: =IF(BM21=50,1,BM21+1) -> 15
BM24: =IF(BM23=50,1,BM23+1) -> 16
BM25: =IF(BM24=50,1,BM24+1) -> 17
BM26: =IF(BM25=50,1,BM25+1) -> 18
BM27: =IF(BM26=50,1,BM26+1) -> 19
BM28: =IF(BM27=50,1,BM27+1) -> 20
BM29: =IF(BM28=50,1,BM28+1) -> 21
BM30: =IF(BM29=50,1,BM29+1) -> 22
BM31: =IF(BM30=50,1,BM30+1) -> 23
BM32: =IF(BM31=50,1,BM31+1) -> 24
BM33: =IF(BM32=50,1,BM32+1) -> 25
BM34: =IF(BM33=50,1,BM33+1) -> 26
BM35: =IF(BM34=50,1,BM34+1) -> 27
BM36: =IF(BM35=50,1,BM35+1) -> 28
B37: FC3901_WAONポイントN倍編集機能 | BM37: =IF(BM36=50,1,BM36+1) -> 29
BM38: =IF(BM37=50,1,BM37+1) -> 30
BM39: =IF(BM38=50,1,BM38+1) -> 31
BM40: =IF(BM39=50,1,BM39+1) -> 32
BM41: =IF(BM40=50,1,BM40+1) -> 33
BM42: =IF(BM41=50,1,BM41+1) -> 34
BM43: =IF(BM42=50,1,BM42+1) -> 35
BM44: =IF(BM43=50,1,BM43+1) -> 36
BM45: =IF(BM44=50,1,BM44+1) -> 37
...

Sheet 画面設計書
A1: システム名 | K1: システム種別 | W1: =IF([1]表紙!W1="","",[1]表紙!W1) -> 基本設計書 | AP1: 作成者 | AT1: 作成日 | AY1: 更新者 | BC1: 更新日 | BH1: 版数
A2: =IF([1]表紙!A2="","",[1]表紙!A2) -> POSサーバー | K2: =IF([1]表紙!K2="","",[1]表紙!K2) -> POSサーバー | AP2: =IF([1]表紙!AP2="","",[1]表紙!AP2) -> DuNT | AT2: =IF([1]表紙!AT2="","",[1]表紙!AT2) -> 45435 | AY2: =IF([1]表紙!AY2="","",[1]表紙!AY2) -> LoiLV | BC2: =IF([1]表紙!BC2="","",[1]表紙!BC2) -> 45446 | BH2: =IF([1]表紙!BH2="","",[1]表紙!BH2) -> 0.2
A4: 機能カテゴリ | H4: =IF([1]表紙!H4="","",[1]表紙!H4) -> 39_WAONポイントN倍設定 | U4: 項目 | Z4: =IF([1]表紙!Z4="","",[1]表紙!Z4) -> 概要設計書 | AP4: =RIGHT(CELL("filename",$A$1),LEN(CELL("filename",$A$1))-FIND("]",CELL("filename",$A$1))) -> 画面設計書
B7: ■ログイン画面のイメージ
B35: ■画面項目定義
B37: 画面項目ID | D37: 項目 | K37: タイプ | N37: I/O | O37: 多言語対象 | P37: アウトプット | AR37: インプット | BC37: 備考
P38: マッピングデータ | X38: 初期値 | AA38: 表示コントロール | AI38: Control enable | AR38: 必須 | AS38: 数字 | AT38: 文字 | AU38: マッピングデータ
P39: API名 | T39: 項目 | AU39: API名 | AY39: 項目
B40: 1 | K40: テキスト | N40: － | O40: ● | P40: － | T40: － | X40: Android POS Control | AA40: ー | AI40: － | AR40: － | AS40: ー | AT40: ー | AU40: － | AY40: ー
B41: 2 | K41: テキスト | N41: O | O41: ● | P41: － | T41: － | X41: User ID | AA41: ー | AI41: ー | AR41: － | AS41: ー | AT41: ー | AU41: － | AY41: ー
B42: 3 | K42: テキスト | N42: I | O42: － | P42: － | X42: － | AA42: ー | AI42: ー | AR42: － | AS42: ー | AT42: ー | AU42: － | AY42: ー
B43: 4 | K43: テキスト | N43: O | O43: ● | P43: － | T43: － | X43: Password | AA43: ー | AI43: ー | AR43: － | AS43: ー | AT43: ー | AU43: － | AY43: ー
B44: 5 | K44: EditText | N44: I | O44: － | P44: － | T44: － | X44: － | AA44: ー | AI44: ー | AR44: － | AS44: ー | AT44: ー | AU44: － | AY44: ー
B45: 6 | K45: ボタン | N45: I | O45: ● | P45: － | T45: － | X45: Login | AA45: ー | AI45: Enable | AR45: － | AS45: ー | AT45: ー | AU45: － | AY45: ー | BC45: Login-01/EmployeeMaster

Sheet テンプレート
A1: システム名 | K1: システム種別 | W1: =IF(表紙!W1="","",表紙!W1) -> 基本設計書 | AP1: 作成者 | AT1: 作成日 | AY1: 更新者 | BC1: 更新日 | BH1: 版数
A2: =IF(表紙!A2="","",表紙!A2) -> POSサーバー | K2: =IF(表紙!K2="","",表紙!K2) -> POSサーバー | AP2: =IF(表紙!AP2="","",表紙!AP2) -> DuNT | AT2: =IF(表紙!AT2="","",表紙!AT2) -> 45435 | AY2: =IF(表紙!AY2="","",表紙!AY2) -> LoiLV | BC2: =IF(表紙!BC2="","",表紙!BC2) -> 45446 | BH2: =IF(表紙!BH2="","",表紙!BH2) -> 0.2
A4: 機能カテゴリ | H4: =IF(表紙!H4="","",表紙!H4) -> 39_WAONポイントN倍設定 | U4: 項目 | Z4: =IF(表紙!Z4="","",表紙!Z4) -> 概要設計書 | AP4: =MID(CELL("filename",A1),FIND("]",CELL("filename",A1))+1,255) -> テンプレート
AX12: `
