Workbook

Sheet 表紙
A1: システム名 | K1: システム種別 | W1: 基本設計書 | AP1: 作成者 | AT1: 作成日 | AY1: 更新者 | BC1: 更新日 | BH1: 版数
A2: POSサーバー | K2: POSサーバ | AP2: =改訂履歴!$H$11 -> DuNT | AT2: =改訂履歴!$B$11 -> 45404 | AY2: =LOOKUP(2,1/(改訂履歴!H11:H30000<>""),改訂履歴!H11:H30000) -> AnhNM | BC2: =LOOKUP(2,1/(改訂履歴!B11:B30000<>""),改訂履歴!B11:B30000) -> 45555 | BH2: =LOOKUP(2,1/(改訂履歴!O11:O30000<>""),改訂履歴!O11:O30000) -> 0.31
A4: 機能カテゴリ | H4: 01_商品管理 | U4: 項目 | Z4: 概要設計 | AP4: {=RIGHT(CELL("filename",$A$1),LEN(CELL("filename",$A$1))-FIND("]",CELL("filename",$A$1)))} -> 表紙
L16: POSサーバーの基本設計書
L24: =K2&"/"&H4&"/"&Z4 -> POSサーバ/01_商品管理/概要設計
Q44: 承認日 | AA44: 承認者 | AQ44: 版数

Sheet 改訂履歴
A1: システム名 | K1: システム種別 | W1: =IF(表紙!W1="","",表紙!W1) -> 基本設計書 | AP1: 作成者 | AT1: 作成日 | AY1: 更新者 | BC1: 更新日 | BH1: 版数
A2: =IF(表紙!A2="","",表紙!A2) -> POSサーバー | K2: =IF(表紙!K2="","",表紙!K2) -> POSサーバ | AP2: =IF(表紙!AP2="","",表紙!AP2) -> DuNT | AT2: =IF(表紙!AT2="","",表紙!AT2) -> 45404 | AY2: =IF(表紙!AY2="","",表紙!AY2) -> AnhNM | BC2: =IF(表紙!BC2="","",表紙!BC2) -> 45555 | BH2: =IF(表紙!BH2="","",表紙!BH2) -> 0.31
A4: 機能カテゴリー | H4: =IF(表紙!H4="","",表紙!H4) -> 01_商品管理 | U4: 項目 | Z4: =IF(表紙!Z4="","",表紙!Z4) -> 概要設計 | AP4: {=RIGHT(CELL("filename",$A$1),LEN(CELL("filename",$A$1))-FIND("]",CELL("filename",$A$1)))} -> 改訂履歴
B8: ■改訂履歴
B10: 更新日 | H10: 更新者 | O10: 版数 | S10: 更新内容 | AX10: 承認日 | BD10: 承認者
B11: 45404 | H11: DuNT | O11: 0.1 | S11: 新規
B13: 45406 | H13: DuNT | O13: 0.2 | S13: 2024/04/24より更新
S14: 機能概要説明シートの新規作成
B15: 45419 | H15: DuNT | O15: 0.21 | S15: 2024/05/02会議内容による更新
B17: 45428 | H17: TuyenNH | O17: 0.22 | S17: 2024年05月15日のコメントによる更新
B19: 45432 | H19: TuyenNH | O19: 0.23 | S19: 2024年05月17日のコメントによる更新
B21: 45428 | H21: TuyenNH | O21: 0.24 | S21: 2024年06月26日のコメントによる更新
B23: 45475 | H23: TinNH | O23: 0.25 | S23: 2024年06月27日の議事録による更新
B25: 45476 | H25: TinNH | O25: 0.26 | S25: 2024年06月27日の議事録による更新
B27: 45478 | H27: TinNH | O27: 0.27 | S27: 2024年07月03日の議事録による更新
B29: 45490 | H29: TuyenNH | O29: 0.28 | S29: 現在、ミックスマッチが1つの商品のみが、確認した後、複数商品に使用できるようになる、
S30: 機能概要シート
B31: 45512 | H31: DUNT | O31: 0.29 | S31: 機能概要
S32: 店舗選択エリアを削除する。 共通印刷帳票コード変更（02_緊急売価変更）
B33: 45553 | H33: TuyenNH | O33: 0.3 | S33: 機能概要
S34: 特売検索機能を追加
B35: 45555 | H35: AnhNM | O35: 0.31 | S35: 機能概要
S36: QA#19287による更新

Sheet 業務フロー
A1: システム名 | K1: システム種別 | W1: =IF(表紙!W1="","",表紙!W1) -> 基本設計書 | AP1: 作成者 | AT1: 作成日 | AY1: 更新者 | BC1: 更新日 | BH1: 版数
A2: =IF(表紙!A2="","",表紙!A2) -> POSサーバー | K2: =IF(表紙!K2="","",表紙!K2) -> POSサーバ | AP2: =IF(表紙!AP2="","",表紙!AP2) -> DuNT | AT2: 45084 | AY2: =IF(表紙!AY2="","",表紙!AY2) -> AnhNM | BC2: =IF(表紙!BC2="","",表紙!BC2) -> 45555 | BH2: =IF(表紙!BH2="","",表紙!BH2) -> 0.31
A4: 機能カテゴリー | H4: =IF(表紙!H4="","",表紙!H4) -> 01_商品管理 | U4: 項目 | Z4: =IF(表紙!Z4="","",表紙!Z4) -> 概要設計 | AP4: {=RIGHT(CELL("filename",$A$1),LEN(CELL("filename",$A$1))-FIND("]",CELL("filename",$A$1)))} -> 業務フロー
B7: ●1_自動釣銭機
B22: ●1_レジ周辺機器
B42: ●外部連携

Sheet 機能概要説明
A1: システム名 | K1: システム種別 | W1: =IF(表紙!W1="","",表紙!W1) -> 基本設計書 | AP1: 作成者 | AT1: 作成日 | AY1: 更新者 | BC1: 更新日 | BH1: 版数
A2: =IF(表紙!A2="","",表紙!A2) -> POSサーバー | K2: =IF(表紙!K2="","",表紙!K2) -> POSサーバ | AP2: =IF(表紙!AP2="","",表紙!AP2) -> DuNT | AT2: =IF(表紙!AT2="","",表紙!AT2) -> 45404 | AY2: =IF(表紙!AY2="","",表紙!AY2) -> AnhNM | BC2: =IF(表紙!BC2="","",表紙!BC2) -> 45555 | BH2: =IF(表紙!BH2="","",表紙!BH2) -> 0.31
A4: 機能カテゴリ | H4: =IF(表紙!H4="","",表紙!H4) -> 01_商品管理 | U4: 項目 | Z4: =IF(表紙!Z4="","",表紙!Z4) -> 概要設計 | AP4: =MID(CELL("filename",A1),FIND("]",CELL("filename",A1))+1,255) -> 機能概要説明
C7: 商品管理機能は、
D8: ・商品情報詳細をビューする。
D9: ・1, 7, 8 定番売価変更が可能
D10: ・当日の緊急売価を変更する。
D11: ・特売売価設定を新規作成・編集する
D12: ・ミックスマッチ新規・編集機能

Sheet 機能概要
K1: システム種別 | W1: =IF(表紙!W1="","",表紙!W1) -> 基本設計書 | AP1: 作成者 | AT1: 作成日 | AY1: 更新者 | BC1: 更新日 | BH1: 版数
A2: =IF(表紙!A2="","",表紙!A2) -> POSサーバー | K2: =IF(表紙!K2="","",表紙!K2) -> POSサーバ | AP2: =IF(表紙!AP2="","",表紙!AP2) -> DuNT | AT2: =IF(表紙!AT2="","",表紙!AT2) -> 45404 | AY2: =IF(表紙!AY2="","",表紙!AY2) -> AnhNM | BC2: =IF(表紙!BC2="","",表紙!BC2) -> 45555 | BH2: =IF(表紙!BH2="","",表紙!BH2) -> 0.31
A4: 機能カテゴリ | H4: =IF(表紙!H4="","",表紙!H4) -> 01_商品管理 | U4: 項目 | Z4: =IF(表紙!Z4="","",表紙!Z4) -> 概要設計 | AP4: {=RIGHT(CELL("filename",$A$1),LEN(CELL("filename",$A$1))-FIND("]",CELL("filename",$A$1)))} -> 機能概要
B7: 01_商品管理
B16: FC0101_商品管理機能 | BM16: =IF(BM15=50,1,BM15+1) -> 1
BM17: =IF(BM16=50,1,BM16+1) -> 2
BM18: =IF(BM17=50,1,BM17+1) -> 3
BM19: =IF(BM18=50,1,BM18+1) -> 4
BM20: =IF(BM19=50,1,BM19+1) -> 5
BM21: =IF(BM20=50,1,BM20+1) -> 6
BM22: =IF(BM21=50,1,BM21+1) -> 7
BM23: =IF(BM22=50,1,BM22+1) -> 8
BM24: =IF(BM23=50,1,BM23+1) -> 9
BM25: =IF(BM24=50,1,BM24+1) -> 10
BM26: =IF(BM25=50,1,BM25+1) -> 11
BM27: =IF(BM26=50,1,BM26+1) -> 12
BM28: =IF(BM27=50,1,BM27+1) -> 13
... BM78: =IF(BM77=50,1,BM77+1) -> 13
B79: FC0102_商品管理（詳細）設定機能 | BM79: =IF(BM78=50,1,BM78+1) -> 14
BM80: =IF(BM79=50,1,BM79+1) -> 15
BM81: =IF(BM80=50,1,BM80+1) -> 16
BM82: =IF(BM81=50,1,BM81+1) -> 17
BM83: =IF(BM82=50,1,BM82+1) -> 18
BM84: =IF(BM83=50,1,BM83+1) -> 19
BM85: =IF(BM84=50,1,BM84+1) -> 20
BM86: =IF(BM85=50,1,BM85+1) -> 21
BM87: =IF(BM86=50,1,BM86+1) -> 22
BM88: =IF(BM87=50,1,BM87+1) -> 23
BM89: =IF(BM88=50,1,BM88+1) -> 24
BM90: =IF(BM89=50,1,BM89+1) -> 25
BM91: =IF(BM90=50,1,BM90+1) -> 26
... BM93: =IF(BM92=50,1,BM92+1) -> 28
BM94: =IF(BM93=50,1,BM93+1) -> 29 | BP94: 管理者権限
BM95: =IF(BM94=50,1,BM94+1) -> 30
BM96: =IF(BM95=50,1,BM95+1) -> 31
BM97: =IF(BM96=50,1,BM96+1) -> 32
BM98: =IF(BM97=50,1,BM97+1) -> 33
BM99: =IF(BM98=50,1,BM98+1) -> 34
BM100: =IF(BM99=50,1,BM99+1) -> 35
BM101: =IF(BM100=50,1,BM100+1) -> 36
...

Sheet 現在売価
A1: システム名 | K1: システム種別 | W1: =IF(表紙!W1="","",表紙!W1) -> 基本設計書 | AP1: 作成者 | AT1: 作成日 | AY1: 更新者 | BC1: 更新日 | BH1: 版数
A2: =IF(表紙!A2="","",表紙!A2) -> POSサーバー | K2: =IF(表紙!K2="","",表紙!K2) -> POSサーバ | AP2: =IF(表紙!AP2="","",表紙!AP2) -> DuNT | AT2: =IF(表紙!AT2="","",表紙!AT2) -> 45404 | AY2: =IF(表紙!AY2="","",表紙!AY2) -> AnhNM | BC2: =IF(表紙!BC2="","",表紙!BC2) -> 45555 | BH2: =IF(表紙!BH2="","",表紙!BH2) -> 0.31
A4: 機能カテゴリ | H4: =IF(表紙!H4="","",表紙!H4) -> 01_商品管理 | U4: 項目 | Z4: =IF(表紙!Z4="","",表紙!Z4) -> 概要設計 | AP4: =MID(CELL("filename",A1),FIND("]",CELL("filename",A1))+1,255) -> 現在売価
B7: ドロップダウン項目のデータ取得
C10: 事項 | G10: カテゴリ値引なし | L10: カテゴリ値引 | S10: 特売設定 | W10: 特売設定＋カテゴリ値引 | AD10: 緊急売価変更 | AI10: 緊急売価変更＋カテゴリ値引 | AQ10: 特売設定＋緊急売価変更 | AY10: 特売設定＋カテゴリ値引＋緊急売価変更
C11: 現在売価 | G11: 定番売価 | L11: 定番売価 - カテゴリ値引 | S11: 特売売価 | W11: 特売－カテゴリ値引 | AD11: 緊急売価 | AI11: 緊急売価－カテゴリ値引 | AQ11: 緊急売価 | AY11: 緊急売価－カテゴリ値引
AX12: `

Sheet 画面設計書
A1: システム名 | K1: システム種別 | W1: =IF(表紙!W1="","",表紙!W1) -> 基本設計書 | AP1: 作成者 | AT1: 作成日 | AY1: 更新者 | BC1: 更新日 | BH1: 版数
A2: =IF(表紙!A2="","",表紙!A2) -> POSサーバー | K2: =IF(表紙!K2="","",表紙!K2) -> POSサーバ | AP2: =IF(表紙!AP2="","",表紙!AP2) -> DuNT | AT2: =IF(表紙!AT2="","",表紙!AT2) -> 45404 | AY2: =IF(表紙!AY2="","",表紙!AY2) -> AnhNM | BC2: =IF(表紙!BC2="","",表紙!BC2) -> 45555 | BH2: =IF(表紙!BH2="","",表紙!BH2) -> 0.31
A4: 機能カテゴリ | H4: =IF(表紙!H4="","",表紙!H4) -> 01_商品管理 | U4: 項目 | Z4: =IF(表紙!Z4="","",表紙!Z4) -> 概要設計 | AP4: =MID(CELL("filename",A1),FIND("]",CELL("filename",A1))+1,255) -> 画面設計書
B7: ■ログイン画面のイメージ
B35: ■画面項目定義
B37: 画面項目ID | D37: 項目 | K37: タイプ | N37: I/O | O37: 多言語対象 | P37: 出力 | AR37: インプット | BC37: 備考
P38: マッピングデータ | X38: 初期値 | AA38: 表示コントロール | AI38: Control enable | AR38: 必須 | AS38: 数字 | AT38: 桁 | AU38: マッピングデータ
P39: API名 | T39: 項目 | AU39: API名 | AY39: 項目
B40: 1 | K40: テキスト | N40: － | O40: ● | P40: － | T40: － | X40: Android POS Control | AA40: ー | AI40: － | AR40: － | AS40: ー | AT40: ー | AU40: － | AY40: ー
B41: 2 | K41: テキスト | N41: O | O41: ● | P41: － | T41: － | X41: User ID | AA41: ー | AI41: ー | AR41: － | AS41: ー | AT41: ー | AU41: － | AY41: ー
B42: 3 | K42: テキスト | N42: I | O42: － | P42: － | X42: － | AA42: ー | AI42: ー | AR42: － | AS42: ー | AT42: ー | AU42: － | AY42: ー
B43: 4 | K43: テキスト | N43: O | O43: ● | P43: － | T43: － | X43: Password | AA43: ー | AI43: ー | AR43: － | AS43: ー | AT43: ー | AU43: － | AY43: ー
B44: 5 | K44: EditText | N44: I | O44: － | P44: － | T44: － | X44: － | AA44: ー | AI44: ー | AR44: － | AS44: ー | AT44: ー | AU44: － | AY44: ー
B45: 6 | K45: ボタン | N45: I | O45: ● | P45: － | T45: － | X45: Login | AA45: ー | AI45: 有効 | AR45: － | AS45: ー | AT45: ー | AU45: － | AY45: ー | BC45: Login-01/EmployeeMaster

Sheet 参照
A1: システム名 | K1: システム種別 | W1: =IF(表紙!W1="","",表紙!W1) -> 基本設計書 | AP1: 作成者 | AT1: 作成日 | AY1: 更新者 | BC1: 更新日 | BH1: 版数
A2: =IF(表紙!A2="","",表紙!A2) -> POSサーバー | K2: =IF(表紙!K2="","",表紙!K2) -> POSサーバ | AP2: =IF(表紙!AP2="","",表紙!AP2) -> DuNT | AT2: =IF(表紙!AT2="","",表紙!AT2) -> 45404 | AY2: =IF(表紙!AY2="","",表紙!AY2) -> AnhNM | BC2: =IF(表紙!BC2="","",表紙!BC2) -> 45555 | BH2: =IF(表紙!BH2="","",表紙!BH2) -> 0.31
A4: 機能カテゴリ | H4: =IF(表紙!H4="","",表紙!H4) -> 01_商品管理 | U4: 項目 | Z4: =IF(表紙!Z4="","",表紙!Z4) -> 概要設計 | AP4: =MID(CELL("filename",A1),FIND("]",CELL("filename",A1))+1,255) -> 参照
B7: ドロップダウン項目のデータ取得
AX12: `
