Workbook

Sheet 表紙
A1: システム名 | K1: システム種別 | W1: 基本設計書 | AP1: 作成者 | AT1: 作成日 | AY1: 更新者 | BC1: 更新日 | BH1: 版数
A2: POSサーバー | K2: POSサーバ | AP2: =改訂履歴!$H$11 -> SonMNT | AT2: =改訂履歴!$B$11 -> 45426 | AY2: =LOOKUP(2,1/(改訂履歴!H11:H30003<>""),改訂履歴!H11:H30003) -> TinNH | BC2: =LOOKUP(2,1/(改訂履歴!B11:B30003<>""),改訂履歴!B11:B30003) -> 45502 | BH2: =LOOKUP(2,1/(改訂履歴!O11:O30003<>""),改訂履歴!O11:O30003) -> 0.2
A4: 機能カテゴリ | H4: 02_緊急売価変更 | U4: 項目 | Z4: 概要設計 | AP4: {=RIGHT(CELL("filename",$A$1),LEN(CELL("filename",$A$1))-FIND("]",CELL("filename",$A$1)))} -> 表紙
L16: POSサーバーの基本設計書
L24: =K2&"/"&H4&"/"&Z4 -> POSサーバ/02_緊急売価変更/概要設計
Q44: 承認日 | AA44: 承認者 | AQ44: 版数

Sheet 改訂履歴
A1: システム名 | K1: システム種別 | W1: =IF(表紙!W1="","",表紙!W1) -> 基本設計書 | AP1: 作成者 | AT1: 作成日 | AY1: 更新者 | BC1: 更新日 | BH1: 版数
A2: =IF(表紙!A2="","",表紙!A2) -> POSサーバー | K2: =IF(表紙!K2="","",表紙!K2) -> POSサーバ | AP2: =IF(表紙!AP2="","",表紙!AP2) -> SonMNT | AT2: =IF(表紙!AT2="","",表紙!AT2) -> 45426 | AY2: =IF(表紙!AY2="","",表紙!AY2) -> TinNH | BC2: =IF(表紙!BC2="","",表紙!BC2) -> 45502 | BH2: =IF(表紙!BH2="","",表紙!BH2) -> 0.2
A4: 機能カテゴリー | H4: =IF(表紙!H4="","",表紙!H4) -> 02_緊急売価変更 | U4: 項目 | Z4: =IF(表紙!Z4="","",表紙!Z4) -> 概要設計 | AP4: {=RIGHT(CELL("filename",$A$1),LEN(CELL("filename",$A$1))-FIND("]",CELL("filename",$A$1)))} -> 改訂履歴
B8: ■改訂履歴
B10: 更新日 | H10: 更新者 | O10: 版数 | S10: 更新内容 | AX10: 承認日 | BD10: 承認者
B11: 45426 | H11: SonMNT | O11: 0.1 | S11: 新規作成
B13: 45428 | H13: TuyenNH | O13: 0.11 | S13: 2024年06月26日のコメントによる更新
B15: 45502 | H15: TinNH | O15: 0.2 | S15: 顧客のバグ#19833による更新
S16: ・現在売価マトリクス追加
S17: ・ページング説明
S18: ・「確定」とESCをタッチした時のバリデーションチェックの説明
S19: ・更新、削除時にPOSとS＆G更新の説明を追加

Sheet 業務フロー
A1: システム名 | K1: システム種別 | W1: =IF(表紙!W1="","",表紙!W1) -> 基本設計書 | AP1: 作成者 | AT1: 作成日 | AY1: 更新者 | BC1: 更新日 | BH1: 版数
A2: =IF(表紙!A2="","",表紙!A2) -> POSサーバー | K2: =IF(表紙!K2="","",表紙!K2) -> POSサーバ | AP2: =IF(表紙!AP2="","",表紙!AP2) -> SonMNT | AT2: 45084 | AY2: =IF(表紙!AY2="","",表紙!AY2) -> TinNH | BC2: =IF(表紙!BC2="","",表紙!BC2) -> 45502 | BH2: =IF(表紙!BH2="","",表紙!BH2) -> 0.2
A4: 機能カテゴリー | H4: =IF(表紙!H4="","",表紙!H4) -> 02_緊急売価変更 | U4: 項目 | Z4: =IF(表紙!Z4="","",表紙!Z4) -> 概要設計 | AP4: {=RIGHT(CELL("filename",$A$1),LEN(CELL("filename",$A$1))-FIND("]",CELL("filename",$A$1)))} -> 業務フロー
B7: ●1_自動釣銭機
B22: ●1_レジ周辺機器
B42: ●外部連携

Sheet 機能概要説明
A1: システム名 | K1: システム種別 | W1: =IF(表紙!W1="","",表紙!W1) -> 基本設計書 | AP1: 作成者 | AT1: 作成日 | AY1: 更新者 | BC1: 更新日 | BH1: 版数
A2: =IF(表紙!A2="","",表紙!A2) -> POSサーバー | K2: =IF(表紙!K2="","",表紙!K2) -> POSサーバ | AP2: =IF(表紙!AP2="","",表紙!AP2) -> SonMNT | AT2: =IF(表紙!AT2="","",表紙!AT2) -> 45426 | AY2: =IF(表紙!AY2="","",表紙!AY2) -> TinNH | BC2: =IF(表紙!BC2="","",表紙!BC2) -> 45502 | BH2: =IF(表紙!BH2="","",表紙!BH2) -> 0.2
A4: 機能カテゴリ | H4: =IF(表紙!H4="","",表紙!H4) -> 02_緊急売価変更 | U4: 項目 | Z4: =IF(表紙!Z4="","",表紙!Z4) -> 概要設計 | AP4: {=RIGHT(CELL("filename",$A$1),LEN(CELL("filename",$A$1))-FIND("]",CELL("filename",$A$1)))} -> 機能概要説明
C7: 緊急売価変更機能により、次のことが可能になる。 | BM7: =IF(BM6=50,1,BM6+1) -> 1
D8: ・複数商品の緊急売価を同時に変更する。（変更日のみ店舗適用） | BM8: =IF(BM7=50,1,BM7+1) -> 2
D9: ・変更日が過ぎると、緊急売価が無効になり、クリアする必要がある。 | BM9: =IF(BM8=50,1,BM8+1) -> 3
BM10: =IF(BM9=50,1,BM9+1) -> 4
BM11: =IF(BM10=50,1,BM10+1) -> 5
BM12: =IF(BM11=50,1,BM11+1) -> 6
BM13: =IF(BM12=50,1,BM12+1) -> 7
BM14: =IF(BM13=50,1,BM13+1) -> 8
BM15: =IF(BM14=50,1,BM14+1) -> 9
BM16: =IF(BM15=50,1,BM15+1) -> 10
BM17: =IF(BM16=50,1,BM16+1) -> 11
BM18: =IF(BM17=50,1,BM17+1) -> 12
BM19: =IF(BM18=50,1,BM18+1) -> 13
BM20: =IF(BM19=50,1,BM19+1) -> 14
BM21: =IF(BM20=50,1,BM20+1) -> 15
... BM57: =IF(BM56=50,1,BM56+1) -> 1

Sheet 機能概要
A1: システム名 | K1: システム種別 | W1: =IF(表紙!W1="","",表紙!W1) -> 基本設計書 | AP1: 作成者 | AT1: 作成日 | AY1: 更新者 | BC1: 更新日 | BH1: 版数
A2: =IF(表紙!A2="","",表紙!A2) -> POSサーバー | K2: =IF(表紙!K2="","",表紙!K2) -> POSサーバ | AP2: =IF(表紙!AP2="","",表紙!AP2) -> SonMNT | AT2: =IF(表紙!AT2="","",表紙!AT2) -> 45426 | AY2: =IF(表紙!AY2="","",表紙!AY2) -> TinNH | BC2: =IF(表紙!BC2="","",表紙!BC2) -> 45502 | BH2: =IF(表紙!BH2="","",表紙!BH2) -> 0.2
A4: 機能カテゴリ | H4: =IF(表紙!H4="","",表紙!H4) -> 02_緊急売価変更 | U4: 項目 | Z4: =IF(表紙!Z4="","",表紙!Z4) -> 概要設計 | AP4: {=RIGHT(CELL("filename",$A$1),LEN(CELL("filename",$A$1))-FIND("]",CELL("filename",$A$1)))} -> 機能概要
B7: 02_緊急売価変更
BM8: =IF(BM7=50,1,BM7+1) -> 1
BM9: =IF(BM8=50,1,BM8+1) -> 2
BM10: =IF(BM9=50,1,BM9+1) -> 3
BM11: =IF(BM10=50,1,BM10+1) -> 4
BM12: =IF(BM11=50,1,BM11+1) -> 5
BM13: =IF(BM12=50,1,BM12+1) -> 6
BM14: =IF(BM13=50,1,BM13+1) -> 7
BM15: =IF(BM14=50,1,BM14+1) -> 8
BM16: =IF(BM15=50,1,BM15+1) -> 9
BM17: =IF(BM16=50,1,BM16+1) -> 10
BM18: =IF(BM17=50,1,BM17+1) -> 11
BM19: =IF(BM18=50,1,BM18+1) -> 12
... BM71: =IF(BM70=50,1,BM70+1) -> 14
BM81: =IF(BM71=50,1,BM71+1) -> 15
B82: FC0202_商品提案機能 | BM82: =IF(BM81=50,1,BM81+1) -> 16
BM83: =IF(BM82=50,1,BM82+1) -> 17
BM84: =IF(BM83=50,1,BM83+1) -> 18
BM85: =IF(BM84=50,1,BM84+1) -> 19
BM86: =IF(BM85=50,1,BM85+1) -> 20
BM87: =IF(BM86=50,1,BM86+1) -> 21
BM88: =IF(BM87=50,1,BM87+1) -> 22
BM89: =IF(BM88=50,1,BM88+1) -> 23
BM90: =IF(BM89=50,1,BM89+1) -> 24
BM91: =IF(BM90=50,1,BM90+1) -> 25
BM92: =IF(BM91=50,1,BM91+1) -> 26
BM93: =IF(BM92=50,1,BM92+1) -> 27
BM94: =IF(BM93=50,1,BM93+1) -> 28
... BM106: =IF(BM105=50,1,BM105+1) -> 40
B107: FC0203_緊急売価一括更新機能 | BM107: =IF(BM106=50,1,BM106+1) -> 41
BM108: =IF(BM107=50,1,BM107+1) -> 42
BM109: =IF(BM108=50,1,BM108+1) -> 43
BM110: =IF(BM109=50,1,BM109+1) -> 44
BM111: =IF(BM110=50,1,BM110+1) -> 45
BM112: =IF(BM111=50,1,BM111+1) -> 46
BM113: =IF(BM112=50,1,BM112+1) -> 47
BM114: =IF(BM113=50,1,BM113+1) -> 48
...

Sheet 画面設計書
A1: システム名 | K1: システム種別 | W1: =IF(表紙!W1="","",表紙!W1) -> 基本設計書 | AP1: 作成者 | AT1: 作成日 | AY1: 更新者 | BC1: 更新日 | BH1: 版数
A2: =IF(表紙!A2="","",表紙!A2) -> POSサーバー | K2: =IF(表紙!K2="","",表紙!K2) -> POSサーバ | AP2: =IF(表紙!AP2="","",表紙!AP2) -> SonMNT | AT2: =IF(表紙!AT2="","",表紙!AT2) -> 45426 | AY2: =IF(表紙!AY2="","",表紙!AY2) -> TinNH | BC2: =IF(表紙!BC2="","",表紙!BC2) -> 45502 | BH2: =IF(表紙!BH2="","",表紙!BH2) -> 0.2
A4: 機能カテゴリ | H4: =IF(表紙!H4="","",表紙!H4) -> 02_緊急売価変更 | U4: 項目 | Z4: =IF(表紙!Z4="","",表紙!Z4) -> 概要設計 | AP4: =MID(CELL("filename",A1),FIND("]",CELL("filename",A1))+1,255) -> 画面設計書
B7: ■ログイン画面のイメージ
B35: ■画面項目定義
B37: 画面項目ID | D37: 項目 | K37: タイプ | N37: I/O | O37: 多言語対象 | P37: 出力 | AR37: インプット | BC37: 備考
P38: マッピングデータ | X38: 初期値 | AA38: 表示コントロール | AI38: Control enable | AR38: 必須 | AS38: 数字 | AT38: 文字 | AU38: マッピングデータ
P39: API名 | T39: 項目 | AU39: API名 | AY39: 項目
B40: 1 | K40: テキスト | N40: － | O40: ● | P40: － | T40: － | X40: Android POS Control | AA40: ー | AI40: － | AR40: － | AS40: ー | AT40: ー | AU40: － | AY40: ー
B41: 2 | K41: テキスト | N41: O | O41: ● | P41: － | T41: － | X41: User ID | AA41: ー | AI41: ー | AR41: － | AS41: ー | AT41: ー | AU41: － | AY41: ー
B42: 3 | K42: テキスト | N42: I | O42: － | P42: － | X42: － | AA42: ー | AI42: ー | AR42: － | AS42: ー | AT42: ー | AU42: － | AY42: ー
B43: 4 | K43: テキスト | N43: O | O43: ● | P43: － | T43: － | X43: Password | AA43: ー | AI43: ー | AR43: － | AS43: ー | AT43: ー | AU43: － | AY43: ー
B44: 5 | K44: EditText | N44: I | O44: － | P44: － | T44: － | X44: － | AA44: ー | AI44: ー | AR44: － | AS44: ー | AT44: ー | AU44: － | AY44: ー
B45: 6 | K45: ボタン | N45: I | O45: ● | P45: － | T45: － | X45: Login | AA45: ー | AI45: Enable | AR45: － | AS45: ー | AT45: ー | AU45: － | AY45: ー | BC45: Login-01/EmployeeMaster

Sheet 現在売価マトリックス
A1: システム名 | K1: システム種別 | W1: =IF(表紙!W1="","",表紙!W1) -> 基本設計書 | AP1: 作成者 | AT1: 作成日 | AY1: 更新者 | BC1: 更新日 | BH1: 版数
A2: =IF(表紙!A2="","",表紙!A2) -> POSサーバー | K2: =IF(表紙!K2="","",表紙!K2) -> POSサーバ | AP2: =IF(表紙!AP2="","",表紙!AP2) -> SonMNT | AT2: =IF(表紙!AT2="","",表紙!AT2) -> 45426 | AY2: =IF(表紙!AY2="","",表紙!AY2) -> TinNH | BC2: =IF(表紙!BC2="","",表紙!BC2) -> 45502 | BH2: =IF(表紙!BH2="","",表紙!BH2) -> 0.2
A4: 機能カテゴリ | H4: =IF(表紙!H4="","",表紙!H4) -> 02_緊急売価変更 | U4: 項目 | Z4: =IF(表紙!Z4="","",表紙!Z4) -> 概要設計 | AP4: =MID(CELL("filename",A1),FIND("]",CELL("filename",A1))+1,255) -> 現在売価マトリックス
B7: 「現在売価」
C9: 画面に表示される「現在売価」が以下の通り
D11: いいえ | F11: カテゴリ値引 | K11: 特売売価設定 | S11: 緊急売価設定 | Z11: 表示内容
D12: 1 | F12: ‐ | K12: ‐ | S12: ‐ | Z12: 定番売価 | AX12: `
D13: 2 | F13: ‐ | K13: 〇 | S13: ‐ | Z13: 特売売価
D14: 3 | F14: ‐ | K14: 〇 | S14: 〇 | Z14: 緊急売価
D15: 4 | F15: ‐ | K15: ‐ | S15: 〇 | Z15: 緊急売価
D16: 5 | F16: 〇 | K16: ‐ | S16: ‐ | Z16: 定番売価－カテゴリ値引額
D17: 6 | F17: 〇 | K17: 〇 | S17: ‐ | Z17: 特売売価－カテゴリ値引額
D18: 7 | F18: 〇 | K18: ‐ | S18: 〇 | Z18: 緊急売価－カテゴリ値引額
D19: 8 | F19: 〇 | K19: 〇 | S19: 〇 | Z19: 緊急売価－カテゴリ値引額
E21: (「‐」・・・設定なし、「〇」・・・設定あり)

Sheet テンプレート
A1: システム名 | K1: システム種別 | W1: =IF(表紙!W1="","",表紙!W1) -> 基本設計書 | AP1: 作成者 | AT1: 作成日 | AY1: 更新者 | BC1: 更新日 | BH1: 版数
A2: =IF(表紙!A2="","",表紙!A2) -> POSサーバー | K2: =IF(表紙!K2="","",表紙!K2) -> POSサーバ | AP2: =IF(表紙!AP2="","",表紙!AP2) -> SonMNT | AT2: =IF(表紙!AT2="","",表紙!AT2) -> 45426 | AY2: =IF(表紙!AY2="","",表紙!AY2) -> TinNH | BC2: =IF(表紙!BC2="","",表紙!BC2) -> 45502 | BH2: =IF(表紙!BH2="","",表紙!BH2) -> 0.2
A4: 機能カテゴリ | H4: =IF(表紙!H4="","",表紙!H4) -> 02_緊急売価変更 | U4: 項目 | Z4: =IF(表紙!Z4="","",表紙!Z4) -> 概要設計 | AP4: =MID(CELL("filename",A1),FIND("]",CELL("filename",A1))+1,255) -> テンプレート
AX12: `
