Workbook
Name a: #REF!
Name all_workbook: SUBSTITUTE(sheet_name,"["&work_book&"]","")
Name all_workbook: SUBSTITUTE(sheet_name,"["&work_book&"]","")
Name Category: #REF!
Name chuc_nang: #REF!
Name Contract: #REF!
Name DAY: #REF!
Name Excel_BuiltIn__FilterDatabase_1: #REF!
Name First_Day: #REF!
Name KIND: #REF!
Name Level: #REF!
Name LIFECYCLE: #REF!
Name list1: #REF!
Name list3: #REF!
Name ListQT: #REF!
Name Lupack.TenDA: #REF!
Name method: #REF!
Name Method.: #REF!
Name Method_New: #REF!
Name MsgSample2: #N/A
Name nhiem_vu: #REF!
Name Print_Area_MI: #REF!
Name Print_Area_MI___0: #REF!
Name Print_Area_MI___15: #REF!
Name Print_Titles_MI: #REF!
Name Priority: #REF!
Name ProjectList: #REF!
Name QGOAL: #REF!
Name QUY_ĐỊNH_AN_NINH_THÔNG_TIN___DỰ_ÁN_HOKEN: #REF!
Name R_11: #REF!
Name R_12: #REF!
Name R_13: #REF!
Name R_14: #REF!
Name R_15: #REF!
Name R_21: #REF!
Name R_22: #REF!
Name R_23: #REF!
Name R_24: #REF!
Name R_31: #REF!
Name R_32: #REF!
Name R_33: #REF!
Name R_34: #REF!
Name R_35: #REF!
Name R_41: #REF!
Name R_42: #REF!
Name R_43: #REF!
Name R_44: #REF!
Name R_45: #REF!
Name R_46: #REF!
Name R_51: #REF!
Name R_52: #REF!
Name R_53: #REF!
Name R_54: #REF!
Name R_61: #REF!
Name R_62: #REF!
Name R_63: #REF!
Name R_71: #REF!
Name R_72: #REF!
Name R_73: #REF!
Name R_74: #REF!

Sheet 表紙
A1: システム名 | K1: システム種別 | W1: 基本設計書 | AP1: 作成者 | AT1: 作成日 | AY1: 更新者 | BC1: 更新日 | BH1: 版数
A2: ignica POS | K2: POS Server | AP2: =改廃履歴!$H$11 -> Thanh Nguyên | AT2: =改廃履歴!$B$11 -> 45336 | AY2: =LOOKUP(2,1/(改廃履歴!H11:H30000<>""),改廃履歴!H11:H30000) -> Thanh Nguyên | BC2: =LOOKUP(2,1/(改廃履歴!B11:B30000<>""),改廃履歴!B11:B30000) -> 45336 | BH2: =LOOKUP(2,1/(改廃履歴!O11:O30000<>""),改廃履歴!O11:O30000) -> 0.1
A4: 機能カテゴリ | H4: 21_ジャーナル検索機能 | U4: 項目 | Z4: 概要設計 | AP4: {=RIGHT(CELL("filename",$A$1),LEN(CELL("filename",$A$1))-FIND("]",CELL("filename",$A$1)))} -> #VALUE!
L16: 現金専用簡易セルフPOS 基本設計書
L24: =K2&"/"&H4&"/"&Z4 -> POS Server/21_ジャーナル検索機能/概要設計
Q44: 承認日 | AA44: 承認者 | AQ44: 版数

Sheet 改廃履歴
A1: システム名 | K1: システム種別 | W1: =IF(表紙!W1="","",表紙!W1) -> 基本設計書 | AP1: 作成者 | AT1: 作成日 | AY1: 更新者 | BC1: 更新日 | BH1: 版数
A2: =IF(表紙!A2="","",表紙!A2) -> ignica POS | K2: =IF(表紙!K2="","",表紙!K2) -> POS Server | AP2: =IF(表紙!AP2="","",表紙!AP2) -> Thanh Nguyên | AT2: =IF(表紙!AT2="","",表紙!AT2) -> 45336 | AY2: =IF(表紙!AY2="","",表紙!AY2) -> Thanh Nguyên | BC2: =IF(表紙!BC2="","",表紙!BC2) -> 45336 | BH2: =IF(表紙!BH2="","",表紙!BH2) -> 0.1
A4: 機能カテゴリ | H4: =IF(表紙!H4="","",表紙!H4) -> 21_ジャーナル検索機能 | U4: 項目 | Z4: =IF(表紙!Z4="","",表紙!Z4) -> 概要設計 | AP4: {=RIGHT(CELL("filename",$A$1),LEN(CELL("filename",$A$1))-FIND("]",CELL("filename",$A$1)))} -> #VALUE!
B8: ■改廃履歴
B10: 更新日付 | H10: 更新者 | O10: 版数 | S10: 変更内容 | AX10: 承認日付 | BD10: 承認者
B11: 45336 | H11: Thanh Nguyên | O11: 0.1 | S11: 新規作成

Sheet 業務フロー凡例
A1: システム名 | K1: システム種別 | W1: 基本設計書 | AP1: 作成者 | AT1: 作成日 | AY1: 更新者 | BC1: 更新日 | BH1: 版数
A2: 現金専用簡易セルフPOS | K2: POSサーバー | AP2: Thanh Nguyên | AT2: 45084 | AY2: Thanh Nguyên | BC2: 45272 | BH2: 0.2
A4: 機能カテゴリ | H4: 全体 | U4: 項目 | Z4: 業務フロー | AP4: {=RIGHT(CELL("filename",$A$1),LEN(CELL("filename",$A$1))-FIND("]",CELL("filename",$A$1)))} -> #VALUE!
B7: ●1_レジ内
B22: ●1_レジ周辺機器
B42: ●外部連携

Sheet 業務フロー
A1: システム名 | K1: システム種別 | W1: =IF(表紙!W1="","",表紙!W1) -> 基本設計書 | AP1: 作成者 | AT1: 作成日 | AY1: 更新者 | BC1: 更新日 | BH1: 版数
A2: =IF(表紙!A2="","",表紙!A2) -> ignica POS | K2: =IF(表紙!K2="","",表紙!K2) -> POS Server | AP2: =IF(表紙!AP2="","",表紙!AP2) -> Thanh Nguyên | AT2: =IF(表紙!AT2="","",表紙!AT2) -> 45336 | AY2: =IF(表紙!AY2="","",表紙!AY2) -> Thanh Nguyên | BC2: =IF(表紙!BC2="","",表紙!BC2) -> 45336 | BH2: =IF(表紙!BH2="","",表紙!BH2) -> 0.1
A4: 機能カテゴリ | H4: =IF(表紙!H4="","",表紙!H4) -> 21_ジャーナル検索機能 | U4: 項目 | Z4: =IF(表紙!Z4="","",表紙!Z4) -> 概要設計 | AP4: {=RIGHT(CELL("filename",$A$1),LEN(CELL("filename",$A$1))-FIND("]",CELL("filename",$A$1)))} -> #VALUE!
B7: ●2_7_ジャーナル検索
AM66: ※あいまい検索と レシートNoが From To
AN67: ジャーナルにある文字2のAND条件で検索
AN68: 合計金額で検索。From to

Sheet 機能概要
A1: システム名 | K1: システム種別 | W1: =IF(表紙!W1="","",表紙!W1) -> 基本設計書 | AP1: 作成者 | AT1: 作成日 | AY1: 更新者 | BC1: 更新日 | BH1: 版数
A2: =IF(表紙!A2="","",表紙!A2) -> ignica POS | K2: =IF(表紙!K2="","",表紙!K2) -> POS Server | AP2: =IF(表紙!AP2="","",表紙!AP2) -> Thanh Nguyên | AT2: =IF(表紙!AT2="","",表紙!AT2) -> 45336 | AY2: =IF(表紙!AY2="","",表紙!AY2) -> Thanh Nguyên | BC2: =IF(表紙!BC2="","",表紙!BC2) -> 45336 | BH2: =IF(表紙!BH2="","",表紙!BH2) -> 0.1
A4: 機能カテゴリ | H4: =IF(表紙!H4="","",表紙!H4) -> 21_ジャーナル検索機能 | U4: 項目 | Z4: =IF(表紙!Z4="","",表紙!Z4) -> 概要設計 | AP4: {=RIGHT(CELL("filename",$A$1),LEN(CELL("filename",$A$1))-FIND("]",CELL("filename",$A$1)))} -> #VALUE!
B7: ●X●●_●●●●●

Sheet 画面設計
A1: システム名 | K1: システム種別 | W1: =IF(表紙!W1="","",表紙!W1) -> 基本設計書 | AP1: 作成者 | AT1: 作成日 | AY1: 更新者 | BC1: 更新日 | BH1: 版数
A2: =IF(表紙!A2="","",表紙!A2) -> ignica POS | K2: =IF(表紙!K2="","",表紙!K2) -> POS Server | AP2: =IF(表紙!AP2="","",表紙!AP2) -> Thanh Nguyên | AT2: =IF(表紙!AT2="","",表紙!AT2) -> 45336 | AY2: =IF(表紙!AY2="","",表紙!AY2) -> Thanh Nguyên | BC2: =IF(表紙!BC2="","",表紙!BC2) -> 45336 | BH2: =IF(表紙!BH2="","",表紙!BH2) -> 0.1
A4: 機能カテゴリ | H4: =IF(表紙!H4="","",表紙!H4) -> 21_ジャーナル検索機能 | U4: 項目 | Z4: =IF(表紙!Z4="","",表紙!Z4) -> 概要設計 | AP4: {=RIGHT(CELL("filename",$A$1),LEN(CELL("filename",$A$1))-FIND("]",CELL("filename",$A$1)))} -> #VALUE!

Sheet API一覧
A1: システム名 | K1: システム種別 | W1: =IF(表紙!W1="","",表紙!W1) -> 基本設計書 | AP1: 作成者 | AT1: 作成日 | AY1: 更新者 | BC1: 更新日 | BH1: 版数 | DD1: 作成情報 | DM1: 更新情報
A2: =IF(表紙!A2="","",表紙!A2) -> ignica POS | K2: =IF(表紙!K2="","",表紙!K2) -> POS Server | AP2: =IF(表紙!AP2="","",表紙!AP2) -> Thanh Nguyên | AT2: =IF(表紙!AT2="","",表紙!AT2) -> 45336 | AY2: =IF(表紙!AY2="","",表紙!AY2) -> Thanh Nguyên | BC2: =IF(表紙!BC2="","",表紙!BC2) -> 45336 | BH2: =IF(表紙!BH2="","",表紙!BH2) -> 0.1 | DD2: 作成者 | DG2: NamDT | DM2: 更新者 | DP2: NamDT
DD3: 作成日 | DG3: 45309 | DM3: 更新日 | DP3: 45309
A4: 機能カテゴリ | H4: =IF(表紙!H4="","",表紙!H4) -> 21_ジャーナル検索機能 | U4: 項目 | Z4: =IF(表紙!Z4="","",表紙!Z4) -> 概要設計 | AP4: {=RIGHT(CELL("filename",$A$1),LEN(CELL("filename",$A$1))-FIND("]",CELL("filename",$A$1)))} -> #VALUE!
B8: No. | E8: API | AC8: メソッド | AI8: 認証 | AQ8: 説明 | CM8: 内部レビュー | CU8: Last update | DC8: デプロイ | DL8: MV関東 | DO8: カスミ
B9: プリセット
B10: R001 | E10: pos/v1/receipt/search | AC10: POST | AI10: トーケン | AQ10: 帳票一覧取得
B11: R002 | E11: pos/v1/receipt/employee | AC11: POST | AI11: トーケン | AQ11: 店舗の係員一覧を取得する。
B12: R003 | E12: pos/v1/receipt/choose | AC12: POST | AI12: トーケン | AQ12: 選択された帳票のデータ明細を取得する。

Sheet R001
A1: システム名 | K1: システム種別 | W1: =IF(表紙!W1="","",表紙!W1) -> 基本設計書 | AP1: 作成者 | AT1: 作成日 | AY1: 更新者 | BC1: 更新日 | BH1: 版数 | BU1: メソッド | CJ1: 認証 | CX1: 作成情報 | DG1: 更新情報
A2: =IF(表紙!A2="","",表紙!A2) -> ignica POS | K2: =IF(表紙!K2="","",表紙!K2) -> POS Server | AP2: =IF(表紙!AP2="","",表紙!AP2) -> Thanh Nguyên | AT2: =IF(表紙!AT2="","",表紙!AT2) -> 45336 | AY2: =IF(表紙!AY2="","",表紙!AY2) -> Thanh Nguyên | BC2: =IF(表紙!BC2="","",表紙!BC2) -> 45336 | BH2: =IF(表紙!BH2="","",表紙!BH2) -> 0.1 | BU2: POST | CJ2: Bearer | CX2: 作成者 | DA2: 富士通)今村 | DG2: 更新者 | DJ2: 富士通)今村
CX3: 作成日 | DA3: 44621 | DG3: 更新日 | DJ3: 44638
A4: 機能カテゴリ | H4: =IF(表紙!H4="","",表紙!H4) -> 21_ジャーナル検索機能 | U4: 項目 | Z4: =IF(表紙!Z4="","",表紙!Z4) -> 概要設計 | AP4: {=RIGHT(CELL("filename",$A$1),LEN(CELL("filename",$A$1))-FIND("]",CELL("filename",$A$1)))} -> #VALUE!
B7: pos/v1/receipt/search
B8: リクエスト | BH8: レスポンス<200：OK>
C9: 属性 | P9: Loại | U9: Số từ | Z9: 備考 | AK9: NN | AN9: 例 | BI9: 属性 | BV9: 型 | CA9: 文字数 | CF9: 備考 | CS9: 例
C10: company_code | P10: String | U10: 10 | Z10: 会社番号 | AK10: 〇 | AN10: { | BI10: number_of_record | BV10: Int | CA10: 10 | CF10: 見つかったレコード数 | CS10: {
C11: store_code | P11: String | U11: 10 | Z11: 店舗番号 | AK11: 〇 | AN11: "company_code": "300", | BI11: list_receipt | CF11: 帳票一覧 | CS11: "number_of_record": 2,
C12: start_date | P12: String | U12: 10 | Z12: 開始日 | AN12: "store_code": "048405", | BJ12: company_code | BV12: String | CA12: 10 | CS12: "list_receipt": [
C13: end_date | P13: String | U13: 10 | Z13: 終了日 | AN13: "start_date": "2023-12-01", | BJ13: store_code | BV13: String | CA13: 10 | CS13: {
C14: start_time | P14: String | U14: 8 | Z14: 開始時刻 | AN14: "end_date": "2023-12-31", | BJ14: store_code | BV14: String | CA14: 10 | CS14: "company_code": "300",
C15: end_time | P15: String | U15: 8 | Z15: 終了時刻 | AN15: "start_time": "06:00:00", | BJ15: receipt_create_date | BV15: String | CA15: 10 | CS15: "store_code": "048405",
C16: receipt_no | P16: String | U16: 18 | Z16: 帳票番号 | AN16: "end_time": "12:00:00", | BJ16: receipt_create_time | BV16: String | CA16: 8 | CS16: "instore_code": "901",
C17: employee_code | P17: String | U17: 16 | Z17: 担当者番号 | AN17: "receipt_no": "", | BJ17: receipt_no | BV17: String | CA17: 18 | CS17: "receipt_create_date": "2023-12-12",
C18: limit | P18: Int | U18: 2 | Z18: 必要なレコードの数 | AK18: 〇 | AN18: "employee_code": "", | BJ18: employee_code | BV18: String | CA18: 16 | CS18: "receipt_create_time": "09:45:34",
C19: offset | P19: Int | U19: 10 | Z19: レコードの取得を開始する位置 | AK19: 〇 | AN19: "limit": 10, | BJ19: log_id | BV19: Long | CA19: 10 | CS19: "receipt_no": "8077",
AN20: "offset": 0 | CS20: "employee_code": "100881136",
AN21: } | CS21: "log_id": 612
CS22: }
CS23: ]
CS24: }
B25: 補足事項 | BH25: エラーメッセージ
BI26: HTTPステータス | BQ26: メッセージ | CS26: 説明
D27: start_date = ''の場合、start_date = '0000-01-01'として設定する。 | BI27: 500 | BQ27: サーバーエラー | CS27: 要確認
D28: end_date = '' の場合、end_date = CURRENT_DATEとして設定する。
D29: start_time = ''の場合、start_time = '00:00:00'として設定する。
D30: end_time = ''の場合、end_time = '24:00:00'として設定する。
D31: receipt_no = ''の場合、全てのreceipt_noを検索する。
D32: employee_code = ''の場合、全てのemployee_codeを検索する。
A38: ・サーバ
B40: 追加情報
D43: SELECT COUNT(*) FROM receiptmaster s
D44: WHERE s.RECORD_VOID_FLAG <> '1' AND s.CompanyCode = ?1 AND s.StoreCode = ?2
D45: AND (s.ReceiptCreateDate BETWEEN IF(?3 = '', '0000-01-01', ?3) AND IF(?4 = '', CURRENT_DATE, ?4))
D46: AND (s.ReceiptCreateTime BETWEEN IF(?5 = '', '00:00:00', ?5) AND IF(?6 = '', '24:00:00', ?6))
D47: AND (IF(?7 = '', true, s.ReceiptNo = ?7))
D48: AND (IF(?8 = '', true, s.EmployeeCode = ?8))
D52: SELECT * FROM receiptmaster s
D53: WHERE s.RECORD_VOID_FLAG <> '1' AND s.CompanyCode = ?1 AND s.StoreCode = ?2
...

Sheet R002
A1: システム名 | K1: システム種別 | W1: =IF(表紙!W1="","",表紙!W1) -> 基本設計書 | AP1: 作成者 | AT1: 作成日 | AY1: 更新者 | BC1: 更新日 | BH1: 版数 | BU1: メソッド | CJ1: 認証 | CX1: 作成情報 | DG1: 更新情報
A2: =IF(表紙!A2="","",表紙!A2) -> ignica POS | K2: =IF(表紙!K2="","",表紙!K2) -> POS Server | AP2: =IF(表紙!AP2="","",表紙!AP2) -> Thanh Nguyên | AT2: =IF(表紙!AT2="","",表紙!AT2) -> 45336 | AY2: =IF(表紙!AY2="","",表紙!AY2) -> Thanh Nguyên | BC2: =IF(表紙!BC2="","",表紙!BC2) -> 45336 | BH2: =IF(表紙!BH2="","",表紙!BH2) -> 0.1 | BU2: POST | CJ2: Bearer | CX2: 作成者 | DA2: 富士通)今村 | DG2: 更新者 | DJ2: 富士通)今村
CX3: 作成日 | DA3: 44621 | DG3: 更新日 | DJ3: 44638
A4: 機能カテゴリ | H4: =IF(表紙!H4="","",表紙!H4) -> 21_ジャーナル検索機能 | U4: 項目 | Z4: =IF(表紙!Z4="","",表紙!Z4) -> 概要設計 | AP4: {=RIGHT(CELL("filename",$A$1),LEN(CELL("filename",$A$1))-FIND("]",CELL("filename",$A$1)))} -> #VALUE!
B7: pos/v1/receipt/employee
B8: リクエスト | BH8: レスポンス<200：OK>
C9: 属性 | P9: 型 | U9: Số từ | Z9: 備考 | AK9: NN | AN9: 例 | BI9: 属性 | BV9: 型 | CA9: số từ | CF9: 備考 | CS9: 例
C10: company_code | P10: String | U10: 10 | Z10: 会社番号 | AK10: 〇 | AN10: { | BI10: code | BV10: String | CA10: 16 | CF10: 担当者番号 | CS10: [
C11: store_code | P11: String | U11: 10 | Z11: 店舗番号 | AK11: 〇 | AN11: "company_code": "300", | BI11: name | BV11: String | CA11: 50 | CF11: 担当者名 | CS11: {
AN12: "store_code": "048405" | CS12: "code": "100616121",
AN13: } | CS13: "name": "136セルフレジ"
CS14: },
CS15: {
CS16: "code": "100639133",
CS17: "name": "１３３セルフレジ
CS18: }
CS19: ]
B25: 補足事項 | BH25: エラーメッセージ
BI26: HTTPステータス | BQ26: メッセージ | CS26: 説明
BI27: 500 | BQ27: サーバーエラー | CS27: 要確認
A38: ・サーバ
B40: 追加情報
D43: SELECT NEW com.pos.system.model.dto.EmployeeMasterDTO(s.employeeCode, s.name) FROM EmployeeMaster s
D44: WHERE s.recordVoidFlag <> '1' AND s.companyCode = '$companyCode' AND s.storeCode = '$storeCode'

Sheet R003
A1: システム名 | K1: システム種別 | W1: =IF(表紙!W1="","",表紙!W1) -> 基本設計書 | AP1: 作成者 | AT1: 作成日 | AY1: 更新者 | BC1: 更新日 | BH1: 版数 | BU1: メソッド | CJ1: 認証 | CX1: 作成情報 | DG1: 更新情報
A2: =IF(表紙!A2="","",表紙!A2) -> ignica POS | K2: =IF(表紙!K2="","",表紙!K2) -> POS Server | AP2: =IF(表紙!AP2="","",表紙!AP2) -> Thanh Nguyên | AT2: =IF(表紙!AT2="","",表紙!AT2) -> 45336 | AY2: =IF(表紙!AY2="","",表紙!AY2) -> Thanh Nguyên | BC2: =IF(表紙!BC2="","",表紙!BC2) -> 45336 | BH2: =IF(表紙!BH2="","",表紙!BH2) -> 0.1 | BU2: POST | CJ2: Bearer | CX2: 作成者 | DA2: 富士通)今村 | DG2: 更新者 | DJ2: 富士通)今村
CX3: 作成日 | DA3: 44621 | DG3: 更新日 | DJ3: 44638
A4: 機能カテゴリ | H4: =IF(表紙!H4="","",表紙!H4) -> 21_ジャーナル検索機能 | U4: 項目 | Z4: =IF(表紙!Z4="","",表紙!Z4) -> 概要設計 | AP4: {=RIGHT(CELL("filename",$A$1),LEN(CELL("filename",$A$1))-FIND("]",CELL("filename",$A$1)))} -> #VALUE!
B6: リクエスト | BH6: レスポンス<200：OK>
C7: 属性 | P7: 型 | U7: Số từ | Z7: 備考 | AK7: NN | AN7: 例 | BI7: 属性 | BV7: 型 | CA7: 文字数 | CF7: 備考 | CS7: 例
C8: log_id | P8: Long | U8: 10 | Z8: ログ番号 | AK8: 〇 | AN8: { | BI8: URL | BV8: String | CA8: - | CF8: 帳票作成のAPI URL | CS8: {
AN9: "log_id": 12655 | BI9: Response | BV9: String | CA9: - | CF9: 帳票作成のデータ | CS9: "url": "https://t3.usmh-fjservice.com/pos/v1/cashchanger/verificate",
AN10: } | CS10: "response": "{"journal": … "}"
CS11: }
B23: 補足事項 | BH23: エラーメッセージ
BI24: HTTPステータス | BQ24: メッセージ | CS24: 説明
BI25: 500 | BQ25: サーバーエラー | CS25: 要確認
A36: ・サーバ
B38: 追加情報
D41: SELECT NEW com.pos.system.model.dto.LogMasterDTO(s.url, s.response) FROM LogMaster s WHERE s.recordVoidFlag <> '1' AND s.recordId = $recordID

Sheet 帳票マスター
A1: システム名 | K1: システム種別 | W1: =IF(表紙!W1="","",表紙!W1) -> 基本設計書 | AP1: 作成者 | AT1: 作成日 | AY1: 更新者 | BC1: 更新日 | BH1: 版数
A2: =IF(表紙!A2="","",表紙!A2) -> ignica POS | K2: =IF(表紙!K2="","",表紙!K2) -> POS Server | AP2: =IF(表紙!AP2="","",表紙!AP2) -> Thanh Nguyên | AT2: =IF(表紙!AT2="","",表紙!AT2) -> 45336 | AY2: =IF(表紙!AY2="","",表紙!AY2) -> Thanh Nguyên | BC2: =IF(表紙!BC2="","",表紙!BC2) -> 45336 | BH2: =IF(表紙!BH2="","",表紙!BH2) -> 0.1
A4: 機能カテゴリ | H4: =IF(表紙!H4="","",表紙!H4) -> 21_ジャーナル検索機能 | U4: 項目 | Z4: =IF(表紙!Z4="","",表紙!Z4) -> 概要設計 | AP4: {=RIGHT(CELL("filename",$A$1),LEN(CELL("filename",$A$1))-FIND("]",CELL("filename",$A$1)))} -> #VALUE!
B7: ■テーブル情報
B8: スキーマ名 | G8: pos_charge | Y8: RDBMS名
B9: 論理名 | G9: 帳票マスター | Y9: バージョン
B10: 物理名 | G10: receiptmaster
B11: 備考
B12: ログが伝票を含む場合、ログマスターテーブルのログより取得する。
B19: ■テーブル情報 | BP19: ="DROP TABLE IF EXISTS `"&$G$8&"`.`"&$G$10&"`;" -> DROP TABLE IF EXISTS `pos_charge`.`receiptmaster`;
B20: No. | D20: 論理名 | R20: 物理名 | AC20: データ型 | AH20: PK | AJ20: Not Null | AM20: Default | AT20: 備考 | BP20: ="CREATE TABLE `"&$G$8&"`.`"&$G$10&"` (" -> CREATE TABLE `pos_charge`.`receiptmaster` (
B21: 1 | D21: Record ID | R21: RECORD_ID | AC21: bigint | AH21: 1 | AJ21: Y | AM21: 自動追加 | BP21: `RECORD_ID` bigint NOT NULL AUTO_INCREMENT COMMENT 'レコードID'
B22: =B21+1 -> 2 | D22: レコード作成日 | R22: RECORD_CREATE_DATE | AC22: date | AJ22: Y | AM22: CURRENT_DATE | BP22: ,`RECORD_CREATE_DATE` date NOT NULL COMMENT 'レコード作成日付'
B23: =B22+1 -> 3 | D23: レコード作成時間 | R23: RECORD_CREATE_TIME | AC23: time | AJ23: Y | AM23: CURRENT_TIME | BP23: ,`RECORD_CREATE_TIME` time NOT NULL COMMENT 'レコード作成時間'
B24: =B23+1 -> 4 | D24: レコード更新日 | R24: RECORD_UPDATE_DATE | AC24: date | AJ24: Y | AM24: CURRENT_DATE | AT24: トリガー更新 | BP24: ,`RECORD_UPDATE_DATE` date NOT NULL COMMENT 'レコード更新日付/トリガーにより更新'
B25: =B24+1 -> 5 | D25: レコード更新時間 | R25: RECORD_UPDATE_TIME | AC25: time | AJ25: Y | AM25: CURRENT_TIME | AT25: トリガー更新 | BP25: ,`RECORD_UPDATE_TIME` time NOT NULL COMMENT 'レコード更新時間/トリガーにより更新'
B26: =B25+1 -> 6 | D26: レコード無効フラグ | R26: RECORD_VOID_FLAG | AC26: char(1) | AJ26: Y | AM26: "" | AT26: 0: Flag enable, 1: Flag disable | BP26: ,`RECORD_VOID_FLAG` char(1) NOT NULL DEFAULT '' COMMENT 'レコード無効フラグ '''': 有効フラグ、 1:無効フラグ'
B27: 7 | D27: 会社コード | R27: CompanyCode | AC27: varchar(10) | AJ27: Y | AT27: Mapping logmaster[CompanyCode] | BP27: =",`"&R27&"` "&AC27&" "&IF(AJ27="Y","NOT NULL","")&" COMMENT '"&D27&"'" -> ,`CompanyCode` varchar(10) NOT NULL COMMENT '会社コード'
B28: =B27+1 -> 8 | D28: 店舗コード | R28: StoreCode | AC28: varchar(10) | AJ28: Y | AT28: Mapping logmaster[StoreCode] | BP28: =",`"&R28&"` "&AC28&" "&IF(AJ28="Y","NOT NULL","")&" COMMENT '"&D28&"'" -> ,`StoreCode` varchar(10) NOT NULL COMMENT '店舗コード'
B29: =B28+1 -> 9 | D29: レジ番号 | R29: InstoreCode | AC29: varchar(10) | AJ29: Y | AT29: Mapping logmaster[InstoreCode] | BP29: =",`"&R29&"` "&AC29&" "&IF(AJ29="Y","NOT NULL","")&" COMMENT '"&D29&"'" -> ,`InstoreCode` varchar(10) NOT NULL COMMENT 'レジ番号'
B30: =B29+1 -> 10 | D30: 帳票作成 | R30: ReceiptCreateDate | AC30: date | AJ30: Y | AT30: logmaster[response]のデータを取得する | BP30: =",`"&R30&"` "&AC30&" "&IF(AJ30="Y","NOT NULL","")&" COMMENT '"&D30&"'" -> ,`ReceiptCreateDate` date NOT NULL COMMENT '帳票作成'
B31: =B30+1 -> 11 | D31: 帳票作成時間 | R31: ReceiptCreateTime | AC31: time | AJ31: Y | AT31: logmaster[response]のデータを取得する | BP31: =",`"&R31&"` "&AC31&" "&IF(AJ31="Y","NOT NULL","")&" COMMENT '"&D31&"'" -> ,`ReceiptCreateTime` time NOT NULL COMMENT '帳票作成時間'
B32: =B31+1 -> 12 | D32: 帳票番号 | R32: ReceiptNo | AC32: varchar(20) | AJ32: Y | AT32: logmaster[response]のデータを取得する | BP32: =",`"&R32&"` "&AC32&" "&IF(AJ32="Y","NOT NULL","")&" COMMENT '"&D32&"'" -> ,`ReceiptNo` varchar(20) NOT NULL COMMENT '帳票番号'
B33: =B32+1 -> 13 | D33: 係員コード | R33: EmployeeCode | AC33: varchar(16) | AJ33: Y | AT33: logmaster[response]のデータを取得する | BP33: =",`"&R33&"` "&AC33&" "&IF(AJ33="Y","NOT NULL","")&" COMMENT '"&D33&"'" -> ,`EmployeeCode` varchar(16) NOT NULL COMMENT '係員コード'
B34: =B33+1 -> 14 | D34: ログID | R34: LogID | AC34: bigint | AJ34: Y | AT34: Mapping logmaster[RECORD_ID] | BP34: =",`"&R34&"` "&AC34&" "&IF(AJ34="Y","NOT NULL","")&" COMMENT '"&D34&"'" -> ,`LogID` bigint NOT NULL COMMENT 'ログID'
BP35: =",`"&R35&"` "&AC35&" "&IF(AJ35="Y","NOT NULL","")&" COMMENT '"&D35&"'" -> ,`` COMMENT ''
BP36: =",`"&R36&"` "&AC36&" "&IF(AJ36="Y","NOT NULL","")&" COMMENT '"&D36&"'" -> ,`` COMMENT ''
BP37: =",`"&R37&"` "&AC37&" "&IF(AJ37="Y","NOT NULL","")&" COMMENT '"&D37&"'" -> ,`` COMMENT ''
BP38: =",`"&R38&"` "&AC38&" "&IF(AJ38="Y","NOT NULL","")&" COMMENT '"&D38&"'" -> ,`` COMMENT ''
BP39: =",`"&R39&"` "&AC39&" "&IF(AJ39="Y","NOT NULL","")&" COMMENT '"&D39&"'" -> ,`` COMMENT ''
BP40: =",`"&R40&"` "&AC40&" "&IF(AJ40="Y","NOT NULL","")&" COMMENT '"&D40&"'" -> ,`` COMMENT ''
BP41: =",`"&R41&"` "&AC41&" "&IF(AJ41="Y","NOT NULL","")&" COMMENT '"&D41&"'" -> ,`` COMMENT ''
BP42: =",`"&R42&"` "&AC42&" "&IF(AJ42="Y","NOT NULL","")&" COMMENT '"&D42&"'" -> ,`` COMMENT ''
BP43: =",`"&R43&"` "&AC43&" "&IF(AJ43="Y","NOT NULL","")&" COMMENT '"&D43&"'" -> ,`` COMMENT ''
BP44: =",`"&R44&"` "&AC44&" "&IF(AJ44="Y","NOT NULL","")&" COMMENT '"&D44&"'" -> ,`` COMMENT ''
BP45: =" , PRIMARY KEY ("&IF(_xlfn.XLOOKUP(1,$AH:$AH,$R:$R,"",0)="","","`"&_xlfn.XLOOKUP(1,$AH:$AH,$R:$R,"",0)&"`")&IF(_xlfn.XLOOKUP(2,$AH:$AH,$R:$R,"",0)="","",",`"&_xlfn.XLOOKUP(2,$AH:$AH,$R:$R,"",0)&"`")&IF(_xlfn.XLOOKUP(3,$AH:$AH,$R:$R,"",0)="","",",`"&_xlfn.XLOOKUP(3,$AH:$AH,$R:$R,"",0)&"`")&IF(_xlfn.XLOOKUP(4,$AH:$AH,$R:$R,"",0)="","",",`"&_xlfn.XLOOKUP(4,$AH:$AH,$R:$R,"",0)&"`")&IF(_xlfn.XLOOKUP(5,$AH:$AH,$R:$R,"",0)="","",",`"&_xlfn.XLOOKUP(5,$AH:$AH,$R:$R,"",0)&"`")&IF(_xlfn.XLOOKUP(6,$AH:$AH,$R:$R,"",0)="","",",`"&_xlfn.XLOOKUP(6,$AH:$AH,$R:$R,"",0)&"`")&IF(_xlfn.XLOOKUP(7,$AH:$AH,$R:$R,"",0)="","",",`"&_xlfn.XLOOKUP(7,$AH:$AH,$R:$R,"",0)&"`")&IF(_xlfn.XLOOKUP(8,$AH:$AH,$R:$R,"",0)="","",",`"&_xlfn.XLOOKUP(8,$AH:$AH,$R:$R,"",0)&"`")&")," -> , PRIMARY KEY (`RECORD_ID`),
BP46: KEY `RECORD_ID` (`RECORD_ID`)
BP47: =") ENGINE=InnoDB DEFAULT CHARSET=utf8mb4 COLLATE=utf8mb4_0900_ai_ci COMMENT = '"&$G$9&"';" -> ) ENGINE=InnoDB DEFAULT CHARSET=utf8mb4 COLLATE=utf8mb4_0900_ai_ci COMMENT = '帳票マスター';
BP49: ="CREATE TRIGGER `"&$G$8&"`.`"&$G$10&"_CR_Date_Time` BEFORE INSERT ON `"&$G$10&"` FOR EACH ROW SET NEW.record_create_date = CURRENT_DATE, NEW.record_create_time = CURRENT_TIME, NEW.record_update_date = CURRENT_DATE, NEW.record_update_time = CURRENT_TIME;" -> CREATE TRIGGER `pos_charge`.`receiptmaster_CR_Date_Time` BEFORE INSERT ON `receiptmaster` FOR EACH ROW SET NEW.record_create_date = CURRENT_DATE, NEW.record_create_time = CURRENT_TIME, NEW.record_update_date = CURRENT_DATE, NEW.record_update_time = CURRENT_TIME;
BP50: ="CREATE TRIGGER `"&$G$8&"`.`"&$G$10&"_UP_Date_Time` BEFORE UPDATE ON `"&$G$10&"` FOR EACH ROW SET NEW.record_update_date = CURRENT_DATE, NEW.record_update_time = CURRENT_TIME;" -> CREATE TRIGGER `pos_charge`.`receiptmaster_UP_Date_Time` BEFORE UPDATE ON `receiptmaster` FOR EACH ROW SET NEW.record_update_date = CURRENT_DATE, NEW.record_update_time = CURRENT_TIME;

Sheet ログマスタ
A1: システム名 | K1: システム種別 | W1: =IF(表紙!W1="","",表紙!W1) -> 基本設計書 | AP1: 作成者 | AT1: 作成日 | AY1: 更新者 | BC1: 更新日 | BH1: 版数
A2: =IF(表紙!A2="","",表紙!A2) -> ignica POS | K2: =IF(表紙!K2="","",表紙!K2) -> POS Server | AP2: =IF(表紙!AP2="","",表紙!AP2) -> Thanh Nguyên | AT2: =IF(表紙!AT2="","",表紙!AT2) -> 45336 | AY2: =IF(表紙!AY2="","",表紙!AY2) -> Thanh Nguyên | BC2: =IF(表紙!BC2="","",表紙!BC2) -> 45336 | BH2: =IF(表紙!BH2="","",表紙!BH2) -> 0.1
A4: 機能カテゴリ | H4: =IF(表紙!H4="","",表紙!H4) -> 21_ジャーナル検索機能 | U4: 項目 | Z4: =IF(表紙!Z4="","",表紙!Z4) -> 概要設計 | AP4: {=RIGHT(CELL("filename",$A$1),LEN(CELL("filename",$A$1))-FIND("]",CELL("filename",$A$1)))} -> #VALUE!
B7: ■テーブル情報
B8: スキーマ名 | G8: pos_charge | Y8: RDBMS名
B9: 論理名 | G9: ログマスタ | Y9: バージョン
B10: 物理名 | G10: logmaster
B11: 備考
B12: タブレットから送信したログより値を取得する。
B19: ■テーブル情報 | BP19: ="DROP TABLE IF EXISTS `"&$G$8&"`.`"&$G$10&"`;" -> DROP TABLE IF EXISTS `pos_charge`.`logmaster`;
B20: No. | D20: 論理名 | R20: 物理名 | AC20: データ型 | AH20: PK | AJ20: Not Null | AM20: デフォルト | AT20: 備考 | BP20: ="CREATE TABLE `"&$G$8&"`.`"&$G$10&"` (" -> CREATE TABLE `pos_charge`.`logmaster` (
B21: 1 | D21: RECORD_ID | R21: RECORD_ID | AC21: bigint | AJ21: Y | AM21: 自動追加 | BP21: `RECORD_ID` bigint NOT NULL AUTO_INCREMENT COMMENT 'レコードID'
B22: =B21+1 -> 2 | D22: レコード作成日 | R22: RECORD_CREATE_DATE | AC22: date | AJ22: Y | AM22: CURRENT_DATE | BP22: ,`RECORD_CREATE_DATE` date NOT NULL COMMENT 'レコード作成日付'
B23: =B22+1 -> 3 | D23: レコード作成時間 | R23: RECORD_CREATE_TIME | AC23: time | AJ23: Y | AM23: CURRENT_TIME | BP23: ,`RECORD_CREATE_TIME` time NOT NULL COMMENT 'レコード作成時間'
B24: =B23+1 -> 4 | D24: レコード更新日 | R24: RECORD_UPDATE_DATE | AC24: date | AJ24: Y | AM24: CURRENT_DATE | AT24: トリガー更新 | BP24: ,`RECORD_UPDATE_DATE` date NOT NULL COMMENT 'レコード更新日付/トリガーにより更新'
B25: =B24+1 -> 5 | D25: レコード更新時間 | R25: RECORD_UPDATE_TIME | AC25: time | AJ25: Y | AM25: CURRENT_TIME | AT25: トリガー更新 | BP25: ,`RECORD_UPDATE_TIME` time NOT NULL COMMENT 'レコード更新時間/トリガーにより更新'
B26: =B25+1 -> 6 | D26: レコード無効フラグ | R26: RECORD_VOID_FLAG | AC26: char(1) | AJ26: Y | AM26: "" | AT26: 0: Flag enable, 1: Flag disable | BP26: ,`RECORD_VOID_FLAG` char(1) NOT NULL DEFAULT '' COMMENT 'レコード無効フラグ '''': 有効フラグ、 1:無効フラグ'
B27: 7 | D27: 会社コード | R27: CompanyCode | AC27: varchar(10) | AM27: NULL | BP27: =",`"&R27&"` "&AC27&" "&IF(AJ27="Y","NOT NULL","")&" COMMENT '"&D27&"'" -> ,`CompanyCode` varchar(10) COMMENT '会社コード'
B28: =B27+1 -> 8 | D28: 店舗コード | R28: StoreCode | AC28: varchar(10) | AM28: NULL | BP28: =",`"&R28&"` "&AC28&" "&IF(AJ28="Y","NOT NULL","")&" COMMENT '"&D28&"'" -> ,`StoreCode` varchar(10) COMMENT '店舗コード'
B29: =B28+1 -> 9 | D29: レジ番号 | R29: InstoreCode | AC29: varchar(10) | AM29: NULL | BP29: =",`"&R29&"` "&AC29&" "&IF(AJ29="Y","NOT NULL","")&" COMMENT '"&D29&"'" -> ,`InstoreCode` varchar(10) COMMENT 'レジ番号'
B30: =B29+1 -> 10 | D30: IPAddress | R30: IpAddress | AC30: varchar(39) | AM30: NULL | BP30: =",`"&R30&"` "&AC30&" "&IF(AJ30="Y","NOT NULL","")&" COMMENT '"&D30&"'" -> ,`IpAddress` varchar(39) COMMENT 'IPAddress'
B31: =B30+1 -> 11 | D31: URL | R31: URL | AC31: TEXT | AM31: NULL | BP31: =",`"&R31&"` "&AC31&" "&IF(AJ31="Y","NOT NULL","")&" COMMENT '"&D31&"'" -> ,`URL` TEXT COMMENT 'URL'
B32: =B31+1 -> 12 | D32: 件名 | R32: Headers | AC32: TEXT | AM32: NULL | BP32: =",`"&R32&"` "&AC32&" "&IF(AJ32="Y","NOT NULL","")&" COMMENT '"&D32&"'" -> ,`Headers` TEXT COMMENT '件名'
B33: =B32+1 -> 13 | D33: リクエスト | R33: Request | AC33: TEXT | AM33: NULL | BP33: =",`"&R33&"` "&AC33&" "&IF(AJ33="Y","NOT NULL","")&" COMMENT '"&D33&"'" -> ,`Request` TEXT COMMENT 'リクエスト'
B34: =B33+1 -> 14 | D34: レスポンスコード | R34: ResponseCode | AC34: smallint | AM34: NULL | BP34: =",`"&R34&"` "&AC34&" "&IF(AJ34="Y","NOT NULL","")&" COMMENT '"&D34&"'" -> ,`ResponseCode` smallint COMMENT 'レスポンスコード'
B35: =B34+1 -> 15 | D35: レスポンス | R35: Response | AC35: mediumtext | AM35: NULL | BP35: =",`"&R35&"` "&AC35&" "&IF(AJ35="Y","NOT NULL","")&" COMMENT '"&D35&"'" -> ,`Response` mediumtext COMMENT 'レスポンス'
BP36: =",`"&R36&"` "&AC36&" "&IF(AJ36="Y","NOT NULL","")&" COMMENT '"&D36&"'" -> ,`` COMMENT ''
BP37: =",`"&R37&"` "&AC37&" "&IF(AJ37="Y","NOT NULL","")&" COMMENT '"&D37&"'" -> ,`` COMMENT ''
BP38: =",`"&R38&"` "&AC38&" "&IF(AJ38="Y","NOT NULL","")&" COMMENT '"&D38&"'" -> ,`` COMMENT ''
BP39: =",`"&R39&"` "&AC39&" "&IF(AJ39="Y","NOT NULL","")&" COMMENT '"&D39&"'" -> ,`` COMMENT ''
BP40: =",`"&R40&"` "&AC40&" "&IF(AJ40="Y","NOT NULL","")&" COMMENT '"&D40&"'" -> ,`` COMMENT ''
BP41: =",`"&R41&"` "&AC41&" "&IF(AJ41="Y","NOT NULL","")&" COMMENT '"&D41&"'" -> ,`` COMMENT ''
BP42: =",`"&R42&"` "&AC42&" "&IF(AJ42="Y","NOT NULL","")&" COMMENT '"&D42&"'" -> ,`` COMMENT ''
BP43: =",`"&R43&"` "&AC43&" "&IF(AJ43="Y","NOT NULL","")&" COMMENT '"&D43&"'" -> ,`` COMMENT ''
BP44: =",`"&R44&"` "&AC44&" "&IF(AJ44="Y","NOT NULL","")&" COMMENT '"&D44&"'" -> ,`` COMMENT ''
BP45: =" , PRIMARY KEY ("&IF(_xlfn.XLOOKUP(1,$AH:$AH,$R:$R,"",0)="","","`"&_xlfn.XLOOKUP(1,$AH:$AH,$R:$R,"",0)&"`")&IF(_xlfn.XLOOKUP(2,$AH:$AH,$R:$R,"",0)="","",",`"&_xlfn.XLOOKUP(2,$AH:$AH,$R:$R,"",0)&"`")&IF(_xlfn.XLOOKUP(3,$AH:$AH,$R:$R,"",0)="","",",`"&_xlfn.XLOOKUP(3,$AH:$AH,$R:$R,"",0)&"`")&IF(_xlfn.XLOOKUP(4,$AH:$AH,$R:$R,"",0)="","",",`"&_xlfn.XLOOKUP(4,$AH:$AH,$R:$R,"",0)&"`")&IF(_xlfn.XLOOKUP(5,$AH:$AH,$R:$R,"",0)="","",",`"&_xlfn.XLOOKUP(5,$AH:$AH,$R:$R,"",0)&"`")&IF(_xlfn.XLOOKUP(6,$AH:$AH,$R:$R,"",0)="","",",`"&_xlfn.XLOOKUP(6,$AH:$AH,$R:$R,"",0)&"`")&IF(_xlfn.XLOOKUP(7,$AH:$AH,$R:$R,"",0)="","",",`"&_xlfn.XLOOKUP(7,$AH:$AH,$R:$R,"",0)&"`")&IF(_xlfn.XLOOKUP(8,$AH:$AH,$R:$R,"",0)="","",",`"&_xlfn.XLOOKUP(8,$AH:$AH,$R:$R,"",0)&"`")&")," -> , PRIMARY KEY (),
BP46: KEY `RECORD_ID` (`RECORD_ID`)
BP47: =") ENGINE=InnoDB DEFAULT CHARSET=utf8mb4 COLLATE=utf8mb4_0900_ai_ci COMMENT = '"&$G$9&"';" -> ) ENGINE=InnoDB DEFAULT CHARSET=utf8mb4 COLLATE=utf8mb4_0900_ai_ci COMMENT = 'ログマスタ';
BP49: ="CREATE TRIGGER `"&$G$8&"`.`"&$G$10&"_CR_Date_Time` BEFORE INSERT ON `"&$G$10&"` FOR EACH ROW SET NEW.record_create_date = CURRENT_DATE, NEW.record_create_time = CURRENT_TIME, NEW.record_update_date = CURRENT_DATE, NEW.record_update_time = CURRENT_TIME;" -> CREATE TRIGGER `pos_charge`.`logmaster_CR_Date_Time` BEFORE INSERT ON `logmaster` FOR EACH ROW SET NEW.record_create_date = CURRENT_DATE, NEW.record_create_time = CURRENT_TIME, NEW.record_update_date = CURRENT_DATE, NEW.record_update_time = CURRENT_TIME;
BP50: ="CREATE TRIGGER `"&$G$8&"`.`"&$G$10&"_UP_Date_Time` BEFORE UPDATE ON `"&$G$10&"` FOR EACH ROW SET NEW.record_update_date = CURRENT_DATE, NEW.record_update_time = CURRENT_TIME;" -> CREATE TRIGGER `pos_charge`.`logmaster_UP_Date_Time` BEFORE UPDATE ON `logmaster` FOR EACH ROW SET NEW.record_update_date = CURRENT_DATE, NEW.record_update_time = CURRENT_TIME;

Sheet テンプレート
A1: システム名 | K1: システム種別 | W1: =IF(表紙!W1="","",表紙!W1) -> 基本設計書 | AP1: 作成者 | AT1: 作成日 | AY1: 更新者 | BC1: 更新日 | BH1: 版数
A2: =IF(表紙!A2="","",表紙!A2) -> ignica POS | K2: =IF(表紙!K2="","",表紙!K2) -> POS Server | AP2: =IF(表紙!AP2="","",表紙!AP2) -> Thanh Nguyên | AT2: =IF(表紙!AT2="","",表紙!AT2) -> 45336 | AY2: =IF(表紙!AY2="","",表紙!AY2) -> Thanh Nguyên | BC2: =IF(表紙!BC2="","",表紙!BC2) -> 45336 | BH2: =IF(表紙!BH2="","",表紙!BH2) -> 0.1
A4: 機能カテゴリ | H4: =IF(表紙!H4="","",表紙!H4) -> 21_ジャーナル検索機能 | U4: 項目 | Z4: =IF(表紙!Z4="","",表紙!Z4) -> 概要設計 | AP4: {=RIGHT(CELL("filename",$A$1),LEN(CELL("filename",$A$1))-FIND("]",CELL("filename",$A$1)))} -> #VALUE!

Sheet Sheet1
