Workbook

Sheet 表紙
A1: システム名 | K1: システム種別 | W1: 基本設計書 | AP1: 作成者 | AT1: 作成日 | AY1: 更新者 | BC1: 更新日 | BH1: 版数
A2: POSサーバー | K2: POSサーバー | AP2: =改訂履歴!$H$11 -> LoiLV | AT2: =改訂履歴!$B$11 -> 45421 | AY2: =LOOKUP(2,1/(改訂履歴!H11:H30000<>""),改訂履歴!H11:H30000) -> LoiLV | BC2: =LOOKUP(2,1/(改訂履歴!B11:B30000<>""),改訂履歴!B11:B30000) -> 45517 | BH2: =LOOKUP(2,1/(改訂履歴!O11:O30000<>""),改訂履歴!O11:O30000) -> 0.3.7
A4: 機能カテゴリ | H4: 25_取扱設定マスタ設定(KSM) | U4: 項目 | Z4: 概要設計書 | AP4: {=RIGHT(CELL("filename",$A$1),LEN(CELL("filename",$A$1))-FIND("]",CELL("filename",$A$1)))} -> 表紙
L16: POSサーバーの基本設計書
L24: =K2&"/"&H4&"/"&Z4 -> POSサーバー/25_取扱設定マスタ設定(KSM)/概要設計書
Q44: 承認日 | AA44: 承認者 | AQ44: 版数

Sheet 改訂履歴
A1: システム名 | K1: システム種別 | W1: =IF(表紙!W1="","",表紙!W1) -> 基本設計書 | AP1: 作成者 | AT1: 作成日 | AY1: 更新者 | BC1: 更新日 | BH1: 版数
A2: =IF(表紙!A2="","",表紙!A2) -> POSサーバー | K2: =IF(表紙!K2="","",表紙!K2) -> POSサーバー | AP2: =IF(表紙!AP2="","",表紙!AP2) -> LoiLV | AT2: =IF(表紙!AT2="","",表紙!AT2) -> 45421 | AY2: =IF(表紙!AY2="","",表紙!AY2) -> LoiLV | BC2: =IF(表紙!BC2="","",表紙!BC2) -> 45517 | BH2: =IF(表紙!BH2="","",表紙!BH2) -> 0.3.7
A4: 機能カテゴリ | H4: =IF(表紙!H4="","",表紙!H4) -> 25_取扱設定マスタ設定(KSM) | U4: 項目 | Z4: =IF(表紙!Z4="","",表紙!Z4) -> 概要設計書 | AP4: {=RIGHT(CELL("filename",$A$1),LEN(CELL("filename",$A$1))-FIND("]",CELL("filename",$A$1)))} -> 改訂履歴
B8: ■改訂履歴
B10: 更新日 | H10: 更新者 | O10: 版数 | S10: 更新内容 | AX10: 承認日 | BD10: 承認者
B11: 45421 | H11: LoiLV | O11: 0.1 | S11: 新規作成
B13: 45426 | H13: LoiLV | O13: 0.2 | S13: 更新
B15: 45428 | H15: LoiLV | O15: 0.3 | S15: 更新
B17: 45429 | H17: LoiLV | O17: 0.3.1 | S17: 更新
B19: 45439 | H19: LoiLV | O19: 0.3.2 | S19: 2024年05月23日のコメントによる更新
B21: 45448 | H21: LoiLV | O21: 0.3.3 | S21: 2024年06月04日のコメントによる更新
B23: 45447 | H23: KSM | O23: 0.3.4 | S23: コメントによる更新
B25: 45453 | H25: KSM | O25: 0.3.5 | S25: 2024年06月06日のコメントによる更新
B27: 45457 | H27: KSM | O27: 0.3.6 | S27: 「取扱有無と下位階層も同設定の詳細」シート：2024年06月06日のコメントによる更新
B29: 45517 | H29: LoiLV | O29: 0.3.7 | S29: シート：機能概要、取扱有無と下位階層も同設定の詳細
S30: 指摘履歴シートによる更新

Sheet 指摘履歴
A1: システム名 | K1: システム種別 | W1: =IF([1]表紙!W1="","",[1]表紙!W1) -> 基本設計書 | AP1: 作成者 | AT1: 作成日 | AY1: 更新者 | BC1: 更新日 | BH1: 版数
A2: =IF([1]表紙!A2="","",[1]表紙!A2) -> POSサーバー | K2: =IF([1]表紙!K2="","",[1]表紙!K2) -> POSサーバー | AP2: カスミ | AT2: 45488 | AY2: 佐々木 | BC2: 45488
A4: 機能カテゴリ | H4: =IF([1]表紙!H4="","",[1]表紙!H4) -> 25_取扱設定マスタ設定(KSM) | U4: 項目 | Z4: =IF([1]表紙!Z4="","",[1]表紙!Z4) -> 概要設計書 | AP4: 指摘履歴
B8: ■改訂履歴
B10: 更新日 | H10: 更新者 | O10: 版数 | S10: 更新内容 | AX10: 承認日 | BD10: 承認者
B11: 45449 | H11: カスミ 佐々木 | S11: 機能概要
S12: 連携されていない場合、「選択された店舗はテナント連携が行われている店舗で はないため、当機能は利用できません。」メッセージを含むエラーモダールが表示される。=>店舗マスタに【ウエルシア社扱い区分】で対象店を設定する。という考慮が必要
B13: 45449 | H13: カスミ 佐々木 | S13: 機能概要
S14: ・有:●〇、無: 〇●を有:●、無: 〇で表示することの方が見易い
B15: 45449 | H15: カスミ 佐々木 | S15: 機能概要
S16: ・部門コード: 名称：データありが必須‣品郡コード: 名称：設定がない場合、「-」を表示する。 ・品種コード: 名称：設定がない場合、「-」を表示する。 ・分類コード: 名称：設定がない場合、「-」を表示する。 ＝＞「ー」表示はなくなる。
B17: 45449 | H17: カスミ 佐々木 | S17: 機能概要
S18: ・「編集」ボタンをタッチすると、MD2501_商品部門編集モダールが表示される。選択行がない場合、「明細行が選択されていません。」エラーモダールが表示される。 ＝＞編集ボタン、MD2501_商品部門編集モダールはなくなる認識
B19: 45449 | H19: カスミ 佐々木 | S19: 機能概要
S20: ・単品で【商品採用店舗確認】画面で設定が行われている場合は除外する
B21: 45449 | H21: カスミ 佐々木 | S21: 機能概要
S22: この画面は部門設定の画面でした。 「単品で【商品採用店舗確認】画面で設定が行われている場合は除外する」は無効として下さい。
B23: 45449 | H23: カスミ 佐々木 | S23: 取扱有無と下位階層も同設定の詳細
S24: ・「1. 商品には取扱有無が設定されていない場合」とはどんな場合でしょうか ※ 【商品採用店舗確認】画面で設定のことでしょうか？
B25: 45449 | H25: カスミ 佐々木 | S25: 取扱有無と下位階層も同設定の詳細
S26: ・下位階層同設定ボタンは常に押下可能という認識です。_x000B_

Sheet 業務フロー凡例
A1: システム名 | K1: システム種別 | W1: =IF(表紙!W1="","",表紙!W1) -> 基本設計書 | AP1: 作成者 | AT1: 作成日 | AY1: 更新者 | BC1: 更新日 | BH1: 版数
A2: =IF(表紙!A2="","",表紙!A2) -> POSサーバー | K2: =IF(表紙!K2="","",表紙!K2) -> POSサーバー | AP2: =IF(表紙!AP2="","",表紙!AP2) -> LoiLV | AT2: 45084 | AY2: =IF(表紙!AY2="","",表紙!AY2) -> LoiLV | BC2: =IF(表紙!BC2="","",表紙!BC2) -> 45517 | BH2: =IF(表紙!BH2="","",表紙!BH2) -> 0.3.7
A4: 機能カテゴリ | H4: =IF(表紙!H4="","",表紙!H4) -> 25_取扱設定マスタ設定(KSM) | U4: 項目 | Z4: =IF(表紙!Z4="","",表紙!Z4) -> 概要設計書 | AP4: {=RIGHT(CELL("filename",$A$1),LEN(CELL("filename",$A$1))-FIND("]",CELL("filename",$A$1)))} -> 業務フロー凡例
B7: ●1_レジ内
B22: ●1_レジ周辺機器
B42: ●外部連携

Sheet 機能概要説明
A1: システム名 | K1: システム種別 | W1: =IF(表紙!W1="","",表紙!W1) -> 基本設計書 | AP1: 作成者 | AT1: 作成日 | AY1: 更新者 | BC1: 更新日 | BH1: 版数
A2: =IF(表紙!A2="","",表紙!A2) -> POSサーバー | K2: =IF(表紙!K2="","",表紙!K2) -> POSサーバー | AP2: =IF(表紙!AP2="","",表紙!AP2) -> LoiLV | AT2: =IF(表紙!AT2="","",表紙!AT2) -> 45421 | AY2: =IF(表紙!AY2="","",表紙!AY2) -> LoiLV | BC2: =IF(表紙!BC2="","",表紙!BC2) -> 45517 | BH2: =IF(表紙!BH2="","",表紙!BH2) -> 0.3.7
A4: 機能カテゴリ | H4: =IF(表紙!H4="","",表紙!H4) -> 25_取扱設定マスタ設定(KSM) | U4: 項目 | Z4: =IF(表紙!Z4="","",表紙!Z4) -> 概要設計書 | AP4: {=RIGHT(CELL("filename",$A$1),LEN(CELL("filename",$A$1))-FIND("]",CELL("filename",$A$1)))} -> 機能概要説明
B7: 取扱設定マスタ設定(KSM)では次のことが可能になる。 | BM7: =IF(BM6=50,1,BM6+1) -> 1
C8: ・各レベルに分類された商品部門を閲覧する。 | BM8: =IF(BM7=50,1,BM7+1) -> 2
C9: ・商品部門の取扱有無を設定: 有、無 | BM9: =IF(BM8=50,1,BM8+1) -> 3
C10: ・部門の一括取扱有無を設定する。
C11: ・この設定は商品部門に関連する画面、機能に適用される。 | BM11: =IF(BM9=50,1,BM9+1) -> 4
C12: ・カスミ様の店舗のみ適用 | BM12: =IF(BM11=50,1,BM11+1) -> 5
BM13: =IF(BM12=50,1,BM12+1) -> 6
BM14: =IF(BM13=50,1,BM13+1) -> 7
BM15: =IF(BM14=50,1,BM14+1) -> 8
BM16: =IF(BM15=50,1,BM15+1) -> 9
BM17: =IF(BM16=50,1,BM16+1) -> 10
BM18: =IF(BM17=50,1,BM17+1) -> 11
BM19: =IF(BM18=50,1,BM18+1) -> 12
BM20: =IF(BM19=50,1,BM19+1) -> 13
BM21: =IF(BM20=50,1,BM20+1) -> 14
BM22: =IF(BM21=50,1,BM21+1) -> 15
BM23: =IF(BM22=50,1,BM22+1) -> 16
BM24: =IF(BM23=50,1,BM23+1) -> 17
... BM58: =IF(BM57=50,1,BM57+1) -> 1

Sheet 機能概要
A1: システム名 | K1: システム種別 | W1: =IF(表紙!W1="","",表紙!W1) -> 基本設計書 | AP1: 作成者 | AT1: 作成日 | AY1: 更新者 | BC1: 更新日 | BH1: 版数
A2: =IF(表紙!A2="","",表紙!A2) -> POSサーバー | K2: =IF(表紙!K2="","",表紙!K2) -> POSサーバー | AP2: =IF(表紙!AP2="","",表紙!AP2) -> LoiLV | AT2: =IF(表紙!AT2="","",表紙!AT2) -> 45421 | AY2: =IF(表紙!AY2="","",表紙!AY2) -> LoiLV | BC2: =IF(表紙!BC2="","",表紙!BC2) -> 45517 | BH2: =IF(表紙!BH2="","",表紙!BH2) -> 0.3.7
A4: 機能カテゴリ | H4: =IF(表紙!H4="","",表紙!H4) -> 25_取扱設定マスタ設定(KSM) | U4: 項目 | Z4: =IF(表紙!Z4="","",表紙!Z4) -> 概要設計書 | AP4: {=RIGHT(CELL("filename",$A$1),LEN(CELL("filename",$A$1))-FIND("]",CELL("filename",$A$1)))} -> 機能概要
B7: 25_取扱設定マスタ設定(KSM)
BM8: =IF(BM7=50,1,BM7+1) -> 1
BM9: =IF(BM8=50,1,BM8+1) -> 2
BM10: =IF(BM9=50,1,BM9+1) -> 3
BM11: =IF(BM10=50,1,BM10+1) -> 4
BM12: =IF(BM11=50,1,BM11+1) -> 5
BM13: =IF(BM12=50,1,BM12+1) -> 6
BM14: =IF(BM13=50,1,BM13+1) -> 7
BM15: =IF(BM14=50,1,BM14+1) -> 8
BM16: =IF(BM15=50,1,BM15+1) -> 9
BM17: =IF(BM16=50,1,BM16+1) -> 10
BM18: =IF(BM17=50,1,BM17+1) -> 11
BM19: =IF(BM18=50,1,BM18+1) -> 12
BM20: =IF(BM19=50,1,BM19+1) -> 13
BM21: =IF(BM20=50,1,BM20+1) -> 14 | BO21: SC2501_取扱設定マスタ設定(KSM)画面
BM22: =IF(BM21=50,1,BM21+1) -> 15
BM23: =IF(BM22=50,1,BM22+1) -> 16
BM24: =IF(BM23=50,1,BM23+1) -> 17
BM25: =IF(BM24=50,1,BM24+1) -> 18
BM26: =IF(BM25=50,1,BM25+1) -> 19
BM27: =IF(BM26=50,1,BM26+1) -> 20
BM28: =IF(BM27=50,1,BM27+1) -> 21
BM29: =IF(BM28=50,1,BM28+1) -> 22
BM30: =IF(BM29=50,1,BM29+1) -> 23
BM31: =IF(BM30=50,1,BM30+1) -> 24
BM32: =IF(BM31=50,1,BM31+1) -> 25
BM33: =IF(BM32=50,1,BM32+1) -> 26
... BM43: =IF(BM42=50,1,BM42+1) -> 36
BM44: =IF(BM43=50,1,BM43+1) -> 37 | BO44: SC2501_取扱設定マスタ設定(KSM)画面
BM45: =IF(BM44=50,1,BM44+1) -> 38 | BO45: 修正後 | CX45: 修正前
BM46: =IF(BM45=50,1,BM45+1) -> 39
BM47: =IF(BM46=50,1,BM46+1) -> 40
BM48: =IF(BM47=50,1,BM47+1) -> 41
BM49: =IF(BM48=50,1,BM48+1) -> 42
BM50: =IF(BM49=50,1,BM49+1) -> 43
BM51: =IF(BM50=50,1,BM50+1) -> 44
BM52: =IF(BM51=50,1,BM51+1) -> 45
...

Sheet 画面設計書
A1: システム名 | K1: システム種別 | W1: =IF(表紙!W1="","",表紙!W1) -> 基本設計書 | AP1: 作成者 | AT1: 作成日 | AY1: 更新者 | BC1: 更新日 | BH1: 版数
A2: =IF(表紙!A2="","",表紙!A2) -> POSサーバー | K2: =IF(表紙!K2="","",表紙!K2) -> POSサーバー | AP2: =IF(表紙!AP2="","",表紙!AP2) -> LoiLV | AT2: =IF(表紙!AT2="","",表紙!AT2) -> 45421 | AY2: =IF(表紙!AY2="","",表紙!AY2) -> LoiLV | BC2: =IF(表紙!BC2="","",表紙!BC2) -> 45517 | BH2: =IF(表紙!BH2="","",表紙!BH2) -> 0.3.7
A4: 機能カテゴリ | H4: =IF(表紙!H4="","",表紙!H4) -> 25_取扱設定マスタ設定(KSM) | U4: 項目 | Z4: =IF(表紙!Z4="","",表紙!Z4) -> 概要設計書 | AP4: =MID(CELL("filename",A1),FIND("]",CELL("filename",A1))+1,255) -> 画面設計書
B7: ■ログイン画面のイメージ
B35: ■画面項目定義
B37: 画面項目ID | D37: 項目 | K37: タイプ | N37: I/O | O37: 多言語対象 | P37: アウトプット | AR37: インプット | BC37: 備考
P38: マッピングデータ | X38: 初期値 | AA38: 表示コントロール | AI38: Control enable | AR38: 必須 | AS38: 数字 | AT38: 文字 | AU38: マッピングデータ
P39: API名 | T39: 項目 | AU39: API名 | AY39: 項目
B40: 1 | K40: テキスト | N40: － | O40: ● | P40: － | T40: － | X40: Android POS Control | AA40: ー | AI40: － | AR40: － | AS40: ー | AT40: ー | AU40: － | AY40: ー
B41: 2 | K41: テキスト | N41: O | O41: ● | P41: － | T41: － | X41: User ID | AA41: ー | AI41: ー | AR41: － | AS41: ー | AT41: ー | AU41: － | AY41: ー
B42: 3 | K42: テキスト | N42: I | O42: － | P42: － | X42: － | AA42: ー | AI42: ー | AR42: － | AS42: ー | AT42: ー | AU42: － | AY42: ー
B43: 4 | K43: テキスト | N43: O | O43: ● | P43: － | T43: － | X43: Password | AA43: ー | AI43: ー | AR43: － | AS43: ー | AT43: ー | AU43: － | AY43: ー
B44: 5 | K44: EditText | N44: I | O44: － | P44: － | T44: － | X44: － | AA44: ー | AI44: ー | AR44: － | AS44: ー | AT44: ー | AU44: － | AY44: ー
B45: 6 | K45: ボタン | N45: I | O45: ● | P45: － | T45: － | X45: Login | AA45: ー | AI45: Enable | AR45: － | AS45: ー | AT45: ー | AU45: － | AY45: ー | BC45: Login-01/EmployeeMaster

Sheet 取扱有無と下位階層も同設定の詳細
A1: システム名 | K1: システム種別 | W1: =IF(表紙!W1="","",表紙!W1) -> 基本設計書 | AP1: 作成者 | AT1: 作成日 | AY1: 更新者 | BC1: 更新日 | BH1: 版数
A2: =IF(表紙!A2="","",表紙!A2) -> POSサーバー | K2: =IF(表紙!K2="","",表紙!K2) -> POSサーバー | AP2: =IF(表紙!AP2="","",表紙!AP2) -> LoiLV | AT2: =IF(表紙!AT2="","",表紙!AT2) -> 45421 | AY2: =IF(表紙!AY2="","",表紙!AY2) -> LoiLV | BC2: =IF(表紙!BC2="","",表紙!BC2) -> 45517 | BH2: =IF(表紙!BH2="","",表紙!BH2) -> 0.3.7
A4: 機能カテゴリ | H4: =IF(表紙!H4="","",表紙!H4) -> 25_取扱設定マスタ設定(KSM) | U4: 項目 | Z4: =IF(表紙!Z4="","",表紙!Z4) -> 概要設計書 | AP4: {=RIGHT(CELL("filename",$A$1),LEN(CELL("filename",$A$1))-FIND("]",CELL("filename",$A$1)))} -> 取扱有無と下位階層も同設定の詳細
B7: 取扱有無と下位階層も同設定の詳細説明
C9: 取扱有無と下位階層も同設定のボタン状態を変更する。
D10: ・取扱有無は取扱設定マスタ編集モダール又は各レコードの「下位階層も同設定」項目にある四角をタッチすることで変更可能
D11: ・「下位階層も同設定」項目の状態：「下位階層も同設定」ボタンが常に有効になる。
E12: ‣部門、品群、品種の状態：全コピー/■、カスタム/□
E13: ‣分類の状態：「-」（品種に従って表示する）
D14: ・下位階層も同設定で黒四角を設定した場合、
E15: ‣部門のレコードで
F16: 品群、品種、分類のレコードの取扱有無を部門に従って設定する。
E17: ‣品群のレコードで
F18: 品種、分類のレコードの取扱有無を品群に従って設定する。
E19: + 品種のレコードで
F20: 分類のレコードを品種に従って設定する。
E21: +分類のレコードで
F22: 他のレコードの取扱有無を変更しない。
D23: ・下位階層も同設定で白い四角を設定した場合
E24: ‣部門、品群、品種のレコードで
F25: 他のレコードの取扱有無を変更しない。
D27: 1. 商品に取扱有無が設定されていない場合、
E28: ・取扱有無：ブランク
E29: ・下位階層も同設定：ブランク
D30: 2. 部門の取扱有無の設定を変更する。
E31: ・「下位階層も同設定」項目では白い四角ボタンを表示する。
E32: ・白い四角ボタンをタッチする。
F33: ‣編集中の部門レコード: 下位階層も同設定で黒い四角ボタンを表示する。
F34: ‣編集中の部門に属する品群、品種、分類のレコード（同一部門コード）：
G35: ▸ 取扱有無を編集中の部門の状態に変更する。
G36: ▸ 品群、品種、分類の下位階層も同設定：黒い四角ボタンを表示する。分類：「-」を表示する。
F38: 部門 | J38: 品群 | O38: 品種 | T38: 分類 | X38: 取扱有無 | AA38: 下位階層も同設定 | AG38: 部門 | AK38: 品群 | AP38: 品種 | AU38: 分類 | AY38: 取扱有無 | BB38: 下位階層も同設定
F39: 01 : 部門 | J39: - | O39: - | T39: - | X39: 有 | AG39: 01 : 部門 | AK39: - | AP39: - | AU39: - | AY39: 有
F40: 01 : 部門 | J40: 1001 : 品群 | O40: - | T40: - | X40: 無 | AG40: 01 : 部門 | AK40: 1001 : 品群 | AP40: - | AU40: - | AY40: 有
F41: 01 : 部門 | J41: 1001 : 品群 | O41: 1090 : 品種 | T41: - | X41: 無 | AG41: 01 : 部門 | AK41: 1001 : 品群 | AP41: 1090 : 品種 | AU41: - | AY41: 有
F42: 01 : 部門 | J42: 1001 : 品群 | O42: 1090 : 品種 | T42: 1091 : 分類 | X42: 無 | AF42: => | AG42: 01 : 部門 | AK42: 1001 : 品群 | AP42: 1090 : 品種 | AU42: 1091 : 分類 | AY42: 有
F43: 01 : 部門 | J43: 1001 : 品群 | O43: 1090 : 品種 | T43: 1092 : 分類 | X43: 無 | AG43: 01 : 部門 | AK43: 1001 : 品群 | AP43: 1090 : 品種 | AU43: 1092 : 分類 | AY43: 有
F44: 01 : 部門 | J44: 1001 : 品群 | O44: 1090 : 品種 | T44: 1093 : 分類 | X44: 無 | AG44: 01 : 部門 | AK44: 1001 : 品群 | AP44: 1090 : 品種 | AU44: 1093 : 分類 | AY44: 有
F45: 01 : 部門 | J45: 1001 : 品群 | O45: 1090 : 品種 | T45: 1094 : 分類 | X45: 無 | AG45: 01 : 部門 | AK45: 1001 : 品群 | AP45: 1090 : 品種 | AU45: 1094 : 分類 | AY45: 有
F46: 02 : 部門 | J46: - | O46: - | T46: - | X46: 無 | AG46: 02 : 部門 | AK46: - | AP46: - | AU46: - | AY46: 無
...

Sheet テンプレート
A1: システム名 | K1: システム種別 | W1: =IF(表紙!W1="","",表紙!W1) -> 基本設計書 | AP1: 作成者 | AT1: 作成日 | AY1: 更新者 | BC1: 更新日 | BH1: 版数
A2: =IF(表紙!A2="","",表紙!A2) -> POSサーバー | K2: =IF(表紙!K2="","",表紙!K2) -> POSサーバー | AP2: =IF(表紙!AP2="","",表紙!AP2) -> LoiLV | AT2: =IF(表紙!AT2="","",表紙!AT2) -> 45421 | AY2: =IF(表紙!AY2="","",表紙!AY2) -> LoiLV | BC2: =IF(表紙!BC2="","",表紙!BC2) -> 45517 | BH2: =IF(表紙!BH2="","",表紙!BH2) -> 0.3.7
A4: 機能カテゴリ | H4: =IF(表紙!H4="","",表紙!H4) -> 25_取扱設定マスタ設定(KSM) | U4: 項目 | Z4: =IF(表紙!Z4="","",表紙!Z4) -> 概要設計書 | AP4: =MID(CELL("filename",A1),FIND("]",CELL("filename",A1))+1,255) -> テンプレート
AX12: `
