Workbook

Sheet 表紙
A1: システム名 | K1: システム種別 | W1: 詳細設計書 | AP1: 作成者 | AT1: 作成日 | AY1: 更新者 | BC1: 更新日 | BH1: 版数
A2: POSサーバー | K2: POSサーバ | AP2: =改訂履歴!$H$11 -> TinNH | AT2: =改訂履歴!$B$11 -> 45478 | AY2: =LOOKUP(2,1/(改訂履歴!H11:H30000<>""),改訂履歴!H11:H30000) -> DuNT | BC2: =LOOKUP(2,1/(改訂履歴!B11:B30000<>""),改訂履歴!B11:B30000) -> 45644 | BH2: =LOOKUP(2,1/(改訂履歴!O11:O30000<>""),改訂履歴!O11:O30000) -> 0.13
A4: 機能カテゴリ | H4: 01_商品管理 | U4: 項目 | Z4: 画面設計書 | AP4: {=RIGHT(CELL("filename",$A$1),LEN(CELL("filename",$A$1))-FIND("]",CELL("filename",$A$1)))} -> 表紙
L16: POSサーバーの詳細設計書
L24: =K2&"/"&H4&"/"&Z4 -> POSサーバ/01_商品管理/画面設計書
Q44: 承認日 | AA44: 承認者 | AQ44: 版数

Sheet 改訂履歴
A1: システム名 | K1: システム種別 | W1: =IF(表紙!W1="","",表紙!W1) -> 詳細設計書 | AP1: 作成者 | AT1: 作成日 | AY1: 更新者 | BC1: 更新日 | BH1: 版数
A2: =IF(表紙!A2="","",表紙!A2) -> POSサーバー | K2: =IF(表紙!K2="","",表紙!K2) -> POSサーバ | AP2: =IF(表紙!AP2="","",表紙!AP2) -> TinNH | AT2: =IF(表紙!AT2="","",表紙!AT2) -> 45478 | AY2: =IF(表紙!AY2="","",表紙!AY2) -> DuNT | BC2: =IF(表紙!BC2="","",表紙!BC2) -> 45644 | BH2: =IF(表紙!BH2="","",表紙!BH2) -> 0.13
A4: 機能カテゴリ | H4: =IF(表紙!H4="","",表紙!H4) -> 01_商品管理 | U4: 項目 | Z4: =IF(表紙!Z4="","",表紙!Z4) -> 画面設計書 | AP4: {=RIGHT(CELL("filename",$A$1),LEN(CELL("filename",$A$1))-FIND("]",CELL("filename",$A$1)))} -> 改訂履歴
B8: ■改訂履歴
B10: 更新日 | H10: 更新者 | O10: 版数 | S10: 更新内容 | AX10: 承認日 | BD10: 承認者
B11: 45478 | H11: TinNH | O11: 0.1 | S11: 新規
B13: 45582 | H13: DuNT | O13: 0.11 | S13: MD0102シートを追加
B15: 45628 | H15: DuNT | O15: 0.12 | S15: SC0103シートを追加
B17: 45644 | H17: DuNT | O17: 0.13 | S17: SC0101、SC0102
S18: APIマッピング更新

Sheet SC0101
A1: システム名 | K1: システム種別 | W1: =IF(表紙!W1="","",表紙!W1) -> 詳細設計書 | AP1: 作成者 | AT1: 作成日 | AY1: 更新者 | BC1: 更新日 | BH1: 版数
A2: =IF(表紙!A2="","",表紙!A2) -> POSサーバー | K2: =IF(表紙!K2="","",表紙!K2) -> POSサーバ | AP2: =IF(表紙!AP2="","",表紙!AP2) -> TinNH | AT2: =IF(表紙!AT2="","",表紙!AT2) -> 45478 | AY2: =IF(表紙!AY2="","",表紙!AY2) -> DuNT | BC2: =IF(表紙!BC2="","",表紙!BC2) -> 45644 | BH2: =IF(表紙!BH2="","",表紙!BH2) -> 0.13
A4: 機能カテゴリ | H4: =IF(表紙!H4="","",表紙!H4) -> 01_商品管理 | U4: 項目 | Z4: =IF(表紙!Z4="","",表紙!Z4) -> 画面設計書 | AP4: =MID(CELL("filename",A1),FIND("]",CELL("filename",A1))+1,255) -> SC0101
B7: ■商品管理画面のイメージ
B50: ■画面項目定義
B52: 画面項目ID | D52: 項目 | K52: タイプ | N52: I/O | O52: 多言語 | P52: 出力 | AR52: インプット | BC52: 備考
P53: マッピングデータ | X53: 初期値 | AA53: 表示コントロール | AI53: Control enable | AR53: 必須 | AS53: 数字 | AT53: 桁 | AU53: マッピングデータ
P54: API名 | T54: 項目 | AU54: API名 | AY54: 項目
B55: 0 | D55: 画面タイトル | K55: テキスト | N55: － | O55: ● | P55: － | T55: － | X55: 商品管理 | AA55: ー | AI55: － | AR55: － | AS55: ー | AT55: ー | AU55: － | AY55: ー | BC55: イベントID：SC0101-01
B56: 1 | D56: リロード | K56: ボタン | N56: I | O56: － | P56: － | T56: － | X56: － | AA56: ー | AI56: デフォルト：有効 | AR56: － | AS56: ー | AT56: ー | AU56: － | AY56: ー
B57: 2 | D57: 出力 | K57: ボタン | N57: I | O57: － | P57: － | T57: － | X57: － | AA57: ー | AI57: デフォルト：無効 | AR57: － | AS57: ー | AT57: ー | AU57: － | AY57: ー
B58: 3 | D58: 印刷 | K58: ボタン | N58: I | O58: － | P58: － | T58: － | X58: － | AA58: ー | AI58: デフォルト：無効 | AR58: － | AS58: ー | AT58: ー | AU58: － | AY58: ー
B59: 4 | D59: 部門コード(タイトル) | K59: テキスト | N59: － | O59: ● | P59: － | T59: － | X59: 部門コード* | AA59: ー | AI59: ー | AR59: － | AS59: ー | AT59: ー | AU59: － | AY59: ー
B60: 5 | D60: 部門コード(値) | K60: EditText | N60: I/O | O60: － | P60: AP1506 | T60: my_company_code (最初の6桁) | X60: － | AA60: ー | AI60: デフォルト：有効 | AR60: ● | AS60: ● | AT60: ー | AU60: AP1506 | AY60: my_company_code (最初の6桁) | BC60: 最大2桁。フォーカスが外れると自動的に「0」を右に追加
B61: 6 | D61: 商品コード（タイトル） | K61: テキスト | N61: － | O61: ● | P61: － | T61: － | X61: 商品コード | AA61: ー | AI61: ー | AR61: － | AS61: ー | AT61: ー | AU61: － | AY61: －
B62: 7 | D62: 商品コード（値） | K62: EditText | N62: I/O | O62: － | P62: AP1506 | T62: my_company_code (最後の6桁) | X62: － | AA62: ー | AI62: デフォルト：有効 | AR62: ● | AS62: ● | AT62: ー | AU62: AP1506 | AY62: my_company_code (最後の6桁) | BC62: 最大6桁。フォーカスが外れると自動的に「0」を右に追加
B63: 8 | D63: PLUコード(タイトル) | K63: テキスト | N63: － | O63: ● | P63: － | T63: － | X63: PLUコード | AA63: ー | AI63: ー | AR63: － | AS63: ー | AT63: ー | AU63: － | AY63: －
B64: 9 | D64: PLUコード(値) | K64: EditText | N64: I/O | O64: － | P64: AP1506 | T64: item_code | X64: － | AA64: ー | AI64: デフォルト：有効 | AR64: ● | AS64: ● | AT64: ー | AU64: AP1506 | AY64: item_code | BC64: イベントID：SC0101-02 最大13桁。フォーカスが外れると自動的に「0」を右に追加
B65: 10 | D65: 商品名称（タイトル） | K65: テキスト | N65: － | O65: ● | P65: － | T65: － | X65: 商品名称 | AA65: ー | AI65: ー | AR65: － | AS65: ー | AT65: ー | AU65: － | AY65: ー
B66: 11 | D66: 商品名称（値） | K66: テキスト | N66: － | O66: － | P66: AP1506 | T66: desciption | X66: － | AA66: 提案商品がある場合、AP1506の説明値を表示する。 商品が見つからない場合、サーバーから返されたエラーメッセージを表示する。 | AI66: デフォルト：無効 | AR66: ● | AS66: ー | AT66: ー | AU66: － | AY66: ー
B67: 12 | D67: 定番売価(タイトル) | K67: テキスト | N67: － | O67: ● | P67: － | T67: － | X67: 定番売価 | AA67: ー | AI67: ー | AR67: － | AS67: ー | AT67: ー | AU67: － | AY67: ー
B68: 13 | D68: 定番売価(値) | K68: テキスト | N68: O | O68: － | P68: AP1506 | T68: unit_price | X68: － | AA68: ー | AI68: デフォルト：無効 | AR68: ● | AS68: ● | AT68: ー | AU68: － | AY68: ー
B69: 14 | D69: 緊急売価(タイトル) | K69: テキスト | N69: － | O69: ● | P69: － | T69: － | X69: 緊急売価 | AA69: ー | AI69: ー | AR69: － | AS69: ー | AT69: ー | AU69: － | AY69: ー
B70: 15 | D70: 緊急売価(値) | K70: テキスト | N70: O | O70: － | P70: AP1506 | T70: force_price | X70: － | AA70: ー | AI70: デフォルト：無効 | AR70: ● | AS70: ● | AT70: ー | AU70: － | AY70: ー | BC70: 緊急売価設定ありの場合のみに表示する。
B71: 16 | D71: 商品詳細情報 | K71: ボタン | N71: － | O71: ● | P71: － | T71: － | X71: 商品管理詳細 | AA71: ー | AI71: デフォルト：無効 提案の商品がある場合、有効になる | AR71: － | AS71: ー | AT71: ー | AU71: － | AY71: ー | BC71: イベントID：SC0101-03
B72: 17 | D72: 緊急売価変更 | K72: ボタン | N72: － | O72: ● | P72: － | T72: － | X72: 緊急売価変更 | AA72: ー | AI72: デフォルト：無効 提案の商品がある場合、有効になる | AR72: ● | AS72: ● | AT72: ー | AU72: － | AY72: ー | BC72: イベントID：SC0101-04
B73: 18 | D73: 特売新規 | K73: ボタン | N73: － | O73: ● | P73: － | T73: － | X73: 特売新規 | AA73: ー | AI73: デフォルト：無効 提案の商品がある場合、有効になる | AR73: ● | AS73: ● | AT73: ー | AU73: － | AY73: ー | BC73: イベントID：SC0101-05
B74: 19 | D74: ミックスマッチ新規 | K74: ボタン | N74: － | O74: ● | P74: － | T74: － | X74: ミックスマッチ新規 | AA74: ー | AI74: デフォルト：無効 提案の商品がある場合、有効になる | AR74: ● | AS74: ● | AT74: ー | AU74: － | AY74: ー | BC74: イベントID：SC0101-06
B75: 20 | D75: 編集 | K75: ボタン | N75: － | O75: ● | P75: － | T75: － | X75: 編集 | AA75: ー | AI75: デフォルト：無効 一覧内でアイテムが選択された場合、有効になる。 | AR75: ● | AS75: ● | AT75: ー | AU75: － | AY75: ー | BC75: イベントID：SC0101-07
B76: 21 | D76: 状態（タイトル） | K76: テキスト | N76: － | O76: ● | P76: － | T76: － | X76: 状態 | AA76: ー | AI76: ー | AR76: － | AS76: ー | AT76: ー | AU76: － | AY76: ー
B77: 22 | D77: 状態（値） | K77: テキスト | N77: O | O77: － | P77: AP0101 | T77: status | X77: － | AA77: ー | AI77: ー | AR77: － | AS77: ー | AT77: ー | AU77: － | AY77: ー | BC77: 0: 実施中 In progress 1: 終了: Ended 2: 未実施: Not implemented 3: 中止: Cancelled 4: NG
B78: 23 | D78: 種別(タイトル) | K78: テキスト | N78: － | O78: ● | P78: － | T78: － | X78: 種別 | AA78: ー | AI78: ー | AR78: － | AS78: ー | AT78: ー | AU78: － | AY78: ー
B79: 24 | D79: 種別(値) | K79: テキスト | N79: O | O79: － | P79: － | T79: － | X79: － | AA79: ミックスマッチの場合、「ミックスマッチ」のテキストを表示する。 特売の場合、「特売」のテキストを表示する。 | AI79: ー | AR79: － | AS79: ー | AT79: ー | AU79: － | AY79: ー
B80: 25 | D80: プロモーション(タイトル) | K80: テキスト | N80: － | O80: ● | P80: － | T80: － | X80: プロモーション | AA80: ー | AI80: ー | AR80: － | AS80: ー | AT80: ー | AU80: － | AY80: ー
B81: 26 | D81: プロモーション(値) | K81: テキスト | N81: O | O81: － | P81: AP0101 | T81: promotion_code | X81: － | AA81: ー | AI81: ー | AR81: － | AS81: ー | AT81: ー | AU81: － | AY81: ー
B82: 27 | D82: ミックスマッチコード(タイトル) | K82: テキスト | N82: － | O82: ● | P82: － | T82: － | X82: ミックスマッチ | AA82: ー | AI82: ー | AR82: － | AS82: ー | AT82: ー | AU82: － | AY82: ー
B83: 28 | D83: ミックスマッチコード(値) | K83: テキスト | N83: O | O83: － | P83: AP0101 | T83: combination_options.code | X83: － | AA83: ー | AI83: ー | AR83: － | AS83: ー | AT83: ー | AU83: － | AY83: ー
B84: 29 | D84: 期間（タイトル） | K84: テキスト | N84: － | O84: ● | P84: － | T84: － | X84: 期間 | AA84: ー | AI84: ー | AR84: － | AS84: ー | AT84: ー | AU84: － | AY84: ー
B85: 30 | D85: 期間（値） | K85: テキスト | N85: O | O85: － | P85: AP0101 | T85: start_date_time ~ end_date_time | X85: － | AA85: ー | AI85: ー | AR85: － | AS85: ー | AT85: ー | AU85: － | AY85: ー | BC85: フォーマット:{yy/mm/dd hh:mm:ss}~{yy/mm/dd hh:mm:ss}
B86: 31 | D86: 売価情報（タイトル） | K86: テキスト | N86: － | O86: ● | P86: － | T86: － | X86: 売価情報 | AA86: ー | AI86: ー | AR86: － | AS86: ー | AT86: ー | AU86: － | AY86: ー
...

Sheet SC0102
A1: システム名 | K1: システム種別 | W1: =IF(表紙!W1="","",表紙!W1) -> 詳細設計書 | AP1: 作成者 | AT1: 作成日 | AY1: 更新者 | BC1: 更新日 | BH1: 版数
A2: =IF(表紙!A2="","",表紙!A2) -> POSサーバー | K2: =IF(表紙!K2="","",表紙!K2) -> POSサーバ | AP2: =IF(表紙!AP2="","",表紙!AP2) -> TinNH | AT2: =IF(表紙!AT2="","",表紙!AT2) -> 45478 | AY2: =IF(表紙!AY2="","",表紙!AY2) -> DuNT | BC2: =IF(表紙!BC2="","",表紙!BC2) -> 45644 | BH2: =IF(表紙!BH2="","",表紙!BH2) -> 0.13
A4: 機能カテゴリ | H4: =IF(表紙!H4="","",表紙!H4) -> 01_商品管理 | U4: 項目 | Z4: =IF(表紙!Z4="","",表紙!Z4) -> 画面設計書 | AP4: =MID(CELL("filename",A1),FIND("]",CELL("filename",A1))+1,255) -> SC0102
B7: ■SC0102_商品詳細画面のイメージ
B48: ■画面項目定義
B50: 画面項目ID | D50: 項目 | K50: タイプ | N50: I/O | O50: 多言語 | P50: 出力 | AR50: インプット | BC50: 備考
P51: マッピングデータ | X51: 初期値 | AA51: 表示コントロール | AI51: Control enable | AR51: 必須 | AS51: 数字 | AT51: 桁 | AU51: マッピングデータ
P52: API名 | T52: 項目 | AU52: API名 | AY52: 項目
B53: 0 | D53: 画面タイトル | K53: テキスト | N53: － | O53: ● | P53: － | T53: － | X53: 商品管理(詳細)設定 | AA53: ー | AI53: － | AR53: － | AS53: ー | AT53: ー | AU53: － | AY53: ー | BC53: イベントID：SC0102-01
B54: 2 | D54: 商品情報エリア | K54: テキスト | N54: － | O54: ● | P54: － | T54: － | X54: 商品情報 | AA54: ー | AI54: ー | AR54: － | AS54: ー | AT54: ー | AU54: － | AY54: ー
B55: 3 | D55: 商品コード（タイトル） | K55: テキスト | N55: － | O55: ● | P55: － | T55: － | X55: 商品コード | AA55: ー | AI55: ー | AR55: － | AS55: ー | AT55: ー | AU55: － | AY55: ー
B56: 4 | D56: 商品コード（値） | K56: EditText | N56: O | O56: － | P56: AP0111 | T56: my_company_code (最後の6桁) | X56: － | AA56: ー | AI56: デフォルト：無効 | AR56: － | AS56: ー | AT56: ー | AU56: AP0102 | AY56: my_company_code
B57: 5 | D57: PLUコード(タイトル) | K57: テキスト | N57: － | O57: ● | P57: － | T57: － | X57: PLUコード（親） | AA57: ー | AI57: ー | AR57: － | AS57: ー | AT57: ー | AU57: － | AY57: ー
B58: 6 | D58: PLUコード(値) | K58: EditText | N58: O | O58: － | P58: AP0111 | T58: item_code | X58: － | AA58: ー | AI58: デフォルト：無効 | AR58: － | AS58: ー | AT58: ー | AU58: AP0102 | AY58: item_code
B59: 7 | D59: 税種別コード（タイトル） | K59: テキスト | N59: － | O59: ● | P59: － | T59: － | X59: 税種別コード | AA59: ー | AI59: ー | AR59: － | AS59: ー | AT59: ー | AU59: － | AY59: ー
B60: 8 | D60: 税種別コード（値） | K60: プルダウン | N60: I/O | O60: － | P60: AP0113 | T60: tax_group_code | X60: － | AA60: ー | AI60: デフォルト：無効 ユーザ権限がシステム管理者である場合のみ有効になる。 | AR60: ● | AS60: ー | AT60: ー | AU60: AP0102 | AY60: tax_group_code
B61: 9 | D61: 税率（タイトル） | K61: テキスト | N61: － | O61: ● | P61: － | T61: － | X61: 税率 | AA61: ー | AI61: ー | AR61: － | AS61: ー | AT61: ー | AU61: － | AY61: ー
B62: 10 | D62: 税率（値） | K62: EditText | N62: I/O | O62: － | P62: AP0111 | T62: tax_rate | X62: － | AA62: ー | AI62: デフォルト：無効 ユーザ権限がシステム管理者である場合のみ有効になる。 | AR62: － | AS62: ● | AT62: ー | AU62: － | AY62: ー | BC62: フォーマット： {tax_rate}%
B63: 11 | D63: 部門（タイトル） | K63: テキスト | N63: － | O63: ● | P63: － | T63: － | X63: 部門 | AA63: ー | AI63: ー | AR63: － | AS63: ー | AT63: ー | AU63: － | AY63: ー
B64: 12 | D64: 部門(値) | K64: EditText | N64: I/O | O64: － | P64: AP0111 | T64: code_level_one | X64: － | AA64: ー | AI64: デフォルト：無効 ユーザ権限がシステム管理者である場合のみ有効になる。 | AR64: ● | AS64: ● | AT64: ー | AU64: AP0102 AP0114 | AY64: code_level_one | BC64: イベントID：SC0102-05 最大2桁。
B65: 13 | D65: 部門(名称） | K65: テキスト | N65: O | O65: ● | P65: AP0111 | T65: description_level_one | X65: － | AA65: ー | AI65: ー | AR65: － | AS65: ー | AT65: ー | AU65: － | AY65: ー
B66: 14 | D66: 品群（タイトル） | K66: テキスト | N66: － | O66: ● | P66: － | T66: － | X66: 品群 | AA66: ー | AI66: ー | AR66: － | AS66: ー | AT66: ー | AU66: － | AY66: ー
B67: 15 | D67: 品群（値） | K67: EditText | N67: I/O | O67: － | P67: AP0111 | T67: code_level_two | X67: － | AA67: ー | AI67: デフォルト：無効 ユーザ権限がシステム管理者である場合のみ有効になる。 | AR67: ● | AS67: ● | AT67: ー | AU67: AP0102 AP0114 | AY67: code_level_two | BC67: イベントID：SC0102-06 最大4桁。
B68: 16 | D68: 品群（名称） | K68: テキスト | N68: O | O68: ● | P68: AP0111 | T68: description_level_two | X68: － | AA68: ー | AI68: ー | AR68: － | AS68: ー | AT68: ー | AU68: － | AY68: ー
B69: 17 | D69: 品種（タイトル） | K69: テキスト | N69: － | O69: ● | P69: － | T69: － | X69: 品種 | AA69: ー | AI69: ー | AR69: － | AS69: ー | AT69: ー | AU69: － | AY69: ー
B70: 18 | D70: 品種（値） | K70: EditText | N70: I/O | O70: － | P70: AP0111 | T70: code_level_three | X70: － | AA70: ー | AI70: デフォルト：無効 ユーザ権限がシステム管理者である場合のみ有効になる。 | AR70: ● | AS70: ● | AT70: ー | AU70: AP0102 AP0114 | AY70: code_level_three | BC70: イベントID：SC0102-07 最大4桁。
B71: 19 | D71: 品種（名称） | K71: テキスト | N71: O | O71: ● | P71: AP0111 | T71: description_level_three | X71: － | AA71: ー | AI71: ー | AR71: － | AS71: ー | AT71: ー | AU71: － | AY71: ー
B72: 20 | D72: 分類（タイトル） | K72: テキスト | N72: － | O72: ● | P72: － | T72: － | X72: 分類 | AA72: ー | AI72: ー | AR72: － | AS72: ー | AT72: ー | AU72: － | AY72: ー
B73: 21 | D73: 分類（値） | K73: EditText | N73: I/O | O73: － | P73: AP0111 | T73: code_level_four | X73: － | AA73: ー | AI73: デフォルト：無効 ユーザ権限がシステム管理者である場合のみ有効になる。 | AR73: ● | AS73: ● | AT73: ー | AU73: AP0102 AP0114 | AY73: code_level_four | BC73: イベントID：SC0102-08 最大4桁。
B74: 22 | D74: 分類（名称） | K74: テキスト | N74: O | O74: ● | P74: AP0111 | T74: description_level_four | X74: － | AA74: ー | AI74: ー | AR74: － | AS74: ー | AT74: ー | AU74: － | AY74: ー
B75: 23 | D75: 定番売価(タイトル) | K75: テキスト | N75: － | O75: ● | P75: － | T75: － | X75: 定番売価 | AA75: ー | AI75: ー | AR75: － | AS75: ー | AT75: ー | AU75: － | AY75: ー
B76: 24 | D76: 定番売価(値) | K76: EditText | N76: I/O | O76: － | P76: AP0111 | T76: standar_pride | X76: － | AA76: ー | AI76: デフォルト：有効 | AR76: ● | AS76: ● | AT76: ー | AU76: AP0102 | AY76: standar_price
B77: 25 | D77: 会員価格（タイトル） | K77: テキスト | N77: － | O77: ● | P77: － | T77: － | X77: 会員売価 | AA77: ー | AI77: ー | AR77: － | AS77: ー | AT77: ー | AU77: －
B78: 26 | D78: 会員価格（値） | K78: EditText | N78: I/O | O78: － | P78: AP0111 | T78: member_pride | X78: － | AA78: ー | AI78: デフォルト：無効 ユーザ権限がシステム管理者である場合のみ有効になる。 | AR78: ● | AS78: ● | AT78: ー | AU78: AP0102 | AY78: member_price
B79: 27 | D79: 原価（タイトル） | K79: テキスト | N79: － | O79: ● | P79: － | T79: － | X79: 原価 | AA79: ー | AI79: ー | AR79: － | AS79: ー | AT79: ー | AU79: －
B80: 28 | D80: 原価（値） | K80: EditText | N80: I/O | O80: － | P80: AP0111 | T80: original_price | X80: － | AA80: ー | AI80: デフォルト：無効 ユーザ権限がシステム管理者である場合のみ有効になる。 | AR80: ● | AS80: ● | AT80: ー | AU80: AP0102 | AY80: original_price
B81: 29 | D81: 商品名称（タイトル） | K81: テキスト | N81: － | O81: ● | P81: － | T81: － | X81: 商品名称 | AA81: ー | AI81: ー | AR81: － | AS81: ー | AT81: ー | AU81: － | AY81: ー
B82: 30 | D82: 商品名称（値） | K82: EditText | N82: I/O | O82: － | P82: AP0111 | T82: product_name | X82: － | AA82: ー | AI82: デフォルト：無効 ユーザ権限がシステム管理者である場合のみ有効になる。 | AR82: ● | AS82: ー | AT82: ー | AU82: AP0102 | AY82: product_name
B83: 31 | D83: レシート商品名称（タイトル） | K83: テキスト | N83: － | O83: ● | P83: － | T83: － | X83: レシート商品名称 | AA83: ー | AI83: ー | AR83: － | AS83: ー | AT83: ー | AU83: －
B84: 32 | D84: レシート商品名称（値） | K84: EditText | N84: I/O | O84: － | P84: AP0111 | T84: receipt_name | X84: － | AA84: ー | AI84: デフォルト：無効 ユーザ権限がシステム管理者である場合のみ有効になる。 | AR84: ● | AS84: ー | AT84: ー | AU84: AP0102 | AY84: receipt_name
...

Sheet MD0102
A1: システム名 | K1: システム種別 | W1: =IF(表紙!W1="","",表紙!W1) -> 詳細設計書 | AP1: 作成者 | AT1: 作成日 | AY1: 更新者 | BC1: 更新日 | BH1: 版数
A2: =IF(表紙!A2="","",表紙!A2) -> POSサーバー | K2: =IF(表紙!K2="","",表紙!K2) -> POSサーバ | AP2: =IF(表紙!AP2="","",表紙!AP2) -> TinNH | AT2: =IF(表紙!AT2="","",表紙!AT2) -> 45478 | AY2: =IF(表紙!AY2="","",表紙!AY2) -> DuNT | BC2: =IF(表紙!BC2="","",表紙!BC2) -> 45644 | BH2: =IF(表紙!BH2="","",表紙!BH2) -> 0.13
A4: 機能カテゴリ | H4: =IF(表紙!H4="","",表紙!H4) -> 01_商品管理 | U4: 項目 | Z4: =IF(表紙!Z4="","",表紙!Z4) -> 画面設計書 | AP4: =MID(CELL("filename",A1),FIND("]",CELL("filename",A1))+1,255) -> MD0102
B7: ■MD0102_プロモーション一覧モーダルのイメージ
B44: ■画面項目定義
B46: 画面項目ID | D46: 項目 | K46: タイプ | N46: I/O | O46: 多言語 | P46: 出力 | AR46: インプット | BC46: 備考
P47: マッピングデータ | X47: 初期値 | AA47: 表示コントロール | AI47: Control enable | AR47: 必須 | AS47: 数字 | AT47: 桁 | AU47: マッピングデータ
P48: API名 | T48: 項目 | AU48: API名 | AY48: 項目
B49: 0 | D49: 画面タイトル | K49: テキスト | N49: － | O49: ● | P49: － | T49: － | X49: プロモーション検索 | AA49: ー | AI49: ー | AR49: － | AS49: ー | AT49: ー | AU49: － | AY49: ー | BC49: イベントID：MD0102-01
B50: 1 | D50: 戻る | K50: ボタン | N50: I | O50: ● | P50: － | T50: － | X50: 前画面 | AA50: ー | AI50: デフォルト：有効 | AR50: － | AS50: ー | AT50: ー | AU50: － | AY50: ー | BC50: イベントID：MD0102-02
B51: 2 | D51: プロモーションコード（タイトル） | K51: テキスト | N51: － | O51: ● | P51: － | T51: － | X51: プロモーションコード | AA51: ー | AI51: ー | AR51: － | AS51: ー | AT51: ー | AU51: － | AY51: ー | BC51: ー
B52: 2.1 | D52: プロモーションコード(値) | K52: EditText | N52: I | O52: － | P52: － | T52: － | X52: － | AA52: ー | AI52: デフォルト：有効 | AR52: ● | AS52: ● | AT52: ー | AU52: AP0105 | AY52: code | BC52: 最大桁数：5
B53: 3 | D53: 検索 | K53: ボタン | N53: I | O53: ● | P53: － | T53: － | X53: 検索 | AA53: ー | AI53: デフォルト：有効 | AR53: － | AS53: ー | AT53: ー | AU53: － | AY53: ー | BC53: イベントID：MD0102-03
B54: 4 | D54: 選択（タイトル） | K54: テキスト | N54: － | O54: ● | P54: － | T54: － | X54: 選択 | AA54: ー | AI54: ー | AR54: － | AS54: ー | AT54: ー | AU54: － | AY54: ー | BC54: ー
B55: 4.1 | D55: 選択（値) | K55: ボタン | N55: I | O55: ● | P55: － | T55: － | X55: 選択 | AA55: ー | AI55: デフォルト：有効 | AR55: － | AS55: ー | AT55: ー | AU55: － | AY55: ー | BC55: イベントID：MD0102-04
B56: 5 | D56: プロモーションコード（タイトル） | K56: テキスト | N56: － | O56: ● | P56: － | T56: － | X56: プロモーション | AA56: ー | AI56: ー | AR56: － | AS56: ー | AT56: ー | AU56: － | AY56: ー | BC56: ー
B57: 5.1 | D57: プロモーションコード(値) | K57: テキスト | N57: I/O | O57: － | P57: AP0105 | T57: code | X57: － | AA57: ー | AR57: － | AS57: － | AT57: ー | AU57: － | AY57: ー | BC57: ー
B58: 6 | D58: プロモーション名称（タイトル） | K58: テキスト | N58: － | O58: ● | P58: － | T58: － | X58: 名称 | AA58: ー | AI58: ー | AR58: － | AS58: ー | AT58: ー | AU58: － | AY58: ー | BC58: ー
B59: 6.1 | D59: プロモーション名称（値） | K59: テキスト | N59: I/O | O59: － | P59: AP0105 | T59: name | X59: － | AA59: ー | AR59: － | AS59: － | AT59: ー | AU59: － | AY59: ー | BC59: ー
B60: 7 | D60: 開始日時（タイトル） | K60: テキスト | N60: － | O60: ● | P60: － | T60: － | X60: 開始日時 | AA60: ー | AI60: ー | AR60: － | AS60: ー | AT60: ー | AU60: － | AY60: ー | BC60: ー
B61: 7.1 | D61: 開始日時（値） | K61: テキスト | N61: I/O | O61: － | P61: AP0105 | T61: start_date_time start_time | X61: － | AA61: ー | AR61: － | AS61: － | AT61: ー | AU61: － | AY61: ー | BC61: 形式：yy/mm/dd hh:mm
B62: 8 | D62: 終了日時（タイトル） | K62: テキスト | N62: － | O62: ● | P62: － | T62: － | X62: 終了日時 | AA62: ー | AI62: ー | AR62: － | AS62: ー | AT62: ー | AU62: － | AY62: ー | BC62: ー
B63: 8.1 | D63: 終了日時（値） | K63: テキスト | N63: I/O | O63: － | P63: AP0105 | T63: end_date_time end_time | X63: － | AA63: ー | AR63: － | AS63: － | AT63: ー | AU63: － | AY63: ー | BC63: 形式：yy/mm/dd hh:mm
B64: 9 | D64: 商品コード（タイトル） | K64: テキスト | N64: － | O64: ● | P64: － | T64: － | X64: 商品コード | AA64: 商品ミックスマッチモードで表示されている場合、表示する。 上記以外の場合、表示しない。 | AI64: ー | AR64: － | AS64: ー | AT64: ー | AU64: － | AY64: －
B65: 9.1 | D65: 商品コード（値） | K65: テキスト | N65: I/O | O65: － | P65: AP1506 | T65: my_company_code (最後の8桁) | X65: － | AA65: 商品ミックスマッチモードで表示されている場合、表示する。 上記以外の場合、表示しない。 | AI65: ー | AR65: － | AS65: ー | AT65: ー | AU65: － | AY65: －
B66: 10 | D66: PLUコード(タイトル) | K66: テキスト | N66: － | O66: ● | P66: － | T66: － | X66: PLUコード | AA66: 商品ミックスマッチモードで表示されている場合、表示する。 上記以外の場合、表示しない。 | AI66: ー | AR66: － | AS66: ー | AT66: ー | AU66: － | AY66: －
B67: 10.1 | D67: PLUコード(値) | K67: テキスト | N67: I/O | O67: － | P67: AP1506 | T67: item_code | X67: － | AA67: 商品ミックスマッチモードで表示されている場合、表示する。 上記以外の場合、表示しない。 | AI67: ー | AR67: － | AS67: ー | AT67: ー | AU67: － | AY67: －
B68: 11 | D68: 商品名称（タイトル） | K68: テキスト | N68: － | O68: ● | P68: － | T68: － | X68: 商品名称 | AA68: 商品ミックスマッチモードで表示されている場合、表示する。 上記以外の場合、表示しない。 | AI68: ー | AR68: － | AS68: ー | AT68: ー | AU68: － | AY68: ー
B69: 11.1 | D69: 商品名称（値） | K69: テキスト | N69: － | O69: － | P69: AP1506 | T69: desciption | X69: － | AA69: 商品ミックスマッチモードで表示されている場合、表示する。 上記以外の場合、表示しない。 | AI69: ー | AR69: － | AS69: ー | AT69: ー | AU69: － | AY69: ー
B70: 12 | D70: 定番売価(タイトル) | K70: テキスト | N70: － | O70: ● | P70: － | T70: － | X70: 定番売価 | AA70: 商品ミックスマッチモードで表示されている場合、表示する。 上記以外の場合、表示しない。 | AI70: ー | AR70: － | AS70: ー | AT70: ー | AU70: － | AY70: ー
B71: 12.1 | D71: 定番売価(値) | K71: テキスト | N71: O | O71: － | P71: AP1506 | T71: unit_price | X71: － | AA71: 商品ミックスマッチモードで表示されている場合、表示する。 上記以外の場合、表示しない。 | AI71: ー | AR71: － | AS71: ー | AT71: ー | AU71: － | AY71: ー

Sheet SC0103
A1: システム名 | K1: システム種別 | W1: =IF(表紙!W1="","",表紙!W1) -> 詳細設計書 | AP1: 作成者 | AT1: 作成日 | AY1: 更新者 | BC1: 更新日 | BH1: 版数
A2: =IF(表紙!A2="","",表紙!A2) -> POSサーバー | K2: =IF(表紙!K2="","",表紙!K2) -> POSサーバ | AP2: =IF(表紙!AP2="","",表紙!AP2) -> TinNH | AT2: =IF(表紙!AT2="","",表紙!AT2) -> 45478 | AY2: =IF(表紙!AY2="","",表紙!AY2) -> DuNT | BC2: =IF(表紙!BC2="","",表紙!BC2) -> 45644 | BH2: =IF(表紙!BH2="","",表紙!BH2) -> 0.13
A4: 機能カテゴリ | H4: =IF(表紙!H4="","",表紙!H4) -> 01_商品管理 | U4: 項目 | Z4: =IF(表紙!Z4="","",表紙!Z4) -> 画面設計書 | AP4: =MID(CELL("filename",A1),FIND("]",CELL("filename",A1))+1,255) -> SC0103
B7: ■緊急売価変更画面のイメージ
E37: 項目ID10に自動フォーカスする
B39: ■画面項目定義
B41: 画面項目ID | D41: 項目 | K41: タイプ | N41: I/O | O41: 多言語 | P41: 出力 | AR41: インプット | BC41: 備考
P42: マッピングデータ | X42: 初期値 | AA42: 表示コントロール | AI42: Control enable | AR42: 必須 | AS42: 数字 | AT42: 桁 | AU42: マッピングデータ
P43: API名 | T43: 項目 | AU43: API名 | AY43: 項目
B44: 0 | D44: 画面タイトル | K44: テキスト | N44: － | O44: ● | P44: － | T44: － | X44: 緊急売価変更 | AA44: ー | AI44: ー | AR44: － | AS44: － | AT44: － | AU44: － | AY44: ー | BC44: イベントID：SC0103-01をご参照ください。
B45: 1 | D45: 部門コード（タイトル） | K45: テキスト | N45: － | O45: ● | P45: － | T45: － | X45: 部門コード＊ | AA45: ー | AI45: ー | AR45: － | AS45: － | AT45: － | AU45: － | AY45: ー | BC45: ー
B46: 2 | D46: 部門コード（値） | K46: テキスト | N46: O | O46: － | P46: － | T46: － | X46: ー | AA46: ー | AI46: ー | AR46: － | AS46: － | AT46: － | AU46: － | AY46: ー | BC46: ー
B47: 3 | D47: 商品コード（タイトル） | K47: テキスト | N47: － | O47: ● | P47: － | T47: － | X47: 商品コード＊ | AA47: ー | AI47: ー | AR47: － | AS47: － | AT47: － | AU47: － | AY47: ー | BC47: ー
B48: 4 | D48: 商品コード（値） | K48: テキスト | N48: O | O48: － | P48: － | T48: － | X48: ー | AA48: ー | AI48: ー | AR48: － | AS48: － | AT48: － | AU48: － | AY48: ー | BC48: ー
B49: 5 | D49: PLUコード（タイトル） | K49: テキスト | N49: － | O49: ● | P49: － | T49: － | X49: PLUコード | AA49: ー | AI49: ー | AR49: － | AS49: － | AT49: － | AU49: － | AY49: ー | BC49: ー
B50: 6 | D50: PLUコード（値） | K50: テキスト | N50: O | O50: － | P50: － | T50: － | X50: ー | AA50: ー | AI50: ー | AR50: － | AS50: － | AT50: － | AU50: － | AY50: ー | BC50: ー
B51: 7 | D51: 商品名称（タイトル） | K51: テキスト | N51: － | O51: ● | P51: － | T51: － | X51: 商品名称 | AA51: ー | AI51: ー | AR51: － | AS51: － | AT51: － | AU51: － | AY51: ー | BC51: ー
B52: 8 | D52: 商品名称（値） | K52: テキスト | N52: O | O52: － | P52: － | T52: － | X52: － | AA52: ー | AI52: ー | AR52: － | AS52: － | AT52: － | AU52: － | AY52: ー | BC52: ー
B53: 9 | D53: 本日売価（タイトル） | K53: テキスト | N53: － | O53: ● | P53: － | T53: － | X53: 本日売価* | AA53: ー | AI53: ー | AR53: － | AS53: － | AT53: － | AU53: － | AY53: ー | BC53: ー
B54: 10 | D54: 本日売価（値） | K54: EditText | N54: I/O | O54: － | P54: － | T54: － | X54: － | AA54: ー | AI54: ー | AR54: ● | AS54: ● | AT54: － | AU54: － | AY54: ー | BC54: 最大数字の6桁。
B55: 11 | D55: 定番売価(タイトル） | K55: テキスト | N55: － | O55: ● | P55: － | T55: － | X55: 定番売価 | AA55: ー | AI55: ー | AR55: － | AS55: － | AT55: － | AU55: － | AY55: ー | BC55: ー
... B60: 16 | D60: 印刷（ヘッダー） | K60: ボタン | N60: I | O60: ● | P60: － | T60: － | X60: － | AA60: ー | AI60: ー | AR60: － | AS60: － | AT60: － | AU60: － | AY60: ー | BC60: イベントID：SC0103-05

Sheet テンプレート
A1: システム名 | K1: システム種別 | W1: =IF(表紙!W1="","",表紙!W1) -> 詳細設計書 | AP1: 作成者 | AT1: 作成日 | AY1: 更新者 | BC1: 更新日 | BH1: 版数
A2: =IF(表紙!A2="","",表紙!A2) -> POSサーバー | K2: =IF(表紙!K2="","",表紙!K2) -> POSサーバ | AP2: =IF(表紙!AP2="","",表紙!AP2) -> TinNH | AT2: =IF(表紙!AT2="","",表紙!AT2) -> 45478 | AY2: =IF(表紙!AY2="","",表紙!AY2) -> DuNT | BC2: =IF(表紙!BC2="","",表紙!BC2) -> 45644 | BH2: =IF(表紙!BH2="","",表紙!BH2) -> 0.13
A4: 機能カテゴリ | H4: =IF(表紙!H4="","",表紙!H4) -> 01_商品管理 | U4: 項目 | Z4: =IF(表紙!Z4="","",表紙!Z4) -> 画面設計書 | AP4: =MID(CELL("filename",A1),FIND("]",CELL("filename",A1))+1,255) -> テンプレート
B7: ■イメージ
B50: ■画面項目定義
B52: 画面項目ID | D52: 項目 | K52: Type | N52: I/O | O52: 多言語 | P52: 出力 | AR52: インプット | BC52: 備考
P53: マッピングデータ | X53: 初期値 | AA53: 表示コントロール | AI53: Control enable | AR53: 必須 | AS53: 数字 | AT53: 桁 | AU53: マッピングデータ
P54: API名 | T54: 項目 | AU54: API名 | AY54: 項目
B55: 0 | AR55: － | AS55: ー | AT55: ー | AU55: － | AY55: ー | BC55: イベントID：SC0101-01
B56: 1 | AR56: － | AS56: ー | AT56: ー | AU56: － | AY56: ー
B57: 2 | AR57: － | AS57: ー | AT57: ー | AU57: － | AY57: ー
B58: 3 | AR58: － | AS58: ー | AT58: ー | AU58: － | AY58: ー
B59: 4 | AR59: － | AS59: ー | AT59: ー | AU59: － | AY59: ー
