Workbook

Sheet 表紙
A1: システム名 | K1: システム種別 | W1: 詳細設計書 | AP1: 作成者 | AT1: 作成日 | AY1: 更新者 | BC1: 更新日 | BH1: 版数
A2: POSサーバー | K2: POSサーバ | AP2: =改訂履歴!$H$11 -> LoiLv | AT2: =改訂履歴!$B$11 -> 45460 | AY2: =LOOKUP(2,1/(改訂履歴!H11:H30000<>""),改訂履歴!H11:H30000) -> TuyenNH | BC2: =LOOKUP(2,1/(改訂履歴!B11:B30000<>""),改訂履歴!B11:B30000) -> 45601 | BH2: =LOOKUP(2,1/(改訂履歴!O11:O30000<>""),改訂履歴!O11:O30000) -> 0.16
A4: 機能カテゴリ | H4: 21_ジャーナル検索 | U4: 項目 | Z4: 画面設計書 | AP4: {=RIGHT(CELL("filename",$A$1),LEN(CELL("filename",$A$1))-FIND("]",CELL("filename",$A$1)))} -> 表紙
L16: POSサーバーの基本設計書
L24: =K2&"/"&H4&"/"&Z4 -> POSサーバ/21_ジャーナル検索/画面設計書
Q44: 承認日 | AA44: 承認者 | AQ44: 版数

Sheet 改訂履歴
A1: システム名 | K1: システム種別 | W1: =IF(表紙!W1="","",表紙!W1) -> 詳細設計書 | AP1: 作成者 | AT1: 作成日 | AY1: 更新者 | BC1: 更新日 | BH1: 版数
A2: =IF(表紙!A2="","",表紙!A2) -> POSサーバー | K2: =IF(表紙!K2="","",表紙!K2) -> POSサーバ | AP2: =IF(表紙!AP2="","",表紙!AP2) -> LoiLv | AT2: =IF(表紙!AT2="","",表紙!AT2) -> 45460 | AY2: =IF(表紙!AY2="","",表紙!AY2) -> TuyenNH | BC2: =IF(表紙!BC2="","",表紙!BC2) -> 45601 | BH2: =IF(表紙!BH2="","",表紙!BH2) -> 0.16
A4: 機能カテゴリ | H4: =IF(表紙!H4="","",表紙!H4) -> 21_ジャーナル検索 | U4: 項目 | Z4: =IF(表紙!Z4="","",表紙!Z4) -> 画面設計書 | AP4: {=RIGHT(CELL("filename",$A$1),LEN(CELL("filename",$A$1))-FIND("]",CELL("filename",$A$1)))} -> 改訂履歴
B8: ■改訂履歴
B10: 更新日 | H10: 更新者 | O10: 版数 | S10: 更新内容 | AX10: 承認日 | BD10: 承認者
B11: 45460 | H11: LoiLv | O11: 0.1 | S11: 新規
B13: 45523 | H13: AnhDD | O13: 0.2 | S13: 2024年08月15日のご指摘： 1. 結果表示エリアのフィールド順序を修正する。 2. ジャーナルNoを追加する。 3. ページングを削除する。
B15: 45530 | H15: AnhDDD | O15: 0.3 | S15: 2024年08月20日のご指摘：イラストのみ修正 1. 担当者フィールド（検索条件）を最下部に配置する. 2. 画面表示時にデフォルト値を画像に追加する.
B17: 45533 | H17: AnhNM | O17: 0.4 | S17: SC2101
S18: [ジャーナルNo]項目を削除
B19: 45580 | H19: TuyenNH | O19: 0.14 | S19: 新たなレイアウトより資料更新
S20: [SC2101]シート
B21: 45596 | H21: TuyenNH | O21: 0.15 | S21: 1. 検索エリアの位置を画面の上部に移動 2. 年の形式は末尾2桁のみを表示する。 3. 「時間帯」項目は時間と分を同時に選択する。 4. 検索結果エリアに「全選択」「全解除」項目を追加 5. 各項目に並び替え（▲/▼）ボタンを追加
S22: [SC2101]シート
B23: 45601 | H23: TuyenNH | O23: 0.16 | S23: 「レシート区分」項目と「モード」を追加
S24: [SC2101]シート

Sheet SC2101
A1: システム名 | K1: システム種別 | W1: =IF(表紙!W1="","",表紙!W1) -> 詳細設計書 | AP1: 作成者 | AT1: 作成日 | AY1: 更新者 | BC1: 更新日 | BH1: 版数
A2: =IF(表紙!A2="","",表紙!A2) -> POSサーバー | K2: =IF(表紙!K2="","",表紙!K2) -> POSサーバ | AP2: =IF(表紙!AP2="","",表紙!AP2) -> LoiLv | AT2: =IF(表紙!AT2="","",表紙!AT2) -> 45460 | AY2: =IF(表紙!AY2="","",表紙!AY2) -> TuyenNH | BC2: =IF(表紙!BC2="","",表紙!BC2) -> 45601 | BH2: =IF(表紙!BH2="","",表紙!BH2) -> 0.16
A4: 機能カテゴリ | H4: =IF(表紙!H4="","",表紙!H4) -> 21_ジャーナル検索 | U4: 項目 | Z4: =IF(表紙!Z4="","",表紙!Z4) -> 画面設計書 | AP4: =MID(CELL("filename",A1),FIND("]",CELL("filename",A1))+1,255) -> SC2101
B7: ■イメージ
C8: 店舗選択エリア
B47: ■画面項目定義
B49: 画面項目ID | D49: 項目 | K49: タイプ | N49: I/O | O49: 多言語 | P49: 出力 | AR49: インプット | BC49: 備考
P50: マッピングデータ | X50: 初期値 | AA50: 表示コントロール | AI50: Control enable | AR50: 必須 | AS50: 数字 | AT50: 桁 | AU50: マッピングデータ
P51: API名 | T51: 項目 | AU51: API名 | AY51: 項目
B52: ヘッダーエリア
B53: 0 | D53: 画面名 | K53: テキスト | N53: － | O53: ● | P53: － | T53: － | X53: ジャーナル検索 | AA53: ー | AI53: － | AR53: － | AS53: ー | AT53: ー | AU53: － | AY53: ー | BC53: イベントID：SC2101-01
B54: 1 | D54: CSV出力 | K54: ボタン | N54: － | O54: － | P54: － | T54: － | X54: － | AA54: － | AE54: － | AI54: レコードがチェック状態の場合 | AR54: － | AS54: ー | AT54: ー | AU54: － | AY54: ー | BC54: イベントID：SC2101-04
B55: 2 | D55: 印刷 | K55: ボタン | N55: － | O55: － | P55: － | T55: － | X55: － | AA55: － | AE55: － | AI55: レコードがチェック状態の場合 | AR55: － | AS55: ー | AT55: ー | AU55: － | AY55: ー | BC55: イベントID：SC2101-03
B56: 検索エリア
D57: 店舗選択エリア | P57: － | T57: － | X57: － | AA57: ユーザーが複数店舗(00, 01)の操作権限を持つ場合は表示する。 | AI57: － | AR57: － | AS57: ー | AT57: ー | AU57: － | AY57: ー
B58: 3 | D58: 店舗選択 | K58: テキスト | N58: － | O58: ● | P58: － | T58: － | X58: 店舗選択 | AA58: ー | AI58: － | AR58: － | AS58: ー | AT58: ー | AU58: － | AY58: ー | BC58: 店舗選択エリアを表示する。
B60: ■ユーザーがシステム権限を持つ場合のイメージ - 検索エリア
B98: ■画面項目定義
B100: 画面項目ID | D100: 項目 | K100: Type | N100: I/O | O100: 多言語 | P100: 出力 | AR100: インプット | BC100: 備考
P101: マッピングデータ | X101: 初期値 | AA101: 表示コントロール | AI101: Control enable | AR101: 必須 | AS101: 数字 | AT101: 桁 | AU101: マッピングデータ
P102: API名 | T102: 項目 | AU102: API名 | AY102: 項目
B103: 検索エリア
D104: 検索条件入力エリア | P104: － | T104: － | X104: － | AA104: － | AI104: － | AR104: － | AS104: ー | AT104: ー | AU104: － | AY104: ー
B105: 4 | D105: 営業日（タイトル） | K105: テキスト | N105: － | O105: ● | P105: － | T105: － | X105: 営業日 | AA105: ー | AI105: ー | AR105: － | AS105: ー | AT105: ー | AU105: － | AY105: ー | BC105: －
B106: 4.1 | D106: 開始営業日（値） | K106: DatePicker | N106: I | O106: ● | P106: － | T106: － | X106: 現在日（曜日） | AA106: ー | AI106: デフォルト：有効 店舗が未入力の場合は無効にする | AR106: ● | AS106: ー | AT106: ー | AU106: AP2102 | AY106: business_date_from | BC106: 形式：yy/MM/dd(E) date pickerタイプを選択するか、edit textタイプを入力できる。入力すると、曜日を自動的に埋め込む。
B107: 4.2 | D107: 終了営業日（値） | K107: DatePicker | N107: I | O107: ● | P107: － | T107: － | X107: 現在日（曜日） | AA107: ー | AI107: デフォルト：有効 店舗が未入力の場合は無効にする | AR107: ● | AS107: ー | AT107: ー | AU107: AP2102 | AY107: business_date_to | BC107: 形式：yy/MM/dd(E) date pickerタイプを選択するか、edit textタイプを入力できる。入力すると、曜日を自動的に埋め込む。
B108: 5 | D108: 時間帯（タイトル） | K108: テキスト | N108: － | O108: ● | P108: － | T108: － | X108: 時間帯 | AA108: ー | AI108: ー | AR108: － | AS108: ー | AT108: ー | AU108: － | AY108: ー
B109: 5.1 | D109: 開始時間帯（値） | K109: TimePicker | N109: I | O109: － | P109: － | T109: － | X109: 0 | AA109: ー | AI109: デフォルト：有効 店舗が未入力の場合は無効にする | AR109: ● | AS109: ー | AT109: ー | AU109: AP2102 | AY109: business_time_from | BC109: 形式：HH:mm date pickerタイプを選択するか、edit textタイプを入力できる。
B110: 5.2 | D110: 終了時間帯（値） | K110: TimePicker | N110: I | O110: － | P110: － | T110: － | X110: 0.99930556 | AA110: ー | AI110: デフォルト：有効 店舗が未入力の場合は無効にする | AR110: ● | AS110: ー | AT110: ー | AU110: AP2102 | AY110: business_time_to | BC110: 形式：HH:mm date pickerタイプを選択するか、edit textタイプを入力できる。
B111: 6 | D111: レジ（タイトル） | K111: テキスト | N111: － | O111: ● | P111: － | T111: － | X111: レジ | AA111: ー | AI111: － | AR111: － | AS111: ー | AT111: ー | AU111: － | AY111: ー
B112: 6.1 | D112: レジ（値） | K112: プルダウン | N112: I/O | O112: － | P112: AP7103 | T112: code, name | X112: ブランク | AA112: ー | AI112: デフォルト：有効 店舗が未入力の場合は無効にする | AR112: － | AS112: ー | AT112: ー | AU112: AP2102 | AY112: cash_register_code | BC112: ・表示形式： [コード : 名称]。1つの値のみ選択 ・プルダウンの値: 行1：ブランク、次の行：「AP7103」APIからのもの
B113: 7 | D113: 担当者（タイトル） | K113: テキスト | N113: － | O113: ● | P113: － | T113: － | X113: 担当者 | AA113: ー | AI113: － | AR113: － | AS113: ー | AT113: ー | AU113: － | AY113: ー
B114: 7.1 | D114: 担当者（値） | K114: プルダウン | N114: I/O | O114: － | P114: AP4001 | T114: code, name | X114: ブランク | AA114: ー | AI114: デフォルト：有効 店舗が未入力の場合は無効にする | AR114: － | AS114: ー | AT114: ー | AU114: AP2102 | AY114: employee_code | BC114: ・表示形式： [コード : 名称]。1つの値のみ選択 ・プルダウンの値: 行1：ブランク、次の行：「AP4001」APIからのもの
B115: 8 | D115: 任意文字列1（タイトル） | K115: テキスト | N115: － | O115: ● | P115: － | T115: － | X115: 任意文字列 | AA115: ー | AI115: － | AR115: － | AS115: ー | AT115: ー | AU115: － | AY115: ー
B116: 8.1 | D116: 任意文字列1（値） | K116: EditText | N116: I | O116: － | P116: － | T116: － | AA116: ー | AI116: デフォルト：有効 店舗が未入力の場合は無効にする | AR116: － | AS116: ● | AT116: ● | AU116: AP2102 | AY116: keyword_1 | BC116: 最大全角25文字 最大半角50文字
B117: 9 | D117: 条件組み合わせタイプ | K117: ラジオボタン | N117: I | O117: － | P117: － | T117: － | X117: OR/AND | AA117: ー | AI117: デフォルト：有効 店舗が未入力の場合は無効にする | AR117: － | AS117: ● | AT117: ー | AU117: AP2102 | AY117: condition_type | BC117: 伝送値： 0: Or 1: And
B118: 10 | D118: 任意文字列2（値） | K118: テキスト | N118: － | O118: ● | P118: － | T118: － | X118: 任意文字列2 | AA118: ー | AI118: － | AR118: － | AS118: ー | AT118: ー | AU118: － | AY118: ー
B119: 10.1 | D119: 任意文字列2（値） | K119: EditText | N119: I | O119: － | P119: － | T119: － | AA119: ー | AI119: デフォルト：有効 店舗が未入力の場合は無効にする | AR119: － | AS119: ● | AT119: ● | AU119: AP2102 | AY119: keyword_2 | BC119: 最大全角25文字 最大半角50文字
B120: 11 | D120: レシートNo.（タイトル） | K120: テキスト | N120: － | O120: ● | P120: － | T120: － | X120: レシートNo. | AA120: ー | AI120: － | AR120: － | AS120: ー | AT120: ー | AU120: － | AY120: ー
B121: 11.1 | D121: 開始レシートNo.(値) | K121: EditText | N121: I | O121: － | P121: － | T121: － | AA121: ー | AI121: デフォルト：有効 店舗が未入力の場合は無効にする | AR121: － | AS121: ● | AT121: ー | AU121: AP2102 | AY121: receipt_no_from | BC121: 最大4桁。
...
