Workbook

Sheet 表紙
A1: システム名 | K1: システム種別 | W1: 詳細設計書 | AP1: 作成者 | AT1: 作成日 | AY1: 更新者 | BC1: 更新日 | BH1: 版数
A2: POSサーバー | K2: POSサーバ | AP2: =改訂履歴!$H$11 -> DuNT | AT2: =改訂履歴!$B$11 -> 45611 | AY2: =LOOKUP(2,1/(改訂履歴!H11:H30000<>""),改訂履歴!H11:H30000) -> DuNT | BC2: =LOOKUP(2,1/(改訂履歴!B11:B30000<>""),改訂履歴!B11:B30000) -> 45611 | BH2: =LOOKUP(2,1/(改訂履歴!O11:O30000<>""),改訂履歴!O11:O30000) -> 0.1
A4: 機能カテゴリ | H4: 82_店舗マスタ設定 | U4: 項目 | Z4: 画面設計書 | AP4: {=RIGHT(CELL("filename",$A$1),LEN(CELL("filename",$A$1))-FIND("]",CELL("filename",$A$1)))} -> 表紙
L16: POSサーバーの詳細設計書
L24: =K2&"/"&H4&"/"&Z4 -> POSサーバ/82_店舗マスタ設定/画面設計書
Q44: 承認日 | AA44: 承認者 | AQ44: 版数

Sheet 改訂履歴
A1: システム名 | K1: システム種別 | W1: =IF(表紙!W1="","",表紙!W1) -> 詳細設計書 | AP1: 作成者 | AT1: 作成日 | AY1: 更新者 | BC1: 更新日 | BH1: 版数
A2: =IF(表紙!A2="","",表紙!A2) -> POSサーバー | K2: =IF(表紙!K2="","",表紙!K2) -> POSサーバ | AP2: =IF(表紙!AP2="","",表紙!AP2) -> DuNT | AT2: =IF(表紙!AT2="","",表紙!AT2) -> 45611 | AY2: =IF(表紙!AY2="","",表紙!AY2) -> DuNT | BC2: =IF(表紙!BC2="","",表紙!BC2) -> 45611 | BH2: =IF(表紙!BH2="","",表紙!BH2) -> 0.1
A4: 機能カテゴリ | H4: =IF(表紙!H4="","",表紙!H4) -> 82_店舗マスタ設定 | U4: 項目 | Z4: =IF(表紙!Z4="","",表紙!Z4) -> 画面設計書 | AP4: {=RIGHT(CELL("filename",$A$1),LEN(CELL("filename",$A$1))-FIND("]",CELL("filename",$A$1)))} -> 改訂履歴
B8: ■改訂履歴
B10: 更新日 | H10: 更新者 | O10: 版数 | S10: 更新内容 | AX10: 承認日 | BD10: 承認者
B11: 45611 | H11: DuNT | O11: 0.1 | S11: 新規

Sheet SC8201
A1: システム名 | K1: システム種別 | W1: =IF(表紙!W1="","",表紙!W1) -> 詳細設計書 | AP1: 作成者 | AT1: 作成日 | AY1: 更新者 | BC1: 更新日 | BH1: 版数
A2: =IF(表紙!A2="","",表紙!A2) -> POSサーバー | K2: =IF(表紙!K2="","",表紙!K2) -> POSサーバ | AP2: =IF(表紙!AP2="","",表紙!AP2) -> DuNT | AT2: =IF(表紙!AT2="","",表紙!AT2) -> 45611 | AY2: =IF(表紙!AY2="","",表紙!AY2) -> DuNT | BC2: =IF(表紙!BC2="","",表紙!BC2) -> 45611 | BH2: =IF(表紙!BH2="","",表紙!BH2) -> 0.1
A4: 機能カテゴリ | H4: =IF(表紙!H4="","",表紙!H4) -> 82_店舗マスタ設定 | U4: 項目 | Z4: =IF(表紙!Z4="","",表紙!Z4) -> 画面設計書 | AP4: =MID(CELL("filename",A1),FIND("]",CELL("filename",A1))+1,255) -> SC8201
B7: ■初期化のイメージ
B39: ■画面項目定義
B41: 画面項目ID | D41: 項目 | K41: タイプ | N41: I/O | O41: 多言語 | P41: 出力 | AR41: インプット | BC41: 備考
P42: マッピングデータ | X42: 初期値 | AA42: 表示コントロール | AI42: Control enable | AR42: 必須 | AS42: 数字 | AT42: 桁 | AU42: マッピングデータ
P43: API名 | T43: 項目 | AU43: API名 | AY43: 項目
B44: 0 | D44: 画面タイトル | K44: テキスト | N44: － | O44: ● | P44: － | T44: － | X44: 店舗マスタ設定 | AA44: ー | AI44: － | AR44: － | AS44: ー | AT44: ー | AU44: － | AY44: ー | BC44: イベントID：SC8201-01
B45: 1 | D45: 店舗コード（タイトル） | K45: テキスト | N45: － | O45: ● | P45: － | T45: － | X45: 店舗コード | AA45: ー | AI45: － | AR45: － | AS45: ー | AT45: ー | AU45: － | AY45: ー
B46: 2 | D46: 店舗コード（値） | K46: EditText | N46: I | O46: － | P46: － | T46: － | X46: － | AA46: ー | AI46: 店舗が選択された場合のみ有効になる。 | AR46: － | AS46: ● | AT46: ー | AU46: AP8201 | AY46: code | BC46: 最大5桁
B47: 3 | D47: 店舗コード検索タイプ | K47: ドロップダウン | N47: I | O47: － | P47: － | X47: を含む/から始まる/で終わる | AA47: ー | AI47: 店舗が選択された場合のみ有効になる。 | AR47: － | AS47: ー | AT47: ー | AU47: AP8201 | AY47: code_filter_type
B48: 4 | D48: 店舗名称（タイトル） | K48: テキスト | N48: － | O48: ● | P48: － | T48: － | X48: 店舗名称 | AA48: ー | AI48: ー | AR48: － | AS48: ー | AT48: ー | AU48: － | AY48: ー
B49: 5 | D49: 店舗名称（値） | K49: EditText | N49: I | O49: － | P49: － | T49: － | X49: － | AA49: ー | AI49: 店舗が選択された場合のみ有効になる。 | AR49: － | AS49: ー | AT49: ー | AU49: － | AY49: name
B50: 6 | D50: 店舗名称検索タイプ | K50: ドロップダウン | N50: I | O50: － | P50: － | T50: － | X50: を含む/から始まる/で終わる | AA50: ー | AI50: 店舗が選択された場合のみ有効になる。 | AR50: － | AS50: ー | AT50: ー | AU50: AP8201 | AY50: name_filter_type
B51: 7 | D51: 業態（タイトル） | K51: テキスト | N51: I | O51: － | P51: － | T51: － | X51: 業態 | AA51: ー | AI51: 店舗が選択された場合のみ有効になる。 | AR51: － | AS51: ー | AT51: ー | AU51: － | AY51: －
B52: 8 | D52: 業態（値） | K52: ドロップダウン | N52: I | O52: － | P52: － | T52: － | X52: 1: FO 2: FS 3: FM 4: BL | AA52: ー | AI52: 店舗が選択された場合のみ有効になる。 | AR52: － | AS52: ー | AT52: ー | AU52: AP8201 | AY52: store_type
B53: 9 | D53: 検索 | K53: ボタン | N53: I | O53: － | P53: － | T53: － | X53: F12：検索 | AA53: ー | AI53: 店舗が選択された場合のみ有効になる。 | AR53: － | AS53: ー | AT53: ー | AU53: － | AY53: ー | BC53: イベントID：SC8201-02
B90: ■画面項目定義
B92: 画面項目ID | D92: 項目 | K92: タイプ | N92: I/O | O92: 多言語 | P92: 出力 | AR92: インプット | BC92: 備考
P93: マッピングデータ | X93: 初期値 | AA93: 表示コントロール | AI93: Control enable | AR93: 必須 | AS93: 数字 | AT93: 桁 | AU93: マッピングデータ
P94: API名 | T94: 項目 | AU94: API名 | AY94: 項目
B95: 8 | D95: 業態（タイトル） | K95: テキスト | N95: － | O95: ● | P95: － | T95: － | X95: 業態 | AA95: ー | AI95: ー | AR95: － | AS95: ー | AT95: ー | AU95: － | AY95: －
B96: 9 | D96: 業態（値） | K96: テキスト | N96: － | O96: － | P96: AP8201 | T96: business_type_code | AA96: ー | AI96: ー | AR96: － | AS96: ー | AT96: ー | AU96: － | AY96: － | BC96: business_type_code = 1:FO business_type_code = 2:FS business_type_code = 3:FM business_type_code = 4:BL
B97: 10 | D97: 店舗コード（タイトル） | K97: テキスト | N97: － | O97: ● | P97: － | T97: － | X97: 店舗コード | AA97: ー | AI97: ー | AR97: － | AS97: ー | AT97: ー | AU97: － | AY97: ー
B98: 11 | D98: 店舗コード（値） | K98: テキスト | N98: O | O98: － | P98: AP8201 | T98: code | X98: － | AA98: ー | AI98: － | AR98: － | AS98: ー | AT98: ー | AU98: － | AY98: ー
B99: 12 | D99: 店舗名称（タイトル） | K99: テキスト | N99: － | O99: ● | P99: － | T99: － | X99: 店舖名称 | AA99: ー | AI99: ー | AR99: － | AS99: ー | AT99: ー | AU99: － | AY99: ー
B100: 13 | D100: 店舗名称（値） | K100: テキスト | N100: O | O100: － | P100: AP8201 | T100: name | X100: － | AA100: ー | AI100: － | AR100: － | AS100: ー | AT100: ー | AU100: － | AY100: ー
B101: 14 | D101: 郵便番号（タイトル） | K101: テキスト | N101: － | O101: ● | P101: － | T101: － | X101: 郵便番号 | AA101: ー | AI101: ー | AR101: － | AS101: ー | AT101: ー | AU101: － | AY101: ー
B102: 15 | D102: 郵便番号（値） | K102: テキスト | N102: O | O102: － | P102: AP8201 | T102: post_code | X102: － | AA102: ー | AI102: － | AR102: － | AS102: ー | AT102: ー | AU102: － | AY102: ー | BC102: 形式:xxx-xxxx
B103: 16 | D103: 住所（タイトル） | K103: テキスト | N103: － | O103: ● | P103: － | T103: － | X103: 住所 | AA103: ー | AI103: ー | AR103: － | AS103: ー | AT103: ー | AU103: － | AY103: ー
B104: 17 | D104: 住所（値） | K104: テキスト | N104: O | O104: － | P104: AP8201 | T104: address | X104: － | AA104: ー | AI104: － | AR104: － | AS104: ー | AT104: ー | AU104: － | AY104: ー
B105: 18 | D105: 電話番号（タイトル） | K105: テキスト | N105: － | O105: ● | P105: － | T105: － | X105: 電話番号 | AA105: ー | AI105: ー | AR105: － | AS105: ー | AT105: ー | AU105: － | AY105: ー
B106: 19 | D106: 電話番号（値） | K106: テキスト | N106: O | O106: － | P106: AP8201 | T106: phone_number | X106: － | AA106: ー | AI106: － | AR106: － | AS106: ー | AT106: ー | AU106: － | AY106: ー | BC106: 最大数字の13桁。11桁の形式：xxx-xxxx-xxxx 10桁の形式：xx-xxxx-xxxx 13桁の形式: xxx-xx-xxxx-xxxx
B107: 20 | D107: 合計POS台数（タイトル） | K107: テキスト | N107: － | O107: ● | P107: － | T107: － | X107: 合計POS台数 | AA107: ー | AI107: ー | AR107: － | AS107: ー | AT107: ー | AU107: － | AY107: ー
B108: 21 | D108: 合計POS台数（値） | K108: テキスト | N108: O | O108: － | P108: AP8201 | T108: total_pos | X108: － | AA108: ー | AI108: － | AR108: － | AS108: ー | AT108: ー | AU108: － | AY108: ー
B109: 22 | D109: 基本ポイント（タイトル） | K109: テキスト | N109: － | O109: ● | P109: － | T109: － | X109: 基本ポイント | AA109: ー | AI109: ー | AR109: － | AS109: ー | AT109: ー | AU109: － | AY109: ー
B110: 23 | D110: 基本ポイント（値） | K110: テキスト | N110: O | O110: － | P110: AP8201 | T110: default_point | X110: － | AA110: ー | AI110: － | AR110: － | AS110: ー | AT110: ー | AU110: － | AY110: ー
B111: 24 | D111: 削除 | K111: ボタン | N111: I | O111: ● | P111: － | T111: － | X111: F10：削除 | AA111: ー | AI111: 1件が選択された場合に有効になる。ログイン中のユーザーが直属の店舗にのみ権限を持つ場合は、常に無効になる。 | AR111: － | AS111: ー | AT111: ー | AU111: － | AY111: ー | BC111: イベントID：SC8201-03
B112: 25 | D112: 編集 | K112: ボタン | N112: I | O112: ● | P112: － | T112: － | X112: F1：編集 | AA112: ー | AI112: 1件が選択された場合に有効になる。 | AR112: － | AS112: ー | AT112: ー | AU112: － | AY112: ー | BC112: イベントID：SC8201-04
...

Sheet MD8201
A1: システム名 | K1: システム種別 | W1: =IF(表紙!W1="","",表紙!W1) -> 詳細設計書 | AP1: 作成者 | AT1: 作成日 | AY1: 更新者 | BC1: 更新日 | BH1: 版数
A2: =IF(表紙!A2="","",表紙!A2) -> POSサーバー | K2: =IF(表紙!K2="","",表紙!K2) -> POSサーバ | AP2: =IF(表紙!AP2="","",表紙!AP2) -> DuNT | AT2: =IF(表紙!AT2="","",表紙!AT2) -> 45611 | AY2: =IF(表紙!AY2="","",表紙!AY2) -> DuNT | BC2: =IF(表紙!BC2="","",表紙!BC2) -> 45611 | BH2: =IF(表紙!BH2="","",表紙!BH2) -> 0.1
A4: 機能カテゴリ | H4: =IF(表紙!H4="","",表紙!H4) -> 82_店舗マスタ設定 | U4: 項目 | Z4: =IF(表紙!Z4="","",表紙!Z4) -> 画面設計書 | AP4: =MID(CELL("filename",A1),FIND("]",CELL("filename",A1))+1,255) -> MD8201
B7: ■イメージ
B61: ■画面項目定義
B63: 画面項目ID | D63: 項目 | K63: タイプ | N63: I/O | O63: 多言語 | P63: 出力 | AR63: インプット | BC63: 備考
P64: マッピングデータ | X64: 初期値 | AA64: 表示コントロール | AI64: Control enable | AR64: 必須 | AS64: 数字 | AT64: 桁 | AU64: マッピングデータ
P65: API名 | T65: 項目 | AU65: API名 | AY65: 項目
B66: 0 | D66: 画面タイトル | K66: テキスト | N66: － | O66: ● | P66: － | T66: － | X66: － | AA66: 新規の場合：新規 編集の場合：編集 コピーの場合：コピー | AI66: － | AR66: － | AS66: ー | AT66: ー | AU66: － | AY66: ー | BC66: イベントID:MD8201-01
B67: 1 | D67: 店舗コード（タイトル） | K67: テキスト | N67: － | O67: ● | P67: － | T67: － | X67: 店舗コード* | AA67: ー | AI67: 新規・コピーの場合：有効 編集の場合：無効 | AR67: － | AS67: ー | AT67: ー | AU67: － | AY67: ー
B68: 2 | D68: 店舗コード（値） | K68: EditText | N68: O | O68: － | P68: AP8201 | T68: code | X68: － | AA68: ー | AI68: － | AR68: ● | AS68: ● | AT68: ー | AU68: AP8204 AP8205 | AY68: code
B69: 3 | D69: 店舗名称（タイトル） | K69: テキスト | N69: － | O69: ● | P69: － | T69: － | X69: 店舖名称* | AA69: ー | AI69: － | AR69: － | AS69: ー | AT69: ー | AU69: － | AY69: －
B70: 4 | D70: 店舗名称（値） | K70: EditText | N70: O | O70: － | P70: AP8201 | T70: name | X70: － | AA70: ー | AI70: 有効 | AR70: ● | AS70: ー | AT70: ー | AU70: AP8204 AP8205 | AY70: name | BC70: 最大半角50文字、全角25文字
B71: 5 | D71: 店舗略称（タイトル） | K71: テキスト | N71: － | O71: ● | P71: － | T71: － | X71: 店舗略称* | AA71: ー | AI71: ー | AR71: － | AS71: ー | AT71: ー | AU71: － | AY71: －
B72: 6 | D72: 店舗略称（値） | K72: EditText | N72: O | O72: － | P72: AP8201 | T72: short_name | X72: － | AA72: ー | AI72: 有効 | AR72: ● | AS72: ー | AT72: ー | AU72: AP8204 AP8205 | AY72: short_name | BC72: 最大半角30文字、全角15文字
B73: 7 | D73: 郵便番号（タイトル） | K73: テキスト | N73: － | O73: ● | P73: － | T73: － | X73: 郵便番号 | AA73: ー | AI73: ー | AR73: － | AS73: ー | AT73: ー | AU73: － | AY73: －
B74: 8 | D74: 郵便番号（値） | K74: EditText | N74: O | O74: － | P74: AP8201 | T74: post_code | X74: － | AA74: ー | AI74: 有効 | AR74: － | AS74: ー | AT74: ー | AU74: AP8204 AP8205 | AY74: post_code | BC74: 7桁の数字のみ入力可能とする。 形式：xxx-xxxx
B75: 9 | D75: 住所（タイトル） | K75: テキスト | N75: － | O75: ● | P75: － | T75: － | X75: 住所 | AA75: ー | AI75: ー | AR75: － | AS75: ー | AT75: ー | AU75: － | AY75: －
B76: 10 | D76: 住所（値） | K76: EditText | N76: O | O76: － | P76: AP8201 | T76: address | X76: － | AA76: ー | AI76: 有効 | AR76: － | AS76: ー | AT76: ー | AU76: AP8204 AP8205 | AY76: address | BC76: 最大半角100文字、全角50文字
B77: 11 | D77: 電話番号（タイトル） | K77: テキスト | N77: － | O77: ● | P77: － | T77: － | X77: 電話番号 | AA77: ー | AI77: ー | AR77: － | AS77: ー | AT77: ー | AU77: － | AY77: －
B78: 12 | D78: 電話番号（値） | K78: EditText | N78: O | O78: － | P78: AP8201 | T78: phone_number | X78: － | AA78: ー | AI78: 有効 | AR78: － | AS78: ー | AT78: ー | AU78: AP8204 AP8205 | AY78: phone_number | BC78: 最大数字の13桁。11桁の形式：xxx-xxxx-xxxx 10桁の形式：xx-xxxx-xxxx 13桁の形式: xxx-xx-xxxx-xxxx
B79: 15 | D79: 業態（タイトル） | K79: テキスト | N79: － | O79: ● | P79: － | T79: － | X79: 業態 | AA79: ー | AI79: ー | AR79: － | AS79: ー | AT79: ー | AU79: － | AY79: －
B80: 16 | D80: 業態（値） | K80: ドロップダウン | N80: O | O80: － | P80: AP8201 | T80: business_type_code | X80: 1: FO 2: FS 3: FM 4: BL | AA80: ー | AI80: 有効 | AR80: － | AS80: ー | AT80: ー | AU80: AP8204 AP8205 | AY80: business_type_code
B81: 13 | D81: 基本ポイント（タイトル） | K81: テキスト | N81: － | O81: ● | P81: － | T81: － | X81: 基本ポイント | AA81: ー | AI81: ー | AR81: － | AS81: ー | AT81: ー | AU81: － | AY81: －
B82: 14 | D82: 基本ポイント（値） | K82: EditText | N82: O | O82: － | P82: AP8201 | T82: default_point | X82: － | AA82: ー | AI82: 有効 | AR82: － | AS82: ー | AT82: ー | AU82: AP8204 AP8205 | AY82: default_point | BC82: 最大数字の6桁。
B83: 15 | D83: 営業開始時間（タイトル） | K83: テキスト | N83: ー | O83: ● | P83: ー | T83: ー | X83: 営業開始時間 | AA83: ー | AI83: ー | AR83: － | AS83: － | AT83: － | AU83: ー | AY83: ー
B84: 16 | D84: 営業開始時間（値） | K84: TimePicker | N84: I | O84: － | P84: AP8201 | T84: start_hours | X84: ー | AI84: ー | AR84: － | AS84: － | AT84: － | AU84: AP8204 AP8205 | AY84: start_hours | BC84: 形式: hh:mm
B85: 17 | D85: 営業終了時間（タイトル） | K85: テキスト | N85: ー | O85: ● | P85: ー | T85: ー | X85: 営業終了時間 | AA85: ー | AI85: ー | AR85: － | AS85: － | AT85: － | AU85: ー | AY85: ー
B86: 18 | D86: 営業終了時間（値） | K86: TimePicker | N86: I | O86: － | P86: AP8201 | T86: end_hours | X86: ー | AI86: ー | AR86: － | AS86: － | AT86: － | AU86: AP8204 AP8205 | AY86: end_hours | BC86: 形式: hh:mm
B87: 19 | D87: コピー元店舗（タイトル） | K87: テキスト | N87: － | O87: ● | P87: － | T87: － | X87: コピー元店舗 | AA87: コピーの場合に表示し、新規作成・編集の場合に表示しない。 | AI87: ー | AR87: － | AS87: ー | AT87: ー | AU87: － | AY87: －
B88: 20 | D88: コピー元店舗（値） | K88: テキスト | N88: O | O88: － | P88: － | T88: － | X88: － | AA88: コピーの場合に表示し、新規作成・編集の場合に表示しない。 | AI88: 無効 | AR88: ● | AS88: ー | AT88: ー | AU88: AP8205 | AY88: copy_source | BC88: 形式：選択されたコピー対象の「コード: 名称」
B89: 21 | D89: 取消 | K89: ボタン | N89: I | O89: ● | P89: ー | T89: ー | X89: 前画面 | AA89: ー | AI89: 有効 | AR89: － | AS89: － | AT89: － | AU89: ー | AY89: ー | BC89: イベントID：MD8201-02
B90: 22 | D90: 登録（新規） | K90: ボタン | N90: I | O90: ● | P90: ー | T90: ー | X90: 登録 | AA90: ` | AI90: 有効 | AR90: － | BC90: イベントID：MD8201-03
B91: 23 | D91: 確定（コピー） | K91: ボタン | N91: I | O91: ● | P91: ー | T91: ー | X91: 確定 | AA91: ー | AI91: 有効 | AR91: － | AS91: － | AT91: － | AU91: ー | AY91: ー | BC91: イベントID：MD8201-03
B92: 24 | D92: 確定（更新） | K92: ボタン | N92: I | O92: ● | P92: ー | T92: ー | X92: 更新 | AA92: ー | AI92: 変更があった場合に有効にする。 | AR92: － | AS92: － | AT92: － | AU92: ー | AY92: ー | BC92: イベントID：MD8201-03

Sheet SCxxxx
A1: システム名 | K1: システム種別 | W1: =IF(表紙!W1="","",表紙!W1) -> 詳細設計書 | AP1: 作成者 | AT1: 作成日 | AY1: 更新者 | BC1: 更新日 | BH1: 版数
A2: =IF(表紙!A2="","",表紙!A2) -> POSサーバー | K2: =IF(表紙!K2="","",表紙!K2) -> POSサーバ | AP2: =IF(表紙!AP2="","",表紙!AP2) -> DuNT | AT2: =IF(表紙!AT2="","",表紙!AT2) -> 45611 | AY2: =IF(表紙!AY2="","",表紙!AY2) -> DuNT | BC2: =IF(表紙!BC2="","",表紙!BC2) -> 45611 | BH2: =IF(表紙!BH2="","",表紙!BH2) -> 0.1
A4: 機能カテゴリ | H4: =IF(表紙!H4="","",表紙!H4) -> 82_店舗マスタ設定 | U4: 項目 | Z4: =IF(表紙!Z4="","",表紙!Z4) -> 画面設計書 | AP4: =MID(CELL("filename",A1),FIND("]",CELL("filename",A1))+1,255) -> SCxxxx
B7: ■イメージ
B35: ■画面項目定義
B37: 画面項目ID | D37: 項目 | K37: タイプ | N37: I/O | O37: 多言語 | P37: 出力 | AR37: インプット | BC37: 備考
P38: マッピングデータ | X38: 初期値 | AA38: 表示コントロール | AI38: Control enable | AR38: 必須 | AS38: 数字 | AT38: 桁 | AU38: マッピングデータ
P39: API名 | T39: 項目 | AU39: API名 | AY39: 項目
B40: 1 | K40: テキスト | N40: － | O40: ● | P40: － | T40: － | X40: Android POS Control | AA40: ー | AI40: － | AR40: － | AS40: ー | AT40: ー | AU40: － | AY40: ー
B41: 2 | K41: テキスト | N41: O | O41: ● | P41: － | T41: － | X41: ユーザーID | AA41: ー | AI41: ー | AR41: － | AS41: ー | AT41: ー | AU41: － | AY41: ー
B42: 3 | K42: テキスト | N42: I | O42: － | P42: － | X42: － | AA42: ー | AI42: ー | AR42: － | AS42: ー | AT42: ー | AU42: － | AY42: ー
B43: 4 | K43: テキスト | N43: O | O43: ● | P43: － | T43: － | X43: Password | AA43: ー | AI43: ー | AR43: － | AS43: ー | AT43: ー | AU43: － | AY43: ー
B44: 5 | K44: EditText | N44: I | O44: － | P44: － | T44: － | X44: － | AA44: ー | AI44: ー | AR44: － | AS44: ー | AT44: ー | AU44: － | AY44: ー
B45: 6 | K45: ボタン | N45: I | O45: ● | P45: － | T45: － | X45: ログイン | AA45: ー | AI45: 有効 | AR45: － | AS45: ー | AT45: ー | AU45: － | AY45: ー | BC45: Login-01/EmployeeMaster
