Workbook

Sheet 表紙
A1: システム名 | K1: システム種別 | W1: 詳細設計書 | AP1: 作成者 | AT1: 作成日 | AY1: 更新者 | BC1: 更新日 | BH1: 版数
A2: POSサーバー | K2: POSサーバー | AP2: =改訂履歴!$H$11 -> DuNT | AT2: =改訂履歴!$B$11 -> 45460 | AY2: =LOOKUP(2,1/(改訂履歴!H11:H30008<>""),改訂履歴!H11:H30008) -> LoiLV | BC2: =LOOKUP(2,1/(改訂履歴!B11:B30008<>""),改訂履歴!B11:B30008) -> 45723 | BH2: =LOOKUP(2,1/(改訂履歴!O11:O30008<>""),改訂履歴!O11:O30008) -> 0.65
A4: 機能カテゴリ | H4: 15_プリセットメニュー設定 | U4: 項目 | Z4: 画面設計書 | AP4: {=RIGHT(CELL("filename",$A$1),LEN(CELL("filename",$A$1))-FIND("]",CELL("filename",$A$1)))} -> 表紙
L16: POSサーバーの基本設計書
L24: =K2&"/"&H4&"/"&Z4 -> POSサーバー/15_プリセットメニュー設定/画面設計書
Q44: 承認日 | AA44: 承認者 | AQ44: 版数

Sheet 改訂履歴
A1: システム名 | K1: システム種別 | W1: =IF(表紙!W1="","",表紙!W1) -> 詳細設計書 | AP1: 作成者 | AT1: 作成日 | AY1: 更新者 | BC1: 更新日 | BH1: 版数
A2: =IF(表紙!A2="","",表紙!A2) -> POSサーバー | K2: =IF(表紙!K2="","",表紙!K2) -> POSサーバー | AP2: =IF(表紙!AP2="","",表紙!AP2) -> DuNT | AT2: =IF(表紙!AT2="","",表紙!AT2) -> 45460 | AY2: =IF(表紙!AY2="","",表紙!AY2) -> LoiLV | BC2: =IF(表紙!BC2="","",表紙!BC2) -> 45723 | BH2: =IF(表紙!BH2="","",表紙!BH2) -> 0.65
A4: 機能カテゴリ | H4: =IF(表紙!H4="","",表紙!H4) -> 15_プリセットメニュー設定 | U4: 項目 | Z4: =IF(表紙!Z4="","",表紙!Z4) -> 画面設計書 | AP4: {=RIGHT(CELL("filename",$A$1),LEN(CELL("filename",$A$1))-FIND("]",CELL("filename",$A$1)))} -> 改訂履歴
B8: ■改訂履歴
B10: 更新日 | H10: 更新者 | O10: 版数 | S10: 更新内容 | AX10: 承認日 | BD10: 承認者
B11: 45460 | H11: DuNT | O11: 0.1 | S11: 新規
B13: 45495 | H13: DuNT | O13: 0.2 | S13: コメントによる画面のイメージを修正する。
S14: SC1501シート: 検索項目の最大長を設定し、AP1508リクエストで必須項目をマークする。
S15: MD1507シート：選択項目：1つのオプションのみ選択可能にする
S16: SC1502シート：2024年6月27日の会議での仕様変更に従って修正する。
B17: 45516 | H17: DuNT | O17: 0.3 | S17: MD1507: オーバーライド店舗一覧
S18: MD1504: AP1507項目のマッピング
S19: SC1501:AP1504コピーAPI項目のマッピング
S20: MD1506, MD15808: AP1509存在のバリデーションチェックAPI項目のマッピング追加
B21: 45525 | H21: DuNT | O21: 0.4 | S21: MD1507: AP1509マッピング
S22: 名称変更：タッチメニュー -> プリセットメニュー
B23: 45546 | H23: DuNT | O23: 0.5 | S23: MD1506：ボタン「確定」を常に有効にする
S24: SC1502: 機能のドロップダウンリストの説明を追加する
S25: MD1507: デフォルトで「新規」チェックボックスを選択する
B26: 45547 | H26: DuNT | O26: 0.6 | S26: SC1502：テキスト「タグ」を「タブ」に修正し、タブ編集で「空きタブ」設定を削除する。
S27: SC1502：プリセット設定画面の初期化時に、最初のタブとタブ編集を表示する。
S28: SC1502：タブ編集で『空きタブ』の設定を削除する。
S29: SC1502：プリセット設定画面の「名称」列を編集できるようにする。
S30: SC1502：プリセット設定画面に編集可能な「予定日」列を追加する。
B31: 45559 | H31: DuNT | O31: 0.61 | S31: SC1502: 項目35のテキストを変更
S32: MD1508: 店舗のドロップダウンリストのデフォルト値を追加で説明する。
B33: 45588 | H33: DuNT | O33: 0.62 | S33: SC1501: プリセットコード入力項目を更新する（4桁の数字のみ入力可能とし、「0」を自動追加しない）
B35: 45603 | H35: DuNT | O35: 0.63 | S35: SC1501：適用日を削除する。
S36: 全ての画面：イメージを更新する。
B37: 45712 | H37: TuyenNH | O37: 0.64 | S37: SC1502：商品名で検索する機能を追加する。
S38: [SC1502]シート
B39: 45723 | H39: LoiLV | O39: 0.65 | S39: プリセットレイアウトコードを更新

Sheet SC1501
A1: システム名 | K1: システム種別 | W1: =IF(表紙!W1="","",表紙!W1) -> 詳細設計書 | AP1: 作成者 | AT1: 作成日 | AY1: 更新者 | BC1: 更新日 | BH1: 版数
A2: =IF(表紙!A2="","",表紙!A2) -> POSサーバー | K2: =IF(表紙!K2="","",表紙!K2) -> POSサーバー | AP2: =IF(表紙!AP2="","",表紙!AP2) -> DuNT | AT2: =IF(表紙!AT2="","",表紙!AT2) -> 45460 | AY2: =IF(表紙!AY2="","",表紙!AY2) -> LoiLV | BC2: =IF(表紙!BC2="","",表紙!BC2) -> 45723 | BH2: =IF(表紙!BH2="","",表紙!BH2) -> 0.65
A4: 機能カテゴリ | H4: =IF(表紙!H4="","",表紙!H4) -> 15_プリセットメニュー設定 | U4: 項目 | Z4: =IF(表紙!Z4="","",表紙!Z4) -> 画面設計書 | AP4: =MID(CELL("filename",A1),FIND("]",CELL("filename",A1))+1,255) -> SC1501
B7: ■SC1501_プリセットレイアウト検索画面のイメージ
B87: ■画面項目定義
B89: 画面項目ID | D89: 項目 | K89: タイプ | N89: I/O | O89: 多言語 | P89: 出力 | AR89: インプット | BC89: 備考
P90: マッピングデータ | X90: 初期値 | AA90: 表示コントロール | AI90: Control enable | AR90: 必須 | AS90: 数字 | AT90: 桁 | AU90: マッピングデータ
P91: API名 | T91: 項目 | AU91: API名 | AY91: 項目
B92: 0 | D92: 画面タイトル | K92: テキスト | N92: － | O92: ● | P92: － | T92: － | X92: プリセット設定 | AA92: 左詰め | AI92: － | AR92: － | AS92: ー | AT92: ー | AU92: － | AY92: ー | BC92: イベントID：SC1501-01
B93: 1 | D93: プリセットレイアウトコード（タイトル） | K93: テキスト | N93: － | O93: ● | P93: － | T93: － | X93: プリセットレイアウトコード | AA93: 左詰め | AI93: ー | AR93: － | AS93: ー | AT93: ー | AU93: － | AY93: －
B94: 2 | D94: プリセットレイアウトコード（値） | K94: EditText | N94: I | O94: － | P94: － | T94: － | X94: － | AA94: ー | AI94: 店舗が選択されている場合、無効になる | AR94: － | AS94: ● | AT94: ー | AU94: AP1501 | AY94: preset_layout_code | BC94: ・最大4桁入力可能。
B95: 3 | D95: プリセットレイアウトコード検索条件 | K95: ドロップダウン | N95: I | O95: ● | P95: － | T95: － | X95: を含む/から始まる/で終わる | AA95: ー | AI95: 店舗が選択されている場合、無効になる | AR95: － | AS95: ー | AT95: ー | AU95: AP1501 | AY95: preset_layout_code_type
B96: 4 | D96: 名称（タイトル） | K96: テキスト | N96: － | O96: － | P96: － | T96: － | X96: 名称 | AA96: 左詰め | AI96: ー | AR96: － | AS96: ー | AT96: ー | AU96: － | AY96: ー
B97: 5 | D97: 名称（値） | K97: EditText | N97: I | O97: － | P97: － | T97: － | X97: － | AA97: ー | AI97: 店舗が選択されている場合、無効になる | AR97: － | AS97: ー | AT97: ー | AU97: AP1501 | AY97: preset_layout_name | BC97: 最大半角50文字、全角25文字
B98: 6 | D98: 名称検索条件 | K98: ドロップダウン | N98: I | O98: ● | P98: － | X98: を含む/から始まる/で終わる | AA98: ー | AI98: 店舗が選択されている場合、無効になる | AR98: － | AS98: ー | AT98: ー | AU98: AP1501 | AY98: preset_layout_name_type
B99: 7 | D99: F12: 検索 | K99: ボタン | N99: I | O99: ● | P99: － | T99: － | X99: F12：検索 | AA99: ー | AI99: 店舗が選択されている場合、無効になる | AR99: － | AS99: ー | AT99: ー | AU99: － | AY99: ー | BC99: イベントID：SC1501-02をご参照ください。
B100: 8 | D100: プリセットレイアウト一覧 | K100: － | N100: I | O100: － | P100: － | T100: － | X100: － | AA100: ー | AI100: ー | AR100: － | AS100: ー | AT100: ー | AU100: － | AY100: ー
B101: 8.1 | D101: 店舗（列名） | K101: テキスト | N101: － | O101: ● | P101: － | T101: － | X101: 店舗 | AA101: 中央 | AI101: ー | AR101: － | AS101: ー | AT101: ー | AU101: － | AY101: ー
B102: 8.2 | D102: 店舗（値） | K102: テキスト | N102: O | O102: － | P102: AP1501 | T102: store_code:store_name | X102: － | AA102: 左詰め | AI102: ー | AR102: ● | AS102: ー | AT102: ー | AU102: AP1508 | AY102: store_code
B103: 8.3 | D103: プリセットレイアウトコード（列名） | K103: テキスト | N103: － | O103: ● | P103: － | T103: － | X103: プリセットレイアウトコード | AA103: 中央 | AI103: ー | AR103: － | AS103: ー | AT103: ー | AU103: － | AY103: ー
B104: 8.4 | D104: プリセットレイアウトコード（値） | K104: テキスト | N104: O | O104: － | P104: AP1501 | T104: preset_layout_code | X104: － | AA104: 右詰め | AI104: ー | AR104: ● | AS104: － | AT104: ー | AU104: AP1508 AP1504 | AY104: preset_layout_code preset_layout_code/item.preset_layout_code | BC104: 新規・削除の場合、AP1508を使用する コピーの場合、AP1504を使用する。
B105: 8.5 | D105: プリセットレイアウト名称（列名） | K105: テキスト | N105: － | O105: ● | P105: － | T105: － | X105: 名称 | AA105: 中央 | AI105: ー | AR105: － | AS105: ー | AT105: ー | AU105: － | AY105: ー
B106: 8.6 | D106: 名称（値） | K106: テキスト | N106: O | O106: － | P106: AP1501 | T106: preset_layout_name | X106: － | AA106: 左詰め | AI106: ー | AR106: ● | AS106: ー | AT106: ー | AU106: AP1508 AP1504 | AY106: preset_layout_name preset_layout_name/item.preset_layout_name | BC106: 新規・削除の場合、AP1508を使用する コピーの場合、AP1504を使用する。
B107: 8.7 | D107: 状態（列名） | K107: テキスト | N107: － | O107: ● | P107: － | T107: － | X107: 状態 | AA107: 中央 | AI107: ー | AR107: － | AS107: ー | AT107: ー | AU107: － | AY107: ー
B108: 8.8 | D108: 状態（値） | K108: テキスト | N108: O | O108: － | P108: AP1501 | T108: status | X108: － | AA108: 左詰め | AI108: ー | AR108: ● | AS108: ー | AT108: ー | AU108: － | AY108: ー | BC108: 0:未反映 1: 反映済み
B109: 9 | D109: F10: 削除 | K109: ボタン | N109: I | O109: ● | P109: － | T109: － | X109: F10：削除 | AA109: ー | AI109: 以下の2つの条件を満たす場合に有効にする。 +ログインユーザーが管理者又はヘッドクオーターである。 +リスト内のアイテムが1つ選択されている。 | AR109: － | AS109: ー | AT109: ー | AU109: － | AY109: ー | BC109: イベントID：SC1501-03
B110: 10 | D110: 編集 | K110: ボタン | N110: I | O110: ● | P110: － | X110: F1：編集 | AA110: ー | AI110: 一覧で1つのアイテムが選択されている場合に有効にする。 | AR110: － | AS110: ー | AT110: ー | AU110: － | AY110: ー | BC110: イベントID：SC1501-04
B111: 11 | D111: 新規 | K111: ボタン | N111: I | O111: ● | P111: － | T111: － | X111: F2：新規 | AA111: ー | AI111: 以下の2つの条件を満たす場合に有効にする。 +ログインユーザーが管理者又はヘッドクオーターである。 +店舗が選択された。 | AR111: － | AS111: ー | AT111: ー | AU111: － | AY111: ー | BC111: イベントID：SC1501-05
B112: 12 | D112: コピー | K112: ボタン | N112: I | O112: ● | P112: － | T112: － | X112: F3：コピー | AA112: ー | AI112: 以下の2つの条件を満たす場合に有効にする。 +ログインユーザーが管理者又はヘッドクオーターである。 +リスト内のアイテムが1つ選択されている。 | AR112: － | AS112: ー | AT112: ー | AU112: － | AY112: ー | BC112: イベントID：SC1501-06
B113: 13 | D113: F09: 確定 | K113: ボタン | N113: I | O113: ● | P113: － | T113: － | X113: F11：確定 | AA113: ー | AI113: 以下の2つの条件を満たす場合に有効にする。 +ログインユーザーが管理者又はヘッドクオーターである。 +データ変更がある（追加、編集、削除） | AR113: － | AS113: ー | AT113: ー | AU113: － | AY113: ー | BC113: イベントID：SC1501-07
B114: 14 | D114: 保存 | K114: ボタン | N114: I | O114: ● | P114: － | T114: － | X114: F9：保存 | AA114: カスミ会社の場合のみ表示する。 | AI114: 以下の2つの条件を満たす場合に有効にする。 +ログインユーザーが管理者又はヘッドクオーターである。 +データのコピー又は新規作成がある。 | AR114: － | AS114: ー | AT114: ー | AU114: － | AY114: ー | BC114: イベントID：SC1501-08

Sheet MD1502
A1: システム名 | K1: システム種別 | W1: =IF(表紙!W1="","",表紙!W1) -> 詳細設計書 | AP1: 作成者 | AT1: 作成日 | AY1: 更新者 | BC1: 更新日 | BH1: 版数
A2: =IF(表紙!A2="","",表紙!A2) -> POSサーバー | K2: =IF(表紙!K2="","",表紙!K2) -> POSサーバー | AP2: =IF(表紙!AP2="","",表紙!AP2) -> DuNT | AT2: =IF(表紙!AT2="","",表紙!AT2) -> 45460 | AY2: =IF(表紙!AY2="","",表紙!AY2) -> LoiLV | BC2: =IF(表紙!BC2="","",表紙!BC2) -> 45723 | BH2: =IF(表紙!BH2="","",表紙!BH2) -> 0.65
A4: 機能カテゴリ | H4: =IF(表紙!H4="","",表紙!H4) -> 15_プリセットメニュー設定 | U4: 項目 | Z4: =IF(表紙!Z4="","",表紙!Z4) -> 画面設計書 | AP4: =MID(CELL("filename",A1),FIND("]",CELL("filename",A1))+1,255) -> MD1502
B7: ■MD1502_プリセットイメージモーダルのイメージ
B35: ■画面項目定義
B37: 画面項目ID | D37: 項目 | K37: タイプ | N37: I/O | O37: 多言語 | P37: 出力 | AR37: インプット | BC37: 備考
P38: マッピングデータ | X38: 初期値 | AA38: 表示コントロール | AI38: Control enable | AR38: 必須 | AS38: 数字 | AT38: 桁 | AU38: マッピングデータ
P39: API名 | T39: 項目 | AU39: API名 | AY39: 項目
B40: １ | D40: イメージ | K40: イメージ | N40: O | O40: ● | P40: AP1505 | T40: url | X40: － | AA40: 中央 | AI40: ー | AR40: － | BC40: イベントID：MD1502-01
B41: 2 | D41: イメージ名 | K41: テキスト | N41: O | O41: ● | P41: AP1505 | T41: name | X41: － | AA41: 中央 | AI41: ー | AR41: － | AS41: ー | AT41: ー | AU41: － | AY41: ー
B42: 3 | D42: アイテム | K42: ビュー | N42: Ⅰ | O42: － | P42: － | T42: － | X42: － | AA42: ー | AI42: ー | AR42: － | AS42: ー | AT42: ー | AU42: － | AY42: ー | BC42: イベントID：MD1502-02
B43: 4 | D43: 決定 | K43: ボタン | N43: I | O43: ● | P43: － | T43: － | X43: 決定 | AA43: 中央 | AI43: 有効 | AR43: － | AS43: ー | AT43: ー | AU43: － | AY43: ー | BC43: イベントID：MD1502-03
B44: 5 | D44: 前画面 | K44: ボタン | N44: I | O44: ● | P44: － | T44: － | X44: 前画面 | AA44: 中央 | AI44: 有効 | AR44: － | AS44: ー | AT44: ー | AU44: － | AY44: ー | BC44: イベントID：MD1502-04
E49: `

Sheet MD1504
A1: システム名 | K1: システム種別 | W1: =IF(表紙!W1="","",表紙!W1) -> 詳細設計書 | AP1: 作成者 | AT1: 作成日 | AY1: 更新者 | BC1: 更新日 | BH1: 版数
A2: =IF(表紙!A2="","",表紙!A2) -> POSサーバー | K2: =IF(表紙!K2="","",表紙!K2) -> POSサーバー | AP2: =IF(表紙!AP2="","",表紙!AP2) -> DuNT | AT2: =IF(表紙!AT2="","",表紙!AT2) -> 45460 | AY2: =IF(表紙!AY2="","",表紙!AY2) -> LoiLV | BC2: =IF(表紙!BC2="","",表紙!BC2) -> 45723 | BH2: =IF(表紙!BH2="","",表紙!BH2) -> 0.65
A4: 機能カテゴリ | H4: =IF(表紙!H4="","",表紙!H4) -> 15_プリセットメニュー設定 | U4: 項目 | Z4: =IF(表紙!Z4="","",表紙!Z4) -> 画面設計書 | AP4: =MID(CELL("filename",A1),FIND("]",CELL("filename",A1))+1,255) -> MD1504
B7: ■MD1504_品種一覧モーダルのイメージ
B37: ■画面項目定義
B39: 画面項目ID | D39: 項目 | K39: タイプ | N39: I/O | O39: 多言語 | P39: 出力 | AR39: インプット | BC39: 備考
P40: マッピングデータ | X40: 初期値 | AA40: 表示コントロール | AI40: Control enable | AR40: 必須 | AS40: 数字 | AT40: 桁 | AU40: マッピングデータ
P41: API名 | T41: 項目 | AU41: API名 | AY41: 項目
B42: ０ | D42: コピータイトル | K42: テキスト | N42: － | O42: ● | P42: － | T42: － | X42: 品種検索 | AA42: ー | AI42: － | AR42: － | AS42: ー | AT42: ー | AU42: － | AY42: ー | BC42: イベントID：MD1504-01
B43: １ | D43: 名称検索（タイトル） | K43: テキスト | N43: － | O43: ● | P43: － | T43: － | X43: 品種名称 | AA43: ー | AI43: ー | AR43: －
B44: 2 | D44: 名称検索（値） | K44: EditText | N44: I | O44: － | P44: － | T44: － | X44: － | AA44: 左詰め | AI44: ー | AR44: － | AS44: ー | AT44: ー | AU44: － | AY44: ー
B45: 3 | D45: 検索 | K45: ボタン | N45: Ⅰ | O45: ● | P45: － | T45: － | X45: 検索 | AA45: 中央 | AI45: 有効 | AR45: － | AS45: ー | AT45: ー | AU45: － | AY45: ー | BC45: イベントID：MD1504-02
B46: 4 | D46: 選択列（タイトル） | K46: テキスト | N46: － | O46: ● | P46: － | T46: － | X46: 選択 | AA46: 中央 | AI46: ー | AR46: － | AS46: ー | AT46: ー | AU46: － | AY46: ー
B47: 5 | D47: 選択ボタン | K47: ボタン | N47: I | O47: ● | P47: － | T47: － | X47: 選択 | AA47: 中央 | AI47: 有効 | AR47: － | AS47: ー | AT47: ー | AU47: － | AY47: ー | BC47: イベントID：MD1504-03
B48: 6 | D48: 品種コード列 | K48: テキスト | N48: － | O48: ● | P48: － | T48: － | X48: 品種コード | AA48: 中央 | AI48: ー | AR48: － | AS48: ー | AT48: ー | AU48: － | AY48: ー
B49: 7 | D49: 品種列 | K49: テキスト | N49: O | O49: － | P49: AP1507 | T49: HierachyItem.code_level_three | X49: － | AA49: 左詰め | AI49: ー | AR49: － | AS49: ー | AT49: ー | AU49: － | AY49: ー
B50: 8 | D50: 品種名称列 | K50: テキスト | N50: － | O50: ● | P50: － | T50: － | X50: 品種名称 | AA50: 中央 | AI50: ー | AR50: － | AS50: ` | AT50: ー | AU50: － | AY50: ー
B51: 9 | D51: 品種名称 | K51: テキスト | N51: O | O51: － | P51: AP1507 | T51: HierachyItem.description_level_three | X51: － | AA51: 左詰め | AI51: ー | AR51: － | AS51: ー | AT51: ー | AU51: － | AY51: ー
B52: 10 | D52: 適用日列 | K52: テキスト | N52: － | O52: ● | P52: － | T52: － | X52: 適用日 | AA52: 中央 | AI52: 検索結果が100件を超えた場合にのみ表示する。 | AR52: － | AS52: ー | AT52: ー | AU52: － | AY52: ー
B53: 11 | D53: 適用日 | K53: テキスト | N53: O | O53: － | P53: AP1507 | T53: HierachyItem.apply_date_level_three | X53: － | AA53: 左詰め | AI53: ー | AR53: － | AS53: ー | AT53: ー | AU53: － | AY53: ー | BC53: フォーマット: yyyy/mm/dd
B54: 12 | D54: ワーニング | K54: テキスト | N54: － | O54: ● | P54: － | T54: － | X54: 検索結果が1000件を超えたため、最初の1000件を表示しています。 | AA54: ー | AI54: ー | AR54: － | AS54: ー | AT54: ー | AU54: － | AY54: ー
B55: 13 | D55: 前画面 | K55: ボタン | N55: I | O55: ● | P55: － | T55: － | X55: 前画面 | AA55: 中央 | AI55: 有効 | AR55: － | AS55: ー | AT55: ー | AU55: － | AY55: ー | BC55: イベントID：MD1504-04
E60: `

Sheet MD1506
A1: システム名 | K1: システム種別 | W1: =IF(表紙!W1="","",表紙!W1) -> 詳細設計書 | AP1: 作成者 | AT1: 作成日 | AY1: 更新者 | BC1: 更新日 | BH1: 版数
A2: =IF(表紙!A2="","",表紙!A2) -> POSサーバー | K2: =IF(表紙!K2="","",表紙!K2) -> POSサーバー | AP2: =IF(表紙!AP2="","",表紙!AP2) -> DuNT | AT2: =IF(表紙!AT2="","",表紙!AT2) -> 45460 | AY2: =IF(表紙!AY2="","",表紙!AY2) -> LoiLV | BC2: =IF(表紙!BC2="","",表紙!BC2) -> 45723 | BH2: =IF(表紙!BH2="","",表紙!BH2) -> 0.65
A4: 機能カテゴリ | H4: =IF(表紙!H4="","",表紙!H4) -> 15_プリセットメニュー設定 | U4: 項目 | Z4: =IF(表紙!Z4="","",表紙!Z4) -> 画面設計書 | AP4: =MID(CELL("filename",A1),FIND("]",CELL("filename",A1))+1,255) -> MD1506
B7: ■MD1506_プリセットレイアウトコピーモーダルのイメージ
D8: カスミ様
B33: ■画面項目定義
B35: 画面項目ID | D35: 項目 | K35: タイプ | N35: I/O | O35: 多言語 | P35: 出力 | AR35: インプット | BC35: 備考
P36: マッピングデータ | X36: 初期値 | AA36: 表示コントロール | AI36: Control enable | AR36: 必須 | AS36: 数字 | AT36: 桁 | AU36: マッピングデータ
P37: API名 | T37: 項目 | AU37: API名 | AY37: 項目
B38: ０ | D38: コピータイトル | K38: テキスト | N38: － | O38: ● | P38: － | T38: － | X38: コピー | AA38: ー | AI38: － | AR38: － | AS38: ー | AT38: ー | AU38: － | AY38: ー | BC38: イベントID：MD1506-01
B39: 1 | D39: プリセットレイアウトコード（タイトル） | K39: テキスト | N39: － | O39: ● | P39: － | X39: プリセットレイアウトコード | AA39: 左詰め | AI39: ー | AR39: － | AS39: ー | AT39: ー | AU39: － | AY39: ー
B40: 2 | D40: プリセットレイアウトコード（値） | K40: EditText | N40: I | O40: － | P40: － | T40: － | X40: － | AA40: ー | AI40: ー | AR40: ● | AS40: ● | AT40: ー | AU40: AP1509 | AY40: preset_layout_code | BC40: 数字のみ入力可能（4桁） 4文字足りない場合は「0」を自動追加する。
B41: 3 | D41: 名称（タイトル） | K41: テキスト | N41: － | O41: ● | P41: － | T41: － | X41: 名称* | AA41: 左詰め | AI41: ー | AR41: － | AS41: ー | AT41: ー | AU41: － | AY41: ー
B42: 4 | D42: 名称（値） | K42: EditText | N42: I | O42: － | P42: － | T42: － | X42: － | AA42: ー | AR42: ● | AS42: ー | AT42: ● | AU42: AP1509 | AY42: preset_layout_name | BC42: 最大50桁。
B43: 5 | D43: 全選択 | K43: ボタン | N43: I | O43: ● | P43: － | X43: 全選択 | AA43: ー | AI43: 少なくとも1つの店舗が選択されていない場合に有効にする。全ての店舗が選択されている場合に無効にする。 | AR43: － | AS43: ー | AT43: ー | AU43: － | AY43: ー | BC43: イベントID：MD1506-02
B44: 6 | D44: 全解除 | K44: ボタン | N44: I | O44: ● | P44: － | T44: － | X44: 全解除 | AA44: ー | AI44: 全ての店舗が選択されている場合に有効にする。少なくとも1つの店舗が選択されている場合に無効にする。 | AR44: － | AS44: ` | AT44: ー | AU44: － | AY44: ー | BC44: イベントID：MD1506-03
B45: 7 | D45: 店舗（タイトル） | K45: テキスト | N45: － | O45: ● | P45: － | T45: － | X45: 店舗* | AA45: 左詰め | AI45: ー | AR45: － | AS45: ー | AT45: ー | AU45: － | AY45: ー
B46: 8 | D46: 店舗アイテム | K46: チェックボックス + テキスト | N46: I | O46: － | P46: － | T46: － | X46: フローの開始時に選択対象店舗が選択された一覧 | AA46: デフォルトで選択されている。 | AI46: 有効 | AR46: ● | AS46: ー | AT46: ー | AU46: AP1509 | AY46: store
B47: 9 | D47: 前画面 | K47: ボタン | N47: I | O47: ● | P47: － | T47: － | X47: 前画面 | AA47: ー | AI47: 有効 | AR47: － | AS47: ー | AT47: ー | AU47: － | AY47: ー | BC47: イベントID：MD1506-04
B48: 10 | D48: 確定 | K48: ボタン | N48: I | O48: ● | P48: － | T48: － | X48: 確定 | AA48: ー | AI48: 有効 | AR48: － | AS48: ー | AT48: ー | AU48: － | AY48: ー | BC48: イベントID：MD1506-05
C55: いなげや様
B79: ■画面項目定義
B81: 画面項目ID | D81: 項目 | K81: タイプ | N81: I/O | O81: 多言語 | P81: 出力 | AR81: インプット | BC81: 備考
P82: マッピングデータ | X82: 初期値 | AA82: 表示コントロール | AI82: Control enable | AR82: 必須 | AS82: 数字 | AT82: 桁 | AU82: マッピングデータ
P83: API名 | T83: 項目 | AU83: API名 | AY83: 項目
B84: ０ | D84: コピータイトル | K84: テキスト | N84: － | O84: ● | P84: － | T84: － | X84: コピー | AA84: ー | AI84: － | AR84: － | AS84: ー | AT84: ー | AU84: － | AY84: ー | BC84: イベントID：MD1506-01
B85: 1 | D85: プリセットレイアウトタイプコード（タイトル） | K85: テキスト | N85: － | O85: ● | P85: － | X85: プリセットレイアウトタイプコード | AA85: 左詰め | AI85: ー | AR85: － | AS85: ー | AT85: ー | AU85: － | AY85: ー
B86: 2 | D86: プリセットレイアウトタイプコード（値） | K86: ドロップダウン | N86: I | O86: － | P86: － | T86: － | X86: － | AA86: ー | AI86: ー | AR86: ● | AS86: ● | AT86: ー | AU86: AP1509 | AY86: preset_layout_code | BC86: ドロップダウンメニューの表示： 1：キャッシュレス 2：キャッシュ
B87: 3 | D87: 名称（タイトル） | K87: テキスト | N87: － | O87: ● | P87: － | T87: － | X87: 名称* | AA87: 左詰め | AI87: ー | AR87: － | AS87: ー | AT87: ー | AU87: － | AY87: ー
B88: 4 | D88: 名称（値） | K88: EditText | N88: I | O88: － | P88: － | T88: － | X88: － | AA88: ー | AR88: ● | AS88: ー | AT88: ● | AU88: AP1509 | AY88: preset_layout_name | BC88: 最大50桁。
B89: 5 | D89: 全選択 | K89: ボタン | N89: I | O89: ● | P89: － | X89: 全選択 | AA89: ー | AI89: 少なくとも1つの店舗が選択されていない場合に有効にする。全ての店舗が選択されている場合に無効にする。 | AR89: － | AS89: ー | AT89: ー | AU89: － | AY89: ー | BC89: イベントID：MD1506-02
B90: 6 | D90: 全解除 | K90: ボタン | N90: I | O90: ● | P90: － | T90: － | X90: 全解除 | AA90: ー | AI90: 全ての店舗が選択されている場合に有効にする。少なくとも1つの店舗が選択されている場合に無効にする。 | AR90: － | AS90: ` | AT90: ー | AU90: － | AY90: ー | BC90: イベントID：MD1506-03
B91: 7 | D91: 店舗（タイトル） | K91: テキスト | N91: － | O91: ● | P91: － | T91: － | X91: 店舗* | AA91: 左詰め | AI91: ー | AR91: － | AS91: ー | AT91: ー | AU91: － | AY91: ー
B92: 8 | D92: 店舗アイテム | K92: チェックボックス + テキスト | N92: I | O92: － | P92: － | T92: － | X92: フローの開始時に選択対象店舗が選択された一覧 | AA92: デフォルトで選択されている。 | AI92: 有効 | AR92: ● | AS92: ー | AT92: ー | AU92: AP1509 | AY92: store
B93: 9 | D93: 前画面 | K93: ボタン | N93: I | O93: ● | P93: － | T93: － | X93: 前画面 | AA93: ー | AI93: 有効 | AR93: － | AS93: ー | AT93: ー | AU93: － | AY93: ー | BC93: イベントID：MD1506-04
B94: 10 | D94: 確定 | K94: ボタン | N94: I | O94: ● | P94: － | T94: － | X94: 確定 | AA94: ー | AI94: 有効 | AR94: － | AS94: ー | AT94: ー | AU94: － | AY94: ー | BC94: イベントID：MD1506-05
E99: `

Sheet MD1507
A1: システム名 | K1: システム種別 | W1: =IF(表紙!W1="","",表紙!W1) -> 詳細設計書 | AP1: 作成者 | AT1: 作成日 | AY1: 更新者 | BC1: 更新日 | BH1: 版数
A2: =IF(表紙!A2="","",表紙!A2) -> POSサーバー | K2: =IF(表紙!K2="","",表紙!K2) -> POSサーバー | AP2: =IF(表紙!AP2="","",表紙!AP2) -> DuNT | AT2: =IF(表紙!AT2="","",表紙!AT2) -> 45460 | AY2: =IF(表紙!AY2="","",表紙!AY2) -> LoiLV | BC2: =IF(表紙!BC2="","",表紙!BC2) -> 45723 | BH2: =IF(表紙!BH2="","",表紙!BH2) -> 0.65
A4: 機能カテゴリ | H4: =IF(表紙!H4="","",表紙!H4) -> 15_プリセットメニュー設定 | U4: 項目 | Z4: =IF(表紙!Z4="","",表紙!Z4) -> 画面設計書 | AP4: =MID(CELL("filename",A1),FIND("]",CELL("filename",A1))+1,255) -> MD1507
B7: ■MD1508_プリセットレイアウト新規作成モーダルのイメージ
B34: ■画面項目定義
B36: 画面項目ID | D36: 項目 | K36: タイプ | N36: I/O | O36: 多言語 | P36: 出力 | AR36: インプット | BC36: 備考
P37: マッピングデータ | X37: 初期値 | AA37: 表示コントロール | AI37: Control enable | AR37: 必須 | AS37: 数字 | AT37: 桁 | AU37: マッピングデータ
P38: API名 | T38: 項目 | AU38: API名 | AY38: 項目
B39: ０ | D39: ダイアログタイトル | K39: テキスト | N39: － | O39: ● | P39: － | T39: － | X39: コピー機能 | AA39: 左詰め | AI39: － | AR39: － | AS39: ー | AT39: ー | AU39: － | AY39: ー | BC39: イベントID：MD1507-01
B40: １ | D40: ダイアログコンテンツ | K40: テキスト | N40: － | O40: ● | X40: 以下の店舗にすでに同一のプリセットレイアウトコード＋予約日が存在します。 新規プリセットレイアウトコードとして追加登録するか？ 上書きするかを選択してください。 （コピー元と同一のデータは上書きが選択できません） | AA40: 左詰め
B41: 2 | D41: 店舗一覧 | K41: リスト | N41: － | O41: － | P41: － | T41: － | X41: － | AA41: － | AI41: － | AR41: － | AS41: ー | AT41: ー | AU41: － | AY41: ー
B42: 2.1 | D42: 店舗情報 | K42: テキスト | N42: － | O42: － | P42: AP1509 | T42: store_code:store_name | X42: コピーされた店舗コード: 店舗名称 | AA42: ー | AI42: ー | AR42: － | AS42: ー | AT42: ー | AU42: AP1510 | AY42: target_stores
B43: 2.2 | D43: 新規 | K43: ラジオボタン | N43: Ⅰ | O43: ● | P43: － | X43: 新規 | AA43: カスミ様：デフォルトでチェックする。 いなげや様：4つのプリセット8xxx1、8xxx2（今日2つのプリセット、明日2つのプリセット）が足りない場合はチェックする。 | AI43: カスミ様：デフォルトで有効になる。 いなげや様：4つのプリセット8xxx1、8xxx2（今日と明日）がある場合は無効になる。 | AR43: － | AS43: ー | AT43: ー | AU43: － | AY43: ー | BC43: 2つの項目のうち1つのみを選択可能とする。
B44: 2.3 | D44: 上書き | K44: ラジオボタン | N44: I | O44: ● | P44: － | T44: － | X44: 上書き | AA44: カスミ様：デフォルトでチェックを外す。 いなげや様：4つのプリセット8xxx1、8xxx2（今日と明日）がある場合はチェックする。 | AI44: ー | AR44: － | AS44: ー | AT44: ー | AU44: － | AY44: ー
B45: 3 | D45: 前画面 | K45: ボタン | N45: I | O45: ● | P45: － | T45: － | X45: 前画面 | AA45: テキストをボタンの中央にする。 | AI45: ー | AR45: － | AS45: ー | AT45: ー | AU45: － | AY45: ー | BC45: イベントID：MD1507-02
B46: 4 | D46: 確定 | K46: ボタン | N46: I | O46: ● | P46: － | T46: － | X46: 確定 | AA46: テキストをボタンの中央にする。 | AI46: ー | AR46: － | AS46: ー | AT46: ー | AU46: － | AY46: ー | BC46: イベントID：MD1507-03
E51: `

Sheet MD1508
A1: システム名 | K1: システム種別 | W1: =IF(表紙!W1="","",表紙!W1) -> 詳細設計書 | AP1: 作成者 | AT1: 作成日 | AY1: 更新者 | BC1: 更新日 | BH1: 版数
A2: =IF(表紙!A2="","",表紙!A2) -> POSサーバー | K2: =IF(表紙!K2="","",表紙!K2) -> POSサーバー | AP2: =IF(表紙!AP2="","",表紙!AP2) -> DuNT | AT2: =IF(表紙!AT2="","",表紙!AT2) -> 45460 | AY2: =IF(表紙!AY2="","",表紙!AY2) -> LoiLV | BC2: =IF(表紙!BC2="","",表紙!BC2) -> 45723 | BH2: =IF(表紙!BH2="","",表紙!BH2) -> 0.65
A4: 機能カテゴリ | H4: =IF(表紙!H4="","",表紙!H4) -> 15_プリセットメニュー設定 | U4: 項目 | Z4: =IF(表紙!Z4="","",表紙!Z4) -> 画面設計書 | AP4: =MID(CELL("filename",A1),FIND("]",CELL("filename",A1))+1,255) -> MD1508
B7: ■MD1508_プリセットレイアウト新規作成モーダルのイメージ
C8: カスミ様
C29: いなげや様
B50: ■MD1508_プリセットレイアウト新規作成モーダル（編集）のイメージ
D51: カスミ様
D72: いなげや様
B95: ■画面項目定義
B97: 画面項目ID | D97: 項目 | K97: タイプ | N97: I/O | O97: 多言語 | P97: 出力 | AR97: インプット | BC97: 備考
P98: マッピングデータ | X98: 初期値 | AA98: 表示コントロール | AI98: Control enable | AR98: 必須 | AS98: 数字 | AT98: 桁 | AU98: マッピングデータ
P99: API名 | T99: 項目 | AU99: API名 | AY99: 項目
B100: ０ | D100: 新規タイトル | K100: テキスト | N100: － | O100: ● | P100: － | T100: － | X100: 新規 | AA100: 左詰め | AI100: － | AR100: － | AS100: ー | AT100: ー | AU100: － | AY100: ー | BC100: イベントID：MD1508-01
B101: １ | D101: 店舗（タイトル） | K101: テキスト | N101: － | O101: ● | X101: 店舗 | AA101: 左詰め
B102: 2 | D102: 店舗（値） | K102: ドロップダウン | N102: Ⅰ | O102: － | P102: － | T102: － | X102: 選択されている店舗一覧 選択中のプリセットの店舗がリストに存在しない場合は、リストに追加する。 | AA102: ー | AI102: ー | AR102: ● | AS102: ー | AT102: ー | AU102: AP1509 | AY102: store | BC102: イベントID：MD1508-05
B103: 3 | D103: プリセットレイアウトコード（タイトル） | K103: テキスト | N103: － | O103: ● | P103: － | T103: － | X103: プリセットレイアウトコード | AA103: 左詰め | AI103: ー | AR103: － | AS103: ー | AT103: ー | AU103: － | AY103: ー
B104: 4.1 | D104: プリセットレイアウトコード（値） カスミ様 | K104: EditText | N104: I | O104: － | P104: － | T104: － | X104: － | AA104: ー | AI104: ー | AR104: ● | AS104: ● | AT104: ー | AU104: AP1509 | AY104: preset_layout_code | BC104: 数字のみ入力可能（4桁） 4桁未満の場合は「0」を自動追加する。
B105: 4.2 | D105: プリセットレイアウトコード（値） いなげや様 | K105: ドロップダウン | N105: I | O105: － | P105: － | T105: － | X105: 8xxx1：キャッシュレス | AA105: ー | AI105: ー | AR105: ● | AS105: ● | AT105: ー | AU105: AP1509 | AY105: preset_layout_code | BC105: ドロップダウンメニューの値： 8xxx1：キャッシュレス、 8xxx2：キャッシュ （xxx：店舗コードの末尾3桁）
B106: 5 | D106: 名称（タイトル） | K106: テキスト | N106: － | O106: ● | P106: － | X106: 名称 | AA106: 左詰め | AI106: ー | AR106: － | AS106: ー | AT106: ー | AU106: － | AY106: ー
B107: 6 | D107: 名称（値） | K107: EditText | N107: I | O107: － | P107: － | T107: － | X107: － | AA107: ー | AI107: ー | AR107: ● | AS107: ー | AT107: ● | AU107: AP1509 | AY107: preset_layout_name | BC107: 最大半角50文字
B108: 7 | D108: 前画面 | K108: ボタン | N108: I | O108: ● | P108: － | T108: － | X108: 前画面 | AA108: ー | AI108: 有効 | AR108: － | AS108: ー | AT108: ー | AU108: － | AY108: ー | BC108: イベントID：MD1508-02
B109: 8 | D109: 登録 | K109: ボタン | N109: I | O109: ● | P109: － | T109: － | X109: 登録 | AA109: ー | AI109: 有効 | AR109: － | AS109: ー | AT109: ー | AU109: － | AY109: ー | BC109: イベントID：MD1508-03
B110: 9 | D110: 編集タイトル | K110: テキスト | N110: － | O110: ● | P110: － | T110: － | X110: 編集 | AA110: 左詰め | AI110: ー | AR110: － | AS110: ー | AT110: ー | AU110: － | AY110: ー
B111: 10 | D111: 更新 | K111: ボタン | N111: I | O111: ● | P111: － | T111: － | X111: 更新 | AA111: ー | AI111: 有効 | AR111: － | AS111: ー | AT111: ー | AU111: － | AY111: ー | BC111: イベントID：MD1508-04
E116: `

Sheet SC1502
A1: システム名 | K1: システム種別 | W1: =IF(表紙!W1="","",表紙!W1) -> 詳細設計書 | AP1: 作成者 | AT1: 作成日 | AY1: 更新者 | BC1: 更新日 | BH1: 版数
A2: =IF(表紙!A2="","",表紙!A2) -> POSサーバー | K2: =IF(表紙!K2="","",表紙!K2) -> POSサーバー | AP2: =IF(表紙!AP2="","",表紙!AP2) -> DuNT | AT2: =IF(表紙!AT2="","",表紙!AT2) -> 45460 | AY2: =IF(表紙!AY2="","",表紙!AY2) -> LoiLV | BC2: =IF(表紙!BC2="","",表紙!BC2) -> 45723 | BH2: =IF(表紙!BH2="","",表紙!BH2) -> 0.65
A4: 機能カテゴリ | H4: =IF(表紙!H4="","",表紙!H4) -> 15_プリセットメニュー設定 | U4: 項目 | Z4: =IF(表紙!Z4="","",表紙!Z4) -> 画面設計書 | AP4: =MID(CELL("filename",A1),FIND("]",CELL("filename",A1))+1,255) -> SC1502
B8: ■SC1502_プリセット（レイアウト）編集画面のイメージ・「+」ボタンをタッチした後
C9: いなげや会社の画面イメージ
D43: カスミ会社の画面イメージ
B71: l画面項目定義
B73: 画面項目ID | D73: 項目 | K73: タイプ | N73: I/O | O73: 多言語 | P73: 出力 | AR73: インプット | BC73: 備考
P74: マッピングデータ | X74: 初期値 | AA74: 表示コントロール | AI74: Control enable | AR74: 必須 | AS74: 数字 | AT74: 桁 | AU74: マッピングデータ
P75: API名 | T75: 項目 | AU75: API名 | AY75: 項目
B76: 0 | D76: 画面タイトル | K76: テキスト | N76: － | O76: ● | P76: － | T76: － | X76: プリセット設定 | AA76: ー | AI76: － | AR76: － | AS76: ー | AT76: ー | AU76: － | AY76: ー | BC76: イベントID：SC1502-01
B77: 1 | D77: 店舗（タイトル） | K77: テキスト | N77: － | O77: ● | P77: － | T77: － | X77: 店舗 | AA77: ー | AI77: ー | AR77: － | AS77: ー | AT77: ー | AU77: － | AY77: ー
B78: 2 | D78: 店舗（値） | K78: テキスト | N78: O | O78: － | P78: AP1501 | T78: store_code:store_name | X78: － | AA78: ー | AI78: ー | AR78: － | AS78: ー | AT78: ー | AU78: AP1508 | AY78: store_code
B79: 3.1 | D79: 名称（タイトル） | K79: テキスト | N79: － | O79: ● | P79: － | X79: 名称* | AA79: ー | AI79: ー | AR79: － | AS79: ー | AT79: ー | AU79: － | AY79: ー
B80: 3.2 | D80: 名称（値） | K80: EditText | N80: O | O80: － | P80: AP1501 | T80: preset_layout_name | X80: － | AA80: ー | AI80: 有効 | AR80: ● | AS80: ● | AT80: ● | AU80: AP1508 | AY80: preset_layout_code | BC80: 最大全角25文字（半角50文字）
B81: 4.1 | D81: 状態（タイトル） | K81: テキスト | N81: － | O81: ● | P81: － | X81: 状態 | AA81: ー | AI81: ー | AR81: － | AS81: ー | AT81: ー | AU81: － | AY81: ー
B82: 4.2 | D82: 状態（値） | K82: テキスト | N82: O | O82: － | P82: AP1501 | T82: status | X82: － | AA82: ー | AI82: ー | AR82: ● | AS82: － | AT82: － | AU82: － | AY82: ー
B83: 5 | D83: プリセットレイアウトコード（タイトル） | K83: テキスト | N83: － | O83: ● | P83: － | X83: プリセットレイアウトコード | AA83: ー | AI83: ー | AR83: － | AS83: ー | AT83: ー | AU83: － | AY83: ー
B84: 6 | D84: プリセットレイアウトコード（値） | K84: テキスト | N84: O | O84: － | P84: AP1501 | T84: preset_layout_code | X84: － | AA84: ー | AI84: ー | AR84: － | AS84: ー | AT84: ー | AU84: AP1508 | AY84: preset_layout_name
B85: 7 | D85: F04: クリア | K85: ボタン | N85: I | O85: ● | P85: － | T85: － | X85: F04: クリア | AA85: ー | AI85: 有効 | AR85: － | AS85: ー | AT85: ー | AU85: － | AY85: ー | BC85: イベントID：SC1502-02
B86: 8 | D86: F09: 確定 | K86: ボタン | N86: I | O86: ● | P86: － | T86: － | X86: F09: 確定 | AA86: ー | AI86: デフォルト：無効。変更データが適用された場合に有効にする。 | AR86: － | AS86: ー | AT86: ー | AU86: － | AY86: ー | BC86: イベントID：SC1502-03
B87: 9 | D87: + | K87: ボタン | N87: I | O87: － | P87: － | T87: － | X87: + | AA87: タブ数 < 10の場合に表示する。 | AI87: ー | AR87: － | AS87: ー | AT87: ー | AU87: － | AY87: ー | BC87: イベントID：SC1502-04
B88: 10 | D88: ビュータイトル | K88: テキスト | N88: － | O88: ● | P88: － | T88: － | X88: タブ編集 | AA88: デフォルトで最初にpage_number = 1の情報を表示する。 | AI88: ー | AR88: － | AS88: ー | AT88: ー | AU88: － | AY88: ー
B89: 11 | D89: タブ名称（タイトル） | K89: テキスト | N89: － | O89: ● | P89: － | T89: － | X89: タブ名称 | AI89: ー | AR89: － | AS89: ー | AT89: ー | AU89: － | AY89: ー
B90: 12 | D90: タブ名称（値） | K90: EditText | N90: I | O90: － | P90: AP1502 | T90: Menu.description | X90: － | AA90: ー | AI90: AP1502のタブのis_hiddenの値がfalseの場合に有効にする。 | AR90: － | AS90: ー | AT90: ー | AU90: AP1508 | AY90: Menu.description | BC90: 最大全角25文字（半角50文字）
B91: 13 | D91: タブの色 | K91: テキスト | N91: － | O91: ● | P91: － | T91: － | X91: タブの色 | AI91: ー | AR91: － | AS91: ー | AT91: ー | AU91: － | AY91: ー
B92: 14 | D92: 色 | K92: ビュー | N92: I | O92: － | P92: AP1502 | T92: Menu.style_key | X92: － | AA92: ー | AI92: AP1502のタブのis_hiddenの値がfalseの場合に有効にする。 | AR92: － | AS92: ー | AT92: ー | AU92: AP1508 | AY92: Menu.style_key | BC92: 未設定の場合、デフォルトで最初の色が選択される。
B93: 15 | D93: 削除 | K93: ボタン | N93: I | O93: ● | P93: － | T93: － | X93: － | AA93: － | AI93: 有効 | AR93: － | AS93: － | AT93: － | AU93: － | AY93: － | BC93: イベントID：SC1502-23
B94: 16 | D94: 表示設定（タイトル） | K94: テキスト | N94: － | O94: ● | P94: － | T94: － | X94: 表示設定 | AI94: ー | AR94: － | AS94: ー | AT94: ー | AU94: － | AY94: ー
B95: 16.1 | D95: 非表示 | K95: チェックボックス + テキスト | N95: I | O95: ● | P95: AP1502 | T95: Menu.is_hidden | X95: 非表示 | AA95: デフォルトで選択されない。 | AI95: 有効
B96: 16.2 | D96: レジ画面表示 | K96: チェックボックス + テキスト | N96: I | O96: ● | P96: AP1502 | T96: Menu.is_display_on_cash_machine | X96: レジ画面表示 | AA96: デフォルトで選択されない。 | AI96: AP1502のタブのis_hiddenの値がfalseの場合に有効にし、項目16.1が選択されているか、AP1502のタブのis_hiddenの値がtrueの場合に無効にする。 | AR96: － | AS96: ー | AT96: ー | AU96: － | AY96: ー
B97: 16.3 | D97: 客用画面表示 | K97: チェックボックス + テキスト | N97: I | O97: ● | P97: AP1502 | T97: Menu.is_display_on_customer_screen | X97: 客用画面表示 | AA97: デフォルトで選択されない。 | AI97: デフォルト：無効。項目16.2が選択され、AP1502のタブのis_hiddenの値がfalseの場合に有効にする。 | AR97: － | AS97: ー | AT97: ー | AU97: － | AY97: ー
B98: 17 | D98: 適用 | K98: ボタン | N98: I | O98: ● | P98: － | T98: － | X98: 適用 | AA98: ー | AI98: 有効 | AR98: － | AS98: ー | AT98: ー | AU98: － | AY98: ー | BC98: イベントID：SC1502-05
B99: 18 | D99: プリセットレイアウトメニューボタンビュー | K99: ビュー | N99: － | O99: － | P99: AP1502 | T99: Menu.style_key | X99: － | AA99: ー | AI99: ー | AR99: － | AS99: ー | AT99: ー | AU99: － | AY99: ー | BC99: イベントID：SC1502-20 イベントID：SC1502-21
B100: 19 | D100: プリセットレイアウトボタンビュー | K100: ビュー | N100: － | O100: － | P100: － | T100: － | X100: － | AA100: ー | AI100: AP1502のタブのis_hiddenの値がfalseの場合に有効にする。 | AR100: － | AS100: ー | AT100: ー | AU100: － | AY100: ー | BC100: 項目18に従ってビューの色を表示する。
B102: ■SC1502_プリセット（レイアウト）編集画面のイメージ・プリセット設定の場合
B137: l画面項目定義
B139: 画面項目ID | D139: 項目 | K139: タイプ | N139: I/O | O139: 多言語 | P139: 出力 | AR139: インプット | BC139: 備考
P140: マッピングデータ | X140: 初期値 | AA140: 表示コントロール | AI140: Control enable | AR140: 必須 | AS140: 数字 | AT140: 桁 | AU140: マッピングデータ
P141: API名 | T141: 項目 | AU141: API名 | AY141: 項目
...

Sheet テンプレート
A1: システム名 | K1: システム種別 | W1: =IF(表紙!W1="","",表紙!W1) -> 詳細設計書 | AP1: 作成者 | AT1: 作成日 | AY1: 更新者 | BC1: 更新日 | BH1: 版数
A2: =IF(表紙!A2="","",表紙!A2) -> POSサーバー | K2: =IF(表紙!K2="","",表紙!K2) -> POSサーバー | AP2: =IF(表紙!AP2="","",表紙!AP2) -> DuNT | AT2: =IF(表紙!AT2="","",表紙!AT2) -> 45460 | AY2: =IF(表紙!AY2="","",表紙!AY2) -> LoiLV | BC2: =IF(表紙!BC2="","",表紙!BC2) -> 45723 | BH2: =IF(表紙!BH2="","",表紙!BH2) -> 0.65
A4: 機能カテゴリ | H4: =IF(表紙!H4="","",表紙!H4) -> 15_プリセットメニュー設定 | U4: 項目 | Z4: =IF(表紙!Z4="","",表紙!Z4) -> 画面設計書 | AP4: =MID(CELL("filename",A1),FIND("]",CELL("filename",A1))+1,255) -> テンプレート
B7: ■イメージ
B57: ■画面項目定義
B59: 画面項目ID | D59: 項目 | K59: タイプ | N59: I/O | O59: 多言語 | P59: 出力 | AR59: インプット | BC59: 備考
P60: マッピングデータ | X60: 初期値 | AA60: 表示コントロール | AI60: Control enable | AR60: 必須 | AS60: 数字 | AT60: 桁 | AU60: マッピングデータ
P61: API名 | T61: 項目 | AU61: API名 | AY61: 項目
B62: 1 | K62: テキスト | N62: － | O62: ● | P62: － | T62: － | X62: Android POS Control | AA62: ー | AI62: － | AR62: － | AS62: ー | AT62: ー | AU62: － | AY62: ー
B63: 2 | K63: テキスト | N63: O | O63: ● | P63: － | T63: － | X63: ユーザーID | AA63: ー | AI63: ー | AR63: － | AS63: ー | AT63: ー | AU63: － | AY63: ー
B64: 3 | K64: テキスト | N64: I | O64: － | P64: － | X64: － | AA64: ー | AI64: ー | AR64: － | AS64: ー | AT64: ー | AU64: － | AY64: ー
B65: 4 | K65: テキスト | N65: O | O65: ● | P65: － | T65: － | X65: Password | AA65: ー | AI65: ー | AR65: － | AS65: ー | AT65: ー | AU65: － | AY65: ー
B66: 5 | K66: EditText | N66: I | O66: － | P66: － | T66: － | X66: － | AA66: ー | AI66: ー | AR66: － | AS66: ー | AT66: ー | AU66: － | AY66: ー
B67: 6 | K67: ボタン | N67: I | O67: ● | P67: － | T67: － | X67: ログイン | AA67: ー | AI67: 有効 | AR67: － | AS67: ー | AT67: ー | AU67: － | AY67: ー | BC67: Login-01/EmployeeMaster
