Workbook

Sheet 表紙
A1: システム名 | K1: システム種別 | W1: 詳細設計書 | AP1: 作成者 | AT1: 作成日 | AY1: 更新者 | BC1: 更新日 | BH1: 版数
A2: POSサーバー | K2: POSサーバ | AP2: =改訂履歴!$H$11 -> TinNH | AT2: =改訂履歴!$B$11 -> 45470 | AY2: =LOOKUP(2,1/(改訂履歴!H11:H30000<>""),改訂履歴!H11:H30000) -> LoiLV | BC2: =LOOKUP(2,1/(改訂履歴!B11:B30000<>""),改訂履歴!B11:B30000) -> 45477 | BH2: =LOOKUP(2,1/(改訂履歴!O11:O30000<>""),改訂履歴!O11:O30000) -> 0.12
A4: 機能カテゴリ | H4: 66_券マスタ設定 | U4: 項目 | Z4: 画面設計書 | AP4: {=RIGHT(CELL("filename",$A$1),LEN(CELL("filename",$A$1))-FIND("]",CELL("filename",$A$1)))} -> 表紙
L16: POSサーバーの基本設計書
L24: =K2&"/"&H4&"/"&Z4 -> POSサーバ/66_券マスタ設定/画面設計書
Q44: 承認日 | AA44: 承認者 | AQ44: 版数

Sheet 改訂履歴
A1: システム名 | K1: システム種別 | W1: =IF(表紙!W1="","",表紙!W1) -> 詳細設計書 | AP1: 作成者 | AT1: 作成日 | AY1: 更新者 | BC1: 更新日 | BH1: 版数
A2: =IF(表紙!A2="","",表紙!A2) -> POSサーバー | K2: =IF(表紙!K2="","",表紙!K2) -> POSサーバ | AP2: =IF(表紙!AP2="","",表紙!AP2) -> TinNH | AT2: =IF(表紙!AT2="","",表紙!AT2) -> 45470 | AY2: =IF(表紙!AY2="","",表紙!AY2) -> LoiLV | BC2: =IF(表紙!BC2="","",表紙!BC2) -> 45477 | BH2: =IF(表紙!BH2="","",表紙!BH2) -> 0.12
A4: 機能カテゴリー | H4: =IF(表紙!H4="","",表紙!H4) -> 66_券マスタ設定 | U4: 項目 | Z4: =IF(表紙!Z4="","",表紙!Z4) -> 画面設計書 | AP4: {=RIGHT(CELL("filename",$A$1),LEN(CELL("filename",$A$1))-FIND("]",CELL("filename",$A$1)))} -> 改訂履歴
B8: ■改訂履歴
B10: 更新日 | H10: 更新者 | O10: 版数 | S10: 更新内容 | AX10: 承認日 | BD10: 承認者
B11: 45470 | H11: TinNH | O11: 0.1 | S11: 新規作成
B13: 45474 | H13: LoiLV | O13: 0.11 | S13: 更新
B15: 45476 | H15: LoiLV | O15: 0.12 | S15: 支払単位額/値引金額・率の更新
B17: 45477 | H17: LoiLV | O17: 0.12 | S17: 更新

Sheet SC6601
A1: システム名 | K1: システム種別 | W1: =IF(表紙!W1="","",表紙!W1) -> 詳細設計書 | AP1: 作成者 | AT1: 作成日 | AY1: 更新者 | BC1: 更新日 | BH1: 版数
A2: =IF(表紙!A2="","",表紙!A2) -> POSサーバー | K2: =IF(表紙!K2="","",表紙!K2) -> POSサーバ | AP2: =IF(表紙!AP2="","",表紙!AP2) -> TinNH | AT2: =IF(表紙!AT2="","",表紙!AT2) -> 45470 | AY2: =IF(表紙!AY2="","",表紙!AY2) -> LoiLV | BC2: =IF(表紙!BC2="","",表紙!BC2) -> 45477 | BH2: =IF(表紙!BH2="","",表紙!BH2) -> 0.12
A4: 機能カテゴリ | H4: =IF(表紙!H4="","",表紙!H4) -> 66_券マスタ設定 | U4: 項目 | Z4: =IF(表紙!Z4="","",表紙!Z4) -> 画面設計書 | AP4: =MID(CELL("filename",A1),FIND("]",CELL("filename",A1))+1,255) -> SC6601
B7: ■イメージ
B47: ■画面項目定義
B49: 画面項目ID | D49: 項目 | K49: Type | N49: I/O | O49: 多言語 | P49: アウトプット | AR49: インプット | BC49: 備考
P50: マッピングデータ | X50: 初期値 | AA50: 表示コントロール | AI50: Control enable | AR50: 必須 | AS50: 数字 | AT50: 文字 | AU50: マッピングデータ
P51: API名 | T51: 項目 | AU51: API名 | AY51: 項目
B52: 0 | D52: 画面タイトル | K52: テキスト | N52: － | O52: ● | P52: － | T52: － | X52: 券マスタ設定 | AA52: ー | AI52: － | AR52: － | AS52: ー | AT52: ー | AU52: － | AY52: ー | BC52: イベントID：SC6601-01
B53: 1 | D53: CSVファイル出力 | K53: ボタン | N53: I | O53: － | P53: － | T53: － | X53: CSVアイコン | AA53: ー | AI53: デフォルト：有効 | AR53: － | AS53: ー | AT53: ー | AU53: － | AY53: ー | BC53: イベントID：SC6601-02
B54: 2 | D54: 印刷 | K54: ボタン | N54: I | O54: － | P54: － | T54: － | X54: 印刷アイコン | AA54: ー | AI54: デフォルト：無効 | AR54: － | AS54: ー | AT54: ー | AU54: － | AY54: ー
B55: 3 | D55: 店舗一覧 | K55: リンク | N55: － | O55: － | P55: － | T55: － | X55: － | AA55: ー | AI55: ー | AR55: － | AS55: ー | AT55: ー | AU55: － | AY55: ー | BC55: ー
B56: 4 | D56: 券種類 (タイトル) | K56: テキスト | N56: － | O56: ● | P56: － | T56: － | X56: 種類 | AA56: ー | AI56: ー | AR56: － | AS56: ー | AT56: ー | AU56: － | AY56: ー | BC56: ー
B57: 5 | D57: 券種類（支払券） | K57: ラジオボタン | N57: I | O57: ● | P57: － | T57: － | X57: 支払券 | AA57: デフォルト：チェックを入れる。 | AI57: デフォルト：有効 | AR57: ● | AS57: ー | AT57: ー | AU57: AP6601 | AY57: type | BC57: ー
B58: 6 | D58: 券種類（値引券） | K58: ラジオボタン | N58: I | O58: ● | P58: － | T58: － | X58: 値引券 | AA58: デフォルト：チェックを外す。 | AI58: デフォルト：有効 | AR58: ● | AS58: ー | AT58: ー | AU58: AP6601 | AY58: type | BC58: ー
B59: 7 | D59: 券名称（タイトル） | K59: テキスト | N59: － | O59: ● | P59: － | T59: － | X59: 券名称 | AA59: ー | AI59: ー | AR59: － | AS59: ー | AT59: ー | AU59: － | AY59: ー | BC59: ー
B60: 8 | D60: 券名称（値） | K60: EditText | N60: I | O60: － | P60: － | T60: － | X60: － | AA60: ー | AI60: デフォルト：有効 | AR60: － | AS60: ー | AT60: ー | AU60: AP6601 | AY60: keyword | BC60: ー
B61: 9 | D61: マッチングタイプ | K61: プルダウン | N61: I | O61: ● | P61: － | T61: － | X61: を含む | AA61: ー | AI61: ー | AR61: － | AS61: ー | AT61: ー | AU61: AP6601 | AY61: search_type | BC61: 0:を含む, 1:から始まる, 2:で終わる
B62: 10 | D62: 検索 | K62: ボタン | N62: I | O62: ● | P62: － | T62: － | X62: 検索 | AA62: ー | AI62: デフォルト：有効 | AR62: － | AS62: ー | AT62: ー | AU62: － | AY62: ー | BC62: イベントID：SC6601-03
B63: 11 | D63: 券マスタ表 | K63: テーブル | N63: O | O63: － | P63: － | T63: － | X63: － | AA63: total_count >0の場合に表示する。 | AI63: ー | AR63: － | AS63: ー | AT63: ー | AU63: － | AY63: ー | BC63: ー
B64: 11.1 | D64: 店舗（ヘッダー） | K64: テキスト | N64: O | O64: ● | P64: － | T64: － | X64: 店舗 | AA64: ー | AI64: ー | AR64: － | AS64: ー | AT64: ー | AU64: － | AY64: ー | BC64: ー
B65: 11.2 | D65: 店舗（ボディ） | K65: テキスト | N65: I/O | O65: － | P65: AP6601 | T65: store_code, store_name | X65: － | AA65: ー | AI65: ー | AR65: － | AS65: ー | AT65: ー | AU65: AP6603 | AY65: store_code | BC65: 表示形式： store_code : store_name
B66: 11.3 | D66: 券コード（ヘッダー） | K66: テキスト | N66: O | O66: ● | P66: － | T66: － | X66: 券コード | AA66: ー | AI66: ー | AR66: － | AS66: ー | AT66: ー | AU66: － | AY66: ー | BC66: ー
... B74: 13.1 | D74: 登録店舗（タイトル） | K74: テキスト | N74: O | O74: ● | P74: － | T74: － | X74: 対象店舗 | AA74: ー | AI74: ー | AR74: － | AS74: ー | AT74: ー | AU74: － | AY74: ー | BC74: ー
B75: 13.2 | D75: 全選択 | K75: ボタン | N75: I/O | O75: ● | P75: － | T75: － | X75: 全選択 | AA75: ー | AI75: デフォルト：有効 | AU75: － | AY75: ー | BC75: イベントID：SC6601-04
B76: 13.3 | D76: 全解除 | K76: ボタン | N76: I/O | O76: ● | P76: － | T76: － | X76: 全解除 | AA76: ー | AI76: デフォルト：有効 | AR76: － | AS76: ー | AT76: ー | AU76: － | AY76: ー | BC76: イベントID：SC6601-05
B77: 13.4 | D77: 登録店舗（値） | K77: チェックボックス | N77: I/O | O77: － | P77: AP1501 | T77: include_stores,store_code, store_name | X77: － | AA77: include_storesにstore_codeが含まれている場合にチェックを入れる。 | AI77: ー | AR77: － | AS77: ー | AT77: ー | AU77: AP6603 | AY77: include_stores | BC77: 表示形式: {□}{store_code : store_name} 複数の店舗選択可能。
B78: 14 | D78: 取消 | K78: ボタン | N78: I | O78: ● | P78: － | T78: － | X78: 取消 | AA78: ー | AI78: デフォルト：有効 | AR78: － | AS78: ー | AT78: ー | AU78: － | AY78: ー | BC78: イベントID：SC6601-06
B79: 15 | D79: 削除 | K79: ボタン | N79: I | O79: ● | P79: － | T79: － | X79: 削除 | AA79: ー | AI79: デフォルト：無効。レコードを選択するした場合、有効になる。 | AR79: － | AS79: ー | AT79: ー | AU79: － | AY79: ー | BC79: イベントID：SC6601-07
B80: 16 | D80: 修正 | K80: ボタン | N80: I | O80: ● | P80: － | T80: － | X80: 編集 | AA80: ー | AI80: デフォルト：無効。レコードを選択するした場合、有効になる。 | AR80: － | AS80: ー | AT80: ー | AU80: － | AY80: ー | BC80: イベントID：SC6601-08
B81: 17 | D81: 新規作成 | K81: ボタン | N81: I | O81: ● | P81: － | T81: － | X81: 新規 | AA81: ー | AI81: デフォルト：有効 | AR81: － | AS81: ー | AT81: ー | AU81: － | AY81: ー | BC81: イベントID：SC6601-09
B82: 18 | D82: 「確定」 | K82: ボタン | N82: I | O82: ● | P82: － | T82: － | X82: 確定 | AA82: ー | AI82: デフォルト：無効。券マスタ表の情報に変更がある場合、有効になる。 | AR82: － | AS82: ー | AT82: ー | AU82: － | AY82: ー | BC82: イベントID：SC6601-10

Sheet MD6601 (支払券追加)
A1: システム名 | K1: システム種別 | W1: 詳細設計書 | AP1: 作成者 | AT1: 作成日 | AY1: 更新者 | BC1: 更新日 | BH1: 版数
A2: POSサーバー | K2: POSサーバー | AP2: =IF(表紙!AP2="","",表紙!AP2) -> TinNH | AT2: =IF(表紙!AT2="","",表紙!AT2) -> 45470 | AY2: =IF(表紙!AY2="","",表紙!AY2) -> LoiLV | BC2: =IF(表紙!BC2="","",表紙!BC2) -> 45477 | BH2: =IF(表紙!BH2="","",表紙!BH2) -> 0.12
A4: 機能カテゴリ | H4: =IF(表紙!H4="","",表紙!H4) -> 66_券マスタ設定 | U4: 項目 | Z4: 画面設計書 | AP4: =MID(CELL("filename",A1),FIND("]",CELL("filename",A1))+1,255) -> MD6601 (支払券追加)
B7: ■イメージ
B48: ■画面項目定義
B50: 画面項目ID | D50: 項目 | K50: Type | N50: I/O | O50: 多言語 | P50: アウトプット | AR50: インプット | BC50: 備考
P51: マッピングデータ | X51: 初期値 | AA51: 表示コントロール | AI51: Control enable | AR51: 必須 | AS51: 数字 | AT51: 文字 | AU51: マッピングデータ
P52: API名 | T52: 項目 | AU52: API名 | AY52: 項目
B53: 0 | D53: モーダルタイトル | K53: テキスト | N53: － | O53: ● | P53: － | T53: － | X53: 支払新規 | AA53: ー | AI53: － | AR53: － | AS53: ー | AT53: ー | AU53: － | AY53: ー | BC53: イベントID：MD6601-01
B54: 1 | D54: 店舗（タイトル） | K54: テキスト | N54: － | O54: ● | P54: － | T54: － | X54: 店舗 | AA54: ー | AI54: ー | AR54: － | AS54: ー | AT54: ー | AU54: － | AY54: ー | BC54: ー
B55: 2 | D55: 店舗（値） | K55: プルダウン | N55: I | O55: ● | P55: － | T55: － | X55: － | AA55: ー | AI55: デフォルト：有効 | AR55: ● | AS55: ー | AT55: ー | AU55: AP6601, AP6602, AP6603 | AY55: selected_stores, selected_store,store_code | BC55: 表示形式: {store_code:store_name} 値一覧には1501モーダルで選択された店舗が含まれている。
B56: 3 | D56: 券コード （タイトル） | K56: テキスト | N56: I | O56: ● | P56: － | T56: － | X56: 券コード | AA56: ー | AI56: ー | AR56: ー | AS56: ー | AT56: ー | AU56: － | AY56: ー | BC56: ー
B57: 4 | D57: 券コード(値) | K57: EditText | N57: I/O | O57: － | P57: AP6601 | T57: code | X57: － | AA57: ー | AI57: デフォルト：有効 | AR57: ● | AS57: ● | AT57: ー | AU57: AP6602, AP6603 | AY57: code | BC57: 最大15文字 イベントID：MD6601-02
B58: 5 | D58: 券検索 | K58: ボタン | N58: I | O58: － | P58: － | T58: － | X58: － | AA58: ー | AI58: デフォルト：有効 | AR58: ー | AS58: ー | AT58: ー | AU58: － | AY58: ー | BC58: イベントID：MD6601-03
B59: 6 | D59: 券名称（タイトル） | K59: テキスト | N59: － | O59: ● | P59: － | T59: － | X59: 券名称 | AA59: ー | AI59: ー | AR59: － | AS59: ー | AT59: ー | AU59: － | AY59: ー | BC59: ー
B60: 7 | D60: 券名称（値） | K60: EditText | N60: I/O | O60: － | P60: AP6601 | T60: name | X60: － | AA60: ー | AI60: ー | AR60: － | AS60: ー | AT60: ー | AU60: AP6603 | AY60: name | BC60: ー
B61: 8 | D61: 単位額(タイトル) | K61: テキスト | N61: － | O61: ● | P61: － | T61: － | X61: 値引金額・率 | AA61: ー | AI61: ー | AR61: － | AS61: ー | AT61: ー | AU61: － | AY61: ー | BC61: ー
B62: 9 | D62: 単位額（値） | K62: EditText | N62: I | O62: － | P62: AP6601 | T62: amount | X62: － | AA62: ー | AI62: ー | AR62: － | AS62: ー | AT62: ー | AU62: AP6603 | AY62: amount | BC62: 最大6文字
B63: 10 | D63: 単位額（単位） | K63: テキスト | N63: － | O63: ● | P63: － | T63: － | X63: 円 | AA63: ー | AI63: ー | AR63: － | AS63: ー | AT63: ー | AU63: － | AY63: ー | BC63: ー
B64: 11 | D64: 返品使用許可フラグ（タイトル） | K64: テキスト | N64: － | O64: ● | P64: － | T64: － | X64: 返品使用許可フラグ | AA64: ー | AI64: ー | AR64: － | AS64: ー | AT64: ー | AU64: － | AY64: ー | BC64: ー
... B97: 44 | D97: 登録 | K97: ボタン | N97: I | O97: ● | P97: － | T97: － | X97: 登録 | AA97: ー | AI97: デフォルト：有効 | AR97: － | AS97: ー | AT97: ー | AU97: － | AY97: ー | BC97: イベントID：MD6601-05

Sheet MD6601 (値引券追加)
A1: システム名 | K1: システム種別 | W1: 詳細設計書 | AP1: 作成者 | AT1: 作成日 | AY1: 更新者 | BC1: 更新日 | BH1: 版数
A2: POSサーバー | K2: POSサーバー | AP2: =IF(表紙!AP2="","",表紙!AP2) -> TinNH | AT2: =IF(表紙!AT2="","",表紙!AT2) -> 45470 | AY2: =IF(表紙!AY2="","",表紙!AY2) -> LoiLV | BC2: =IF(表紙!BC2="","",表紙!BC2) -> 45477 | BH2: =IF(表紙!BH2="","",表紙!BH2) -> 0.12
A4: 機能カテゴリ | H4: =IF(表紙!H4="","",表紙!H4) -> 66_券マスタ設定 | U4: 項目 | Z4: 画面設計書 | AP4: =MID(CELL("filename",A1),FIND("]",CELL("filename",A1))+1,255) -> MD6601 (値引券追加)
B7: ■イメージ
B47: ■画面項目定義
B49: 画面項目ID | D49: 項目 | K49: Type | N49: I/O | O49: 多言語 | P49: アウトプット | AR49: インプット | BC49: 備考
P50: マッピングデータ | X50: 初期値 | AA50: 表示コントロール | AI50: Control enable | AR50: 必須 | AS50: 数字 | AT50: 文字 | AU50: マッピングデータ
P51: API名 | T51: 項目 | AU51: API名 | AY51: 項目
B52: 0 | D52: モーダルタイトル | K52: テキスト | N52: － | O52: ● | P52: － | T52: － | X52: 値引新規 | AA52: ー | AI52: － | AR52: － | AS52: ー | AT52: ー | AU52: － | AY52: ー | BC52: イベントID：MD6601-06
B53: 1 | D53: 店舗（タイトル） | K53: テキスト | N53: － | O53: ● | P53: － | T53: － | X53: 店舗 | AA53: ー | AI53: ー | AR53: － | AS53: ー | AT53: ー | AU53: － | AY53: ー | BC53: ー
B54: 2 | D54: 店舗（値） | K54: プルダウン | N54: I | O54: ● | P54: － | T54: － | X54: － | AA54: ー | AI54: デフォルト：有効 | AR54: ● | AS54: ー | AT54: ー | AU54: AP6601, AP6602, AP6603 | AY54: selected_stores, selected_store,store_code | BC54: 表示形式: {store_code:store_name} 値一覧には1501モーダルで選択された店舗が含まれている。
B55: 3 | D55: 券コード （タイトル） | K55: テキスト | N55: I | O55: ● | P55: － | T55: － | X55: 券コード | AA55: ー | AI55: ー | AR55: ー | AS55: ー | AT55: ー | AU55: － | AY55: ー | BC55: ー
B56: 4 | D56: 券コード(値) | K56: EditText | N56: I/O | O56: － | P56: AP6601 | T56: code | X56: － | AA56: ー | AI56: デフォルト：有効 | AR56: ● | AS56: ● | AT56: ー | AU56: AP6602, AP6603 | AY56: code | BC56: 最大15文字 イベントID：MD6601-02
B57: 5 | D57: 券検索 | K57: ボタン | N57: I | O57: － | P57: － | T57: － | X57: － | AA57: ー | AI57: デフォルト：有効 | AR57: ー | AS57: ー | AT57: ー | AU57: － | AY57: ー | BC57: イベントID：MD6601-03
B58: 6 | D58: 券名称（タイトル） | K58: テキスト | N58: － | O58: ● | P58: － | T58: － | X58: 券名称 | AA58: ー | AI58: ー | AR58: － | AS58: ー | AT58: ー | AU58: － | AY58: ー | BC58: ー
B59: 7 | D59: 券名称（値） | K59: EditText | N59: I | O59: － | P59: － | T59: － | X59: － | AA59: ー | AI59: ー | AR59: － | AS59: ー | AT59: ー | AU59: AP6603 | AY59: name | BC59: ー
B60: 8 | D60: 値引金額・率・タイプ（タイトル） | K60: テキスト | N60: － | O60: ● | P60: － | T60: － | X60: 値引金額・率・タイプ | AA60: ー | AI60: ー | AR60: － | AS60: ー | AT60: ー | BC60: ー
B61: 9 | D61: 値引金額・率・タイプ（値引） | K61: ラジオボタン | N61: I | O61: ● | P61: － | T61: － | X61: 値引 | AA61: デフォルト：チェックを入れる。 | AI61: ー | AR61: ● | AS61: ー | AT61: ー | AU61: AP6603 | AY61: discount_type
B62: 10 | D62: 値引金額・率・タイプ（割引） | K62: ラジオボタン | N62: I | O62: ● | P62: － | T62: － | X62: 割引 | AA62: デフォルト：チェックを外す。 | AI62: ー | AR62: ● | AS62: ー | AT62: ー | AU62: AP6603 | AY62: discount_type | BC62: ー
B63: 11 | D63: 値引金額 | K63: EditText | N63: I | O63: － | P63: － | T63: － | X63: － | AA63: ー | AI63: デフォルト：有効。[値引金額・率・タイプ（割引）]が選択された場合に無効になる。 | AR63: ● | AS63: ● | AT63: ー | AU63: AP6603 | AY63: amount | BC63: 最大6文字
B64: 12 | D64: 値引金額（区分） | K64: プルダウン | N64: I | O64: － | P64: － | T64: － | X64: 1:単品値引 | AA64: ー | AI64: デフォルト：有効。[値引金額・率・タイプ（割引）]が選択された場合に無効になる。 | AR64: ● | AS64: ー | AT64: ー | AU64: AP6603 | AY64: category | BC64: 値一覧は以下が含まれている。:1:単品値引1, 2:単品値引2, 3:単品値引3, 4:単品値引4, 5:単品値引5, 11:小計値引1, 13:小計値引3, 14:小計値引4, 15:小計値引5. 形式:{amount_discount_code:amount_discount_name}
B65: 13 | D65: 割引率 | K65: EditText | N65: I | O65: － | P65: － | T65: － | X65: － | AA65: ー | AI65: デフォルト：無効。[値引金額・率・タイプ（値引]が選択された場合に有効になる。 | AR65: ● | AS65: ● | AT65: ー | AU65: AP6603 | AY65: amount | BC65: 最大2文字
B66: 14 | D66: 割引率（区分） | K66: プルダウン | N66: I | O66: － | P66: － | T66: － | X66: 6:単品割引 | AA66: ー | AI66: デフォルト：無効。[値引金額・率・タイプ（値引]が選択された場合に有効になる。 | AR66: ● | AS66: ー | AT66: ー | AU66: AP6603 | AY66: category | BC66: 値一覧は以下が含まれている。6:単品割引1, 7:単品割引2, 8:単品割引3, 9:単品割引4, 10:単品割引, 16:小計割引1, 17:小計割引2, 18:小計割引3, 19:小計割引4, 20:小計割引5 形式:{percentage_discount_code:percentage_discount_name}
B67: 15 | D67: 適用区分 | K67: テキスト | N67: I | O67: － | P67: － | T67: － | X67: 適用区分 | AA67: ー | AI67: ー | AR67: － | AS67: ー | AT67: ー | AU67: － | AY67: ー | BC67: ー
B68: 16 | D68: 適用区分（期間） | K68: ラジオボタン | N68: I | O68: ● | P68: － | T68: － | X68: 期間 | AA68: デフォルト：チェックを入れる。 | AI68: デフォルト：有効。[適用区分(期間)]が選択された場合に無効になる。 | AR68: ● | AS68: ー | AT68: ー | AU68: AP6603 | AY68: apply_type | BC68: ー
B69: 17 | D69: 適用区分（タイムサービス） | K69: ラジオボタン | N69: I | O69: ● | P69: － | T69: － | X69: タイムサービス | AA69: デフォルト：チェックを外す。 | AI69: デフォルト：無効。[適用区分（タイムサービス）]が選択された場合に有効になる。 | AR69: ● | AS69: ー | AT69: ー | AU69: AP6603 | AY69: apply_type | BC69: ー
B70: 18 | D70: 期間・タイムサービス | K70: テキスト | N70: I | O70: － | P70: － | T70: － | X70: 期間・タイムサービス | AA70: ー | AI70: ー | AR70: － | AS70: ー | AT70: ー | AU70: － | AY70: ー | BC70: ー
B71: 19 | D71: 適用区分（開始期間） | K71: DatePicker | N71: I | O71: ● | P71: － | T71: － | X71: [現在日付] | AA71: ー | AI71: デフォルト：有効 | AR71: ● | AS71: ー | AT71: ー | AU71: AP6603 | AY71: start_date_time | BC71: ー
B72: 20 | D72: 適用区分（終了期間） | K72: DatePicker | N72: I | O72: ● | P72: － | T72: － | X72: [現在日付] | AA72: ー | AI72: デフォルト：有効 | AR72: ● | AS72: ー | AT72: ー | AU72: AP6603 | AY72: end_date_time
B73: 21 | D73: 適用区分（開始タイムサービス） | K73: EditText | N73: I | O73: － | P73: － | T73: － | X73: 0 | AA73: ー | AI73: デフォルト：無効。[適用区分（タイムサービス）]が選択された場合に有効になる。 | AR73: ● | AS73: ー | AT73: ー | AU73: AP6603 | AY73: start_date_time | BC73: 00:00-23:59
B74: 22 | D74: 適用区分（終了タイムサービス） | K74: EditText | N74: I | O74: － | P74: － | T74: － | X74: 0.99930556 | AA74: ー | AI74: デフォルト：無効。[適用区分（タイムサービス）]が選択された場合に有効になる。 | AR74: ● | AS74: ー | AT74: ー | AU74: AP6603 | AY74: end_date_time | BC74: 00:00-23:59
B75: 23 | D75: 採用曜日 | K75: テキスト | N75: I | O75: － | P75: － | T75: － | X75: 採用曜日 | AA75: ー | AI75: ー | AR75: － | AS75: ー | AT75: ー | AU75: － | AY75: ー | BC75: ー
B76: 24 | D76: 採用曜日（毎日） | K76: ラジオボタン | N76: I | O76: ● | P76: － | T76: － | X76: 毎日 | AA76: デフォルト：チェックを入れる。 | AI76: デフォルト：有効 | AR76: ● | AS76: ー | AT76: ー | AU76: AP6603 | AY76: date_categorize_type_code | BC76: ー
B77: 25 | D77: 採用曜日（曜日指定） | K77: ラジオボタン | N77: I | O77: ● | P77: － | T77: － | X77: 曜日指定 | AA77: デフォルト：チェックを外す。 | AI77: デフォルト：無効。[採用曜日(毎日)]が選択された場合に有効になる。 | AR77: ● | AS77: ー | AT77: ー | AU77: AP6603 | AY77: date_categorize_type_code | BC77: ー
B78: 26 | D78: 日 | K78: チェックボックス | N78: I | O78: ● | P78: － | T78: － | X78: 日 | AA78: デフォルト：チェックを外す。 | AI78: デフォルト：無効。[採用曜日(毎日)]が選択された場合に有効になる。 | AR78: － | AS78: ー | AT78: ー | AU78: AP6603 | AY78: is_sunday | BC78: ー
B79: 27 | D79: 月 | K79: チェックボックス | N79: I | O79: ● | P79: － | T79: － | X79: 月 | AA79: デフォルト：チェックを外す。 | AI79: デフォルト：無効。[採用曜日(毎日)]が選択された場合に有効になる。 | AR79: － | AS79: ー | AT79: ー | AU79: AP6603 | AY79: is_monday | BC79: ー
B80: 28 | D80: 火 | K80: チェックボックス | N80: I | O80: ● | P80: － | T80: － | X80: 火 | AA80: デフォルト：チェックを外す。 | AI80: デフォルト：無効。[採用曜日(毎日)]が選択された場合に有効になる。 | AR80: － | AS80: ー | AT80: ー | AU80: AP6603 | AY80: is_tuesday | BC80: ー
B81: 29 | D81: 水 | K81: チェックボックス | N81: I | O81: ● | P81: － | T81: － | X81: 水 | AA81: デフォルト：チェックを外す。 | AI81: デフォルト：無効。[採用曜日(毎日)]が選択された場合に有効になる。 | AR81: － | AS81: ー | AT81: ー | AU81: AP6603 | AY81: is_wednesday | BC81: ー
B82: 30 | D82: 木 | K82: チェックボックス | N82: I | O82: ● | P82: － | T82: － | X82: 木 | AA82: デフォルト：チェックを外す。 | AI82: デフォルト：無効。[採用曜日(毎日)]が選択された場合に有効になる。 | AR82: － | AS82: ー | AT82: ー | AU82: AP6603 | AY82: is_thursday | BC82: ー
B83: 31 | D83: 金 | K83: チェックボックス | N83: I | O83: ● | P83: － | T83: － | X83: 金 | AA83: デフォルト：チェックを外す。 | AI83: デフォルト：無効。[採用曜日(毎日)]が選択された場合に有効になる。 | AR83: － | AS83: ー | AT83: ー | AU83: AP6603 | AY83: is_friday | BC83: ー
...

Sheet MD6601 (支払券編集)
A1: システム名 | K1: システム種別 | W1: 詳細設計書 | AP1: 作成者 | AT1: 作成日 | AY1: 更新者 | BC1: 更新日 | BH1: 版数
A2: POSサーバー | K2: POSサーバー | AP2: =IF(表紙!AP2="","",表紙!AP2) -> TinNH | AT2: =IF(表紙!AT2="","",表紙!AT2) -> 45470 | AY2: =IF(表紙!AY2="","",表紙!AY2) -> LoiLV | BC2: =IF(表紙!BC2="","",表紙!BC2) -> 45477 | BH2: =IF(表紙!BH2="","",表紙!BH2) -> 0.12
A4: 機能カテゴリ | H4: =IF(表紙!H4="","",表紙!H4) -> 66_券マスタ設定 | U4: 項目 | Z4: 画面設計書 | AP4: =MID(CELL("filename",A1),FIND("]",CELL("filename",A1))+1,255) -> MD6601 (支払券編集)
B7: ■イメージ
B47: ■画面項目定義
B49: 画面項目ID | D49: 項目 | K49: Type | N49: I/O | O49: 多言語 | P49: アウトプット | AR49: インプット | BC49: 備考
P50: マッピングデータ | X50: 初期値 | AA50: 表示コントロール | AI50: Control enable | AR50: 必須 | AS50: 数字 | AT50: 文字 | AU50: マッピングデータ
P51: API名 | T51: 項目 | AU51: API名 | AY51: 項目
B52: 0 | D52: モーダルタイトル | K52: テキスト | N52: － | O52: ● | P52: － | T52: － | X52: 支払編集 | AA52: ー | AI52: － | AR52: － | AS52: ー | AT52: ー | AU52: － | AY52: ー | BC52: イベントID：MD6601-07
B53: 1 | D53: 店舗（タイトル） | K53: テキスト | N53: － | O53: ● | P53: － | T53: － | X53: 店舗 | AA53: ー | AI53: ー | AR53: － | AS53: ー | AT53: ー | AU53: － | AY53: ー | BC53: ー
B54: 2 | D54: 店舗（値） | K54: プルダウン | N54: I/O | O54: ● | P54: AP6601 | T54: store_code | X54: － | AA54: ー | AI54: デフォルト：無効 | AR54: ● | AS54: ー | AT54: ー | AU54: AP6602, AP6603 | AY54: selected_store,store_code | BC54: 表示形式: {store_code:store_name} 値一覧には1501モーダルで選択された店舗が含まれている。
B55: 3 | D55: 券コード （タイトル） | K55: テキスト | N55: I | O55: ● | P55: － | T55: － | X55: 券コード | AA55: ー | AI55: ー | AR55: ー | AS55: ー | AT55: ー | AU55: － | AY55: ー | BC55: ー
B56: 4 | D56: 券コード(値) | K56: EditText | N56: I/O | O56: － | P56: AP6601 | T56: code | X56: － | AA56: ー | AI56: デフォルト：無効 | AR56: ● | AS56: ● | AT56: ー | AU56: AP6602, AP6603 | AY56: code | BC56: 最大15文字
B57: 5 | D57: 券検索 | K57: ボタン | N57: I | O57: － | P57: － | T57: － | X57: － | AA57: ー | AI57: デフォルト：無効 | AR57: ー | AS57: ー | AT57: ー | AU57: － | AY57: ー | BC57: ー
B58: 6 | D58: 券名称（タイトル） | K58: テキスト | N58: － | O58: ● | P58: － | T58: － | X58: 券名称 | AA58: ー | AI58: ー | AR58: － | AS58: ー | AT58: ー | AU58: － | AY58: ー | BC58: ー
B59: 7 | D59: 券名称（値） | K59: EditText | N59: I/O | O59: － | P59: AP6601 | T59: name | X59: － | AA59: ー | AI59: ー | AR59: ● | AS59: ー | AT59: ー | AU59: AP6603 | AY59: name | BC59: ー
B60: 8 | D60: 単位額(タイトル) | K60: テキスト | N60: － | O60: ● | P60: － | T60: － | X60: 値引金額・率 | AA60: ー | AI60: ー | AR60: － | AS60: ー | AT60: ー | AU60: － | AY60: ー | BC60: ー
B61: 9 | D61: 単位額（値） | K61: EditText | N61: I/O | O61: － | P61: AP6601 | T61: amount | X61: － | AA61: ー | AI61: ー | AR61: － | AS61: ー | AT61: ー | AU61: AP6603 | AY61: amount | BC61: 最大6文字
B62: 10 | D62: 単位額（単位） | K62: テキスト | N62: － | O62: ● | P62: － | T62: － | X62: 円 | AA62: ー | AI62: ー | AR62: － | AS62: ー | AT62: ー | AU62: － | AY62: ー | BC62: ー
B63: 11 | D63: 返品使用許可フラグ（タイトル） | K63: テキスト | N63: － | O63: ● | P63: － | T63: － | X63: 返品使用許可フラグ | AA63: ー | AI63: ー | AR63: － | AS63: ー | AT63: ー | AU63: － | AY63: ー | BC63: ー
... B96: 44 | D96: 登録 | K96: ボタン | N96: I | O96: ● | P96: － | T96: － | X96: 登録 | AA96: ー | AI96: デフォルト：有効 | AR96: － | AS96: ー | AT96: ー | AU96: － | AY96: ー | BC96: イベントID：MD6601-08

Sheet MD6601 (値引券編集)
A1: システム名 | K1: システム種別 | W1: 詳細設計書 | AP1: 作成者 | AT1: 作成日 | AY1: 更新者 | BC1: 更新日 | BH1: 版数
A2: POSサーバー | K2: POSサーバー | AP2: =IF(表紙!AP2="","",表紙!AP2) -> TinNH | AT2: =IF(表紙!AT2="","",表紙!AT2) -> 45470 | AY2: =IF(表紙!AY2="","",表紙!AY2) -> LoiLV | BC2: =IF(表紙!BC2="","",表紙!BC2) -> 45477 | BH2: =IF(表紙!BH2="","",表紙!BH2) -> 0.12
A4: 機能カテゴリ | H4: =IF(表紙!H4="","",表紙!H4) -> 66_券マスタ設定 | U4: 項目 | Z4: 画面設計書 | AP4: =MID(CELL("filename",A1),FIND("]",CELL("filename",A1))+1,255) -> MD6601 (値引券編集)
B7: ■イメージ
B47: ■画面項目定義
B49: 画面項目ID | D49: 項目 | K49: Type | N49: I/O | O49: 多言語 | P49: アウトプット | AR49: インプット | BC49: 備考
P50: マッピングデータ | X50: 初期値 | AA50: 表示コントロール | AI50: Control enable | AR50: 必須 | AS50: 数字 | AT50: 文字 | AU50: マッピングデータ
P51: API名 | T51: 項目 | AU51: API名 | AY51: 項目
B52: 0 | D52: モーダルタイトル | K52: テキスト | N52: － | O52: ● | P52: － | T52: － | X52: 値引新規 | AA52: ー | AI52: － | AR52: － | AS52: ー | AT52: ー | AU52: － | AY52: ー | BC52: イベントID：MD6601-09
B53: 1 | D53: 店舗（タイトル） | K53: テキスト | N53: － | O53: ● | P53: － | T53: － | X53: 店舗 | AA53: ー | AI53: ー | AR53: － | AS53: ー | AT53: ー | AU53: － | AY53: ー | BC53: ー
B54: 2 | D54: 店舗（値） | K54: プルダウン | N54: I/O | O54: ● | P54: AP6601 | T54: store_code | X54: － | AA54: ー | AI54: デフォルト：無効 | AR54: ● | AS54: ー | AT54: ー | AU54: AP6602, AP6603 | AY54: selected_store,store_code | BC54: 表示形式: {store_code:store_name} 値一覧には1501モーダルで選択された店舗が含まれている。
B55: 3 | D55: 券コード （タイトル） | K55: テキスト | N55: I | O55: ● | P55: － | T55: － | X55: 券コード | AA55: ー | AI55: ー | AR55: ー | AS55: ー | AT55: ー | AU55: － | AY55: ー | BC55: ー
B56: 4 | D56: 券コード(値) | K56: EditText | N56: I/O | O56: － | P56: AP6601 | T56: code | X56: － | AA56: ー | AI56: デフォルト：無効 | AR56: ● | AS56: ● | AT56: ー | AU56: AP6602, AP6603 | AY56: code | BC56: 最大15文字
B57: 5 | D57: 券検索 | K57: ボタン | N57: I | O57: － | P57: － | T57: ー | X57: － | AA57: ー | AI57: デフォルト：無効 | AR57: ー | AS57: ー | AT57: ー | AU57: － | AY57: ー | BC57: ー
B58: 6 | D58: 券名称（タイトル） | K58: テキスト | N58: － | O58: ● | P58: － | T58: ー | X58: 券名称 | AA58: ー | AI58: ー | AR58: － | AS58: ー | AT58: ー | AU58: － | AY58: ー | BC58: ー
B59: 7 | D59: 券名称（値） | K59: EditText | N59: I/O | O59: － | P59: AP6601 | T59: name | X59: － | AA59: ー | AI59: ー | AR59: － | AS59: ー | AT59: ー | AU59: AP6603 | AY59: name | BC59: ー
B60: 8 | D60: 値引金額・率・タイプ（タイトル） | K60: テキスト | N60: － | O60: ● | P60: － | X60: 値引金額・率・タイプ | AA60: ー | AI60: ー | AR60: － | AS60: ー | AT60: ー | BC60: ー
B61: 9 | D61: 値引金額・率・タイプ（値引） | K61: ラジオボタン | N61: I/O | O61: ● | P61: AP6601 | T61: discount_type | X61: 値引 | AA61: デフォルト：チェックを入れる。 | AI61: ー | AR61: ● | AS61: ー | AT61: ー | AU61: AP6603 | AY61: discount_type
B62: 10 | D62: 値引金額・率・タイプ（割引） | K62: ラジオボタン | N62: I/O | O62: ● | P62: AP6601 | T62: discount_type | X62: 割引 | AA62: デフォルト：チェックを外す。 | AI62: ー | AR62: ● | AS62: ー | AT62: ー | AU62: AP6603 | AY62: discount_type | BC62: ー
B63: 11 | D63: 値引金額 | K63: EditText | N63: I/O | O63: － | P63: AP6601 | T63: amount | X63: － | AA63: ー | AI63: デフォルト：有効。[値引金額・率・タイプ（割引）]が選択された場合に無効になる。 | AR63: ● | AS63: ● | AT63: ー | AU63: AP6603 | AY63: amount | BC63: 最大6文字
B64: 12 | D64: 値引金額（区分） | K64: プルダウン | N64: I/O | O64: － | P64: AP6601 | T64: category | X64: 1:単品値引 | AA64: ー | AI64: デフォルト：有効。[値引金額・率・タイプ（割引）]が選択された場合に無効になる。 | AR64: ● | AS64: ー | AT64: ー | AU64: AP6603 | AY64: category | BC64: 値一覧は以下が含まれている。 :1:単品値引1, 2:単品値引2, 3:単品値引3, 4:単品値引4, 5:単品値引5, 11:小計値引1, 13:小計値引3, 14:小計値引4, 15:小計値引5. 形式:{amount_discount_code:amount_discount_name}
B65: 13 | D65: 割引率 | K65: EditText | N65: I/O | O65: － | P65: AP6601 | T65: amount | X65: － | AA65: ー | AI65: デフォルト：無効。[値引金額・率・タイプ（値引]が選択された場合に有効になる。 | AR65: ● | AS65: ● | AT65: ー | AU65: AP6603 | AY65: amount | BC65: 最大2文字
B66: 14 | D66: 割引率（区分） | K66: プルダウン | N66: I/O | O66: － | P66: AP6601 | T66: category | X66: 6:単品割引 | AA66: ー | AI66: デフォルト：無効。[値引金額・率・タイプ（値引]が選択された場合に有効になる。 | AR66: ● | AS66: ー | AT66: ー | AU66: AP6603 | AY66: category | BC66: 値一覧は以下が含まれている。 6:単品割引1, 7:単品割引2, 8:単品割引3, 9:単品割引4, 10:単品割引, 16:小計割引1, 17:小計割引2, 18:小計割引3, 19:小計割引4, 20:小計割引5 形式:{percentage_discount_code:percentage_discount_name}
B67: 15 | D67: 適用区分 | K67: テキスト | N67: I | O67: － | P67: － | T67: ー | X67: 適用区分 | AA67: ー | AI67: ー | AR67: － | AS67: ー | AT67: ー | AU67: － | AY67: ー | BC67: ー
B68: 16 | D68: 適用区分（期間） | K68: ラジオボタン | N68: I/O | O68: ● | P68: AP6601 | T68: apply_type | X68: 期間 | AA68: デフォルト：チェックを入れる。 | AI68: デフォルト：有効。[適用区分(期間)]が選択された場合に無効になる。 | AR68: ● | AS68: ー | AT68: ー | AU68: AP6603 | AY68: apply_type | BC68: ー
B69: 17 | D69: 適用区分（タイムサービス） | K69: ラジオボタン | N69: I/O | O69: ● | P69: AP6601 | T69: apply_type | X69: タイムサービス | AA69: デフォルト：チェックを外す。 | AI69: デフォルト：無効。[適用区分（タイムサービス）]が選択された場合に有効になる。 | AR69: ● | AS69: ー | AT69: ー | AU69: AP6603 | AY69: apply_type | BC69: ー
B70: 18 | D70: 期間・タイムサービス | K70: テキスト | N70: I | O70: － | P70: － | T70: ー | X70: 期間・タイムサービス | AA70: ー | AI70: ー | AR70: － | AS70: ー | AT70: ー | AU70: － | AY70: ー | BC70: ー
B71: 19 | D71: 適用区分（開始期間） | K71: DatePicker | N71: I/O | O71: ● | P71: AP6601 | T71: start_date_time | X71: [現在日付] | AA71: ー | AI71: デフォルト：有効 | AR71: ● | AS71: ー | AT71: ー | AU71: AP6603 | AY71: start_date_time | BC71: ー
B72: 20 | D72: 適用区分（終了期間） | K72: DatePicker | N72: I/O | O72: ● | P72: AP6601 | T72: end_date_time | X72: [現在日付] | AA72: ー | AI72: デフォルト：有効 | AR72: ● | AS72: ー | AT72: ー | AU72: AP6603 | AY72: end_date_time
B73: 21 | D73: 適用区分（開始タイムサービス） | K73: EditText | N73: I/O | O73: － | P73: AP6601 | T73: start_date_time | X73: 0 | AA73: ー | AI73: デフォルト：無効。[適用区分（タイムサービス）]が選択された場合に有効になる。 | AR73: ● | AS73: ー | AT73: ー | AU73: AP6603 | AY73: start_date_time | BC73: 00:00-23:59
B74: 22 | D74: 適用区分（終了タイムサービス） | K74: EditText | N74: I/O | O74: － | P74: AP6601 | T74: end_date_time | X74: 0.99930556 | AA74: ー | AI74: デフォルト：無効。[適用区分（タイムサービス）]が選択された場合に有効になる。 | AR74: ● | AS74: ー | AT74: ー | AU74: AP6603 | AY74: end_date_time | BC74: 00:00-23:59
B75: 23 | D75: 採用曜日 | K75: テキスト | N75: I | O75: － | P75: － | T75: ー | X75: 採用曜日 | AA75: ー | AI75: ー | AR75: － | AS75: ー | AT75: ー | AU75: － | AY75: ー | BC75: ー
B76: 24 | D76: 採用曜日（毎日） | K76: ラジオボタン | N76: I/O | O76: ● | P76: AP6601 | T76: date_categorize_type_code | X76: 毎日 | AA76: デフォルト：チェックを入れる。 | AI76: デフォルト：有効 | AR76: ● | AS76: ー | AT76: ー | AU76: AP6603 | AY76: date_categorize_type_code | BC76: ー
B77: 25 | D77: 採用曜日（曜日指定） | K77: ラジオボタン | N77: I/O | O77: ● | P77: AP6601 | T77: date_categorize_type_code | X77: 曜日指定 | AA77: デフォルト：チェックを外す。 | AI77: デフォルト：無効。[採用曜日(毎日)]が選択された場合に有効になる。 | AR77: ● | AS77: ー | AT77: ー | AU77: AP6603 | AY77: date_categorize_type_code | BC77: ー
B78: 26 | D78: 日 | K78: チェックボックス | N78: I/O | O78: ● | P78: AP6601 | T78: is_sunday | X78: 日 | AA78: デフォルト：チェックを外す。 | AI78: デフォルト：無効。[採用曜日(毎日)]が選択された場合に有効になる。 | AR78: － | AS78: ー | AT78: ー | AU78: AP6603 | AY78: is_sunday | BC78: ー
B79: 27 | D79: 月 | K79: チェックボックス | N79: I/O | O79: ● | P79: AP6601 | T79: is_monday | X79: 月 | AA79: デフォルト：チェックを外す。 | AI79: デフォルト：無効。[採用曜日(毎日)]が選択された場合に有効になる。 | AR79: － | AS79: ー | AT79: ー | AU79: AP6603 | AY79: is_monday | BC79: ー
B80: 28 | D80: 火 | K80: チェックボックス | N80: I/O | O80: ● | P80: AP6601 | T80: is_tuesday | X80: 火 | AA80: デフォルト：チェックを外す。 | AI80: デフォルト：無効。[採用曜日(毎日)]が選択された場合に有効になる。 | AR80: － | AS80: ー | AT80: ー | AU80: AP6603 | AY80: is_tuesday | BC80: ー
B81: 29 | D81: 水 | K81: チェックボックス | N81: I/O | O81: ● | P81: AP6601 | T81: is_wednesday | X81: 水 | AA81: デフォルト：チェックを外す。 | AI81: デフォルト：無効。[採用曜日(毎日)]が選択された場合に有効になる。 | AR81: － | AS81: ー | AT81: ー | AU81: AP6603 | AY81: is_wednesday | BC81: ー
B82: 30 | D82: 木 | K82: チェックボックス | N82: I/O | O82: ● | P82: AP6601 | T82: is_thursday | X82: 木 | AA82: デフォルト：チェックを外す。 | AI82: デフォルト：無効。[採用曜日(毎日)]が選択された場合に有効になる。 | AR82: － | AS82: ー | AT82: ー | AU82: AP6603 | AY82: is_thursday | BC82: ー
B83: 31 | D83: 金 | K83: チェックボックス | N83: I/O | O83: ● | P83: AP6601 | T83: is_friday | X83: 金 | AA83: デフォルト：チェックを外す。 | AI83: デフォルト：無効。[採用曜日(毎日)]が選択された場合に有効になる。 | AR83: － | AS83: ー | AT83: ー | AU83: AP6603 | AY83: is_friday | BC83: ー
...

Sheet MD6602
A1: システム名 | K1: システム種別 | W1: 詳細設計書 | AP1: 作成者 | AT1: 作成日 | AY1: 更新者 | BC1: 更新日 | BH1: 版数
A2: POSサーバー | K2: POSサーバー | AP2: =IF(表紙!AP2="","",表紙!AP2) -> TinNH | AT2: =IF(表紙!AT2="","",表紙!AT2) -> 45470 | AY2: =IF(表紙!AY2="","",表紙!AY2) -> LoiLV | BC2: =IF(表紙!BC2="","",表紙!BC2) -> 45477 | BH2: =IF(表紙!BH2="","",表紙!BH2) -> 0.12
A4: 機能カテゴリ | H4: =IF(表紙!H4="","",表紙!H4) -> 66_券マスタ設定 | U4: 項目 | Z4: 画面設計書 | AP4: =MID(CELL("filename",A1),FIND("]",CELL("filename",A1))+1,255) -> MD6602
B7: ■イメージ
B47: ■画面項目定義
B49: 画面項目ID | D49: 項目 | K49: Type | N49: I/O | O49: 多言語 | P49: アウトプット | AR49: インプット | BC49: 備考
P50: マッピングデータ | X50: 初期値 | AA50: 表示コントロール | AI50: Control enable | AR50: 必須 | AS50: 数字 | AT50: 文字 | AU50: マッピングデータ
P51: API名 | T51: 項目 | AU51: API名 | AY51: 項目
B52: 1 | D52: モーダル名 | K52: テキスト | N52: － | O52: ● | P52: － | T52: － | X52: 券検索 | AA52: ー | AI52: － | AR52: － | AS52: ー | AT52: ー | AU52: － | AY52: ー | BC52: イベントID：MD6602-01
B53: 2 | D53: テーブル | K53: テーブル | N53: － | O53: － | P53: － | T53: － | X53: － | AA53: ー | AI53: ー | AR53: － | AS53: ー | AT53: ー | AU53: － | AY53: ー
B54: 2.1 | D54: 選択（ヘッダー） | K54: テキスト | N54: － | O54: ● | P54: － | T54: － | X54: 選択 | AA54: ー | AI54: ー | AR54: － | AS54: ー | AT54: ー | AU54: － | AY54: ー
B55: 2.2 | D55: 選択（ボディ） | K55: ボタン | N55: I | O55: ● | P55: － | X55: 選択 | AA55: ー | AI55: デフォルト：有効 | AR55: － | AS55: ー | AT55: ー | AU55: － | AY55: ー | BC55: イベントID：MD6602-02
B56: 2.3 | D56: 券コード（ヘッダー） | K56: テキスト | N56: =$N$54 -> － | O56: ● | P56: － | T56: － | X56: 券コード | AA56: ー | AI56: ー | AR56: － | AS56: ー | AT56: ー | AU56: － | AY56: ー
B57: 2.4 | D57: 券コード（ボディ） | K57: テキスト | N57: I/O | O57: － | P57: AP601 | T57: code | X57: － | AA57: ー | AI57: ー | AR57: － | AS57: ー | AT57: ー | AU57: － | AY57: ー
B58: 2.5 | D58: 券名称（ヘッダー） | K58: テキスト | N58: =$N$54 -> － | O58: ● | P58: － | T58: － | X58: 券名称 | AA58: ー | AI58: ー | AR58: － | AS58: ー | AT58: ー | AU58: － | AY58: ー
B59: 2.6 | D59: 券名称（ボディ） | K59: テキスト | N59: I/O | O59: － | P59: AP601 | T59: name | X59: － | AA59: ー | AI59: ー | AR59: － | AS59: ー | AT59: ー | AU59: － | AY59: ー
B60: 2.7 | D60: 支払単位額/値引金額・率（ヘッダー） | K60: テキスト | N60: =$N$54 -> － | O60: ● | P60: － | T60: － | X60: ラヴィギフト券 | AA60: ー | AI60: ー | AR60: － | AS60: ー | AT60: ー | AU60: － | AY60: ー
B61: 2.8 | D61: 支払単位額/値引金額・率（ボディ） | K61: テキスト | N61: I/O | O61: － | P61: AP601 | T61: amount | X61: － | AA61: ー | AI61: ー | AR61: － | AS61: ー | AT61: ー | AU61: － | AY61: ー
B62: 3 | D62: 取消 | K62: ボタン | N62: =$N$54 -> － | O62: ● | P62: － | T62: － | X62: 単位額 | AA62: ー | AI62: デフォルト：有効 | AR62: － | AS62: ー | AT62: ー | AU62: － | AY62: ー | BC62: イベントID：MD6602-03

Sheet CSV
A1: システム名 | K1: システム種別 | W1: 詳細設計書 | AP1: 作成者 | AT1: 作成日 | AY1: 更新者 | BC1: 更新日 | BH1: 版数
A2: POSサーバー | K2: POSサーバー | AP2: =IF(表紙!AP2="","",表紙!AP2) -> TinNH | AT2: =IF(表紙!AT2="","",表紙!AT2) -> 45470 | AY2: =IF(表紙!AY2="","",表紙!AY2) -> LoiLV | BC2: =IF(表紙!BC2="","",表紙!BC2) -> 45477 | BH2: =IF(表紙!BH2="","",表紙!BH2) -> 0.12
A4: 機能カテゴリ | H4: =IF(表紙!H4="","",表紙!H4) -> 66_券マスタ設定 | U4: 項目 | Z4: 画面設計書 | AP4: =MID(CELL("filename",A1),FIND("]",CELL("filename",A1))+1,255) -> CSV
B7: ■イメージ
B25: ■画面項目定義
B27: 画面項目ID | D27: 項目 | K27: Type | N27: I/O | O27: 多言語 | P27: アウトプット | AR27: インプット | BC27: 備考
P28: マッピングデータ | X28: 初期値 | AA28: 表示コントロール | AI28: Control enable | AR28: 必須 | AS28: 数字 | AT28: 文字 | AU28: マッピングデータ
P29: API名 | T29: 項目 | AU29: API名 | AY29: 項目
B30: 1 | D30: 店舗コード（ヘッダー） | K30: テキスト | N30: － | O30: ● | P30: － | T30: － | X30: 店舗コード | AA30: ー | AI30: － | AR30: － | AS30: ー | AT30: ー | AU30: － | AY30: ー | BC30: ー
B31: 2 | D31: 店舗コード（ボディ） | K31: テキスト | N31: O | O31: － | P31: AP6601 | T31: store_code | X31: － | AA31: ー | AI31: ー | AR31: － | AS31: ー | AT31: ー | AU31: － | AY31: ー | BC31: データ：SC6601の券マスタテーブル
B32: 3 | D32: 店舗名称（ヘッダー） | K32: テキスト | N32: － | O32: ● | P32: － | X32: 店舗名称 | AA32: ー | AI32: ー | AR32: － | AS32: ー | AT32: ー | AU32: － | AY32: ー | BC32: ー
B33: 4 | D33: 店舗名称（ボディ） | K33: テキスト | N33: O | O33: － | P33: AP6601 | T33: store_name | X33: － | AA33: ー | AI33: ー | AR33: － | AS33: ー | AT33: ー | AU33: － | AY33: ー | BC33: データ：SC6601の券マスタテーブル
B34: 5 | D34: 券コード（ヘッダー） | K34: テキスト | N34: － | O34: ● | P34: － | T34: － | X34: 券コード | AA34: ー | AI34: ー | AR34: － | AS34: ー | AT34: ー | AU34: － | AY34: ー | BC34: ー
B35: 6 | D35: 券コード（ボディ） | K35: テキスト | N35: O | O35: － | P35: AP6601 | T35: code | X35: － | AA35: ー | AI35: ー | AR35: － | AS35: ー | AT35: ー | AU35: － | AY35: ー | BC35: データ：SC6601の券マスタテーブル
B36: 1 | D36: 券名称（ヘッダー） | K36: テキスト | N36: － | O36: ● | P36: － | T36: － | X36: 券名称 | AA36: ー | AI36: － | AR36: － | AS36: ー | AT36: ー | AU36: － | AY36: ー | BC36: ー
B37: 2 | D37: 券名称（ボディ） | K37: テキスト | N37: O | O37: － | P37: AP6601 | T37: name | X37: － | AA37: ー | AI37: ー | AR37: － | AS37: ー | AT37: ー | AU37: － | AY37: ー | BC37: データ：SC6601の券マスタテーブル
B38: 3 | D38: 支払単位額/値引金額・率（ヘッダー） | K38: テキスト | N38: － | O38: ● | P38: － | T38: － | X38: 支払単位額/値引金額・率 | AA38: ー | AI38: ー | AR38: － | AS38: ー | AT38: ー | AU38: － | AY38: ー | BC38: ー
B39: 4 | D39: 支払単位額/値引金額・率（ボディ） | K39: テキスト | N39: O | O39: － | P39: AP6601 | T39: amount, discount_type | X39: － | AA39: ー | AI39: ー | AR39: － | AS39: ー | AT39: ー | AU39: － | AY39: ー | BC39: データ：SC6601の券マスタテーブル ・discount_type=1の場合、{amount}%を表示する。 ・discoun_type=2の場合、{amount}円を表示する。
B40: 5 | D40: 登録店舗（ヘッダー） | K40: テキスト | N40: － | O40: ● | P40: － | T40: － | X40: 除外店舗 | AA40: ー | AI40: ー | AR40: － | AS40: ー | AT40: ー | AU40: － | AY40: ー | BC40: ー
B41: 6 | D41: 登録店舗（ボディ） | K41: テキスト | N41: O | O41: － | P41: AP1501 | T41: include_stores | X41: － | AA41: include_storesはにstore codeが含まれている場合に表示される。 | AI41: ー | AR41: － | AS41: ー | AT41: ー | AU41: － | AY41: ー | BC41: ・表示される場合は「*」を表示する。 ・include_stores: SC6601の[登録店舗（値）]
