Workbook

Sheet 表紙
A1: システム名 | K1: システム種別 | W1: 詳細設計書 | AP1: 作成者 | AT1: 作成日 | AY1: 更新者 | BC1: 更新日 | BH1: 版数
A2: POSサーバー | K2: POSサーバ | AP2: =改訂履歴!$H$11 -> DuNT | AT2: =改訂履歴!$B$11 -> 45489 | AY2: =LOOKUP(2,1/(改訂履歴!H11:H30003<>""),改訂履歴!H11:H30003) -> TinNH | BC2: =LOOKUP(2,1/(改訂履歴!B11:B30003<>""),改訂履歴!B11:B30003) -> 45595 | BH2: =LOOKUP(2,1/(改訂履歴!O11:O30003<>""),改訂履歴!O11:O30003) -> 0.7
A4: 機能カテゴリ | H4: 71_レジマスタ設定 | U4: 項目 | Z4: 画面設計書 | AP4: {=RIGHT(CELL("filename",$A$1),LEN(CELL("filename",$A$1))-FIND("]",CELL("filename",$A$1)))} -> 表紙
L16: POSサーバーの詳細設計書
L24: =K2&"/"&H4&"/"&Z4 -> POSサーバ/71_レジマスタ設定/画面設計書
Q44: 承認日 | AA44: 承認者 | AQ44: 版数

Sheet 改訂履歴
A1: システム名 | K1: システム種別 | W1: =IF(表紙!W1="","",表紙!W1) -> 詳細設計書 | AP1: 作成者 | AT1: 作成日 | AY1: 更新者 | BC1: 更新日 | BH1: 版数
A2: =IF(表紙!A2="","",表紙!A2) -> POSサーバー | K2: =IF(表紙!K2="","",表紙!K2) -> POSサーバ | AP2: =IF(表紙!AP2="","",表紙!AP2) -> DuNT | AT2: =IF(表紙!AT2="","",表紙!AT2) -> 45489 | AY2: =IF(表紙!AY2="","",表紙!AY2) -> TinNH | BC2: =IF(表紙!BC2="","",表紙!BC2) -> 45595 | BH2: =IF(表紙!BH2="","",表紙!BH2) -> 0.7
A4: 機能カテゴリ | H4: =IF(表紙!H4="","",表紙!H4) -> 71_レジマスタ設定 | U4: 項目 | Z4: =IF(表紙!Z4="","",表紙!Z4) -> 画面設計書 | AP4: {=RIGHT(CELL("filename",$A$1),LEN(CELL("filename",$A$1))-FIND("]",CELL("filename",$A$1)))} -> 改訂履歴
B8: ■改訂履歴
B10: 更新日 | H10: 更新者 | O10: 版数 | S10: 更新内容 | AX10: 承認日 | BD10: 承認者
B11: 45489 | H11: DuNT | O11: 0.1 | S11: 新規
B13: 45512 | H13: DuNT | O13: 0.2 | S13: SC7101：有効条件更新
B15: 45525 | H15: DuNT | O15: 0.3 | S15: MD7101：AP7105APIマッピング更新
S16: MD7101：テナントレジ部門項目を追加
B17: 45512 | H17: DuNT | O17: 0.4 | S17: MD7101：ドロップダウン表示リストを追加で説明する
B19: 45547 | H19: DuNT | O19: 0.5 | S19: 支払い種別項目を削除する。
B21: 45548 | H21: DuNT | O21: 0.6 | S21: MD7101：IPアドレスとMACアドレスの形式のバリデーションチェックを追加
S22: MD7101：選択中の店舗に基づいてドロップダウンリストのプリセットレイアウト、メッセージの初期値をフィルターする。
B23: 45555 | H23: DuNT | O23: 0.61 | S23: SC7101、MD7101：ドロップダウンリストの各項目のデータマッピングを追加する。
B25: 45558 | H25: DuNT | O25: 0.62 | S25: 閉じる、戻る、登録、確定ボタンを追加で説明する。
B27: 45558 | H27: DuNT | O27: 0.63 | S27: MD7101：入力可能な各項目の最大桁数の説明
B29: 45559 | H29: DuNT | O29: 0.64 | S29: MD7101：店舗が選択されていない場合、ドロップダウン「店舗」初期値を追加で説明する
B31: 45562 | H31: DuNT | O31: 0.65 | S31: SC7102：API「AP7102」のマッピング
B33: 45567 | H33: AnhDD | O33: 0.66 | S33: SC7101、SC7102、MD7101: CashRegisterMasterのtype_code を非表示にする。
B35: 45569 | H35: DuNT | O35: 0.67 | S35: SC7101：店舗が選択されていない場合、画面上の全ての項目が操作不可（取込ボタンを除く）
S36: SC7102：クリアボタンを追加する。コード欄を追加する。
S37: MD7101: インターフェースを更新する。MACアドレス入力部分の説明を追加、項目11のテキストを修正
S38: SC7101、SC7102、MD7101：CashRegisterMasterのtype_code を非表示にする。
B39: 45580 | H39: DuNT | O39: 0.68 | S39: MD7101：コピー：店舗選択時、全ての店舗を表示する。
S40: MD7101：編集モーダルでは、変更がある場合のみ「確定」ボタンを有効にする。
S41: MD7101：以下の項目をコピーし、その他の項目は空欄とする。 店舗、レジ種別、ノード種別、プリセットレイアウト、ファンクションレイアウト、キーボードレイアウト、レシートメッセージ
B42: 45595 | H42: TinNH | O42: 0.7 | S42: MD7101
S43: ・構成比除外, 380アテンダントモニタ除外を追加する。

Sheet SC7101
A1: システム名 | K1: システム種別 | W1: =IF(表紙!W1="","",表紙!W1) -> 詳細設計書 | AP1: 作成者 | AT1: 作成日 | AY1: 更新者 | BC1: 更新日 | BH1: 版数
A2: =IF(表紙!A2="","",表紙!A2) -> POSサーバー | K2: =IF(表紙!K2="","",表紙!K2) -> POSサーバ | AP2: =IF(表紙!AP2="","",表紙!AP2) -> DuNT | AT2: =IF(表紙!AT2="","",表紙!AT2) -> 45489 | AY2: =IF(表紙!AY2="","",表紙!AY2) -> TinNH | BC2: =IF(表紙!BC2="","",表紙!BC2) -> 45595 | BH2: =IF(表紙!BH2="","",表紙!BH2) -> 0.7
A4: 機能カテゴリ | H4: =IF(表紙!H4="","",表紙!H4) -> 71_レジマスタ設定 | U4: 項目 | Z4: =IF(表紙!Z4="","",表紙!Z4) -> 画面設計書 | AP4: =MID(CELL("filename",A1),FIND("]",CELL("filename",A1))+1,255) -> SC7101
B7: ■SC7101_レジマスタ設定画面のイメージ
B64: ■画面項目定義
B66: 画面項目ID | D66: 項目 | K66: タイプ | N66: I/O | O66: 多言語 | P66: 出力 | AR66: インプット | BC66: 備考
P67: マッピングデータ | X67: 初期値 | AA67: 表示コントロール | AI67: Control enable | AR67: 必須 | AS67: 数字 | AT67: 桁 | AU67: マッピングデータ
P68: API名 | T68: 項目 | AU68: API名 | AY68: 項目
B69: 0 | D69: 画面タイトル | K69: テキスト | N69: － | O69: ● | P69: － | T69: － | X69: レジマスタ設定 | AA69: ー | AI69: － | AR69: － | AS69: ー | AT69: ー | AU69: － | AY69: ー | BC69: イベントID：SC7101-01
B70: 1 | D70: 店舗（列名） | K70: テキスト | N70: － | O70: ● | P70: － | T70: － | X70: 店舗 | AA70: ー | AI70: ー | AR70: － | AS70: ー | AT70: ー | AU70: － | AY70: ー
B71: 1.1 | D71: 店舗（値） | K71: テキスト | N71: O | O71: － | P71: AP7102 | T71: CashMachine.store_code:CashMachine.store_name | X71: －
B72: 2 | D72: レジ番号（列名） | K72: テキスト | N72: － | O72: ● | P72: － | X72: レジ番号 | AA72: ー | AI72: ー | AR72: － | AS72: ー | AT72: ー | AU72: － | AY72: ー
B73: 2.1 | D73: レジ番号（値） | K73: テキスト | N73: O | O73: － | P73: AP7102 | T73: CashMachine.code | X73: Password | AA73: ー | AI73: ー | AR73: － | AS73: ー | AT73: ー | AU73: － | AY73: ー
B74: 3 | D74: レジ種別（列名） | K74: テキスト | N74: － | O74: ● | P74: － | T74: － | X74: レジ種別 | AA74: ー | AI74: ー | AR74: － | AS74: ー | AT74: ー | AU74: － | AY74: ー
B75: 3.1 | D75: レジ種別（値） | K75: テキスト | N75: O | O75: － | P75: AP7102 | T75: CashMachine.type_name | X75: － | AA75: ー | AI75: ー | AR75: － | AS75: ー | AT75: ー | AU75: － | AY75: ー | BC75: 更新された場合、新しいtype_codeとtype_nameを表示する。
B76: 4 | D76: ノード種別（列名) | K76: テキスト | N76: － | O76: ● | P76: － | T76: － | X76: ノード種別 | AA76: ー | AI76: ー | AR76: － | AS76: ー | AT76: ー | AU76: － | AY76: ー
B77: 4.1 | D77: ノード種別（値) | K77: テキスト | N77: O | O77: － | P77: AP7102 | T77: CashMachine.type_node:CashMachine.type_node_name | X77: － | AA77: ー | AI77: ー | AR77: － | AS77: ー | AT77: ー | AU77: － | AY77: ー | BC77: 更新された場合、新しいtype_node_codeとtype_node_name を表示する。
B78: 5 | D78: プリセットレイアウト（列名） | K78: テキスト | N78: － | O78: ● | P78: － | T78: － | X78: プリセットレイアウト | AA78: ー | AI78: ー | AR78: － | AS78: ー | AT78: ー | AU78: － | AY78: ー
B79: 5.1 | D79: プリセットレイアウト（値） | K79: テキスト | N79: O | O79: － | P79: AP7102 | T79: CashMachine.button_layout_code:CashMachine.button_layout_name | X79: － | AA79: ー | AI79: ー | AR79: － | AS79: ー | AT79: ー | AU79: － | AY79: ー | BC79: 更新された場合、新しいbutton_layout_codeとbutton_layout_nameを表示する。
B80: 6 | D80: ファンクションレイアウト（列名） | K80: テキスト | N80: － | O80: ● | P80: － | T80: － | X80: ファンクションレイアウト | AA80: ー | AI80: ー | AR80: － | AS80: ー | AT80: ー | AU80: － | AY80: ー
B81: 6.1 | D81: ファンクションレイアウト（値） | K81: テキスト | N81: O | O81: － | P81: AP7102 | T81: CashMachine.function_layout_code :CashMachine.function_layout_name | X81: － | AA81: ー | AI81: ー | AR81: － | AS81: ー | AT81: ー | AU81: － | AY81: ー | BC81: 更新された場合、新しいfunction_layout_codeとfunction_layout_nameを表示する。
B82: 7 | D82: キーボードレイアウト（列名） | K82: テキスト | N82: － | O82: ● | P82: － | T82: － | X82: キーボードレイアウト | AA82: ー | AI82: ー | AR82: － | AS82: ー | AT82: ー | AU82: － | AY82: ー
B83: 7.1 | D83: キーボードレイアウト （値） | K83: テキスト | N83: O | O83: － | P83: AP7102 | T83: CashMachine.keyboard_layout_code:CashMachine.keyboard_layout_name | X83: － | AA83: ー | AI83: ー | AR83: － | AS83: ー | AT83: ー | AU83: － | AY83: ー | BC83: 更新された場合、新しいkeyboard_layout_codeとkeyboard_layout_nameを表示する。
B84: 8 | D84: レシートメッセージ（列名） | K84: テキスト | N84: － | O84: ● | P84: － | T84: － | X84: レシートメッセージ | AA84: ー | AI84: ー | AR84: － | AS84: ー | AT84: ー | AU84: － | AY84: ー
B85: 8.1 | D85: レシートメッセージ（値） | K85: テキスト | N85: O | O85: － | P85: AP7102 | T85: CashMachine.receipt_message_code:CashMachine.receipt_message | X85: － | AA85: ー | AI85: ー | AR85: － | AS85: ー | AT85: ー | AU85: － | AY85: ー | BC85: 更新された場合、新しいreceipt_message_codeとreceipt_messageを表示する。
B86: 9 | D86: IPアドレス（列名） | K86: テキスト | N86: － | O86: ● | P86: － | T86: － | X86: IPアドレス | AA86: ー | AI86: ー | AR86: － | AS86: ー | AT86: ー | AU86: － | AY86: ー
B87: 9.1 | D87: IPアドレス（値） | K87: テキスト | N87: O | O87: － | P87: AP7102 | T87: CashMachine.ip_address | X87: － | AA87: ー | AI87: ー | AR87: － | AS87: ー | AT87: ー | AU87: － | AY87: ー
B88: 10 | D88: MACアドレス（列名） | K88: テキスト | N88: － | O88: ● | P88: － | T88: － | X88: MACアドレス | AA88: ー | AI88: ー | AR88: － | AS88: ー | AT88: ー | AU88: － | AY88: ー
B89: 10.1 | D89: MACアドレス（値） | K89: テキスト | N89: O | O89: － | P89: AP7102 | T89: CashMachine.mac_address | X89: － | AA89: ー | AI89: ー | AR89: － | AS89: ー | AT89: ー | AU89: － | AY89: ー
B90: 11 | D90: 店舗選択ビュー | K90: View | N90: － | O90: － | P90: － | T90: － | X90: － | AA90: ー | AI90: ー | AR90: － | AS90: ー | AT90: ー | AU90: － | AY90: ー
B91: 11.1 | D91: 決定 | K91: ボタン | N91: I | O91: ● | P91: － | T91: － | X91: 決定 | AA91: ー | AI91: ー | AR91: － | AS91: ー | AT91: ー | AU91: － | AY91: ー | BC91: イベントID：SC7101-02
B92: 12 | D92: 検索条件ビュー | K92: View | N92: － | O92: － | P92: － | T92: － | X92: 検索条件 | AA92: ー | AI92: ー | AR92: － | AS92: ー | AT92: ー | AU92: － | AY92: ー
B93: 12.1 | D93: レジ番号 （タイトル） | K93: テキスト | N93: － | O93: ● | P93: － | T93: － | X93: レジ番号 | AA93: ー | AI93: ー | AR93: － | AS93: ー | AT93: ー | AU93: － | AY93: ー
B94: 12.2 | D94: レジ番号 （値） | K94: Edittext | N94: I | O94: － | P94: － | T94: － | X94: － | AA94: ー | AI94: ー | AR94: － | AS94: ● | AT94: ー | AU94: AP7102 | AY94: cash_machine_no | BC94: 0-15桁
B95: 12.3 | D95: レジ種別（タイトル） | K95: テキスト | N95: － | O95: ● | P95: － | T95: － | X95: レジ種別 | AA95: ー | AI95: ー | AR95: － | AS95: ー | AT95: ー | AU95: － | AY95: ー
B96: 12.4 | D96: レジ種別（値） | K96: ドロップダウン | N96: I | O96: － | P96: AP7103 | T96: CashRegisterType.code: CashRegisterType.name | X96: － | AA96: ー | AI96: ー | AR96: － | AS96: ー | AT96: ー | AU96: AP7102 | AY96: cash_machine_no
B97: 12.5 | D97: ノード種別（タイトル） | K97: テキスト | N97: － | O97: ● | P97: － | T97: － | X97: ノード種別 | AA97: ー | AI97: ー | AR97: － | AS97: ー | AT97: ー | AU97: － | AY97: ー
B98: 12.6 | D98: ノード種別（値） | K98: ドロップダウン | N98: I | O98: － | P98: AP1503 (MC7101) | T98: items.setting_data_type:items.event_group_name | X98: － | AA98: ー | AI98: ー | AR98: － | AS98: ー | AT98: ー | AU98: AP7102 | AY98: node_type
B99: 12.7 | D99: プリセットレイアウト（タイトル） | K99: テキスト | N99: － | O99: ● | P99: － | T99: － | X99: プリセットレイアウト | AA99: ー | AI99: ー | AR99: － | AS99: ー | AT99: ー | AU99: － | AY99: ー
B100: 12.8 | D100: プリセットレイアウト（値） | K100: ドロップダウン | N100: I | O100: － | P100: AP1501 | T100: preset_layouts.preset_layout_code : preset_layouts.preset_layout_name | X100: － | AA100: ー | AI100: ー | AR100: － | AS100: ー | AT100: ー | AU100: AP7102 | AY100: preset_layout_id
...

Sheet SC7102
A1: システム名 | K1: システム種別 | W1: =IF(表紙!W1="","",表紙!W1) -> 詳細設計書 | AP1: 作成者 | AT1: 作成日 | AY1: 更新者 | BC1: 更新日 | BH1: 版数
A2: =IF(表紙!A2="","",表紙!A2) -> POSサーバー | K2: =IF(表紙!K2="","",表紙!K2) -> POSサーバ | AP2: =IF(表紙!AP2="","",表紙!AP2) -> DuNT | AT2: =IF(表紙!AT2="","",表紙!AT2) -> 45489 | AY2: =IF(表紙!AY2="","",表紙!AY2) -> TinNH | BC2: =IF(表紙!BC2="","",表紙!BC2) -> 45595 | BH2: =IF(表紙!BH2="","",表紙!BH2) -> 0.7
A4: 機能カテゴリ | H4: =IF(表紙!H4="","",表紙!H4) -> 71_レジマスタ設定 | U4: 項目 | Z4: =IF(表紙!Z4="","",表紙!Z4) -> 画面設計書 | AP4: =MID(CELL("filename",A1),FIND("]",CELL("filename",A1))+1,255) -> SC7102
B7: ■SC7102_レジ種別追加画面のイメージ
B47: ■画面項目定義
B49: 画面項目ID | D49: 項目 | K49: タイプ | N49: I/O | O49: 多言語 | P49: 出力 | AR49: インプット | BC49: 備考
P50: マッピングデータ | X50: 初期値 | AA50: 表示コントロール | AI50: Control enable | AR50: 必須 | AS50: 数字 | AT50: 桁 | AU50: マッピングデータ
P51: API名 | T51: 項目 | AU51: API名 | AY51: 項目
B52: 0 | D52: 画面タイトル | K52: テキスト | N52: － | O52: ● | P52: － | T52: － | X52: レジ種別追加 | AA52: － | AI52: － | AR52: － | AS52: － | AT52: － | AU52: － | AY52: － | BC52: イベントID：SC7102-01
B53: 1 | D53: No（タイトル） | K53: テキスト | N53: － | O53: － | P53: － | T53: － | X53: No | AA53: － | AI53: － | AR53: － | AS53: － | AT53: － | AU53: － | AY53: －
B54: 2 | D54: No（値） | K54: テキスト | N54: － | O54: － | P54: － | T54: － | X54: － | AA54: － | AI54: － | AR54: － | AS54: － | AT54: － | AU54: － | AY54: － | BC54: リスト内のアイテムの表示順
B55: 3 | D55: レジ種別のID列 | K55: テキスト | N55: － | O55: ● | P55: － | T55: － | X55: コード | AA55: － | AI55: － | AR55: － | AS55: － | AT55: － | AU55: － | AY55: －
B56: 4 | D56: レジ種別ID（値） | K56: EditText | N56: － | O56: － | P56: AP7103 | T56: CashRegisterType.code | X56: － | AA56: － | AI56: アイテムが新規モードの場合にのみ入力可能 | AR56: ● | AS56: ● | AT56: － | AU56: AP7104 | AY56: CashRegisterType.code | BC56: 最大数字の2桁。
B57: 5 | D57: レジ種別名称の列 | K57: テキスト | N57: － | O57: ● | P57: － | T57: － | X57: レジ種別 | AA57: － | AI57: － | AR57: － | AS57: － | AT57: － | AU57: － | AY57: －
B58: 6 | D58: レジ種別名称（値） | K58: EditText | N58: － | O58: － | P58: AP7103 | T58: CashRegisterType.name－ | X58: － | AA58: － | AI58: アイテムが新規モード、編集モードの場合にのみ入力可能 | AR58: ● | AS58: － | AT58: － | AU58: AP7104 | AY58: CashRegisterType.name | BC58: 50桁。50桁を超えた場合：MSG_VAL_002
B59: 7 | D59: 検索条件エリアタイトル | K59: テキスト | N59: － | O59: ● | P59: － | T59: － | X59: 検索条件 | AA59: － | AI59: － | AR59: － | AS59: － | AT59: － | AU59: － | AY59: －
B60: 8 | D60: レジ種別検索タイトル | K60: テキスト | N60: － | O60: ● | P60: － | T60: － | X60: レジ種別 | AA60: － | AI60: － | AR60: － | AS60: － | AT60: － | AU60: － | AY60: －
B61: 9 | D61: 検索条件（値） | K61: EditText | N61: I | O61: － | X61: － | AA61: － | AI61: － | AR61: － | AS61: － | AT61: ● | AU61: AP7103 | AY61: type_name
B62: 10 | D62: F04:クリア | K62: ボタン | N62: I | O62: ● | P62: － | T62: － | X62: F04:クリア | AA62: － | AI62: 有効 | AR62: － | AS62: － | AT62: － | AU62: － | AY62: － | BC62: イベントID：SC7102-07
B63: 11 | D63: 検索 | K63: ボタン | N63: I | O63: ● | P63: － | T63: － | X63: 検索 | AA63: － | AI63: 有効 | AR63: － | AS63: － | AT63: － | AU63: － | AY63: － | BC63: イベントID：SC7102-02
B64: 12 | D64: 削除 | K64: ボタン | N64: I | O64: ● | P64: － | T64: － | X64: F10 :削除 | AA64: － | AI64: 1件をフォーカスした時に有効にする | AR64: － | AS64: － | AT64: － | AU64: － | AY64: － | BC64: イベントID：SC7102-03
B65: 13 | D65: 新規 | K65: ボタン | N65: I | O65: ● | P65: － | T65: － | X65: F02 :新規 | AA65: － | AI65: 有効 | AR65: － | AS65: － | AT65: － | AU65: － | AY65: － | BC65: イベントID：SC7102-05
B66: 14 | D66: 編集 | K66: ボタン | N66: I | O66: ● | P66: － | T66: － | X66: F01 :編集 | AA66: － | AI66: 1つのレコードにフォーカスし、そのレコードが削除としてマークされていない場合は有効にする。 | AR66: － | AS66: － | AT66: － | AU66: － | AY66: － | BC66: イベントID：SC7102-04
B67: 15 | D67: 決定 | K67: ボタン | N67: I | O67: ● | P67: － | T67: － | X67: F11 :確定 | AA67: － | AI67: 変更があった場合に有効にする（1つのアイテムを新規作成する時にコードと名称を入力しない場合は変更があったと見なさず、確定ボタンを無効にする。） | AR67: － | AS67: － | AT67: － | AU67: － | AY67: － | BC67: イベントID：SC7102-06

Sheet MD7101
A1: システム名 | K1: システム種別 | W1: =IF(表紙!W1="","",表紙!W1) -> 詳細設計書 | AP1: 作成者 | AT1: 作成日 | AY1: 更新者 | BC1: 更新日 | BH1: 版数
A2: =IF(表紙!A2="","",表紙!A2) -> POSサーバー | K2: =IF(表紙!K2="","",表紙!K2) -> POSサーバ | AP2: =IF(表紙!AP2="","",表紙!AP2) -> DuNT | AT2: =IF(表紙!AT2="","",表紙!AT2) -> 45489 | AY2: =IF(表紙!AY2="","",表紙!AY2) -> TinNH | BC2: =IF(表紙!BC2="","",表紙!BC2) -> 45595 | BH2: =IF(表紙!BH2="","",表紙!BH2) -> 0.7
A4: 機能カテゴリ | H4: =IF(表紙!H4="","",表紙!H4) -> 71_レジマスタ設定 | U4: 項目 | Z4: =IF(表紙!Z4="","",表紙!Z4) -> 画面設計書 | AP4: =MID(CELL("filename",A1),FIND("]",CELL("filename",A1))+1,255) -> MD7101
B7: ■MD7101_レジマスタ設定編集モーダルのイメージ
B94: ■画面項目定義
B96: 画面項目ID | D96: 項目 | K96: タイプ | N96: I/O | O96: 多言語 | P96: 出力 | AR96: インプット | BC96: 備考
P97: マッピングデータ | X97: 初期値 | AA97: 表示コントロール | AI97: Control enable | AR97: 必須 | AS97: 数字 | AT97: 桁 | AU97: マッピングデータ
P98: API名 | T98: 項目 | AU98: API名 | AY98: 項目
B99: 0 | D99: モーダル（タイトル） | K99: テキスト | N99: ー | O99: ● | P99: ー | T99: ー | X99: 新規 コピー 編集 | AA99: ・新規の場合：新規 ・コピーの場合：コピー ・編集の場合：編集 | AI99: ー | AR99: － | AS99: － | AT99: － | AU99: ー | AY99: ー | BC99: イベントID：MD7101-01
B100: 1 | D100: 店舗（タイトル） | K100: テキスト | N100: ー | O100: ● | P100: ー | T100: ー | X100: 店舗* | AA100: ー | AI100: ー | AR100: － | AS100: － | AT100: － | AU100: ー | AY100: ー
B101: 2 | D101: 店舗（値） | K101: ドロップダウン | N101: I/O | O101: － | P101: AP7101 | T101: store_code | X101: 追加の場合、選択されている店舗一覧 コピーの場合、ユーザーが操作権限を持つ全て店舗一覧 | AA101: 編集・コピーの場合、AP7101レスポンスでstore_code=store_codeのアイテムを選択する。 新規の場合、アイテムを選択しない。 | AI101: 新規の場合：有効 編集・コピーの場合：無効 | AR101: ● | AS101: ● | AT101: － | AU101: AP7105 | AY101: store_code | BC101: 初期店舗一覧のアイテムフォーマット: 「store_code:store_name」 イベントID：MD7101-01
B102: 3 | D102: レジ番号（タイトル） | K102: テキスト | N102: ー | O102: ● | P102: ー | T102: ー | X102: レジ番号* | AA102: ー | AI102: ー | AR102: － | AS102: － | AT102: － | AU102: ー | AY102: ー
B103: 4 | D103: レジ番号（値） | K103: EditText | N103: I/O | O103: － | P103: AP7101 | T103: code | X103: ー | AA103: 編集の場合: AP7101レスポンスのコード値 コピー・新規の場合: 空き | AI103: 編集の場合：無効 新規・コピーの場合：有効 | AR103: ● | AS103: ● | AT103: － | AU103: AP7105 | AY103: code | BC103: 数字のみ入力可能。最大4桁
B104: 5 | D104: レジ種別（タイトル） | K104: テキスト | N104: ー | O104: ● | P104: ー | T104: ー | X104: レジ種別* | AA104: ー | AI104: ー | AR104: － | AS104: － | AT104: － | AU104: ー | AY104: ー
B105: 6 | D105: レジ種別（値） | K105: ドロップダウン | N105: I/O | O105: － | P105: AP7101 | T105: type_code | X105: AP7103レスポンス | AA105: 編集・コピーの場合: AP7101レスポンスでtype_code=type_codeのアイテムを選択する。 新規の場合、アイテムを選択しない。 | AI105: 有効 | AR105: ● | AS105: ● | AT105: － | AU105: AP7105 | AY105: type_code | BC105: AP7103マッピング初期一覧のアイテムフォーマット：code:name
B106: 7 | D106: ノード種別（タイトル） | K106: テキスト | N106: ー | O106: ● | P106: ー | T106: ー | X106: ノード種別* | AA106: ー | AI106: ー | AR106: － | AS106: － | AT106: － | AU106: ー | AY106: ー
B107: 8 | D107: ノード種別（値） | K107: ドロップダウン | N107: I/O | O107: － | P107: AP7101 | T107: type_node | X107: AP1503レスポンス(MC7101) | AA107: 編集・コピーの場合:AP7101レスポンスでtype_node=type_nodeのアイテムを選択する。 新規の場合、アイテムを選択しない。 | AI107: 有効 | AR107: ● | AS107: ● | AT107: － | AU107: AP7105 | AY107: type_node | BC107: AP1503マッピング初期一覧のアイテムフォーマット：setting_data_type：event_group_name
B108: 9 | D108: プリセットレイアウト（タイトル） | K108: テキスト | N108: ー | O108: ● | P108: ー | T108: ー | X108: プリセットレイアウト* | AA108: ー | AI108: ー | AR108: － | AS108: － | AT108: － | AU108: ー | AY108: ー
B109: 10 | D109: プリセットレイアウト（値） | K109: ドロップダウン | N109: I/O | O109: － | P109: AP7101 | T109: button_layout_code | X109: AP1501レスポンス（store_code=項目ID2で選択された店舗） | AA109: 編集・コピーの場合：AP7101レスポンスでbutton_layout_code=button_layout_codeのアイテムを選択する。 新規の場合、アイテムを選択しない。 | AI109: 有効 | AR109: ● | AS109: ● | AT109: － | AU109: AP7105 | AY109: button_layout_code | BC109: AP1501マッピング初期一覧のアイテムフォーマット：preset_layout_code：preset_layout_name
B110: 11 | D110: ファンクションレイアウト（タイトル） | K110: テキスト | N110: ー | O110: ● | P110: ー | T110: ー | X110: ファンクションレイアウト* | AA110: ー | AI110: ー | AR110: － | AS110: － | AT110: － | AU110: ー | AY110: ー
B111: 12 | D111: ファンクションレイアウト（値） | K111: ドロップダウン | N111: I/O | O111: － | P111: AP7101 | T111: function_layout_code | X111: AP1503レスポンス(MC7102) | AA111: 編集・コピーの場合：AP7101レスポンスでfunction_layout_code=function_layout_codeのアイテムを選択する。 新規の場合、アイテムを選択しない。 | AI111: 有効 | AR111: ● | AS111: ● | AT111: － | AU111: AP7105 | AY111: function_layout_code | BC111: AP1503マッピング初期一覧のアイテムフォーマット：setting_data_type：event_group_name
B112: 13 | D112: キーボードレイアウト（タイトル） | K112: テキスト | N112: ー | O112: ● | P112: ー | T112: ー | X112: キーボードレイアウト* | AA112: ー | AI112: ー | AR112: － | AS112: － | AT112: － | AU112: ー | AY112: ー
B113: 14 | D113: キーボードレイアウト（値） | K113: ドロップダウン | N113: I/O | O113: － | P113: AP7101 | T113: keyboard_layout_code | X113: AP1503レスポンス(MC7103) | AA113: 編集・コピーの場合：AP7101レスポンスでkeyboard_layout_code=keyboard_layout_codeのアイテムを選択する。 新規の場合、アイテムを選択しない。 | AI113: 有効 | AR113: ● | AS113: ● | AT113: － | AU113: AP7105 | AY113: keyboard_layout_code | BC113: AP1503マッピング初期一覧のアイテムフォーマット：setting_data_type：event_group_name
B114: 15 | D114: レシートメッセージ（タイトル） | K114: テキスト | N114: ー | O114: ● | P114: ー | T114: ー | X114: レシートメッセージ* | AA114: ー | AI114: ー | AR114: － | AS114: － | AT114: － | AU114: ー | AY114: ー
B115: 16 | D115: レシートメッセージ（値） | K115: ドロップダウン | N115: I/O | O115: － | P115: AP7101 | T115: receipt_message_code | X115: AP8301レスポンス（store_code=項目ID2で選択された店舗） | AA115: 編集・コピーの場合：AP7101レスポンスでreceipt_message_code=receipt_message_codeのアイテムを選択する。 新規の場合、アイテムを選択しない。 | AI115: 有効 | AR115: ● | AS115: ● | AT115: － | AU115: AP7105 | AY115: receipt_message_code | BC115: AP8301マッピング初期一覧のアイテムフォーマット：sub_type_code:sub_type_name
B116: 17 | D116: IPアドレス（タイトル） | K116: テキスト | N116: ー | O116: ● | P116: ー | T116: ー | X116: IPアドレス | AA116: ー | AI116: ー | AR116: － | AS116: － | AT116: － | AU116: ー | AY116: ー
B117: 18 | D117: IPアドレス（値） | K117: EditText | N117: I/O | O117: － | P117: AP7101 | T117: ip_address | X117: ー | AA117: 編集の場合：AP7101レスポンスのip_addressの値 新規・コピーの場合：空き | AI117: 有効 | AR117: － | AS117: ● | AT117: ● | AU117: AP7105 | AY117: ip_address | BC117: 形式：IPv4: x.x.x.x（xは0から255の範囲）
B118: 19 | D118: MACアドレス（タイトル） | K118: テキスト | N118: ー | O118: ● | P118: ー | T118: ー | X118: MACアドレス | AA118: ー | AI118: ー | AR118: － | AS118: － | AT118: － | AU118: ー | AY118: ー
B119: 20 | D119: MACアドレス（値） | K119: EditText | N119: I/O | O119: － | P119: AP7101 | T119: mac_address | X119: ー | AA119: 編集の場合：AP7101レスポンスのmac_addressの値 新規・コピーの場合：空き | AI119: 有効 | AR119: － | AS119: ● | AT119: ● | AU119: AP7105 | AY119: mac_address | BC119: 形式：XX:XX:XX:XX:XX:XX（X：[0-9]又は[a-f]又は[A-F]）
B120: 21 | D120: 起動時間（タイトル） | K120: テキスト | N120: ー | O120: ● | P120: ー | T120: ー | X120: 起動時間 | AA120: ー | AI120: ー | AR120: － | AS120: － | AT120: － | AU120: ー | AY120: ー
B121: 22 | D121: 起動時間（値） | K121: Time Picker | N121: I/O | O121: － | P121: AP7101 | T121: start_up_time | X121: ー | AA121: 編集の場合：AP7101レスポンスのstart_up_timesの値 新規・コピーの場合：空き | AI121: 有効 | AR121: － | AS121: ● | AT121: ● | AU121: AP7105 | AY121: start_up_time
B122: 23 | D122: 客数集計除外（タイトル） | K122: テキスト | N122: ー | O122: ● | P122: ー | T122: ー | X122: 客数集計除外 | AA122: ー | AI122: ー | AR122: － | AS122: － | AT122: － | AU122: ー | AY122: ー
B123: 24 | D123: 客数集計除外（値） | K123: チェックボックス | N123: I/O | O123: － | P123: AP7101 | T123: customer_count_excluded | X123: FALSE | AA123: ー | AI123: 有効 | AR123: － | AS123: － | AT123: － | AU123: AP7105 | AY123: customer_count_excluded
B124: 25 | D124: 朝割除外（タイトル） | K124: テキスト | N124: ー | O124: ● | P124: ー | T124: ー | X124: 朝割除外 | AA124: ー | AI124: ー | AR124: － | AS124: － | AT124: － | AU124: ー | AY124: ー
B125: 26 | D125: 朝割除外（値） | K125: チェックボックス | N125: I/O | O125: － | P125: AP7101 | T125: morning_discount_excluded | X125: FALSE | AI125: 有効 | AR125: － | AS125: － | AT125: － | AU125: AP7105 | AY125: morning_discount_excluded
B126: 27 | D126: メガ割除外（タイトル） | K126: テキスト | N126: ー | O126: ● | P126: ー | T126: ー | X126: メガ割除外 | AA126: ー | AI126: ー | AR126: － | AS126: － | AT126: － | AU126: ー | AY126: ー
B127: 28 | D127: メガ割除外（値） | K127: チェックボックス | N127: I/O | O127: － | P127: AP7101 | T127: mega_discount_excluded | X127: FALSE | AA127: ー | AI127: 有効 | AR127: － | AS127: － | AT127: － | AU127: AP7105 | AY127: mega_discount_excluded
B128: 28-1 | D128: 構成比除外（タイトル） | K128: テキスト | N128: ー | O128: ● | P128: ー | T128: ー | X128: 構成比除外 | AA128: ー | AI128: ー | AR128: － | AS128: － | AT128: － | AU128: ー | AY128: ー
B129: 28-2 | D129: 構成比除外（値） | K129: チェックボックス | N129: I/O | O129: － | P129: AP7101 | T129: rate_customer_excluded | X129: FALSE | AA129: ー | AI129: 有効 | AR129: － | AS129: － | AT129: － | AU129: AP7105 | AY129: rate_customer_excluded
B130: 28-3 | D130: 380アテンダントモニタ除外（タイトル） | K130: テキスト | N130: ー | O130: ● | P130: ー | T130: ー | X130: 380アテンダントモニタ除外 | AA130: ー | AI130: ー | AR130: － | AS130: － | AT130: － | AU130: ー | AY130: ー
...
