Workbook

Sheet 表紙
A1: システム名 | K1: システム種別 | W1: 詳細設計書 | AP1: 作成者 | AT1: 作成日 | AY1: 更新者 | BC1: 更新日 | BH1: 版数
A2: POSサーバー | K2: POSサーバ | AP2: =改訂履歴!$H$11 -> TuyenNH | AT2: =改訂履歴!$B$11 -> 45544 | AY2: =LOOKUP(2,1/(改訂履歴!H11:H30000<>""),改訂履歴!H11:H30000) -> DuNT | BC2: =LOOKUP(2,1/(改訂履歴!B11:B30000<>""),改訂履歴!B11:B30000) -> 45628 | BH2: =LOOKUP(2,1/(改訂履歴!O11:O30000<>""),改訂履歴!O11:O30000) -> 0.16
A4: 機能カテゴリ | H4: 03_店舗特売入力 | U4: 項目 | Z4: 画面設計書 | AP4: {=RIGHT(CELL("filename",$A$1),LEN(CELL("filename",$A$1))-FIND("]",CELL("filename",$A$1)))} -> 表紙
L16: POSサーバーの基本設計書
L24: =K2&"/"&H4&"/"&Z4 -> POSサーバ/03_店舗特売入力/画面設計書
Q44: 承認日 | AA44: 承認者 | AQ44: 版数

Sheet 改訂履歴
A1: システム名 | K1: システム種別 | W1: =IF(表紙!W1="","",表紙!W1) -> 詳細設計書 | AP1: 作成者 | AT1: 作成日 | AY1: 更新者 | BC1: 更新日 | BH1: 版数
A2: =IF(表紙!A2="","",表紙!A2) -> POSサーバー | K2: =IF(表紙!K2="","",表紙!K2) -> POSサーバ | AP2: =IF(表紙!AP2="","",表紙!AP2) -> TuyenNH | AT2: =IF(表紙!AT2="","",表紙!AT2) -> 45544 | AY2: =IF(表紙!AY2="","",表紙!AY2) -> DuNT | BC2: =IF(表紙!BC2="","",表紙!BC2) -> 45628 | BH2: =IF(表紙!BH2="","",表紙!BH2) -> 0.16
A4: 機能カテゴリ | H4: =IF(表紙!H4="","",表紙!H4) -> 03_店舗特売入力 | U4: 項目 | Z4: =IF(表紙!Z4="","",表紙!Z4) -> 画面設計書 | AP4: {=RIGHT(CELL("filename",$A$1),LEN(CELL("filename",$A$1))-FIND("]",CELL("filename",$A$1)))} -> 改訂履歴
B8: ■改訂履歴
B10: 更新日 | H10: 更新者 | O10: 版数 | S10: 更新内容 | AX10: 承認日 | BD10: 承認者
B11: 45544 | H11: TuyenNH | O11: 0.1 | S11: 新規
B13: 45582 | H13: DuNT | O13: 0.11 | S13: MD0102シートを削除
B15: 45596 | H15: TuyenNH | O15: 0.12 | S15: ・「割引率」項目更新：最大2桁入力可能。（01～99）
B17: 45611 | H17: TuyenNH | O17: 0.13 | S17: 特売割引設定モードで表示されている場合、画面タイトルは「特売マスタ割引設定」と表示される。
B19: 45617 | H19: DuNT | O19: 0.14 | S19: SC0301：状態列を追加で説明 商品コード、PLUコードの入力項目を有効・無効にする。
B21: 45624 | H21: TuyenNH | O21: 0.15 | S21: SC0301：有効項目判定ロジックを追加
B23: 45628 | H23: DuNT | O23: 0.16 | S23: フロー01から移動した場合の表示を更新

Sheet SC0301
A1: システム名 | K1: システム種別 | W1: =IF(表紙!W1="","",表紙!W1) -> 詳細設計書 | AP1: 作成者 | AT1: 作成日 | AY1: 更新者 | BC1: 更新日 | BH1: 版数
A2: =IF(表紙!A2="","",表紙!A2) -> POSサーバー | K2: =IF(表紙!K2="","",表紙!K2) -> POSサーバ | AP2: =IF(表紙!AP2="","",表紙!AP2) -> TuyenNH | AT2: =IF(表紙!AT2="","",表紙!AT2) -> 45544 | AY2: =IF(表紙!AY2="","",表紙!AY2) -> DuNT | BC2: =IF(表紙!BC2="","",表紙!BC2) -> 45628 | BH2: =IF(表紙!BH2="","",表紙!BH2) -> 0.16
A4: 機能カテゴリ | H4: =IF(表紙!H4="","",表紙!H4) -> 03_店舗特売入力 | U4: 項目 | Z4: =IF(表紙!Z4="","",表紙!Z4) -> 画面設計書 | AP4: =MID(CELL("filename",A1),FIND("]",CELL("filename",A1))+1,255) -> SC0301
B7: ■イメージ
C8: 店舗選択エリア
B44: ■画面項目定義
B46: 画面項目ID | D46: 項目 | K46: タイプ | N46: I/O | O46: 多言語 | P46: 出力 | AR46: インプット | BC46: 備考
P47: マッピングデータ | X47: 初期値 | AA47: 表示コントロール | AI47: Control enable | AR47: 必須 | AS47: 数字 | AT47: 桁 | AU47: マッピングデータ
P48: API名 | T48: 項目 | AU48: API名 | AY48: 項目
B49: 0 | D49: 画面タイトル | K49: テキスト | N49: － | O49: ● | P49: － | T49: － | X49: 特売マスタ売価設定 | AA49: ・特売割引設定ボタンをタッチする =>タイトルを「特売マスタ売価設定」に切り替える。 ・特売売価設定ボタンをタッチする =>タイトルを「特売マスタ割引設定」に切り替える。 | AI49: ー | AR49: － | AS49: ー | AT49: ー | AU49: － | AY49: ー | BC49: イベントID：SC0301-01
B50: 1 | D50: 店舗選択タブ（タイトル） | K50: テキスト | N50: － | O50: ● | P50: － | T50: － | X50: 店舖選択 | AA50: ー | AI50: ー | AR50: － | AS50: ー | AT50: ー | AU50: － | AY50: ー | BC50: ー
B51: 1.1 | D51: 店舗選択エリア | K51: － | N51: － | O51: － | P51: － | T51: － | X51: － | AA51: ー | AI51: ー | AR51: － | AS51: ー | AT51: ー | AU51: － | AY51: ー | BC51: 20_画面設計_00_共通.xlsxの店舗選択エリアシートをご参照ください。
B54: ■イメージ
C55: 検索エリア
B90: ■画面項目定義
B92: 画面項目ID | D92: 項目 | K92: Type | N92: I/O | O92: 多言語 | P92: 出力 | AR92: インプット | BC92: 備考
P93: マッピングデータ | X93: 初期値 | AA93: 表示コントロール | AI93: Control enable | AR93: 必須 | AS93: 数字 | AT93: 桁 | AU93: マッピングデータ
P94: API名 | T94: 項目 | AU94: API名 | AY94: 項目
B95: 2 | D95: 検索タブ（タイトル） | K95: テキスト | N95: － | O95: ● | P95: － | T95: － | X95: 検索条件 | AA95: ー | AI95: ー | AR95: － | AS95: ー | AT95: ー | AU95: － | AY95: ー | BC95: ー
B96: 3 | D96: プロモーションコード* (タイトル) | K96: テキスト | N96: － | O96: ● | P96: － | T96: － | X96: プロモーションコード* | AA96: ー | AI96: ー | AR96: － | AS96: ー | AT96: ー | AU96: － | AY96: ー | BC96: ー
B97: 3.1 | D97: プロモーションコード* (値) | K97: EditText | N97: I | O97: － | P97: － | T97: － | X97: － | AA97: ー | AI97: ・店舗が選択された場合：有効 ・有効なプロモーションコードが選択された場合：無効 | AR97: ● | AS97: ● | AT97: ー | AU97: AP0301 | AY97: promotion_code | BC97: ・イベントID：SC0301-02 ・最大桁数：5 ・イベントID：MD0102-04を実行すると、MD0102_プロモーション一覧モーダルから選択されたデータを表示する。
B98: 3.2 | D98: プロモーション名（値） | K98: テキスト | N98: O | O98: － | P98: AP0106 | T98: name | X98: － | AA98: ー | AI98: ー | AR98: － | AS98: ー | AT98: ー | AU98: － | AY98: ー | BC98: イベントID：MD0102-04を実行すると、MD0102_プロモーション一覧モーダルから選択されたデータを表示する。
B99: 4 | D99: 検索 | K99: ボタン | N99: I | O99: ● | P99: － | T99: － | X99: 検索 | AA99: ー | AI99: デフォルト：有効 | AR99: － | AS99: ー | AT99: ー | AU99: － | AY99: ー | BC99: イベントID：SC0301-03
B100: 5 | D100: プロモーション期間（タイトル） | K100: テキスト | N100: － | O100: ● | P100: － | T100: － | X100: プロモーション期間 | AA100: ー | AI100: ー | AR100: － | AS100: ー | AT100: ー | AU100: － | AY100: ー | BC100: ー
B101: 5.1 | D101: プロモーション開始日（値） | K101: テキスト | N101: O | O101: － | P101: AP0106 | T101: start_date_time | X101: － | AA101: ー | AI101: ー | AR101: － | AS101: ー | AT101: ー | AU101: － | AY101: ー | BC101: イベントID：MD0102-04を実行すると、MD0102_プロモーション一覧モーダルから選択されたデータを表示する。
B102: 5.2 | D102: プロモーション開始時刻（値） | K102: テキスト | N102: O | O102: － | P102: AP0106 | T102: start_time | X102: － | AA102: ー | AI102: ー | AR102: － | AS102: ー | AT102: ー | AU102: － | AY102: ー | BC102: イベントID：MD0102-04を実行すると、MD0102_プロモーション一覧モーダルから選択されたデータを表示する。
B103: 5.3 | D103: プロモーション終了日（値） | K103: テキスト | N103: O | O103: － | P103: AP0106 | T103: end_date_time | X103: － | AA103: ー | AI103: ー | AR103: － | AS103: ー | AT103: ー | AU103: － | AY103: ー | BC103: イベントID：MD0102-04を実行すると、MD0102_プロモーション一覧モーダルから選択されたデータを表示する。
B104: 5.4 | D104: プロモーション終了時刻（値） | K104: テキスト | N104: O | O104: － | P104: AP0106 | T104: end_time | X104: － | AA104: ー | AI104: ー | AR104: － | AS104: ー | AT104: ー | AU104: － | AY104: ー | BC104: イベントID：MD0102-04を実行すると、MD0102_プロモーション一覧モーダルから選択されたデータを表示する。
B105: 6 | D105: 部門コード（タイトル） | K105: テキスト | N105: － | O105: ● | P105: － | T105: － | X105: 部門コード | AA105: ー | AI105: ー | AR105: － | AS105: ー | AT105: ー | AU105: － | AY105: ー | BC105: ー
B106: 6.1 | D106: 部門コード（値） | K106: EditText | N106: I | O106: － | P106: － | T106: － | X106: － | AA106: ー | AI106: ・有効なプロモーションコードが選択されていない場合、またはSC0101から画面を開いた場合：無効 ・店舗が選択され、有効なプロモーションが選択された場合：有効 | AR106: － | AS106: ● | AT106: ー | AU106: AP0301 | AY106: md_hierarchy_code_level_one | BC106: 最大桁数：2
... B120: 18 | D120: 商品コード切替 | K120: ボタン | N120: I | O120: ● | P120: － | T120: － | X120: 商品コード切替 | AA120: ・「商品コード切替」ボタンをタッチする => 「PLUコード切替」に切り替える。 ・「PLUコード切替」ボタンをタッチする => 「商品コード切替」に切り替える。 | AI120: デフォルト：有効。 *SC0101から画面を開いた場合：無効 | AR120: － | AS120: ー | AT120: ー | AU120: － | AY120: ー | BC120: ・イベントID：SC0301-07 ・商品コード切替と表示されている場合、「部門コード（値）」と「商品コード」を無効にする。 ・「PLUコード切替」と表示されている場合、「PLUコード」を無効にする。
B123: ■イメージ
C124: データ表示エリア
B159: ■画面項目定義
B161: 画面項目ID | D161: 項目 | K161: タイプ | N161: I/O | O161: 多言語 | P161: 出力 | AR161: インプット | BC161: 備考
P162: マッピングデータ | X162: 初期値 | AA162: 表示コントロール | AI162: Control enable | AR162: 必須 | AS162: 数字 | AT162: 桁 | AU162: マッピングデータ
P163: API名 | T163: 項目 | AU163: API名 | AY163: 項目
B164: 19 | D164: 有効（タイトル） | K164: テキスト | N164: － | O164: ● | P164: － | T164: － | X164: 有効 | AA164: ー | AI164: ー | AR164: － | AS164: ー | AT164: ー | AU164: － | AY164: ー
B165: 19.1 | D165: 有効（値） | K165: テキスト | N165: O | O165: － | P165: AP0301 AP1506 | T165: valid | X165: － | AA165: ・新規モード： +一覧に商品が存在していない場合、「新規」を表示する。 +一覧に商品が存在した場合、「変更」を表示する。 ・編集モード：備考列の値に該当する有効な値をレスポンスAP0301に表示する。 | AI165: ー | AR165: － | AS165: ー | AT165: ー | AU165: － | AY165: － | BC165: ・検索を実行する場合、特売売価の有効を表示する。 0: 実施中 1: 終了 2: 未実施 3: 中止 4: NG =>ロジック判定の詳細はAP0301をご参照ください。 ・商品情報を提案する場合、以下のように表示する。 0: 新規 1: 変更 =>ロジック判定の詳細はAP1506をご参照ください。
B166: 20 | D166: 状態（タイトル） | K166: テキスト | N166: － | O166: ● | P166: － | T166: － | X166: 状態 | AA166: ー | AI166: ー | AR166: － | AS166: ー | AT166: ー | AU166: － | AY166: ー | BC166: ー
...
