Workbook

Sheet 表紙
A1: システム名 | K1: システム種別 | W1: 詳細設計書 | AP1: 作成者 | AT1: 作成日 | AY1: 更新者 | BC1: 更新日 | BH1: 版数
A2: POSサーバー | K2: POSサーバ | AP2: =改訂履歴!$H$11 -> DuNT | AT2: =改訂履歴!$B$11 -> 45540 | AY2: =LOOKUP(2,1/(改訂履歴!H11:H30000<>""),改訂履歴!H11:H30000) -> DuNT | BC2: =LOOKUP(2,1/(改訂履歴!B11:B30000<>""),改訂履歴!B11:B30000) -> 45540 | BH2: =LOOKUP(2,1/(改訂履歴!O11:O30000<>""),改訂履歴!O11:O30000) -> 0.1
A4: 機能カテゴリ | H4: 16_保留・保留解除 | U4: 項目 | Z4: 画面設計書 | AP4: {=RIGHT(CELL("filename",$A$1),LEN(CELL("filename",$A$1))-FIND("]",CELL("filename",$A$1)))} -> 表紙
L16: POSサーバーの詳細設計書
L24: =K2&"/"&H4&"/"&Z4 -> POSサーバ/16_保留・保留解除/画面設計書
Q44: 承認日 | AA44: 承認者 | AQ44: 版数

Sheet 改訂履歴
A1: システム名 | K1: システム種別 | W1: =IF(表紙!W1="","",表紙!W1) -> 詳細設計書 | AP1: 作成者 | AT1: 作成日 | AY1: 更新者 | BC1: 更新日 | BH1: 版数
A2: =IF(表紙!A2="","",表紙!A2) -> POSサーバー | K2: =IF(表紙!K2="","",表紙!K2) -> POSサーバ | AP2: =IF(表紙!AP2="","",表紙!AP2) -> DuNT | AT2: =IF(表紙!AT2="","",表紙!AT2) -> 45540 | AY2: =IF(表紙!AY2="","",表紙!AY2) -> DuNT | BC2: =IF(表紙!BC2="","",表紙!BC2) -> 45540 | BH2: =IF(表紙!BH2="","",表紙!BH2) -> 0.1
A4: 機能カテゴリー | H4: =IF(表紙!H4="","",表紙!H4) -> 16_保留・保留解除 | U4: 項目 | Z4: =IF(表紙!Z4="","",表紙!Z4) -> 画面設計書 | AP4: {=RIGHT(CELL("filename",$A$1),LEN(CELL("filename",$A$1))-FIND("]",CELL("filename",$A$1)))} -> 改訂履歴
B8: ■改訂履歴
B10: 更新日 | H10: 更新者 | O10: 版数 | S10: 更新内容 | AX10: 承認日 | BD10: 承認者
B11: 45540 | H11: DuNT | O11: 0.1 | S11: 新規

Sheet SC1601
A1: システム名 | K1: システム種別 | W1: =IF(表紙!W1="","",表紙!W1) -> 詳細設計書 | AP1: 作成者 | AT1: 作成日 | AY1: 更新者 | BC1: 更新日 | BH1: 版数
A2: =IF(表紙!A2="","",表紙!A2) -> POSサーバー | K2: =IF(表紙!K2="","",表紙!K2) -> POSサーバ | AP2: =IF(表紙!AP2="","",表紙!AP2) -> DuNT | AT2: =IF(表紙!AT2="","",表紙!AT2) -> 45540 | AY2: =IF(表紙!AY2="","",表紙!AY2) -> DuNT | BC2: =IF(表紙!BC2="","",表紙!BC2) -> 45540 | BH2: =IF(表紙!BH2="","",表紙!BH2) -> 0.1
A4: 機能カテゴリ | H4: =IF(表紙!H4="","",表紙!H4) -> 16_保留・保留解除 | U4: 項目 | Z4: =IF(表紙!Z4="","",表紙!Z4) -> 画面設計書 | AP4: =MID(CELL("filename",A1),FIND("]",CELL("filename",A1))+1,255) -> SC1601
B7: ■イメージ
B45: ■画面項目定義
B47: 画面項目ID | D47: 項目 | K47: タイプ | N47: I/O | O47: 多言語 | P47: 出力 | AR47: インプット | BC47: 備考
P48: マッピングデータ | X48: 初期値 | AA48: 表示コントロール | AI48: Control enable | AR48: 必須 | AS48: 数字 | AT48: 桁 | AU48: マッピングデータ
P49: API名 | T49: 項目 | AU49: API名 | AY49: 項目
B50: 0 | D50: 画面タイトル | K50: テキスト | N50: － | O50: ● | P50: － | T50: － | X50: 保留・保留解除設定 | AA50: ー | AI50: ー | AR50: － | AS50: ー | AT50: ー | AU50: － | AY50: ー | BC50: イベントID：SC1601-01をご参照ください。
D51: 検索エリア | K51: － | N51: － | O51: － | P51: － | T51: － | X51: － | AA51: ー | AI51: － | AR51: － | AS51: ー | AT51: ー | AU51: － | AY51: ー
B52: 1 | D52: 区分（タイトル） | K52: テキスト | N52: － | O52: ● | P52: － | T52: － | X52: 区分 | AA52: ー | AI52: ー | AR52: － | AS52: ー | AT52: ー | AU52: － | AY52: ー
B53: 2 | D53: 区分（値） | K53: ドロップダウン | N53: I | O53: － | P53: － | X53: － | AA53: ー | AI53: ー | AR53: － | AS53: ー | AT53: ー | AU53: － | AY53: ー
B54: 3 | D54: レシートNo.（タイトル） | K54: テキスト | N54: － | O54: ● | P54: － | T54: － | X54: レシートNo | AA54: ー | AI54: ー | AR54: － | AS54: ー | AT54: ー | AU54: － | AY54: ー
B55: 4 | D55: レシートNo.（値） | K55: EditText | N55: I | O55: － | P55: － | T55: － | X55: － | AA55: ー | AI55: ー | AR55: － | AS55: ー | AT55: ー | AU55: － | AY55: ー
B56: 5 | D56: レジNo（タイトル） | K56: テキスト | N56: － | O56: ● | P56: － | T56: － | X56: レジNo | AA56: ー | AI56: ー | AR56: － | AS56: ー | AT56: ー | AU56: － | AY56: ー
B57: 6 | D57: レジNo（値） | K57: EditText | N57: I | O57: － | P57: － | T57: － | X57: － | AA57: ー | AI57: ー | AR57: － | AS57: ー | AT57: ー | AU57: － | AY57: ー
B58: 7 | D58: 保留日時（タイトル） | K58: テキスト | N58: － | O58: ● | P58: － | T58: － | X58: 日時 | AA58: ー | AI58: ー | AR58: － | AS58: ー | AT58: ー | AU58: － | AY58: ー
B59: 8 | D59: 開始日（値） | K59: EditText | N59: I | O59: － | P59: － | T59: － | X59: 開始年月日 | AA59: ー | AI59: ー | AR59: － | AS59: ー | AT59: ー | AU59: － | AY59: ー
B60: 9 | D60: 開始時刻 (値) | K60: EditText | N60: I | O60: － | P60: － | T60: － | X60: 開始時間 | AA60: ー | AI60: ー | AR60: － | AS60: ー | AT60: ー | AU60: － | AY60: ー
B61: 10 | D61: ~ | K61: テキスト | N61: － | O61: － | P61: － | T61: － | X61: ~ | AA61: ー | AI61: ー | AR61: － | AS61: ー | AT61: ー | AU61: － | AY61: ー
B62: 11 | D62: 終了日（値） | K62: EditText | N62: I | O62: － | P62: － | T62: － | X62: 終了年月日 | AA62: ー | AI62: ー | AR62: － | AS62: ー | AT62: ー | AU62: － | AY62: ー
B63: 12 | D63: 終了時刻（値） | K63: EditText | N63: I | O63: － | P63: － | T63: － | X63: 終了時間 | AA63: ー | AI63: ー | AR63: － | AS63: ー | AT63: ー | AU63: － | AY63: ー
B64: 13 | D64: 検索 | K64: ボタン | N64: I | O64: ● | P64: － | T64: － | X64: 検索 | AA64: ー | AI64: 有効 | AR64: － | AS64: ー | AT64: ー | AU64: － | AY64: ー | BC64: イベントID：SC1601-02
B68: ■イメージ
B105: 画面項目ID | D105: 項目 | K105: Type | N105: I/O | O105: 多言語 | P105: 出力 | AR105: インプット | BC105: 備考
P106: マッピングデータ | X106: 初期値 | AA106: 表示コントロール | AI106: Control enable | AR106: 必須 | AS106: 数字 | AT106: 桁 | AU106: マッピングデータ
P107: API名 | T107: 項目 | AU107: API名 | AY107: 項目
D108: 保留・保留解除一覧
B109: 14 | D109: 全て印刷 | K109: チェックボックス | N109: I | O109: ● | P109: － | T109: － | X109: 印刷 | AA109: ー | AI109: ー | AR109: － | AS109: ー | AT109: ー | AU109: － | AY109: ー | BC109: イベントID：SC1601-03
B110: 15 | D110: アイテム印刷 | K110: チェックボックス | N110: I | O110: － | P110: － | T110: － | X110: － | AA110: ー | AI110: ー | AR110: － | AS110: ー | AT110: ー | AU110: － | AY110: ー
B111: 16 | D111: 区分（タイトル） | K111: テキスト | N111: － | O111: ● | P111: － | T111: － | X111: 区分 | AA111: ー | AI111: ー | AR111: － | AS111: ー | AT111: ー | AU111: － | AY111: ー
B112: 17 | D112: 区分（値） | K112: テキスト | N112: O | O112: － | P112: － | T112: － | X112: － | AA112: ー | AI112: ー | AR112: － | AS112: ー | AT112: ー | AU112: － | AY112: ー
B113: 18 | D113: 店舗（タイトル） | K113: テキスト | N113: － | O113: ● | P113: － | T113: － | X113: 店舗 | AA113: ー | AI113: ー | AR113: － | AS113: ー | AT113: ー | AU113: － | AY113: ー
B114: 19 | D114: 店舗（値） | K114: テキスト | N114: O | O114: － | P114: － | T114: － | X114: － | AA114: ー | AI114: ー | AR114: － | AS114: ー | AT114: ー | AU114: － | AY114: ー
B115: 20 | D115: レジNo（タイトル） | K115: テキスト | N115: － | O115: ● | P115: － | T115: － | X115: レジNo | AA115: ー | AI115: ー | AR115: － | AS115: ー | AT115: ー | AU115: － | AY115: ー
B116: 21 | D116: レジNo（値） | K116: テキスト | N116: O | O116: － | P116: － | T116: － | X116: － | AA116: ー | AI116: ー | AR116: － | AS116: ー | AT116: ー | AU116: － | AY116: ー
B117: 22 | D117: レシートNo（タイトル） | K117: テキスト | N117: － | O117: ● | P117: － | T117: － | X117: レシートNo | AA117: ー | AI117: ー | AR117: － | AS117: ー | AT117: ー | AU117: － | AY117: ー
B118: 23 | D118: レシートNo（値） | K118: テキスト | N118: O | O118: － | P118: － | T118: － | X118: － | AA118: ー | AI118: ー | AR118: － | AS118: ー | AT118: ー | AU118: － | AY118: ー
B119: 24 | D119: 保留日時（タイトル） | K119: テキスト | N119: － | O119: ● | P119: － | T119: － | X119: 保留日時 | AA119: ー | AI119: ー | AR119: － | AS119: ー | AT119: ー | AU119: － | AY119: ー
B120: 25 | D120: 保留日時（値) | K120: テキスト | N120: O | O120: － | P120: － | T120: － | X120: － | AA120: ー | AI120: ー | AR120: － | AS120: ー | AT120: ー | AU120: － | AY120: ー
...
