Workbook

Sheet 表紙
A1: システム名 | K1: システム種別 | W1: 詳細設計書 | AP1: 作成者 | AT1: 作成日 | AY1: 更新者 | BC1: 更新日 | BH1: 版数
A2: POSサーバー | K2: POSサーバ | AP2: =改訂履歴!$H$11 -> DuNT | AT2: =改訂履歴!$B$11 -> 45636 | AY2: =LOOKUP(2,1/(改訂履歴!H11:H30000<>""),改訂履歴!H11:H30000) -> DuNT | BC2: =LOOKUP(2,1/(改訂履歴!B11:B30000<>""),改訂履歴!B11:B30000) -> 45636 | BH2: =LOOKUP(2,1/(改訂履歴!O11:O30000<>""),改訂履歴!O11:O30000) -> 0.1
A4: 機能カテゴリ | H4: 31_レジ別速報・日報 | U4: 項目 | Z4: 画面設計書 | AP4: {=RIGHT(CELL("filename",$A$1),LEN(CELL("filename",$A$1))-FIND("]",CELL("filename",$A$1)))} -> 表紙
L16: POSサーバーの詳細設計書
L24: =K2&"/"&H4&"/"&Z4 -> POSサーバ/31_レジ別速報・日報 /画面設計書
Q44: 承認日 | AA44: 承認者 | AQ44: 版数

Sheet 改訂履歴
A1: システム名 | K1: システム種別 | W1: =IF(表紙!W1="","",表紙!W1) -> 詳細設計書 | AP1: 作成者 | AT1: 作成日 | AY1: 更新者 | BC1: 更新日 | BH1: 版数
A2: =IF(表紙!A2="","",表紙!A2) -> POSサーバー | K2: =IF(表紙!K2="","",表紙!K2) -> POSサーバ | AP2: =IF(表紙!AP2="","",表紙!AP2) -> DuNT | AT2: =IF(表紙!AT2="","",表紙!AT2) -> 45636 | AY2: =IF(表紙!AY2="","",表紙!AY2) -> DuNT | BC2: =IF(表紙!BC2="","",表紙!BC2) -> 45636 | BH2: =IF(表紙!BH2="","",表紙!BH2) -> 0.1
A4: 機能カテゴリ | H4: =IF(表紙!H4="","",表紙!H4) -> 31_レジ別速報・日報 | U4: 項目 | Z4: =IF(表紙!Z4="","",表紙!Z4) -> 画面設計書 | AP4: {=RIGHT(CELL("filename",$A$1),LEN(CELL("filename",$A$1))-FIND("]",CELL("filename",$A$1)))} -> 改訂履歴
B8: ■改訂履歴
B10: 更新日 | H10: 更新者 | O10: 版数 | S10: 更新内容 | AX10: 承認日 | BD10: 承認者
B11: 45636 | H11: DuNT | O11: 0.1 | S11: 新規

Sheet SC3101
A1: システム名 | K1: システム種別 | W1: =IF(表紙!W1="","",表紙!W1) -> 詳細設計書 | AP1: 作成者 | AT1: 作成日 | AY1: 更新者 | BC1: 更新日 | BH1: 版数
A2: =IF(表紙!A2="","",表紙!A2) -> POSサーバー | K2: =IF(表紙!K2="","",表紙!K2) -> POSサーバ | AP2: =IF(表紙!AP2="","",表紙!AP2) -> DuNT | AT2: =IF(表紙!AT2="","",表紙!AT2) -> 45636 | AY2: =IF(表紙!AY2="","",表紙!AY2) -> DuNT | BC2: =IF(表紙!BC2="","",表紙!BC2) -> 45636 | BH2: =IF(表紙!BH2="","",表紙!BH2) -> 0.1
A4: 機能カテゴリ | H4: =IF(表紙!H4="","",表紙!H4) -> 31_レジ別速報・日報 | U4: 項目 | Z4: =IF(表紙!Z4="","",表紙!Z4) -> 画面設計書 | AP4: =MID(CELL("filename",A1),FIND("]",CELL("filename",A1))+1,255) -> SC3101
B7: ■店舗を選択した時の初期化画面のイメージ
B40: ■画面項目定義
B42: 画面項目ID | D42: 項目 | K42: タイプ | N42: I/O | O42: 多言語 | P42: 出力 | AR42: インプット | BC42: 備考
P43: マッピングデータ | X43: 初期値 | AA43: 表示コントロール | AI43: Control enable | AR43: 必須 | AS43: 数字 | AT43: 桁 | AU43: マッピングデータ
P44: API名 | T44: 項目 | AU44: API名 | AY44: 項目
B45: 0 | D45: 画面タイトル | K45: テキスト | N45: － | O45: ● | P45: － | T45: － | X45: レジ別速報／日報 | AA45: ー | AI45: － | AR45: － | AS45: ー | AT45: ー | AU45: － | AY45: ー | BC45: イベントID：SC3101-01
B46: =B45+1 -> 1 | D46: 営業種別（タイトル） | K46: テキスト | N46: － | O46: ● | P46: － | T46: － | X46: 営業種別 | AA46: ー | AI46: ー | AR46: － | AS46: ー | AT46: ー | AU46: － | AY46: ー
B47: =B46+1 -> 2 | D47: 営業種別（値） | K47: ラジオボタン | N47: I | O47: ● | P47: － | T47: － | X47: 速報 | AA47: 以下の2つオプションがある。 ・速報 ・日報 | AI47: 対象店舗が選択された場合は有効になる。 | AR47: ● | AS47: ー | AT47: ー | AU47: － | AY47: ー
B48: =B47+1 -> 3 | D48: 営業日（タイトル） | K48: テキスト | N48: － | O48: ● | P48: － | T48: － | X48: 営業日 | AA48: ー | AI48: ー | AR48: － | AS48: ー | AT48: ー | AU48: － | AY48: ー
B49: =B48+1 -> 4 | D49: 営業日（値） | K49: Date picker | N49: I | O49: － | P49: － | T49: － | X49: 現在日 | AA49: ー | AI49: 対象店舗が選択され、営業種別 = 日報の場合に有効になる。 | AR49: ● | AS49: － | AT49: ー | AU49: － | AY49: ー
B50: =B49+1 -> 5 | D50: 検索 | K50: ボタン | N50: I | O50: ● | P50: － | T50: － | X50: 検索 | AA50: ー | AI50: 対象店舗が選択された場合は有効になる。 | AR50: － | AS50: ー | AT50: ー | AU50: － | AY50: ー | BC50: イベントID：SC3101-02
B51: =B50+1 -> 6 | D51: 印刷 | K51: ボタン | N51: I | O51: － | P51: － | T51: － | X51: － | AA51: ー | AI51: 対象店舗が選択された場合は有効になる。 | AR51: － | AS51: － | AT51: ー | AU51: － | AY51: ー
B54: ■検索結果がある時の画面のイメージ
B86: ■画面項目定義
B88: 画面項目ID | D88: 項目 | K88: タイプ | N88: I/O | O88: 多言語 | P88: 出力 | AR88: インプット | BC88: 備考
P89: マッピングデータ | X89: 初期値 | AA89: 表示コントロール | AI89: Control enable | AR89: 必須 | AS89: 数字 | AT89: 桁 | AU89: マッピングデータ
P90: API名 | T90: 項目 | AU90: API名 | AY90: 項目
B91: 7 | D91: レジ（タイトル） | K91: テキスト | N91: － | O91: ● | P91: － | T91: － | X91: レジ | AA91: ー | AI91: － | AR91: － | AS91: ー | AT91: ー | AU91: － | AY91: ー
B92: =B91+1 -> 8 | D92: 合計（タイトル） | K92: テキスト | N92: － | O92: ● | P92: － | T92: － | X92: 合計 | AA92: ー | AI92: ー | AR92: － | AS92: ー | AT92: ー | AU92: － | AY92: ー
B93: =B92+1 -> 9 | D93: レジ名称（値） | K93: テキスト | N93: O | O93: － | P93: － | T93: － | X93: － | AA93: ー | AI93: ー | AR93: － | AS93: ー | AT93: ー | AU93: － | AY93: ー
B94: =B93+1 -> 10 | D94: 売上（タイトル） | K94: テキスト | N94: － | O94: ● | P94: － | T94: － | X94: 売上 | AA94: ー | AI94: ー | AR94: － | AS94: ー | AT94: ー | AU94: － | AY94: ー
B95: =B94+1 -> 11 | D95: 全てのレジの総売上 | K95: テキスト | N95: O | O95: － | P95: － | T95: － | X95: － | AA95: ー | AI95: ー | AR95: － | AS95: － | AT95: ー | AU95: － | AY95: ー
B96: =B95+1 -> 12 | D96: 各レジの売上 | K96: テキスト | N96: O | O96: － | P96: － | T96: － | X96: － | AA96: ー | AI96: ー | AR96: － | AS96: － | AT96: ー | AU96: － | AY96: ー
B97: =B96+1 -> 13 | D97: 客数（タイトル） | K97: テキスト | N97: ー | O97: ● | P97: － | T97: － | X97: 客数 | AA97: ー | AI97: ー | AR97: － | AS97: － | AT97: ー | AU97: － | AY97: ー
B98: =B97+1 -> 14 | D98: 全てのレジの総客数 | K98: テキスト | N98: O | O98: － | P98: － | T98: － | X98: － | AA98: ー | AI98: ー | AR98: － | AS98: － | AT98: ー | AU98: － | AY98: ー | BC98: 形式：xxx,xxx
B99: =B98+1 -> 15 | D99: 各レジの客数 | K99: テキスト | N99: O | O99: － | P99: － | T99: － | X99: － | AA99: ー | AI99: ー | AR99: － | AS99: － | AT99: ー | AU99: － | AY99: ー | BC99: 形式：xxx,xxx
B100: =B99+1 -> 16 | D100: 点数（タイトル） | K100: テキスト | N100: － | O100: ● | P100: － | T100: － | X100: 点数 | AA100: ー | AI100: ー | AR100: － | AS100: － | AT100: ー | AU100: － | AY100: ー
B101: =B100+1 -> 17 | D101: 全てのレジの総点数 | K101: テキスト | N101: O | O101: － | P101: － | T101: － | X101: － | AA101: ー | AI101: ー | AR101: － | AS101: － | AT101: ー | AU101: － | AY101: ー | BC101: 形式：xxx,xxx
B102: =B101+1 -> 18 | D102: 各レジの点数 | K102: テキスト | N102: O | O102: － | P102: － | T102: － | X102: － | AA102: ー | AI102: ー | AR102: － | AS102: － | AT102: ー | AU102: － | AY102: ー | BC102: 形式：xxx,xxx
B103: =B102+1 -> 19 | D103: 外税額（タイトル） | K103: テキスト | N103: － | O103: ● | P103: － | T103: － | X103: 外税額 | AA103: ー | AI103: ー | AR103: － | AS103: － | AT103: ー | AU103: － | AY103: ー
B104: =B103+1 -> 20 | D104: 全てのレジの総外税額 | K104: テキスト | N104: O | O104: － | P104: － | T104: － | X104: － | AA104: ー | AI104: ー | AR104: － | AS104: － | AT104: ー | AU104: － | AY104: ー | BC104: 形式：xxx,xxx
B105: =B104+1 -> 21 | D105: 各レジの外税額 | K105: テキスト | N105: O | O105: － | P105: － | T105: － | X105: － | AA105: ー | AI105: ー | AR105: － | AS105: － | AT105: ー | AU105: － | AY105: ー | BC105: 形式：xxx,xxx
B106: =B105+1 -> 22 | D106: 内税額（タイトル） | K106: テキスト | N106: － | O106: ● | P106: － | T106: － | X106: 内税額 | AA106: ー | AI106: ー | AR106: － | AS106: － | AT106: ー | AU106: － | AY106: ー
B107: =B106+1 -> 23 | D107: 全てのレジの総内税額 | K107: テキスト | N107: O | O107: － | P107: － | T107: － | X107: － | AA107: ー | AI107: ー | AR107: － | AS107: － | AT107: ー | AU107: － | AY107: ー | BC107: 形式：xxx,xxx
B108: =B107+1 -> 24 | D108: 各レジの内税額 | K108: テキスト | N108: O | O108: － | P108: － | T108: － | X108: － | AA108: ー | AI108: ー | AR108: － | AS108: － | AT108: ー | AU108: － | AY108: ー | BC108: 形式：xxx,xxx
B109: =B108+1 -> 25 | D109: 点単価（タイトル） | K109: テキスト | N109: － | O109: ● | P109: － | T109: － | X109: 点単価 | AA109: ー | AI109: ー | AR109: － | AS109: － | AT109: ー | AU109: － | AY109: ー
B110: =B109+1 -> 26 | D110: 点単価（全てのレジの合計） | K110: テキスト | N110: O | O110: － | P110: － | T110: － | X110: － | AA110: ー | AI110: ー | AR110: － | AS110: － | AT110: ー | AU110: － | AY110: ー | BC110: 形式：xxx,xxx.y
...

Sheet SC3102
A1: システム名 | K1: システム種別 | W1: =IF(表紙!W1="","",表紙!W1) -> 詳細設計書 | AP1: 作成者 | AT1: 作成日 | AY1: 更新者 | BC1: 更新日 | BH1: 版数
A2: =IF(表紙!A2="","",表紙!A2) -> POSサーバー | K2: =IF(表紙!K2="","",表紙!K2) -> POSサーバ | AP2: =IF(表紙!AP2="","",表紙!AP2) -> DuNT | AT2: =IF(表紙!AT2="","",表紙!AT2) -> 45636 | AY2: =IF(表紙!AY2="","",表紙!AY2) -> DuNT | BC2: =IF(表紙!BC2="","",表紙!BC2) -> 45636 | BH2: =IF(表紙!BH2="","",表紙!BH2) -> 0.1
A4: 機能カテゴリ | H4: =IF(表紙!H4="","",表紙!H4) -> 31_レジ別速報・日報 | U4: 項目 | Z4: =IF(表紙!Z4="","",表紙!Z4) -> 画面設計書 | AP4: =MID(CELL("filename",A1),FIND("]",CELL("filename",A1))+1,255) -> SC3102
B7: ■売上部門タブ画面のイメージ
AX21: レジ別単品別売上点検
AX23: レジ別時間売上
B43: ■画面項目定義
B45: 画面項目ID | D45: 項目 | K45: タイプ | N45: I/O | O45: 多言語 | P45: 出力 | AR45: インプット | BC45: 備考
P46: マッピングデータ | X46: 初期値 | AA46: 表示コントロール | AI46: Control enable | AR46: 必須 | AS46: 数字 | AT46: 桁 | AU46: マッピングデータ
P47: API名 | T47: 項目 | AU47: API名 | AY47: 項目
B48: 0 | D48: 画面タイトル | K48: テキスト | N48: － | O48: ● | P48: － | T48: － | X48: レジ別速報／日報 (詳細） | AA48: ー | AI48: － | AR48: － | AS48: ー | AT48: ー | AU48: － | AY48: ー | BC48: イベントID：SC3102-01をご参照ください。
B49: 検索条件ビュー
B50: =B48+1 -> 1 | D50: 営業種別（タイトル） | K50: テキスト | N50: － | O50: ● | P50: － | T50: － | X50: 営業種別* | AA50: ー | AI50: ー | AR50: － | AS50: ー | AT50: ー | AU50: － | AY50: ー
B51: =B50+1 -> 2 | D51: 営業種別（値） | K51: ラジオボタン | N51: I | O51: ● | P51: － | T51: － | X51: 速報 | AA51: 以下の3つオプションがある。 ・速報 ・日報 ・月報 | AI51: 対象店舗が選択された場合は有効になる。 | AR51: ● | AS51: ー | AT51: ー | AU51: － | AY51: ー
B52: =B51+1 -> 3 | D52: 営業日（タイトル） | K52: テキスト | N52: － | O52: ● | P52: － | T52: － | X52: 営業日* | AA52: ・項目8が速報又は日報を選択している場合、「営業日」を表示する。 ・項目8が月報を選択している場合、営業月を表示する。 | AI52: ー | AR52: － | AS52: ー | AT52: ー | AU52: － | AY52: ー
B53: 4.1 | D53: 営業日（値） | K53: Date picker | N53: I | O53: － | P53: － | T53: － | X53: 当日 | AA53: ・項目8が速報又は日報を選択している場合に表示する。 | AI53: 対象店舗が選択され、営業種別 = 日報の場合に有効になる。 | AR53: ● | AS53: － | AT53: ー | AU53: － | AY53: ー
B54: 4.2 | D54: 営業月（値） | K54: ドロップダウン | N54: I | O54: － | P54: － | T54: － | X54: 当月 | AA54: ・項目8が月報を選択されている場合、「当月」と「前月」の2つの値を持つドロップダウンを表示する。 | AI54: 対象店舗が選択された場合は有効になる。 | AR54: － | AS54: － | AT54: ー | AU54: － | AY54: ー
B55: 5 | D55: レジ番号（タイトル） | K55: テキスト | N55: － | O55: ● | P55: － | T55: － | X55: レジ* | AA55: ー | AI55: － | AR55: － | AS55: ー | AT55: ー | AU55: － | AY55: ー
B56: =B55+1 -> 6 | D56: レジ番号（値） | K56: テキスト | N56: O | O56: － | P56: － | T56: － | X56: － | AA56: ー | AI56: ー | AR56: － | AS56: ー | AT56: ー | AU56: － | AY56: ー | BC56: 形式：コード：名称
B57: =B56+1 -> 7 | D57: 検索 | K57: ボタン | N57: I | O57: ● | P57: － | T57: － | X57: 検索 | AA57: ー | AI57: ー | AR57: － | AS57: － | AT57: ー | AU57: － | AY57: ー | BC57: イベントID：SC3102-02
B58: 14 | D58: 印刷 | K58: ボタン | N58: I | O58: ● | P58: － | T58: － | X58: － | AA58: ー | AI58: ー | AR58: － | AS58: － | AT58: ー | AU58: － | AY58: ー | BC58: イベントID：SC3102-03
B59: 部門売上タブ
B60: =B57+1 -> 8 | D60: 売上部門タブ（タイトル） | K60: テキスト | N60: ー | O60: ● | P60: － | T60: － | X60: 売上部門 | AA60: ー | AI60: ー | AR60: － | AS60: － | AT60: ー | AU60: － | AY60: ー | BC60: イベントID：SC3102-04
B61: =B60+1 -> 9 | D61: 売上部門ビュー（タイトル） | K61: テキスト | N61: － | O61: ● | P61: － | T61: － | X61: 部門売上 | AA61: ー | AI61: ー | AR61: － | AS61: － | AT61: ー | AU61: － | AY61: ー
B62: =B61+1 -> 10 | D62: 金額（列名） | K62: テキスト | N62: ー | O62: ● | P62: － | T62: － | X62: 金額 | AA62: ー | AI62: ー
B63: =B62+1 -> 11 | D63: 点数（件数）（列名） | K63: テキスト | N63: ー | O63: ● | P63: － | T63: － | X63: 点数(件数) | AA63: ー | AI63: ー | AR63: － | AS63: － | AT63: ー | AU63: － | AY63: ー
B64: =B63+1 -> 12 | D64: 当月度累計金額（列名） | K64: テキスト | N64: ー | O64: ● | P64: － | T64: － | X64: 当月度累計金額 | AA64: ー | AI64: ー | AR64: － | AS64: － | AT64: ー | AU64: － | AY64: ー
B65: =B64+1 -> 13 | D65: 当月度累計点数（件数）（列名） | K65: テキスト | N65: － | O65: ● | P65: － | T65: － | X65: 当月度累計点数(件数) | AA65: ー | AI65: ー | AR65: － | AS65: － | AT65: ー | AU65: － | AY65: ー
B66: 15.1 | D66: 部門売上（行名） | K66: テキスト | N66: ー | O66: ● | P66: － | T66: － | X66: 部門売上 | AA66: ー | AI66: ー | AR66: － | AS66: ー | AT66: ー | AU66: － | AY66: ー
B67: 15.2 | D67: 金額（値） | K67: テキスト | N67: O | O67: － | P67: － | T67: － | X67: － | AA67: ー | AI67: ー | AR67: － | AS67: ー | AT67: ー | AU67: － | AY67: ー
B68: 15.3 | D68: 点数（値） | K68: テキスト | N68: O | O68: － | P68: － | T68: － | X68: － | AA68: ー | AI68: ー | AR68: － | AS68: ー | AT68: ー | AU68: － | AY68: ー
B69: 15.4 | D69: 当月度累計金額（列名） | K69: テキスト | N69: O | O69: － | P69: － | T69: － | X69: － | AA69: ー | AI69: ー | AR69: － | AS69: － | AT69: ー | AU69: － | AY69: ー
B70: 15.5 | D70: 当月度累計点数（値） | K70: テキスト | N70: O | O70: － | P70: － | T70: － | X70: － | AA70: ー | AI70: ー | AR70: － | AS70: － | AT70: ー | AU70: － | AY70: ー
B71: =B65+3 -> 16 | D71: 売上外部門（行名） | K71: テキスト | N71: ー | O71: ● | P71: － | T71: － | X71: 売上外部門 | AA71: ー | AI71: ー | AR71: － | AS71: － | AT71: ー | AU71: － | AY71: ー
B72: =B71+1 -> 17 | D72: 部門計（行名） | K72: テキスト | N72: － | O72: ● | P72: － | T72: － | X72: 部門計 | AA72: ー | AI72: ー | AR72: － | AS72: － | AT72: ー | AU72: － | AY72: ー
B73: =B72+1 -> 18 | D73: 総売上 | K73: ビュー | N73: O | O73: － | P73: － | T73: － | X73: － | AA73: ー | AI73: ー | AR73: － | AS73: － | AT73: ー | AU73: － | AY73: ー
B74: =B73+1 -> 19 | D74: 金額（列名） | K74: テキスト | N74: － | O74: ● | P74: － | T74: － | X74: 金額 | AA74: ー | AI74: ー | AR74: － | AS74: － | AT74: ー | AU74: － | AY74: ー
B75: =B74+1 -> 20 | D75: 点数(件数)（列名） | K75: テキスト | N75: － | O75: ● | P75: － | T75: － | X75: 点数(件数) | AA75: ー | AI75: ー | AR75: － | AS75: － | AT75: ー | AU75: － | AY75: ー
B76: =B75+1 -> 21 | D76: 客故（列名） | K76: テキスト | N76: － | O76: ● | P76: － | T76: － | X76: 客故 | AA76: ー | AI76: ー | AR76: － | AS76: － | AT76: ー | AU76: － | AY76: ー
B77: =B76+1 -> 22 | D77: 点単価（列名） | K77: テキスト | N77: － | O77: ● | P77: － | T77: － | X77: 点単価 | AA77: ー | AI77: ー | AR77: － | AS77: － | AT77: ー | AU77: － | AY77: ー
...
