Workbook

Sheet 表紙
A1: システム名 | K1: システム種別 | W1: 詳細設計書 | AP1: 作成者 | AT1: 作成日 | AY1: 更新者 | BC1: 更新日 | BH1: 版数
A2: POSサーバー | K2: POSサーバ | AP2: =改訂履歴!$H$11 -> AnhDD | AT2: =改訂履歴!$B$11 -> 45515 | AY2: =LOOKUP(2,1/(改訂履歴!H11:H30000<>""),改訂履歴!H11:H30000) -> HueDT | BC2: =LOOKUP(2,1/(改訂履歴!B11:B30000<>""),改訂履歴!B11:B30000) -> 45600 | BH2: =LOOKUP(2,1/(改訂履歴!O11:O30000<>""),改訂履歴!O11:O30000) -> 0.2
A4: 機能カテゴリ | H4: APX004 | U4: 項目 | Z4: API設計書 | AP4: {=RIGHT(CELL("filename",$A$1),LEN(CELL("filename",$A$1))-FIND("]",CELL("filename",$A$1)))} -> 表紙
L16: POSサーバーの詳細設計書
L24: =K2&"/"&H4&"/"&Z4 -> POSサーバ/APX004/API設計書
Q44: 承認日 | AA44: 承認者 | AQ44: 版数

Sheet 改訂履歴
A1: システム名 | K1: システム種別 | W1: =IF(表紙!W1="","",表紙!W1) -> 詳細設計書 | AP1: 作成者 | AT1: 作成日 | AY1: 更新者 | BC1: 更新日 | BH1: 版数
A2: =IF(表紙!A2="","",表紙!A2) -> POSサーバー | K2: =IF(表紙!K2="","",表紙!K2) -> POSサーバ | AP2: =IF(表紙!AP2="","",表紙!AP2) -> AnhDD | AT2: =IF(表紙!AT2="","",表紙!AT2) -> 45515 | AY2: =IF(表紙!AY2="","",表紙!AY2) -> HueDT | BC2: =IF(表紙!BC2="","",表紙!BC2) -> 45600 | BH2: =IF(表紙!BH2="","",表紙!BH2) -> 0.2
A4: 機能カテゴリ | H4: =IF(表紙!H4="","",表紙!H4) -> APX004 | U4: 項目 | Z4: =IF(表紙!Z4="","",表紙!Z4) -> API設計書 | AP4: {=RIGHT(CELL("filename",$A$1),LEN(CELL("filename",$A$1))-FIND("]",CELL("filename",$A$1)))} -> 改訂履歴
B8: ■改訂履歴
B10: 更新日 | H10: 更新者 | O10: 版数 | S10: 更新内容 | AX10: 承認日 | BD10: 承認者
B11: 45515 | H11: AnhDD | O11: 0.1 | S11: 新規
B13: 45600 | H13: HueDT | O13: 0.2 | S13: レスポンス情報を追加する。

Sheet 処理フロー凡例
A1: システム名 | K1: システム種別 | W1: =IF(表紙!W1="","",表紙!W1) -> 詳細設計書 | AP1: 作成者 | AT1: 作成日 | AY1: 更新者 | BC1: 更新日 | BH1: 版数
A2: =IF(表紙!A2="","",表紙!A2) -> POSサーバー | K2: =IF(表紙!K2="","",表紙!K2) -> POSサーバ | AP2: =IF(表紙!AP2="","",表紙!AP2) -> AnhDD | AT2: =IF(表紙!AT2="","",表紙!AT2) -> 45515 | AY2: =IF(表紙!AY2="","",表紙!AY2) -> HueDT | BC2: =IF(表紙!BC2="","",表紙!BC2) -> 45600 | BH2: =IF(表紙!BH2="","",表紙!BH2) -> 0.2
A4: 機能カテゴリ | H4: =IF(表紙!H4="","",表紙!H4) -> APX004 | U4: 項目 | Z4: =IF(表紙!Z4="","",表紙!Z4) -> API設計書 | AP4: =MID(CELL("filename",A1),FIND("]",CELL("filename",A1))+1,255) -> 処理フロー凡例
B7: ●API処理フロー

Sheet APX004
A1: システム名 | K1: システム種別 | W1: =IF(表紙!W1="","",表紙!W1) -> 詳細設計書 | AP1: 作成者 | AT1: 作成日 | AY1: 更新者 | BC1: 更新日 | BH1: 版数
A2: =IF(表紙!A2="","",表紙!A2) -> POSサーバー | K2: =IF(表紙!K2="","",表紙!K2) -> POSサーバ | AP2: =IF(表紙!AP2="","",表紙!AP2) -> AnhDD | AT2: =IF(表紙!AT2="","",表紙!AT2) -> 45515 | AY2: =IF(表紙!AY2="","",表紙!AY2) -> HueDT | BC2: =IF(表紙!BC2="","",表紙!BC2) -> 45600 | BH2: =IF(表紙!BH2="","",表紙!BH2) -> 0.2
A4: 機能カテゴリ | H4: =IF(表紙!H4="","",表紙!H4) -> APX004 | U4: 項目 | Z4: =IF(表紙!Z4="","",表紙!Z4) -> API設計書 | AP4: =MID(CELL("filename",A1),FIND("]",CELL("filename",A1))+1,255) -> APX004
B7: 1. 概要
C9: ユーザーが操作権限を持つ店舗一覧を取得する。
B11: 2. リクエスト
C13: 2.1 Request URL
C15: No. | E15: URL | AG15: HTTPメソッド | AQ15: 備考
C16: 1 | E16: api/v1/users/stores | AG16: GET | AQ16: -
C18: 2. 2 Request Header
C20: No. | E20: ヘッダー | L20: 必須 | O20: 型 | S20: デフォルト値 | Z20: 項目説明 | AQ20: 備考
C21: 1 | E21: Accept | L21: - | O21: String | S21: - | Z21: Accept | AQ21: サーバーが返却できるデータ種類情報を説明する。
C22: 2 | E22: Content-Type | L22: - | O22: String | S22: - | Z22: Content-Type | AQ22: 送信リクエストの本文情報のタイプを定義する。例: application/json, mutilpart/form-data. 転送データのタイプによって、content-typeが必須又は必須ではない。例： ・入力がjsonの場合、content-typeが必須であり、application/jsonの値を受け取る。
C25: 3 | E25: User-Agent | L25: - | O25: String | S25: - | Z25: User-Agent | AQ25: サーバーを呼び出すクライアントのアプリケーション/ソフトウェア/ブラウザを定義する。
C26: 4 | E26: Accept-Encoding | L26: - | O26: String | S26: - | Z26: Accept-Encoding | AQ26: データ暗号化アルゴリズムを定義する。サーバーから受信したデータに使用できる： zip、gzip、png、gif等
C29: 2.3 Query Parameter/ path parameter
D31: NA
C33: 2.4 Request Body
C35: No. | E35: パラメータ | L35: 必須 | O35: 型 | S35: デフォルト値 | Z35: 項目説明 | AQ35: 備考
B41: 3. レスポンス
C43: 3.1. 正常の場合のレスポンスフォーマット
C45: No. | E45: JSON name | L45: 型 | S45: 項目説明 | AC45: 備考
C46: 1 | E46: items | L46: List<Object> | S46: ユーザーが操作権限を持つ店舗一覧
C47: =C46+1 -> 2 | E47: store_code | L47: string | S47: UserStore.StoreCode | AC47: UserStore.StoreCode
C48: 3 | E48: store_name | L48: string | S48: MStore.TenName | AC48: StoreMaster.Name
C49: 4 | E49: short_name | L49: String | S49: MStore.TenShortNm | AC49: 店舗略称
C50: 5 | E50: post_code | L50: String | S50: MStore.PostCd | AC50: 郵便番号
C51: 6 | E51: address | L51: String | S51: MStore.Address1-MStore.Address2-MStore.Address3 | AC51: 店舗のアドレス
C52: 7 | E52: phone_number | L52: String | S52: MStore.TelNum | AC52: 店舗の電話番号
C53: 8 | E53: start_hours | L53: String | S53: MStore.StartHours | AC53: 開店時間 HH:mm
C54: 9 | E54: end_hours | L54: String | S54: MStore.EndHours | AC54: 閉店時間 HH:mm
C55: 10 | E55: business_type_code | L55: String | S55: MStore.BusinessTypeCode | AC55: 店舗分類
C56: 11 | E56: default_point | L56: Int | S56: MStore.DefaultPoint | AC56: 店舗の基本ポイント設定
C57: ※サンプル
D60: {
E61: "items": [
F62: {
G63: "store_code": "09176",
G64: "store_name": "湖北店"
G65: "short_name": "検証店”,
...

Sheet 処理フロー
A1: システム名 | K1: システム種別 | W1: =IF(表紙!W1="","",表紙!W1) -> 詳細設計書 | AP1: 作成者 | AT1: 作成日 | AY1: 更新者 | BC1: 更新日 | BH1: 版数
A2: =IF(表紙!A2="","",表紙!A2) -> POSサーバー | K2: =IF(表紙!K2="","",表紙!K2) -> POSサーバ | AP2: =IF(表紙!AP2="","",表紙!AP2) -> AnhDD | AT2: =IF(表紙!AT2="","",表紙!AT2) -> 45515 | AY2: =IF(表紙!AY2="","",表紙!AY2) -> HueDT | BC2: =IF(表紙!BC2="","",表紙!BC2) -> 45600 | BH2: =IF(表紙!BH2="","",表紙!BH2) -> 0.2
A4: 機能カテゴリ | H4: =IF(表紙!H4="","",表紙!H4) -> APX004 | U4: 項目 | Z4: =IF(表紙!Z4="","",表紙!Z4) -> API設計書 | AP4: =MID(CELL("filename",A1),FIND("]",CELL("filename",A1))+1,255) -> 処理フロー

Sheet テンプレート
A1: システム名 | K1: システム種別 | W1: =IF(表紙!W1="","",表紙!W1) -> 詳細設計書 | AP1: 作成者 | AT1: 作成日 | AY1: 更新者 | BC1: 更新日 | BH1: 版数
A2: =IF(表紙!A2="","",表紙!A2) -> POSサーバー | K2: =IF(表紙!K2="","",表紙!K2) -> POSサーバ | AP2: =IF(表紙!AP2="","",表紙!AP2) -> AnhDD | AT2: =IF(表紙!AT2="","",表紙!AT2) -> 45515 | AY2: =IF(表紙!AY2="","",表紙!AY2) -> HueDT | BC2: =IF(表紙!BC2="","",表紙!BC2) -> 45600 | BH2: =IF(表紙!BH2="","",表紙!BH2) -> 0.2
A4: 機能カテゴリ | H4: =IF(表紙!H4="","",表紙!H4) -> APX004 | U4: 項目 | Z4: =IF(表紙!Z4="","",表紙!Z4) -> API設計書 | AP4: =MID(CELL("filename",A1),FIND("]",CELL("filename",A1))+1,255) -> テンプレート
