Workbook

Sheet 表紙
A1: システム名 | K1: システム種別 | W1: 詳細設計書 | AP1: 作成者 | AT1: 作成日 | AY1: 更新者 | BC1: 更新日 | BH1: 版数
A2: POSサーバー | K2: POSサーバ | AP2: =改訂履歴!$H$11 -> LoiLV | AT2: =改訂履歴!$B$11 -> 45468 | AY2: =LOOKUP(2,1/(改訂履歴!H11:H30000<>""),改訂履歴!H11:H30000) -> AnhDD | BC2: =LOOKUP(2,1/(改訂履歴!B11:B30000<>""),改訂履歴!B11:B30000) -> 45515 | BH2: =LOOKUP(2,1/(改訂履歴!O11:O30000<>""),改訂履歴!O11:O30000) -> 0.12
A4: 機能カテゴリ | H4: APX002 | U4: 項目 | Z4: API設計書 | AP4: {=RIGHT(CELL("filename",$A$1),LEN(CELL("filename",$A$1))-FIND("]",CELL("filename",$A$1)))} -> 表紙
L16: POSサーバーの詳細設計書
L24: =K2&"/"&H4&"/"&Z4 -> POSサーバ/APX002/API設計書
Q44: 承認日 | AA44: 承認者 | AQ44: 版数

Sheet 改訂履歴
A1: システム名 | K1: システム種別 | W1: =IF(表紙!W1="","",表紙!W1) -> 詳細設計書 | AP1: 作成者 | AT1: 作成日 | AY1: 更新者 | BC1: 更新日 | BH1: 版数
A2: =IF(表紙!A2="","",表紙!A2) -> POSサーバー | K2: =IF(表紙!K2="","",表紙!K2) -> POSサーバ | AP2: =IF(表紙!AP2="","",表紙!AP2) -> LoiLV | AT2: =IF(表紙!AT2="","",表紙!AT2) -> 45468 | AY2: =IF(表紙!AY2="","",表紙!AY2) -> AnhDD | BC2: =IF(表紙!BC2="","",表紙!BC2) -> 45515 | BH2: =IF(表紙!BH2="","",表紙!BH2) -> 0.12
A4: 機能カテゴリー | H4: =IF(表紙!H4="","",表紙!H4) -> APX002 | U4: 項目 | Z4: =IF(表紙!Z4="","",表紙!Z4) -> API設計書 | AP4: {=RIGHT(CELL("filename",$A$1),LEN(CELL("filename",$A$1))-FIND("]",CELL("filename",$A$1)))} -> 改訂履歴
B8: ■改訂履歴
B10: 更新日 | H10: 更新者 | O10: 版数 | S10: 更新内容 | AX10: 承認日 | BD10: 承認者
B11: 45468 | H11: LoiLV | O11: 0.1 | S11: 新規作成
B13: 45476 | H13: LoiLV | O13: 0.11 | S13: レスポンス成功の更新
B15: 45515 | H15: AnhDD | O15: 0.12 | S15: APX002
S16: トークンアクセスの有効期限を修正する ユーザーから返された情報を追加する

Sheet 処理フロー凡例
A1: システム名 | K1: システム種別 | W1: =IF(表紙!W1="","",表紙!W1) -> 詳細設計書 | AP1: 作成者 | AT1: 作成日 | AY1: 更新者 | BC1: 更新日 | BH1: 版数
A2: =IF(表紙!A2="","",表紙!A2) -> POSサーバー | K2: =IF(表紙!K2="","",表紙!K2) -> POSサーバ | AP2: =IF(表紙!AP2="","",表紙!AP2) -> LoiLV | AT2: =IF(表紙!AT2="","",表紙!AT2) -> 45468 | AY2: =IF(表紙!AY2="","",表紙!AY2) -> AnhDD | BC2: =IF(表紙!BC2="","",表紙!BC2) -> 45515 | BH2: =IF(表紙!BH2="","",表紙!BH2) -> 0.12
A4: 機能カテゴリ | H4: =IF(表紙!H4="","",表紙!H4) -> APX002 | U4: 項目 | Z4: =IF(表紙!Z4="","",表紙!Z4) -> API設計書 | AP4: =MID(CELL("filename",A1),FIND("]",CELL("filename",A1))+1,255) -> 処理フロー凡例
B7: ●API処理フロー

Sheet APX002
A1: システム名 | K1: システム種別 | W1: =IF(表紙!W1="","",表紙!W1) -> 詳細設計書 | AP1: 作成者 | AT1: 作成日 | AY1: 更新者 | BC1: 更新日 | BH1: 版数
A2: =IF(表紙!A2="","",表紙!A2) -> POSサーバー | K2: =IF(表紙!K2="","",表紙!K2) -> POSサーバ | AP2: =IF(表紙!AP2="","",表紙!AP2) -> LoiLV | AT2: =IF(表紙!AT2="","",表紙!AT2) -> 45468 | AY2: =IF(表紙!AY2="","",表紙!AY2) -> AnhDD | BC2: =IF(表紙!BC2="","",表紙!BC2) -> 45515 | BH2: =IF(表紙!BH2="","",表紙!BH2) -> 0.12
A4: 機能カテゴリ | H4: =IF(表紙!H4="","",表紙!H4) -> APX002 | U4: 項目 | Z4: =IF(表紙!Z4="","",表紙!Z4) -> API設計書 | AP4: =MID(CELL("filename",A1),FIND("]",CELL("filename",A1))+1,255) -> APX002
B7: 1. 概要
C9: トークンアクセス対象APIが401エラーになっている場合、新しいトークンをリフレッシュする。
B11: 2. リクエスト
C13: 2.1 Request URL
C15: No. | E15: URL | AG15: HTTPメソッド | AQ15: 備考
C16: 1 | E16: api/v1/auth/refresh | AG16: POST | AQ16: -
C18: 2. 2 Request Header
C20: No. | E20: ヘッダー | L20: 必須 | O20: 型 | S20: デフォルト値 | Z20: 項目説明 | AQ20: 備考
C21: 1 | E21: Refresh-Token | L21: ○ | O21: String | S21: - | Z21: Refresh-Token | AQ21: -
C22: 2 | E22: Accept | L22: - | O22: String | S22: - | Z22: Accept | AQ22: サーバーが返却できるデータ種類情報を説明する。
C23: 3 | E23: Content-Type | L23: - | O23: String | S23: - | Z23: Content-Type | AQ23: 送信リクエストの本文情報のタイプを定義する。例: application/json, mutilpart/form-data. 転送データのタイプによって、content-typeが必須又は必須ではない。例： ・入力がjsonの場合、content-typeが必須であり、application/jsonの値を受け取る。
C26: 4 | E26: User-Agent | L26: - | O26: String | S26: - | Z26: User-Agent | AQ26: サーバーを呼び出すクライアントのアプリケーション/ソフトウェア/ブラウザを定義する。
C27: 5 | E27: Accept-Encoding | L27: - | O27: String | S27: - | Z27: Accept-Encoding | AQ27: データ暗号化アルゴリズムを定義する。サーバーから受信したデータに使用できる： zip、gzip、png、gif等
C30: 2.3 Query Parameter/ path parameter
D32: NA
C34: 2.4 Request Body
D36: NA
B38: 3. レスポンス
C40: 3.1. 正常の場合のレスポンスフォーマット
C42: No. | E42: JSON name | L42: 型 | S42: 項目説明 | AC42: 備考
C43: 1 | E43: access_token | L43: string | S43: access token | AC43: 有効期限： 5分
C44: =C43+1 -> 2 | E44: refresh_token | L44: string | S44: refresh token | AC44: 有効期限：1日
C45: 3 | E45: user_detail | L45: Object | S45: ユーザー詳細情報 | AC45: -
C46: =C45+1 -> 4 | E46: user_name | L46: string | S46: ユーザーログイン名 | AC46: -
C47: =C46+1 -> 5 | E47: name | L47: string | S47: 表示に使用されるユーザー名 | AC47: -
C48: =C47+1 -> 6 | E48: role_code | L48: string | S48: ユーザーロールコード | AC48: 3つのユーザーロールがある： ・00: System administrator (企業の全て店舗にアクセスする権限) ・01 : Headquarters user (複数の店舗にアクセスする権限) ・02 : Store user (1つの店舗のみにアクセスする権限)
C49: =C48+1 -> 7 | E49: role_name | L49: string | S49: ユーザーロール名 | AC49: -
C50: =C49+1 -> 8 | E50: company_code | L50: string | S50: 会社コード | AC50: 100: カスミ、800：いなげや
C51: =C50+1 -> 9 | E51: company_name | L51: string | S51: 会社名 | AC51: 100：カスミ、800：いなげや Company.Name
C52: =C51+1 -> 10 | E52: store_code | L52: string | S52: 店舗コード | AC52: StoreMaster.Code
C53: =C52+1 -> 11 | E53: store_name | L53: string | S53: 店舗名 | AC53: StoreMaster.Name
C54: =C53+1 -> 12 | E54: permissions | L54: List<Object> | S54: アクセス可能権限一覧 | AC54: -
C55: =C54+1 -> 13 | E55: code | L55: string | S55: 権限コード | AC55: 01 - 99: 01～99の機能に該当する。
C56: =C55+1 -> 14 | E56: alias_name | L56: string | S56: 権限エイリアス名称 | AC56: 01～99の機能のエイリアス名称
C58: ※サンプル
D61: {
E62: "access_token": "eyJhbGciOiJIUzI1NiIsInR5cCI6IkpXVCJ9.eyJpc3MiOiJodHRwczovL2V4YW1wbGUuYXV0aDAuY29tLyIsImF1ZCI6Imh0dHBzOi8vYXBpLmV4YW1wbGUuY29tL2NhbGFuZGFyL3YxLyIsInN1YiI6InVzcl8xMjMiLCJpYXQiOjE0NTg3ODU3OTYsImV4cCI6MTQ1ODg3MjE5Nn0.CA7eaHjIHz5NxeIJoFK9krqaeZrPLwmMmgI_XiQiIkQ",
...

Sheet 処理フロー
A1: システム名 | K1: システム種別 | W1: =IF(表紙!W1="","",表紙!W1) -> 詳細設計書 | AP1: 作成者 | AT1: 作成日 | AY1: 更新者 | BC1: 更新日 | BH1: 版数
A2: =IF(表紙!A2="","",表紙!A2) -> POSサーバー | K2: =IF(表紙!K2="","",表紙!K2) -> POSサーバ | AP2: =IF(表紙!AP2="","",表紙!AP2) -> LoiLV | AT2: =IF(表紙!AT2="","",表紙!AT2) -> 45468 | AY2: =IF(表紙!AY2="","",表紙!AY2) -> AnhDD | BC2: =IF(表紙!BC2="","",表紙!BC2) -> 45515 | BH2: =IF(表紙!BH2="","",表紙!BH2) -> 0.12
A4: 機能カテゴリ | H4: =IF(表紙!H4="","",表紙!H4) -> APX002 | U4: 項目 | Z4: =IF(表紙!Z4="","",表紙!Z4) -> API設計書 | AP4: =MID(CELL("filename",A1),FIND("]",CELL("filename",A1))+1,255) -> 処理フロー

Sheet テンプレート
A1: システム名 | K1: システム種別 | W1: =IF(表紙!W1="","",表紙!W1) -> 詳細設計書 | AP1: 作成者 | AT1: 作成日 | AY1: 更新者 | BC1: 更新日 | BH1: 版数
A2: =IF(表紙!A2="","",表紙!A2) -> POSサーバー | K2: =IF(表紙!K2="","",表紙!K2) -> POSサーバ | AP2: =IF(表紙!AP2="","",表紙!AP2) -> LoiLV | AT2: =IF(表紙!AT2="","",表紙!AT2) -> 45468 | AY2: =IF(表紙!AY2="","",表紙!AY2) -> AnhDD | BC2: =IF(表紙!BC2="","",表紙!BC2) -> 45515 | BH2: =IF(表紙!BH2="","",表紙!BH2) -> 0.12
A4: 機能カテゴリ | H4: =IF(表紙!H4="","",表紙!H4) -> APX002 | U4: 項目 | Z4: =IF(表紙!Z4="","",表紙!Z4) -> API設計書 | AP4: =MID(CELL("filename",A1),FIND("]",CELL("filename",A1))+1,255) -> テンプレート
