Workbook

Sheet 表紙
A1: システム名 | K1: システム種別 | W1: 詳細設計書 | AP1: 作成者 | AT1: 作成日 | AY1: 更新者 | BC1: 更新日 | BH1: 版数
A2: POSサーバー | K2: POSサーバ | AP2: =改訂履歴!$H$11 -> DuNT | AT2: =改訂履歴!$B$11 -> 45540 | AY2: =LOOKUP(2,1/(改訂履歴!H11:H30000<>""),改訂履歴!H11:H30000) -> DuNT | BC2: =LOOKUP(2,1/(改訂履歴!B11:B30000<>""),改訂履歴!B11:B30000) -> 45540 | BH2: =LOOKUP(2,1/(改訂履歴!O11:O30000<>""),改訂履歴!O11:O30000) -> 0.1
A4: 機能カテゴリ | H4: 16_保留・保留解除 | U4: 項目 | Z4: 機能設計書 | AP4: {=RIGHT(CELL("filename",$A$1),LEN(CELL("filename",$A$1))-FIND("]",CELL("filename",$A$1)))} -> 表紙
L16: POSサーバーの詳細設計書
L24: =K2&"/"&H4&"/"&Z4 -> POSサーバ/16_保留・保留解除/機能設計書
Q44: 承認日 | AA44: 承認者 | AQ44: 版数

Sheet 改訂履歴
A1: システム名 | K1: システム種別 | W1: =IF(表紙!W1="","",表紙!W1) -> 詳細設計書 | AP1: 作成者 | AT1: 作成日 | AY1: 更新者 | BC1: 更新日 | BH1: 版数
A2: =IF(表紙!A2="","",表紙!A2) -> POSサーバー | K2: =IF(表紙!K2="","",表紙!K2) -> POSサーバ | AP2: =IF(表紙!AP2="","",表紙!AP2) -> DuNT | AT2: =IF(表紙!AT2="","",表紙!AT2) -> 45540 | AY2: =IF(表紙!AY2="","",表紙!AY2) -> DuNT | BC2: =IF(表紙!BC2="","",表紙!BC2) -> 45540 | BH2: =IF(表紙!BH2="","",表紙!BH2) -> 0.1
A4: 機能カテゴリー | H4: =IF(表紙!H4="","",表紙!H4) -> 16_保留・保留解除 | U4: 項目 | Z4: =IF(表紙!Z4="","",表紙!Z4) -> 機能設計書 | AP4: {=RIGHT(CELL("filename",$A$1),LEN(CELL("filename",$A$1))-FIND("]",CELL("filename",$A$1)))} -> 改訂履歴
B8: ■改訂履歴
B10: 更新日 | H10: 更新者 | O10: 版数 | S10: 更新内容 | AX10: 承認日 | BD10: 承認者
B11: 45540 | H11: DuNT | O11: 0.1 | S11: 新規

Sheet SC1601
A1: システム名 | K1: システム種別 | W1: =IF(表紙!W1="","",表紙!W1) -> 詳細設計書 | AP1: 作成者 | AT1: 作成日 | AY1: 更新者 | BC1: 更新日 | BH1: 版数
A2: =IF(表紙!A2="","",表紙!A2) -> POSサーバー | K2: =IF(表紙!K2="","",表紙!K2) -> POSサーバ | AP2: =IF(表紙!AP2="","",表紙!AP2) -> DuNT | AT2: =IF(表紙!AT2="","",表紙!AT2) -> 45540 | AY2: =IF(表紙!AY2="","",表紙!AY2) -> DuNT | BC2: =IF(表紙!BC2="","",表紙!BC2) -> 45540 | BH2: =IF(表紙!BH2="","",表紙!BH2) -> 0.1
A4: 機能カテゴリ | H4: =IF(表紙!H4="","",表紙!H4) -> 16_保留・保留解除 | U4: 項目 | Z4: =IF(表紙!Z4="","",表紙!Z4) -> 機能設計書 | AP4: =MID(CELL("filename",A1),FIND("]",CELL("filename",A1))+1,255) -> SC1601
A7: ■機能説明
A9: 画面ID | E9: SC1601 | O9: 画面名 | U9: 保留・保留解除画面
A11: イベントID | G11: SC1601-01 | M11: 画面初期化
A12: インプット | M12: 処理概要 | AU12: 出力 | BF12: 参照情報
BF14: 20_画面設計_16_保留・保留解除.xlsx
N15: 1. 20_画面設計_16_保留・保留解除.xlsxの説明に従って画面項目を初期化する。
A23: イベントID | G23: SC1601-02 | M23: 保留・保留解除の検索
A24: インプット | M24: 処理概要 | AU24: 出力 | BF24: 参照情報
BF26: 20_画面設計_16_保留・保留解除.xlsx
N27: 1. 検索条件に基づいて保留情報を検索する。
O29: 1.1 AP1601API呼出処理を実行する。
P30: APIのパラメータ | W30: パラメータの値
P31: selected_stores | W31: 選択されている対象店舗一覧
P32: type | W32: 検索タイプ：0:全て、1:保留、2:保留解除
P33: receipt_no | W33: SC1601画面の検索エリアに入力されたレシートNo
P34: cash_register no | W34: SC1601画面の検索エリアに入力されたレジNo
P35: start_date_time | W35: SC1601画面の検索エリアに入力された開始日時
P36: end_date_time | W36: SC1601画面の検索エリアに入力された終了日時
O38: 1.2 返却された結果情報
P39: ①．成功した場合：
Q40: 返却された結果
Q41: 1. status_code | AB41: 200 (OK)
Q42: 2. message | AB42: ブランク
Q43: 3. data | AB43: 保留・保留解除一覧
P45: 20_画面設計_16_保留・保留解除.xlsxの説明に従って画面にデータをマッピングする。
P47: ②．エラーの場合、以下のように実行する。
Q48: 他のエラーの場合、APIエラーの共通表示処理を実行する。
A53: イベントID | G53: SC1601-03 | M53: 全選択
A54: インプット | M54: 処理概要 | AU54: 出力 | BF54: 参照情報
N56: 印刷チェックボックスにチェックを入れた時： | BF56: 20_画面設計_16_保留・保留解除.xlsx
O57: ・選択されていない場合：一覧の全てのアイテムを選択し、同時に「印刷」チェックボックスも選択する。
O58: ・選択されている場合：一覧の全てのアイテムを選択解除し、同時に「印刷」チェックボックスも選択解除する。
N59: また、任意のアイテムのチェックボックスにチェックを入れた時：
O60: ・全てのアイテムが選択されている場合、「印刷」チェックボックスが選択状態に切り替わる。
O61: ・1つのアイテムが選択解除されている場合、「印刷」チェックボックスが選択解除状態に切り替わる。
A66: イベントID | G66: SC1601-04 | M66: 検索結果と検索条件をクリアする。
A67: インプット | M67: 処理概要 | AU67: 出力 | BF67: 参照情報
...

Sheet テンプレート
A1: システム名 | K1: システム種別 | W1: =IF(表紙!W1="","",表紙!W1) -> 詳細設計書 | AP1: 作成者 | AT1: 作成日 | AY1: 更新者 | BC1: 更新日 | BH1: 版数
A2: =IF(表紙!A2="","",表紙!A2) -> POSサーバー | K2: =IF(表紙!K2="","",表紙!K2) -> POSサーバ | AP2: =IF(表紙!AP2="","",表紙!AP2) -> DuNT | AT2: =IF(表紙!AT2="","",表紙!AT2) -> 45540 | AY2: =IF(表紙!AY2="","",表紙!AY2) -> DuNT | BC2: =IF(表紙!BC2="","",表紙!BC2) -> 45540 | BH2: =IF(表紙!BH2="","",表紙!BH2) -> 0.1
A4: 機能カテゴリ | H4: =IF(表紙!H4="","",表紙!H4) -> 16_保留・保留解除 | U4: 項目 | Z4: =IF(表紙!Z4="","",表紙!Z4) -> 機能設計書 | AP4: =MID(CELL("filename",A1),FIND("]",CELL("filename",A1))+1,255) -> テンプレート
A7: ■機能説明
A9: 画面ID | E9: SC1601 | O9: 画面名 | U9: 保留・保留解除画面
A11: イベントID | G11: KN1010201
A12: インプット | M12: 処理概要 | AU12: 出力 | BF12: 参照情報
N15: 1. ロジック1
N26: 2. ロジック2
