Workbook

Sheet 表紙
A1: システム名 | K1: システム種別 | W1: 詳細設計書 | AP1: 作成者 | AT1: 作成日 | AY1: 更新者 | BC1: 更新日 | BH1: 版数
A2: POSサーバー | K2: POSサーバ | AP2: =改訂履歴!$H$11 -> DuNT | AT2: =改訂履歴!$B$11 -> 45533 | AY2: =LOOKUP(2,1/(改訂履歴!H11:H30000<>""),改訂履歴!H11:H30000) -> DuNT | BC2: =LOOKUP(2,1/(改訂履歴!B11:B30000<>""),改訂履歴!B11:B30000) -> 45533 | BH2: =LOOKUP(2,1/(改訂履歴!O11:O30000<>""),改訂履歴!O11:O30000) -> 0.1
A4: 機能カテゴリ | H4: 01_商品管理 | U4: 項目 | Z4: 機能設計書 | AP4: {=RIGHT(CELL("filename",$A$1),LEN(CELL("filename",$A$1))-FIND("]",CELL("filename",$A$1)))} -> 表紙
L16: POSサーバーの詳細設計書
L24: =K2&"/"&H4&"/"&Z4 -> POSサーバ/01_商品管理/機能設計書
Q44: 承認日 | AA44: 承認者 | AQ44: 版数

Sheet 改訂履歴
A1: システム名 | K1: システム種別 | W1: =IF(表紙!W1="","",表紙!W1) -> 詳細設計書 | AP1: 作成者 | AT1: 作成日 | AY1: 更新者 | BC1: 更新日 | BH1: 版数
A2: =IF(表紙!A2="","",表紙!A2) -> POSサーバー | K2: =IF(表紙!K2="","",表紙!K2) -> POSサーバ | AP2: =IF(表紙!AP2="","",表紙!AP2) -> DuNT | AT2: =IF(表紙!AT2="","",表紙!AT2) -> 45533 | AY2: =IF(表紙!AY2="","",表紙!AY2) -> DuNT | BC2: =IF(表紙!BC2="","",表紙!BC2) -> 45533 | BH2: =IF(表紙!BH2="","",表紙!BH2) -> 0.1
A4: 機能カテゴリ | H4: =IF(表紙!H4="","",表紙!H4) -> 01_商品管理 | U4: 項目 | Z4: =IF(表紙!Z4="","",表紙!Z4) -> 機能設計書 | AP4: {=RIGHT(CELL("filename",$A$1),LEN(CELL("filename",$A$1))-FIND("]",CELL("filename",$A$1)))} -> 改訂履歴
B8: ■改訂履歴
B10: 更新日 | H10: 更新者 | O10: 版数 | S10: 更新内容 | AX10: 承認日 | BD10: 承認者
B11: 45533 | H11: DuNT | O11: 0.1 | S11: 新規

Sheet SC0101
A1: システム名 | K1: システム種別 | W1: =IF(表紙!W1="","",表紙!W1) -> 詳細設計書 | AP1: 作成者 | AT1: 作成日 | AY1: 更新者 | BC1: 更新日 | BH1: 版数
A2: =IF(表紙!A2="","",表紙!A2) -> POSサーバー | K2: =IF(表紙!K2="","",表紙!K2) -> POSサーバ | AP2: =IF(表紙!AP2="","",表紙!AP2) -> DuNT | AT2: =IF(表紙!AT2="","",表紙!AT2) -> 45533 | AY2: =IF(表紙!AY2="","",表紙!AY2) -> DuNT | BC2: =IF(表紙!BC2="","",表紙!BC2) -> 45533 | BH2: =IF(表紙!BH2="","",表紙!BH2) -> 0.1
A4: 機能カテゴリ | H4: =IF(表紙!H4="","",表紙!H4) -> 01_商品管理 | U4: 項目 | Z4: =IF(表紙!Z4="","",表紙!Z4) -> 機能設計書 | AP4: =MID(CELL("filename",A1),FIND("]",CELL("filename",A1))+1,255) -> SC0101
A7: ■機能説明
A9: 画面ID | E9: SC0101 | O9: 画面名 | U9: 商品管理画面
A11: イベントID | G11: SC0101-01 | M11: 画面初期化
A12: インプット | M12: 処理概要 | AU12: 出力 | BF12: 参照情報
BF14: 20_画面設計_01_商品管理.xlsx
N15: 1. 画面項目の初期化を実行する。
O16: 20_画面設計_01_商品管理.xlsxをご参照ください。
A24: イベントID | G24: SC0101-02 | M24: 画面初期化
A25: インプット | M25: 処理概要 | AU25: 出力 | BF25: 参照情報
BF27: 20_画面設計_01_商品管理.xlsx
N28: 1. PLUの長さを確認する。
O29: 13桁の場合、ステップ2を実行する。
O30: 13桁未満の場合、「0」を追加して13桁になる。その後、ステップ2を実行する。 | BF30: 40_API設計/API_15_プリセットメニュー設定/40_API設計_AP1507_階層一覧取得.xlsx
N31: 2. API「AP1506」を使用して商品を提案する。
O32: 入力桁数が2桁未満の場合、「0」を追加して、AP1507_商品種類検索のAPIを呼び出す。
O34: 2.1 「AP1506」API呼出処理を実行する。
P35: APIのパラメータ | W35: パラメータの値
P36: selected_store | W36: 選択されている対象店舗
P37: plu | W37: 画面で入力された値
P38: group_code | W38: 画面で入力された値
P39: product_code | W39: 画面で入力された値
P40: promotion_code | W40: null
O42: 2.2 返却された結果情報
P43: ①．成功した場合：
Q44: 返却された結果
Q45: 1. status_code | AB45: 200 (OK)
Q46: 2. message | AB46: ブランク
Q47: 3. data | AB47: 提案商品情報
Q49: ステップ4を実行する。
P50: ②．エラーの場合、以下のように実行する。
Q51: 404エラーの場合、以下のファイルの画面項目の説明に従ってエラー表示処理を実行する。
Q52: 20_画面設計_01_商品管理.xlsx
Q53: その他のエラーの場合、APIエラーの共通表示処理を実行する。
N54: 3. 画面項目の「AP1506」APIレスポンスをマッピングする。
O55: 20_画面設計_01_商品管理.xlsxをご参照ください。
N57: 4. 商品のミックスマッチ・特売一覧を取得する。
O58: 4.1 「AP0101」API呼出処理を実行する。
...

Sheet SC0102
A1: システム名 | K1: システム種別 | W1: =IF(表紙!W1="","",表紙!W1) -> 詳細設計書 | AP1: 作成者 | AT1: 作成日 | AY1: 更新者 | BC1: 更新日 | BH1: 版数
A2: =IF(表紙!A2="","",表紙!A2) -> POSサーバー | K2: =IF(表紙!K2="","",表紙!K2) -> POSサーバ | AP2: =IF(表紙!AP2="","",表紙!AP2) -> DuNT | AT2: =IF(表紙!AT2="","",表紙!AT2) -> 45533 | AY2: =IF(表紙!AY2="","",表紙!AY2) -> DuNT | BC2: =IF(表紙!BC2="","",表紙!BC2) -> 45533 | BH2: =IF(表紙!BH2="","",表紙!BH2) -> 0.1
A4: 機能カテゴリ | H4: =IF(表紙!H4="","",表紙!H4) -> 01_商品管理 | U4: 項目 | Z4: =IF(表紙!Z4="","",表紙!Z4) -> 機能設計書 | AP4: =MID(CELL("filename",A1),FIND("]",CELL("filename",A1))+1,255) -> SC0102
A7: ■機能説明
A9: 画面ID | E9: SC0102 | O9: 画面名 | U9: 商品詳細画面
A11: イベントID | G11: SC0102-01 | M11: 画面初期化
A12: インプット | M12: 処理概要 | AU12: 出力 | BF12: 参照情報
BF14: 20_画面設計_01_商品管理.xlsx
N15: 1. AP0111を使用して商品詳細を取得する。
O17: 1.1 「AP0111」API呼出処理を実行する。
P18: APIのパラメータ | W18: パラメータの値
P19: selected_store | W19: 選択されている対象店舗
P20: PLU | W20: SC0101画面から渡された商品のPLUコード
P21: my_company_code | W21: SC0101画面から渡されたmy_company_codeの値
O23: 1.2 返却された結果情報
P24: ①．成功した場合：
Q25: 返却された結果
Q26: 1. status_code | AB26: 200 (OK)
Q27: 2. message | AB27: ブランク
Q28: 3. data | AB28: 商品詳細情報
P30: ②．エラーの場合、以下のように実行する。
Q31: その他のエラーの場合、APIエラーの共通表示処理を実行する。
N32: 2. AP0113を使用して、ドロップダウンに表示する税種別一覧を取得する。
O34: 2.1 「AP0113」API呼出処理を実行する。
P35: APIのパラメータ | W35: パラメータの値
P36: selected_store | W36: 選択されている対象店舗
O38: 2.2 返却された結果情報
P39: ①．成功した場合：
Q40: 返却された結果
Q41: 1. status_code | AB41: 200 (OK)
Q42: 2. message | AB42: ブランク
Q43: 3. data | AB43: 税種別一覧
P45: ②．エラーの場合、以下のように実行する。
Q46: その他のエラーの場合、APIエラーの共通表示処理を実行する。
N49: 3. 画面項目の初期化を実行する。
O50: 20_画面設計_01_商品管理.xlsxをご参照ください。
A56: イベントID | G56: SC0102-02 | M56: 編集取消
A57: インプット | M57: 処理概要 | AU57: 出力 | BF57: 参照情報
N60: 1. 編集を取り消し、SC0101_商品管理画面に遷移する。
A68: イベントID | G68: SC0102-03 | M68: 商品削除
...

Sheet MD0102
A1: システム名 | K1: システム種別 | W1: =IF(表紙!W1="","",表紙!W1) -> 詳細設計書 | AP1: 作成者 | AT1: 作成日 | AY1: 更新者 | BC1: 更新日 | BH1: 版数
A2: =IF(表紙!A2="","",表紙!A2) -> POSサーバー | K2: =IF(表紙!K2="","",表紙!K2) -> POSサーバ | AP2: =IF(表紙!AP2="","",表紙!AP2) -> DuNT | AT2: =IF(表紙!AT2="","",表紙!AT2) -> 45533 | AY2: =IF(表紙!AY2="","",表紙!AY2) -> DuNT | BC2: =IF(表紙!BC2="","",表紙!BC2) -> 45533 | BH2: =IF(表紙!BH2="","",表紙!BH2) -> 0.1
A4: 機能カテゴリ | H4: =IF(表紙!H4="","",表紙!H4) -> 01_商品管理 | U4: 項目 | Z4: =IF(表紙!Z4="","",表紙!Z4) -> 機能設計書 | AP4: =MID(CELL("filename",A1),FIND("]",CELL("filename",A1))+1,255) -> MD0102
A7: ■機能説明
A9: 画面ID | E9: MD0102 | O9: 画面名 | U9: プロモーション一覧モーダル
A11: イベントID | G11: MD0102_01 | M11: 画面初期化
A12: インプット | M12: 処理概要 | AU12: 出力 | BF12: 参照情報
BF14: ▪20_画面設計_01_商品管理.xlsx
N15: 1. 画面項目の初期化を実行する。
O16: 20_画面設計_03_店舗特売入力.xlsxをご参照ください。
A22: イベントID | G22: MD0102_02 | M22: SC0301画面に戻る
A23: インプット | M23: 処理概要 | AU23: 出力 | BF23: 参照情報
BF25: ▪20_画面設計_01_商品管理.xlsx
N26: 1. MD0102_プロモーション一覧モーダルを閉じて、
O27: SC0301_店舗特売入力画面を表示する。
A34: イベントID | G34: MD0102_03 | M34: プロモーションの情報を検索する
A35: インプット | M35: 処理概要 | AU35: 出力 | BF35: 参照情報
BF37: ▪20_画面設計_01_商品管理.xlsx ▪ 40_API設計_AP0105_プロモーション一覧取得.xlsx
N38: 1. KN0106_プロモーション一覧取得機能
O39: 入力されたpromotion_codeが5未満の場合、「0」を追加して、API 「AP0105_プロモーション一覧取得」を呼び出す。
P40: API「AP0105_プロモーション一覧取得」を呼び出す。
O41: 1.1 AP0105_プロモーション一覧取得API呼出処理を実行する。
P42: APIのパラメータ | W42: パラメータの値
P43: store_code | W43: 選択された店舗
P44: code | W44: 画面で入力されたプロモーションコード
P46: ・40_API設計_AP0105_プロモーション一覧取得.xlsxをご参照ください。
O47: 1.2 返却された結果情報
P48: ▪商品情報取得が成功した場合、
Q49: ・返却レスポンスは40_API設計_AP0105_プロモーション一覧取得.xlsxをご参照ください。
Q50: ・以下の画面設計に従って画面に返されるAPIレスポンスのマッピングを実行する。
R51: 20_画面設計_03_店舗特売入力.xlsx
P53: ▪商品情報取得が失敗した場合、
Q54: ・返却レスポンスは40_API設計_AP0105_プロモーション一覧取得.xlsxをご参照ください。
Q55: ・20_画面設計_03_店舗特売入力.xlsxの記載に従ってエラーメッセージを画面に表示する。
A60: イベントID | G60: MD0102_04 | M60: プロモーションを選択する
A61: インプット | M61: 処理概要 | AU61: 出力 | BF61: 参照情報
BF63: ▪20_画面設計_01_商品管理.xlsx
N64: 1. MD0102_プロモーション一覧モーダルを閉じて、
O65: プロモーションの詳細情報を使用中の画面に渡す。
O66: 一覧画面に送信される項目：
...

Sheet テンプレート
A1: システム名 | K1: システム種別 | W1: =IF(表紙!W1="","",表紙!W1) -> 詳細設計書 | AP1: 作成者 | AT1: 作成日 | AY1: 更新者 | BC1: 更新日 | BH1: 版数
A2: =IF(表紙!A2="","",表紙!A2) -> POSサーバー | K2: =IF(表紙!K2="","",表紙!K2) -> POSサーバ | AP2: =IF(表紙!AP2="","",表紙!AP2) -> DuNT | AT2: =IF(表紙!AT2="","",表紙!AT2) -> 45533 | AY2: =IF(表紙!AY2="","",表紙!AY2) -> DuNT | BC2: =IF(表紙!BC2="","",表紙!BC2) -> 45533 | BH2: =IF(表紙!BH2="","",表紙!BH2) -> 0.1
A4: 機能カテゴリ | H4: =IF(表紙!H4="","",表紙!H4) -> 01_商品管理 | U4: 項目 | Z4: =IF(表紙!Z4="","",表紙!Z4) -> 機能設計書 | AP4: =MID(CELL("filename",A1),FIND("]",CELL("filename",A1))+1,255) -> テンプレート
A7: ■機能説明
A9: 画面ID | E9: SCxxxxxx | O9: 画面名
A11: イベントID | G11: KN1010201
A12: インプット | M12: 処理概要 | AU12: 出力 | BF12: 参照情報
N15: 1. ロジック1
N26: 2. ロジック2
