Workbook

Sheet 表紙
A1: システム名 | K1: システム種別 | W1: 詳細設計書 | AP1: 作成者 | AT1: 作成日 | AY1: 更新者 | BC1: 更新日 | BH1: 版数
A2: POSサーバー | K2: POSサーバ | AP2: =改訂履歴!$H$11 -> SonMNT | AT2: =改訂履歴!$B$11 -> 45456 | AY2: =LOOKUP(2,1/(改訂履歴!H11:H30001<>""),改訂履歴!H11:H30001) -> AnhDD | BC2: =LOOKUP(2,1/(改訂履歴!B11:B30001<>""),改訂履歴!B11:B30001) -> 45617 | BH2: =LOOKUP(2,1/(改訂履歴!O11:O30001<>""),改訂履歴!O11:O30001) -> 0.7
A4: 機能カテゴリ | H4: 00_共通 | U4: 項目 | Z4: 機能設計書 | AP4: {=RIGHT(CELL("filename",$A$1),LEN(CELL("filename",$A$1))-FIND("]",CELL("filename",$A$1)))} -> 表紙
L16: POSサーバーの詳細設計書
L24: =K2&"/"&H4&"/"&Z4 -> POSサーバ/00_共通/機能設計書
Q44: 承認日 | AA44: 承認者 | AQ44: 版数

Sheet 改訂履歴
A1: システム名 | K1: システム種別 | W1: =IF(表紙!W1="","",表紙!W1) -> 詳細設計書 | AP1: 作成者 | AT1: 作成日 | AY1: 更新者 | BC1: 更新日 | BH1: 版数
A2: =IF(表紙!A2="","",表紙!A2) -> POSサーバー | K2: =IF(表紙!K2="","",表紙!K2) -> POSサーバ | AP2: =IF(表紙!AP2="","",表紙!AP2) -> SonMNT | AT2: =IF(表紙!AT2="","",表紙!AT2) -> 45456 | AY2: =IF(表紙!AY2="","",表紙!AY2) -> AnhDD | BC2: =IF(表紙!BC2="","",表紙!BC2) -> 45617 | BH2: =IF(表紙!BH2="","",表紙!BH2) -> 0.7
A4: 機能カテゴリー | H4: =IF(表紙!H4="","",表紙!H4) -> 00_共通 | U4: 項目 | Z4: =IF(表紙!Z4="","",表紙!Z4) -> 機能設計書 | AP4: {=RIGHT(CELL("filename",$A$1),LEN(CELL("filename",$A$1))-FIND("]",CELL("filename",$A$1)))} -> 改訂履歴
B8: ■改訂履歴
B10: 更新日 | H10: 更新者 | O10: 版数 | S10: 更新内容 | AX10: 承認日 | BD10: 承認者
B11: 45456 | H11: SonMNT | O11: 0.1 | S11: 新規
B13: 45505 | H13: DuNT | O13: 0.2 | S13: バリデーションチェック共通、店舗選択エリア、ヘッダー、ページング、モーダルのシートを作成する。
S14: 共通APIレスポンスシートを削除する。
B15: 45524 | H15: AnhDD | O15: 0.3 | S15: ローカルストレージ情報保存シートを作成する。
S16: ヘッダー：Escキーを押したときにメインメニューに戻る処理を追加する。
S17: 店舗選択エリア：店舗検索ロジックを修正する。
B18: 45568 | H18: TuyenNH | O18: 0.4 | S18: 以下のアクションをヘッダーエリアに追加する。CSV出力、印刷、ESC、メニュー
S19: シート：[ヘッダー]
B20: 45569 | H20: DuNT | O20: 0.5 | S20: 店舗選択エリア：新しい設計に従って更新する
S21: ローカル ストレージ情報の保存：イベントIDLocalStorage-01の更新
B22: 45593 | H22: AnhDD | O22: 0.6 | S22: ファンクションキー
S23: ファンクションキーシートを新規作成
B24: 45617 | H24: AnhDD | O24: 0.7 | S24: 店舗選択エリア
S25: Store-06の処理ロジック修正

Sheet ログ記録方針
A1: システム名 | K1: システム種別 | W1: 基本設計書 | AP1: 作成者 | AT1: 作成日 | AY1: 更新者 | BC1: 更新日 | BH1: 版数
A2: POSサーバー | K2: POSサーバー | AP2: =IF(表紙!AP2="","",表紙!AP2) -> SonMNT | AT2: =IF(表紙!AT2="","",表紙!AT2) -> 45456 | AY2: =IF(表紙!AY2="","",表紙!AY2) -> AnhDD | BC2: =IF(表紙!BC2="","",表紙!BC2) -> 45617 | BH2: =IF(表紙!BH2="","",表紙!BH2) -> 0.7
A4: 機能カテゴリ | H4: =IF(表紙!H4="","",表紙!H4) -> 00_共通 | U4: 項目 | Z4: 概要設計書 | AP4: =MID(CELL("filename",A1),FIND("]",CELL("filename",A1))+1,255) -> ログ記録方針
B7: ログ記録方針
B9: 概要：
C11: 1. 使用ライブラリ：SLF4J
C13: 2. ログ記録ファイルの保存先：
D14: {0}src/main/resource/logs/ | AX14: `
D15: ・{0}はプロジェクトのパスである。
C17: 3. レベル別ログ情報
D19: 3.1 情報ログ
E20: ・意味: 業務フロープログラムの情報を保存するため
E21: ・ログ形式：[{0}] [pos_server] [INFO] [{1}] : class_{2}_function_{3}(Line_{4})_{5}
F22: パラメータは以下の通り
G23: （{0}: yyyy-MM-dd HH:mm:ss.SSS形式でログ表示時間）
G24: {1}: 実行中のスレッド
G25: {2}: クラス名
G26: {3}: 関数名
G27: {4}: このログを出力する行
G28: {5}: 通知メッセージの内容
D30: 3.2 デバッグログ
E31: ・意味: 業務フロープログラムの情報を保存するため
E32: ・ログ形式：[{0}] [pos_server] [DEBUG] [{1}] : class_{2}_function_{3}(Line_{4})_{5}
F33: パラメータは以下の通り
G34: （{0}: yyyy-MM-dd HH:mm:ss.SSS形式でログ表示時間）
G35: {1}: 実行中のスレッド
G36: {2}: クラス名
G37: {3}: 関数名
G38: {4}: このログを出力する行
G39: {5}: 通知メッセージの内容
D41: 3.3 警告ログ：プログラムの狭い範囲内で重大度の低いエラー情報を保存する。
E42: ・ログ形式：[{0}] [pos_server] [WARN] [{1}] : class_{2}_function_{3}(Line_{4})_{5}
F43: パラメータは以下の通り
G44: （{0}: yyyy-MM-dd HH:mm:ss.SSS形式でログ表示時間）
G45: {1}: 実行中のスレッド
G46: {2}: クラス名
G47: {3}: 関数名
G48: {4}: このログを出力する行
G49: {5}: メッセージ内容には、例外クラス名（Exceptionがある場合）とエラー情報の内容を含む必要がある。
E50: ・注意: WARNINGログには、ログ出力行の下にトレースを追加する必要がある（例外がある場合）
...

Sheet 共通バリデーションチェック
A1: システム名 | K1: システム種別 | W1: 基本設計書 | AP1: 作成者 | AT1: 作成日 | AY1: 更新者 | BC1: 更新日 | BH1: 版数
A2: POSサーバー | K2: POSサーバー | AP2: =IF(表紙!AP2="","",表紙!AP2) -> SonMNT | AT2: =IF(表紙!AT2="","",表紙!AT2) -> 45456 | AY2: =IF(表紙!AY2="","",表紙!AY2) -> AnhDD | BC2: =IF(表紙!BC2="","",表紙!BC2) -> 45617 | BH2: =IF(表紙!BH2="","",表紙!BH2) -> 0.7
A4: 機能カテゴリ | H4: =IF(表紙!H4="","",表紙!H4) -> 00_共通 | U4: 項目 | Z4: 概要設計書 | AP4: =MID(CELL("filename",A1),FIND("]",CELL("filename",A1))+1,255) -> 共通バリデーションチェック
B7: 共通バリデーションチェック
B9: No | D9: バリデーションチェックの内容 | W9: From | Z9: エラーメッセージ
B10: 1 | D10: 入力必須 | W10: BE/FE | Z10: MSG_VAL_001 （{0}：項目名）
B11: 2 | D11: 形式不正 | W11: BE/FE | Z11: MSG_VAL_003 （{0}：項目名）
B12: 3 | D12: 最大長 | W12: BE | Z12: MSG_VAL_002 （{0}：項目名、{1}：最大値）
B13: 4 | D13: 禁則文字 | W13: BE/FE | Z13: MSG_VAL_005
B14: 5 | D14: 過去日 | W14: BE/FE | Z14: MSG_VAL_022
B15: 6 | D15: 日付不正 | W15: BE/FE | Z15: MSG_VAL_016
B16: 7 | D16: ファイル形式不正 | W16: BE/FE | Z16: MSG_VAL_030
B17: 8 | D17: 数字のみ入力可能 | W17: BE | Z17: MSG_VAL_026
B18: 9 | D18: 時間不正 | W18: BE/FE | Z18: MSG_VAL_016
B19: 10
B20: 11
B21: 12
B22: 13
B23: 14
B24: 15
B25: 16

Sheet 店舗選択エリア
A1: システム名 | K1: システム種別 | W1: 基本設計書 | AP1: 作成者 | AT1: 作成日 | AY1: 更新者 | BC1: 更新日 | BH1: 版数
A2: POSサーバー | K2: POSサーバー | AP2: =IF(表紙!AP2="","",表紙!AP2) -> SonMNT | AT2: =IF(表紙!AT2="","",表紙!AT2) -> 45456 | AY2: =IF(表紙!AY2="","",表紙!AY2) -> AnhDD | BC2: =IF(表紙!BC2="","",表紙!BC2) -> 45617 | BH2: =IF(表紙!BH2="","",表紙!BH2) -> 0.7
A4: 機能カテゴリ | H4: =IF(表紙!H4="","",表紙!H4) -> 00_共通 | U4: 項目 | Z4: 概要設計書 | AP4: =MID(CELL("filename",A1),FIND("]",CELL("filename",A1))+1,255) -> 店舗選択エリア
A7: ■機能説明
A9: 画面ID | E9: 店舗選択エリア | O9: 画面名
A11: イベントID | G11: Store-01 | M11: 店舗一覧エリア初期化
A12: インプット | M12: 処理概要 | AU12: 出力 | BF12: 参照情報
BF14: 20_画面設計_00_共通.xlsx
N15: 1. イベントID「「LocalStorage-01」（ローカルストレージ情報保存シート）でのログイン、トークンリフレッシュ後に
O16: 取得した店舗一覧を表示する。
O17: 20_画面設計_00_共通.xlsxの店舗選択エリア、検索エリアをご参照ください。
O18: イベントID「LocalStorage-01」でのログイン、トークンリフレッシュ後にAPI「AP1503」の結果を使用して店舗タイプのドロップダウンを表示する。
O19: 1つの店舗のみがある場合、店舗リストエリアを表示せず、そのアカウントの店舗を各画面の対象店舗として保存する。
A26: イベントID | G26: Store-02 | M26: 店舗検索
A27: インプット | M27: 処理概要 | AU27: 出力 | BF27: 参照情報
N30: 1. 店舗検索
N31: ・イベントID「LocalStorage-01」 (シート[ローカルストレージ情報保存])でのログイン、トークンリフレッシュ後に取得した店舗一覧から店舗一覧を検索する。LocalStorage-01 (シート[ローカルストレージ情報保存])
N32: ・検索内容はユーザーが入力した内容である。
N33: ・検索タイプ：含む（contain）
N34: ・検索データには以下が含まれている。店舗コード、店舗名
N35: ・この検索は、ユーザーが対象店舗を見つけやすくするために店舗一覧を絞り込むことのみを目的としている。ユーザーが
N36: 店舗を選択（チェックボックスまたはラジオボタンを選択）すると、その店舗がフローの対象として使用される。
N37: 2. 検索結果表示
N38: ・店舗一覧表示エリアに検索条件を満たす内容を表示する。
A43: イベントID | G43: Store-03 | M43: 全選択
A44: インプット | M44: 処理概要 | AU44: 出力 | BF44: 参照情報
N47: 1. 画面に表示されている一覧の全ての店舗を選択する。
A54: イベントID | G54: Store-04 | M54: 全解除
A55: インプット | M55: 処理概要 | AU55: 出力 | BF55: 参照情報
N58: 1. 画面に表示されている一覧から全ての店舗を選択解除する。
A64: イベントID | G64: Store-05 | M64: 店舗グループを選択する。
A65: インプット | M65: 処理概要 | AU65: 出力 | BF65: 参照情報
N68: 1. 店舗グループの分類と店舗名称・コード入力項目の値に基づいてリストをフィルターする。
N70: 2. 検索結果表示
N71: ・店舗一覧表示エリアに検索条件を満たす内容を表示する。
A76: イベントID | G76: Store-06 | M76: 店舗一覧のアイテムのチェックボックスの状態を変更する。
A77: インプット | M77: 処理概要 | AU77: 出力 | BF77: 参照情報
N80: 1. 検索条件および結果リストのデータをクリアする。
O81: 結果リストのデータが変更されていない場合、データをクリアし、ステップ2を実行する。
O82: 結果リストのデータが変更されている場合、「編集情報が失われます。よろしいですか？」確認モーダルを表示する。
...

Sheet ヘッダー
A1: システム名 | K1: システム種別 | W1: 基本設計書 | AP1: 作成者 | AT1: 作成日 | AY1: 更新者 | BC1: 更新日 | BH1: 版数
A2: POSサーバー | K2: POSサーバー | AP2: =IF(表紙!AP2="","",表紙!AP2) -> SonMNT | AT2: =IF(表紙!AT2="","",表紙!AT2) -> 45456 | AY2: =IF(表紙!AY2="","",表紙!AY2) -> AnhDD | BC2: =IF(表紙!BC2="","",表紙!BC2) -> 45617 | BH2: =IF(表紙!BH2="","",表紙!BH2) -> 0.7
A4: 機能カテゴリ | H4: =IF(表紙!H4="","",表紙!H4) -> 00_共通 | U4: 項目 | Z4: 概要設計書 | AP4: =MID(CELL("filename",A1),FIND("]",CELL("filename",A1))+1,255) -> ヘッダー
A7: ■機能説明
A9: 画面ID | E9: ヘッダー | O9: 画面名
A11: イベントID | G11: Header-01 | M11: ヘッダー初期化
A12: インプット | M12: 処理概要 | AU12: 出力 | BF12: 参照情報
N15: 1. 各画面の画面設計に従ってヘッダーを初期化する。 | BF15: 20_画面設計_00_共通.xlsx
A22: イベントID | G22: Header-02 | M22: CSV出力
A23: インプット | M23: 処理概要 | AU23: 出力 | BF23: 参照情報
BF25: -
N26: 1. 各画面の設計に従ってCSVを出力する。
A32: イベントID | G32: Header-03 | M32: pdf印刷
A33: インプット | M33: 処理概要 | AU33: 出力 | BF33: 参照情報
BF35: -
N36: 1. 各画面の設計に従ってPDFファイルを印刷する。
A42: イベントID | G42: Header-04 | M42: ESC
A43: インプット | M43: 処理概要 | AU43: 出力 | BF43: 参照情報
BF45: -
N46: 1. 前の画面に戻る。
O47: ・画面上のボタンをタッチする。
O48: ・キーボードの「ESC」キーを押す。
O49: ・データが変更された場合、確認モーダルを表示する（メッセージ = MSG_CONFIRM_002）
P50: OKをタッチすると、前の操作画面に遷移する。
P51: 取消：モーダルを閉じる。
O52: ・データが変更されていない場合、前の操作画面に戻る。
A58: イベントID | G58: Header-05 | M58: メインメニューに戻る
A59: インプット | M59: 処理概要 | AU59: 出力 | BF59: 参照情報
N62: 1. その画面に変更データがあるかを確認する。
O63: ・データが変更された場合、confirmモーダルを表示する（メッセージ = MSG_CONFIRM_002）
P64: OK: SCX101_メインメニュー画面に遷移する。
P65: 取消：モーダルを閉じる。
O66: ・データが変更されていない場合、SCX101_メインメニュー画面に遷移する。
A71: イベントID | G71: Header-06 | M71: メインメニューに戻る
A72: インプット | M72: 処理概要 | AU72: 出力 | BF72: 参照情報
N75: 1. その画面に変更データがあるかを確認する。
O76: ・データが変更された場合、確認モーダルを表示する（メッセージ = MSG_CONFIRM_002）
P77: OK: SCX101_メインメニュー画面に遷移する。
P78: 取消：モーダルを閉じる
O79: ・データが変更されていない場合、タブ又はブラウザを閉じる。

Sheet ページング
A1: システム名 | K1: システム種別 | W1: 基本設計書 | AP1: 作成者 | AT1: 作成日 | AY1: 更新者 | BC1: 更新日 | BH1: 版数
A2: POSサーバー | K2: POSサーバー | AP2: =IF(表紙!AP2="","",表紙!AP2) -> SonMNT | AT2: =IF(表紙!AT2="","",表紙!AT2) -> 45456 | AY2: =IF(表紙!AY2="","",表紙!AY2) -> AnhDD | BC2: =IF(表紙!BC2="","",表紙!BC2) -> 45617 | BH2: =IF(表紙!BH2="","",表紙!BH2) -> 0.7
A4: 機能カテゴリ | H4: =IF(表紙!H4="","",表紙!H4) -> 00_共通 | U4: 項目 | Z4: 概要設計書 | AP4: =MID(CELL("filename",A1),FIND("]",CELL("filename",A1))+1,255) -> ページング
A7: ■機能説明
A9: 画面ID | E9: ページング | O9: 画面名
A11: イベントID | G11: Paging-01 | M11: ヘッダー初期化
A12: インプット | M12: 処理概要 | AU12: 出力 | BF12: 参照情報
N15: 1. 各画面の画面設計に従って初期化する。 | BF15: 20_画面設計_00_共通.xlsx
A22: イベントID | G22: Paging-02 | M22: 先頭行に遷移する。
A23: インプット | M23: 処理概要 | AU23: 出力 | BF23: 参照情報
N26: 1. ページ1の先頭行に遷移する。
A33: イベントID | G33: Paging-03 | M33: 最終行に遷移する。
A34: インプット | M34: 処理概要 | AU34: 出力 | BF34: 参照情報
N37: 1. 最後ページの最終行に遷移する。
A44: イベントID | G44: Paging-04 | M44: 前頁に遷移する。
A45: インプット | M45: 処理概要 | AU45: 出力 | BF45: 参照情報
N48: 1. 前頁に遷移する。
A55: イベントID | G55: Paging-05 | M55: 次頁に遷移する。
A56: インプット | M56: 処理概要 | AU56: 出力 | BF56: 参照情報
N59: 1. 次頁に遷移する。

Sheet モーダル
A1: システム名 | K1: システム種別 | W1: 基本設計書 | AP1: 作成者 | AT1: 作成日 | AY1: 更新者 | BC1: 更新日 | BH1: 版数
A2: POSサーバー | K2: POSサーバー | AP2: =IF(表紙!AP2="","",表紙!AP2) -> SonMNT | AT2: =IF(表紙!AT2="","",表紙!AT2) -> 45456 | AY2: =IF(表紙!AY2="","",表紙!AY2) -> AnhDD | BC2: =IF(表紙!BC2="","",表紙!BC2) -> 45617 | BH2: =IF(表紙!BH2="","",表紙!BH2) -> 0.7
A4: 機能カテゴリ | H4: =IF(表紙!H4="","",表紙!H4) -> 00_共通 | U4: 項目 | Z4: 概要設計書 | AP4: =MID(CELL("filename",A1),FIND("]",CELL("filename",A1))+1,255) -> モーダル
A7: ■機能説明
A9: 画面ID | E9: モーダル | O9: 画面名
A11: イベントID | G11: Modal-01 | M11: モーダルを初期化する。
A12: インプット | M12: 処理概要 | AU12: 出力 | BF12: 参照情報
N15: 1. 各種モーダルの画面設計に従って初期化する。 | BF15: 20_画面設計_00_共通.xlsx
O16: 「20_画面設計_00_共通.xlsx」のモーダルシートをご参照ください。
A22: イベントID | G22: Modal-02 | M22: モーダルが伝える内容に同意する
A23: インプット | M23: 処理概要 | AU23: 出力 | BF23: 参照情報
N26: 1. モーダルを閉じる。
O27: 確認モーダルの場合、各機能の詳細設計書で記載されるアクションを実行する。
O28: 機能
A33: イベントID | G33: Modal-03 | M33: モーダルを閉じる
A34: インプット | M34: 処理概要 | AU34: 出力 | BF34: 参照情報
N37: 1. モーダルを閉じる。
A44: イベントID | G44: Modal-04 | M44: ローディングを表示する
A45: インプット | M45: 処理概要 | AU45: 出力 | BF45: 参照情報
N48: 1. モーダルを表示する。
N49: 2. アクションが完了したら、ローディングモーダルを閉じる。
N50: 備考: 1つの時点で、1つのローディング表示モーダルのみが実行される。ローディング表示モーダルが自動的にキャンセルされ、
N51: ユーザーから閉じるアクションがない。

Sheet ローカルストレージ情報保存
A1: システム名 | K1: システム種別 | W1: 基本設計書 | AP1: 作成者 | AT1: 作成日 | AY1: 更新者 | BC1: 更新日 | BH1: 版数
A2: POSサーバー | K2: POSサーバー | AP2: =IF(表紙!AP2="","",表紙!AP2) -> SonMNT | AT2: =IF(表紙!AT2="","",表紙!AT2) -> 45456 | AY2: =IF(表紙!AY2="","",表紙!AY2) -> AnhDD | BC2: =IF(表紙!BC2="","",表紙!BC2) -> 45617 | BH2: =IF(表紙!BH2="","",表紙!BH2) -> 0.7
A4: 機能カテゴリ | H4: =IF(表紙!H4="","",表紙!H4) -> 00_共通 | U4: 項目 | Z4: 概要設計書 | AP4: =MID(CELL("filename",A1),FIND("]",CELL("filename",A1))+1,255) -> ローカルストレージ情報保存
A7: ■機能説明
A9: 画面ID | E9: モーダル | O9: 画面名
A11: イベントID | G11: LocalStorage-01 | M11: ストレージ値を保存する
A12: インプット | M12: 処理概要 | AU12: 出力 | BF12: 参照情報
N15: 1. KNX101_操作権限がある店舗一覧取得機能を呼び出す。 | BF15: 20_画面設計_00_共通.xlsx
P17: 1.1 ユーザーの権限を確認する
Q18: ①．「店舗ユーザー」の場合
R19: 処理を終了し、現在の画面に遷移する。
Q20: ②．「店舗ユーザー」ではない場合
R21: 1.2ステップを実行する。
P22: 1.2 「APX004」API呼出処理
P24: APIのパラメータ | W24: パラメータの値
P27: 1.3 返却された結果情報
P28: ①．「更新成功」の場合
Q29: 返却された結果
Q30: 1. status_code | AB30: 200 (OK)
Q31: 2. message | AB31: Success
Q32: 3. data | AB32: ユーザーが操作権限を持つ店舗一覧
Q34: 「40_API設計_X004_店舗一覧.xlsx」のレスポンスをご参照ください。
Q35: 操作権限がある店舗一覧をローカルストレージに保存する。
Q36: ステップ2を実行する。
P37: ②．エラーの場合、以下のように実行する。
Q38: 操作権限がある店舗一覧をローカルストレージに [] として保存する。
N39: 2. 店舗グループの分類一覧を取得する。
P40: 2.1「AP1503」API呼出処理
P42: APIのパラメータ | W42: パラメータの値
P43: master_code | W43: MC8201
P45: 2.2 返却された結果情報
P46: ①．「更新成功」の場合
Q47: 返却された結果
Q48: 1. status_code | AB48: 200 (OK)
Q49: 2. message | AB49: Success
Q50: 3. data | AB50: 店舗グループの分類一覧
Q52: 40_API設計_AP1503_コードマスタ取得.xlsxのレスポンスをご参照ください。
Q53: 店舗グループの分類一覧をローカルストレージに保存する。
P55: ②．エラーの場合、以下のように実行する。
Q56: 店舗グループの分類一覧をローカルストレージに[]として保存する。

Sheet ファンクションキー
A1: システム名 | K1: システム種別 | W1: 基本設計書 | AP1: 作成者 | AT1: 作成日 | AY1: 更新者 | BC1: 更新日 | BH1: 版数
A2: POSサーバー | K2: POSサーバー | AP2: =IF(表紙!AP2="","",表紙!AP2) -> SonMNT | AT2: =IF(表紙!AT2="","",表紙!AT2) -> 45456 | AY2: =IF(表紙!AY2="","",表紙!AY2) -> AnhDD | BC2: =IF(表紙!BC2="","",表紙!BC2) -> 45617 | BH2: =IF(表紙!BH2="","",表紙!BH2) -> 0.7
A4: 機能カテゴリ | H4: =IF(表紙!H4="","",表紙!H4) -> 00_共通 | U4: 項目 | Z4: 概要設計書 | AP4: =MID(CELL("filename",A1),FIND("]",CELL("filename",A1))+1,255) -> ファンクションキー
B7: 共通規約
D8: PF1～PF7 ：任意
D9: PF8～PF12、ESC :キー固定
B11: 機能詳細
B13: No | C13: 画面・機能 | I13: F01 | K13: F02 | M13: F03 | O13: F04 | Q13: F05 | S13: F06 | U13: F07 | W13: F08 | Y13: F09 | AA13: F10 | AC13: F11 | AE13: F12 | AG13: ESC
B14: 1 | C14: 01 商品管理 | I14: 商品マスタ簡易 | K14: 緊急売価変更 | M14: 特売新規 | O14: ミックスマッチ新規 | AG14: 前画面
B15: 2 | C15: 02 緊急売価変更 | W15: クリア | X15: 印刷 | Y15: 印刷 | Z15: 確定 | AA15: 削除 | AC15: 確定 | AG15: 前画面 | AH15: 前画面
B16: 3 | C16: 03 店舗特売入力 | W16: クリア | X16: 印刷 | AC16: 確定 | AG16: 前画面 | AH16: 前画面
B17: 4 | C17: 04 商品採用店舗確認 | AG17: 前画面 | AH17: 前画面
B18: 5 | C18: 05 ミックスマッチ設定 | I18: 前頁 | K18: 次頁 | M18: 先頭行 | O18: 最終行 | Q18: 検索 | W18: クリア | AC18: 確定 | AE18: 検索 | AG18: 前画面 | AH18: 前画面
B19: 6 | C19: 06 1, 7, 8 定番売価変更画面 | I19: 前頁 | K19: 次頁 | M19: 先頭行 | O19: 最終行 | W19: クリア | Y19: 印刷 | AC19: 確定 | AE19: 検索 | AG19: 前画面 | AH19: 前画面
B20: 7 | C20: 07 セットマッチ設定 | AG20: 前画面 | AH20: 前画面
B21: 8 | C21: 08 カテゴリ値引・割引設定 | I21: 検索 | K21: 新規 | M21: 行追加 | Q21: 行編集 | S21: 行削除 | W21: クリア | AA21: 削除 | AC21: 確定 | AE21: 検索 | AG21: 前画面 | AH21: 前画面
B22: 9 | C22: 10 プロモーションメンテ | W22: クリア | AC22: 確定 | AE22: 検索 | AG22: 前画面 | AH22: 前画面
B23: 10 | C23: 22 クレジット小計割引設定 | I23: 取消 | K23: 決定 | W23: クリア | AC23: 確定 | AG23: 前画面 | AH23: 前画面
B24: 11 | C24: 28 レシートクーポン設定 | I24: 編集 | K24: 新規 | AA24: 削除 | AC24: 確定 | AG24: 前画面 | AH24: 前画面
B25: 12 | C25: 37 メガ割設定 | W25: クリア | AC25: 確定 | AG25: 前画面 | AH25: 前画面
B26: 13 | C26: 38 朝割設定 | W26: クリア | AA26: 朝割解除 | AC26: 確定 | AG26: 前画面 | AH26: 前画面
B27: 14 | C27: 66 券マスタ設定 | AG27: 前画面 | AH27: 前画面
B28: 15 | C28: 96 カテゴリ割引レシートクーポン設定 | AG28: 前画面 | AH28: 前画面
B29: 16 | C29: 23 ポイント単位使用設定 | AG29: 前画面 | AH29: 前画面
B30: 17 | C30: 39 WAONポイントN倍設定 | I30: 取消 | AA30: 削除 | AC30: 確定 | AG30: 前画面 | AH30: 前画面
B31: 18 | C31: 21 ジャーナル検索 | AE31: 検索 | AG31: 前画面 | AH31: 前画面
B32: 19 | C32: 15 タッチメニュー設定 | I32: 編集 | K32: 新規 | M32: コピー | AA32: 削除 | AC32: 確定 | AE32: 検索 | AG32: 前画面 | AH32: 前画面
B33: 20 | C33: 18 タッチメニュー小計設定 | AE33: 検索 | AG33: 前画面 | AH33: 前画面
B34: 21 | C34: 62 画像アップロード | M34: 全選択 | O34: 前取消 | AG34: 前画面 | AH34: 前画面
B35: 22 | C35: 11 部門別売上速報 | I35: 上階層 | K35: 下階層 | AE35: 検索 | AG35: 前画面 | AH35: 前画面
B36: 23 | C36: 12 単品速報/日報 | AE36: 検索 | AG36: 前画面 | AH36: 前画面
B37: 24 | C37: 14 テナント売上速報・日報 | AE37: 検索 | AG37: 前画面 | AH37: 前画面
B38: 25 | C38: 19 売価変更勧告リスト | I38: 選択 | K38: 取消 | M38: 全選択 | O38: 前取消 | AG38: 前画面 | AH38: 前画面
B39: 26 | C39: 29 レジ別時間帯別点検 | AG39: 前画面 | AH39: 前画面
B40: 27 | C40: 31 レジ別速報/日報 | AE40: 検索 | AG40: 前画面 | AH40: 前画面
B41: 28 | C41: 32 レジ別単品別売上点検 | I41: サマリ画面 | AE41: 検索 | AG41: 前画面 | AH41: 前画面
B42: 29 | C42: 20 レジ精算入力 | AG42: 前画面 | AH42: 前画面
B43: 30 | C43: 33 釣銭機状況照会 | Y43: 補充リスト | AE43: 検索 | AG43: 前画面 | AH43: 前画面
B44: 31 | C44: 71 レジマスタ設定 | AG44: 前画面 | AH44: 前画面
B45: 32 | C45: 81 釣銭機警告設定 | AG45: 前画面 | AH45: 前画面
...
