Workbook

Sheet 表紙
A1: システム名 | K1: システム種別 | W1: 詳細設計書 | AP1: 作成者 | AT1: 作成日 | AY1: 更新者 | BC1: 更新日 | BH1: 版数
A2: POSサーバー | K2: POSサーバー | AP2: =改訂履歴!$H$11 -> DuNT | AT2: =改訂履歴!$B$11 -> 45448 | AY2: =LOOKUP(2,1/(改訂履歴!H11:H30000<>""),改訂履歴!H11:H30000) -> DuNT | BC2: =LOOKUP(2,1/(改訂履歴!B11:B30000<>""),改訂履歴!B11:B30000) -> 45448 | BH2: =LOOKUP(2,1/(改訂履歴!O11:O30000<>""),改訂履歴!O11:O30000) -> 0.1
A4: 機能カテゴリ | H4: 04_商品採用店舗確認 | U4: 項目 | Z4: 機能設計書 | AP4: {=RIGHT(CELL("filename",$A$1),LEN(CELL("filename",$A$1))-FIND("]",CELL("filename",$A$1)))} -> 表紙
L16: POSサーバーの基本設計書
L24: =K2&"/"&H4&"/"&Z4 -> POSサーバー/04_商品採用店舗確認/機能設計書
Q44: 承認日 | AA44: 承認者 | AQ44: 版数

Sheet 改訂履歴
A1: システム名 | K1: システム種別 | W1: =IF(表紙!W1="","",表紙!W1) -> 詳細設計書 | AP1: 作成者 | AT1: 作成日 | AY1: 更新者 | BC1: 更新日 | BH1: 版数
A2: =IF(表紙!A2="","",表紙!A2) -> POSサーバー | K2: =IF(表紙!K2="","",表紙!K2) -> POSサーバー | AP2: =IF(表紙!AP2="","",表紙!AP2) -> DuNT | AT2: =IF(表紙!AT2="","",表紙!AT2) -> 45448 | AY2: =IF(表紙!AY2="","",表紙!AY2) -> DuNT | BC2: =IF(表紙!BC2="","",表紙!BC2) -> 45448 | BH2: =IF(表紙!BH2="","",表紙!BH2) -> 0.1
A4: 機能カテゴリ | H4: =IF(表紙!H4="","",表紙!H4) -> 04_商品採用店舗確認 | U4: 項目 | Z4: =IF(表紙!Z4="","",表紙!Z4) -> 機能設計書 | AP4: {=RIGHT(CELL("filename",$A$1),LEN(CELL("filename",$A$1))-FIND("]",CELL("filename",$A$1)))} -> 改訂履歴
B8: ■改訂履歴
B10: 更新日 | H10: 更新者 | O10: 版数 | S10: 更新内容 | AX10: 承認日 | BD10: 承認者
B11: 45448 | H11: DuNT | O11: 0.1 | S11: 新規作成

Sheet SC0401
A1: システム名 | K1: システム種別 | W1: =IF(表紙!W1="","",表紙!W1) -> 詳細設計書 | AP1: 作成者 | AT1: 作成日 | AY1: 更新者 | BC1: 更新日 | BH1: 版数
A2: =IF(表紙!A2="","",表紙!A2) -> POSサーバー | K2: =IF(表紙!K2="","",表紙!K2) -> POSサーバー | AP2: =IF(表紙!AP2="","",表紙!AP2) -> DuNT | AT2: =IF(表紙!AT2="","",表紙!AT2) -> 45448 | AY2: =IF(表紙!AY2="","",表紙!AY2) -> DuNT | BC2: =IF(表紙!BC2="","",表紙!BC2) -> 45448 | BH2: =IF(表紙!BH2="","",表紙!BH2) -> 0.1
A4: 機能カテゴリ | H4: =IF(表紙!H4="","",表紙!H4) -> 04_商品採用店舗確認 | U4: 項目 | Z4: =IF(表紙!Z4="","",表紙!Z4) -> 機能設計書 | AP4: =MID(CELL("filename",A1),FIND("]",CELL("filename",A1))+1,255) -> SC0401
A7: ■機能説明
A9: 画面ID | E9: SC0401 | O9: 画面名 | U9: ■主な商品採用店舗画面
A11: イベントID | G11: SC0401-01 | M11: 画面初期化
A12: インプット | M12: 処理概要 | AU12: アウトプット | BF12: 参照情報
BF14: 20_画面設計書_04_商品採用店舗確認.xlsx
N15: 1. 画面項目の初期化を実行する。
O16: 20_画面設計書_04_商品採用店舗確認.xlsxのファイルをご参照ください。
N17: 2. 選択中の店舗がウエルシアに連携されているかを確認する。
O18: ・ウエルシアに連携されていない場合、「選択された店舗はテナント連携が行われている店舗で はないため、当機能は利用できません。」エラーダイアログを表示する。
O21: ・ウエルシアに連携されている場合、フローを続行する。
A28: イベントID | G28: SC0401-02 | M28: 商品採用店舗検索
A29: インプット | M29: 処理概要 | AU29: アウトプット | BF29: 参照情報
BF31: 20_画面設計書_04_商品採用店舗確認.xlsx 40_API設計書_AP1506.xlsx
N32: 1. PLUコード入力項目を確認する。
O33: PLUコードの文字数が13文字足りない場合、PLUコードの前に「0」を自動的に追加する。
O34: PLUコードの文字数が13文字の場合、KN1501_商品提案機能を実行する。
N35: 2. KN1501_商品提案機能
O37: 1.1 AP1506API呼出処理を実行する。
O39: APIのパラメータ | V39: パラメータの値
O40: PLU | V40: ユーザーが画面上で入力した商品のPLU コード
O42: 1.2 返却された結果情報
O43: ①．「更新成功」の場合
P44: 返却された結果
P45: 1. status_code | AA45: 200 (OK)
P46: 2. message | AA46: ブランク
P47: 3. data | AA47: 商品情報
P49: 40_API設計書_AP1506.xlsxのレスポンスをご参照ください。
P51: 20_画面設計書_04_商品採用店舗確認.xlsxのファイルに従って画面に返却されたAPIレスポンスのマッピングを行う。
P53: 注意：商品に親PLUがある場合、ユーザーが入力した子PLUを親PLUに置き換えて画面に表示する。
O55: ②．エラーの場合、以下のように実行する。
P56: APIエラーの共通表示処理を実行する。
A69: イベントID | G69: SC0401-03 | M69: 入力情報クリア
A70: インプット | M70: 処理概要 | AU70: アウトプット | BF70: 参照情報
BF72: 20_画面設計書_04_商品採用店舗確認.xlsx
N73: 1. 画面に表示されている商品情報を全てクリアする。
N74: 画面を初期状態で表示する。
A81: イベントID | G81: SC0401-04 | M81: 商品売上計算店舗対象変更情報保存
...

Sheet テンプレート
A1: システム名 | K1: システム種別 | W1: =IF(表紙!W1="","",表紙!W1) -> 詳細設計書 | AP1: 作成者 | AT1: 作成日 | AY1: 更新者 | BC1: 更新日 | BH1: 版数
A2: =IF(表紙!A2="","",表紙!A2) -> POSサーバー | K2: =IF(表紙!K2="","",表紙!K2) -> POSサーバー | AP2: =IF(表紙!AP2="","",表紙!AP2) -> DuNT | AT2: =IF(表紙!AT2="","",表紙!AT2) -> 45448 | AY2: =IF(表紙!AY2="","",表紙!AY2) -> DuNT | BC2: =IF(表紙!BC2="","",表紙!BC2) -> 45448 | BH2: =IF(表紙!BH2="","",表紙!BH2) -> 0.1
A4: 機能カテゴリ | H4: =IF(表紙!H4="","",表紙!H4) -> 04_商品採用店舗確認 | U4: 項目 | Z4: =IF(表紙!Z4="","",表紙!Z4) -> 機能設計書 | AP4: =MID(CELL("filename",A1),FIND("]",CELL("filename",A1))+1,255) -> テンプレート
A7: ■機能説明
A9: 画面ID | E9: SCxxxxxx | O9: 画面名
A11: イベントID | G11: KN1010201
A12: インプット | M12: 処理概要 | AU12: アウトプット | BF12: 参照情報
N15: 1. ロジック1
N26: 2. ロジック2
