Workbook

Sheet 表紙
A1: システム名 | K1: システム種別 | W1: 詳細設計書 | AP1: 作成者 | AT1: 作成日 | AY1: 更新者 | BC1: 更新日 | BH1: 版数
A2: POSサーバー | K2: POSサーバ | AP2: =改訂履歴!$H$11 -> TuyenNH | AT2: =改訂履歴!$B$11 -> 45645 | AY2: =LOOKUP(2,1/(改訂履歴!H11:H30000<>""),改訂履歴!H11:H30000) -> TuyenNH | BC2: =LOOKUP(2,1/(改訂履歴!B11:B30000<>""),改訂履歴!B11:B30000) -> 45645 | BH2: =LOOKUP(2,1/(改訂履歴!O11:O30000<>""),改訂履歴!O11:O30000) -> 0.1
A4: 機能カテゴリ | H4: 08_カテゴリ値引／割引設定 | U4: 項目 | Z4: 機能設計書 | AP4: {=RIGHT(CELL("filename",$A$1),LEN(CELL("filename",$A$1))-FIND("]",CELL("filename",$A$1)))} -> 表紙
L16: POSサーバーの基本設計書
L24: =K2&"/"&H4&"/"&Z4 -> POSサーバ/08_カテゴリ値引／割引設定/機能設計書
Q44: 承認日 | AA44: 承認者 | AQ44: 版数

Sheet 改訂履歴
A1: システム名 | K1: システム種別 | W1: =IF(表紙!W1="","",表紙!W1) -> 詳細設計書 | AP1: 作成者 | AT1: 作成日 | AY1: 更新者 | BC1: 更新日 | BH1: 版数
A2: =IF(表紙!A2="","",表紙!A2) -> POSサーバー | K2: =IF(表紙!K2="","",表紙!K2) -> POSサーバ | AP2: =IF(表紙!AP2="","",表紙!AP2) -> TuyenNH | AT2: =IF(表紙!AT2="","",表紙!AT2) -> 45645 | AY2: =IF(表紙!AY2="","",表紙!AY2) -> TuyenNH | BC2: =IF(表紙!BC2="","",表紙!BC2) -> 45645 | BH2: =IF(表紙!BH2="","",表紙!BH2) -> 0.1
A4: 機能カテゴリ | H4: =IF(表紙!H4="","",表紙!H4) -> 08_カテゴリ値引／割引設定 | U4: 項目 | Z4: =IF(表紙!Z4="","",表紙!Z4) -> 機能設計書 | AP4: {=RIGHT(CELL("filename",$A$1),LEN(CELL("filename",$A$1))-FIND("]",CELL("filename",$A$1)))} -> 改訂履歴
B8: ■改訂履歴
B10: 更新日 | H10: 更新者 | O10: 版数 | S10: 更新内容 | AX10: 承認日 | BD10: 承認者
B11: 45645 | H11: TuyenNH | O11: 0.1 | S11: 新規

Sheet SC0801
A1: システム名 | K1: システム種別 | W1: =IF(表紙!W1="","",表紙!W1) -> 詳細設計書 | AP1: 作成者 | AT1: 作成日 | AY1: 更新者 | BC1: 更新日 | BH1: 版数
A2: =IF(表紙!A2="","",表紙!A2) -> POSサーバー | K2: =IF(表紙!K2="","",表紙!K2) -> POSサーバ | AP2: =IF(表紙!AP2="","",表紙!AP2) -> TuyenNH | AT2: =IF(表紙!AT2="","",表紙!AT2) -> 45645 | AY2: =IF(表紙!AY2="","",表紙!AY2) -> TuyenNH | BC2: =IF(表紙!BC2="","",表紙!BC2) -> 45645 | BH2: =IF(表紙!BH2="","",表紙!BH2) -> 0.1
A4: 機能カテゴリ | H4: =IF(表紙!H4="","",表紙!H4) -> 08_カテゴリ値引／割引設定 | U4: 項目 | Z4: =IF(表紙!Z4="","",表紙!Z4) -> 機能設計書 | AP4: =MID(CELL("filename",A1),FIND("]",CELL("filename",A1))+1,255) -> SC0801
A7: ■機能説明
A9: 画面ID | E9: SC0801 | O9: 画面名 | U9: カテゴリ値引・割引設定
A11: イベントID | G11: SC0801_01 | M11: 画面初期化
A12: インプット | M12: 処理概要 | AU12: 出力 | BF12: 参照情報
BF14: ▪20_画面設計_08_カテゴリ値引・割引設定.xlsx
N15: 1. 画面項目の初期化を実行する。
O16: 20_画面設計_08_カテゴリ値引・割引設定.xlsxをご参照ください。
A22: イベントID | G22: SC0801_02 | M22: カテゴリ値引・割引作成
A23: インプット | M23: 処理概要 | AU23: 出力 | BF23: 参照情報
BF25: ▪20_画面設計_08_カテゴリ値引・割引設定.xlsx
N26: 1. 新規作成モードに切り替える。
O27: 20_画面設計_08_カテゴリ値引・割引設定.xlsxをご参照ください。
A34: イベントID | G34: SC0801_03 | M34: カテゴリ値引・割引検索
A35: インプット | M35: 処理概要 | AU35: 出力 | BF35: 参照情報
BF37: ▪20_画面設計_08_カテゴリ値引・割引設定.xlsx ▪40_API設計_AP0801_カテゴリ値引・割引一覧取得.xlsx
N38: 1. KN0801_自動割引一覧取得機能
O39: 1.1 MD0801モーダルを開き、API「AP0801_カテゴリ値引・割引一覧取得」呼出処理を実行する。
P40: APIのパラメータ | W40: パラメータの値
P41: selected_store | W41: 選択された店舗
P43: 40_API設計_AP0801_カテゴリ値引・割引一覧取得.xlsxをご参照ください。
O44: 1.2 返却された結果情報
P45: ▪商品情報取得が成功した場合、
Q46: ・返却レスポンスはAPI_AP0801_カテゴリ値引・割引一覧取得.xlsxをご参照ください。
Q47: ・以下の画面設計に従って画面に返されるAPIレスポンスのマッピングを実行する。
R48: 20_画面設計_08_カテゴリ値引・割引設定.xlsx
P50: ▪商品情報取得が失敗した場合、
Q51: ・返却レスポンスは40_API設計_AP0801_カテゴリ値引・割引一覧取得.xlsxをご参照ください。
Q52: ・20_画面設計_08_カテゴリ値引・割引設定.xlsxの説明に従ってエラーメッセージを画面に表示する。
A57: イベントID | G57: SC0801_04 | M57: 商品階層表示
A58: インプット | M58: 処理概要 | AU58: 出力 | BF58: 参照情報
BF60: ▪20_画面設計_08_カテゴリ値引・割引設定.xlsx ▪ 40_API設計_AP1507_階層一覧取得.xlsx
N61: 1. KN2501_商品部門一覧取得機能
O62: 1.1 API「AP1507_階層一覧取得」呼出処理を実行する。
P63: APIのパラメータ | W63: パラメータの値
P64: selected_store | W64: 選択された店舗
P65: level | W65: 1
P66: filter-code | W66: 画面に入力された部門コード
...

Sheet MD0801
A1: システム名 | K1: システム種別 | W1: =IF(表紙!W1="","",表紙!W1) -> 詳細設計書 | AP1: 作成者 | AT1: 作成日 | AY1: 更新者 | BC1: 更新日 | BH1: 版数
A2: =IF(表紙!A2="","",表紙!A2) -> POSサーバー | K2: =IF(表紙!K2="","",表紙!K2) -> POSサーバ | AP2: =IF(表紙!AP2="","",表紙!AP2) -> TuyenNH | AT2: =IF(表紙!AT2="","",表紙!AT2) -> 45645 | AY2: =IF(表紙!AY2="","",表紙!AY2) -> TuyenNH | BC2: =IF(表紙!BC2="","",表紙!BC2) -> 45645 | BH2: =IF(表紙!BH2="","",表紙!BH2) -> 0.1
A4: 機能カテゴリ | H4: =IF(表紙!H4="","",表紙!H4) -> 08_カテゴリ値引／割引設定 | U4: 項目 | Z4: =IF(表紙!Z4="","",表紙!Z4) -> 機能設計書 | AP4: =MID(CELL("filename",A1),FIND("]",CELL("filename",A1))+1,255) -> MD0801
A7: ■機能説明
A9: 画面ID | E9: MD0102 | O9: 画面名 | U9: プロモーション一覧モーダル
A11: イベントID | G11: MD0801_01 | M11: モーダルを初期化する。
A12: インプット | M12: 処理概要 | AU12: 出力 | BF12: 参照情報
BF14: ▪20_画面設計_08_カテゴリ値引・割引設定.xlsx
N15: 1. 画面項目の初期化を実行する。
O16: 20_画面設計_08_カテゴリ値引・割引設定.xlsxをご参照ください。
A22: イベントID | G22: MD0801_02 | M22: カテゴリ値引・割引情報検索
A23: インプット | M23: 処理概要 | AU23: 出力 | BF23: 参照情報
BF25: ▪20_画面設計_08_カテゴリ値引・割引設定.xlsx 40_API設計_AP0802_カテゴリ値引・割引詳細取得.xlsx
N26: 1. KN0802_自動割引詳細取得機能
O27: 1.1 API「AP0802_カテゴリ値引・割引詳細取得」呼出処理を実行する。
P28: APIのパラメータ | W28: パラメータの値
P29: store_code | W29: 選択された店舗
P30: record_id | W30: レコードID
P32: 40_API設計_AP0802_カテゴリ値引・割引詳細取得.xlsxをご参照ください。
O33: 1.2 返却された結果情報
P34: ▪商品情報取得が成功した場合、
Q35: ・返却レスポンスは40_API設計_AP0802_カテゴリ値引・割引詳細取得.xlsxをご参照ください。
Q36: ・以下の画面設計に従って画面に返されるAPIレスポンスのマッピングを実行する。
R37: 20_画面設計_08_カテゴリ値引・割引設定.xlsx
P39: ▪商品情報取得が失敗した場合、
Q40: ・返却レスポンスは40_API設計_AP0802_カテゴリ値引・割引詳細取得.xlsxをご参照ください。
Q41: ・20_画面設計_08_カテゴリ値引・割引設定.xlsxの説明に従ってエラーメッセージを画面に表示する。
A46: イベントID | G46: MD0801_02 | M46: 前画面
A47: インプット | M47: 処理概要 | AU47: 出力 | BF47: 参照情報
BF49: ▪20_画面設計_08_カテゴリ値引・割引設定.xlsx
N50: 1. MD0801_カテゴリ値引／割引情報モーダルを閉じる。
O51: API_AP0802_カテゴリ値引・割引詳細取得を呼び出さない。
