Workbook

Sheet 表紙
A1: システム名 | K1: システム種別 | W1: 詳細設計書 | AP1: 作成者 | AT1: 作成日 | AY1: 更新者 | BC1: 更新日 | BH1: 版数
A2: POSサーバー | K2: POSサーバ | AP2: =改訂履歴!$H$11 -> TuyenNH | AT2: =改訂履歴!$B$11 -> 45462 | AY2: =LOOKUP(2,1/(改訂履歴!H11:H30001<>""),改訂履歴!H11:H30001) -> AnhDD | BC2: =LOOKUP(2,1/(改訂履歴!B11:B30001<>""),改訂履歴!B11:B30001) -> 45630 | BH2: =LOOKUP(2,1/(改訂履歴!O11:O30001<>""),改訂履歴!O11:O30001) -> 0.43
A4: 機能カテゴリ | H4: 40_従業員設定 | U4: 項目 | Z4: 機能設計書 | AP4: {=RIGHT(CELL("filename",$A$1),LEN(CELL("filename",$A$1))-FIND("]",CELL("filename",$A$1)))} -> 表紙
L16: POSサーバーの基本設計書
L24: =K2&"/"&H4&"/"&Z4 -> POSサーバ/40_従業員設定/機能設計書
Q44: 承認日 | AA44: 承認者 | AQ44: 版数

Sheet 改訂履歴
A1: システム名 | K1: システム種別 | W1: =IF(表紙!W1="","",表紙!W1) -> 詳細設計書 | AP1: 作成者 | AT1: 作成日 | AY1: 更新者 | BC1: 更新日 | BH1: 版数
A2: =IF(表紙!A2="","",表紙!A2) -> POSサーバー | K2: =IF(表紙!K2="","",表紙!K2) -> POSサーバ | AP2: =IF(表紙!AP2="","",表紙!AP2) -> TuyenNH | AT2: =IF(表紙!AT2="","",表紙!AT2) -> 45462 | AY2: =IF(表紙!AY2="","",表紙!AY2) -> AnhDD | BC2: =IF(表紙!BC2="","",表紙!BC2) -> 45630 | BH2: =IF(表紙!BH2="","",表紙!BH2) -> 0.43
A4: 機能カテゴリ | H4: =IF(表紙!H4="","",表紙!H4) -> 40_従業員設定 | U4: 項目 | Z4: =IF(表紙!Z4="","",表紙!Z4) -> 機能設計書 | AP4: {=RIGHT(CELL("filename",$A$1),LEN(CELL("filename",$A$1))-FIND("]",CELL("filename",$A$1)))} -> 改訂履歴
B8: ■改訂履歴
B10: 更新日 | H10: 更新者 | O10: 版数 | S10: 更新内容 | AX10: 承認日 | BD10: 承認者
B11: 45462 | H11: TuyenNH | O11: 0.1 | S11: 新規
B13: 45459 | H13: TuyenNH | O13: 0.2 | S13: 従業員名の検索と新規作成・更新時に「,」のバリデーションチェックを削除する。
S14: シート：SC4001、MD4001、MD4002
B15: 45545 | H15: DuNT | O15: 0.3 | S15: SC4001: 検索条件のバリデーションチェックを削除し、削除取消を追加し、最大1000件の制限を削除する。
S16: MD4001: 入力最大長のバリデーションチェックを削除する。
S17: MD4002: 入力最大長のバリデーションチェックを削除し、数字のみの入力のバリデーションチェックを削除する
B18: 45555 | H18: DuNT | O18: 0.4 | S18: SC4001: CSV取込イベントを追加
B20: 45613 | H20: DuNT | O20: 0.41 | S20: SC4001：従業員バーコードPDFファイル名を追加する。
B22: 45629 | H22: DuNT | O22: 0.42 | S22: バーコード生成形式を追加
B24: 45630 | H24: AnhDD | O24: 0.43 | S24: CSVファイル形式のバリデーションチェックエラーを修正

Sheet SC4001
A1: システム名 | K1: システム種別 | W1: =IF(表紙!W1="","",表紙!W1) -> 詳細設計書 | AP1: 作成者 | AT1: 作成日 | AY1: 更新者 | BC1: 更新日 | BH1: 版数
A2: =IF(表紙!A2="","",表紙!A2) -> POSサーバー | K2: =IF(表紙!K2="","",表紙!K2) -> POSサーバ | AP2: =IF(表紙!AP2="","",表紙!AP2) -> TuyenNH | AT2: =IF(表紙!AT2="","",表紙!AT2) -> 45462 | AY2: =IF(表紙!AY2="","",表紙!AY2) -> AnhDD | BC2: =IF(表紙!BC2="","",表紙!BC2) -> 45630 | BH2: =IF(表紙!BH2="","",表紙!BH2) -> 0.43
A4: 機能カテゴリ | H4: =IF(表紙!H4="","",表紙!H4) -> 40_従業員設定 | U4: 項目 | Z4: =IF(表紙!Z4="","",表紙!Z4) -> 機能設計書 | AP4: =MID(CELL("filename",A1),FIND("]",CELL("filename",A1))+1,255) -> SC4001
A7: ■機能説明
A9: 画面ID | E9: SC4001 | O9: 画面名 | U9: 従業員一覧画面
A11: イベントID | G11: SC4001_01 | M11: 画面初期化
A12: インプット | M12: 処理概要 | AU12: 出力 | BF12: 参照情報
BF14: ▪20_画面設計_40_従業員設定.xlsx
N15: 1. 画面項目の初期化を実行する。
O16: 20_画面設計_40_従業員設定.xlsxのファイルをご参照ください。
A22: イベントID | G22: SC4001_02 | M22: 従業員情報検索
A23: インプット | M23: 処理概要 | AU23: 出力 | BF23: 参照情報
BF25: ▪20_画面設計_40_従業員設定.xlsx ▪ 40_API設計_AP4001_店舗従業員一覧取得.xlsx
N26: 1. KN4001_従業員情報一覧取得機能
O27: 1.1 「AP4001」API呼出処理を実行する。
P28: APIのパラメータ | W28: パラメータの値
P29: selected_stores | W29: 選択された店舗一覧
P30: employee_code | W30: 画面で入力した従業員コード
P31: employee_code_type | W31: 画面で選択した従業員コードの検索タイプ
P32: employee_name | W32: 画面で入力した従業員名
P33: employee_name_type | W33: 画面で選択した従業員名の検索タイプ
P35: 「40_API設計_AP4001_店舗従業員一覧取得.xlsx」をご参照ください。
O37: 1.2 返却された結果情報
P38: ▪従業員一覧取得が成功した場合、
Q39: ・返されるレスポンスは「40_API設計_AP4001_店舗従業員一覧取得.xlsx」をご参照ください。
Q40: ・以下の画面設計に従って画面に返されるAPIレスポンスのマッピングを実行する。
R41: 20_画面設計_40_従業員設定.xlsx
P43: ▪ 従業員一覧取得が失敗した場合、
Q44: ・返されるレスポンスは「40_API設計_AP4001_店舗従業員一覧取得.xlsx」をご参照ください。
Q45: ・エラーメッセージを画面に表示する。
A50: イベントID | G50: SC4001_03 | M50: 従業員バーコード帳票印刷
A51: インプット | M51: 処理概要 | AU51: 出力 | BF51: 参照情報
BF53: ▪20_画面設計_40_従業員設定.xlsx
N54: 1. 帳票印刷条件を確認する。
O55: ▪バリデーションチェックのエラーがある。
P56: ・従業員が選択されていない場合、message = MSG_VAL_008を表示する。
O57: ▪バリデーションチェックのエラーがない：ステップ2を実行する。
N58: 2. 従業員バーコードリストのPDFファイルを作成する。
O59: ▪カスミ会社の従業員の場合、
P60: 以下の形式でバーコードを作成する。
...

Sheet MD4001
A1: システム名 | K1: システム種別 | W1: =IF(表紙!W1="","",表紙!W1) -> 詳細設計書 | AP1: 作成者 | AT1: 作成日 | AY1: 更新者 | BC1: 更新日 | BH1: 版数
A2: =IF(表紙!A2="","",表紙!A2) -> POSサーバー | K2: =IF(表紙!K2="","",表紙!K2) -> POSサーバ | AP2: =IF(表紙!AP2="","",表紙!AP2) -> TuyenNH | AT2: =IF(表紙!AT2="","",表紙!AT2) -> 45462 | AY2: =IF(表紙!AY2="","",表紙!AY2) -> AnhDD | BC2: =IF(表紙!BC2="","",表紙!BC2) -> 45630 | BH2: =IF(表紙!BH2="","",表紙!BH2) -> 0.43
A4: 機能カテゴリ | H4: =IF(表紙!H4="","",表紙!H4) -> 40_従業員設定 | U4: 項目 | Z4: =IF(表紙!Z4="","",表紙!Z4) -> 機能設計書 | AP4: =MID(CELL("filename",A1),FIND("]",CELL("filename",A1))+1,255) -> MD4001
A7: ■機能説明
A9: 画面ID | E9: MD4001 | O9: 画面名 | U9: 従業員編集モーダル
A11: イベントID | G11: SC4001_01 | M11: 画面初期化
A12: インプット | M12: 処理概要 | AU12: 出力 | BF12: 参照情報
BF14: ▪20_画面設計_40_従業員設定.xlsx
N15: 1. 画面項目の初期化を実行する。
O16: 20_画面設計_40_従業員設定.xlsxのファイルをご参照ください。
A22: イベントID | G22: MD4001-02 | M22: 従業員一覧画面に戻る。
A23: インプット | M23: 処理概要 | AU23: 出力 | BF23: 参照情報
BF25: ▪20_画面設計_40_従業員設定.xlsx
N26: 1. MD4001モーダルを閉じてSC4001画面に戻る。
A33: イベントID | G33: SC4001_03 | M33: 従業員情報更新
A34: インプット | M34: 処理概要 | AU34: 出力 | BF34: 参照情報
BF36: ▪20_画面設計_40_従業員設定.xlsx
N37: 1. 項目のバリデーションチェックを行う。
O38: ▪バリデーションチェックのエラーがある：
P39: ・「従業員名」項目：
Q40: 入力必須のバリデーションチェック：メッセージ = MSG_VAL_001。その中 ：{0}が「従業員名」である。
O43: ▪バリデーションチェックのエラーがない：
P44: ・SC4001画面に戻り、変更情報を表示する。

Sheet MD4002
A1: システム名 | K1: システム種別 | W1: =IF(表紙!W1="","",表紙!W1) -> 詳細設計書 | AP1: 作成者 | AT1: 作成日 | AY1: 更新者 | BC1: 更新日 | BH1: 版数
A2: =IF(表紙!A2="","",表紙!A2) -> POSサーバー | K2: =IF(表紙!K2="","",表紙!K2) -> POSサーバ | AP2: =IF(表紙!AP2="","",表紙!AP2) -> TuyenNH | AT2: =IF(表紙!AT2="","",表紙!AT2) -> 45462 | AY2: =IF(表紙!AY2="","",表紙!AY2) -> AnhDD | BC2: =IF(表紙!BC2="","",表紙!BC2) -> 45630 | BH2: =IF(表紙!BH2="","",表紙!BH2) -> 0.43
A4: 機能カテゴリ | H4: =IF(表紙!H4="","",表紙!H4) -> 40_従業員設定 | U4: 項目 | Z4: =IF(表紙!Z4="","",表紙!Z4) -> 機能設計書 | AP4: =MID(CELL("filename",A1),FIND("]",CELL("filename",A1))+1,255) -> MD4002
A7: ■機能説明
A9: 画面ID | E9: MD4002 | O9: 画面名 | U9: 従業員新規作成モーダル
A11: イベントID | G11: SC4002_01 | M11: 画面初期化
A12: インプット | M12: 処理概要 | AU12: 出力 | BF12: 参照情報
BF14: ▪20_画面設計_40_従業員設定.xlsx
N15: 1. 画面項目の初期化を実行する。
O16: 20_画面設計_40_従業員設定.xlsxのファイルをご参照ください。
A22: イベントID | G22: MD4002-02 | M22: 従業員一覧画面に戻る。
A23: インプット | M23: 処理概要 | AU23: 出力 | BF23: 参照情報
BF25: ▪20_画面設計_40_従業員設定.xlsx
N26: 1. MD4002モーダルを閉じてSC4001画面に戻る。
A33: イベントID | G33: SC4002_03 | M33: 従業員情報作成
A34: インプット | M34: 処理概要 | AU34: 出力 | BF34: 参照情報
BF36: ▪20_画面設計_40_従業員設定.xlsx ▪ 40_API設計_AP4003_従業員重複確認.xlsx
N37: 1. 項目のバリデーションチェックを行う。
O38: ▪バリデーションチェックのエラーがある：
P39: ・「店舗」項目：
Q40: ・入力必須のバリデーションチェック：メッセージ = MSG_VAL_001。その中 ：{0}が店舗である。
P41: ・「従業員コード」項目：
Q42: ・入力必須のバリデーションチェック：メッセージ = MSG_VAL_001。その中 ：{0}が「従業員コード」である。
P43: ・「従業員名」項目：
Q44: 入力必須のバリデーションチェック：メッセージ = MSG_VAL_001。その中 ：{0}が「従業員名」である。
P45: ▪バリデーションチェックのエラーがない：KN4004_従業員重複確認機能を実行する。
O46: 2. KN4004_従業員重複確認機能
P47: 2.1 作成された従業員重複を画面上の表示データ一覧で確認する。
Q48: ▪ 重複した場合、message = MSG_ERR_003を表示する。
Q49: ▪ 重複しない場合、「AP4003」APIを呼び出してデータベースのデータ重複を確認する。
P50: 2.2 「AP4003」API呼出処理を実行する。
Q51: APIのパラメータ | X51: パラメータの値
Q52: selected_store | X52: 選択された店舗
Q53: employee_code | X53: 画面で入力した従業員コード
Q55: 「40_API設計_AP4003_従業員重複確認.xlsx」をご参照ください。
P57: 2.3 返却された結果情報
Q58: ▪成功した場合、
R59: ・返却レスポンスは「40_API設計_AP4003_従業員重複確認.xlsx」をご参照ください。
R60: ・重複した場合、message = MSG_ERR_003を表示する。
R61: ・重複しない場合、SC4001画面に戻り、作成された従業員を表示する。
...

Sheet テンプレート
A1: システム名 | K1: システム種別 | W1: =IF(表紙!W1="","",表紙!W1) -> 詳細設計書 | AP1: 作成者 | AT1: 作成日 | AY1: 更新者 | BC1: 更新日 | BH1: 版数
A2: =IF(表紙!A2="","",表紙!A2) -> POSサーバー | K2: =IF(表紙!K2="","",表紙!K2) -> POSサーバ | AP2: =IF(表紙!AP2="","",表紙!AP2) -> TuyenNH | AT2: =IF(表紙!AT2="","",表紙!AT2) -> 45462 | AY2: =IF(表紙!AY2="","",表紙!AY2) -> AnhDD | BC2: =IF(表紙!BC2="","",表紙!BC2) -> 45630 | BH2: =IF(表紙!BH2="","",表紙!BH2) -> 0.43
A4: 機能カテゴリ | H4: =IF(表紙!H4="","",表紙!H4) -> 40_従業員設定 | U4: 項目 | Z4: =IF(表紙!Z4="","",表紙!Z4) -> 機能設計書 | AP4: =MID(CELL("filename",A1),FIND("]",CELL("filename",A1))+1,255) -> テンプレート
A7: ■機能説明
A9: 画面ID | E9: SCxxxxxx | O9: 画面名
A11: イベントID | G11: KN1010201
A12: インプット | M12: 処理概要 | AU12: 出力 | BF12: 参照情報
N15: 1. ロジック1
N26: 2. ロジック2
