Workbook

Sheet 表紙
A1: システム名 | K1: システム種別 | W1: 詳細設計書 | AP1: 作成者 | AT1: 作成日 | AY1: 更新者 | BC1: 更新日 | BH1: 版数
A2: POSサーバー | K2: POSサーバ | AP2: =改訂履歴!$H$11 -> TuyenNH | AT2: =改訂履歴!$B$11 -> 45519 | AY2: =LOOKUP(2,1/(改訂履歴!H11:H30000<>""),改訂履歴!H11:H30000) -> TuyenNH | BC2: =LOOKUP(2,1/(改訂履歴!B11:B30000<>""),改訂履歴!B11:B30000) -> 45519 | BH2: =LOOKUP(2,1/(改訂履歴!O11:O30000<>""),改訂履歴!O11:O30000) -> 0.1
A4: 機能カテゴリ | H4: 02_緊急売価変更 | U4: 項目 | Z4: 機能設計書 | AP4: {=RIGHT(CELL("filename",$A$1),LEN(CELL("filename",$A$1))-FIND("]",CELL("filename",$A$1)))} -> 表紙
L16: POSサーバーの詳細設計書
L24: =K2&"/"&H4&"/"&Z4 -> POSサーバ/02_緊急売価変更/機能設計書
Q44: 承認日 | AA44: 承認者 | AQ44: 版数

Sheet 改訂履歴
A1: システム名 | K1: システム種別 | W1: =IF(表紙!W1="","",表紙!W1) -> 詳細設計書 | AP1: 作成者 | AT1: 作成日 | AY1: 更新者 | BC1: 更新日 | BH1: 版数
A2: =IF(表紙!A2="","",表紙!A2) -> POSサーバー | K2: =IF(表紙!K2="","",表紙!K2) -> POSサーバ | AP2: =IF(表紙!AP2="","",表紙!AP2) -> TuyenNH | AT2: =IF(表紙!AT2="","",表紙!AT2) -> 45519 | AY2: =IF(表紙!AY2="","",表紙!AY2) -> TuyenNH | BC2: =IF(表紙!BC2="","",表紙!BC2) -> 45519 | BH2: =IF(表紙!BH2="","",表紙!BH2) -> 0.1
A4: 機能カテゴリー | H4: =IF(表紙!H4="","",表紙!H4) -> 02_緊急売価変更 | U4: 項目 | Z4: =IF(表紙!Z4="","",表紙!Z4) -> 機能設計書 | AP4: {=RIGHT(CELL("filename",$A$1),LEN(CELL("filename",$A$1))-FIND("]",CELL("filename",$A$1)))} -> 改訂履歴
B8: ■改訂履歴
B10: 更新日 | H10: 更新者 | O10: 版数 | S10: 更新内容 | AX10: 承認日 | BD10: 承認者
B11: 45519 | H11: TuyenNH | O11: 0.1 | S11: 新規

Sheet SC0201
A1: システム名 | K1: システム種別 | W1: =IF(表紙!W1="","",表紙!W1) -> 詳細設計書 | AP1: 作成者 | AT1: 作成日 | AY1: 更新者 | BC1: 更新日 | BH1: 版数
A2: =IF(表紙!A2="","",表紙!A2) -> POSサーバー | K2: =IF(表紙!K2="","",表紙!K2) -> POSサーバ | AP2: =IF(表紙!AP2="","",表紙!AP2) -> TuyenNH | AT2: =IF(表紙!AT2="","",表紙!AT2) -> 45519 | AY2: =IF(表紙!AY2="","",表紙!AY2) -> TuyenNH | BC2: =IF(表紙!BC2="","",表紙!BC2) -> 45519 | BH2: =IF(表紙!BH2="","",表紙!BH2) -> 0.1
A4: 機能カテゴリ | H4: =IF(表紙!H4="","",表紙!H4) -> 02_緊急売価変更 | U4: 項目 | Z4: =IF(表紙!Z4="","",表紙!Z4) -> 機能設計書 | AP4: =MID(CELL("filename",A1),FIND("]",CELL("filename",A1))+1,255) -> SC0201
A7: ■機能説明
A9: 画面ID | E9: SC0201 | O9: 画面名 | U9: 緊急売価変更
A11: イベントID | G11: SC0201_01 | M11: 画面初期化
A12: インプット | M12: 処理概要 | AU12: 出力 | BF12: 参照情報
BF14: ▪20_画面設計_02_緊急売価変更.xlsx
N15: 1. 画面項目の初期化を実行する。
O16: 20_画面設計_02_緊急売価変更.xlsxをご参照ください。
A22: イベントID | G22: SC0201_02 | M22: 部門提案
A23: インプット | M23: 処理概要 | AU23: 出力 | BF23: 参照情報
BF25: ▪20_画面設計_02_緊急売価変更.xlsx ▪40_API設計_AP1507_階層一覧取得.xlsx
N26: 1. AP1507を使用して品種を検索する。
O27: 入力桁数が2桁未満の場合、「0」を追加して、AP1507_品種検索のAPIを呼び出す。
O29: 1.1 AP1507API呼出処理を実行する。
P30: APIのパラメータ | W30: パラメータの値
P31: level | W31: 1
P32: filter-code | W32: 画面で入力された値
O34: 1.2 返却された結果情報
P35: ①．成功した場合：
Q36: 返却された結果
Q37: 1. status_code | AB37: 200 (OK)
Q38: 2. message | AB38: ブランク
Q39: 3. data | AB39: 品種一覧
P41: ②．エラーの場合、以下のように実行する。
Q42: 401エラーの場合、以下のファイルの説明に従ってエラー表示処理を実行する（エラーメッセージ = MSG_ER_001）
Q43: 20_画面設計_02_緊急売価変更.xlsx
Q44: 他のエラーの場合、APIエラーの共通表示処理を実行する。
N45: 2. 画面項目の「AP1507」APIレスポンスをマッピングする。
O46: 20_画面設計_02_緊急売価変更.xlsxをご参照ください。
A51: イベントID | G51: SC0201_03 | M51: 緊急売価検索
A52: インプット | M52: 処理概要 | AU52: 出力 | BF52: 参照情報
BF54: ▪20_画面設計_02_緊急売価変更.xlsx 40_API設計_AP0201_緊急売価リスト取得.xlsx
N55: 1. 検索条件を確認する。
O56: ▪バリデーションチェックのエラーがある：
P57: ・「予約日付」項目:
Q58: 日付が存在せずに形式が不正な場合、 MSG_VAL_003を表示する。
Q59: 過去日の場合、MSG_VAL_037を表示する。
O61: ▪バリデーションチェックのエラーがない場合：KN0201_部門コード別緊急売価検索機能を実行する。
...
