Workbook

Sheet 表紙
A1: システム名 | K1: システム種別 | W1: 詳細設計書 | AP1: 作成者 | AT1: 作成日 | AY1: 更新者 | BC1: 更新日 | BH1: 版数
A2: POSサーバー | K2: POSサーバ | AP2: =改訂履歴!$H$11 -> SonMNT | AT2: =改訂履歴!$B$11 -> 45468 | AY2: =LOOKUP(2,1/(改訂履歴!H11:H30000<>""),改訂履歴!H11:H30000) -> AnhTTP | BC2: =LOOKUP(2,1/(改訂履歴!B11:B30000<>""),改訂履歴!B11:B30000) -> 45643 | BH2: =LOOKUP(2,1/(改訂履歴!O11:O30000<>""),改訂履歴!O11:O30000) -> 0.4
A4: 機能カテゴリ | H4: 10_プロモーションメンテ | U4: 項目 | Z4: 機能設計書 | AP4: {=RIGHT(CELL("filename",$A$1),LEN(CELL("filename",$A$1))-FIND("]",CELL("filename",$A$1)))} -> 表紙
L16: POSサーバーの詳細設計書
L24: =K2&"/"&H4&"/"&Z4 -> POSサーバ/10_プロモーションメンテ/機能設計書
Q44: 承認日 | AA44: 承認者 | AQ44: 版数

Sheet 改訂履歴
A1: システム名 | K1: システム種別 | W1: =IF(表紙!W1="","",表紙!W1) -> 詳細設計書 | AP1: 作成者 | AT1: 作成日 | AY1: 更新者 | BC1: 更新日 | BH1: 版数
A2: =IF(表紙!A2="","",表紙!A2) -> POSサーバー | K2: =IF(表紙!K2="","",表紙!K2) -> POSサーバ | AP2: =IF(表紙!AP2="","",表紙!AP2) -> SonMNT | AT2: =IF(表紙!AT2="","",表紙!AT2) -> 45468 | AY2: =IF(表紙!AY2="","",表紙!AY2) -> AnhTTP | BC2: =IF(表紙!BC2="","",表紙!BC2) -> 45643 | BH2: =IF(表紙!BH2="","",表紙!BH2) -> 0.4
A4: 機能カテゴリ | H4: =IF(表紙!H4="","",表紙!H4) -> 10_プロモーションメンテ | U4: 項目 | Z4: =IF(表紙!Z4="","",表紙!Z4) -> 機能設計書 | AP4: {=RIGHT(CELL("filename",$A$1),LEN(CELL("filename",$A$1))-FIND("]",CELL("filename",$A$1)))} -> 改訂履歴
B8: ■改訂履歴
B10: 更新日 | H10: 更新者 | O10: 版数 | S10: 更新内容 | AX10: 承認日 | BD10: 承認者
B11: 45468 | H11: SonMNT | O11: 0.1 | S11: 新規
B13: 45489 | H13: TuyenNH | O13: 0.2 | S13: 検索イベントロジックを追加で説明 ・【プロモーション】未入力時検索条件 ・①未入力時：先頭99XXXのプロモーションコードを表示し、その後ろに昇順でプロモーションコードを表示 ・②入力時で入力プロモーションコード以上が存在する場合：プロモーションコード昇順でプロモーションコードを表示 ・③入力時で入力プロモーションコード以上が存在しない場合：「データが見つかりませんでした。」を表示
S14: SC1001シート
B15: 45506 | H15: DuNT | O15: 0.3 | S15: 2024/07/25のご指摘による修正
S16: SC1001シート
B17: 45643 | H17: AnhTTP | O17: 0.4 | S17: 新しい画面レイアウトに基づいて処理を更新
S18: SC1001シート

Sheet 指摘履歴
A1: システム名 | K1: システム種別 | W1: 詳細設計書 | AP1: 作成者 | AT1: 作成日 | AY1: 更新者 | BC1: 更新日 | BH1: 版数
A2: POSサーバー | K2: POSサーバー | AP2: カスミ | AT2: 45495 | AY2: 佐々木 | BC2: 45495
A4: 機能カテゴリー | H4: 10_プロモーションメンテ | U4: 項目 | Z4: 機能設計書 | AP4: {=RIGHT(CELL("filename",$A$1),LEN(CELL("filename",$A$1))-FIND("]",CELL("filename",$A$1)))} -> 指摘履歴
B8: ■改訂履歴
B10: 更新日 | H10: 更新者 | O10: 版数 | S10: 更新内容 | AX10: 承認日 | BD10: 承認者
B11: 45498 | H11: カスミ 佐々木 | S11: SC1001
S12: ・テーブルエリアに10行を作成し、ユーザーが新規作成対象プロモーション情報を入力できる。 ＝＞行数は画面レイアウトに可能な範囲で多くする
B13: 45498 | H13: カスミ 佐々木 | S13: SC1001
S14: +24時間店舗の開始/終了時刻は09:00/09:00、通常店舗の開始/終了時刻は7:00～2:00となる。 ＝＞店マスタ 販促時間より開始、終了時間を取得する。
B15: 45498 | H15: カスミ 佐々木 | S15: SC1001
S16: QA95 QA96

Sheet SC1001
A1: システム名 | K1: システム種別 | W1: 詳細設計書 | AP1: 作成者 | AT1: 作成日 | AY1: 更新者 | BC1: 更新日 | BH1: 版数
A2: POSサーバー | K2: POSサーバー | AP2: TuyenNH | AT2: 45462 | AY2: TuyenNH | BC2: 45462 | BH2: 0.1
A4: 機能カテゴリ | H4: =IF(表紙!H4="","",表紙!H4) -> 10_プロモーションメンテ | U4: 項目 | Z4: 機能設計書 | AP4: =MID(CELL("filename",A1),FIND("]",CELL("filename",A1))+1,255) -> SC1001
A7: ■機能説明
A9: 画面ID | E9: SC1001 | O9: 画面名 | U9: プロモーションメンテ画面
A11: イベントID | G11: SC1001_01 | M11: 画面初期化
A12: インプット | M12: 処理概要 | AU12: 出力 | BF12: 参照情報
BF14: 20_画面設計_10_プロモーションメンテ.xlsx
N15: 1. 初期化モードで画面項目を初期化する。
O16: 20_画面設計_10_プロモーションメンテ.xlsxをご参照ください。
A22: イベントID | G22: SC1001_02 | M22: プロモーション情報検索
A23: インプット | M23: 処理概要 | AU23: 出力 | BF23: 参照情報
BF25: ・20_画面設計_10_プロモーションメンテ.xlsx ・40_API設計_AP0105_プロモーション一覧取得.xlsx
N26: 1. プロモーション検索機能を実行する。
P27: 1.1 「AP0105」API呼出処理を実行する。
Q28: APIのパラメータ | X28: パラメータの値
Q29: store_code | X29: 選択された店舗
Q30: code | X30: 画面で入力されたプロモーションコード
Q31: page_number | X31: ・現在のページの場合、デフォルト = 1、 ・次頁の場合、現在のページ + 1
Q32: limit | X32: 12
Q34: ・promotion_codeが入力されていない場合、
R35: => 選択された店舗の全てのプロモーションを検索する。
Q36: ・promotion_codeが入力されている場合、
R37: => プロモーション >=入力されたプロモーションの条件で検索する。
P38: 1.2 返却された結果情報
Q39: 検索が成功した場合、
R40: ・返却レスポンスは40_API設計_AP0105_プロモーション一覧取得.xlsxをご参照ください。
R41: プロモーション一覧を表示する。20_画面設計_40_プロモーションメンテ.xlsxをご参照ください。
S42: +検索条件を満たすデータがある場合、
T43: 先頭99XXXのプロモーションコードを表示し、その後ろに昇順でプロモーションコードを表示する。
S44: +検索条件を満たすデータがない場合、
T45: モーダルを表示する（メッセージ：MSG_ERR_001）
T46: 新規モードで一覧画面を表示する。
R47: ・[F04:クリア]ボタンを有効にする。[新規]ボタンを無効にする。
R48: ・APIから返されたレコード一覧を表示し、ユーザーが編集と削除できる。
R49: ・一覧エリアに変更データがある場合、[F09:確定]ボタンが有効になる。
Q50: 検索が失敗した場合、
R51: ・画面にエラーモーダルを表示する。
R52: ・新規モードで一覧画面を表示する。
A58: イベントID | G58: SC1001_03 | M58: プロモーション新規作成
...

Sheet テンプレート
A1: システム名 | K1: システム種別 | W1: =IF(表紙!W1="","",表紙!W1) -> 詳細設計書 | AP1: 作成者 | AT1: 作成日 | AY1: 更新者 | BC1: 更新日 | BH1: 版数
A2: =IF(表紙!A2="","",表紙!A2) -> POSサーバー | K2: =IF(表紙!K2="","",表紙!K2) -> POSサーバ | AP2: =IF(表紙!AP2="","",表紙!AP2) -> SonMNT | AT2: =IF(表紙!AT2="","",表紙!AT2) -> 45468 | AY2: =IF(表紙!AY2="","",表紙!AY2) -> AnhTTP | BC2: =IF(表紙!BC2="","",表紙!BC2) -> 45643 | BH2: =IF(表紙!BH2="","",表紙!BH2) -> 0.4
A4: 機能カテゴリ | H4: =IF(表紙!H4="","",表紙!H4) -> 10_プロモーションメンテ | U4: 項目 | Z4: =IF(表紙!Z4="","",表紙!Z4) -> 機能設計書 | AP4: =MID(CELL("filename",A1),FIND("]",CELL("filename",A1))+1,255) -> テンプレート
A7: ■機能説明
A9: 画面ID | E9: SCxxxxxx | O9: 画面名
A11: イベントID | G11: KN1010201
A12: インプット | M12: 処理概要 | AU12: 出力 | BF12: 参照情報
N15: 1. ロジック1
N26: 2. ロジック2
