Workbook

Sheet 表紙
A1: システム名 | K1: システム種別 | W1: 詳細設計書 | AP1: 作成者 | AT1: 作成日 | AY1: 更新者 | BC1: 更新日 | BH1: 版数
A2: POSサーバー | K2: POSサーバ | AP2: =改訂履歴!$H$11 -> DuNT | AT2: =改訂履歴!$B$11 -> 45496 | AY2: =LOOKUP(2,1/(改訂履歴!H11:H30002<>""),改訂履歴!H11:H30002) -> DuNT | BC2: =LOOKUP(2,1/(改訂履歴!B11:B30002<>""),改訂履歴!B11:B30002) -> 45623 | BH2: =LOOKUP(2,1/(改訂履歴!O11:O30002<>""),改訂履歴!O11:O30002) -> 0.55
A4: 機能カテゴリ | H4: 71_レジマスタ設定 | U4: 項目 | Z4: 機能設計書 | AP4: {=RIGHT(CELL("filename",$A$1),LEN(CELL("filename",$A$1))-FIND("]",CELL("filename",$A$1)))} -> 表紙
L16: POSサーバーの基本設計書
L24: =K2&"/"&H4&"/"&Z4 -> POSサーバ/71_レジマスタ設定/機能設計書
Q44: 承認日 | AA44: 承認者 | AQ44: 版数

Sheet 改訂履歴
A1: システム名 | K1: システム種別 | W1: =IF(表紙!W1="","",表紙!W1) -> 詳細設計書 | AP1: 作成者 | AT1: 作成日 | AY1: 更新者 | BC1: 更新日 | BH1: 版数
A2: =IF(表紙!A2="","",表紙!A2) -> POSサーバー | K2: =IF(表紙!K2="","",表紙!K2) -> POSサーバ | AP2: =IF(表紙!AP2="","",表紙!AP2) -> DuNT | AT2: =IF(表紙!AT2="","",表紙!AT2) -> 45496 | AY2: =IF(表紙!AY2="","",表紙!AY2) -> DuNT | BC2: =IF(表紙!BC2="","",表紙!BC2) -> 45623 | BH2: =IF(表紙!BH2="","",表紙!BH2) -> 0.55
A4: 機能カテゴリ | H4: =IF(表紙!H4="","",表紙!H4) -> 71_レジマスタ設定 | U4: 項目 | Z4: =IF(表紙!Z4="","",表紙!Z4) -> 機能設計書 | AP4: {=RIGHT(CELL("filename",$A$1),LEN(CELL("filename",$A$1))-FIND("]",CELL("filename",$A$1)))} -> 改訂履歴
B8: ■改訂履歴
B10: 更新日 | H10: 更新者 | O10: 版数 | S10: 更新内容 | AX10: 承認日 | BD10: 承認者
B11: 45496 | H11: DuNT | O11: 0.1 | S11: 新規
B13: 45512 | H13: DuNT | O13: 0.2 | S13: MD7101：新規作成時の重複バリデーションチェックを修正する。
S14: SC7102: 新規作成されたレコードを編集・削除する。
B15: 45525 | H15: DuNT | O15: 0.3 | S15: CSV説明ファイルを別途作成する
S16: テナントレジ部門バリデーションチェックの説明を追加する。
B17: 45527 | H17: DuNT | O17: 0.4 | S17: SC7101: レシートメッセージのリストのみを取得する。
B19: 45547 | H19: DuNT | O19: 0.5 | S19: SC7101：イベントIDSC7101-02：支払い種別リストを取得する API 呼び出しを削除する（MC7104）
S20: SC7101：イベントIDSC7101-03：1000件を超えた場合の説明を追加する。
S21: SC7101：削除ボタンタッチ時に詳細な説明を追加する。
S22: SC7102：編集、削除、新規、確定のボタンをタッチした時に詳細な説明を追加する。
B23: 45555 | H23: DuNT | O23: 0.51 | S23: SC7101：CSVファイルの一部のレコードを取り込む際にエラーが発生した場合のメッセージを追加する。
B25: 45559 | H25: DuNT | O25: 0.52 | S25: SC7101：イベントID「SC7101-02」：ドロップダウンの値をロードするステップを追加する。
S26: SC7101：イベントID「SC7101-11」：保存が成功した後、店舗を選択しなかった場合の処理を追加する。
B27: 45569 | H27: DuNT | O27: 0.53 | S27: SC7102：イベントID「SC7102-07」を追加
S28: SC7101：フロー15とマッピングコピーを説明 イベントID：「SC7101-08」、「SC7101-09」、「SC7101-10」
B29: 45580 | H29: DuNT | O29: 0.54 | S29: MD7101
S30: 店舗を選択した後、元のデータを保持する。 ※上記の項目のうち、店舗ごとに管理されているマスターデータ（例:プリセットレイアウト）がある場合、コピー後に店舗を変更した際に、同じコードを持つレコードを選択する。それがない場合は、その項目を空欄にする。
B31: 45623 | H31: DuNT | O31: 0.55 | S31: SC7102
S32: イベントID「SC7102-08」を追加

Sheet SC7101
A1: システム名 | K1: システム種別 | W1: =IF(表紙!W1="","",表紙!W1) -> 詳細設計書 | AP1: 作成者 | AT1: 作成日 | AY1: 更新者 | BC1: 更新日 | BH1: 版数
A2: =IF(表紙!A2="","",表紙!A2) -> POSサーバー | K2: =IF(表紙!K2="","",表紙!K2) -> POSサーバ | AP2: =IF(表紙!AP2="","",表紙!AP2) -> DuNT | AT2: =IF(表紙!AT2="","",表紙!AT2) -> 45496 | AY2: =IF(表紙!AY2="","",表紙!AY2) -> DuNT | BC2: =IF(表紙!BC2="","",表紙!BC2) -> 45623 | BH2: =IF(表紙!BH2="","",表紙!BH2) -> 0.55
A4: 機能カテゴリ | H4: =IF(表紙!H4="","",表紙!H4) -> 71_レジマスタ設定 | U4: 項目 | Z4: =IF(表紙!Z4="","",表紙!Z4) -> 機能設計書 | AP4: =MID(CELL("filename",A1),FIND("]",CELL("filename",A1))+1,255) -> SC7101
A7: ■機能説明
A9: 画面ID | E9: SC7101 | O9: 画面名 | U9: レジマスタ設定画面
A11: イベントID | G11: SC7101-01 | M11: 画面初期化
A12: インプット | M12: 処理概要 | AU12: 出力 | BF12: 参照情報
BF14: 20_画面設計_71_レジマスタ設定.xlsx
N15: 1. 画面項目の初期化を実行する。
O16: 20_画面設計_71_レジマスタ設定.xlsxのSC7101シートをご参照ください。
A23: イベントID | G23: SC7101-02 | M23: 画面初期化データを取得する。
A24: インプット | M24: 処理概要 | AU24: 出力 | BF24: 参照情報
N27: 1. KN7101_検索条件一覧取得機能を実行する。
O28: 1.1 「AP1503」APIを使用してノード種別、ファンクションレイアウト、キーボードレイアウトの一覧を取得する。
O30: 1.1.1「AP1503」APIを呼び出す。
P32: APIのパラメータ | W32: パラメータの値
P33: master_code | W33: MC7101, MC7102, MC7103
O35: 1.1.2 返却された結果情報
O36: ①．一覧取得成功の場合
P37: 返却された結果
P38: 1. status_code | AA38: 200 (OK)
P39: 2. message | AA39: ブランク
P40: 3. data | AA40: コードマスタ一覧
BF41: 40_API設計_AP1503_コードマスタ取得.xlsx
P42: 40_API設計_AP1503_コードマスタ取得.xlsxのレスポンスをご参照ください。
O43: ②．エラーの場合、以下のように実行する。
P44: 404エラーの場合：空き一覧を表示する。
P45: その他のエラーの場合、APIエラーの共通表示処理を実行する。
O47: 1.2 「AP7103」API を使用してレジ種別一覧を取得する。
O49: 1.2.1 「AP7103」APIを呼び出す。
P51: APIのパラメータ | W51: パラメータの値
P52: type | W52: null
O54: 1.2.2 返却された結果情報
O55: ①．一覧取得成功の場合
P56: 返却された結果
P57: 1. status_code | AA57: 200 (OK) | BF57: 40_API設計_AP7103_レジ種別一覧.xlsx
P58: 2. message | AA58: ブランク
P59: 3. data | AA59: レジ種別一覧
P61: 40_API設計_AP7103_レジ種別一覧.xlsxのレスポンスをご参照ください。
O62: ②．エラーの場合、以下のように実行する。
...

Sheet SC7102
A1: システム名 | K1: システム種別 | W1: =IF(表紙!W1="","",表紙!W1) -> 詳細設計書 | AP1: 作成者 | AT1: 作成日 | AY1: 更新者 | BC1: 更新日 | BH1: 版数
A2: =IF(表紙!A2="","",表紙!A2) -> POSサーバー | K2: =IF(表紙!K2="","",表紙!K2) -> POSサーバ | AP2: =IF(表紙!AP2="","",表紙!AP2) -> DuNT | AT2: =IF(表紙!AT2="","",表紙!AT2) -> 45496 | AY2: =IF(表紙!AY2="","",表紙!AY2) -> DuNT | BC2: =IF(表紙!BC2="","",表紙!BC2) -> 45623 | BH2: =IF(表紙!BH2="","",表紙!BH2) -> 0.55
A4: 機能カテゴリ | H4: =IF(表紙!H4="","",表紙!H4) -> 71_レジマスタ設定 | U4: 項目 | Z4: =IF(表紙!Z4="","",表紙!Z4) -> 機能設計書 | AP4: =MID(CELL("filename",A1),FIND("]",CELL("filename",A1))+1,255) -> SC7102
A7: ■機能説明
A9: 画面ID | E9: SC7102 | O9: 画面名 | U9: レジ種別追加画面
A11: イベントID | G11: SC7102-01 | M11: 画面初期化
A12: インプット | M12: 処理概要 | AU12: 出力 | BF12: 参照情報
N15: 1.KN7104_レジ種別一覧取得機能を実行する。
O17: 1.1 「AP7103」APIを呼び出す。
P19: APIのパラメータ | W19: パラメータの値
P20: type | W20: null
O22: 1.2 返却された結果情報
O23: ①．一覧取得成功の場合
P24: 返却された結果
P25: 1. status_code | AA25: 200 (OK)
P26: 2. message | AA26: ブランク
P27: 3. data | AA27: レジ種別一覧
P29: 40_API設計_AP7103_レジ種別一覧.xlsxのレスポンスをご参照ください。
O30: ②．エラーの場合、以下のように実行する。
P32: その他のエラーの場合、APIエラーの共通表示処理を実行する。
N34: 2. 画面項目の初期化を実行する。 | BF34: 20_画面設計_71_レジマスタ設定.xlsx
O36: レジ一覧を画面に表示する。
O37: 20_画面設計_71_レジマスタ設定.xlsxのSC7102シートをご参照ください。
A43: イベントID | G43: SC7102-02 | M43: レジ種別検索
A44: インプット | M44: 処理概要 | AU44: 出力 | BF44: 参照情報
N47: 1.KN7104_レジ種別一覧取得機能を実行する。
O49: 1.1 「AP7103」APIを呼び出す。
P51: APIのパラメータ | W51: パラメータの値
P52: type | W52: 画面から入力されたテキスト
O54: 1.2 返却された結果情報
O55: ①．一覧取得成功の場合
P56: 返却された結果
P57: 1. status_code | AA57: 200 (OK)
P58: 2. message | AA58: ブランク
P59: 3. data | AA59: レジ種別一覧
P61: 40_API設計_AP7103_レジ種別一覧.xlsxのレスポンスをご参照ください。
O62: ②．エラーの場合、以下のように実行する。
P63: APIエラーの共通表示処理を実行する。
N65: 2. レジ種別一覧を画面に表示する。 | BF65: 20_画面設計_71_レジマスタ設定.xlsx
O67: レジ一覧を画面に表示する。
...

Sheet MD7101
A1: システム名 | K1: システム種別 | W1: =IF(表紙!W1="","",表紙!W1) -> 詳細設計書 | AP1: 作成者 | AT1: 作成日 | AY1: 更新者 | BC1: 更新日 | BH1: 版数
A2: =IF(表紙!A2="","",表紙!A2) -> POSサーバー | K2: =IF(表紙!K2="","",表紙!K2) -> POSサーバ | AP2: =IF(表紙!AP2="","",表紙!AP2) -> DuNT | AT2: =IF(表紙!AT2="","",表紙!AT2) -> 45496 | AY2: =IF(表紙!AY2="","",表紙!AY2) -> DuNT | BC2: =IF(表紙!BC2="","",表紙!BC2) -> 45623 | BH2: =IF(表紙!BH2="","",表紙!BH2) -> 0.55
A4: 機能カテゴリ | H4: =IF(表紙!H4="","",表紙!H4) -> 71_レジマスタ設定 | U4: 項目 | Z4: =IF(表紙!Z4="","",表紙!Z4) -> 機能設計書 | AP4: =MID(CELL("filename",A1),FIND("]",CELL("filename",A1))+1,255) -> MD7101
A7: ■機能説明
A9: 画面ID | E9: MD7101 | O9: 画面名 | U9: レジマスタ設定編集モーダル
A11: イベントID | G11: MD7101-01 | M11: 画面初期化
A12: インプット | M12: 処理概要 | AU12: 出力 | BF12: 参照情報
N15: 1.画面初期化モードを確認する。
O16: 1.1 編集の場合：KN7102_レジ詳細取得機能を実行する。
O18: 1.1.1 「AP7101」APIを呼び出す。
P20: APIのパラメータ | W20: パラメータの値
P21: code | W21: 選択されたレジコード
O23: 1.1.2 返却された結果情報
O24: ①．一覧取得成功の場合
P25: 返却された結果
P26: 1. status_code | AA26: 200 (OK)
P27: 2. message | AA27: ブランク
P28: 3. data | AA28: 対象レジ詳細情報
P30: 40_API設計_AP7101_レジ詳細.xlsxのレスポンスをご参照ください。
O31: ②．エラーの場合、以下のように実行する。
P32: その他のエラーの場合、APIエラーの共通表示処理を実行する。 | BF32: 40_API設計_AP7101_レジ詳細.xlsx
O33: 1.2 コピー・新規の場合、ステップ2を実行する。
N35: 2. 画面項目の初期化を実行する。
O37: レジ一覧を画面に表示する。
O38: 20_画面設計_71_レジマスタ設定.xlsxのMD7101シートをご参照ください。
A43: イベントID | G43: MD7101-02 | M43: モーダルを閉じる
A44: インプット | M44: 処理概要 | AU44: 出力 | BF44: 参照情報
N47: 1. モーダルを閉じて、SC7101_レジマスタ設定画面を表示する。
A53: イベントID | G53: MD7101-03 | M53: レジ設定を一時保存する。
A54: インプット | M54: 処理概要 | AU54: 出力 | BF54: 参照情報
N57: 1. 必須項目のバリデーションチェックを行う。
O58: 20_画面設計_71_レジマスタ設定.xlsxの
O59: MD7101シートの必須項目をご参照ください。
O60: ▪バリデーションチェックが失敗した場合：エラーモーダルを表示する。（エラーメッセージ = MSG_VAL_001。その中：{0}が項目タイトルである）
O61: ▪入力必須のバリデーションチェックが成功した場合、ステップ2を実行する。
N62: 2. ノード種別を確認する。
O63: 2.1 node_type = 05（テナントレジ)の場合
P64: 部門の入力必須のバリデーションチェックを行う。
P65: ▪バリデーションチェックが失敗した場合：エラーモーダルを表示する。（エラーメッセージ = MSG_VAL_001。その中：{0}が項目タイトルである）
P66: ▪バリデーションチェックが成功した場合、ステップ2.3を実行する。
...

Sheet テンプレート
A1: システム名 | K1: システム種別 | W1: =IF(表紙!W1="","",表紙!W1) -> 詳細設計書 | AP1: 作成者 | AT1: 作成日 | AY1: 更新者 | BC1: 更新日 | BH1: 版数
A2: =IF(表紙!A2="","",表紙!A2) -> POSサーバー | K2: =IF(表紙!K2="","",表紙!K2) -> POSサーバ | AP2: =IF(表紙!AP2="","",表紙!AP2) -> DuNT | AT2: =IF(表紙!AT2="","",表紙!AT2) -> 45496 | AY2: =IF(表紙!AY2="","",表紙!AY2) -> DuNT | BC2: =IF(表紙!BC2="","",表紙!BC2) -> 45623 | BH2: =IF(表紙!BH2="","",表紙!BH2) -> 0.55
A4: 機能カテゴリ | H4: =IF(表紙!H4="","",表紙!H4) -> 71_レジマスタ設定 | U4: 項目 | Z4: =IF(表紙!Z4="","",表紙!Z4) -> 機能設計書 | AP4: =MID(CELL("filename",A1),FIND("]",CELL("filename",A1))+1,255) -> テンプレート
A7: ■機能説明
A9: 画面ID | E9: SCxxxxxx | O9: 画面名
A11: イベントID | G11: KN1010201
A12: インプット | M12: 処理概要 | AU12: 出力 | BF12: 参照情報
N15: 1. ロジック1
N26: 2. ロジック2
