Workbook

Sheet 表紙
A1: システム名 | K1: システム種別 | W1: 詳細設計書 | AP1: 作成者 | AT1: 作成日 | AY1: 更新者 | BC1: 更新日 | BH1: 版数
A2: POSサーバー | K2: POSサーバ | AP2: =改訂履歴!$H$11 -> DuNT | AT2: =改訂履歴!$B$11 -> 45582 | AY2: =LOOKUP(2,1/(改訂履歴!H11:H30000<>""),改訂履歴!H11:H30000) -> DuNT | BC2: =LOOKUP(2,1/(改訂履歴!B11:B30000<>""),改訂履歴!B11:B30000) -> 45582 | BH2: =LOOKUP(2,1/(改訂履歴!O11:O30000<>""),改訂履歴!O11:O30000) -> 0.1
A4: 機能カテゴリ | H4: 05_ミックスマッチ設定 | U4: 項目 | Z4: 機能設計書 | AP4: {=RIGHT(CELL("filename",$A$1),LEN(CELL("filename",$A$1))-FIND("]",CELL("filename",$A$1)))} -> 表紙
L16: POSサーバーの詳細設計書
L24: =K2&"/"&H4&"/"&Z4 -> POSサーバ/05_ミックスマッチ設定/機能設計書
Q44: 承認日 | AA44: 承認者 | AQ44: 版数

Sheet 改訂履歴
A1: システム名 | K1: システム種別 | W1: =IF(表紙!W1="","",表紙!W1) -> 詳細設計書 | AP1: 作成者 | AT1: 作成日 | AY1: 更新者 | BC1: 更新日 | BH1: 版数
A2: =IF(表紙!A2="","",表紙!A2) -> POSサーバー | K2: =IF(表紙!K2="","",表紙!K2) -> POSサーバ | AP2: =IF(表紙!AP2="","",表紙!AP2) -> DuNT | AT2: =IF(表紙!AT2="","",表紙!AT2) -> 45582 | AY2: =IF(表紙!AY2="","",表紙!AY2) -> DuNT | BC2: =IF(表紙!BC2="","",表紙!BC2) -> 45582 | BH2: =IF(表紙!BH2="","",表紙!BH2) -> 0.1
A4: 機能カテゴリー | H4: =IF(表紙!H4="","",表紙!H4) -> 05_ミックスマッチ設定 | U4: 項目 | Z4: =IF(表紙!Z4="","",表紙!Z4) -> 機能設計書 | AP4: {=RIGHT(CELL("filename",$A$1),LEN(CELL("filename",$A$1))-FIND("]",CELL("filename",$A$1)))} -> 改訂履歴
B8: ■改訂履歴
B10: 更新日 | H10: 更新者 | O10: 版数 | S10: 更新内容 | AX10: 承認日 | BD10: 承認者
B11: 45582 | H11: DuNT | O11: 0.1 | S11: 新規

Sheet SC0501
A1: システム名 | K1: システム種別 | W1: =IF(表紙!W1="","",表紙!W1) -> 詳細設計書 | AP1: 作成者 | AT1: 作成日 | AY1: 更新者 | BC1: 更新日 | BH1: 版数
A2: =IF(表紙!A2="","",表紙!A2) -> POSサーバー | K2: =IF(表紙!K2="","",表紙!K2) -> POSサーバ | AP2: =IF(表紙!AP2="","",表紙!AP2) -> DuNT | AT2: =IF(表紙!AT2="","",表紙!AT2) -> 45582 | AY2: =IF(表紙!AY2="","",表紙!AY2) -> DuNT | BC2: =IF(表紙!BC2="","",表紙!BC2) -> 45582 | BH2: =IF(表紙!BH2="","",表紙!BH2) -> 0.1
A4: 機能カテゴリ | H4: =IF(表紙!H4="","",表紙!H4) -> 05_ミックスマッチ設定 | U4: 項目 | Z4: =IF(表紙!Z4="","",表紙!Z4) -> 機能設計書 | AP4: =MID(CELL("filename",A1),FIND("]",CELL("filename",A1))+1,255) -> SC0501
A7: ■機能説明
A9: 画面ID | E9: SC0501 | O9: 画面名 | U9: ミックスマッチ設定
A11: イベントID | G11: SC0501-01 | M11: 画面初期化
A12: インプット | M12: 処理概要 | AU12: 出力 | BF12: 参照情報
BF14: 20_画面設計_05_ミックスマッチ設定.xlsx
N15: 1. 画面項目の初期化を実行する。
O16: 20_画面設計_05_ミックスマッチ設定.xlsxをご参照ください。
A22: イベントID | G22: SC0501-02 | M22: プロモーション提案
A23: インプット | M23: 処理概要 | AU23: 出力 | BF23: 参照情報
BF25: 20_画面設計_05_ミックスマッチ設定.xlsx
N26: 1. KN0106_プロモーション情報取得機能
O27: 1.1 「AP0106_プロモーション情報取得」呼出処理を実行する。
P28: APIのパラメータ | W28: パラメータの値
P29: selected_store | W29: 選択された店舗
P30: promotion_code | W30: 画面で入力されたプロモーションコード
P32: 40_API設計_AP0106_ プロモーション情報取得.xlsxをご参照ください。
O33: 1.2 返却された結果情報
P34: ▪商品情報取得が成功した場合、
Q35: ・返却レスポンスは40_API設計_AP0106_プロモーション情報取得.xlsxをご参照ください。
Q36: ・以下の画面設計に従って画面に返されるAPIレスポンスのマッピングを実行する。
R37: 20_画面設計_05_ミックスマッチ設定.xlsx
Q38: 有効なプロモーションが選択された場合、プロモーション検索ボタンを無効にする。
P39: ▪ プロモーションが存在していない場合 (response code = 404)
Q40: ・返却レスポンスは40_API設計_AP0106_プロモーション情報取得.xlsxをご参照ください。
Q41: ・20_画面設計_05_ミックスマッチ設定.xlsxの説明に従って、エラーメッセージを画面に表示する。
A47: イベントID | G47: SC0501-03 | M47: プロモーション情報検索
A48: インプット | M48: 処理概要 | AU48: 出力 | BF48: 参照情報
BF50: 20_画面設計_05_ミックスマッチ設定.xlsx
N51: MD0102_プロモーション一覧モーダルに遷移する。
N52: MD0102でプロモーションを選択した場合、モーダルを閉じ、以下のファイルの説明に従って選択されたプロモーション情報を表示する。
N53: 20_画面設計_05_ミックスマッチ設定.xlsx
N54: 有効なプロモーションが選択された場合、プロモーション検索ボタンを無効にする。
A59: イベントID | G59: SC0501-04 | M59: ミックスマッチ検索
A60: インプット | M60: 処理概要 | AU60: 出力 | BF60: 参照情報
BF62: 20_画面設計_05_ミックスマッチ設定.xlsx 40_API設計_AP0501_ミックスマッチ詳細情報.xlsx
N63: 1. ミックスマッチコード入力必須のバリデーションチェックを行う。
O64: 値がある場合、ステップ2を実行する。
...

Sheet MD0501
A1: システム名 | K1: システム種別 | W1: =IF(表紙!W1="","",表紙!W1) -> 詳細設計書 | AP1: 作成者 | AT1: 作成日 | AY1: 更新者 | BC1: 更新日 | BH1: 版数
A2: =IF(表紙!A2="","",表紙!A2) -> POSサーバー | K2: =IF(表紙!K2="","",表紙!K2) -> POSサーバ | AP2: =IF(表紙!AP2="","",表紙!AP2) -> DuNT | AT2: =IF(表紙!AT2="","",表紙!AT2) -> 45582 | AY2: =IF(表紙!AY2="","",表紙!AY2) -> DuNT | BC2: =IF(表紙!BC2="","",表紙!BC2) -> 45582 | BH2: =IF(表紙!BH2="","",表紙!BH2) -> 0.1
A4: 機能カテゴリ | H4: =IF(表紙!H4="","",表紙!H4) -> 05_ミックスマッチ設定 | U4: 項目 | Z4: =IF(表紙!Z4="","",表紙!Z4) -> 機能設計書 | AP4: =MID(CELL("filename",A1),FIND("]",CELL("filename",A1))+1,255) -> MD0501
A7: ■機能説明
A9: 画面ID | E9: MD0501 | O9: 画面名 | U9: ミックスマッチ検索モーダル
A11: イベントID | G11: MD0501-01 | M11: 画面初期化
A12: インプット | M12: 処理概要 | AU12: 出力 | BF12: 参照情報
BF14: 20_画面設計_05_ミックスマッチ設定.xlsx
N15: 1. 画面項目の初期化を実行する。
O16: 20_画面設計_05_ミックスマッチ設定.xlsxのMD0501シートをご参照ください。
A23: イベントID | G23: MD0501-02 | M23: ミックスマッチ検索
A24: インプット | M24: 処理概要 | AU24: 出力 | BF24: 参照情報
BF26: 40_API設計_AP0505_ミックスマッチ一覧取得.xlsx
N27: 1. AP0505を使用してミックスマッチを検索する。
O28: 1.1 「AP0106_プロモーション情報取得」呼出処理を実行する。
P29: APIのパラメータ | W29: パラメータの値
P30: selected_store | W30: 選択中の対象店舗
P31: promotion_code | W31: 画面に入力したプロモーションコードの値 (5桁未満の場合は「0」を追加する)
P32: mix_match_code | W32: 画面に入力したミックスマッチコードの値（5桁未満の場合は「0」を追加する）
P33: code_level_one | W33: 画面に入力した部門コードの値 (2桁未満の場合は「0」を追加する)
P34: duration | W34: 画面で選択しているアイテムのインデックス
P35: date | W35: 画面に入力した日付の値
P36: 40_API設計_AP0505_ミックスマッチ一覧取得.xlsxをご参照ください。
O37: 1.2 返却された結果情報
P38: ▪ミックスマッチ一覧取得が成功した場合、
Q39: ・返却レスポンスは40_API設計_AP0505_ミックスマッチ一覧取得.xlsxをご参照ください。
Q40: ・以下の画面設計に従ってモーダルに返されるAPIレスポンスのマッピングを実行する。
R41: 20_画面設計_05_ミックスマッチ設定.xlsx
R42: 1000件を超えた場合、MSG_INFO_001（その中に、{0} = 1000）を表示する。
P43: ▪ミックスマッチが存在しない場合（レスポンスコード = 404）
Q44: ミックスマッチのテーブルの列名の行の下に、サーバーから返されたエラーメッセージを表示する。
P45: ▪他のエラーの場合、エラーモーダルを表示する（サーバーから返されたメッセージ）
A51: イベントID | G51: MD0501-03 | M51: SC0501画面に戻る
A52: インプット | M52: 処理概要 | AU52: 出力 | BF52: 参照情報
N55: 1. MD0501_汎用マスタ設定モーダルを閉じ、
O56: SC0501_ミックスマッチ設定画面を表示する。
A63: イベントID | G63: MD0502-04 | M63: 対象ミックスマッチ選択
A64: インプット | M64: 処理概要 | AU64: 出力 | BF64: 参照情報
BF66: イベントID：SC0501-04
N67: 1. モーダルを閉じ、同時にミックスマッチコードとプロモーションコードをSC0501_ミックスマッチ設定画面に渡し、
...

Sheet MD0502
A1: システム名 | K1: システム種別 | W1: =IF(表紙!W1="","",表紙!W1) -> 詳細設計書 | AP1: 作成者 | AT1: 作成日 | AY1: 更新者 | BC1: 更新日 | BH1: 版数
A2: =IF(表紙!A2="","",表紙!A2) -> POSサーバー | K2: =IF(表紙!K2="","",表紙!K2) -> POSサーバ | AP2: =IF(表紙!AP2="","",表紙!AP2) -> DuNT | AT2: =IF(表紙!AT2="","",表紙!AT2) -> 45582 | AY2: =IF(表紙!AY2="","",表紙!AY2) -> DuNT | BC2: =IF(表紙!BC2="","",表紙!BC2) -> 45582 | BH2: =IF(表紙!BH2="","",表紙!BH2) -> 0.1
A4: 機能カテゴリ | H4: =IF(表紙!H4="","",表紙!H4) -> 05_ミックスマッチ設定 | U4: 項目 | Z4: =IF(表紙!Z4="","",表紙!Z4) -> 機能設計書 | AP4: =MID(CELL("filename",A1),FIND("]",CELL("filename",A1))+1,255) -> MD0502
A7: ■機能説明
A9: 画面ID | E9: MD0502 | O9: 画面名 | U9: 汎用マスタ設定モーダル
A11: イベントID | G11: MD0502-01 | M11: 画面初期化
A12: インプット | M12: 処理概要 | AU12: 出力 | BF12: 参照情報
BF14: 20_画面設計_05_ミックスマッチ設定.xlsx
N15: 1. 画面項目の初期化を実行する。
O16: 20_画面設計_05_ミックスマッチ設定.xlsxのMD0502シートをご参照ください。
A23: イベントID | G23: MD0502-02 | M23: SC0501画面に戻る
A24: インプット | M24: 処理概要 | AU24: 出力 | BF24: 参照情報
N27: 1. MD0501_汎用マスタ設定モーダルを閉じ、
O28: SC0501_ミックスマッチ設定画面を表示する。
A35: イベントID | G35: MD0502-03 | M35: ミックスマッチオプションに設定を適用する。
A36: インプット | M36: 処理概要 | AU36: 出力 | BF36: 参照情報
N39: 1. 3オプションの設定値の重複のバリデーションチェックを行う。
O40: ・重複している設定値がない場合：ステップ2とステップ3を実行する。
O41: ・重複している設定値がある場合：MSG_VAL_050を表示する。
N43: 2. モーダルを閉じる
N44: 3. SC0501_ミックスマッチ設定画面のミックスマッチオプションの成立個数に設定値を更新する。
O45: オプションを追加する場合、オプションを昇順に追加する。
O46: オプションを減らす場合、末尾のオプションを削除する。
