Workbook

Sheet 表紙
A1: システム名 | K1: システム種別 | W1: 詳細設計書 | AP1: 作成者 | AT1: 作成日 | AY1: 更新者 | BC1: 更新日 | BH1: 版数
A2: POSサーバー | K2: POSサーバ | AP2: =改訂履歴!$H$11 -> LoiLV | AT2: =改訂履歴!$B$11 -> 45460 | AY2: =LOOKUP(2,1/(改訂履歴!H11:H30000<>""),改訂履歴!H11:H30000) -> TuyenNH | BC2: =LOOKUP(2,1/(改訂履歴!B11:B30000<>""),改訂履歴!B11:B30000) -> 45596 | BH2: =LOOKUP(2,1/(改訂履歴!O11:O30000<>""),改訂履歴!O11:O30000) -> 0.15
A4: 機能カテゴリ | H4: 21_ジャーナル検索 | U4: 項目 | Z4: 機能設計書 | AP4: {=RIGHT(CELL("filename",$A$1),LEN(CELL("filename",$A$1))-FIND("]",CELL("filename",$A$1)))} -> 表紙
L16: POSサーバーの基本設計書
L24: =K2&"/"&H4&"/"&Z4 -> POSサーバ/21_ジャーナル検索/機能設計書
Q44: 承認日 | AA44: 承認者 | AQ44: 版数

Sheet 改訂履歴
A1: システム名 | K1: システム種別 | W1: =IF(表紙!W1="","",表紙!W1) -> 詳細設計書 | AP1: 作成者 | AT1: 作成日 | AY1: 更新者 | BC1: 更新日 | BH1: 版数
A2: =IF(表紙!A2="","",表紙!A2) -> POSサーバー | K2: =IF(表紙!K2="","",表紙!K2) -> POSサーバ | AP2: =IF(表紙!AP2="","",表紙!AP2) -> LoiLV | AT2: =IF(表紙!AT2="","",表紙!AT2) -> 45460 | AY2: =IF(表紙!AY2="","",表紙!AY2) -> TuyenNH | BC2: =IF(表紙!BC2="","",表紙!BC2) -> 45596 | BH2: =IF(表紙!BH2="","",表紙!BH2) -> 0.15
A4: 機能カテゴリ | H4: =IF(表紙!H4="","",表紙!H4) -> 21_ジャーナル検索 | U4: 項目 | Z4: =IF(表紙!Z4="","",表紙!Z4) -> 機能設計書 | AP4: {=RIGHT(CELL("filename",$A$1),LEN(CELL("filename",$A$1))-FIND("]",CELL("filename",$A$1)))} -> 改訂履歴
B8: ■改訂履歴
B10: 更新日 | H10: 更新者 | O10: 版数 | S10: 更新内容 | AX10: 承認日 | BD10: 承認者
B11: 45460 | H11: LoiLV | O11: 0.1 | S11: 新規
B13: 45517 | H13: AnhDD | O13: 0.2 | S13: 更新
B15: 45533 | H15: AnhNM | O15: 0.3 | S15: SC2101
S16: MSG_VAL_003をMSG_VAL_016に変更
B17: 45539 | H17: AnhDD | O17: 0.4 | S17: SC2101: limit、pageを削除
B19: 45580 | H19: TuyenNH | O19: 0.5 | S19: ・t_journalテーブルのDB構造を変更する。 ・金額での検索項目を削除する。 ・開始日から終了日までの期間で検索する。
S20: [SC101]シート
B21: 45596 | H21: TuyenNH | O21: 0.15 | S21: 「F1：全解除」、「F2：全選択」のアクションを説明 ・表示項目とCSV・PDF出力項目に、ソート（▲/▼）ロジックを追加
S22: [SC2101]シート

Sheet SC2101
A1: システム名 | K1: システム種別 | W1: =IF(表紙!W1="","",表紙!W1) -> 詳細設計書 | AP1: 作成者 | AT1: 作成日 | AY1: 更新者 | BC1: 更新日 | BH1: 版数
A2: =IF(表紙!A2="","",表紙!A2) -> POSサーバー | K2: =IF(表紙!K2="","",表紙!K2) -> POSサーバ | AP2: =IF(表紙!AP2="","",表紙!AP2) -> LoiLV | AT2: =IF(表紙!AT2="","",表紙!AT2) -> 45460 | AY2: =IF(表紙!AY2="","",表紙!AY2) -> TuyenNH | BC2: =IF(表紙!BC2="","",表紙!BC2) -> 45596 | BH2: =IF(表紙!BH2="","",表紙!BH2) -> 0.15
A4: 機能カテゴリ | H4: =IF(表紙!H4="","",表紙!H4) -> 21_ジャーナル検索 | U4: 項目 | Z4: =IF(表紙!Z4="","",表紙!Z4) -> 機能設計書 | AP4: =MID(CELL("filename",A1),FIND("]",CELL("filename",A1))+1,255) -> SC2101
A7: ■機能説明
A9: 画面ID | E9: SC2101 | O9: 画面名 | U9: ジャーナル検索画面
A11: イベントID | G11: SC2101-01 | M11: 画面初期化
A12: インプット | M12: 処理概要 | AU12: 出力 | BF12: 参照情報
BF14: 20_画面設計_21_ジャーナル検索.xlsx 40_API設計_AP7103_レジ種別一覧.xlsx 40_API設計_AP4001_店舗従業員一覧取得.xlsx
N15: 1. 画面項目の初期化を実行する。
O16: 「20_画面設計_21_ジャーナル検索.xlsx」ファイルをご参照ください。
N17: 2. 以下の機能を同時に実行する。
O18: 2.1 KN2101_レジ種別一覧取得
P19: 2.1.1「AP7103」API呼出処理
P21: APIのパラメータ | W21: パラメータの値
P24: 2.1.2 返却された結果情報
P25: ①．「更新成功」の場合
Q26: 返却された結果
Q27: 1. status_code | AB27: 200 (OK)
Q28: 2. message | AB28: ブランク
Q29: 3. data | AB29: レジ一覧
Q31: 40_API設計_AP7103_レジ種別一覧.xlsxのレスポンスをご参照ください。
Q33: 「20_画面設計_21_ジャーナル検索.xlsx」に従って画面に返されたAPIレスポンスをマッピングする。
P37: ②．エラーの場合、以下のように実行する。
Q38: SC2101_ジャーナル検索画面の[レジ（値）]項目に空のデータを表示する。
O41: 2.2 KN4001_従業員情報一覧取得機能
P42: 2.2.1「AP4001」API呼出処理
P44: APIのパラメータ | W44: パラメータの値
P45: store_code | W45: ユーザーが店舗一覧モーダルで選択した店舗コード
P47: 2.2.2 返却された結果情報
P48: ①．「更新成功」の場合
Q49: 返却された結果
Q50: 1. status_code | AB50: 200 (OK)
Q51: 2. message | AB51: ブランク
Q52: 3. data | AB52: 従業員一覧
Q54: 「40_API設計_AP4001_店舗従業員一覧取得.xlsx」のレスポンスをご参照ください。
Q56: 「20_画面設計_21_ジャーナル検索.xlsx」に従って画面に返されたAPIレスポンスをマッピングする。
P60: ②．エラーの場合、以下のように実行する。
Q61: SC2101_ジャーナル検索画面の[担当者（値）]項目に空のデータを表示する。
A68: イベントID | G68: SC2101-02 | M68: ジャーナル検索
A69: インプット | M69: 処理概要 | AU69: 出力 | BF69: 参照情報
...

Sheet テンプレート
A1: システム名 | K1: システム種別 | W1: =IF(表紙!W1="","",表紙!W1) -> 詳細設計書 | AP1: 作成者 | AT1: 作成日 | AY1: 更新者 | BC1: 更新日 | BH1: 版数
A2: =IF(表紙!A2="","",表紙!A2) -> POSサーバー | K2: =IF(表紙!K2="","",表紙!K2) -> POSサーバ | AP2: =IF(表紙!AP2="","",表紙!AP2) -> LoiLV | AT2: =IF(表紙!AT2="","",表紙!AT2) -> 45460 | AY2: =IF(表紙!AY2="","",表紙!AY2) -> TuyenNH | BC2: =IF(表紙!BC2="","",表紙!BC2) -> 45596 | BH2: =IF(表紙!BH2="","",表紙!BH2) -> 0.15
A4: 機能カテゴリ | H4: =IF(表紙!H4="","",表紙!H4) -> 21_ジャーナル検索 | U4: 項目 | Z4: =IF(表紙!Z4="","",表紙!Z4) -> 機能設計書 | AP4: =MID(CELL("filename",A1),FIND("]",CELL("filename",A1))+1,255) -> テンプレート
A7: ■機能説明
A9: 画面ID | E9: SCxxxxxx | O9: 画面名
A11: イベントID | G11: KN1010201
A12: インプット | M12: 処理概要 | AU12: 出力 | BF12: 参照情報
N15: 1. ロジック1
N26: 2. ロジック2
