Workbook

Sheet 表紙
A1: システム名 | K1: システム種別 | W1: 詳細設計書 | AP1: 作成者 | AT1: 作成日 | AY1: 更新者 | BC1: 更新日 | BH1: 版数
A2: POSサーバー | K2: POSサーバ | AP2: =改訂履歴!$H$11 -> DuNT | AT2: =改訂履歴!$B$11 -> 45611 | AY2: =LOOKUP(2,1/(改訂履歴!H11:H30000<>""),改訂履歴!H11:H30000) -> DuNT | BC2: =LOOKUP(2,1/(改訂履歴!B11:B30000<>""),改訂履歴!B11:B30000) -> 45623 | BH2: =LOOKUP(2,1/(改訂履歴!O11:O30000<>""),改訂履歴!O11:O30000) -> 0.11
A4: 機能カテゴリ | H4: 82_店舗マスタ設定 | U4: 項目 | Z4: 機能設計書 | AP4: {=RIGHT(CELL("filename",$A$1),LEN(CELL("filename",$A$1))-FIND("]",CELL("filename",$A$1)))} -> 表紙
L16: POSサーバーの基本設計書
L24: =K2&"/"&H4&"/"&Z4 -> POSサーバ/82_店舗マスタ設定/機能設計書
Q44: 承認日 | AA44: 承認者 | AQ44: 版数

Sheet 改訂履歴
A1: システム名 | K1: システム種別 | W1: =IF(表紙!W1="","",表紙!W1) -> 詳細設計書 | AP1: 作成者 | AT1: 作成日 | AY1: 更新者 | BC1: 更新日 | BH1: 版数
A2: =IF(表紙!A2="","",表紙!A2) -> POSサーバー | K2: =IF(表紙!K2="","",表紙!K2) -> POSサーバ | AP2: =IF(表紙!AP2="","",表紙!AP2) -> DuNT | AT2: =IF(表紙!AT2="","",表紙!AT2) -> 45611 | AY2: =IF(表紙!AY2="","",表紙!AY2) -> DuNT | BC2: =IF(表紙!BC2="","",表紙!BC2) -> 45623 | BH2: =IF(表紙!BH2="","",表紙!BH2) -> 0.11
A4: 機能カテゴリ | H4: =IF(表紙!H4="","",表紙!H4) -> 82_店舗マスタ設定 | U4: 項目 | Z4: =IF(表紙!Z4="","",表紙!Z4) -> 機能設計書 | AP4: {=RIGHT(CELL("filename",$A$1),LEN(CELL("filename",$A$1))-FIND("]",CELL("filename",$A$1)))} -> 改訂履歴
B8: ■改訂履歴
B10: 更新日 | H10: 更新者 | O10: 版数 | S10: 更新内容 | AX10: 承認日 | BD10: 承認者
B11: 45611 | H11: DuNT | O11: 0.1 | S11: 新規
B13: 45623 | H13: DuNT | O13: 0.11 | S13: MD8201：バリデーションチェック更新
S14: SC8201：SC8201-07、SC8201-08、SC8201-02

Sheet SC8201
A1: システム名 | K1: システム種別 | W1: =IF(表紙!W1="","",表紙!W1) -> 詳細設計書 | AP1: 作成者 | AT1: 作成日 | AY1: 更新者 | BC1: 更新日 | BH1: 版数
A2: =IF(表紙!A2="","",表紙!A2) -> POSサーバー | K2: =IF(表紙!K2="","",表紙!K2) -> POSサーバ | AP2: =IF(表紙!AP2="","",表紙!AP2) -> DuNT | AT2: =IF(表紙!AT2="","",表紙!AT2) -> 45611 | AY2: =IF(表紙!AY2="","",表紙!AY2) -> DuNT | BC2: =IF(表紙!BC2="","",表紙!BC2) -> 45623 | BH2: =IF(表紙!BH2="","",表紙!BH2) -> 0.11
A4: 機能カテゴリ | H4: =IF(表紙!H4="","",表紙!H4) -> 82_店舗マスタ設定 | U4: 項目 | Z4: =IF(表紙!Z4="","",表紙!Z4) -> 機能設計書 | AP4: =MID(CELL("filename",A1),FIND("]",CELL("filename",A1))+1,255) -> SC8201
A7: ■機能説明
A9: 画面ID | E9: SC8201 | O9: 画面名 | U9: 店舗一覧
A11: イベントID | G11: SC8201-01 | M11: 画面初期化
A12: インプット | M12: 処理概要 | AU12: 出力 | BF12: 参照情報
BF14: 20_画面設計_82_店舗マスタ設定.xlsx
N15: 1. 画面項目の初期化を実行する。
O16: 20_画面設計_82_店舗マスタ設定.xlsxのSC8201シートをご参照ください。
A23: イベントID | G23: SC8201-02 | M23: 店舗検索
A24: インプット | M24: 処理概要 | AU24: 出力 | BF24: 参照情報
BF26: 20_画面設計_82_店舗マスタ設定.xlsx
N27: 1. KN8206_店舗マスタ検索機能
O28: 1.1 API「AP8201: 店舗情報検索」呼出処理を実行する。
P29: APIのパラメータ | W29: パラメータの値
P30: code | W30: 画面に入力された値
P31: code_filter_type | W31: 画面で選択された値
P32: name | W32: 画面に入力された値
P33: name_filter_type | W33: 画面で選択された値
P34: store_type | W34: 画面で選択された店舗種別
P36: 「40_API設計_AP8201_店舗一覧取得.xlsx」をご参照ください。
O37: 1.2 返却された結果情報
P38: ▪ 店舗一覧取得が成功した場合、
Q39: ・返却レスポンスは「40_API設計_AP8201_店舗一覧取得.xlsx」をご参照ください。
Q40: ・以下の画面設計に従って画面に返されるAPIレスポンスのマッピングを実行する。
R41: 20_画面設計_82_店舗マスタ設定.xlsx
P43: ▪ エラーの場合、
Q44: ・サーバーから返されたエラーメッセージを含むエラーモーダルを表示する。
A49: イベントID | G49: SC8201-03 | M49: 店舗削除
A50: インプット | M50: 処理概要 | AU50: 出力 | BF50: 参照情報
BF52: 20_画面設計_82_店舗マスタ設定.xlsx 40_API設計_AP8202_店舗が削除可能であるかを確認.xlsx
N53: 1. 対象レコードが選択されているかを確認する。
N54: ▪対象レコードが選択されていない場合：エラーモーダルを表示する（エラーメッセージ = MSG_ERR_010）
N55: ▪コピーされたが、確定されていない1件がある場合、エラーモーダルを表示する（エラーメッセージ= MSG_VAL_012）
N56: ▪削除マークが付いていないレコードが選択されている場合：ステップ2を実行する。
N57: ▪削除マークが付いているレコードが選択されている場合：operation_type = 3（対象レコードの削除）を解除し、削除前の状態に戻る。
N59: 2. 店舗が削除可能であるかを確認する。
O60: 2.1 API「AP8202：店舗が削除可能であるかを確認」呼出処理を実行する。
P61: APIのパラメータ | W61: パラメータの値
...

Sheet MD8201
A1: システム名 | K1: システム種別 | W1: =IF(表紙!W1="","",表紙!W1) -> 詳細設計書 | AP1: 作成者 | AT1: 作成日 | AY1: 更新者 | BC1: 更新日 | BH1: 版数
A2: =IF(表紙!A2="","",表紙!A2) -> POSサーバー | K2: =IF(表紙!K2="","",表紙!K2) -> POSサーバ | AP2: =IF(表紙!AP2="","",表紙!AP2) -> DuNT | AT2: =IF(表紙!AT2="","",表紙!AT2) -> 45611 | AY2: =IF(表紙!AY2="","",表紙!AY2) -> DuNT | BC2: =IF(表紙!BC2="","",表紙!BC2) -> 45623 | BH2: =IF(表紙!BH2="","",表紙!BH2) -> 0.11
A4: 機能カテゴリ | H4: =IF(表紙!H4="","",表紙!H4) -> 82_店舗マスタ設定 | U4: 項目 | Z4: =IF(表紙!Z4="","",表紙!Z4) -> 機能設計書 | AP4: =MID(CELL("filename",A1),FIND("]",CELL("filename",A1))+1,255) -> MD8201
A7: ■機能説明
A9: 画面ID | E9: MD8201 | O9: 画面名 | U9: 店舗情報モーダル
A11: イベントID | G11: MD8201-01 | M11: 画面初期化
A12: インプット | M12: 処理概要 | AU12: 出力 | BF12: 参照情報
BF14: 20_画面設計_82_店舗マスタ設定.xlsx
N15: 1. 画面項目の初期化を実行する。
O16: 20_画面設計_82_店舗マスタ設定.xlsxのMD8201シートをご参照ください。
A23: イベントID | G23: MD8201-02 | M23: モーダルを閉じる
A24: インプット | M24: 処理概要 | AU24: 出力 | BF24: 参照情報
BF26: 20_画面設計_82_店舗マスタ設定.xlsx
N27: モーダルを閉じ、SC8201_店舗マスタ設定画面を表示する。
A35: イベントID | G35: MD8201-03 | M35: 店舗設定を一時的に保存する。
A36: インプット | M36: 処理概要 | AU36: 出力 | BF36: 参照情報
N39: 1. 必須項目のバリデーションチェックを行う。
O40: 以下のファイルの店舗コード、店舗名称、店舗略称の必須入力のバリデーションチェックを行う。
O41: 20_画面設計_82_店舗マスタ設定.xlsxのMD8201シート
O42: ▪バリデーションチェックが失敗した場合：エラーモーダルを表示する。（エラーメッセージ = MSG_VAL_001。その中：{0}が項目タイトルである）
O43: ▪入力必須のバリデーションチェックが成功した場合、ステップ2を実行する。
N44: 2. 新規作成・コピーされたアイテムは、画面に表示されている一覧と重複バリデーションチェックを行う。
O45: ▪重複している場合、
P46: エラーモーダルを表示する（エラーメッセージ = MSG_VAL_032）
O47: ▪重複していない場合、
P48: ステップ3を実行する。
N49: 3. 新規作成・コピーされたアイテムに対しては存在のバリデーションチェックを行う。
O50: 2.1 「AP8203_店舗存在バリデーションチェック」API呼出処理を実行する。。
P51: APIのパラメータ | W51: パラメータの値
P52: store_code | W52: 画面に入力された値
P54: 40_API設計_AP8203_店舗存在バリデーションチェック.xlsxをご参照ください。
O55: 2.2 返却された結果情報
P56: ▪is_existed = trueの場合、存在している。
Q57: エラーモーダルを表示する（エラーメッセージ = MSG_VAL_032）
P58: ▪is_existed = falseの場合、存在していない。
Q59: モーダルを閉じ、SC8201_店舗マスタ設定画面に戻る。
Q60: SC8201_店舗マスタ設定画面で、operation_type = 1 の入力された情報の1行を
Q61: 追加する(新規作成の場合)
N62: 4. 編集アイテムは
O63: ・モーダルを閉じ、SC8201_店舗マスタ設定画面に戻る。
...
