Workbook
Name a: #REF!
Name a: #REF!
Name a: #REF!
Name a: #REF!
Name a: #REF!
Name a: #REF!
Name all_workbook: SUBSTITUTE(sheet_name,"["&work_book&"]","")
Name all_workbook: SUBSTITUTE(sheet_name,"["&work_book&"]","")
Name all_workbook: SUBSTITUTE(sheet_name,"["&work_book&"]","")
Name all_workbook: SUBSTITUTE(sheet_name,"["&work_book&"]","")
Name all_workbook: SUBSTITUTE(sheet_name,"["&work_book&"]","")
Name all_workbook: SUBSTITUTE(sheet_name,"["&work_book&"]","")
Name all_workbook: SUBSTITUTE(sheet_name,"["&work_book&"]","")
Name all_workbook: SUBSTITUTE(sheet_name,"["&work_book&"]","")
Name Category: [2]_master!$A$2:$A$16
Name chuc_nang: '[3]CN - NV DEV1'!$A$3:$A$7
Name Contract: [4]Data!$C$3:$C$10
Name DAY: #REF!
Name DAY: #REF!
Name DAY: #REF!
Name DAY: #REF!
Name DAY: #REF!
Name DAY: #REF!
Name Excel_BuiltIn__FilterDatabase_1: #REF!
Name Excel_BuiltIn__FilterDatabase_1: #REF!
Name Excel_BuiltIn__FilterDatabase_1: #REF!
Name Excel_BuiltIn__FilterDatabase_1: #REF!
Name Excel_BuiltIn__FilterDatabase_1: #REF!
Name Excel_BuiltIn__FilterDatabase_1: #REF!
Name First_Day: #REF!
Name First_Day: #REF!
Name First_Day: #REF!
Name First_Day: #REF!
Name First_Day: #REF!
Name First_Day: #REF!
Name KIND: [5]Temp!$A$19:$D$19
Name Level: #REF!
Name Level: #REF!
Name Level: #REF!
Name Level: #REF!
Name Level: #REF!
Name Level: #REF!
Name LIFECYCLE: [5]Temp!$A$21:$D$21
Name list1: '[6]Human Management'!#REF!
Name list1: '[6]Human Management'!#REF!
Name list1: '[6]Human Management'!#REF!
Name list1: '[6]Human Management'!#REF!
Name list1: '[6]Human Management'!#REF!
Name list3: '[6]Human Management'!#REF!
Name list3: '[6]Human Management'!#REF!
Name list3: '[6]Human Management'!#REF!
Name list3: '[6]Human Management'!#REF!
Name list3: '[6]Human Management'!#REF!
Name ListQT: [7]Library!$B$1:$B$43
Name Lupack.TenDA: [7]PRJList!$B$3:$B$73
Name method: #REF!
Name method: #REF!
Name method: #REF!
Name method: #REF!
Name method: #REF!

Sheet 表紙
A1: システム名 | K1: システム種別 | AP1: 作成者 | AT1: 作成日 | AY1: 更新者 | BC1: 更新日 | BH1: 版数
A2: 現金専用簡易セルフPOS | AP2: ThaiDD | AT2: 45225 | AY2: =LOOKUP(2,1/(改廃履歴!H11:H30000<>""),改廃履歴!H11:H30000) -> ThaiDD | BC2: =LOOKUP(2,1/(改廃履歴!B11:B30000<>""),改廃履歴!B11:B30000) -> 45316 | BH2: =LOOKUP(2,1/(改廃履歴!O11:O30000<>""),改廃履歴!O11:O30000) -> 0.4
A4: 機能カテゴリ | H4: Thiết kế API Preset | U4: 項目 | AP4: 表紙
L16: Thiết kế API Preset
L24: =K2&"/"&H4&"/"&Z4 -> /Thiết kế API Preset/
Q44: 承認日 | AA44: 承認者 | AQ44: 版数

Sheet 改廃履歴
A1: システム名 | K1: システム種別 | W1: =IF(表紙!W1="","",表紙!W1) | AP1: 作成者 | AT1: 作成日 | AY1: 更新者 | BC1: 更新日 | BH1: 版数
A2: =IF(表紙!A2="","",表紙!A2) -> 現金専用簡易セルフPOS | K2: =IF(表紙!K2="","",表紙!K2) | AP2: =IF(表紙!AP2="","",表紙!AP2) -> ThaiDD | AT2: =IF(表紙!AT2="","",表紙!AT2) -> 45225 | AY2: =IF(表紙!AY2="","",表紙!AY2) -> ThaiDD | BC2: =IF(表紙!BC2="","",表紙!BC2) -> 45316 | BH2: =IF(表紙!BH2="","",表紙!BH2) -> 0.4
A4: 機能カテゴリ | H4: =IF(表紙!H4="","",表紙!H4) -> Thiết kế API Preset | U4: 項目 | Z4: =IF(表紙!Z4="","",表紙!Z4) | AP4: 改廃履歴
B8: ■改廃履歴
B10: 更新日付 | H10: 更新者 | O10: 版数 | S10: 変更内容 | AX10: 承認日付 | BD10: 承認者
B11: 45225 | H11: ThaiDD | O11: 0.1 | S11: Tạo mới
B13: 45257 | H13: DatTV | O13: 0.2 | S13: Sửa lại api A001 và P003
B15: 45265 | H15: ThaiDD | O15: 0.3 | S15: Sửa sheet [JSON定義<menu-button> ], thêm sheet [API P004] và [API P005]
B17: 45287 | H17: ThaiDD | O17: 0.4 | S17: Sửa tên API, Thêm sheet [API P001] và [API P003], [API P006]
B19: 45316 | H19: ThaiDD | O19: 0.4 | S19: Sửa tên sheet [API P001], [API P002], [API P004], [API P005] và [API P006]

Sheet API一覧
A1: 現金POS | AC1: 製品 | AP1: 設計 | DD1: 作成情報 | DM1: 更新情報
AC2: POS-Controller | AP2: API List | DD2: 作成者 | DG2: =IF(表紙!AP2="","",表紙!AP2) -> ThaiDD | DM2: 更新者 | DP2: =IF(表紙!AY2="","",表紙!AY2) -> ThaiDD
DD3: 作成日 | DG3: =IF([10]表紙!AT2="","",[10]表紙!AT2) -> 45097 | DM3: 更新日 | DP3: =IF(表紙!BC2="","",表紙!BC2) -> 45316
B6: No. | E6: API | AC6: METHOD | AI6: Authentication | AQ6: Explanation | CM6: Internal review | CU6: Last update | DC6: Deploy | DL6: MV | DO6: kasumi
B7: Preset
B8: P001 | E8: pos/v1/preset/store | AC8: POST | AI8: Token | AQ8: Lấy danh sách các loại cửa hàng sử dụng chức năng preset
B9: P002 | E9: pos/v1/preset/search | AC9: POST | AI9: Token | AQ9: Tìm kiếm danh sách cài đặt button preset
B10: P003 | E10: pos/v1/preset/detail | AC10: POST | AI10: Token | AQ10: Lấy chi tiết data preset đối với một loại cài đặt button preset
B11: P004 | E11: pos/v1/preset/item | AC11: POST | AI11: Token | AQ11: Lấy thông tin item từ server Fuji thông qua Plu
B12: P005 | E12: pos/v1/preset/detail/update | AC12: POST | AI12: Token | AQ12: Thêm, sửa, xóa data preset
B13: P006 | E13: pos/v1/preset/update | AC13: POST | AI13: Token | AQ13: Update thay đổi (thêm, xóa) loại thanh toán pos button layout code
B14: A001 | E14: pos/v1/preset/app | AC14: POST | AI14: Pos-Token | AQ14: - Tablet sử dụng API này để check update và download nội dung preset update để sử dụng offline - POS-Token được tạo ra bởi server Fujitsu (API A1), dùng cho app POS-Android trên Tablet

Sheet API P001
A1: 現金POS | M1: 製品 | AE1: 設計 | AR1: No. | BB1: API | BU1: METHOD | CJ1: 認証 | CX1: 作成情報 | DG1: 作成情報
M2: POS-Controller | AE2: API Design | AR2: P001 | BB2: pos/v1/preset/store | BU2: POST | CJ2: Bear | CX2: 作成者 | DA2: ThaiDD | DG2: 更新者 | DJ2: ThaiDD
CX3: 作成日 | DA3: 44861 | DG3: 更新日 | DJ3: =IF(表紙!BC2="","",表紙!BC2) -> 45316
B5: リクエスト | BH5: レスポンス<200：OK>
C6: プロパティ | P6: 型 | U6: 文字数 | Z6: 説明 | AK6: 必須 | AN6: 例 | BI6: プロパティ | BV6: 型 | CA6: 文字数 | CF6: 説明 | CS6: 例
C7: (Không có) | BJ7: [
BK8: {
BI9: "company_code": "300",
BI10: "store_code": "0000000002",
BI11: "store_name": "カスミ 並木店",
BI12: "prefecture": "東京都",
BK13: },
BK14: {
BI15: "company_code": "300",
BI16: "store_code": "0000000002",
BI17: "store_name": "カスミ 並木店",
BI18: "prefecture": "茨城県",
BK19: }
BJ20: ]
B22: 補足事項 | BH22: エラーメッセージ
BI23: HTTPステータス | BQ23: メッセージ | CS23: 説明
BI24: 400 | BQ24: Invalid Input
BI25: 404 | BQ25: Not found
A33: ▪Server
B35: Request mapping DB | BH35: Response mapping DB
C36: Properties | V36: Table [Column] | BI36: Properties | CB36: Table [Column]
BI37: company_code | CB37: storemaster[CompanyCode]
BI38: store_code | CB38: storemaster[StoreCode]
BI39: store_name | CB39: storemaster[BranchName]
C49: Additional Information
E51: Query:
E52: SELECT CompanyCode, StoreCode, BranchName FROM storemaster

Sheet API P002
A1: 現金POS | M1: 製品 | AE1: 設計 | AR1: No. | BB1: API | BU1: METHOD | CJ1: 認証 | CX1: 作成情報 | DG1: 作成情報
M2: POS-Controller | AE2: API Design | AR2: P002 | BB2: pos/v1/preset/search | BU2: POST | CJ2: Bear | CX2: 作成者 | DA2: ThaiDD | DG2: 更新者 | DJ2: ThaiDD
CX3: 作成日 | DA3: 44861 | DG3: 更新日 | DJ3: =IF(表紙!BC2="","",表紙!BC2) -> 45316
B5: リクエスト | BH5: レスポンス<200：OK>
C6: プロパティ | P6: 型 | U6: 文字数 | Z6: 説明 | AK6: 必須 | AN6: 例 | BI6: プロパティ | BV6: 型 | CA6: 文字数 | CF6: 説明 | CS6: 例
C7: list_store | P7: String | U7: - | AK7: - | BJ7: [
E8: company_code | P8: String | U8: - | AK8: - | BK8: {
E9: store_code | P9: String | U9: - | AK9: - | BI9: "company_code": "300",
C10: branch_name | P10: String | U10: - | AK10: - | BI10: "store_code": "048405",
C11: button_layout_code | P11: String | U11: - | AK11: - | BI11: "branch_name": "MV関東TEST(048405)",
C12: button_layout_name | P12: String | U12: - | AK12: - | BI12: "button_layout_code": "2201",
BI13: "button_layout_name": "WAON cash charge (Ignica money)",
BI14: "apply_date": "2019-06-12",
BI15: "prefecture": "東京都",
BK16: },
BJ17: ]
B22: 補足事項 | BH22: エラーメッセージ
D23: Khi list_store = null => Tìm kiếm trong tất cả các cửa hàng | BI23: HTTPステータス | BQ23: メッセージ | CS23: 説明
BI24: 400 | BQ24: Invalid Input
BI25: 404 | BQ25: Not found
A33: ▪Server
B35: Request mapping DB | BH35: Response mapping DB
C36: Properties | V36: Table [Column] | BI36: Properties | CB36: Table [Column]
C37: company_code | V37: presetmenumaster[CompanyCode] | BI37: company_code | CB37: presetmenumaster[CompanyCode]
C38: store_code | V38: presetmenumaster[StoreCode] | BI38: store_code | CB38: presetmenumaster[StoreCode]
C39: branch_name | V39: storemaster[BranchName] | BI39: branch_name | CB39: storemaster[BranchName]
C40: button_layout_code | V40: presetmenumaster[ButtonLayoutCode] | BI40: button_layout_code | CB40: presetmenumaster[ButtonLayoutCode]
C41: button_layout_name | V41: presetmenumaster[ButtonLayoutName] | BI41: button_layout_name | CB41: presetmenumaster[ButtonLayoutName]
BI42: apply_date | CB42: presetmenumaster[ApplyDate]
C49: Additional Information
E51: Query:
E52: Sẽ lấy PresetMenuMaster với PageNumber = 0 làm đại diện cho từng loại hình thanh toán máy pos
E53: SELECT s.Prefecture, p.CompanyCode, p.StoreCode, s.BranchName, p.ButtonLayoutCode, p.ButtonLayoutName, p.ApplyDate FROM presetmenumaster p,
E54: (SELECT Prefecture, CompanyCode, StoreCode, BranchName FROM storemaster where BranchName LIKE '%MV%' AND (CompanyCode, StoreCode) IN (('300', '048405'), ('300', '0000000005'))) s
E55: WHERE p.CompanyCode = s.CompanyCode AND p.StoreCode = s.StoreCode AND p.ButtonLayoutCode LIKE '%2201%' AND p.ButtonLayoutName LIKE '%Ignica%' AND p.PageNumber = 0
E56: GROUP BY p.CompanyCode, p.StoreCode, p.ButtonLayoutCode, p.ApplyDate, s.BranchName, p.ButtonLayoutName

Sheet API P003
A1: 現金POS | M1: 製品 | AE1: 設計 | AR1: No. | BB1: API | BU1: METHOD | CJ1: 認証 | CX1: 作成情報 | DG1: 作成情報
M2: POS-Controller | AE2: API Design | AR2: P003 | BB2: pos/v1/preset/detail | BU2: POST | CJ2: Bear | CX2: 作成者 | DA2: ThaiDD | DG2: 更新者 | DJ2: ThaiDD
CX3: 作成日 | DA3: 44861 | DG3: 更新日 | DJ3: =IF(表紙!BC2="","",表紙!BC2) -> 45316
B5: リクエスト | BH5: レスポンス<200：OK>
C6: プロパティ | P6: 型 | U6: 文字数 | Z6: 説明 | AK6: 必須 | AN6: 例 | BI6: プロパティ | BV6: 型 | CA6: 文字数 | CF6: 説明 | CS6: 例
C7: company_code | P7: String | U7: - | AK7: 〇 | AN7: {
C8: store_code | P8: String | U8: - | AK8: 〇 | AN8: company_code: "300", | BI8: JSON定義<menu> | BV8: json | CA8: - | CF8: Reference JSON定義<menu>
C9: button_layout_code | P9: String | U9: - | AK9: 〇 | AN9: store_code: "048405",
AN10: button_layout_code: "2201",
AN11: }
B22: 補足事項 | BH22: エラーメッセージ
BI23: HTTPステータス | BQ23: メッセージ | CS23: 説明
BI24: 400 | BQ24: Invalid Input
BI25: 404 | BQ25: Not found
A32: ▪Server
B34: Additional Information | FX34: "description": "きゅうり １本 ",
FX35: "sub_description": "03"
C36: Query: | FX36: }
FX37: },
C38: SELECT * FROM presetmenumaster s join presetmenubuttonmaster p ON s.CompanyCode = p.CompanyCode AND s.StoreCode = p.StoreCode AND | FX38: {
C39: s.ButtonLayoutCode = p.ButtonLayoutCode ANDs.GroupCode = p.GroupCode AND s.PageNumber = p.PageNumber AND s.ApplyDate = p.ApplyDate | FX39: "button_column_number": 1,
C40: join itemmaster i ON p.CompanyCode =i.CompanyCode AND p.StoreCode = i.StoreCode AND p.settingData = i.itemCode | FX40: "button_row_number": 2,
C41: WHERE s.CompanyCode = '300' AND s.StoreCode = '048405' AND s.ButtonLayoutCode = '2201' AND (s.RECORD_VOID_FLAG = '0' OR s.RECORD_VOID_FLAG = '') AND | FX41: "update_date": "2023-08-04",
C42: (p.RECORD_VOID_FLAG = '0' OR p.RECORD_VOID_FLAG = '') AND (i.RECORD_VOID_FLAG = '0' OR i.RECORD_VOID_FLAG = '') | FX42: "update_time": "00:25:42",
FX43: "apply_date": "2019-06-12",
FX44: "button_column_span": 2,
FX45: "button_row_span": 1,
FX46: "description": "レタス",
FX47: "update_time": "10:49:26",
FX48: "apply_date": "2019-06-12",
FX49: "button_column_span": 2,

Sheet API P003_old
A1: 現金POS | M1: 製品 | AE1: 設計 | AR1: No. | BB1: API | BU1: METHOD | CJ1: 認証 | CX1: 作成情報 | DG1: 更新情報
M2: POS-Controller | AE2: API Design | AR2: =MID(CELL("filename",A1),FIND("]",CELL("filename",A1))+1,255) -> API P003_old | BB2: pos/v1/preset/create | BU2: POST | CJ2: Bearer | CX2: 作成者 | DA2: ThaiDD | DG2: 更新者 | DJ2: ThaiDD
CX3: 作成日 | DA3: 44861 | DG3: 更新日 | DJ3: 44861
A5: ▪Client
B7: Request | BH7: Response<200：OK>
C8: Properties | P8: Type | U8: Length | Z8: Explanation | AK8: required | AN8: Example | BI8: Properties | BV8: Type | CA8: Length | CF8: Explanation | CS8: Example
C9: menu | P9: json | Z9: JSON定義<menu> | BI9: なし | BV9: - | CA9: - | CF9: -
C10: files | P10: multipart/form-data
B17: Additional information | BH17: Error Message
C18: business_type_code: | BI18: HTTP Status | BQ18: message | CS18: Explaination
D19: 2203: Normal cash register ( Ignica money) | BI19: 400 | BQ19: Invalid input
D20: 6202: WAON cash charge (Ignica money)
D21: Trường hợp không điền thông tin các trường preset thì tất cả các giá trị set = null
A27: ▪Server
B29: Request mapping DB | BH29: Response mapping DB
C30: Properties | V30: Table [Column] | BI30: Properties | CB30: Table [Column]
C31: Reference JSON定義<menu>
B39: Additional Information
C40: - Lưu thời điểm create vào PresetMenuMaster[RECORD_CREATE_DATE], PresetMenuMaster[RECORD_CREATE_TIME]
C41: - Lưu thời điểm update vào PresetMenuMaster[RECORD_UPDATE_DATE], PresetMenuMaster[RECORD_UPDATE_TIME] là thời điểm create record
C42: - Lưu mã nhân viên thực hiện update vào cột PresetMenuMaster[LAST_UPDATER]
C43: - set giá trị default PresetMenuMaster[RECORD_VOID_FLAG] = 0 (enable)

Sheet API P004
A1: 現金POS | M1: 製品 | AE1: 設計 | AR1: No. | BB1: API | BU1: METHOD | CJ1: 認証 | CX1: 作成情報 | DG1: 作成情報
M2: POS-Controller | AE2: API Design | AR2: P004 | BB2: pos/v1/preset/item | BU2: POST | CJ2: Bear | CX2: 作成者 | DA2: ThaiDD | DG2: 更新者 | DJ2: ThaiDD
CX3: 作成日 | DA3: 44861 | DG3: 更新日 | DJ3: =IF(表紙!BC2="","",表紙!BC2) -> 45316
B5: リクエスト | BH5: レスポンス<200：OK>
C6: プロパティ | P6: 型 | U6: 文字数 | Z6: 説明 | AK6: 必須 | AN6: 例 | BI6: プロパティ | BV6: 型 | CA6: 文字数 | CF6: 説明 | CS6: 例
C7: company_code | P7: String | U7: - | AK7: 〇 | BJ7: {
C8: store_code | P8: String | U8: - | AK8: 〇 | BJ8: "company_code": "300",
C9: item_code | P9: String | U9: - | AK9: 〇 | BJ9: "store_code": "048405",
BJ10: "item_price": 48.0000,
BJ11: "item_code": "0000000000100",
BJ12: "parent_code": "003002",
BJ13: "description": "きゅうり １本 ",
BJ14: "sub_description": "03"
BK15: }
B22: 補足事項 | BH22: エラーメッセージ
BI23: HTTPステータス | BQ23: メッセージ | CS23: 説明
BI24: 400 | BQ24: Invalid Input
BI25: 404 | BQ25: Not found
A32: ▪Server
B34: Request mapping DB | BH34: Response mapping DB
C35: Properties | V35: Table [Column] | BI35: Properties | CB35: Table [Column]
BI36: company_code | CB36: itemmaster[CompanyCode]
BI37: store_code | CB37: itemmaster[StoreCode]
BI38: item_price | CB38: Response API S010 sales/plu
BI39: item_code | CB39: itemmaster[ItemCode]
BI40: parent_code | CB40: itemmaster[ParentCode]
BI41: description | CB41: Response API S010 sales/plu
BI42: sub_description | CB42: itemmaster[SubDescription]
B48: Additional Information
E50: Query:
E51: SELECT* FROM itemmaster Where ItemCode = '0000000000100' AND CompanyCode = '300' AND StoreCode = '048405'

Sheet API P005
A1: 現金POS | M1: 製品 | AE1: 設計 | AR1: No. | BB1: API | BU1: METHOD | CJ1: 認証 | CX1: 作成情報 | DG1: 作成情報
M2: POS-Controller | AE2: API Design | AR2: P005 | BB2: pos/v1/preset/detail/update | BU2: POST | CJ2: Bear | CX2: 作成者 | DA2: ThaiDD | DG2: 更新者 | DJ2: ThaiDD
CX3: 作成日 | DA3: 44861 | DG3: 更新日 | DJ3: =IF(表紙!BC2="","",表紙!BC2) -> 45316
B5: リクエスト | BH5: レスポンス<200：OK>
C6: プロパティ | P6: 型 | U6: 文字数 | Z6: 説明 | AK6: 必須 | AN6: 例 | BI6: プロパティ | BV6: 型 | CA6: 文字数 | CF6: 説明 | CS6: 例
C7: json | P7: application/json | U7: - | Z7: JSON定義<menu> | AK7: 〇 | BI7: (Không có)
C8: files | P8: multipart/form-data | U8: - | Z8: Dữ liệu của các ảnh
B14: 補足事項 | BH14: エラーメッセージ
BI15: HTTPステータス | BQ15: メッセージ | CS15: 説明
BI16: 400 | BQ16: Invalid Input
BI17: 404 | BQ17: Not found
BI18: 409 | BQ18: Data Exist
A24: ▪Server
B26: Additional Information | FX26: "parent_code": "003002",
FX27: "description": "きゅうり １本 ",
C28: - Khi xóa item thì không delete row đó trong bảng, mà set cột RECORD_VOID_FLAG = 1 (disable) | FX28: "sub_description": "03"
C29: - Khi chọn empty tab thì set tất cả các menu button cột RECORD_VOID_FLAG = 1 (disable) | FX29: }
C30: - Lưu thời điểm update vào RECORD_UPDATE_DATE] và [RECORD_UPDATE_TIME] cho từng item được update trong bảng storemaster, presetmenumaster, presetmenubuttonmaster và itemmaster | FX30: },
C31: - Khi thêm mới thì add sản phẩm vào DB | FX31: {
FX32: "button_column_number": 1,
C33: Query: | FX33: "button_row_number": 2,
C34: UPDATE storemaster s SET s.RECORD_UPDATE_DATE = DATE(NOW()), s.RECORD_UPDATE_TIME = TIME(NOW()) | FX34: "update_date": "2023-08-04",
C35: WHERE s.CompanyCode = '300' AND s.StoreCode = '048405'; | FX35: "update_time": "00:25:42",
C36: - [record_flag] = 0 thực hiện chức năng update | FX36: "apply_date": "2019-06-12",
D37: UPDATE presetmenumaster s SET s.Description = '他色の野菜', s.styleKey = 'PresetRadioButtonLeftStyle2', s.RECORD_UPDATE_DATE = DATE(NOW()), s.RECORD_UPDATE_TIME = TIME(NOW()) | FX37: "button_column_span": 2,
D38: WHERE s.CompanyCode = '300' AND s.StoreCode = '048405' AND s.ButtonLayoutCode = '2201' AND s.GroupCode = 1 AND s.PageNumber = 1 AND s.ApplyDate = '2019-06-12' AND RECORD_VOID_FLAG != '1' | FX38: "button_row_span": 1,
FX39: "description": "レタス",
D40: UPDATE presetmenubuttonmaster s SET s.ButtonColumnSpan = 2, s.ButtonRowSpan = 1, s.StyleKey = 'PresetButtonStyle4', | FX40: "style_key": "PresetButtonStyle4",
D41: s.RECORD_UPDATE_DATE = DATE(NOW()), s.RECORD_UPDATE_TIME = TIME(NOW()), s.StyleInformation = 'kyuuri_cucumber.png' | FX41: "style_information": "vegetable_green_lettuce.png",
D42: WHERE s.CompanyCode = '300' AND s.StoreCode = '048405' AND s.ButtonLayoutCode = '2201' AND s.GroupCode = 1 AND s.PageNumber = 1 AND s.ApplyDate = '2019-06-12' AND | FX42: "event_group_code": 1,
D43: s.ButtonColumnNumber = 2 AND s.ButtonRowNumber = 2 | FX43: "record_void_flag": "0",
FX44: "product_info": {
C45: - [record_flag] = 1 thực hiện Xóa (disable bằng cách update trường [RECORD_VOID_FLAG] = 1) | FX45: "item_price": 138.0000,
E46: + TH Xóa PresetMenuMaster | FX46: "item_code": "0000000000101",
G47: UPDATE presetmenumaster SET RECORD_VOID_FLAG = 1 WHERE CompanyCode = '300' AND StoreCode = '048405' AND ButtonLayoutCode = '2201' AND PageNumber = 1 | FX47: "parent_code": "003002",
G48: UPDATE presetmenubuttonmaster SET RECORD_VOID_FLAG = 1 WHERE CompanyCode = '300' AND StoreCode = '048405' AND ButtonLayoutCode = '2201' AND PageNumber = 1 | FX48: "description": "レタス Ｌ ",
E50: + TH Xóa PresetMenuButtonMaster
G51: UPDATE presetmenubuttonmaster SET RECORD_VOID_FLAG = 1 WHERE CompanyCode = '300' AND StoreCode = '048405' AND ButtonLayoutCode = '2201' AND PageNumber = 1 AND SettingData = '0000000000100'
C53: - [record_flag] = 2 thực hiện Thêm mới (TH đang bị disable thì update enable , TH chưa tồn tại thì thực hiện insert data)
E54: + TH Thêm PresetMenuMaster
...

Sheet API P006
A1: 現金POS | M1: 製品 | AE1: 設計 | AR1: No. | BB1: API | BU1: METHOD | CJ1: 認証 | CX1: 作成情報 | DG1: 作成情報
M2: POS-Controller | AE2: API Design | AR2: P006 | BB2: pos/v1/preset/update | BU2: POST | CJ2: Bear | CX2: 作成者 | DA2: ThaiDD | DG2: 更新者 | DJ2: ThaiDD
CX3: 作成日 | DA3: 44861 | DG3: 更新日 | DJ3: =IF([11]表紙!BC2="","",[11]表紙!BC2) -> 45287
B5: リクエスト | BH5: レスポンス<200：OK>
C6: プロパティ | P6: 型 | U6: 文字数 | Z6: 説明 | AK6: 必須 | AN6: 例 | BI6: プロパティ | BV6: 型 | CA6: 文字数 | CF6: 説明 | CS6: 例
C7: [ | P7: application/json | AK7: 〇 | BI7: (Không có)
D8: company_code | P8: String | U8: - | AK8: 〇
D9: store_code | P9: String | U9: - | AK9: 〇
D10: button_layout_code | P10: String | U10: - | AK10: 〇
D11: button_layout_name | P11: String | U11: - | AK11: -
D12: apply_date | P12: String | U12: - | AK12: -
D13: record_flag | P13: String | U13: - | AK13: 〇
C14: ]
B21: 補足事項 | BH21: エラーメッセージ
BI22: HTTPステータス | BQ22: メッセージ | CS22: 説明
D23: [record_flag] = 1 : Chức năng Xóa, [record_flag] = 2 : Chức năng thêm loại hình thanh toán máy pos | BI23: 400 | BQ23: Invalid Input
D24: [apply_date], [button_layout_name] trường này chỉ bắt buộc khi thực hiện chức năng thêm mới | BI24: 409 | BQ24: Data Exist
A32: ▪Server
B34: Request mapping DB | BH34: Response mapping DB
C35: Properties | V35: Table [Column] | BI35: Properties | CB35: Table [Column]
C36: company_code | V36: presetmenumaster[CompanyCode]
C37: store_code | V37: presetmenumaster[StoreCode]
C38: button_layout_code | V38: presetmenumaster[ButtonLayoutCode]
C39: button_layout_name | V39: presetmenumaster[ButtonLayoutName]
C40: apply_date | V40: presetmenumaster[ApplyDate]
C41: record_flag
C48: Additional Information
D50: Query:
D51: - [record_flag] = 1 : Chức năng Xóa (Disable tất cả các PresetMenuMaster và PresetMenuButtonMaster => update [RECORD_VOID_FLAG] = '1')
E52: UPDATE presetmenumaster SET RECORD_VOID_FLAG = '1' WHERE CompanyCode = '300' AND StoreCode = '048405' AND ButtonLayoutCode = '2201'
E53: UPDATE presetmenubuttonmaster SET RECORD_VOID_FLAG = '1' WHERE CompanyCode = '300' AND StoreCode = '048405' AND ButtonLayoutCode = '2201'
D55: - [record_flag] = 2 : Chức năng thêm mới loại hình thanh toán máy POS
F56: + Check loại hình thanh toán mới đã tồn tại chưa. (Nếu câu query dưới đây có kết quả => đã tồn tại | Ngược lại => Chưa tồn tại)
H57: SELECT * FROM presetmenumaster WHERE CompanyCode = '300' AND StoreCode = '048405' AND ButtonLayoutCode = '2201' AND RECORD_VOID_FLAG != '1'
F59: + Thực hiện update data mới vào DB (Trường hợp Update lỗi => Thực hiện Insert Data)
H60: UPDATE presetmenumaster SET RECORD_VOID_FLAG = '0', ButtonLayoutName = 'Ignica WAON', ApplyDate = '2024-01-01' WHERE CompanyCode = '300' AND StoreCode = '048405' AND ButtonLayoutCode = '2201' AND GroupCode = 0 AND PageNumber = 0
F62: + Thực hiện insert Data thêm mới vào DB (Default sẽ là thêm data có PageNumber = 0 để khi vào phần edit sẽ không hiển thị data này nên)
H63: INSERT INTO presetmenumaster VALUES (0 , '2024-01-23', '00:34:47.000000', '2024-01-23', '00:34:47.000000', '0', '300', '048405', '2203', '0', '0', '2019-06-12', '0', '0', '', '', '123Thaidd')

Sheet A001
A1: 現金POS | M1: 製品 | AE1: 設計 | AR1: No. | BB1: API | BU1: METHOD | CJ1: 認証 | CX1: 作成情報 | DG1: 作成情報
M2: POS-Controller | AE2: API Design | AR2: P006 | BB2: pos/v1/preset/app | BU2: POST | CJ2: Bear | CX2: 作成者 | DA2: ThaiDD | DG2: 更新者 | DJ2: ThaiDD
CX3: 作成日 | DA3: 44861 | DG3: 更新日 | DJ3: =IF(表紙!BC2="","",表紙!BC2) -> 45316
B5: リクエスト | BH5: レスポンス<200：OK>
C6: プロパティ | P6: 型 | U6: 文字数 | Z6: 説明 | AK6: 必須 | AN6: 例 | BI6: プロパティ | BV6: 型 | CA6: 文字数 | CF6: 説明 | CS6: 例
Z7: tìm kiếm tất cả | AN7: {
C8: update_date | P8: string | U8: - | Z8: format yyyy-MM-dd | AK8: - | AN8: "update_date": "2023-07-13", | BI8: JSON定義<menu> | BV8: json | CA8: - | CF8: Reference JSON定義<menu>
C9: update_time | P9: String | U9: - | Z9: format HH:mm:ss | AK9: - | AN9: "update_time": "22:32:22"
AN10: }
B21: 補足事項 | BH21: エラーメッセージ
BI22: HTTPステータス | BQ22: メッセージ | CS22: 説明
D23: Header truyển bearer token của app pos | BI23: 400 | BQ23: Invalid Input
D24: Truyền ngày giờ | BI24: 404 | BQ24: Not found
D25: Mặc định 1 trong 2 trường
D26: truyền null hoặc empty thì
D27: tìm kiếm tất cả
A31: ▪Server
B33: Additional Information | FX33: "description": "きゅうり １本 ",
FX34: "sub_description": "03"
C35: Query: | FX35: }
FX36: },
C37: SELECT * FROM presetmenumaster s join presetmenubuttonmaster p ON s.CompanyCode = p.CompanyCode AND s.StoreCode = p.StoreCode AND | FX37: {
C38: s.BusinessTypeCode = p.BusinessTypeCode ANDs.GroupCode = p.GroupCode AND s.PageNumber = p.PageNumber AND s.ApplyDate = p.ApplyDate | FX38: "button_column_number": 1,
C39: join itemmaster i ON p.CompanyCode =i.CompanyCode AND p.StoreCode = i.StoreCode AND p.settingData = i.itemCode | FX39: "button_row_number": 2,
C40: WHERE s.CompanyCode = '300' AND s.StoreCode = '048405' AND (s.RECORD_VOID_FLAG = '0' OR s.RECORD_VOID_FLAG = '') AND | FX40: "update_date": "2023-08-04",
C41: (s.RECORD_UPDATE_DATE > '2023-07-13' OR (s.RECORD_UPDATE_DATE = '2023-07-13'AND s.RECORD_UPDATE_TIME > '22:32:22') AND | FX41: "update_time": "00:25:42",
C42: (p.RECORD_VOID_FLAG = '0' OR p.RECORD_VOID_FLAG = '') AND (i.RECORD_VOID_FLAG = '0' OR i.RECORD_VOID_FLAG = '') | FX42: "apply_date": "2019-06-12",
FX43: "button_column_span": 2,
FX44: "button_row_span": 1,
FX45: "description": "レタス",
FX46: "update_time": "10:49:26",
FX47: "apply_date": "2019-06-12",
FX48: "button_column_span": 2,

Sheet JSON定義<menu>
A1: 現金POS | M1: 製品 | AE1: 設計 | AR1: No. | BB1: API | BU1: METHOD | CJ1: 認証 | CX1: 作成情報 | DG1: 更新情報
M2: POS-Controller | AE2: WebAPI 設計 | BB2: =MID(CELL("filename",A1),FIND("]",CELL("filename",A1))+1,255) -> JSON定義<menu> | BU2: - | CJ2: - | CX2: 作成者 | DA2: ThaiDD | DG2: 更新者 | DJ2: ThaiDD
CX3: 作成日 | DA3: 45088 | DG3: 更新日 | DJ3: =IF(表紙!BC2="","",表紙!BC2) -> 45316
A5: ▪Client
C7: Properties | AB7: Type | AG7: Length | AL7: Explanation | BS7: required | BV7: Example
BV8: [
BV9: {
C10: company_code | AB10: string | BV10: "company_code": "300",
C11: store_code | AB11: string | BV11: "store_code": "048405",
C12: business_type_code | AB12: string | BV12: "button_layout_code": "2201",
C13: group_code | AB13: int | BV13: "group_code": 1,
C14: page_number | AB14: int | BV14: "page_number": 1,
C15: apply_date | AB15: string | BV15: "apply_date": "2019-06-12",
C16: update_date | AB16: string | BV16: "update_date": "2023-08-04",
C17: update_time | AB17: string | BV17: "update_time": "11:26:43",
C18: button_column_count | AB18: int | BV18: "button_column_count": 10,
C19: button_row_count | AB19: int | BV19: "button_row_count": 5,
C20: description | AB20: string | BV20: "description": "緑色の野菜A",
C21: style_key | AB21: string | BV21: "style_key": "PresetRadioButtonLeftStyle2",
C22: record_flag | AB22: string | BV22: "record_flag": "0",
C23: menu_buttons | AB23: json array | AG23: - | AL23: reference JSON定義<menu-button> | BV23: "menu_buttons": []
BV24: }
BV25: ]
B27: 補足事項
E29: [record_flag] = 0 : Chức năng Update, [record_flag] = 1 : Chức năng Xóa, [record_flag] = 2 : Chức năng thêm sản phẩm
A34: ▪Server
B36: Request mapping DB | BH36: Response mapping DB
C37: Properties | V37: Table [Column] | BI37: Properties | CB37: Table [Column]
BI38: company_code | CB38: presetmenumaster[CompanyCode]
BI39: store_code | CB39: presetmenumaster[StoreCode]
BI40: button_layout_code | CB40: presetmenumaster[ButtonLayoutCode]
BI41: group_code | CB41: presetmenumaster[GroupCode]
BI42: page_number | CB42: presetmenumaster[PageNumber]
BI43: apply_date | CB43: presetmenumaster[ApplyDate]
BI44: update_date | CB44: presetmenumaster[RECORD_UPDATE_DATE]
BI45: update_time | CB45: presetmenumaster[RECORD_UPDATE_TIME]
BI46: button_column_count | CB46: presetmenumaster[ButtonColumnCount]
BI47: button_row_count | CB47: presetmenumaster[ButtonRowCount]
BI48: description | CB48: presetmenumaster[Description]
BI49: style_key | CB49: presetmenumaster[StyleKey]
...

Sheet JSON定義<menu-button> 
A1: 現金POS | M1: 製品 | AE1: 設計 | AR1: No. | BB1: API | BU1: METHOD | CJ1: 認証 | CX1: 作成情報 | DG1: 更新情報
M2: POS-Controller | AE2: WebAPI 設計 | BB2: =MID(CELL("filename",A1),FIND("]",CELL("filename",A1))+1,255) -> JSON定義<menu-button> | BU2: - | CJ2: - | CX2: 作成者 | DA2: ThaiDD | DG2: 更新者 | DJ2: ThaiDD
CX3: 作成日 | DA3: 45088 | DG3: 更新日 | DJ3: =IF(表紙!BC2="","",表紙!BC2) -> 45316
A5: ▪Client
C7: Properties | AB7: Type | AG7: Length | AL7: Explanation | BS7: required | BV7: Example
BV8: {
C9: menu_buttons | AB9: json | BV9: "menu_buttons": [{
D10: button_column_number | AB10: int | BV10: "button_column_number": 1,
D11: button_row_number | AB11: int | BV11: "button_row_number": 1,
D12: update_date | AB12: string | BV12: "update_date": "2023-08-04",
D13: update_time | AB13: string | BV13: "update_time": "22:49:49",
D14: apply_date | AB14: string | BV14: "apply_date": "2019-06-12",
D15: button_column_span | AB15: int | BV15: "button_column_span": 2,
D16: button_row_span | AB16: int | BV16: "button_row_span": 1,
D17: description | AB17: string | BV17: "description": "きゅうり",
D18: style_key | AB18: string | BV18: "style_key": "PresetButtonStyle4",
D19: style_information | AB19: string | BV19: "style_information": "fish_sake_kirimi.png",
D20: event_group_code | AB20: int | BV20: "event_group_code": 1,
D21: record_flag | AB21: string | BV21: "record_flag": "0",
D22: has_changed_image | AB22: bool | AI22: Chỉ sử dụng cho API update pos/v1/preset/update | CB22: "has_changed_image": true,
D23: product_info | AB23: json | BV23: "product_info": {
F24: item_price | AB24: long | BV24: "item_price": 48.0000,
F25: item_code | AB25: string | BV25: "item_code": "0000000000100",
F26: parent_code | AB26: string | BV26: "parent_code": "003002",
F27: description | AB27: string | BV27: "description": "きゅうり １本 ",
F28: sub_description | AB28: string | BV28: "sub_description": "03"
BV29: }
B41: 補足事項
F43: [record_flag] = 0 : Chức năng Update, [record_flag] = 1 : Chức năng Xóa, [record_flag] = 2 : Chức năng Insert
A48: ▪Server
B50: Request mapping DB | BH50: Response mapping DB
C51: Properties | V51: Table [Column] | BI51: Properties | CB51: Table [Column]
BI52: menu_buttons
BJ53: button_column_number | CB53: presetmenubuttonmaster[ButtonColumnNumber]
BJ54: button_row_number | CB54: presetmenubuttonmaster[ButtonRowNumber]
BJ55: update_date | CB55: presetmenubuttonmaster[RECORD_UPDATE_DATE]
BJ56: update_time | CB56: presetmenubuttonmaster[RECORD_UPDATE_TIME]
BJ57: apply_date | CB57: presetmenubuttonmaster[ApplyDate]
BJ58: button_column_span | CB58: presetmenubuttonmaster[ButtonColumnSpan]
BJ59: button_row_span | CB59: presetmenubuttonmaster[ButtonRowSpan]
...
