Workbook

Sheet 表紙
A1: システム名 | K1: システム種別 | W1: 詳細設計書 | AP1: 作成者 | AT1: 作成日 | AY1: 更新者 | BC1: 更新日 | BH1: 版数
A2: POSサーバー | K2: POSサーバー | AP2: =改訂履歴!$H$11 -> DuNT | AT2: =改訂履歴!$B$11 -> 45665 | AY2: =LOOKUP(2,1/(改訂履歴!H11:H30000<>""),改訂履歴!H11:H30000) -> DuNT | BC2: =LOOKUP(2,1/(改訂履歴!B11:B30000<>""),改訂履歴!B11:B30000) -> 45721 | BH2: =LOOKUP(2,1/(改訂履歴!O11:O30000<>""),改訂履歴!O11:O30000) -> 0.12
A4: 機能カテゴリ | H4: AP4502 | U4: 項目 | Z4: API設計書 | AP4: {=RIGHT(CELL("filename",$A$1),LEN(CELL("filename",$A$1))-FIND("]",CELL("filename",$A$1)))} -> 表紙
L16: POSサーバーの基本設計書
L24: =K2&"/"&H4&"/"&Z4 -> POSサーバー/AP4502/API設計書
Q44: 承認日 | AA44: 承認者 | AQ44: 版数

Sheet 改訂履歴
A1: システム名 | K1: システム種別 | W1: =IF(表紙!W1="","",表紙!W1) -> 詳細設計書 | AP1: 作成者 | AT1: 作成日 | AY1: 更新者 | BC1: 更新日 | BH1: 版数
A2: =IF(表紙!A2="","",表紙!A2) -> POSサーバー | K2: =IF(表紙!K2="","",表紙!K2) -> POSサーバー | AP2: =IF(表紙!AP2="","",表紙!AP2) -> DuNT | AT2: =IF(表紙!AT2="","",表紙!AT2) -> 45665 | AY2: =IF(表紙!AY2="","",表紙!AY2) -> DuNT | BC2: =IF(表紙!BC2="","",表紙!BC2) -> 45721 | BH2: =IF(表紙!BH2="","",表紙!BH2) -> 0.12
A4: 機能カテゴリ | H4: =IF(表紙!H4="","",表紙!H4) -> AP4502 | U4: 項目 | Z4: =IF(表紙!Z4="","",表紙!Z4) -> API設計書 | AP4: {=RIGHT(CELL("filename",$A$1),LEN(CELL("filename",$A$1))-FIND("]",CELL("filename",$A$1)))} -> 改訂履歴
B8: ■改訂履歴
B10: 更新日 | H10: 更新者 | O10: 版数 | S10: 更新内容 | AX10: 承認日 | BD10: 承認者
B11: 45665 | H11: DuNT | O11: 0.1 | S11: 新規
B13: 45720 | H13: DuNT | O13: 0.11 | S13: ロジック更新
B15: 45721 | H15: DuNT | O15: 0.12 | S15: create_date、update_date項目を削除する。

Sheet 処理フロー凡例
A1: システム名 | K1: システム種別 | W1: =IF(表紙!W1="","",表紙!W1) -> 詳細設計書 | AP1: 作成者 | AT1: 作成日 | AY1: 更新者 | BC1: 更新日 | BH1: 版数
A2: =IF(表紙!A2="","",表紙!A2) -> POSサーバー | K2: =IF(表紙!K2="","",表紙!K2) -> POSサーバー | AP2: =IF(表紙!AP2="","",表紙!AP2) -> DuNT | AT2: =IF(表紙!AT2="","",表紙!AT2) -> 45665 | AY2: =IF(表紙!AY2="","",表紙!AY2) -> DuNT | BC2: =IF(表紙!BC2="","",表紙!BC2) -> 45721 | BH2: =IF(表紙!BH2="","",表紙!BH2) -> 0.12
A4: 機能カテゴリ | H4: =IF(表紙!H4="","",表紙!H4) -> AP4502 | U4: 項目 | Z4: =IF(表紙!Z4="","",表紙!Z4) -> API設計書 | AP4: =MID(CELL("filename",A1),FIND("]",CELL("filename",A1))+1,255) -> 処理フロー凡例
B7: ●API処理フロー

Sheet AP4502
A1: システム名 | K1: システム種別 | W1: =IF(表紙!W1="","",表紙!W1) -> 詳細設計書 | AP1: 作成者 | AT1: 作成日 | AY1: 更新者 | BC1: 更新日 | BH1: 版数
A2: =IF(表紙!A2="","",表紙!A2) -> POSサーバー | K2: =IF(表紙!K2="","",表紙!K2) -> POSサーバー | AP2: =IF(表紙!AP2="","",表紙!AP2) -> DuNT | AT2: =IF(表紙!AT2="","",表紙!AT2) -> 45665 | AY2: =IF(表紙!AY2="","",表紙!AY2) -> DuNT | BC2: =IF(表紙!BC2="","",表紙!BC2) -> 45721 | BH2: =IF(表紙!BH2="","",表紙!BH2) -> 0.12
A4: 機能カテゴリ | H4: =IF(表紙!H4="","",表紙!H4) -> AP4502 | U4: 項目 | Z4: =IF(表紙!Z4="","",表紙!Z4) -> API設計書 | AP4: =MID(CELL("filename",A1),FIND("]",CELL("filename",A1))+1,255) -> AP4502
B7: 1. 概要
C9: PLUコードを基に商品が既に存在しているかを確認する。
B11: 2. リクエスト
C13: 2.1 Request URL
C15: No. | E15: URL | AG15: HTTPメソッド | AQ15: 備考
C16: 1 | E16: api/v1/product/existed | AG16: GET
C18: 2. 2 Request Header
C20: No. | E20: ヘッダー | L20: 必須 | O20: 型 | S20: デフォルト値 | Z20: 項目説明 | AQ20: 備考
C21: 1 | E21: Authorization | L21: ○ | O21: String | S21: - | Z21: Api key | AQ21: 形式："Bearer {api_key}"
C22: 2 | E22: Accept | L22: - | O22: String | S22: - | Z22: Accept
C23: 3 | E23: Content-Type | L23: ○ | O23: String | S23: application/json | Z23: Content-Type
C26: 4 | E26: User-Agent | L26: - | O26: String | S26: - | Z26: User-Agent
C27: 5 | E27: Accept-Encoding | L27: - | O27: String | S27: - | Z27: Accept-Encoding
C30: 2.3 Query Parameter/ path parameter
C32: No. | E32: パラメータ | L32: 必須 | O32: 型 | S32: デフォルト値 | Z32: 項目説明 | AQ32: 備考
C33: 1 | E33: plu | L33: - | O33: string | S33: - | Z33: PLUコード | AQ33: ・13桁。13桁未満の場合、エラーメッセージ = MSG_VAL_002
C35: 2.4 Request Body
D36: NA
C37: No. | E37: JSON name | L37: 型 | S37: 項目説明 | AC37: 備考
C38: 1 | E38: record_id | L38: BigInt | S38: m_item.RECORD_ID
C39: 3 | E39: my_company_code | L39: String | S39: m_item.MyCompanyCode
C40: 4 | E40: item_code | L40: String | S40: m_item.ItemCode
C41: 5 | E41: tax_group_code | L41: String | S41: m_item.TaxGroupCode | AC41: 商品の税種別コード
C42: 6 | E42: tax_group_name | L42: String | S42: TaxCodeMaster.Description | AC42: 税種別の名称
C43: 7 | E43: tax_rate | L43: Int | S43: TaxCodeMaster.Rate | AC43: 税率
C44: 8 | E44: code_level_one | L44: string | S44: m_item.MDHierarchyCode1 | AC44: 部門コード
C45: 9 | E45: level_one | L45: Int | S45: m_mdhierarchymaster.MDHierarchyLevel | AC45: 部門
C46: 10 | E46: description_level_one | L46: string | S46: m_mdhierarchymaster.Description | AC46: 部門名称
C47: 11 | E47: code_level_two | L47: string | S47: m_item.MDHierarchyCode2 | AC47: 品群コード
C48: 12 | E48: level_two | L48: Int | S48: m_mdhierarchymaster.MDHierarchyLevel | AC48: 品群
C49: 13 | E49: description_level_two | L49: string | S49: m_mdhierarchymaster.Description | AC49: 品群名称
C50: 14 | E50: code_level_three | L50: string | S50: m_item.MDHierarchyCode3 | AC50: 品種コード
C51: 15 | E51: level_three | L51: Int | S51: m_mdhierarchymaster.MDHierarchyLevel | AC51: 品種
C52: 16 | E52: description_level_three | L52: string | S52: m_mdhierarchymaster.Description | AC52: 品種名称
... C55: 19 | E55: description_level_four | L55: string | S55: m_mdhierarchymaster.Description | AC55: 分類名称
C56: 20 | E56: unit_price | L56: Decimal | S56: m_item.UnitPrice
C57: 21 | E57: member_price | L57: Decimal | S57: m_item.MemberPrice
...

Sheet 処理フロー
A1: システム名 | K1: システム種別 | W1: =IF(表紙!W1="","",表紙!W1) -> 詳細設計書 | AP1: 作成者 | AT1: 作成日 | AY1: 更新者 | BC1: 更新日 | BH1: 版数
A2: =IF(表紙!A2="","",表紙!A2) -> POSサーバー | K2: =IF(表紙!K2="","",表紙!K2) -> POSサーバー | AP2: =IF(表紙!AP2="","",表紙!AP2) -> DuNT | AT2: =IF(表紙!AT2="","",表紙!AT2) -> 45665 | AY2: =IF(表紙!AY2="","",表紙!AY2) -> DuNT | BC2: =IF(表紙!BC2="","",表紙!BC2) -> 45721 | BH2: =IF(表紙!BH2="","",表紙!BH2) -> 0.12
A4: 機能カテゴリ | H4: =IF(表紙!H4="","",表紙!H4) -> AP4502 | U4: 項目 | Z4: =IF(表紙!Z4="","",表紙!Z4) -> API設計書 | AP4: =MID(CELL("filename",A1),FIND("]",CELL("filename",A1))+1,255) -> 処理フロー

Sheet テンプレート
A1: システム名 | K1: システム種別 | W1: =IF(表紙!W1="","",表紙!W1) -> 詳細設計書 | AP1: 作成者 | AT1: 作成日 | AY1: 更新者 | BC1: 更新日 | BH1: 版数
A2: =IF(表紙!A2="","",表紙!A2) -> POSサーバー | K2: =IF(表紙!K2="","",表紙!K2) -> POSサーバー | AP2: =IF(表紙!AP2="","",表紙!AP2) -> DuNT | AT2: =IF(表紙!AT2="","",表紙!AT2) -> 45665 | AY2: =IF(表紙!AY2="","",表紙!AY2) -> DuNT | BC2: =IF(表紙!BC2="","",表紙!BC2) -> 45721 | BH2: =IF(表紙!BH2="","",表紙!BH2) -> 0.12
A4: 機能カテゴリ | H4: =IF(表紙!H4="","",表紙!H4) -> AP4502 | U4: 項目 | Z4: =IF(表紙!Z4="","",表紙!Z4) -> API設計書 | AP4: =MID(CELL("filename",A1),FIND("]",CELL("filename",A1))+1,255) -> テンプレート
